{"received_ms":1789987928719,"monotonic_ns":1019369550090700,"raw":"{\"market\":\"0x28a45972fccdaf0fba75dacc59725521035e177d09dd92174f9f52740bccb025\", \"asset_id\":\"114356653315647913247200886351065428002113119844334520181865067698979836634569\", \"bids\":[{\"price\":\"0.01\", \"size\":\"1609.43\"}, {\"price\":\"0.02\", \"size\":\"574.82\"}, {\"price\":\"0.03\", \"size\":\"4012.57\"}, {\"price\":\"0.04\", \"size\":\"625.48\"}, {\"price\":\"0.05\", \"size\":\"5635\"}, {\"price\":\"0.06\", \"size\":\"5298.67\"}, {\"price\":\"0.07\", \"size\":\"6196.71\"}, {\"price\":\"0.08\", \"size\":\"714.5\"}, {\"price\":\"0.09\", \"size\":\"610.12\"}, {\"price\":\"0.1\", \"size\":\"580\"}, {\"price\":\"0.11\", \"size\":\"316.1\"}, {\"price\":\"0.12\", \"size\":\"504.34\"}, {\"price\":\"0.13\", \"size\":\"265\"}], \"asks\":[{\"price\":\"0.99\", \"size\":\"1491.91\"}, {\"price\":\"0.98\", \"size\":\"385.35\"}, {\"price\":\"0.97\", \"size\":\"1270.08\"}, {\"price\":\"0.96\", \"size\":\"165.3\"}, {\"price\":\"0.95\", \"size\":\"237.01\"}, {\"price\":\"0.94\", \"size\":\"85.67\"}, {\"price\":\"0.93\", \"size\":\"159.29\"}, {\"price\":\"0.92\", \"size\":\"81.51\"}, {\"price\":\"0.91\", \"size\":\"252.12\"}, {\"price\":\"0.9\", \"size\":\"99.01\"}, {\"price\":\"0.89\", \"size\":\"129.1\"}, {\"price\":\"0.88\", \"size\":\"67.34\"}, {\"price\":\"0.87\", \"size\":\"123.7\"}, {\"price\":\"0.86\", \"size\":\"66.15\"}, {\"price\":\"0.85\", \"size\":\"197.39\"}, {\"price\":\"0.84\", \"size\":\"65.25\"}, {\"price\":\"0.83\", \"size\":\"115.89\"}, {\"price\":\"0.82\", \"size\":\"64.56\"}, {\"price\":\"0.81\", \"size\":\"113.27\"}, {\"price\":\"0.8\", \"size\":\"74.81\"}, {\"price\":\"0.79\", \"size\":\"112\"}, {\"price\":\"0.78\", \"size\":\"64\"}, {\"price\":\"0.77\", \"size\":\"111\"}, {\"price\":\"0.76\", \"size\":\"64\"}, {\"price\":\"0.75\", \"size\":\"110\"}, {\"price\":\"0.74\", \"size\":\"250\"}, {\"price\":\"0.73\", \"size\":\"289\"}, {\"price\":\"0.72\", \"size\":\"244\"}, {\"price\":\"0.71\", \"size\":\"297\"}, {\"price\":\"0.7\", \"size\":\"281\"}, {\"price\":\"0.69\", \"size\":\"297\"}, {\"price\":\"0.68\", \"size\":\"267\"}, {\"price\":\"0.67\", \"size\":\"310\"}, {\"price\":\"0.66\", \"size\":\"272.64\"}, {\"price\":\"0.65\", \"size\":\"297\"}, {\"price\":\"0.64\", \"size\":\"285.33\"}, {\"price\":\"0.63\", \"size\":\"297\"}, {\"price\":\"0.62\", \"size\":\"272.05\"}, {\"price\":\"0.61\", \"size\":\"310\"}, {\"price\":\"0.6\", \"size\":\"1067\"}, {\"price\":\"0.59\", \"size\":\"297\"}, {\"price\":\"0.58\", \"size\":\"279\"}, {\"price\":\"0.57\", \"size\":\"297\"}, {\"price\":\"0.56\", \"size\":\"267\"}, {\"price\":\"0.55\", \"size\":\"297\"}, {\"price\":\"0.54\", \"size\":\"267\"}, {\"price\":\"0.53\", \"size\":\"302\"}, {\"price\":\"0.52\", \"size\":\"267\"}, {\"price\":\"0.51\", \"size\":\"297\"}, {\"price\":\"0.5\", \"size\":\"267\"}, {\"price\":\"0.49\", \"size\":\"297\"}, {\"price\":\"0.48\", \"size\":\"267\"}, {\"price\":\"0.47\", \"size\":\"297\"}, {\"price\":\"0.46\", \"size\":\"267\"}, {\"price\":\"0.45\", \"size\":\"297\"}, {\"price\":\"0.44\", \"size\":\"267\"}, {\"price\":\"0.43\", \"size\":\"309\"}, {\"price\":\"0.42\", \"size\":\"267\"}, {\"price\":\"0.41\", \"size\":\"297\"}, {\"price\":\"0.4\", \"size\":\"279\"}, {\"price\":\"0.39\", \"size\":\"297\"}, {\"price\":\"0.38\", \"size\":\"267\"}, {\"price\":\"0.37\", \"size\":\"309\"}, {\"price\":\"0.36\", \"size\":\"267\"}, {\"price\":\"0.35\", \"size\":\"297\"}, {\"price\":\"0.34\", \"size\":\"267\"}, {\"price\":\"0.33\", \"size\":\"322\"}, {\"price\":\"0.32\", \"size\":\"292\"}, {\"price\":\"0.31\", \"size\":\"322\"}, {\"price\":\"0.3\", \"size\":\"292\"}, {\"price\":\"0.29\", \"size\":\"403\"}, {\"price\":\"0.28\", \"size\":\"438.8\"}, {\"price\":\"0.27\", \"size\":\"404\"}, {\"price\":\"0.26\", \"size\":\"455.53\"}, {\"price\":\"0.25\", \"size\":\"520\"}, {\"price\":\"0.24\", \"size\":\"424.91\"}, {\"price\":\"0.23\", \"size\":\"547.49\"}, {\"price\":\"0.22\", \"size\":\"433.82\"}, {\"price\":\"0.21\", \"size\":\"427\"}, {\"price\":\"0.2\", \"size\":\"562\"}, {\"price\":\"0.19\", \"size\":\"590\"}, {\"price\":\"0.18\", \"size\":\"753\"}, {\"price\":\"0.17\", \"size\":\"494\"}, {\"price\":\"0.16\", \"size\":\"2920\"}, {\"price\":\"0.15\", \"size\":\"2971.35\"}, {\"price\":\"0.14\", \"size\":\"3600.17\"}], \"hash\":\"6eb971054f6eb4fd9ca10cad142387644a3354cf\", \"timestamp\":\"1789987928697\", \"event_type\":\"book\"}","raw_base64":null}
{"received_ms":1789987928719,"monotonic_ns":1019369550237300,"raw":"{\"market\":\"0x28a45972fccdaf0fba75dacc59725521035e177d09dd92174f9f52740bccb025\", \"asset_id\":\"61819828071723399190623735325323968706432622380635304641786792960078828866875\", \"bids\":[{\"price\":\"0.01\", \"size\":\"1491.91\"}, {\"price\":\"0.02\", \"size\":\"385.35\"}, {\"price\":\"0.03\", \"size\":\"1270.08\"}, {\"price\":\"0.04\", \"size\":\"165.3\"}, {\"price\":\"0.05\", \"size\":\"237.01\"}, {\"price\":\"0.06\", \"size\":\"85.67\"}, {\"price\":\"0.07\", \"size\":\"159.29\"}, {\"price\":\"0.08\", \"size\":\"81.51\"}, {\"price\":\"0.09\", \"size\":\"252.12\"}, {\"price\":\"0.1\", \"size\":\"99.01\"}, {\"price\":\"0.11\", \"size\":\"129.1\"}, {\"price\":\"0.12\", \"size\":\"67.34\"}, {\"price\":\"0.13\", \"size\":\"123.7\"}, {\"price\":\"0.14\", \"size\":\"66.15\"}, {\"price\":\"0.15\", \"size\":\"197.39\"}, {\"price\":\"0.16\", \"size\":\"65.25\"}, {\"price\":\"0.17\", \"size\":\"115.89\"}, {\"price\":\"0.18\", \"size\":\"64.56\"}, {\"price\":\"0.19\", \"size\":\"113.27\"}, {\"price\":\"0.2\", \"size\":\"74.81\"}, {\"price\":\"0.21\", \"size\":\"112\"}, {\"price\":\"0.22\", \"size\":\"64\"}, {\"price\":\"0.23\", \"size\":\"111\"}, {\"price\":\"0.24\", \"size\":\"64\"}, {\"price\":\"0.25\", \"size\":\"110\"}, {\"price\":\"0.26\", \"size\":\"250\"}, {\"price\":\"0.27\", \"size\":\"289\"}, {\"price\":\"0.28\", \"size\":\"244\"}, {\"price\":\"0.29\", \"size\":\"297\"}, {\"price\":\"0.3\", \"size\":\"281\"}, {\"price\":\"0.31\", \"size\":\"297\"}, {\"price\":\"0.32\", \"size\":\"267\"}, {\"price\":\"0.33\", \"size\":\"310\"}, {\"price\":\"0.34\", \"size\":\"272.64\"}, {\"price\":\"0.35\", \"size\":\"297\"}, {\"price\":\"0.36\", \"size\":\"285.33\"}, {\"price\":\"0.37\", \"size\":\"297\"}, {\"price\":\"0.38\", \"size\":\"272.05\"}, {\"price\":\"0.39\", \"size\":\"310\"}, {\"price\":\"0.4\", \"size\":\"1067\"}, {\"price\":\"0.41\", \"size\":\"297\"}, {\"price\":\"0.42\", \"size\":\"279\"}, {\"price\":\"0.43\", \"size\":\"297\"}, {\"price\":\"0.44\", \"size\":\"267\"}, {\"price\":\"0.45\", \"size\":\"297\"}, {\"price\":\"0.46\", \"size\":\"267\"}, {\"price\":\"0.47\", \"size\":\"302\"}, {\"price\":\"0.48\", \"size\":\"267\"}, {\"price\":\"0.49\", \"size\":\"297\"}, {\"price\":\"0.5\", \"size\":\"267\"}, {\"price\":\"0.51\", \"size\":\"297\"}, {\"price\":\"0.52\", \"size\":\"267\"}, {\"price\":\"0.53\", \"size\":\"297\"}, {\"price\":\"0.54\", \"size\":\"267\"}, {\"price\":\"0.55\", \"size\":\"297\"}, {\"price\":\"0.56\", \"size\":\"267\"}, {\"price\":\"0.57\", \"size\":\"309\"}, {\"price\":\"0.58\", \"size\":\"267\"}, {\"price\":\"0.59\", \"size\":\"297\"}, {\"price\":\"0.6\", \"size\":\"279\"}, {\"price\":\"0.61\", \"size\":\"297\"}, {\"price\":\"0.62\", \"size\":\"267\"}, {\"price\":\"0.63\", \"size\":\"309\"}, {\"price\":\"0.64\", \"size\":\"267\"}, {\"price\":\"0.65\", \"size\":\"297\"}, {\"price\":\"0.66\", \"size\":\"267\"}, {\"price\":\"0.67\", \"size\":\"322\"}, {\"price\":\"0.68\", \"size\":\"292\"}, {\"price\":\"0.69\", \"size\":\"322\"}, {\"price\":\"0.7\", \"size\":\"292\"}, {\"price\":\"0.71\", \"size\":\"403\"}, {\"price\":\"0.72\", \"size\":\"438.8\"}, {\"price\":\"0.73\", \"size\":\"404\"}, {\"price\":\"0.74\", \"size\":\"455.53\"}, {\"price\":\"0.75\", \"size\":\"520\"}, {\"price\":\"0.76\", \"size\":\"424.91\"}, {\"price\":\"0.77\", \"size\":\"547.49\"}, {\"price\":\"0.78\", \"size\":\"433.82\"}, {\"price\":\"0.79\", \"size\":\"427\"}, {\"price\":\"0.8\", \"size\":\"562\"}, {\"price\":\"0.81\", \"size\":\"590\"}, {\"price\":\"0.82\", \"size\":\"753\"}, {\"price\":\"0.83\", \"size\":\"494\"}, {\"price\":\"0.84\", \"size\":\"2920\"}, {\"price\":\"0.85\", \"size\":\"2971.35\"}, {\"price\":\"0.86\", \"size\":\"3600.17\"}], \"asks\":[{\"price\":\"0.99\", \"size\":\"1609.43\"}, {\"price\":\"0.98\", \"size\":\"574.82\"}, {\"price\":\"0.97\", \"size\":\"4012.57\"}, {\"price\":\"0.96\", \"size\":\"625.48\"}, {\"price\":\"0.95\", \"size\":\"5635\"}, {\"price\":\"0.94\", \"size\":\"5298.67\"}, {\"price\":\"0.93\", \"size\":\"6196.71\"}, {\"price\":\"0.92\", \"size\":\"714.5\"}, {\"price\":\"0.91\", \"size\":\"610.12\"}, {\"price\":\"0.9\", \"size\":\"580\"}, {\"price\":\"0.89\", \"size\":\"316.1\"}, {\"price\":\"0.88\", \"size\":\"504.34\"}, {\"price\":\"0.87\", \"size\":\"265\"}], \"hash\":\"2f464cbbd1afdc6f3a672c0252102f6ce89b2e6d\", \"timestamp\":\"1789987928697\", \"event_type\":\"book\"}","raw_base64":null}
{"received_ms":1789987928721,"monotonic_ns":1019369551483100,"raw":"{\"market\":\"0x28a45972fccdaf0fba75dacc59725521035e177d09dd92174f9f52740bccb025\", \"price_changes\":[{\"asset_id\":\"61819828071723399190623735325323968706432622380635304641786792960078828866875\", \"price\":\"0.86\", \"size\":\"4600.17\", \"side\":\"BUY\", \"hash\":\"3dd29dfdffca09eadf9a87413355664b684378dd\", \"best_bid\":\"0.86\", \"best_ask\":\"0.87\"}, {\"asset_id\":\"114356653315647913247200886351065428002113119844334520181865067698979836634569\", \"price\":\"0.14\", \"size\":\"4600.17\", \"side\":\"SELL\", \"hash\":\"30c7ef99ecb7a9439485132559d7c920842f7694\", \"best_bid\":\"0.13\", \"best_ask\":\"0.14\"}], \"timestamp\":\"1789987928701\", \"event_type\":\"price_change\"}","raw_base64":null}
{"received_ms":1789987928721,"monotonic_ns":1019369551944500,"raw":"{\"market\":\"0x28a45972fccdaf0fba75dacc59725521035e177d09dd92174f9f52740bccb025\", \"price_changes\":[{\"asset_id\":\"114356653315647913247200886351065428002113119844334520181865067698979836634569\", \"price\":\"0.01\", \"size\":\"1669.43\", \"side\":\"BUY\", \"hash\":\"2ee4b3c2f5ba61a23c6e3adcae443c5a6f271e3b\", \"best_bid\":\"0.13\", \"best_ask\":\"0.14\"}, {\"asset_id\":\"61819828071723399190623735325323968706432622380635304641786792960078828866875\", \"price\":\"0.99\", \"size\":\"1669.43\", \"side\":\"SELL\", \"hash\":\"58dfe61a3d4df2bb6a09989847ee38f27b799976\", \"best_bid\":\"0.86\", \"best_ask\":\"0.87\"}], \"timestamp\":\"1789987928701\", \"event_type\":\"price_change\"}","raw_base64":null}
{"received_ms":1789987928739,"monotonic_ns":1019369569954900,"raw":"{\"market\":\"0x28a45972fccdaf0fba75dacc59725521035e177d09dd92174f9f52740bccb025\", \"asset_id\":\"61819828071723399190623735325323968706432622380635304641786792960078828866875\", \"price\":\"0.87\", \"size\":\"5\", \"fee_rate_bps\":\"0\", \"side\":\"BUY\", \"timestamp\":\"1789987928717\", \"event_type\":\"last_trade_price\", \"transaction_hash\":\"0xff3db33fda4af47f6e56470b15a4b45a91d57fa7ded5c6e61e3684038c14f0a5\"}","raw_base64":null}
{"received_ms":1789987928750,"monotonic_ns":1019369580935600,"raw":"{\"market\":\"0x28a45972fccdaf0fba75dacc59725521035e177d09dd92174f9f52740bccb025\", \"price_changes\":[{\"asset_id\":\"61819828071723399190623735325323968706432622380635304641786792960078828866875\", \"price\":\"0.86\", \"size\":\"4595.17\", \"side\":\"BUY\", \"hash\":\"59aa5b5efff7823d57992466652c64b18051242a\", \"best_bid\":\"0.86\", \"best_ask\":\"0.87\"}, {\"asset_id\":\"114356653315647913247200886351065428002113119844334520181865067698979836634569\", \"price\":\"0.14\", \"size\":\"4595.17\", \"side\":\"SELL\", \"hash\":\"3b3e418dc4863c878c9cbd103e181b6b75c90903\", \"best_bid\":\"0.13\", \"best_ask\":\"0.14\"}], \"timestamp\":\"1789987928727\", \"event_type\":\"price_change\"}","raw_base64":null}
{"received_ms":1789987928750,"monotonic_ns":1019369581064200,"raw":"{\"market\":\"0x28a45972fccdaf0fba75dacc59725521035e177d09dd92174f9f52740bccb025\", \"price_changes\":[{\"asset_id\":\"61819828071723399190623735325323968706432622380635304641786792960078828866875\", \"price\":\"0.86\", \"size\":\"4580\", \"side\":\"BUY\", \"hash\":\"acd5fe039ecb9ebcb65f15a44d23c266d489df4d\", \"best_bid\":\"0.86\", \"best_ask\":\"0.87\"}, {\"asset_id\":\"114356653315647913247200886351065428002113119844334520181865067698979836634569\", \"price\":\"0.14\", \"size\":\"4580\", \"side\":\"SELL\", \"hash\":\"21d7d3ff1251b698e4ccf98e3cd4b257fbfc0ca3\", \"best_bid\":\"0.13\", \"best_ask\":\"0.14\"}], \"timestamp\":\"1789987928727\", \"event_type\":\"price_change\"}","raw_base64":null}
{"received_ms":1789987928750,"monotonic_ns":1019369581162000,"raw":"{\"market\":\"0x28a45972fccdaf0fba75dacc59725521035e177d09dd92174f9f52740bccb025\", \"price_changes\":[{\"asset_id\":\"61819828071723399190623735325323968706432622380635304641786792960078828866875\", \"price\":\"0.86\", \"size\":\"4570\", \"side\":\"BUY\", \"hash\":\"376dd553d2011a250e2a46996f502c50f080cce1\", \"best_bid\":\"0.86\", \"best_ask\":\"0.87\"}, {\"asset_id\":\"114356653315647913247200886351065428002113119844334520181865067698979836634569\", \"price\":\"0.14\", \"size\":\"4570\", \"side\":\"SELL\", \"hash\":\"144ec2bdb77e4791511074827cf17f5f4a9b8c7b\", \"best_bid\":\"0.13\", \"best_ask\":\"0.14\"}], \"timestamp\":\"1789987928728\", \"event_type\":\"price_change\"}","raw_base64":null}
{"received_ms":1789987928751,"monotonic_ns":1019369581602000,"raw":"{\"market\":\"0x28a45972fccdaf0fba75dacc59725521035e177d09dd92174f9f52740bccb025\", \"price_changes\":[{\"asset_id\":\"61819828071723399190623735325323968706432622380635304641786792960078828866875\", \"price\":\"0.76\", \"size\":\"434.91\", \"side\":\"BUY\", \"hash\":\"1afb77a6389153cbbf77148d680d74070e8eda10\", \"best_bid\":\"0.86\", \"best_ask\":\"0.87\"}, {\"asset_id\":\"114356653315647913247200886351065428002113119844334520181865067698979836634569\", \"price\":\"0.24\", \"size\":\"434.91\", \"side\":\"SELL\", \"hash\":\"6f7b1f3e70686f29e2bb6c8a4e458931905bf306\", \"best_bid\":\"0.13\", \"best_ask\":\"0.14\"}], \"timestamp\":\"1789987928729\", \"event_type\":\"price_change\"}","raw_base64":null}
{"received_ms":1789987928754,"monotonic_ns":1019369584703300,"raw":"{\"market\":\"0x28a45972fccdaf0fba75dacc59725521035e177d09dd92174f9f52740bccb025\", \"price_changes\":[{\"asset_id\":\"61819828071723399190623735325323968706432622380635304641786792960078828866875\", \"price\":\"0.86\", \"size\":\"3570\", \"side\":\"BUY\", \"hash\":\"cac3704eb761446b0a84255f904cd3a9573c1f9c\", \"best_bid\":\"0.86\", \"best_ask\":\"0.87\"}, {\"asset_id\":\"114356653315647913247200886351065428002113119844334520181865067698979836634569\", \"price\":\"0.14\", \"size\":\"3570\", \"side\":\"SELL\", \"hash\":\"9e3251b7a7f97f2318f99e07f8d08b704c374945\", \"best_bid\":\"0.13\", \"best_ask\":\"0.14\"}], \"timestamp\":\"1789987928733\", \"event_type\":\"price_change\"}","raw_base64":null}
{"received_ms":1789987928755,"monotonic_ns":1019369586073500,"raw":"{\"market\":\"0x28a45972fccdaf0fba75dacc59725521035e177d09dd92174f9f52740bccb025\", \"price_changes\":[{\"asset_id\":\"114356653315647913247200886351065428002113119844334520181865067698979836634569\", \"price\":\"0.07\", \"size\":\"6521.71\", \"side\":\"BUY\", \"hash\":\"5095c3031a36cd1a0680db69c81a40f46852a54b\", \"best_bid\":\"0.13\", \"best_ask\":\"0.14\"}, {\"asset_id\":\"61819828071723399190623735325323968706432622380635304641786792960078828866875\", \"price\":\"0.93\", \"size\":\"6521.71\", \"side\":\"SELL\", \"hash\":\"3c4c9b51c87d1c2db0f8880d0db4932b02700442\", \"best_bid\":\"0.86\", \"best_ask\":\"0.87\"}], \"timestamp\":\"1789987928734\", \"event_type\":\"price_change\"}","raw_base64":null}
{"received_ms":1789987928756,"monotonic_ns":1019369586620900,"raw":"{\"market\":\"0x28a45972fccdaf0fba75dacc59725521035e177d09dd92174f9f52740bccb025\", \"price_changes\":[{\"asset_id\":\"114356653315647913247200886351065428002113119844334520181865067698979836634569\", \"price\":\"0.06\", \"size\":\"6172.67\", \"side\":\"BUY\", \"hash\":\"9806d82561fed27d946d7e722c30080285b08bd4\", \"best_bid\":\"0.13\", \"best_ask\":\"0.14\"}, {\"asset_id\":\"61819828071723399190623735325323968706432622380635304641786792960078828866875\", \"price\":\"0.94\", \"size\":\"6172.67\", \"side\":\"SELL\", \"hash\":\"2ce6c202ce36b83543e95cb130523fe1724ace83\", \"best_bid\":\"0.86\", \"best_ask\":\"0.87\"}], \"timestamp\":\"1789987928735\", \"event_type\":\"price_change\"}","raw_base64":null}
{"received_ms":1789987928766,"monotonic_ns":1019369596483100,"raw":"{\"market\":\"0x28a45972fccdaf0fba75dacc59725521035e177d09dd92174f9f52740bccb025\", \"price_changes\":[{\"asset_id\":\"61819828071723399190623735325323968706432622380635304641786792960078828866875\", \"price\":\"0.73\", \"size\":\"504\", \"side\":\"BUY\", \"hash\":\"a0738090823d6a211659be7e7a0f5424c46fb6b0\", \"best_bid\":\"0.86\", \"best_ask\":\"0.87\"}, {\"asset_id\":\"114356653315647913247200886351065428002113119844334520181865067698979836634569\", \"price\":\"0.27\", \"size\":\"504\", \"side\":\"SELL\", \"hash\":\"c88178a45b64597e9492739f21bc3a6fda537f3e\", \"best_bid\":\"0.13\", \"best_ask\":\"0.14\"}], \"timestamp\":\"1789987928744\", \"event_type\":\"price_change\"}","raw_base64":null}
{"received_ms":1789987928767,"monotonic_ns":1019369597669500,"raw":"{\"market\":\"0x28a45972fccdaf0fba75dacc59725521035e177d09dd92174f9f52740bccb025\", \"price_changes\":[{\"asset_id\":\"114356653315647913247200886351065428002113119844334520181865067698979836634569\", \"price\":\"0.01\", \"size\":\"1689.43\", \"side\":\"BUY\", \"hash\":\"8f7a3eee40bb84bb360056842951751ec745d9db\", \"best_bid\":\"0.13\", \"best_ask\":\"0.14\"}, {\"asset_id\":\"61819828071723399190623735325323968706432622380635304641786792960078828866875\", \"price\":\"0.99\", \"size\":\"1689.43\", \"side\":\"SELL\", \"hash\":\"b8b5581738717917a9a2fa3782498e237a29c0f4\", \"best_bid\":\"0.86\", \"best_ask\":\"0.87\"}], \"timestamp\":\"1789987928745\", \"event_type\":\"price_change\"}","raw_base64":null}
{"received_ms":1789987928773,"monotonic_ns":1019369603278200,"raw":"{\"market\":\"0x28a45972fccdaf0fba75dacc59725521035e177d09dd92174f9f52740bccb025\", \"price_changes\":[{\"asset_id\":\"61819828071723399190623735325323968706432622380635304641786792960078828866875\", \"price\":\"0.73\", \"size\":\"404\", \"side\":\"BUY\", \"hash\":\"ceb41bae40d3cd2bab5fb2576ae938f59507b73f\", \"best_bid\":\"0.86\", \"best_ask\":\"0.87\"}, {\"asset_id\":\"114356653315647913247200886351065428002113119844334520181865067698979836634569\", \"price\":\"0.27\", \"size\":\"404\", \"side\":\"SELL\", \"hash\":\"256b718a9931d1debc8264663d6d4883a9c63bf2\", \"best_bid\":\"0.13\", \"best_ask\":\"0.14\"}], \"timestamp\":\"1789987928752\", \"event_type\":\"price_change\"}","raw_base64":null}
{"received_ms":1789987928781,"monotonic_ns":1019369611534900,"raw":"{\"market\":\"0x28a45972fccdaf0fba75dacc59725521035e177d09dd92174f9f52740bccb025\", \"price_changes\":[{\"asset_id\":\"61819828071723399190623735325323968706432622380635304641786792960078828866875\", \"price\":\"0.86\", \"size\":\"3605.17\", \"side\":\"BUY\", \"hash\":\"1524fed760766f81368a829e70ed27c594b1e300\", \"best_bid\":\"0.86\", \"best_ask\":\"0.87\"}, {\"asset_id\":\"114356653315647913247200886351065428002113119844334520181865067698979836634569\", \"price\":\"0.14\", \"size\":\"3605.17\", \"side\":\"SELL\", \"hash\":\"b04e8a843f81bd6374148304db7a08c8c6640699\", \"best_bid\":\"0.13\", \"best_ask\":\"0.14\"}], \"timestamp\":\"1789987928760\", \"event_type\":\"price_change\"}","raw_base64":null}
{"received_ms":1789987928786,"monotonic_ns":1019369616539700,"raw":"{\"market\":\"0x28a45972fccdaf0fba75dacc59725521035e177d09dd92174f9f52740bccb025\", \"price_changes\":[{\"asset_id\":\"61819828071723399190623735325323968706432622380635304641786792960078828866875\", \"price\":\"0.86\", \"size\":\"4485.17\", \"side\":\"BUY\", \"hash\":\"f2d5b47b1124d2e673b75718ce8461ee06d73936\", \"best_bid\":\"0.86\", \"best_ask\":\"0.87\"}, {\"asset_id\":\"114356653315647913247200886351065428002113119844334520181865067698979836634569\", \"price\":\"0.14\", \"size\":\"4485.17\", \"side\":\"SELL\", \"hash\":\"47875f7afc2e67e48b54ba475fb6df5c2cf4602c\", \"best_bid\":\"0.13\", \"best_ask\":\"0.14\"}], \"timestamp\":\"1789987928766\", \"event_type\":\"price_change\"}","raw_base64":null}
{"received_ms":1789987928801,"monotonic_ns":1019369631679200,"raw":"{\"market\":\"0x28a45972fccdaf0fba75dacc59725521035e177d09dd92174f9f52740bccb025\", \"price_changes\":[{\"asset_id\":\"61819828071723399190623735325323968706432622380635304641786792960078828866875\", \"price\":\"0.85\", \"size\":\"2941.35\", \"side\":\"BUY\", \"hash\":\"87175ffa12021584aa731ef04f88f70e0556ebd5\", \"best_bid\":\"0.86\", \"best_ask\":\"0.87\"}, {\"asset_id\":\"114356653315647913247200886351065428002113119844334520181865067698979836634569\", \"price\":\"0.15\", \"size\":\"2941.35\", \"side\":\"SELL\", \"hash\":\"f6ab7435d9d17b8c6936366eb833a83860eda111\", \"best_bid\":\"0.13\", \"best_ask\":\"0.14\"}], \"timestamp\":\"1789987928780\", \"event_type\":\"price_change\"}","raw_base64":null}
{"received_ms":1789987928804,"monotonic_ns":1019369635019300,"raw":"{\"market\":\"0x28a45972fccdaf0fba75dacc59725521035e177d09dd92174f9f52740bccb025\", \"price_changes\":[{\"asset_id\":\"61819828071723399190623735325323968706432622380635304641786792960078828866875\", \"price\":\"0.77\", \"size\":\"587.49\", \"side\":\"BUY\", \"hash\":\"4810ee24ff8a4a9133ee1fb9137c78c6cd9eef0f\", \"best_bid\":\"0.86\", \"best_ask\":\"0.87\"}, {\"asset_id\":\"114356653315647913247200886351065428002113119844334520181865067698979836634569\", \"price\":\"0.23\", \"size\":\"587.49\", \"side\":\"SELL\", \"hash\":\"81fc69293526298dd60a0d99c4315688e0965f7f\", \"best_bid\":\"0.13\", \"best_ask\":\"0.14\"}], \"timestamp\":\"1789987928783\", \"event_type\":\"price_change\"}","raw_base64":null}
{"received_ms":1789987928804,"monotonic_ns":1019369635110000,"raw":"{\"market\":\"0x28a45972fccdaf0fba75dacc59725521035e177d09dd92174f9f52740bccb025\", \"price_changes\":[{\"asset_id\":\"61819828071723399190623735325323968706432622380635304641786792960078828866875\", \"price\":\"0.85\", \"size\":\"2852.35\", \"side\":\"BUY\", \"hash\":\"a538fc0d187fe847585b7a72b450ab8acd700e7f\", \"best_bid\":\"0.86\", \"best_ask\":\"0.87\"}, {\"asset_id\":\"114356653315647913247200886351065428002113119844334520181865067698979836634569\", \"price\":\"0.15\", \"size\":\"2852.35\", \"side\":\"SELL\", \"hash\":\"b04e23da65de5d82b486aa31fa26797faee9c741\", \"best_bid\":\"0.13\", \"best_ask\":\"0.14\"}], \"timestamp\":\"1789987928784\", \"event_type\":\"price_change\"}","raw_base64":null}
{"received_ms":1789987928805,"monotonic_ns":1019369635334200,"raw":"{\"market\":\"0x28a45972fccdaf0fba75dacc59725521035e177d09dd92174f9f52740bccb025\", \"price_changes\":[{\"asset_id\":\"61819828071723399190623735325323968706432622380635304641786792960078828866875\", \"price\":\"0.77\", \"size\":\"547.49\", \"side\":\"BUY\", \"hash\":\"86be7a2fe62aef786614c995eec440f14e4ad663\", \"best_bid\":\"0.86\", \"best_ask\":\"0.87\"}, {\"asset_id\":\"114356653315647913247200886351065428002113119844334520181865067698979836634569\", \"price\":\"0.23\", \"size\":\"547.49\", \"side\":\"SELL\", \"hash\":\"771a9a1533c7f62be8b2141250741fedb36b5952\", \"best_bid\":\"0.13\", \"best_ask\":\"0.14\"}], \"timestamp\":\"1789987928784\", \"event_type\":\"price_change\"}","raw_base64":null}
{"received_ms":1789987928832,"monotonic_ns":1019369662829800,"raw":"{\"market\":\"0x28a45972fccdaf0fba75dacc59725521035e177d09dd92174f9f52740bccb025\", \"price_changes\":[{\"asset_id\":\"114356653315647913247200886351065428002113119844334520181865067698979836634569\", \"price\":\"0.07\", \"size\":\"6196.71\", \"side\":\"BUY\", \"hash\":\"3ff68db48f9d7e868f4812e8bdc152b6a5557a69\", \"best_bid\":\"0.13\", \"best_ask\":\"0.14\"}, {\"asset_id\":\"61819828071723399190623735325323968706432622380635304641786792960078828866875\", \"price\":\"0.93\", \"size\":\"6196.71\", \"side\":\"SELL\", \"hash\":\"6f64063509c6f7a9c589743663cef9102b5f236d\", \"best_bid\":\"0.86\", \"best_ask\":\"0.87\"}], \"timestamp\":\"1789987928811\", \"event_type\":\"price_change\"}","raw_base64":null}
{"received_ms":1789987928838,"monotonic_ns":1019369668898600,"raw":"{\"market\":\"0x28a45972fccdaf0fba75dacc59725521035e177d09dd92174f9f52740bccb025\", \"price_changes\":[{\"asset_id\":\"114356653315647913247200886351065428002113119844334520181865067698979836634569\", \"price\":\"0.01\", \"size\":\"1669.43\", \"side\":\"BUY\", \"hash\":\"98c4f3fbe8cbd5cc3bec572917a1b7d4c8e483eb\", \"best_bid\":\"0.13\", \"best_ask\":\"0.14\"}, {\"asset_id\":\"61819828071723399190623735325323968706432622380635304641786792960078828866875\", \"price\":\"0.99\", \"size\":\"1669.43\", \"side\":\"SELL\", \"hash\":\"ab29095b332e153865aba97ace3ebea04cfd6281\", \"best_bid\":\"0.86\", \"best_ask\":\"0.87\"}], \"timestamp\":\"1789987928818\", \"event_type\":\"price_change\"}","raw_base64":null}
{"received_ms":1789987928839,"monotonic_ns":1019369669976400,"raw":"{\"market\":\"0x28a45972fccdaf0fba75dacc59725521035e177d09dd92174f9f52740bccb025\", \"price_changes\":[{\"asset_id\":\"61819828071723399190623735325323968706432622380635304641786792960078828866875\", \"price\":\"0.73\", \"size\":\"504\", \"side\":\"BUY\", \"hash\":\"a3991d813cdbd0e8e543445d737327a58e1cebad\", \"best_bid\":\"0.86\", \"best_ask\":\"0.87\"}, {\"asset_id\":\"114356653315647913247200886351065428002113119844334520181865067698979836634569\", \"price\":\"0.27\", \"size\":\"504\", \"side\":\"SELL\", \"hash\":\"ffdd37bb67d7f9123a753edba25e57fc6df5150e\", \"best_bid\":\"0.13\", \"best_ask\":\"0.14\"}], \"timestamp\":\"1789987928819\", \"event_type\":\"price_change\"}","raw_base64":null}
{"received_ms":1789987928841,"monotonic_ns":1019369672187600,"raw":"{\"market\":\"0x28a45972fccdaf0fba75dacc59725521035e177d09dd92174f9f52740bccb025\", \"price_changes\":[{\"asset_id\":\"61819828071723399190623735325323968706432622380635304641786792960078828866875\", \"price\":\"0.73\", \"size\":\"404\", \"side\":\"BUY\", \"hash\":\"f595310d48e2660760adcf136cac2c8011bd1ecb\", \"best_bid\":\"0.86\", \"best_ask\":\"0.87\"}, {\"asset_id\":\"114356653315647913247200886351065428002113119844334520181865067698979836634569\", \"price\":\"0.27\", \"size\":\"404\", \"side\":\"SELL\", \"hash\":\"2f4e3f1c4d00bf8d2a154a08432703c10e8462dd\", \"best_bid\":\"0.13\", \"best_ask\":\"0.14\"}], \"timestamp\":\"1789987928822\", \"event_type\":\"price_change\"}","raw_base64":null}
{"received_ms":1789987928842,"monotonic_ns":1019369672478700,"raw":"{\"market\":\"0x28a45972fccdaf0fba75dacc59725521035e177d09dd92174f9f52740bccb025\", \"price_changes\":[{\"asset_id\":\"61819828071723399190623735325323968706432622380635304641786792960078828866875\", \"price\":\"0.86\", \"size\":\"4588.17\", \"side\":\"BUY\", \"hash\":\"718275f118a767e5e032ef2c6f2bf2bee5f0332a\", \"best_bid\":\"0.86\", \"best_ask\":\"0.87\"}, {\"asset_id\":\"114356653315647913247200886351065428002113119844334520181865067698979836634569\", \"price\":\"0.14\", \"size\":\"4588.17\", \"side\":\"SELL\", \"hash\":\"e4441f103da3c7850e8718fffe841bff7cae9598\", \"best_bid\":\"0.13\", \"best_ask\":\"0.14\"}], \"timestamp\":\"1789987928822\", \"event_type\":\"price_change\"}","raw_base64":null}
{"received_ms":1789987928842,"monotonic_ns":1019369673150300,"raw":"{\"market\":\"0x28a45972fccdaf0fba75dacc59725521035e177d09dd92174f9f52740bccb025\", \"price_changes\":[{\"asset_id\":\"61819828071723399190623735325323968706432622380635304641786792960078828866875\", \"price\":\"0.84\", \"size\":\"3020\", \"side\":\"BUY\", \"hash\":\"f9b08a1a2342d978dfae9607aef731f19f1c2338\", \"best_bid\":\"0.86\", \"best_ask\":\"0.87\"}, {\"asset_id\":\"114356653315647913247200886351065428002113119844334520181865067698979836634569\", \"price\":\"0.16\", \"size\":\"3020\", \"side\":\"SELL\", \"hash\":\"ccffa07e77464319fcedfaded042a0ba57615163\", \"best_bid\":\"0.13\", \"best_ask\":\"0.14\"}], \"timestamp\":\"1789987928823\", \"event_type\":\"price_change\"}","raw_base64":null}
{"received_ms":1789987928844,"monotonic_ns":1019369674375900,"raw":"{\"market\":\"0x28a45972fccdaf0fba75dacc59725521035e177d09dd92174f9f52740bccb025\", \"price_changes\":[{\"asset_id\":\"61819828071723399190623735325323968706432622380635304641786792960078828866875\", \"price\":\"0.85\", \"size\":\"2861.35\", \"side\":\"BUY\", \"hash\":\"50c9cc07b717b3719b6dda5a5939cae1178b65a3\", \"best_bid\":\"0.86\", \"best_ask\":\"0.87\"}, {\"asset_id\":\"114356653315647913247200886351065428002113119844334520181865067698979836634569\", \"price\":\"0.15\", \"size\":\"2861.35\", \"side\":\"SELL\", \"hash\":\"5f2d2188168a0f39367893c7df419abe566532ca\", \"best_bid\":\"0.13\", \"best_ask\":\"0.14\"}], \"timestamp\":\"1789987928823\", \"event_type\":\"price_change\"}","raw_base64":null}
{"received_ms":1789987928847,"monotonic_ns":1019369677914100,"raw":"{\"market\":\"0x28a45972fccdaf0fba75dacc59725521035e177d09dd92174f9f52740bccb025\", \"price_changes\":[{\"asset_id\":\"114356653315647913247200886351065428002113119844334520181865067698979836634569\", \"price\":\"0.03\", \"size\":\"3992.57\", \"side\":\"BUY\", \"hash\":\"860e246895885d0577dd81117fd381aa08de1092\", \"best_bid\":\"0.13\", \"best_ask\":\"0.14\"}, {\"asset_id\":\"61819828071723399190623735325323968706432622380635304641786792960078828866875\", \"price\":\"0.97\", \"size\":\"3992.57\", \"side\":\"SELL\", \"hash\":\"d8ad8b5e7da90cf44d518990bcf2187ae3d17b8b\", \"best_bid\":\"0.86\", \"best_ask\":\"0.87\"}], \"timestamp\":\"1789987928827\", \"event_type\":\"price_change\"}","raw_base64":null}
{"received_ms":1789987928870,"monotonic_ns":1019369700455400,"raw":"{\"market\":\"0x28a45972fccdaf0fba75dacc59725521035e177d09dd92174f9f52740bccb025\", \"price_changes\":[{\"asset_id\":\"61819828071723399190623735325323968706432622380635304641786792960078828866875\", \"price\":\"0.01\", \"size\":\"1496.91\", \"side\":\"BUY\", \"hash\":\"6b149a5bdd25a427e31395ec5bce2b1832b3d16b\", \"best_bid\":\"0.86\", \"best_ask\":\"0.87\"}, {\"asset_id\":\"114356653315647913247200886351065428002113119844334520181865067698979836634569\", \"price\":\"0.99\", \"size\":\"1496.91\", \"side\":\"SELL\", \"hash\":\"687ba71a35b842e48215e6f9d1db5c9bc17f7716\", \"best_bid\":\"0.13\", \"best_ask\":\"0.14\"}], \"timestamp\":\"1789987928849\", \"event_type\":\"price_change\"}","raw_base64":null}
{"received_ms":1789987928876,"monotonic_ns":1019369706669400,"raw":"{\"market\":\"0x28a45972fccdaf0fba75dacc59725521035e177d09dd92174f9f52740bccb025\", \"price_changes\":[{\"asset_id\":\"61819828071723399190623735325323968706432622380635304641786792960078828866875\", \"price\":\"0.86\", \"size\":\"4675.17\", \"side\":\"BUY\", \"hash\":\"442e16da7dd66045e46e72a7295bdd01e5e36410\", \"best_bid\":\"0.86\", \"best_ask\":\"0.87\"}, {\"asset_id\":\"114356653315647913247200886351065428002113119844334520181865067698979836634569\", \"price\":\"0.14\", \"size\":\"4675.17\", \"side\":\"SELL\", \"hash\":\"44eca45afe4847692dafeb98ef3cb3a62e8f15ad\", \"best_bid\":\"0.13\", \"best_ask\":\"0.14\"}], \"timestamp\":\"1789987928856\", \"event_type\":\"price_change\"}","raw_base64":null}
{"received_ms":1789987928876,"monotonic_ns":1019369707079100,"raw":"{\"market\":\"0x28a45972fccdaf0fba75dacc59725521035e177d09dd92174f9f52740bccb025\", \"price_changes\":[{\"asset_id\":\"114356653315647913247200886351065428002113119844334520181865067698979836634569\", \"price\":\"0.06\", \"size\":\"6182.67\", \"side\":\"BUY\", \"hash\":\"100b58d09d964f8b47ecc650d5f765357660163a\", \"best_bid\":\"0.13\", \"best_ask\":\"0.14\"}, {\"asset_id\":\"61819828071723399190623735325323968706432622380635304641786792960078828866875\", \"price\":\"0.94\", \"size\":\"6182.67\", \"side\":\"SELL\", \"hash\":\"35c6fe1722d6ae16cc931dc9dcef9ab7adf7faaf\", \"best_bid\":\"0.86\", \"best_ask\":\"0.87\"}], \"timestamp\":\"1789987928856\", \"event_type\":\"price_change\"}","raw_base64":null}
{"received_ms":1789987928877,"monotonic_ns":1019369707818000,"raw":"{\"market\":\"0x28a45972fccdaf0fba75dacc59725521035e177d09dd92174f9f52740bccb025\", \"price_changes\":[{\"asset_id\":\"114356653315647913247200886351065428002113119844334520181865067698979836634569\", \"price\":\"0.01\", \"size\":\"1689.43\", \"side\":\"BUY\", \"hash\":\"b1234f1374c82938c8c0d318796f12e9ebb37c36\", \"best_bid\":\"0.13\", \"best_ask\":\"0.14\"}, {\"asset_id\":\"61819828071723399190623735325323968706432622380635304641786792960078828866875\", \"price\":\"0.99\", \"size\":\"1689.43\", \"side\":\"SELL\", \"hash\":\"70f8a9d2e2377699270b3cf30c6253703a39d4cf\", \"best_bid\":\"0.86\", \"best_ask\":\"0.87\"}], \"timestamp\":\"1789987928857\", \"event_type\":\"price_change\"}","raw_base64":null}
{"received_ms":1789987928878,"monotonic_ns":1019369708948600,"raw":"{\"market\":\"0x28a45972fccdaf0fba75dacc59725521035e177d09dd92174f9f52740bccb025\", \"price_changes\":[{\"asset_id\":\"114356653315647913247200886351065428002113119844334520181865067698979836634569\", \"price\":\"0.07\", \"size\":\"6511.71\", \"side\":\"BUY\", \"hash\":\"df8e0a20aaee6e00b4aeffa961d353bed1588310\", \"best_bid\":\"0.13\", \"best_ask\":\"0.14\"}, {\"asset_id\":\"61819828071723399190623735325323968706432622380635304641786792960078828866875\", \"price\":\"0.93\", \"size\":\"6511.71\", \"side\":\"SELL\", \"hash\":\"e0b8bcfdb668fb8f3e6d3e1e2a1cebf03d119b31\", \"best_bid\":\"0.86\", \"best_ask\":\"0.87\"}], \"timestamp\":\"1789987928858\", \"event_type\":\"price_change\"}","raw_base64":null}
{"received_ms":1789987928890,"monotonic_ns":1019369720665200,"raw":"{\"market\":\"0x28a45972fccdaf0fba75dacc59725521035e177d09dd92174f9f52740bccb025\", \"price_changes\":[{\"asset_id\":\"61819828071723399190623735325323968706432622380635304641786792960078828866875\", \"price\":\"0.75\", \"size\":\"420\", \"side\":\"BUY\", \"hash\":\"217f3cd3885805bc9056956b3837627c9e981761\", \"best_bid\":\"0.86\", \"best_ask\":\"0.87\"}, {\"asset_id\":\"114356653315647913247200886351065428002113119844334520181865067698979836634569\", \"price\":\"0.25\", \"size\":\"420\", \"side\":\"SELL\", \"hash\":\"71543bab4eaff22d2e3973a25070b1689033b265\", \"best_bid\":\"0.13\", \"best_ask\":\"0.14\"}], \"timestamp\":\"1789987928869\", \"event_type\":\"price_change\"}","raw_base64":null}
{"received_ms":1789987928890,"monotonic_ns":1019369720751600,"raw":"{\"market\":\"0x28a45972fccdaf0fba75dacc59725521035e177d09dd92174f9f52740bccb025\", \"price_changes\":[{\"asset_id\":\"61819828071723399190623735325323968706432622380635304641786792960078828866875\", \"price\":\"0.83\", \"size\":\"434\", \"side\":\"BUY\", \"hash\":\"217f3cd3885805bc9056956b3837627c9e981761\", \"best_bid\":\"0.86\", \"best_ask\":\"0.87\"}, {\"asset_id\":\"114356653315647913247200886351065428002113119844334520181865067698979836634569\", \"price\":\"0.17\", \"size\":\"434\", \"side\":\"SELL\", \"hash\":\"71543bab4eaff22d2e3973a25070b1689033b265\", \"best_bid\":\"0.13\", \"best_ask\":\"0.14\"}], \"timestamp\":\"1789987928869\", \"event_type\":\"price_change\"}","raw_base64":null}
{"received_ms":1789987928902,"monotonic_ns":1019369733186700,"raw":"{\"market\":\"0x28a45972fccdaf0fba75dacc59725521035e177d09dd92174f9f52740bccb025\", \"price_changes\":[{\"asset_id\":\"61819828071723399190623735325323968706432622380635304641786792960078828866875\", \"price\":\"0.01\", \"size\":\"1491.91\", \"side\":\"BUY\", \"hash\":\"d10d1ac5c0e1e6149b96db45f98ee72ae428602d\", \"best_bid\":\"0.86\", \"best_ask\":\"0.87\"}, {\"asset_id\":\"114356653315647913247200886351065428002113119844334520181865067698979836634569\", \"price\":\"0.99\", \"size\":\"1491.91\", \"side\":\"SELL\", \"hash\":\"7836b8c48969bad545813f1c1c894ad2087bd3af\", \"best_bid\":\"0.13\", \"best_ask\":\"0.14\"}], \"timestamp\":\"1789987928882\", \"event_type\":\"price_change\"}","raw_base64":null}
{"received_ms":1789987928905,"monotonic_ns":1019369735599500,"raw":"{\"market\":\"0x28a45972fccdaf0fba75dacc59725521035e177d09dd92174f9f52740bccb025\", \"price_changes\":[{\"asset_id\":\"114356653315647913247200886351065428002113119844334520181865067698979836634569\", \"price\":\"0.05\", \"size\":\"5615\", \"side\":\"BUY\", \"hash\":\"fe2721310c188d1d4bf2ed7d3c32877053b62424\", \"best_bid\":\"0.13\", \"best_ask\":\"0.14\"}, {\"asset_id\":\"61819828071723399190623735325323968706432622380635304641786792960078828866875\", \"price\":\"0.95\", \"size\":\"5615\", \"side\":\"SELL\", \"hash\":\"943147b31276fb032e7be7e22accce2e7b1ebd76\", \"best_bid\":\"0.86\", \"best_ask\":\"0.87\"}], \"timestamp\":\"1789987928883\", \"event_type\":\"price_change\"}","raw_base64":null}
{"received_ms":1789987928909,"monotonic_ns":1019369739587800,"raw":"{\"market\":\"0x28a45972fccdaf0fba75dacc59725521035e177d09dd92174f9f52740bccb025\", \"price_changes\":[{\"asset_id\":\"61819828071723399190623735325323968706432622380635304641786792960078828866875\", \"price\":\"0.84\", \"size\":\"3080\", \"side\":\"BUY\", \"hash\":\"632bb077946697f2e85f909042c09cf986c290cc\", \"best_bid\":\"0.86\", \"best_ask\":\"0.87\"}, {\"asset_id\":\"114356653315647913247200886351065428002113119844334520181865067698979836634569\", \"price\":\"0.16\", \"size\":\"3080\", \"side\":\"SELL\", \"hash\":\"0f5dceb232e32faa897693635b2adf1e16ff6978\", \"best_bid\":\"0.13\", \"best_ask\":\"0.14\"}], \"timestamp\":\"1789987928888\", \"event_type\":\"price_change\"}","raw_base64":null}
{"received_ms":1789987928926,"monotonic_ns":1019369756350600,"raw":"{\"market\":\"0x28a45972fccdaf0fba75dacc59725521035e177d09dd92174f9f52740bccb025\", \"price_changes\":[{\"asset_id\":\"61819828071723399190623735325323968706432622380635304641786792960078828866875\", \"price\":\"0.77\", \"size\":\"587.49\", \"side\":\"BUY\", \"hash\":\"30740bf31c2928fddba26fd87d82c412a24dc78f\", \"best_bid\":\"0.86\", \"best_ask\":\"0.87\"}, {\"asset_id\":\"114356653315647913247200886351065428002113119844334520181865067698979836634569\", \"price\":\"0.23\", \"size\":\"587.49\", \"side\":\"SELL\", \"hash\":\"4535100fdf7bbf729337e5cd62a2888378daa38a\", \"best_bid\":\"0.13\", \"best_ask\":\"0.14\"}], \"timestamp\":\"1789987928906\", \"event_type\":\"price_change\"}","raw_base64":null}
{"received_ms":1789987928936,"monotonic_ns":1019369766356500,"raw":"{\"market\":\"0x28a45972fccdaf0fba75dacc59725521035e177d09dd92174f9f52740bccb025\", \"price_changes\":[{\"asset_id\":\"114356653315647913247200886351065428002113119844334520181865067698979836634569\", \"price\":\"0.11\", \"size\":\"136.1\", \"side\":\"BUY\", \"hash\":\"add944e8561ec45679e2404322753d2167388db2\", \"best_bid\":\"0.13\", \"best_ask\":\"0.14\"}, {\"asset_id\":\"61819828071723399190623735325323968706432622380635304641786792960078828866875\", \"price\":\"0.89\", \"size\":\"136.1\", \"side\":\"SELL\", \"hash\":\"6f432f011ed75a1d4c602c81894d26e64448656e\", \"best_bid\":\"0.86\", \"best_ask\":\"0.87\"}], \"timestamp\":\"1789987928915\", \"event_type\":\"price_change\"}","raw_base64":null}
{"received_ms":1789987928949,"monotonic_ns":1019369779384800,"raw":"{\"market\":\"0x28a45972fccdaf0fba75dacc59725521035e177d09dd92174f9f52740bccb025\", \"price_changes\":[{\"asset_id\":\"114356653315647913247200886351065428002113119844334520181865067698979836634569\", \"price\":\"0.07\", \"size\":\"6491.71\", \"side\":\"BUY\", \"hash\":\"e720b09add01361691aeb17a4d4ad79f5751e368\", \"best_bid\":\"0.13\", \"best_ask\":\"0.14\"}, {\"asset_id\":\"61819828071723399190623735325323968706432622380635304641786792960078828866875\", \"price\":\"0.93\", \"size\":\"6491.71\", \"side\":\"SELL\", \"hash\":\"f847fbf95524fda49d8bef7cd1cfafd2f7bc95d2\", \"best_bid\":\"0.86\", \"best_ask\":\"0.87\"}], \"timestamp\":\"1789987928923\", \"event_type\":\"price_change\"}","raw_base64":null}
{"received_ms":1789987928949,"monotonic_ns":1019369779450000,"raw":"{\"market\":\"0x28a45972fccdaf0fba75dacc59725521035e177d09dd92174f9f52740bccb025\", \"price_changes\":[{\"asset_id\":\"114356653315647913247200886351065428002113119844334520181865067698979836634569\", \"price\":\"0.03\", \"size\":\"4012.57\", \"side\":\"BUY\", \"hash\":\"fd782457efef3e135fab736526768a98415e1edb\", \"best_bid\":\"0.13\", \"best_ask\":\"0.14\"}, {\"asset_id\":\"61819828071723399190623735325323968706432622380635304641786792960078828866875\", \"price\":\"0.97\", \"size\":\"4012.57\", \"side\":\"SELL\", \"hash\":\"18d38338df8362914a9b2578552d10c967149380\", \"best_bid\":\"0.86\", \"best_ask\":\"0.87\"}], \"timestamp\":\"1789987928925\", \"event_type\":\"price_change\"}","raw_base64":null}
{"received_ms":1789987928957,"monotonic_ns":1019369787933500,"raw":"{\"market\":\"0x28a45972fccdaf0fba75dacc59725521035e177d09dd92174f9f52740bccb025\", \"price_changes\":[{\"asset_id\":\"61819828071723399190623735325323968706432622380635304641786792960078828866875\", \"price\":\"0.79\", \"size\":\"447\", \"side\":\"BUY\", \"hash\":\"09e3a9b90fc8f8438e990b0fe074f0e337cb50fa\", \"best_bid\":\"0.86\", \"best_ask\":\"0.87\"}, {\"asset_id\":\"114356653315647913247200886351065428002113119844334520181865067698979836634569\", \"price\":\"0.21\", \"size\":\"447\", \"side\":\"SELL\", \"hash\":\"db3321214a7040664dfec492dc315bd7a9ca1a18\", \"best_bid\":\"0.13\", \"best_ask\":\"0.14\"}], \"timestamp\":\"1789987928937\", \"event_type\":\"price_change\"}","raw_base64":null}
{"received_ms":1789987928962,"monotonic_ns":1019369792544800,"raw":"{\"market\":\"0x28a45972fccdaf0fba75dacc59725521035e177d09dd92174f9f52740bccb025\", \"price_changes\":[{\"asset_id\":\"61819828071723399190623735325323968706432622380635304641786792960078828866875\", \"price\":\"0.75\", \"size\":\"520\", \"side\":\"BUY\", \"hash\":\"1b602e3b82e99e336bf10d4cc32c4be1251647a0\", \"best_bid\":\"0.86\", \"best_ask\":\"0.87\"}, {\"asset_id\":\"114356653315647913247200886351065428002113119844334520181865067698979836634569\", \"price\":\"0.25\", \"size\":\"520\", \"side\":\"SELL\", \"hash\":\"4933d29db9ae472f715f5628445b8bccfe4d6f89\", \"best_bid\":\"0.13\", \"best_ask\":\"0.14\"}], \"timestamp\":\"1789987928941\", \"event_type\":\"price_change\"}","raw_base64":null}
{"received_ms":1789987928962,"monotonic_ns":1019369792849800,"raw":"{\"market\":\"0x28a45972fccdaf0fba75dacc59725521035e177d09dd92174f9f52740bccb025\", \"price_changes\":[{\"asset_id\":\"61819828071723399190623735325323968706432622380635304641786792960078828866875\", \"price\":\"0.76\", \"size\":\"424.91\", \"side\":\"BUY\", \"hash\":\"2c71e16dc14c7c892c0f167c6d428abd777d21c5\", \"best_bid\":\"0.86\", \"best_ask\":\"0.87\"}, {\"asset_id\":\"114356653315647913247200886351065428002113119844334520181865067698979836634569\", \"price\":\"0.24\", \"size\":\"424.91\", \"side\":\"SELL\", \"hash\":\"fb817722713c6c1939437b651fee3758eb4a4900\", \"best_bid\":\"0.13\", \"best_ask\":\"0.14\"}], \"timestamp\":\"1789987928942\", \"event_type\":\"price_change\"}","raw_base64":null}
{"received_ms":1789987928964,"monotonic_ns":1019369794623200,"raw":"{\"market\":\"0x28a45972fccdaf0fba75dacc59725521035e177d09dd92174f9f52740bccb025\", \"price_changes\":[{\"asset_id\":\"61819828071723399190623735325323968706432622380635304641786792960078828866875\", \"price\":\"0.75\", \"size\":\"420\", \"side\":\"BUY\", \"hash\":\"5533bb879f6bf75862f11f8ff1700699a767b871\", \"best_bid\":\"0.86\", \"best_ask\":\"0.87\"}, {\"asset_id\":\"114356653315647913247200886351065428002113119844334520181865067698979836634569\", \"price\":\"0.25\", \"size\":\"420\", \"side\":\"SELL\", \"hash\":\"abe2afb2610c46f6e2dd912d067a24c7263cd034\", \"best_bid\":\"0.13\", \"best_ask\":\"0.14\"}], \"timestamp\":\"1789987928943\", \"event_type\":\"price_change\"}","raw_base64":null}
{"received_ms":1789987928965,"monotonic_ns":1019369796125900,"raw":"{\"market\":\"0x28a45972fccdaf0fba75dacc59725521035e177d09dd92174f9f52740bccb025\", \"price_changes\":[{\"asset_id\":\"61819828071723399190623735325323968706432622380635304641786792960078828866875\", \"price\":\"0.86\", \"size\":\"4680.17\", \"side\":\"BUY\", \"hash\":\"6ed3f5aafe53682caafbe124b831cbd1a44613e8\", \"best_bid\":\"0.86\", \"best_ask\":\"0.87\"}, {\"asset_id\":\"114356653315647913247200886351065428002113119844334520181865067698979836634569\", \"price\":\"0.14\", \"size\":\"4680.17\", \"side\":\"SELL\", \"hash\":\"6468221f4c562afac2eaf8fedeb965feced7515b\", \"best_bid\":\"0.13\", \"best_ask\":\"0.14\"}], \"timestamp\":\"1789987928944\", \"event_type\":\"price_change\"}","raw_base64":null}
{"received_ms":1789987928968,"monotonic_ns":1019369798726100,"raw":"{\"market\":\"0x28a45972fccdaf0fba75dacc59725521035e177d09dd92174f9f52740bccb025\", \"price_changes\":[{\"asset_id\":\"61819828071723399190623735325323968706432622380635304641786792960078828866875\", \"price\":\"0.86\", \"size\":\"4645\", \"side\":\"BUY\", \"hash\":\"29f714e16bb8b5c230e34cb4497b8abc25d6bea4\", \"best_bid\":\"0.86\", \"best_ask\":\"0.87\"}, {\"asset_id\":\"114356653315647913247200886351065428002113119844334520181865067698979836634569\", \"price\":\"0.14\", \"size\":\"4645\", \"side\":\"SELL\", \"hash\":\"0733182dc121ebc5ef52cf5d700358c2f7e0485d\", \"best_bid\":\"0.13\", \"best_ask\":\"0.14\"}], \"timestamp\":\"1789987928948\", \"event_type\":\"price_change\"}","raw_base64":null}
{"received_ms":1789987928976,"monotonic_ns":1019369806417200,"raw":"{\"market\":\"0x28a45972fccdaf0fba75dacc59725521035e177d09dd92174f9f52740bccb025\", \"price_changes\":[{\"asset_id\":\"61819828071723399190623735325323968706432622380635304641786792960078828866875\", \"price\":\"0.86\", \"size\":\"4655\", \"side\":\"BUY\", \"hash\":\"1780f9bbfd1b6de6af8fb5b12d3f3b706e3c4f7f\", \"best_bid\":\"0.86\", \"best_ask\":\"0.87\"}, {\"asset_id\":\"114356653315647913247200886351065428002113119844334520181865067698979836634569\", \"price\":\"0.14\", \"size\":\"4655\", \"side\":\"SELL\", \"hash\":\"8b70145a0988840c3e0d63f59e918cdc2ff313e9\", \"best_bid\":\"0.13\", \"best_ask\":\"0.14\"}], \"timestamp\":\"1789987928955\", \"event_type\":\"price_change\"}","raw_base64":null}
{"received_ms":1789987928979,"monotonic_ns":1019369810063100,"raw":"{\"market\":\"0x28a45972fccdaf0fba75dacc59725521035e177d09dd92174f9f52740bccb025\", \"price_changes\":[{\"asset_id\":\"114356653315647913247200886351065428002113119844334520181865067698979836634569\", \"price\":\"0.05\", \"size\":\"5635\", \"side\":\"BUY\", \"hash\":\"60edf3d392f93bf49a6aa6362a3940d8d9a0ff82\", \"best_bid\":\"0.13\", \"best_ask\":\"0.14\"}, {\"asset_id\":\"61819828071723399190623735325323968706432622380635304641786792960078828866875\", \"price\":\"0.95\", \"size\":\"5635\", \"side\":\"SELL\", \"hash\":\"b3cd9b3c9102dcee28a16255b4877039e432df14\", \"best_bid\":\"0.86\", \"best_ask\":\"0.87\"}], \"timestamp\":\"1789987928959\", \"event_type\":\"price_change\"}","raw_base64":null}
{"received_ms":1789987928992,"monotonic_ns":1019369822605300,"raw":"{\"market\":\"0x28a45972fccdaf0fba75dacc59725521035e177d09dd92174f9f52740bccb025\", \"price_changes\":[{\"asset_id\":\"114356653315647913247200886351065428002113119844334520181865067698979836634569\", \"price\":\"0.07\", \"size\":\"6176.71\", \"side\":\"BUY\", \"hash\":\"3946aac56642b4160436e194b60fdf9226df64b4\", \"best_bid\":\"0.13\", \"best_ask\":\"0.14\"}, {\"asset_id\":\"61819828071723399190623735325323968706432622380635304641786792960078828866875\", \"price\":\"0.93\", \"size\":\"6176.71\", \"side\":\"SELL\", \"hash\":\"d13d5ac1d34ccb79a00209c4f5f6ba97cd84d209\", \"best_bid\":\"0.86\", \"best_ask\":\"0.87\"}], \"timestamp\":\"1789987928972\", \"event_type\":\"price_change\"}","raw_base64":null}
{"received_ms":1789987928997,"monotonic_ns":1019369827457600,"raw":"{\"market\":\"0x28a45972fccdaf0fba75dacc59725521035e177d09dd92174f9f52740bccb025\", \"price_changes\":[{\"asset_id\":\"61819828071723399190623735325323968706432622380635304641786792960078828866875\", \"price\":\"0.79\", \"size\":\"527\", \"side\":\"BUY\", \"hash\":\"4eda027e0eca4ad946cc3d6373b5a415c916d2e3\", \"best_bid\":\"0.86\", \"best_ask\":\"0.87\"}, {\"asset_id\":\"114356653315647913247200886351065428002113119844334520181865067698979836634569\", \"price\":\"0.21\", \"size\":\"527\", \"side\":\"SELL\", \"hash\":\"556e63af503ec69d3a309a3b921a9fe8841ef30a\", \"best_bid\":\"0.13\", \"best_ask\":\"0.14\"}], \"timestamp\":\"1789987928974\", \"event_type\":\"price_change\"}","raw_base64":null}
{"received_ms":1789987928997,"monotonic_ns":1019369827537600,"raw":"{\"market\":\"0x28a45972fccdaf0fba75dacc59725521035e177d09dd92174f9f52740bccb025\", \"price_changes\":[{\"asset_id\":\"61819828071723399190623735325323968706432622380635304641786792960078828866875\", \"price\":\"0.8\", \"size\":\"582\", \"side\":\"BUY\", \"hash\":\"1305bd17016a51cf3f8b309bfdc12223bccfb812\", \"best_bid\":\"0.86\", \"best_ask\":\"0.87\"}, {\"asset_id\":\"114356653315647913247200886351065428002113119844334520181865067698979836634569\", \"price\":\"0.2\", \"size\":\"582\", \"side\":\"SELL\", \"hash\":\"da28e3c644819b829a1fa74ce278b5b7ef456130\", \"best_bid\":\"0.13\", \"best_ask\":\"0.14\"}], \"timestamp\":\"1789987928975\", \"event_type\":\"price_change\"}","raw_base64":null}
{"received_ms":1789987928998,"monotonic_ns":1019369828928900,"raw":"{\"market\":\"0x28a45972fccdaf0fba75dacc59725521035e177d09dd92174f9f52740bccb025\", \"price_changes\":[{\"asset_id\":\"61819828071723399190623735325323968706432622380635304641786792960078828866875\", \"price\":\"0.79\", \"size\":\"447\", \"side\":\"BUY\", \"hash\":\"74a9ce4d0f8f74701d55410b2a2c4a59ceeca8c4\", \"best_bid\":\"0.86\", \"best_ask\":\"0.87\"}, {\"asset_id\":\"114356653315647913247200886351065428002113119844334520181865067698979836634569\", \"price\":\"0.21\", \"size\":\"447\", \"side\":\"SELL\", \"hash\":\"e874458bee2923e07ea61b6455f9f12a26632128\", \"best_bid\":\"0.13\", \"best_ask\":\"0.14\"}], \"timestamp\":\"1789987928976\", \"event_type\":\"price_change\"}","raw_base64":null}
{"received_ms":1789987928998,"monotonic_ns":1019369829016500,"raw":"{\"market\":\"0x28a45972fccdaf0fba75dacc59725521035e177d09dd92174f9f52740bccb025\", \"price_changes\":[{\"asset_id\":\"61819828071723399190623735325323968706432622380635304641786792960078828866875\", \"price\":\"0.8\", \"size\":\"562\", \"side\":\"BUY\", \"hash\":\"74a9ce4d0f8f74701d55410b2a2c4a59ceeca8c4\", \"best_bid\":\"0.86\", \"best_ask\":\"0.87\"}, {\"asset_id\":\"114356653315647913247200886351065428002113119844334520181865067698979836634569\", \"price\":\"0.2\", \"size\":\"562\", \"side\":\"SELL\", \"hash\":\"e874458bee2923e07ea61b6455f9f12a26632128\", \"best_bid\":\"0.13\", \"best_ask\":\"0.14\"}], \"timestamp\":\"1789987928976\", \"event_type\":\"price_change\"}","raw_base64":null}
{"received_ms":1789987928999,"monotonic_ns":1019369829952700,"raw":"{\"market\":\"0x28a45972fccdaf0fba75dacc59725521035e177d09dd92174f9f52740bccb025\", \"price_changes\":[{\"asset_id\":\"61819828071723399190623735325323968706432622380635304641786792960078828866875\", \"price\":\"0.86\", \"size\":\"4670.17\", \"side\":\"BUY\", \"hash\":\"c5cba103858d101b317a7411401ca971aeda6da4\", \"best_bid\":\"0.86\", \"best_ask\":\"0.87\"}, {\"asset_id\":\"114356653315647913247200886351065428002113119844334520181865067698979836634569\", \"price\":\"0.14\", \"size\":\"4670.17\", \"side\":\"SELL\", \"hash\":\"aefb1b85768055b486df11f87faca839f067bafc\", \"best_bid\":\"0.13\", \"best_ask\":\"0.14\"}], \"timestamp\":\"1789987928979\", \"event_type\":\"price_change\"}","raw_base64":null}
{"received_ms":1789987929023,"monotonic_ns":1019369853500600,"raw":"{\"market\":\"0x28a45972fccdaf0fba75dacc59725521035e177d09dd92174f9f52740bccb025\", \"price_changes\":[{\"asset_id\":\"114356653315647913247200886351065428002113119844334520181865067698979836634569\", \"price\":\"0.1\", \"size\":\"520\", \"side\":\"BUY\", \"hash\":\"b63c439269b7362fae2d73bbc3f0ad941a1934c8\", \"best_bid\":\"0.13\", \"best_ask\":\"0.14\"}, {\"asset_id\":\"61819828071723399190623735325323968706432622380635304641786792960078828866875\", \"price\":\"0.9\", \"size\":\"520\", \"side\":\"SELL\", \"hash\":\"1d731a225e51cd08dfce3aa8195c270dfcdd5645\", \"best_bid\":\"0.86\", \"best_ask\":\"0.87\"}], \"timestamp\":\"1789987929002\", \"event_type\":\"price_change\"}","raw_base64":null}
{"received_ms":1789987929024,"monotonic_ns":1019369854488800,"raw":"{\"market\":\"0x28a45972fccdaf0fba75dacc59725521035e177d09dd92174f9f52740bccb025\", \"price_changes\":[{\"asset_id\":\"61819828071723399190623735325323968706432622380635304641786792960078828866875\", \"price\":\"0.75\", \"size\":\"520\", \"side\":\"BUY\", \"hash\":\"0011353fbee295284a90988cc6c5143805408af7\", \"best_bid\":\"0.86\", \"best_ask\":\"0.87\"}, {\"asset_id\":\"114356653315647913247200886351065428002113119844334520181865067698979836634569\", \"price\":\"0.25\", \"size\":\"520\", \"side\":\"SELL\", \"hash\":\"cf2438fff5fb0446746e5bb0802cb3b6266b8ac6\", \"best_bid\":\"0.13\", \"best_ask\":\"0.14\"}], \"timestamp\":\"1789987929003\", \"event_type\":\"price_change\"}","raw_base64":null}
{"received_ms":1789987929033,"monotonic_ns":1019369863548500,"raw":"{\"market\":\"0x28a45972fccdaf0fba75dacc59725521035e177d09dd92174f9f52740bccb025\", \"price_changes\":[{\"asset_id\":\"61819828071723399190623735325323968706432622380635304641786792960078828866875\", \"price\":\"0.75\", \"size\":\"420\", \"side\":\"BUY\", \"hash\":\"0e6a34f3a6281851cb0b3f3d2b61d14af5258a56\", \"best_bid\":\"0.86\", \"best_ask\":\"0.87\"}, {\"asset_id\":\"114356653315647913247200886351065428002113119844334520181865067698979836634569\", \"price\":\"0.25\", \"size\":\"420\", \"side\":\"SELL\", \"hash\":\"d49ea02cd0fb7ca8371f9e650138840d5bf8f1ee\", \"best_bid\":\"0.13\", \"best_ask\":\"0.14\"}], \"timestamp\":\"1789987929012\", \"event_type\":\"price_change\"}","raw_base64":null}
{"received_ms":1789987929037,"monotonic_ns":1019369868114600,"raw":"{\"market\":\"0x28a45972fccdaf0fba75dacc59725521035e177d09dd92174f9f52740bccb025\", \"price_changes\":[{\"asset_id\":\"61819828071723399190623735325323968706432622380635304641786792960078828866875\", \"price\":\"0.86\", \"size\":\"4583.17\", \"side\":\"BUY\", \"hash\":\"efd77072af3b710e620b40a2eeddaa39c5b8e2c3\", \"best_bid\":\"0.86\", \"best_ask\":\"0.87\"}, {\"asset_id\":\"114356653315647913247200886351065428002113119844334520181865067698979836634569\", \"price\":\"0.14\", \"size\":\"4583.17\", \"side\":\"SELL\", \"hash\":\"75535b786dfe7aced5a442b9d452aba1c3a481a7\", \"best_bid\":\"0.13\", \"best_ask\":\"0.14\"}], \"timestamp\":\"1789987929017\", \"event_type\":\"price_change\"}","raw_base64":null}
{"received_ms":1789987929042,"monotonic_ns":1019369873178800,"raw":"{\"market\":\"0x28a45972fccdaf0fba75dacc59725521035e177d09dd92174f9f52740bccb025\", \"price_changes\":[{\"asset_id\":\"61819828071723399190623735325323968706432622380635304641786792960078828866875\", \"price\":\"0.86\", \"size\":\"4480.17\", \"side\":\"BUY\", \"hash\":\"4a7b8bee1305e96bb1d435169fc7ce00cf795259\", \"best_bid\":\"0.86\", \"best_ask\":\"0.87\"}, {\"asset_id\":\"114356653315647913247200886351065428002113119844334520181865067698979836634569\", \"price\":\"0.14\", \"size\":\"4480.17\", \"side\":\"SELL\", \"hash\":\"90cb7ba176710fc83bb1e078bf03cd9f516bd0e5\", \"best_bid\":\"0.13\", \"best_ask\":\"0.14\"}], \"timestamp\":\"1789987929022\", \"event_type\":\"price_change\"}","raw_base64":null}
{"received_ms":1789987929050,"monotonic_ns":1019369880727600,"raw":"{\"market\":\"0x28a45972fccdaf0fba75dacc59725521035e177d09dd92174f9f52740bccb025\", \"price_changes\":[{\"asset_id\":\"114356653315647913247200886351065428002113119844334520181865067698979836634569\", \"price\":\"0.07\", \"size\":\"6372.71\", \"side\":\"BUY\", \"hash\":\"c1a1d13b5aa50883694a1b968e6be865866a908b\", \"best_bid\":\"0.13\", \"best_ask\":\"0.14\"}, {\"asset_id\":\"61819828071723399190623735325323968706432622380635304641786792960078828866875\", \"price\":\"0.93\", \"size\":\"6372.71\", \"side\":\"SELL\", \"hash\":\"4a1a399dd5990f395c19afa6343d49aa158f7fdd\", \"best_bid\":\"0.86\", \"best_ask\":\"0.87\"}], \"timestamp\":\"1789987929029\", \"event_type\":\"price_change\"}","raw_base64":null}
{"received_ms":1789987929051,"monotonic_ns":1019369881318100,"raw":"{\"market\":\"0x28a45972fccdaf0fba75dacc59725521035e177d09dd92174f9f52740bccb025\", \"price_changes\":[{\"asset_id\":\"61819828071723399190623735325323968706432622380635304641786792960078828866875\", \"price\":\"0.86\", \"size\":\"3600.17\", \"side\":\"BUY\", \"hash\":\"3b969929be50090654e725ad5c828f80aaeb02cb\", \"best_bid\":\"0.86\", \"best_ask\":\"0.87\"}, {\"asset_id\":\"114356653315647913247200886351065428002113119844334520181865067698979836634569\", \"price\":\"0.14\", \"size\":\"3600.17\", \"side\":\"SELL\", \"hash\":\"433e6daaef7318e4e12b4c5d63e070e0028b7ea6\", \"best_bid\":\"0.13\", \"best_ask\":\"0.14\"}], \"timestamp\":\"1789987929030\", \"event_type\":\"price_change\"}","raw_base64":null}
{"received_ms":1789987929055,"monotonic_ns":1019369885340300,"raw":"{\"market\":\"0x28a45972fccdaf0fba75dacc59725521035e177d09dd92174f9f52740bccb025\", \"price_changes\":[{\"asset_id\":\"114356653315647913247200886351065428002113119844334520181865067698979836634569\", \"price\":\"0.1\", \"size\":\"560\", \"side\":\"BUY\", \"hash\":\"0cb9722e0b997a718d3a6dc71b5882211627e9cb\", \"best_bid\":\"0.13\", \"best_ask\":\"0.14\"}, {\"asset_id\":\"61819828071723399190623735325323968706432622380635304641786792960078828866875\", \"price\":\"0.9\", \"size\":\"560\", \"side\":\"SELL\", \"hash\":\"aa127b0d650edbad97183bf027c408498327d124\", \"best_bid\":\"0.86\", \"best_ask\":\"0.87\"}], \"timestamp\":\"1789987929034\", \"event_type\":\"price_change\"}","raw_base64":null}
{"received_ms":1789987929055,"monotonic_ns":1019369885751500,"raw":"{\"market\":\"0x28a45972fccdaf0fba75dacc59725521035e177d09dd92174f9f52740bccb025\", \"price_changes\":[{\"asset_id\":\"114356653315647913247200886351065428002113119844334520181865067698979836634569\", \"price\":\"0.01\", \"size\":\"1694.43\", \"side\":\"BUY\", \"hash\":\"f0e499f10b659375dc9bf7ccd5959b1ca0dac316\", \"best_bid\":\"0.13\", \"best_ask\":\"0.14\"}, {\"asset_id\":\"61819828071723399190623735325323968706432622380635304641786792960078828866875\", \"price\":\"0.99\", \"size\":\"1694.43\", \"side\":\"SELL\", \"hash\":\"04684319b6a0f53fada47ec5901b2e0c6808864e\", \"best_bid\":\"0.86\", \"best_ask\":\"0.87\"}], \"timestamp\":\"1789987929035\", \"event_type\":\"price_change\"}","raw_base64":null}
{"received_ms":1789987929063,"monotonic_ns":1019369894103600,"raw":"{\"market\":\"0x28a45972fccdaf0fba75dacc59725521035e177d09dd92174f9f52740bccb025\", \"price_changes\":[{\"asset_id\":\"61819828071723399190623735325323968706432622380635304641786792960078828866875\", \"price\":\"0.79\", \"size\":\"527\", \"side\":\"BUY\", \"hash\":\"1e461ef63dd649df360751b51763e2986be825ab\", \"best_bid\":\"0.86\", \"best_ask\":\"0.87\"}, {\"asset_id\":\"114356653315647913247200886351065428002113119844334520181865067698979836634569\", \"price\":\"0.21\", \"size\":\"527\", \"side\":\"SELL\", \"hash\":\"9a2d30bd4d7372092ea34919fdc104629c5230c5\", \"best_bid\":\"0.13\", \"best_ask\":\"0.14\"}], \"timestamp\":\"1789987929043\", \"event_type\":\"price_change\"}","raw_base64":null}
{"received_ms":1789987929064,"monotonic_ns":1019369894906900,"raw":"{\"market\":\"0x28a45972fccdaf0fba75dacc59725521035e177d09dd92174f9f52740bccb025\", \"price_changes\":[{\"asset_id\":\"61819828071723399190623735325323968706432622380635304641786792960078828866875\", \"price\":\"0.8\", \"size\":\"582\", \"side\":\"BUY\", \"hash\":\"bc4d5b208254d55c45d86b704d5dde2a378213be\", \"best_bid\":\"0.86\", \"best_ask\":\"0.87\"}, {\"asset_id\":\"114356653315647913247200886351065428002113119844334520181865067698979836634569\", \"price\":\"0.2\", \"size\":\"582\", \"side\":\"SELL\", \"hash\":\"7fe0739fbd3e810efb10edb5746dac05544593a6\", \"best_bid\":\"0.13\", \"best_ask\":\"0.14\"}], \"timestamp\":\"1789987929044\", \"event_type\":\"price_change\"}","raw_base64":null}
{"received_ms":1789987929067,"monotonic_ns":1019369897452600,"raw":"{\"market\":\"0x28a45972fccdaf0fba75dacc59725521035e177d09dd92174f9f52740bccb025\", \"price_changes\":[{\"asset_id\":\"61819828071723399190623735325323968706432622380635304641786792960078828866875\", \"price\":\"0.79\", \"size\":\"447\", \"side\":\"BUY\", \"hash\":\"1a1aac3e1c232a67cb3a2ac71c4cea29d6f1a44e\", \"best_bid\":\"0.86\", \"best_ask\":\"0.87\"}, {\"asset_id\":\"114356653315647913247200886351065428002113119844334520181865067698979836634569\", \"price\":\"0.21\", \"size\":\"447\", \"side\":\"SELL\", \"hash\":\"99fbd26768492c60b3d582cf393e86da576323eb\", \"best_bid\":\"0.13\", \"best_ask\":\"0.14\"}], \"timestamp\":\"1789987929046\", \"event_type\":\"price_change\"}","raw_base64":null}
{"received_ms":1789987929067,"monotonic_ns":1019369897531600,"raw":"{\"market\":\"0x28a45972fccdaf0fba75dacc59725521035e177d09dd92174f9f52740bccb025\", \"price_changes\":[{\"asset_id\":\"61819828071723399190623735325323968706432622380635304641786792960078828866875\", \"price\":\"0.8\", \"size\":\"562\", \"side\":\"BUY\", \"hash\":\"1a1aac3e1c232a67cb3a2ac71c4cea29d6f1a44e\", \"best_bid\":\"0.86\", \"best_ask\":\"0.87\"}, {\"asset_id\":\"114356653315647913247200886351065428002113119844334520181865067698979836634569\", \"price\":\"0.2\", \"size\":\"562\", \"side\":\"SELL\", \"hash\":\"99fbd26768492c60b3d582cf393e86da576323eb\", \"best_bid\":\"0.13\", \"best_ask\":\"0.14\"}], \"timestamp\":\"1789987929046\", \"event_type\":\"price_change\"}","raw_base64":null}
{"received_ms":1789987929083,"monotonic_ns":1019369913286500,"raw":"{\"market\":\"0x28a45972fccdaf0fba75dacc59725521035e177d09dd92174f9f52740bccb025\", \"price_changes\":[{\"asset_id\":\"61819828071723399190623735325323968706432622380635304641786792960078828866875\", \"price\":\"0.86\", \"size\":\"4558.17\", \"side\":\"BUY\", \"hash\":\"f940ab2245d2dfd1a27ae3c2a8fae0343580f23a\", \"best_bid\":\"0.86\", \"best_ask\":\"0.87\"}, {\"asset_id\":\"114356653315647913247200886351065428002113119844334520181865067698979836634569\", \"price\":\"0.14\", \"size\":\"4558.17\", \"side\":\"SELL\", \"hash\":\"cffb93e7cefbc666c8ee804d028c6e9c5f75afd3\", \"best_bid\":\"0.13\", \"best_ask\":\"0.14\"}], \"timestamp\":\"1789987929062\", \"event_type\":\"price_change\"}","raw_base64":null}
{"received_ms":1789987929095,"monotonic_ns":1019369925865100,"raw":"{\"market\":\"0x28a45972fccdaf0fba75dacc59725521035e177d09dd92174f9f52740bccb025\", \"price_changes\":[{\"asset_id\":\"114356653315647913247200886351065428002113119844334520181865067698979836634569\", \"price\":\"0.1\", \"size\":\"580\", \"side\":\"BUY\", \"hash\":\"724fa4e1019fdc1779b7c5a6663f95f43de4c787\", \"best_bid\":\"0.13\", \"best_ask\":\"0.14\"}, {\"asset_id\":\"61819828071723399190623735325323968706432622380635304641786792960078828866875\", \"price\":\"0.9\", \"size\":\"580\", \"side\":\"SELL\", \"hash\":\"e417cfcad40454af9075107df0e1495d220abaa5\", \"best_bid\":\"0.86\", \"best_ask\":\"0.87\"}], \"timestamp\":\"1789987929067\", \"event_type\":\"price_change\"}","raw_base64":null}
{"received_ms":1789987929095,"monotonic_ns":1019369926187800,"raw":"{\"market\":\"0x28a45972fccdaf0fba75dacc59725521035e177d09dd92174f9f52740bccb025\", \"price_changes\":[{\"asset_id\":\"61819828071723399190623735325323968706432622380635304641786792960078828866875\", \"price\":\"0.75\", \"size\":\"520\", \"side\":\"BUY\", \"hash\":\"b967d74701dcfb29a1687c622c0c2c91fdb65520\", \"best_bid\":\"0.86\", \"best_ask\":\"0.87\"}, {\"asset_id\":\"114356653315647913247200886351065428002113119844334520181865067698979836634569\", \"price\":\"0.25\", \"size\":\"520\", \"side\":\"SELL\", \"hash\":\"4c91de1de68013345a4d7a93c3d691a545cb64b3\", \"best_bid\":\"0.13\", \"best_ask\":\"0.14\"}], \"timestamp\":\"1789987929073\", \"event_type\":\"price_change\"}","raw_base64":null}
{"received_ms":1789987929115,"monotonic_ns":1019369945309400,"raw":"{\"market\":\"0x28a45972fccdaf0fba75dacc59725521035e177d09dd92174f9f52740bccb025\", \"price_changes\":[{\"asset_id\":\"61819828071723399190623735325323968706432622380635304641786792960078828866875\", \"price\":\"0.75\", \"size\":\"420\", \"side\":\"BUY\", \"hash\":\"991108aede99a8e164a1b20cf0c05d9e41fdbaaf\", \"best_bid\":\"0.86\", \"best_ask\":\"0.87\"}, {\"asset_id\":\"114356653315647913247200886351065428002113119844334520181865067698979836634569\", \"price\":\"0.25\", \"size\":\"420\", \"side\":\"SELL\", \"hash\":\"d2aca663dc3b8e03859bc30ef92c94b94bda7b25\", \"best_bid\":\"0.13\", \"best_ask\":\"0.14\"}], \"timestamp\":\"1789987929086\", \"event_type\":\"price_change\"}","raw_base64":null}
{"received_ms":1789987929121,"monotonic_ns":1019369952215300,"raw":"{\"market\":\"0x28a45972fccdaf0fba75dacc59725521035e177d09dd92174f9f52740bccb025\", \"price_changes\":[{\"asset_id\":\"114356653315647913247200886351065428002113119844334520181865067698979836634569\", \"price\":\"0.07\", \"size\":\"5683.71\", \"side\":\"BUY\", \"hash\":\"bf41a60b5995c021e55c9475de020c27e9945700\", \"best_bid\":\"0.13\", \"best_ask\":\"0.14\"}, {\"asset_id\":\"61819828071723399190623735325323968706432622380635304641786792960078828866875\", \"price\":\"0.93\", \"size\":\"5683.71\", \"side\":\"SELL\", \"hash\":\"ded0e3639ea29813262de1e99ac05e50b06c8396\", \"best_bid\":\"0.86\", \"best_ask\":\"0.87\"}], \"timestamp\":\"1789987929100\", \"event_type\":\"price_change\"}","raw_base64":null}
{"received_ms":1789987929122,"monotonic_ns":1019369952413600,"raw":"{\"market\":\"0x28a45972fccdaf0fba75dacc59725521035e177d09dd92174f9f52740bccb025\", \"price_changes\":[{\"asset_id\":\"114356653315647913247200886351065428002113119844334520181865067698979836634569\", \"price\":\"0.07\", \"size\":\"5487.71\", \"side\":\"BUY\", \"hash\":\"59fcb4bb81f1703d0543ba5feeb8897f52e5a925\", \"best_bid\":\"0.13\", \"best_ask\":\"0.14\"}, {\"asset_id\":\"61819828071723399190623735325323968706432622380635304641786792960078828866875\", \"price\":\"0.93\", \"size\":\"5487.71\", \"side\":\"SELL\", \"hash\":\"db87ebd4c618a39b9ad71c45ee8f575632de4408\", \"best_bid\":\"0.86\", \"best_ask\":\"0.87\"}], \"timestamp\":\"1789987929101\", \"event_type\":\"price_change\"}","raw_base64":null}
{"received_ms":1789987929123,"monotonic_ns":1019369954082100,"raw":"{\"market\":\"0x28a45972fccdaf0fba75dacc59725521035e177d09dd92174f9f52740bccb025\", \"price_changes\":[{\"asset_id\":\"114356653315647913247200886351065428002113119844334520181865067698979836634569\", \"price\":\"0.06\", \"size\":\"5308.67\", \"side\":\"BUY\", \"hash\":\"49ecb5115b4ed63a34105e95b1eece8d56abc55d\", \"best_bid\":\"0.13\", \"best_ask\":\"0.14\"}, {\"asset_id\":\"61819828071723399190623735325323968706432622380635304641786792960078828866875\", \"price\":\"0.94\", \"size\":\"5308.67\", \"side\":\"SELL\", \"hash\":\"adaa0700e472ff3ea2808d9f70a503d5d4fe57a1\", \"best_bid\":\"0.86\", \"best_ask\":\"0.87\"}], \"timestamp\":\"1789987929101\", \"event_type\":\"price_change\"}","raw_base64":null}
{"received_ms":1789987929123,"monotonic_ns":1019369954146400,"raw":"{\"market\":\"0x28a45972fccdaf0fba75dacc59725521035e177d09dd92174f9f52740bccb025\", \"price_changes\":[{\"asset_id\":\"114356653315647913247200886351065428002113119844334520181865067698979836634569\", \"price\":\"0.06\", \"size\":\"5298.67\", \"side\":\"BUY\", \"hash\":\"f164fbc154b315a18b6e8f841cc4d0c0f0e36060\", \"best_bid\":\"0.13\", \"best_ask\":\"0.14\"}, {\"asset_id\":\"61819828071723399190623735325323968706432622380635304641786792960078828866875\", \"price\":\"0.94\", \"size\":\"5298.67\", \"side\":\"SELL\", \"hash\":\"11487c660af500ef7dc73191ea0d76862d50dc0c\", \"best_bid\":\"0.86\", \"best_ask\":\"0.87\"}], \"timestamp\":\"1789987929101\", \"event_type\":\"price_change\"}","raw_base64":null}
{"received_ms":1789987929135,"monotonic_ns":1019369966199700,"raw":"{\"market\":\"0x28a45972fccdaf0fba75dacc59725521035e177d09dd92174f9f52740bccb025\", \"price_changes\":[{\"asset_id\":\"61819828071723399190623735325323968706432622380635304641786792960078828866875\", \"price\":\"0.79\", \"size\":\"527\", \"side\":\"BUY\", \"hash\":\"226db9712d04f55d29cc3a237cc0780f5d2795c4\", \"best_bid\":\"0.86\", \"best_ask\":\"0.87\"}, {\"asset_id\":\"114356653315647913247200886351065428002113119844334520181865067698979836634569\", \"price\":\"0.21\", \"size\":\"527\", \"side\":\"SELL\", \"hash\":\"dc2ceb11f0c77e542f23f4452dc0e1790156ccfa\", \"best_bid\":\"0.13\", \"best_ask\":\"0.14\"}], \"timestamp\":\"1789987929115\", \"event_type\":\"price_change\"}","raw_base64":null}
{"received_ms":1789987929136,"monotonic_ns":1019369966498500,"raw":"{\"market\":\"0x28a45972fccdaf0fba75dacc59725521035e177d09dd92174f9f52740bccb025\", \"price_changes\":[{\"asset_id\":\"61819828071723399190623735325323968706432622380635304641786792960078828866875\", \"price\":\"0.8\", \"size\":\"582\", \"side\":\"BUY\", \"hash\":\"950039cd39a800636f302e5de4ba52fdc0d3741d\", \"best_bid\":\"0.86\", \"best_ask\":\"0.87\"}, {\"asset_id\":\"114356653315647913247200886351065428002113119844334520181865067698979836634569\", \"price\":\"0.2\", \"size\":\"582\", \"side\":\"SELL\", \"hash\":\"66914707a1debae200265fa195efa9083e3dc6db\", \"best_bid\":\"0.13\", \"best_ask\":\"0.14\"}], \"timestamp\":\"1789987929116\", \"event_type\":\"price_change\"}","raw_base64":null}
{"received_ms":1789987929140,"monotonic_ns":1019369970722900,"raw":"{\"market\":\"0x28a45972fccdaf0fba75dacc59725521035e177d09dd92174f9f52740bccb025\", \"price_changes\":[{\"asset_id\":\"61819828071723399190623735325323968706432622380635304641786792960078828866875\", \"price\":\"0.79\", \"size\":\"447\", \"side\":\"BUY\", \"hash\":\"e61b3f814d091b0f55dd22a6112e6eaa331f088f\", \"best_bid\":\"0.86\", \"best_ask\":\"0.87\"}, {\"asset_id\":\"114356653315647913247200886351065428002113119844334520181865067698979836634569\", \"price\":\"0.21\", \"size\":\"447\", \"side\":\"SELL\", \"hash\":\"3ee43b3c0d6a73c4b6807392adfc7d90af6a4dbc\", \"best_bid\":\"0.13\", \"best_ask\":\"0.14\"}], \"timestamp\":\"1789987929119\", \"event_type\":\"price_change\"}","raw_base64":null}
{"received_ms":1789987929140,"monotonic_ns":1019369970810500,"raw":"{\"market\":\"0x28a45972fccdaf0fba75dacc59725521035e177d09dd92174f9f52740bccb025\", \"price_changes\":[{\"asset_id\":\"61819828071723399190623735325323968706432622380635304641786792960078828866875\", \"price\":\"0.8\", \"size\":\"562\", \"side\":\"BUY\", \"hash\":\"e61b3f814d091b0f55dd22a6112e6eaa331f088f\", \"best_bid\":\"0.86\", \"best_ask\":\"0.87\"}, {\"asset_id\":\"114356653315647913247200886351065428002113119844334520181865067698979836634569\", \"price\":\"0.2\", \"size\":\"562\", \"side\":\"SELL\", \"hash\":\"3ee43b3c0d6a73c4b6807392adfc7d90af6a4dbc\", \"best_bid\":\"0.13\", \"best_ask\":\"0.14\"}], \"timestamp\":\"1789987929119\", \"event_type\":\"price_change\"}","raw_base64":null}
{"received_ms":1789987929158,"monotonic_ns":1019369989194000,"raw":"{\"market\":\"0x28a45972fccdaf0fba75dacc59725521035e177d09dd92174f9f52740bccb025\", \"price_changes\":[{\"asset_id\":\"61819828071723399190623735325323968706432622380635304641786792960078828866875\", \"price\":\"0.85\", \"size\":\"2760.35\", \"side\":\"BUY\", \"hash\":\"6137414f05a46a929a2e13ad338f8151a0b7f282\", \"best_bid\":\"0.86\", \"best_ask\":\"0.87\"}, {\"asset_id\":\"114356653315647913247200886351065428002113119844334520181865067698979836634569\", \"price\":\"0.15\", \"size\":\"2760.35\", \"side\":\"SELL\", \"hash\":\"0e5359359650a70384ad7c4be4b1773f6ff463a0\", \"best_bid\":\"0.13\", \"best_ask\":\"0.14\"}], \"timestamp\":\"1789987929138\", \"event_type\":\"price_change\"}","raw_base64":null}
{"received_ms":1789987929161,"monotonic_ns":1019369991787300,"raw":"{\"market\":\"0x28a45972fccdaf0fba75dacc59725521035e177d09dd92174f9f52740bccb025\", \"price_changes\":[{\"asset_id\":\"61819828071723399190623735325323968706432622380635304641786792960078828866875\", \"price\":\"0.85\", \"size\":\"2751.35\", \"side\":\"BUY\", \"hash\":\"abeccd409e6398b2890da8e176f57e32f5a5b57a\", \"best_bid\":\"0.86\", \"best_ask\":\"0.87\"}, {\"asset_id\":\"114356653315647913247200886351065428002113119844334520181865067698979836634569\", \"price\":\"0.15\", \"size\":\"2751.35\", \"side\":\"SELL\", \"hash\":\"b7956ee653a264ec3f93e990c9bb1e22bb13c862\", \"best_bid\":\"0.13\", \"best_ask\":\"0.14\"}], \"timestamp\":\"1789987929141\", \"event_type\":\"price_change\"}","raw_base64":null}
{"received_ms":1789987929162,"monotonic_ns":1019369992523400,"raw":"{\"market\":\"0x28a45972fccdaf0fba75dacc59725521035e177d09dd92174f9f52740bccb025\", \"price_changes\":[{\"asset_id\":\"114356653315647913247200886351065428002113119844334520181865067698979836634569\", \"price\":\"0.07\", \"size\":\"6078.71\", \"side\":\"BUY\", \"hash\":\"ca49f76f02e79aa397913f9eac5f4787678eb48c\", \"best_bid\":\"0.13\", \"best_ask\":\"0.14\"}, {\"asset_id\":\"61819828071723399190623735325323968706432622380635304641786792960078828866875\", \"price\":\"0.93\", \"size\":\"6078.71\", \"side\":\"SELL\", \"hash\":\"140a9b80b193c9d052dea8457a1083a1105cc775\", \"best_bid\":\"0.86\", \"best_ask\":\"0.87\"}], \"timestamp\":\"1789987929141\", \"event_type\":\"price_change\"}","raw_base64":null}
{"received_ms":1789987929164,"monotonic_ns":1019369995174700,"raw":"{\"market\":\"0x28a45972fccdaf0fba75dacc59725521035e177d09dd92174f9f52740bccb025\", \"price_changes\":[{\"asset_id\":\"114356653315647913247200886351065428002113119844334520181865067698979836634569\", \"price\":\"0.06\", \"size\":\"6201.67\", \"side\":\"BUY\", \"hash\":\"9492754e93408daccd92787b9ec9fd434860c006\", \"best_bid\":\"0.13\", \"best_ask\":\"0.14\"}, {\"asset_id\":\"61819828071723399190623735325323968706432622380635304641786792960078828866875\", \"price\":\"0.94\", \"size\":\"6201.67\", \"side\":\"SELL\", \"hash\":\"540cf3416d0cdb2ee93a87d10f72e541dc8de6ba\", \"best_bid\":\"0.86\", \"best_ask\":\"0.87\"}], \"timestamp\":\"1789987929142\", \"event_type\":\"price_change\"}","raw_base64":null}
{"received_ms":1789987929168,"monotonic_ns":1019369999092800,"raw":"{\"market\":\"0x28a45972fccdaf0fba75dacc59725521035e177d09dd92174f9f52740bccb025\", \"price_changes\":[{\"asset_id\":\"61819828071723399190623735325323968706432622380635304641786792960078828866875\", \"price\":\"0.75\", \"size\":\"520\", \"side\":\"BUY\", \"hash\":\"6142e63d7db542f3567d031bc0babcf444b6a710\", \"best_bid\":\"0.86\", \"best_ask\":\"0.87\"}, {\"asset_id\":\"114356653315647913247200886351065428002113119844334520181865067698979836634569\", \"price\":\"0.25\", \"size\":\"520\", \"side\":\"SELL\", \"hash\":\"b46889bdd92762233a77faece6f3f2ba271959a3\", \"best_bid\":\"0.13\", \"best_ask\":\"0.14\"}], \"timestamp\":\"1789987929146\", \"event_type\":\"price_change\"}","raw_base64":null}
{"received_ms":1789987929173,"monotonic_ns":1019370003446800,"raw":"{\"market\":\"0x28a45972fccdaf0fba75dacc59725521035e177d09dd92174f9f52740bccb025\", \"price_changes\":[{\"asset_id\":\"61819828071723399190623735325323968706432622380635304641786792960078828866875\", \"price\":\"0.75\", \"size\":\"420\", \"side\":\"BUY\", \"hash\":\"c40a0c9ca22ef1c829e770bc18fc39e308c292f4\", \"best_bid\":\"0.86\", \"best_ask\":\"0.87\"}, {\"asset_id\":\"114356653315647913247200886351065428002113119844334520181865067698979836634569\", \"price\":\"0.25\", \"size\":\"420\", \"side\":\"SELL\", \"hash\":\"a7528c7bd46eed9f6865f6d00b9ed7d3e3ba9d04\", \"best_bid\":\"0.13\", \"best_ask\":\"0.14\"}], \"timestamp\":\"1789987929152\", \"event_type\":\"price_change\"}","raw_base64":null}
{"received_ms":1789987929181,"monotonic_ns":1019370012187100,"raw":"{\"market\":\"0x28a45972fccdaf0fba75dacc59725521035e177d09dd92174f9f52740bccb025\", \"price_changes\":[{\"asset_id\":\"114356653315647913247200886351065428002113119844334520181865067698979836634569\", \"price\":\"0.01\", \"size\":\"1689.43\", \"side\":\"BUY\", \"hash\":\"feda6f2e33674f6d27cab2145d08d7c57f4a1c74\", \"best_bid\":\"0.13\", \"best_ask\":\"0.14\"}, {\"asset_id\":\"61819828071723399190623735325323968706432622380635304641786792960078828866875\", \"price\":\"0.99\", \"size\":\"1689.43\", \"side\":\"SELL\", \"hash\":\"9b018263f9dc17db854fd67a262e528e7b9187b4\", \"best_bid\":\"0.86\", \"best_ask\":\"0.87\"}], \"timestamp\":\"1789987929161\", \"event_type\":\"price_change\"}","raw_base64":null}
{"received_ms":1789987929187,"monotonic_ns":1019370017736600,"raw":"{\"market\":\"0x28a45972fccdaf0fba75dacc59725521035e177d09dd92174f9f52740bccb025\", \"price_changes\":[{\"asset_id\":\"114356653315647913247200886351065428002113119844334520181865067698979836634569\", \"price\":\"0.05\", \"size\":\"5615\", \"side\":\"BUY\", \"hash\":\"ddf743ca2b483847455e369506a87e7fba2d74fe\", \"best_bid\":\"0.13\", \"best_ask\":\"0.14\"}, {\"asset_id\":\"61819828071723399190623735325323968706432622380635304641786792960078828866875\", \"price\":\"0.95\", \"size\":\"5615\", \"side\":\"SELL\", \"hash\":\"74c13705796cc3ab16ec5ab8cb123cdf071ec15f\", \"best_bid\":\"0.86\", \"best_ask\":\"0.87\"}], \"timestamp\":\"1789987929167\", \"event_type\":\"price_change\"}","raw_base64":null}
{"received_ms":1789987929193,"monotonic_ns":1019370023688700,"raw":"{\"market\":\"0x28a45972fccdaf0fba75dacc59725521035e177d09dd92174f9f52740bccb025\", \"price_changes\":[{\"asset_id\":\"114356653315647913247200886351065428002113119844334520181865067698979836634569\", \"price\":\"0.07\", \"size\":\"6328.71\", \"side\":\"BUY\", \"hash\":\"6a7840cdffb0c34badae2a519d33e462f97cf4f8\", \"best_bid\":\"0.13\", \"best_ask\":\"0.14\"}, {\"asset_id\":\"61819828071723399190623735325323968706432622380635304641786792960078828866875\", \"price\":\"0.93\", \"size\":\"6328.71\", \"side\":\"SELL\", \"hash\":\"3f54b8346a1e82d2697295b0933db66c98c1dca5\", \"best_bid\":\"0.86\", \"best_ask\":\"0.87\"}], \"timestamp\":\"1789987929173\", \"event_type\":\"price_change\"}","raw_base64":null}
{"received_ms":1789987929196,"monotonic_ns":1019370026810100,"raw":"{\"market\":\"0x28a45972fccdaf0fba75dacc59725521035e177d09dd92174f9f52740bccb025\", \"price_changes\":[{\"asset_id\":\"61819828071723399190623735325323968706432622380635304641786792960078828866875\", \"price\":\"0.86\", \"size\":\"4676.17\", \"side\":\"BUY\", \"hash\":\"729285a9f973b6c204d1b4fe4b44cec428c326f0\", \"best_bid\":\"0.86\", \"best_ask\":\"0.87\"}, {\"asset_id\":\"114356653315647913247200886351065428002113119844334520181865067698979836634569\", \"price\":\"0.14\", \"size\":\"4676.17\", \"side\":\"SELL\", \"hash\":\"50f3f0bca73d1055724d85976b1d9e1abf2d77e6\", \"best_bid\":\"0.13\", \"best_ask\":\"0.14\"}], \"timestamp\":\"1789987929174\", \"event_type\":\"price_change\"}","raw_base64":null}
{"received_ms":1789987929196,"monotonic_ns":1019370026861300,"raw":"{\"market\":\"0x28a45972fccdaf0fba75dacc59725521035e177d09dd92174f9f52740bccb025\", \"price_changes\":[{\"asset_id\":\"61819828071723399190623735325323968706432622380635304641786792960078828866875\", \"price\":\"0.84\", \"size\":\"2980\", \"side\":\"BUY\", \"hash\":\"a4eb79fea5c18528b5161f0aa5b2e2474d4b2925\", \"best_bid\":\"0.86\", \"best_ask\":\"0.87\"}, {\"asset_id\":\"114356653315647913247200886351065428002113119844334520181865067698979836634569\", \"price\":\"0.16\", \"size\":\"2980\", \"side\":\"SELL\", \"hash\":\"5eca7010ad314887806b8636029d84061d356dcb\", \"best_bid\":\"0.13\", \"best_ask\":\"0.14\"}], \"timestamp\":\"1789987929175\", \"event_type\":\"price_change\"}","raw_base64":null}
{"received_ms":1789987929196,"monotonic_ns":1019370026917900,"raw":"{\"market\":\"0x28a45972fccdaf0fba75dacc59725521035e177d09dd92174f9f52740bccb025\", \"price_changes\":[{\"asset_id\":\"61819828071723399190623735325323968706432622380635304641786792960078828866875\", \"price\":\"0.86\", \"size\":\"3718.17\", \"side\":\"BUY\", \"hash\":\"7d7ffbc9273fd7eb5e82bbfc284e45a5a31e97ee\", \"best_bid\":\"0.86\", \"best_ask\":\"0.87\"}, {\"asset_id\":\"114356653315647913247200886351065428002113119844334520181865067698979836634569\", \"price\":\"0.14\", \"size\":\"3718.17\", \"side\":\"SELL\", \"hash\":\"711b54afda48dfbeccd3281873e71c419450877d\", \"best_bid\":\"0.13\", \"best_ask\":\"0.14\"}], \"timestamp\":\"1789987929175\", \"event_type\":\"price_change\"}","raw_base64":null}
{"received_ms":1789987929197,"monotonic_ns":1019370027624200,"raw":"{\"market\":\"0x28a45972fccdaf0fba75dacc59725521035e177d09dd92174f9f52740bccb025\", \"price_changes\":[{\"asset_id\":\"61819828071723399190623735325323968706432622380635304641786792960078828866875\", \"price\":\"0.85\", \"size\":\"2772.35\", \"side\":\"BUY\", \"hash\":\"bc4a371c0b4de6e0a3379bff04ebaee5d5cd1099\", \"best_bid\":\"0.86\", \"best_ask\":\"0.87\"}, {\"asset_id\":\"114356653315647913247200886351065428002113119844334520181865067698979836634569\", \"price\":\"0.15\", \"size\":\"2772.35\", \"side\":\"SELL\", \"hash\":\"26956f9538d0aa7f342f2e003a2097ca7149e42d\", \"best_bid\":\"0.13\", \"best_ask\":\"0.14\"}], \"timestamp\":\"1789987929176\", \"event_type\":\"price_change\"}","raw_base64":null}
{"received_ms":1789987929202,"monotonic_ns":1019370032861600,"raw":"{\"market\":\"0x28a45972fccdaf0fba75dacc59725521035e177d09dd92174f9f52740bccb025\", \"price_changes\":[{\"asset_id\":\"61819828071723399190623735325323968706432622380635304641786792960078828866875\", \"price\":\"0.79\", \"size\":\"527\", \"side\":\"BUY\", \"hash\":\"d455dff0b1bbeacebc3240e9e752bfda88d508e0\", \"best_bid\":\"0.86\", \"best_ask\":\"0.87\"}, {\"asset_id\":\"114356653315647913247200886351065428002113119844334520181865067698979836634569\", \"price\":\"0.21\", \"size\":\"527\", \"side\":\"SELL\", \"hash\":\"d6c37cec1779598a969d987717be4744f35d92eb\", \"best_bid\":\"0.13\", \"best_ask\":\"0.14\"}], \"timestamp\":\"1789987929180\", \"event_type\":\"price_change\"}","raw_base64":null}
{"received_ms":1789987929203,"monotonic_ns":1019370033904400,"raw":"{\"market\":\"0x28a45972fccdaf0fba75dacc59725521035e177d09dd92174f9f52740bccb025\", \"price_changes\":[{\"asset_id\":\"61819828071723399190623735325323968706432622380635304641786792960078828866875\", \"price\":\"0.8\", \"size\":\"582\", \"side\":\"BUY\", \"hash\":\"40e760f2c2b785e8622e82d8f66db5b9678f7c34\", \"best_bid\":\"0.86\", \"best_ask\":\"0.87\"}, {\"asset_id\":\"114356653315647913247200886351065428002113119844334520181865067698979836634569\", \"price\":\"0.2\", \"size\":\"582\", \"side\":\"SELL\", \"hash\":\"923a471d90f4f0b72665073402faf8fd3755a770\", \"best_bid\":\"0.13\", \"best_ask\":\"0.14\"}], \"timestamp\":\"1789987929181\", \"event_type\":\"price_change\"}","raw_base64":null}
{"received_ms":1789987929207,"monotonic_ns":1019370037701000,"raw":"{\"market\":\"0x28a45972fccdaf0fba75dacc59725521035e177d09dd92174f9f52740bccb025\", \"price_changes\":[{\"asset_id\":\"61819828071723399190623735325323968706432622380635304641786792960078828866875\", \"price\":\"0.79\", \"size\":\"447\", \"side\":\"BUY\", \"hash\":\"7b062d9c23b6b1a5d7aee65a943bbcbca41d1c7c\", \"best_bid\":\"0.86\", \"best_ask\":\"0.87\"}, {\"asset_id\":\"114356653315647913247200886351065428002113119844334520181865067698979836634569\", \"price\":\"0.21\", \"size\":\"447\", \"side\":\"SELL\", \"hash\":\"ebb4157a374b5146e55ec7ee122f14a6b0587329\", \"best_bid\":\"0.13\", \"best_ask\":\"0.14\"}], \"timestamp\":\"1789987929186\", \"event_type\":\"price_change\"}","raw_base64":null}
{"received_ms":1789987929207,"monotonic_ns":1019370037757700,"raw":"{\"market\":\"0x28a45972fccdaf0fba75dacc59725521035e177d09dd92174f9f52740bccb025\", \"price_changes\":[{\"asset_id\":\"61819828071723399190623735325323968706432622380635304641786792960078828866875\", \"price\":\"0.8\", \"size\":\"562\", \"side\":\"BUY\", \"hash\":\"7b062d9c23b6b1a5d7aee65a943bbcbca41d1c7c\", \"best_bid\":\"0.86\", \"best_ask\":\"0.87\"}, {\"asset_id\":\"114356653315647913247200886351065428002113119844334520181865067698979836634569\", \"price\":\"0.2\", \"size\":\"562\", \"side\":\"SELL\", \"hash\":\"ebb4157a374b5146e55ec7ee122f14a6b0587329\", \"best_bid\":\"0.13\", \"best_ask\":\"0.14\"}], \"timestamp\":\"1789987929186\", \"event_type\":\"price_change\"}","raw_base64":null}
{"received_ms":1789987929222,"monotonic_ns":1019370053168300,"raw":"{\"market\":\"0x28a45972fccdaf0fba75dacc59725521035e177d09dd92174f9f52740bccb025\", \"price_changes\":[{\"asset_id\":\"114356653315647913247200886351065428002113119844334520181865067698979836634569\", \"price\":\"0.07\", \"size\":\"6348.71\", \"side\":\"BUY\", \"hash\":\"329c511651e869030a4cb7d1a5a9ab5eaa828290\", \"best_bid\":\"0.13\", \"best_ask\":\"0.14\"}, {\"asset_id\":\"61819828071723399190623735325323968706432622380635304641786792960078828866875\", \"price\":\"0.93\", \"size\":\"6348.71\", \"side\":\"SELL\", \"hash\":\"802b4f3e3fbd998ec2c786a693fc95f83e640a88\", \"best_bid\":\"0.86\", \"best_ask\":\"0.87\"}], \"timestamp\":\"1789987929202\", \"event_type\":\"price_change\"}","raw_base64":null}
{"received_ms":1789987929227,"monotonic_ns":1019370058042800,"raw":"{\"market\":\"0x28a45972fccdaf0fba75dacc59725521035e177d09dd92174f9f52740bccb025\", \"price_changes\":[{\"asset_id\":\"61819828071723399190623735325323968706432622380635304641786792960078828866875\", \"price\":\"0.84\", \"size\":\"3075\", \"side\":\"BUY\", \"hash\":\"2a0443d2aefa9c174e9ae04c77b3fe62ffc227bf\", \"best_bid\":\"0.86\", \"best_ask\":\"0.87\"}, {\"asset_id\":\"114356653315647913247200886351065428002113119844334520181865067698979836634569\", \"price\":\"0.16\", \"size\":\"3075\", \"side\":\"SELL\", \"hash\":\"69ac957585bc35c0c2e79dcc36d5e506d1c68db5\", \"best_bid\":\"0.13\", \"best_ask\":\"0.14\"}], \"timestamp\":\"1789987929206\", \"event_type\":\"price_change\"}","raw_base64":null}
{"received_ms":1789987929229,"monotonic_ns":1019370059690400,"raw":"{\"market\":\"0x28a45972fccdaf0fba75dacc59725521035e177d09dd92174f9f52740bccb025\", \"price_changes\":[{\"asset_id\":\"61819828071723399190623735325323968706432622380635304641786792960078828866875\", \"price\":\"0.85\", \"size\":\"2937.35\", \"side\":\"BUY\", \"hash\":\"d14ec7ea1f7eb3ae187ce4e539d63bd216a21ca0\", \"best_bid\":\"0.86\", \"best_ask\":\"0.87\"}, {\"asset_id\":\"114356653315647913247200886351065428002113119844334520181865067698979836634569\", \"price\":\"0.15\", \"size\":\"2937.35\", \"side\":\"SELL\", \"hash\":\"3791307d1ae8f8fbf1ef21533ec7813ab19ec1a5\", \"best_bid\":\"0.13\", \"best_ask\":\"0.14\"}], \"timestamp\":\"1789987929208\", \"event_type\":\"price_change\"}","raw_base64":null}
{"received_ms":1789987929229,"monotonic_ns":1019370059856600,"raw":"{\"market\":\"0x28a45972fccdaf0fba75dacc59725521035e177d09dd92174f9f52740bccb025\", \"price_changes\":[{\"asset_id\":\"61819828071723399190623735325323968706432622380635304641786792960078828866875\", \"price\":\"0.86\", \"size\":\"4475.17\", \"side\":\"BUY\", \"hash\":\"27a1e6155502b62bfc0146fe787cbb4300670889\", \"best_bid\":\"0.86\", \"best_ask\":\"0.87\"}, {\"asset_id\":\"114356653315647913247200886351065428002113119844334520181865067698979836634569\", \"price\":\"0.14\", \"size\":\"4475.17\", \"side\":\"SELL\", \"hash\":\"b17f4e4982931e54ab16ebd948bfff62312fecbf\", \"best_bid\":\"0.13\", \"best_ask\":\"0.14\"}], \"timestamp\":\"1789987929209\", \"event_type\":\"price_change\"}","raw_base64":null}
{"received_ms":1789987929235,"monotonic_ns":1019370065408400,"raw":"{\"market\":\"0x28a45972fccdaf0fba75dacc59725521035e177d09dd92174f9f52740bccb025\", \"price_changes\":[{\"asset_id\":\"61819828071723399190623735325323968706432622380635304641786792960078828866875\", \"price\":\"0.75\", \"size\":\"520\", \"side\":\"BUY\", \"hash\":\"36190ff4fb4050a0a59bea584ff6dcd6e8e16b61\", \"best_bid\":\"0.86\", \"best_ask\":\"0.87\"}, {\"asset_id\":\"114356653315647913247200886351065428002113119844334520181865067698979836634569\", \"price\":\"0.25\", \"size\":\"520\", \"side\":\"SELL\", \"hash\":\"580ff6df9b805f35c90fef95e960f404a70a3e0e\", \"best_bid\":\"0.13\", \"best_ask\":\"0.14\"}], \"timestamp\":\"1789987929212\", \"event_type\":\"price_change\"}","raw_base64":null}
{"received_ms":1789987929242,"monotonic_ns":1019370072808700,"raw":"{\"market\":\"0x28a45972fccdaf0fba75dacc59725521035e177d09dd92174f9f52740bccb025\", \"price_changes\":[{\"asset_id\":\"61819828071723399190623735325323968706432622380635304641786792960078828866875\", \"price\":\"0.75\", \"size\":\"420\", \"side\":\"BUY\", \"hash\":\"1759f84d1929b49ddf1f742f7dd09c681eab294c\", \"best_bid\":\"0.86\", \"best_ask\":\"0.87\"}, {\"asset_id\":\"114356653315647913247200886351065428002113119844334520181865067698979836634569\", \"price\":\"0.25\", \"size\":\"420\", \"side\":\"SELL\", \"hash\":\"d8c63feef31c2a2965c6d3c6afab69365e779335\", \"best_bid\":\"0.13\", \"best_ask\":\"0.14\"}], \"timestamp\":\"1789987929221\", \"event_type\":\"price_change\"}","raw_base64":null}
{"received_ms":1789987929270,"monotonic_ns":1019370100963600,"raw":"{\"market\":\"0x28a45972fccdaf0fba75dacc59725521035e177d09dd92174f9f52740bccb025\", \"price_changes\":[{\"asset_id\":\"61819828071723399190623735325323968706432622380635304641786792960078828866875\", \"price\":\"0.86\", \"size\":\"4470.17\", \"side\":\"BUY\", \"hash\":\"ac88924af4ce7ff9c3122dbaa96bb2099443896e\", \"best_bid\":\"0.86\", \"best_ask\":\"0.87\"}, {\"asset_id\":\"114356653315647913247200886351065428002113119844334520181865067698979836634569\", \"price\":\"0.14\", \"size\":\"4470.17\", \"side\":\"SELL\", \"hash\":\"871856e679fe67a4fd33d61189528eab4fd3e20d\", \"best_bid\":\"0.13\", \"best_ask\":\"0.14\"}], \"timestamp\":\"1789987929235\", \"event_type\":\"price_change\"}","raw_base64":null}
{"received_ms":1789987929270,"monotonic_ns":1019370101023500,"raw":"{\"market\":\"0x28a45972fccdaf0fba75dacc59725521035e177d09dd92174f9f52740bccb025\", \"price_changes\":[{\"asset_id\":\"61819828071723399190623735325323968706432622380635304641786792960078828866875\", \"price\":\"0.86\", \"size\":\"4460.17\", \"side\":\"BUY\", \"hash\":\"ac1d0f838be9a395f79c6437f5348b7658579689\", \"best_bid\":\"0.86\", \"best_ask\":\"0.87\"}, {\"asset_id\":\"114356653315647913247200886351065428002113119844334520181865067698979836634569\", \"price\":\"0.14\", \"size\":\"4460.17\", \"side\":\"SELL\", \"hash\":\"9ddce22173231c593222289bddf9c83948c5b85c\", \"best_bid\":\"0.13\", \"best_ask\":\"0.14\"}], \"timestamp\":\"1789987929236\", \"event_type\":\"price_change\"}","raw_base64":null}
{"received_ms":1789987929270,"monotonic_ns":1019370101078800,"raw":"{\"market\":\"0x28a45972fccdaf0fba75dacc59725521035e177d09dd92174f9f52740bccb025\", \"price_changes\":[{\"asset_id\":\"61819828071723399190623735325323968706432622380635304641786792960078828866875\", \"price\":\"0.86\", \"size\":\"4445\", \"side\":\"BUY\", \"hash\":\"d25160168433afd9f44cfc8c96fd167c35ca254c\", \"best_bid\":\"0.86\", \"best_ask\":\"0.87\"}, {\"asset_id\":\"114356653315647913247200886351065428002113119844334520181865067698979836634569\", \"price\":\"0.14\", \"size\":\"4445\", \"side\":\"SELL\", \"hash\":\"63b6071c93224b98c3a08702a796e5af307f89d9\", \"best_bid\":\"0.13\", \"best_ask\":\"0.14\"}], \"timestamp\":\"1789987929237\", \"event_type\":\"price_change\"}","raw_base64":null}
{"received_ms":1789987929276,"monotonic_ns":1019370106976700,"raw":"{\"market\":\"0x28a45972fccdaf0fba75dacc59725521035e177d09dd92174f9f52740bccb025\", \"price_changes\":[{\"asset_id\":\"61819828071723399190623735325323968706432622380635304641786792960078828866875\", \"price\":\"0.76\", \"size\":\"434.91\", \"side\":\"BUY\", \"hash\":\"dcff4260fc3a13ec51089ab42d6daa15329411d3\", \"best_bid\":\"0.86\", \"best_ask\":\"0.87\"}, {\"asset_id\":\"114356653315647913247200886351065428002113119844334520181865067698979836634569\", \"price\":\"0.24\", \"size\":\"434.91\", \"side\":\"SELL\", \"hash\":\"beaa0b72c1da2f599512c4d8274ed4b87ad5cc36\", \"best_bid\":\"0.13\", \"best_ask\":\"0.14\"}], \"timestamp\":\"1789987929241\", \"event_type\":\"price_change\"}","raw_base64":null}
{"received_ms":1789987929307,"monotonic_ns":1019370137702800,"raw":"{\"market\":\"0x28a45972fccdaf0fba75dacc59725521035e177d09dd92174f9f52740bccb025\", \"price_changes\":[{\"asset_id\":\"61819828071723399190623735325323968706432622380635304641786792960078828866875\", \"price\":\"0.86\", \"size\":\"3688\", \"side\":\"BUY\", \"hash\":\"e2b0e79ee56defd0f3d282affc0b00d27061299c\", \"best_bid\":\"0.86\", \"best_ask\":\"0.87\"}, {\"asset_id\":\"114356653315647913247200886351065428002113119844334520181865067698979836634569\", \"price\":\"0.14\", \"size\":\"3688\", \"side\":\"SELL\", \"hash\":\"3b6ee7956b9ab468fb38e011991a0c929416e1c7\", \"best_bid\":\"0.13\", \"best_ask\":\"0.14\"}], \"timestamp\":\"1789987929263\", \"event_type\":\"price_change\"}","raw_base64":null}
{"received_ms":1789987929307,"monotonic_ns":1019370137760300,"raw":"{\"market\":\"0x28a45972fccdaf0fba75dacc59725521035e177d09dd92174f9f52740bccb025\", \"price_changes\":[{\"asset_id\":\"114356653315647913247200886351065428002113119844334520181865067698979836634569\", \"price\":\"0.07\", \"size\":\"7234.71\", \"side\":\"BUY\", \"hash\":\"6b01cbc667b1ca2f944f9b2cd648ceb7b5d27694\", \"best_bid\":\"0.13\", \"best_ask\":\"0.14\"}, {\"asset_id\":\"61819828071723399190623735325323968706432622380635304641786792960078828866875\", \"price\":\"0.93\", \"size\":\"7234.71\", \"side\":\"SELL\", \"hash\":\"77bd804910c8628785f171f4dc2b4bbb9bd22a51\", \"best_bid\":\"0.86\", \"best_ask\":\"0.87\"}], \"timestamp\":\"1789987929273\", \"event_type\":\"price_change\"}","raw_base64":null}
{"received_ms":1789987929307,"monotonic_ns":1019370137809000,"raw":"{\"market\":\"0x28a45972fccdaf0fba75dacc59725521035e177d09dd92174f9f52740bccb025\", \"price_changes\":[{\"asset_id\":\"61819828071723399190623735325323968706432622380635304641786792960078828866875\", \"price\":\"0.86\", \"size\":\"3723.17\", \"side\":\"BUY\", \"hash\":\"943bd46147fdb01f8041bbc445288c4a6ea5e60d\", \"best_bid\":\"0.86\", \"best_ask\":\"0.87\"}, {\"asset_id\":\"114356653315647913247200886351065428002113119844334520181865067698979836634569\", \"price\":\"0.14\", \"size\":\"3723.17\", \"side\":\"SELL\", \"hash\":\"154537af8ce4821b97b691d9c5cc27278a4b4030\", \"best_bid\":\"0.13\", \"best_ask\":\"0.14\"}], \"timestamp\":\"1789987929273\", \"event_type\":\"price_change\"}","raw_base64":null}
{"received_ms":1789987929307,"monotonic_ns":1019370137856900,"raw":"{\"market\":\"0x28a45972fccdaf0fba75dacc59725521035e177d09dd92174f9f52740bccb025\", \"price_changes\":[{\"asset_id\":\"114356653315647913247200886351065428002113119844334520181865067698979836634569\", \"price\":\"0.06\", \"size\":\"5298.67\", \"side\":\"BUY\", \"hash\":\"c41dceec04939b79f8b4ead12e8b64d6fca88d55\", \"best_bid\":\"0.13\", \"best_ask\":\"0.14\"}, {\"asset_id\":\"61819828071723399190623735325323968706432622380635304641786792960078828866875\", \"price\":\"0.94\", \"size\":\"5298.67\", \"side\":\"SELL\", \"hash\":\"052156249abd5d5d60e55367b49693fd150db6d6\", \"best_bid\":\"0.86\", \"best_ask\":\"0.87\"}], \"timestamp\":\"1789987929274\", \"event_type\":\"price_change\"}","raw_base64":null}
{"received_ms":1789987929328,"monotonic_ns":1019370159026700,"raw":"{\"market\":\"0x28a45972fccdaf0fba75dacc59725521035e177d09dd92174f9f52740bccb025\", \"price_changes\":[{\"asset_id\":\"61819828071723399190623735325323968706432622380635304641786792960078828866875\", \"price\":\"0.75\", \"size\":\"520\", \"side\":\"BUY\", \"hash\":\"0574e54fc33924674f28b351d102ba028709fbd2\", \"best_bid\":\"0.86\", \"best_ask\":\"0.87\"}, {\"asset_id\":\"114356653315647913247200886351065428002113119844334520181865067698979836634569\", \"price\":\"0.25\", \"size\":\"520\", \"side\":\"SELL\", \"hash\":\"5cd370b719a6d6603fc40b3ae08ba7e00d2fa33a\", \"best_bid\":\"0.13\", \"best_ask\":\"0.14\"}], \"timestamp\":\"1789987929285\", \"event_type\":\"price_change\"}","raw_base64":null}
{"received_ms":1789987929328,"monotonic_ns":1019370159086500,"raw":"{\"market\":\"0x28a45972fccdaf0fba75dacc59725521035e177d09dd92174f9f52740bccb025\", \"price_changes\":[{\"asset_id\":\"61819828071723399190623735325323968706432622380635304641786792960078828866875\", \"price\":\"0.75\", \"size\":\"420\", \"side\":\"BUY\", \"hash\":\"62e1743158885ef8d6d6c713a29d1610f37749cb\", \"best_bid\":\"0.86\", \"best_ask\":\"0.87\"}, {\"asset_id\":\"114356653315647913247200886351065428002113119844334520181865067698979836634569\", \"price\":\"0.25\", \"size\":\"420\", \"side\":\"SELL\", \"hash\":\"9b67e317d47327372160c942a76a4603c1354e32\", \"best_bid\":\"0.13\", \"best_ask\":\"0.14\"}], \"timestamp\":\"1789987929288\", \"event_type\":\"price_change\"}","raw_base64":null}
{"received_ms":1789987929328,"monotonic_ns":1019370159136700,"raw":"{\"market\":\"0x28a45972fccdaf0fba75dacc59725521035e177d09dd92174f9f52740bccb025\", \"price_changes\":[{\"asset_id\":\"61819828071723399190623735325323968706432622380635304641786792960078828866875\", \"price\":\"0.86\", \"size\":\"4207.17\", \"side\":\"BUY\", \"hash\":\"aaa886b75738b108deb81855137b83d7fcb78edb\", \"best_bid\":\"0.86\", \"best_ask\":\"0.87\"}, {\"asset_id\":\"114356653315647913247200886351065428002113119844334520181865067698979836634569\", \"price\":\"0.14\", \"size\":\"4207.17\", \"side\":\"SELL\", \"hash\":\"4a5b1711d16dc41c386d99e137f8862ef853fab3\", \"best_bid\":\"0.13\", \"best_ask\":\"0.14\"}], \"timestamp\":\"1789987929307\", \"event_type\":\"price_change\"}","raw_base64":null}
{"received_ms":1789987929334,"monotonic_ns":1019370164463700,"raw":"{\"market\":\"0x28a45972fccdaf0fba75dacc59725521035e177d09dd92174f9f52740bccb025\", \"price_changes\":[{\"asset_id\":\"114356653315647913247200886351065428002113119844334520181865067698979836634569\", \"price\":\"0.03\", \"size\":\"3992.57\", \"side\":\"BUY\", \"hash\":\"be4828be04e3f6dcfa5964270b89902e4e0f09e3\", \"best_bid\":\"0.13\", \"best_ask\":\"0.14\"}, {\"asset_id\":\"61819828071723399190623735325323968706432622380635304641786792960078828866875\", \"price\":\"0.97\", \"size\":\"3992.57\", \"side\":\"SELL\", \"hash\":\"653d0eaaf2d14ac9420acdbe85a4d1d613ff8d9d\", \"best_bid\":\"0.86\", \"best_ask\":\"0.87\"}], \"timestamp\":\"1789987929313\", \"event_type\":\"price_change\"}","raw_base64":null}
{"received_ms":1789987929355,"monotonic_ns":1019370185692400,"raw":"{\"market\":\"0x28a45972fccdaf0fba75dacc59725521035e177d09dd92174f9f52740bccb025\", \"price_changes\":[{\"asset_id\":\"114356653315647913247200886351065428002113119844334520181865067698979836634569\", \"price\":\"0.11\", \"size\":\"126.1\", \"side\":\"BUY\", \"hash\":\"b7626c81b0a90e0bbb382a9684bde66496556431\", \"best_bid\":\"0.13\", \"best_ask\":\"0.14\"}, {\"asset_id\":\"61819828071723399190623735325323968706432622380635304641786792960078828866875\", \"price\":\"0.89\", \"size\":\"126.1\", \"side\":\"SELL\", \"hash\":\"4b4d759c664ba1f2175351df2175ca7deb6f0593\", \"best_bid\":\"0.86\", \"best_ask\":\"0.87\"}], \"timestamp\":\"1789987929334\", \"event_type\":\"price_change\"}","raw_base64":null}
{"received_ms":1789987929355,"monotonic_ns":1019370185900600,"raw":"{\"market\":\"0x28a45972fccdaf0fba75dacc59725521035e177d09dd92174f9f52740bccb025\", \"price_changes\":[{\"asset_id\":\"114356653315647913247200886351065428002113119844334520181865067698979836634569\", \"price\":\"0.12\", \"size\":\"514.34\", \"side\":\"BUY\", \"hash\":\"0ec946551e620f9f3033396c87b7bcd6c6b3497c\", \"best_bid\":\"0.13\", \"best_ask\":\"0.14\"}, {\"asset_id\":\"61819828071723399190623735325323968706432622380635304641786792960078828866875\", \"price\":\"0.88\", \"size\":\"514.34\", \"side\":\"SELL\", \"hash\":\"ad8fdb78bb5510a475ef14d7f70f283efe80bc57\", \"best_bid\":\"0.86\", \"best_ask\":\"0.87\"}], \"timestamp\":\"1789987929335\", \"event_type\":\"price_change\"}","raw_base64":null}
{"received_ms":1789987929361,"monotonic_ns":1019370191891000,"raw":"{\"market\":\"0x28a45972fccdaf0fba75dacc59725521035e177d09dd92174f9f52740bccb025\", \"price_changes\":[{\"asset_id\":\"114356653315647913247200886351065428002113119844334520181865067698979836634569\", \"price\":\"0.07\", \"size\":\"7344.71\", \"side\":\"BUY\", \"hash\":\"4e0981e9236cd79955232bd57ece6e4b656b3b90\", \"best_bid\":\"0.13\", \"best_ask\":\"0.14\"}, {\"asset_id\":\"61819828071723399190623735325323968706432622380635304641786792960078828866875\", \"price\":\"0.93\", \"size\":\"7344.71\", \"side\":\"SELL\", \"hash\":\"8262918252427407d264917c4da60e92f655fd53\", \"best_bid\":\"0.86\", \"best_ask\":\"0.87\"}], \"timestamp\":\"1789987929339\", \"event_type\":\"price_change\"}","raw_base64":null}
{"received_ms":1789987929361,"monotonic_ns":1019370191948200,"raw":"{\"market\":\"0x28a45972fccdaf0fba75dacc59725521035e177d09dd92174f9f52740bccb025\", \"price_changes\":[{\"asset_id\":\"61819828071723399190623735325323968706432622380635304641786792960078828866875\", \"price\":\"0.86\", \"size\":\"3723.17\", \"side\":\"BUY\", \"hash\":\"3662065d631c7ab84b7d3374d7abf5e208a25ccf\", \"best_bid\":\"0.86\", \"best_ask\":\"0.87\"}, {\"asset_id\":\"114356653315647913247200886351065428002113119844334520181865067698979836634569\", \"price\":\"0.14\", \"size\":\"3723.17\", \"side\":\"SELL\", \"hash\":\"c330139a70ca0ff10c286cced0e3d1e83bc61390\", \"best_bid\":\"0.13\", \"best_ask\":\"0.14\"}], \"timestamp\":\"1789987929340\", \"event_type\":\"price_change\"}","raw_base64":null}
{"received_ms":1789987929361,"monotonic_ns":1019370192094500,"raw":"{\"market\":\"0x28a45972fccdaf0fba75dacc59725521035e177d09dd92174f9f52740bccb025\", \"price_changes\":[{\"asset_id\":\"114356653315647913247200886351065428002113119844334520181865067698979836634569\", \"price\":\"0.06\", \"size\":\"5312.67\", \"side\":\"BUY\", \"hash\":\"891f6779160d013092c581bf779b91494ee381aa\", \"best_bid\":\"0.13\", \"best_ask\":\"0.14\"}, {\"asset_id\":\"61819828071723399190623735325323968706432622380635304641786792960078828866875\", \"price\":\"0.94\", \"size\":\"5312.67\", \"side\":\"SELL\", \"hash\":\"6c208070fa81624e980e1bb9148abebb7142ba12\", \"best_bid\":\"0.86\", \"best_ask\":\"0.87\"}], \"timestamp\":\"1789987929341\", \"event_type\":\"price_change\"}","raw_base64":null}
{"received_ms":1789987929366,"monotonic_ns":1019370196834800,"raw":"{\"market\":\"0x28a45972fccdaf0fba75dacc59725521035e177d09dd92174f9f52740bccb025\", \"price_changes\":[{\"asset_id\":\"114356653315647913247200886351065428002113119844334520181865067698979836634569\", \"price\":\"0.05\", \"size\":\"5635\", \"side\":\"BUY\", \"hash\":\"d1a723b3a08108aaf0291367e11dd944df93be4f\", \"best_bid\":\"0.13\", \"best_ask\":\"0.14\"}, {\"asset_id\":\"61819828071723399190623735325323968706432622380635304641786792960078828866875\", \"price\":\"0.95\", \"size\":\"5635\", \"side\":\"SELL\", \"hash\":\"3a3621fe070d44280f5e7fd36f4794d105201794\", \"best_bid\":\"0.86\", \"best_ask\":\"0.87\"}], \"timestamp\":\"1789987929345\", \"event_type\":\"price_change\"}","raw_base64":null}
{"received_ms":1789987929377,"monotonic_ns":1019370207901400,"raw":"{\"market\":\"0x28a45972fccdaf0fba75dacc59725521035e177d09dd92174f9f52740bccb025\", \"price_changes\":[{\"asset_id\":\"61819828071723399190623735325323968706432622380635304641786792960078828866875\", \"price\":\"0.75\", \"size\":\"520\", \"side\":\"BUY\", \"hash\":\"eadb65bbf5479c7b0637f238ecc499950aa4ecbd\", \"best_bid\":\"0.86\", \"best_ask\":\"0.87\"}, {\"asset_id\":\"114356653315647913247200886351065428002113119844334520181865067698979836634569\", \"price\":\"0.25\", \"size\":\"520\", \"side\":\"SELL\", \"hash\":\"e977d749f102c2222d5cae5bf2f3d3666cd71486\", \"best_bid\":\"0.13\", \"best_ask\":\"0.14\"}], \"timestamp\":\"1789987929355\", \"event_type\":\"price_change\"}","raw_base64":null}
{"received_ms":1789987929383,"monotonic_ns":1019370213460100,"raw":"{\"market\":\"0x28a45972fccdaf0fba75dacc59725521035e177d09dd92174f9f52740bccb025\", \"price_changes\":[{\"asset_id\":\"61819828071723399190623735325323968706432622380635304641786792960078828866875\", \"price\":\"0.75\", \"size\":\"420\", \"side\":\"BUY\", \"hash\":\"b572f6e11c97a07c1cea87bf972de3187bcb8b55\", \"best_bid\":\"0.86\", \"best_ask\":\"0.87\"}, {\"asset_id\":\"114356653315647913247200886351065428002113119844334520181865067698979836634569\", \"price\":\"0.25\", \"size\":\"420\", \"side\":\"SELL\", \"hash\":\"aad30863796e2af8dbd1d7f7ba905de95f238116\", \"best_bid\":\"0.13\", \"best_ask\":\"0.14\"}], \"timestamp\":\"1789987929362\", \"event_type\":\"price_change\"}","raw_base64":null}
{"received_ms":1789987929390,"monotonic_ns":1019370220754400,"raw":"{\"market\":\"0x28a45972fccdaf0fba75dacc59725521035e177d09dd92174f9f52740bccb025\", \"price_changes\":[{\"asset_id\":\"61819828071723399190623735325323968706432622380635304641786792960078828866875\", \"price\":\"0.86\", \"size\":\"4061.17\", \"side\":\"BUY\", \"hash\":\"973f55dc0bd7002c5d05d5490367efe9bb1a7b8e\", \"best_bid\":\"0.86\", \"best_ask\":\"0.87\"}, {\"asset_id\":\"114356653315647913247200886351065428002113119844334520181865067698979836634569\", \"price\":\"0.14\", \"size\":\"4061.17\", \"side\":\"SELL\", \"hash\":\"626d0b8556002ea3910dc9a12697d1a17956c8c6\", \"best_bid\":\"0.13\", \"best_ask\":\"0.14\"}], \"timestamp\":\"1789987929370\", \"event_type\":\"price_change\"}","raw_base64":null}
{"received_ms":1789987929391,"monotonic_ns":1019370221476100,"raw":"{\"market\":\"0x28a45972fccdaf0fba75dacc59725521035e177d09dd92174f9f52740bccb025\", \"price_changes\":[{\"asset_id\":\"114356653315647913247200886351065428002113119844334520181865067698979836634569\", \"price\":\"0.07\", \"size\":\"7779.71\", \"side\":\"BUY\", \"hash\":\"9bcc8bbb4a70077f4b79fb004acaea1baaac8ce6\", \"best_bid\":\"0.13\", \"best_ask\":\"0.14\"}, {\"asset_id\":\"61819828071723399190623735325323968706432622380635304641786792960078828866875\", \"price\":\"0.93\", \"size\":\"7779.71\", \"side\":\"SELL\", \"hash\":\"bbb40ed6ce15acdf087b9d175470dc0f6914a8d6\", \"best_bid\":\"0.86\", \"best_ask\":\"0.87\"}], \"timestamp\":\"1789987929371\", \"event_type\":\"price_change\"}","raw_base64":null}
{"received_ms":1789987929392,"monotonic_ns":1019370223029400,"raw":"{\"market\":\"0x28a45972fccdaf0fba75dacc59725521035e177d09dd92174f9f52740bccb025\", \"price_changes\":[{\"asset_id\":\"61819828071723399190623735325323968706432622380635304641786792960078828866875\", \"price\":\"0.85\", \"size\":\"2942.35\", \"side\":\"BUY\", \"hash\":\"c5b74cff51134e7aa1df1b8d9178640e8a02165f\", \"best_bid\":\"0.86\", \"best_ask\":\"0.87\"}, {\"asset_id\":\"114356653315647913247200886351065428002113119844334520181865067698979836634569\", \"price\":\"0.15\", \"size\":\"2942.35\", \"side\":\"SELL\", \"hash\":\"552a092660145feac211d088daf1a70f98b0bc9a\", \"best_bid\":\"0.13\", \"best_ask\":\"0.14\"}], \"timestamp\":\"1789987929371\", \"event_type\":\"price_change\"}","raw_base64":null}
{"received_ms":1789987929416,"monotonic_ns":1019370246441100,"raw":"{\"market\":\"0x28a45972fccdaf0fba75dacc59725521035e177d09dd92174f9f52740bccb025\", \"price_changes\":[{\"asset_id\":\"61819828071723399190623735325323968706432622380635304641786792960078828866875\", \"price\":\"0.79\", \"size\":\"527\", \"side\":\"BUY\", \"hash\":\"6354c16dbc3516c87c1c9507decf0f15f031c30c\", \"best_bid\":\"0.86\", \"best_ask\":\"0.87\"}, {\"asset_id\":\"114356653315647913247200886351065428002113119844334520181865067698979836634569\", \"price\":\"0.21\", \"size\":\"527\", \"side\":\"SELL\", \"hash\":\"86583963702da4643b9adcb9676a73cb770391e6\", \"best_bid\":\"0.13\", \"best_ask\":\"0.14\"}], \"timestamp\":\"1789987929395\", \"event_type\":\"price_change\"}","raw_base64":null}
{"received_ms":1789987929416,"monotonic_ns":1019370246860200,"raw":"{\"market\":\"0x28a45972fccdaf0fba75dacc59725521035e177d09dd92174f9f52740bccb025\", \"price_changes\":[{\"asset_id\":\"61819828071723399190623735325323968706432622380635304641786792960078828866875\", \"price\":\"0.8\", \"size\":\"582\", \"side\":\"BUY\", \"hash\":\"b690a4e6e0be2dc4578c8ab3ac3f8aea71fe5327\", \"best_bid\":\"0.86\", \"best_ask\":\"0.87\"}, {\"asset_id\":\"114356653315647913247200886351065428002113119844334520181865067698979836634569\", \"price\":\"0.2\", \"size\":\"582\", \"side\":\"SELL\", \"hash\":\"db29370932e6bb550f226a58c8dae091a23fb8ad\", \"best_bid\":\"0.13\", \"best_ask\":\"0.14\"}], \"timestamp\":\"1789987929396\", \"event_type\":\"price_change\"}","raw_base64":null}
{"received_ms":1789987929416,"monotonic_ns":1019370246924000,"raw":"{\"market\":\"0x28a45972fccdaf0fba75dacc59725521035e177d09dd92174f9f52740bccb025\", \"price_changes\":[{\"asset_id\":\"61819828071723399190623735325323968706432622380635304641786792960078828866875\", \"price\":\"0.79\", \"size\":\"447\", \"side\":\"BUY\", \"hash\":\"ef2fd516b541f1c105702c07f9a0d76bae6add4f\", \"best_bid\":\"0.86\", \"best_ask\":\"0.87\"}, {\"asset_id\":\"114356653315647913247200886351065428002113119844334520181865067698979836634569\", \"price\":\"0.21\", \"size\":\"447\", \"side\":\"SELL\", \"hash\":\"412e2ac22e2175898f863f83cc96e8b5e5c87a81\", \"best_bid\":\"0.13\", \"best_ask\":\"0.14\"}], \"timestamp\":\"1789987929396\", \"event_type\":\"price_change\"}","raw_base64":null}
{"received_ms":1789987929416,"monotonic_ns":1019370246969000,"raw":"{\"market\":\"0x28a45972fccdaf0fba75dacc59725521035e177d09dd92174f9f52740bccb025\", \"price_changes\":[{\"asset_id\":\"61819828071723399190623735325323968706432622380635304641786792960078828866875\", \"price\":\"0.8\", \"size\":\"562\", \"side\":\"BUY\", \"hash\":\"ef2fd516b541f1c105702c07f9a0d76bae6add4f\", \"best_bid\":\"0.86\", \"best_ask\":\"0.87\"}, {\"asset_id\":\"114356653315647913247200886351065428002113119844334520181865067698979836634569\", \"price\":\"0.2\", \"size\":\"562\", \"side\":\"SELL\", \"hash\":\"412e2ac22e2175898f863f83cc96e8b5e5c87a81\", \"best_bid\":\"0.13\", \"best_ask\":\"0.14\"}], \"timestamp\":\"1789987929396\", \"event_type\":\"price_change\"}","raw_base64":null}
{"received_ms":1789987929420,"monotonic_ns":1019370250467200,"raw":"{\"market\":\"0x28a45972fccdaf0fba75dacc59725521035e177d09dd92174f9f52740bccb025\", \"price_changes\":[{\"asset_id\":\"114356653315647913247200886351065428002113119844334520181865067698979836634569\", \"price\":\"0.07\", \"size\":\"7841.71\", \"side\":\"BUY\", \"hash\":\"329969affe6739cf543a081fbf9c7e1a1c63ac4d\", \"best_bid\":\"0.13\", \"best_ask\":\"0.14\"}, {\"asset_id\":\"61819828071723399190623735325323968706432622380635304641786792960078828866875\", \"price\":\"0.93\", \"size\":\"7841.71\", \"side\":\"SELL\", \"hash\":\"ef58e7f7381f99d005e9baa99755e33c42bd005c\", \"best_bid\":\"0.86\", \"best_ask\":\"0.87\"}], \"timestamp\":\"1789987929399\", \"event_type\":\"price_change\"}","raw_base64":null}
{"received_ms":1789987929431,"monotonic_ns":1019370261713200,"raw":"{\"market\":\"0x28a45972fccdaf0fba75dacc59725521035e177d09dd92174f9f52740bccb025\", \"price_changes\":[{\"asset_id\":\"61819828071723399190623735325323968706432622380635304641786792960078828866875\", \"price\":\"0.86\", \"size\":\"4066.17\", \"side\":\"BUY\", \"hash\":\"844bc2196098b14c5d8c6124fc86b98225ab9a6f\", \"best_bid\":\"0.86\", \"best_ask\":\"0.87\"}, {\"asset_id\":\"114356653315647913247200886351065428002113119844334520181865067698979836634569\", \"price\":\"0.14\", \"size\":\"4066.17\", \"side\":\"SELL\", \"hash\":\"01dffbadc9f5deda302264a4136a268b2a0563ea\", \"best_bid\":\"0.13\", \"best_ask\":\"0.14\"}], \"timestamp\":\"1789987929410\", \"event_type\":\"price_change\"}","raw_base64":null}
{"received_ms":1789987929432,"monotonic_ns":1019370262462100,"raw":"{\"market\":\"0x28a45972fccdaf0fba75dacc59725521035e177d09dd92174f9f52740bccb025\", \"price_changes\":[{\"asset_id\":\"114356653315647913247200886351065428002113119844334520181865067698979836634569\", \"price\":\"0.05\", \"size\":\"5615\", \"side\":\"BUY\", \"hash\":\"755cbde66a260ae7df0a4f4fd22da016a50e311a\", \"best_bid\":\"0.13\", \"best_ask\":\"0.14\"}, {\"asset_id\":\"61819828071723399190623735325323968706432622380635304641786792960078828866875\", \"price\":\"0.95\", \"size\":\"5615\", \"side\":\"SELL\", \"hash\":\"8f88c8efb871fb383413122996737e8641d1d98e\", \"best_bid\":\"0.86\", \"best_ask\":\"0.87\"}], \"timestamp\":\"1789987929412\", \"event_type\":\"price_change\"}","raw_base64":null}
{"received_ms":1789987929453,"monotonic_ns":1019370283654800,"raw":"{\"market\":\"0x28a45972fccdaf0fba75dacc59725521035e177d09dd92174f9f52740bccb025\", \"price_changes\":[{\"asset_id\":\"61819828071723399190623735325323968706432622380635304641786792960078828866875\", \"price\":\"0.94\", \"size\":\"5282.67\", \"side\":\"SELL\", \"hash\":\"174bace6e542598a1363cc5906e393bb87541111\", \"best_bid\":\"0.86\", \"best_ask\":\"0.87\"}, {\"asset_id\":\"114356653315647913247200886351065428002113119844334520181865067698979836634569\", \"price\":\"0.06\", \"size\":\"5282.67\", \"side\":\"BUY\", \"hash\":\"399c658a892673cc1d92223b5de50aa44cb37923\", \"best_bid\":\"0.13\", \"best_ask\":\"0.14\"}], \"timestamp\":\"1789987929433\", \"event_type\":\"price_change\"}","raw_base64":null}
{"received_ms":1789987929462,"monotonic_ns":1019370293002200,"raw":"{\"market\":\"0x28a45972fccdaf0fba75dacc59725521035e177d09dd92174f9f52740bccb025\", \"price_changes\":[{\"asset_id\":\"114356653315647913247200886351065428002113119844334520181865067698979836634569\", \"price\":\"0.05\", \"size\":\"5635\", \"side\":\"BUY\", \"hash\":\"0a400433d188c68def6320b58a7a9e57e8faa34a\", \"best_bid\":\"0.13\", \"best_ask\":\"0.14\"}, {\"asset_id\":\"61819828071723399190623735325323968706432622380635304641786792960078828866875\", \"price\":\"0.95\", \"size\":\"5635\", \"side\":\"SELL\", \"hash\":\"def9ca21f35513b85005a8b7144a6a646ec62922\", \"best_bid\":\"0.86\", \"best_ask\":\"0.87\"}], \"timestamp\":\"1789987929440\", \"event_type\":\"price_change\"}","raw_base64":null}
{"received_ms":1789987929463,"monotonic_ns":1019370293608600,"raw":"{\"market\":\"0x28a45972fccdaf0fba75dacc59725521035e177d09dd92174f9f52740bccb025\", \"price_changes\":[{\"asset_id\":\"114356653315647913247200886351065428002113119844334520181865067698979836634569\", \"price\":\"0.12\", \"size\":\"519.34\", \"side\":\"BUY\", \"hash\":\"aa8a180594c47dcafb4131af6c921f98d62bccb7\", \"best_bid\":\"0.13\", \"best_ask\":\"0.14\"}, {\"asset_id\":\"61819828071723399190623735325323968706432622380635304641786792960078828866875\", \"price\":\"0.88\", \"size\":\"519.34\", \"side\":\"SELL\", \"hash\":\"790ba319f94dcf28e092fbee7b41b99841ee7d89\", \"best_bid\":\"0.86\", \"best_ask\":\"0.87\"}], \"timestamp\":\"1789987929442\", \"event_type\":\"price_change\"}","raw_base64":null}
{"received_ms":1789987929466,"monotonic_ns":1019370296851500,"raw":"{\"market\":\"0x28a45972fccdaf0fba75dacc59725521035e177d09dd92174f9f52740bccb025\", \"price_changes\":[{\"asset_id\":\"114356653315647913247200886351065428002113119844334520181865067698979836634569\", \"price\":\"0.07\", \"size\":\"7234.71\", \"side\":\"BUY\", \"hash\":\"ced82da302b53dd3d6bf7aedae2c2ac8956cdd2b\", \"best_bid\":\"0.13\", \"best_ask\":\"0.14\"}, {\"asset_id\":\"61819828071723399190623735325323968706432622380635304641786792960078828866875\", \"price\":\"0.93\", \"size\":\"7234.71\", \"side\":\"SELL\", \"hash\":\"a460415bddf5d0ee18abef68c01c7426a0e19847\", \"best_bid\":\"0.86\", \"best_ask\":\"0.87\"}], \"timestamp\":\"1789987929446\", \"event_type\":\"price_change\"}","raw_base64":null}
{"received_ms":1789987929472,"monotonic_ns":1019370302828900,"raw":"{\"market\":\"0x28a45972fccdaf0fba75dacc59725521035e177d09dd92174f9f52740bccb025\", \"price_changes\":[{\"asset_id\":\"61819828071723399190623735325323968706432622380635304641786792960078828866875\", \"price\":\"0.85\", \"size\":\"2937.35\", \"side\":\"BUY\", \"hash\":\"b4d3c1219ca89169a76c8ae1111b41a06c609644\", \"best_bid\":\"0.86\", \"best_ask\":\"0.87\"}, {\"asset_id\":\"114356653315647913247200886351065428002113119844334520181865067698979836634569\", \"price\":\"0.15\", \"size\":\"2937.35\", \"side\":\"SELL\", \"hash\":\"0c44f3973da79d2a0f752f81725676a785051a54\", \"best_bid\":\"0.13\", \"best_ask\":\"0.14\"}], \"timestamp\":\"1789987929451\", \"event_type\":\"price_change\"}","raw_base64":null}
{"received_ms":1789987929472,"monotonic_ns":1019370302895600,"raw":"{\"market\":\"0x28a45972fccdaf0fba75dacc59725521035e177d09dd92174f9f52740bccb025\", \"price_changes\":[{\"asset_id\":\"114356653315647913247200886351065428002113119844334520181865067698979836634569\", \"price\":\"0.07\", \"size\":\"6348.71\", \"side\":\"BUY\", \"hash\":\"9fc924a1327f651fdf7916fb1bca00f357248c16\", \"best_bid\":\"0.13\", \"best_ask\":\"0.14\"}, {\"asset_id\":\"61819828071723399190623735325323968706432622380635304641786792960078828866875\", \"price\":\"0.93\", \"size\":\"6348.71\", \"side\":\"SELL\", \"hash\":\"0ee11ded1443eb08069b84b69874aa080ed55f13\", \"best_bid\":\"0.86\", \"best_ask\":\"0.87\"}], \"timestamp\":\"1789987929451\", \"event_type\":\"price_change\"}","raw_base64":null}
{"received_ms":1789987929472,"monotonic_ns":1019370303218300,"raw":"{\"market\":\"0x28a45972fccdaf0fba75dacc59725521035e177d09dd92174f9f52740bccb025\", \"price_changes\":[{\"asset_id\":\"61819828071723399190623735325323968706432622380635304641786792960078828866875\", \"price\":\"0.85\", \"size\":\"2772.35\", \"side\":\"BUY\", \"hash\":\"623209e7721e6a3bb5428853d85832486eeadcbc\", \"best_bid\":\"0.86\", \"best_ask\":\"0.87\"}, {\"asset_id\":\"114356653315647913247200886351065428002113119844334520181865067698979836634569\", \"price\":\"0.15\", \"size\":\"2772.35\", \"side\":\"SELL\", \"hash\":\"b95704368ffb4bad72120bb66db82355a8df4c3d\", \"best_bid\":\"0.13\", \"best_ask\":\"0.14\"}], \"timestamp\":\"1789987929452\", \"event_type\":\"price_change\"}","raw_base64":null}
{"received_ms":1789987929476,"monotonic_ns":1019370306787500,"raw":"{\"market\":\"0x28a45972fccdaf0fba75dacc59725521035e177d09dd92174f9f52740bccb025\", \"price_changes\":[{\"asset_id\":\"61819828071723399190623735325323968706432622380635304641786792960078828866875\", \"price\":\"0.86\", \"size\":\"3728.17\", \"side\":\"BUY\", \"hash\":\"293b26ec93c8f70b056d72a3fbce3ae8fe4fed00\", \"best_bid\":\"0.86\", \"best_ask\":\"0.87\"}, {\"asset_id\":\"114356653315647913247200886351065428002113119844334520181865067698979836634569\", \"price\":\"0.14\", \"size\":\"3728.17\", \"side\":\"SELL\", \"hash\":\"8d06ea35cf427276874fe768fc761c009cfc5868\", \"best_bid\":\"0.13\", \"best_ask\":\"0.14\"}], \"timestamp\":\"1789987929456\", \"event_type\":\"price_change\"}","raw_base64":null}
{"received_ms":1789987929487,"monotonic_ns":1019370317755200,"raw":"{\"market\":\"0x28a45972fccdaf0fba75dacc59725521035e177d09dd92174f9f52740bccb025\", \"price_changes\":[{\"asset_id\":\"61819828071723399190623735325323968706432622380635304641786792960078828866875\", \"price\":\"0.01\", \"size\":\"1496.91\", \"side\":\"BUY\", \"hash\":\"1804f6c523f34def5106b3f5aa4be19d0c9d6d50\", \"best_bid\":\"0.86\", \"best_ask\":\"0.87\"}, {\"asset_id\":\"114356653315647913247200886351065428002113119844334520181865067698979836634569\", \"price\":\"0.99\", \"size\":\"1496.91\", \"side\":\"SELL\", \"hash\":\"f4075f3d3ebdc3c0140b2aa7499ced4260118a1d\", \"best_bid\":\"0.13\", \"best_ask\":\"0.14\"}], \"timestamp\":\"1789987929467\", \"event_type\":\"price_change\"}","raw_base64":null}
{"received_ms":1789987929502,"monotonic_ns":1019370332301300,"raw":"{\"market\":\"0x28a45972fccdaf0fba75dacc59725521035e177d09dd92174f9f52740bccb025\", \"price_changes\":[{\"asset_id\":\"114356653315647913247200886351065428002113119844334520181865067698979836634569\", \"price\":\"0.07\", \"size\":\"6913.71\", \"side\":\"BUY\", \"hash\":\"82d1de1ce8f888e2768c8ae562889fac8e7db30d\", \"best_bid\":\"0.13\", \"best_ask\":\"0.14\"}, {\"asset_id\":\"61819828071723399190623735325323968706432622380635304641786792960078828866875\", \"price\":\"0.93\", \"size\":\"6913.71\", \"side\":\"SELL\", \"hash\":\"ee768b885d881665ee0cebe74478f562781d05c5\", \"best_bid\":\"0.86\", \"best_ask\":\"0.87\"}], \"timestamp\":\"1789987929480\", \"event_type\":\"price_change\"}","raw_base64":null}
{"received_ms":1789987929512,"monotonic_ns":1019370343047100,"raw":"{\"market\":\"0x28a45972fccdaf0fba75dacc59725521035e177d09dd92174f9f52740bccb025\", \"price_changes\":[{\"asset_id\":\"61819828071723399190623735325323968706432622380635304641786792960078828866875\", \"price\":\"0.86\", \"size\":\"3733.17\", \"side\":\"BUY\", \"hash\":\"a55dd68875b5009e328dda4e1bb7c5e3e779d18d\", \"best_bid\":\"0.86\", \"best_ask\":\"0.87\"}, {\"asset_id\":\"114356653315647913247200886351065428002113119844334520181865067698979836634569\", \"price\":\"0.14\", \"size\":\"3733.17\", \"side\":\"SELL\", \"hash\":\"ee0fb104cb7481e72477d3c9c5b1faa9f8642bd4\", \"best_bid\":\"0.13\", \"best_ask\":\"0.14\"}], \"timestamp\":\"1789987929489\", \"event_type\":\"price_change\"}","raw_base64":null}
{"received_ms":1789987929516,"monotonic_ns":1019370346741800,"raw":"{\"market\":\"0x28a45972fccdaf0fba75dacc59725521035e177d09dd92174f9f52740bccb025\", \"price_changes\":[{\"asset_id\":\"114356653315647913247200886351065428002113119844334520181865067698979836634569\", \"price\":\"0.05\", \"size\":\"5615\", \"side\":\"BUY\", \"hash\":\"fcd4c2633870d972afd1ae0cc799ff3e4d6be5a1\", \"best_bid\":\"0.13\", \"best_ask\":\"0.14\"}, {\"asset_id\":\"61819828071723399190623735325323968706432622380635304641786792960078828866875\", \"price\":\"0.95\", \"size\":\"5615\", \"side\":\"SELL\", \"hash\":\"16e1e0e1034a627ac3d9d9aa0cba4248cf7caf4b\", \"best_bid\":\"0.86\", \"best_ask\":\"0.87\"}], \"timestamp\":\"1789987929494\", \"event_type\":\"price_change\"}","raw_base64":null}
{"received_ms":1789987929516,"monotonic_ns":1019370346845400,"raw":"{\"market\":\"0x28a45972fccdaf0fba75dacc59725521035e177d09dd92174f9f52740bccb025\", \"price_changes\":[{\"asset_id\":\"114356653315647913247200886351065428002113119844334520181865067698979836634569\", \"price\":\"0.06\", \"size\":\"5332.67\", \"side\":\"BUY\", \"hash\":\"92cf881d87b486457809399c822e7a6a5c7cc172\", \"best_bid\":\"0.13\", \"best_ask\":\"0.14\"}, {\"asset_id\":\"61819828071723399190623735325323968706432622380635304641786792960078828866875\", \"price\":\"0.94\", \"size\":\"5332.67\", \"side\":\"SELL\", \"hash\":\"7eb7c4c12bc8b5f41c8859d7ec53dcf341e4b963\", \"best_bid\":\"0.86\", \"best_ask\":\"0.87\"}], \"timestamp\":\"1789987929494\", \"event_type\":\"price_change\"}","raw_base64":null}
{"received_ms":1789987929522,"monotonic_ns":1019370352523600,"raw":"{\"market\":\"0x28a45972fccdaf0fba75dacc59725521035e177d09dd92174f9f52740bccb025\", \"price_changes\":[{\"asset_id\":\"61819828071723399190623735325323968706432622380635304641786792960078828866875\", \"price\":\"0.94\", \"size\":\"5362.67\", \"side\":\"SELL\", \"hash\":\"034ffe3542d9411d203cbb3b0393e22f388c9b03\", \"best_bid\":\"0.86\", \"best_ask\":\"0.87\"}, {\"asset_id\":\"114356653315647913247200886351065428002113119844334520181865067698979836634569\", \"price\":\"0.06\", \"size\":\"5362.67\", \"side\":\"BUY\", \"hash\":\"9c9fbd47bfd426e359df31f5821524957393bbc9\", \"best_bid\":\"0.13\", \"best_ask\":\"0.14\"}], \"timestamp\":\"1789987929500\", \"event_type\":\"price_change\"}","raw_base64":null}
{"received_ms":1789987929525,"monotonic_ns":1019370355492300,"raw":"{\"market\":\"0x28a45972fccdaf0fba75dacc59725521035e177d09dd92174f9f52740bccb025\", \"price_changes\":[{\"asset_id\":\"61819828071723399190623735325323968706432622380635304641786792960078828866875\", \"price\":\"0.75\", \"size\":\"520\", \"side\":\"BUY\", \"hash\":\"fe9ad622bc56347f74ec1b1f0fd91baa4a21d23a\", \"best_bid\":\"0.86\", \"best_ask\":\"0.87\"}, {\"asset_id\":\"114356653315647913247200886351065428002113119844334520181865067698979836634569\", \"price\":\"0.25\", \"size\":\"520\", \"side\":\"SELL\", \"hash\":\"c48298af3e1a92f5d9c87d9a5c2845e2539db192\", \"best_bid\":\"0.13\", \"best_ask\":\"0.14\"}], \"timestamp\":\"1789987929503\", \"event_type\":\"price_change\"}","raw_base64":null}
{"received_ms":1789987929526,"monotonic_ns":1019370356691800,"raw":"{\"market\":\"0x28a45972fccdaf0fba75dacc59725521035e177d09dd92174f9f52740bccb025\", \"price_changes\":[{\"asset_id\":\"61819828071723399190623735325323968706432622380635304641786792960078828866875\", \"price\":\"0.75\", \"size\":\"420\", \"side\":\"BUY\", \"hash\":\"5e503d39d6825e960cfd99e98f6fc388e07b06ba\", \"best_bid\":\"0.86\", \"best_ask\":\"0.87\"}, {\"asset_id\":\"114356653315647913247200886351065428002113119844334520181865067698979836634569\", \"price\":\"0.25\", \"size\":\"420\", \"side\":\"SELL\", \"hash\":\"91b23a9376054e76dcf26029eccb999b95776163\", \"best_bid\":\"0.13\", \"best_ask\":\"0.14\"}], \"timestamp\":\"1789987929506\", \"event_type\":\"price_change\"}","raw_base64":null}
{"received_ms":1789987929527,"monotonic_ns":1019370358142400,"raw":"{\"market\":\"0x28a45972fccdaf0fba75dacc59725521035e177d09dd92174f9f52740bccb025\", \"price_changes\":[{\"asset_id\":\"61819828071723399190623735325323968706432622380635304641786792960078828866875\", \"price\":\"0.01\", \"size\":\"1491.91\", \"side\":\"BUY\", \"hash\":\"c58ef43ca19559b19c5bd75b647777757605a9d9\", \"best_bid\":\"0.86\", \"best_ask\":\"0.87\"}, {\"asset_id\":\"114356653315647913247200886351065428002113119844334520181865067698979836634569\", \"price\":\"0.99\", \"size\":\"1491.91\", \"side\":\"SELL\", \"hash\":\"9fe475e26014b8475aa1d6705362443d286ee6fe\", \"best_bid\":\"0.13\", \"best_ask\":\"0.14\"}], \"timestamp\":\"1789987929506\", \"event_type\":\"price_change\"}","raw_base64":null}
{"received_ms":1789987929533,"monotonic_ns":1019370363967100,"raw":"{\"market\":\"0x28a45972fccdaf0fba75dacc59725521035e177d09dd92174f9f52740bccb025\", \"price_changes\":[{\"asset_id\":\"114356653315647913247200886351065428002113119844334520181865067698979836634569\", \"price\":\"0.07\", \"size\":\"7799.71\", \"side\":\"BUY\", \"hash\":\"dfdb60aa3c7b28872b6e8810ae02af2c46de2a4e\", \"best_bid\":\"0.13\", \"best_ask\":\"0.14\"}, {\"asset_id\":\"61819828071723399190623735325323968706432622380635304641786792960078828866875\", \"price\":\"0.93\", \"size\":\"7799.71\", \"side\":\"SELL\", \"hash\":\"aae4820ff310fcf7aea84e35fd989b5244033611\", \"best_bid\":\"0.86\", \"best_ask\":\"0.87\"}], \"timestamp\":\"1789987929513\", \"event_type\":\"price_change\"}","raw_base64":null}
{"received_ms":1789987929534,"monotonic_ns":1019370364382600,"raw":"{\"market\":\"0x28a45972fccdaf0fba75dacc59725521035e177d09dd92174f9f52740bccb025\", \"price_changes\":[{\"asset_id\":\"61819828071723399190623735325323968706432622380635304641786792960078828866875\", \"price\":\"0.86\", \"size\":\"3941.17\", \"side\":\"BUY\", \"hash\":\"88da5ad10de0b7dd028252025bec5546a8a9cb7d\", \"best_bid\":\"0.86\", \"best_ask\":\"0.87\"}, {\"asset_id\":\"114356653315647913247200886351065428002113119844334520181865067698979836634569\", \"price\":\"0.14\", \"size\":\"3941.17\", \"side\":\"SELL\", \"hash\":\"822b83488106e6840b58e8892d8740256e1ba425\", \"best_bid\":\"0.13\", \"best_ask\":\"0.14\"}], \"timestamp\":\"1789987929513\", \"event_type\":\"price_change\"}","raw_base64":null}
{"received_ms":1789987929534,"monotonic_ns":1019370364675000,"raw":"{\"market\":\"0x28a45972fccdaf0fba75dacc59725521035e177d09dd92174f9f52740bccb025\", \"price_changes\":[{\"asset_id\":\"61819828071723399190623735325323968706432622380635304641786792960078828866875\", \"price\":\"0.85\", \"size\":\"2777.35\", \"side\":\"BUY\", \"hash\":\"933576e7f57117ada65e1d9805b1796f5057d9a0\", \"best_bid\":\"0.86\", \"best_ask\":\"0.87\"}, {\"asset_id\":\"114356653315647913247200886351065428002113119844334520181865067698979836634569\", \"price\":\"0.15\", \"size\":\"2777.35\", \"side\":\"SELL\", \"hash\":\"13d5bc0c7d1ca2008926cb02e7d58d668f213d4d\", \"best_bid\":\"0.13\", \"best_ask\":\"0.14\"}], \"timestamp\":\"1789987929514\", \"event_type\":\"price_change\"}","raw_base64":null}
{"received_ms":1789987929538,"monotonic_ns":1019370368803200,"raw":"{\"market\":\"0x28a45972fccdaf0fba75dacc59725521035e177d09dd92174f9f52740bccb025\", \"price_changes\":[{\"asset_id\":\"61819828071723399190623735325323968706432622380635304641786792960078828866875\", \"price\":\"0.86\", \"size\":\"3951.17\", \"side\":\"BUY\", \"hash\":\"057c09ef83aa52d8a4445d239ca32d1b9007ec2b\", \"best_bid\":\"0.86\", \"best_ask\":\"0.87\"}, {\"asset_id\":\"114356653315647913247200886351065428002113119844334520181865067698979836634569\", \"price\":\"0.14\", \"size\":\"3951.17\", \"side\":\"SELL\", \"hash\":\"17be541379ea044737e4121d35c1bdc55822e054\", \"best_bid\":\"0.13\", \"best_ask\":\"0.14\"}], \"timestamp\":\"1789987929517\", \"event_type\":\"price_change\"}","raw_base64":null}
{"received_ms":1789987929539,"monotonic_ns":1019370369962300,"raw":"{\"market\":\"0x28a45972fccdaf0fba75dacc59725521035e177d09dd92174f9f52740bccb025\", \"price_changes\":[{\"asset_id\":\"61819828071723399190623735325323968706432622380635304641786792960078828866875\", \"price\":\"0.86\", \"size\":\"3916\", \"side\":\"BUY\", \"hash\":\"c1669c9eefa237e9d77dabe65d5966aea776fb97\", \"best_bid\":\"0.86\", \"best_ask\":\"0.87\"}, {\"asset_id\":\"114356653315647913247200886351065428002113119844334520181865067698979836634569\", \"price\":\"0.14\", \"size\":\"3916\", \"side\":\"SELL\", \"hash\":\"71b1b7114669e0c325a13e989c54ff77edadccec\", \"best_bid\":\"0.13\", \"best_ask\":\"0.14\"}], \"timestamp\":\"1789987929517\", \"event_type\":\"price_change\"}","raw_base64":null}
{"received_ms":1789987929539,"monotonic_ns":1019370370016000,"raw":"{\"market\":\"0x28a45972fccdaf0fba75dacc59725521035e177d09dd92174f9f52740bccb025\", \"price_changes\":[{\"asset_id\":\"61819828071723399190623735325323968706432622380635304641786792960078828866875\", \"price\":\"0.76\", \"size\":\"424.91\", \"side\":\"BUY\", \"hash\":\"bc6a44d869c0b07f06baa54711260a7eac9ae018\", \"best_bid\":\"0.86\", \"best_ask\":\"0.87\"}, {\"asset_id\":\"114356653315647913247200886351065428002113119844334520181865067698979836634569\", \"price\":\"0.24\", \"size\":\"424.91\", \"side\":\"SELL\", \"hash\":\"bfeb5e78cc2f4a0f064c8889cc30820e932bd387\", \"best_bid\":\"0.13\", \"best_ask\":\"0.14\"}], \"timestamp\":\"1789987929518\", \"event_type\":\"price_change\"}","raw_base64":null}
{"received_ms":1789987929541,"monotonic_ns":1019370372047700,"raw":"{\"market\":\"0x28a45972fccdaf0fba75dacc59725521035e177d09dd92174f9f52740bccb025\", \"price_changes\":[{\"asset_id\":\"61819828071723399190623735325323968706432622380635304641786792960078828866875\", \"price\":\"0.86\", \"size\":\"3921\", \"side\":\"BUY\", \"hash\":\"3f059ebac11523d5607b0a28fcecbe14de3c5fec\", \"best_bid\":\"0.86\", \"best_ask\":\"0.87\"}, {\"asset_id\":\"114356653315647913247200886351065428002113119844334520181865067698979836634569\", \"price\":\"0.14\", \"size\":\"3921\", \"side\":\"SELL\", \"hash\":\"14d613d2b70640e694af1ce80e4d48bd3072c205\", \"best_bid\":\"0.13\", \"best_ask\":\"0.14\"}], \"timestamp\":\"1789987929520\", \"event_type\":\"price_change\"}","raw_base64":null}
{"received_ms":1789987929543,"monotonic_ns":1019370374069700,"raw":"{\"market\":\"0x28a45972fccdaf0fba75dacc59725521035e177d09dd92174f9f52740bccb025\", \"price_changes\":[{\"asset_id\":\"114356653315647913247200886351065428002113119844334520181865067698979836634569\", \"price\":\"0.03\", \"size\":\"4012.57\", \"side\":\"BUY\", \"hash\":\"bdd17386b4d90d28cc493f45328f016cb7d08862\", \"best_bid\":\"0.13\", \"best_ask\":\"0.14\"}, {\"asset_id\":\"61819828071723399190623735325323968706432622380635304641786792960078828866875\", \"price\":\"0.97\", \"size\":\"4012.57\", \"side\":\"SELL\", \"hash\":\"16944633060791719a3838b59fd17f62945a60bb\", \"best_bid\":\"0.86\", \"best_ask\":\"0.87\"}], \"timestamp\":\"1789987929523\", \"event_type\":\"price_change\"}","raw_base64":null}
{"received_ms":1789987929551,"monotonic_ns":1019370381872400,"raw":"{\"market\":\"0x28a45972fccdaf0fba75dacc59725521035e177d09dd92174f9f52740bccb025\", \"price_changes\":[{\"asset_id\":\"114356653315647913247200886351065428002113119844334520181865067698979836634569\", \"price\":\"0.06\", \"size\":\"5348.67\", \"side\":\"BUY\", \"hash\":\"080a2d5a57dccc46937fc13d6e46fa5df4df2c2e\", \"best_bid\":\"0.13\", \"best_ask\":\"0.14\"}, {\"asset_id\":\"61819828071723399190623735325323968706432622380635304641786792960078828866875\", \"price\":\"0.94\", \"size\":\"5348.67\", \"side\":\"SELL\", \"hash\":\"f4f8529b71abaf65afce63a8ef7acc785c830cb5\", \"best_bid\":\"0.86\", \"best_ask\":\"0.87\"}], \"timestamp\":\"1789987929529\", \"event_type\":\"price_change\"}","raw_base64":null}
{"received_ms":1789987929557,"monotonic_ns":1019370387745000,"raw":"{\"market\":\"0x28a45972fccdaf0fba75dacc59725521035e177d09dd92174f9f52740bccb025\", \"price_changes\":[{\"asset_id\":\"61819828071723399190623735325323968706432622380635304641786792960078828866875\", \"price\":\"0.79\", \"size\":\"527\", \"side\":\"BUY\", \"hash\":\"3a0a8b67d933a660704d9d91724c9dc634145754\", \"best_bid\":\"0.86\", \"best_ask\":\"0.87\"}, {\"asset_id\":\"114356653315647913247200886351065428002113119844334520181865067698979836634569\", \"price\":\"0.21\", \"size\":\"527\", \"side\":\"SELL\", \"hash\":\"b8050ff87cfcdf1481c52be7d19953b7cf14b955\", \"best_bid\":\"0.13\", \"best_ask\":\"0.14\"}], \"timestamp\":\"1789987929536\", \"event_type\":\"price_change\"}","raw_base64":null}
{"received_ms":1789987929557,"monotonic_ns":1019370388208000,"raw":"{\"market\":\"0x28a45972fccdaf0fba75dacc59725521035e177d09dd92174f9f52740bccb025\", \"price_changes\":[{\"asset_id\":\"61819828071723399190623735325323968706432622380635304641786792960078828866875\", \"price\":\"0.8\", \"size\":\"582\", \"side\":\"BUY\", \"hash\":\"c34291eabc102ac180d0bce8bd2e10a2a789f78c\", \"best_bid\":\"0.86\", \"best_ask\":\"0.87\"}, {\"asset_id\":\"114356653315647913247200886351065428002113119844334520181865067698979836634569\", \"price\":\"0.2\", \"size\":\"582\", \"side\":\"SELL\", \"hash\":\"7ed1a71a8e83c205448f3bebf758b87453218803\", \"best_bid\":\"0.13\", \"best_ask\":\"0.14\"}], \"timestamp\":\"1789987929537\", \"event_type\":\"price_change\"}","raw_base64":null}
{"received_ms":1789987929559,"monotonic_ns":1019370389796800,"raw":"{\"market\":\"0x28a45972fccdaf0fba75dacc59725521035e177d09dd92174f9f52740bccb025\", \"price_changes\":[{\"asset_id\":\"61819828071723399190623735325323968706432622380635304641786792960078828866875\", \"price\":\"0.79\", \"size\":\"447\", \"side\":\"BUY\", \"hash\":\"13b7139cd9f44e4da7edf64f9b7d344864cacf2c\", \"best_bid\":\"0.86\", \"best_ask\":\"0.87\"}, {\"asset_id\":\"114356653315647913247200886351065428002113119844334520181865067698979836634569\", \"price\":\"0.21\", \"size\":\"447\", \"side\":\"SELL\", \"hash\":\"998561ca42ba95774411e09afaca7fed18be767d\", \"best_bid\":\"0.13\", \"best_ask\":\"0.14\"}], \"timestamp\":\"1789987929539\", \"event_type\":\"price_change\"}","raw_base64":null}
{"received_ms":1789987929559,"monotonic_ns":1019370389860800,"raw":"{\"market\":\"0x28a45972fccdaf0fba75dacc59725521035e177d09dd92174f9f52740bccb025\", \"price_changes\":[{\"asset_id\":\"61819828071723399190623735325323968706432622380635304641786792960078828866875\", \"price\":\"0.8\", \"size\":\"562\", \"side\":\"BUY\", \"hash\":\"13b7139cd9f44e4da7edf64f9b7d344864cacf2c\", \"best_bid\":\"0.86\", \"best_ask\":\"0.87\"}, {\"asset_id\":\"114356653315647913247200886351065428002113119844334520181865067698979836634569\", \"price\":\"0.2\", \"size\":\"562\", \"side\":\"SELL\", \"hash\":\"998561ca42ba95774411e09afaca7fed18be767d\", \"best_bid\":\"0.13\", \"best_ask\":\"0.14\"}], \"timestamp\":\"1789987929539\", \"event_type\":\"price_change\"}","raw_base64":null}
{"received_ms":1789987929574,"monotonic_ns":1019370404554600,"raw":"{\"market\":\"0x28a45972fccdaf0fba75dacc59725521035e177d09dd92174f9f52740bccb025\", \"price_changes\":[{\"asset_id\":\"61819828071723399190623735325323968706432622380635304641786792960078828866875\", \"price\":\"0.86\", \"size\":\"3936.17\", \"side\":\"BUY\", \"hash\":\"b910eea76d5880d49c1174bd9e8e0b1425be7458\", \"best_bid\":\"0.86\", \"best_ask\":\"0.87\"}, {\"asset_id\":\"114356653315647913247200886351065428002113119844334520181865067698979836634569\", \"price\":\"0.14\", \"size\":\"3936.17\", \"side\":\"SELL\", \"hash\":\"a4dc1453ef4336dae070f5424e95459ff7d4d1b1\", \"best_bid\":\"0.13\", \"best_ask\":\"0.14\"}], \"timestamp\":\"1789987929553\", \"event_type\":\"price_change\"}","raw_base64":null}
{"received_ms":1789987929579,"monotonic_ns":1019370409423400,"raw":"{\"market\":\"0x28a45972fccdaf0fba75dacc59725521035e177d09dd92174f9f52740bccb025\", \"price_changes\":[{\"asset_id\":\"114356653315647913247200886351065428002113119844334520181865067698979836634569\", \"price\":\"0.07\", \"size\":\"6913.71\", \"side\":\"BUY\", \"hash\":\"64c85cf56ef5dca16eb9b32db8253db2549cb4a2\", \"best_bid\":\"0.13\", \"best_ask\":\"0.14\"}, {\"asset_id\":\"61819828071723399190623735325323968706432622380635304641786792960078828866875\", \"price\":\"0.93\", \"size\":\"6913.71\", \"side\":\"SELL\", \"hash\":\"40584002b1fc990a9d5e80c67d59dc7d2d46accc\", \"best_bid\":\"0.86\", \"best_ask\":\"0.87\"}], \"timestamp\":\"1789987929558\", \"event_type\":\"price_change\"}","raw_base64":null}
{"received_ms":1789987929582,"monotonic_ns":1019370412533800,"raw":"{\"market\":\"0x28a45972fccdaf0fba75dacc59725521035e177d09dd92174f9f52740bccb025\", \"price_changes\":[{\"asset_id\":\"114356653315647913247200886351065428002113119844334520181865067698979836634569\", \"price\":\"0.11\", \"size\":\"118.1\", \"side\":\"BUY\", \"hash\":\"4a873064e342ac4aeeae5ba84ff739b5f66b35d3\", \"best_bid\":\"0.13\", \"best_ask\":\"0.14\"}, {\"asset_id\":\"61819828071723399190623735325323968706432622380635304641786792960078828866875\", \"price\":\"0.89\", \"size\":\"118.1\", \"side\":\"SELL\", \"hash\":\"607fbf5d5ff7fd5b69eab77b22564fff02cb04d8\", \"best_bid\":\"0.86\", \"best_ask\":\"0.87\"}], \"timestamp\":\"1789987929561\", \"event_type\":\"price_change\"}","raw_base64":null}
{"received_ms":1789987929584,"monotonic_ns":1019370415015400,"raw":"{\"market\":\"0x28a45972fccdaf0fba75dacc59725521035e177d09dd92174f9f52740bccb025\", \"price_changes\":[{\"asset_id\":\"61819828071723399190623735325323968706432622380635304641786792960078828866875\", \"price\":\"0.84\", \"size\":\"3239\", \"side\":\"BUY\", \"hash\":\"d0f217b4271fc812833265824bc6b22cdcf21508\", \"best_bid\":\"0.86\", \"best_ask\":\"0.87\"}, {\"asset_id\":\"114356653315647913247200886351065428002113119844334520181865067698979836634569\", \"price\":\"0.16\", \"size\":\"3239\", \"side\":\"SELL\", \"hash\":\"718b5cc12dd8fc8f5d47c124c55b2f304314c09d\", \"best_bid\":\"0.13\", \"best_ask\":\"0.14\"}], \"timestamp\":\"1789987929563\", \"event_type\":\"price_change\"}","raw_base64":null}
{"received_ms":1789987929593,"monotonic_ns":1019370423412200,"raw":"{\"market\":\"0x28a45972fccdaf0fba75dacc59725521035e177d09dd92174f9f52740bccb025\", \"price_changes\":[{\"asset_id\":\"61819828071723399190623735325323968706432622380635304641786792960078828866875\", \"price\":\"0.75\", \"size\":\"520\", \"side\":\"BUY\", \"hash\":\"b2da6de7fbd481c867145e8ff384bdeb16976adb\", \"best_bid\":\"0.86\", \"best_ask\":\"0.87\"}, {\"asset_id\":\"114356653315647913247200886351065428002113119844334520181865067698979836634569\", \"price\":\"0.25\", \"size\":\"520\", \"side\":\"SELL\", \"hash\":\"402a625f76013028b4e8106510eb7691f8e75c2e\", \"best_bid\":\"0.13\", \"best_ask\":\"0.14\"}], \"timestamp\":\"1789987929571\", \"event_type\":\"price_change\"}","raw_base64":null}
{"received_ms":1789987929599,"monotonic_ns":1019370429722300,"raw":"{\"market\":\"0x28a45972fccdaf0fba75dacc59725521035e177d09dd92174f9f52740bccb025\", \"price_changes\":[{\"asset_id\":\"114356653315647913247200886351065428002113119844334520181865067698979836634569\", \"price\":\"0.09\", \"size\":\"618.12\", \"side\":\"BUY\", \"hash\":\"64b76d3c98a8260eed7509c0795eb0988929a2d2\", \"best_bid\":\"0.13\", \"best_ask\":\"0.14\"}, {\"asset_id\":\"61819828071723399190623735325323968706432622380635304641786792960078828866875\", \"price\":\"0.91\", \"size\":\"618.12\", \"side\":\"SELL\", \"hash\":\"ce308b04c97ae872ddcc1c234a5adb0b0bb762bc\", \"best_bid\":\"0.86\", \"best_ask\":\"0.87\"}], \"timestamp\":\"1789987929579\", \"event_type\":\"price_change\"}","raw_base64":null}
{"received_ms":1789987929600,"monotonic_ns":1019370430551900,"raw":"{\"market\":\"0x28a45972fccdaf0fba75dacc59725521035e177d09dd92174f9f52740bccb025\", \"price_changes\":[{\"asset_id\":\"61819828071723399190623735325323968706432622380635304641786792960078828866875\", \"price\":\"0.75\", \"size\":\"420\", \"side\":\"BUY\", \"hash\":\"c19c07d9223a3530fbbec6109d767e3ff456b167\", \"best_bid\":\"0.86\", \"best_ask\":\"0.87\"}, {\"asset_id\":\"114356653315647913247200886351065428002113119844334520181865067698979836634569\", \"price\":\"0.25\", \"size\":\"420\", \"side\":\"SELL\", \"hash\":\"db5dfda99dedfb569461b7cf5e77f043e1a5a5d4\", \"best_bid\":\"0.13\", \"best_ask\":\"0.14\"}], \"timestamp\":\"1789987929579\", \"event_type\":\"price_change\"}","raw_base64":null}
{"received_ms":1789987929612,"monotonic_ns":1019370443249000,"raw":"{\"market\":\"0x28a45972fccdaf0fba75dacc59725521035e177d09dd92174f9f52740bccb025\", \"price_changes\":[{\"asset_id\":\"114356653315647913247200886351065428002113119844334520181865067698979836634569\", \"price\":\"0.07\", \"size\":\"7984.71\", \"side\":\"BUY\", \"hash\":\"c46bb093286b55c8125a85f99123ce138976db9f\", \"best_bid\":\"0.13\", \"best_ask\":\"0.14\"}, {\"asset_id\":\"61819828071723399190623735325323968706432622380635304641786792960078828866875\", \"price\":\"0.93\", \"size\":\"7984.71\", \"side\":\"SELL\", \"hash\":\"42a87a1c6b72453b7627f2492a66686d9bbaf866\", \"best_bid\":\"0.86\", \"best_ask\":\"0.87\"}], \"timestamp\":\"1789987929592\", \"event_type\":\"price_change\"}","raw_base64":null}
{"received_ms":1789987929628,"monotonic_ns":1019370459021300,"raw":"{\"market\":\"0x28a45972fccdaf0fba75dacc59725521035e177d09dd92174f9f52740bccb025\", \"price_changes\":[{\"asset_id\":\"61819828071723399190623735325323968706432622380635304641786792960078828866875\", \"price\":\"0.79\", \"size\":\"527\", \"side\":\"BUY\", \"hash\":\"0dd17cd473b078b7d78d3e9641b997660b461034\", \"best_bid\":\"0.86\", \"best_ask\":\"0.87\"}, {\"asset_id\":\"114356653315647913247200886351065428002113119844334520181865067698979836634569\", \"price\":\"0.21\", \"size\":\"527\", \"side\":\"SELL\", \"hash\":\"fc77478e036c2f126df47ae8c3896792e2a30064\", \"best_bid\":\"0.13\", \"best_ask\":\"0.14\"}], \"timestamp\":\"1789987929608\", \"event_type\":\"price_change\"}","raw_base64":null}
{"received_ms":1789987929629,"monotonic_ns":1019370460168800,"raw":"{\"market\":\"0x28a45972fccdaf0fba75dacc59725521035e177d09dd92174f9f52740bccb025\", \"price_changes\":[{\"asset_id\":\"61819828071723399190623735325323968706432622380635304641786792960078828866875\", \"price\":\"0.8\", \"size\":\"582\", \"side\":\"BUY\", \"hash\":\"0332f00c15ea31dd7ba35c22d9ecc8a464df45b9\", \"best_bid\":\"0.86\", \"best_ask\":\"0.87\"}, {\"asset_id\":\"114356653315647913247200886351065428002113119844334520181865067698979836634569\", \"price\":\"0.2\", \"size\":\"582\", \"side\":\"SELL\", \"hash\":\"0795474a82e74f8b6e0837927fcee06c856c5719\", \"best_bid\":\"0.13\", \"best_ask\":\"0.14\"}], \"timestamp\":\"1789987929609\", \"event_type\":\"price_change\"}","raw_base64":null}
{"received_ms":1789987929635,"monotonic_ns":1019370465493300,"raw":"{\"market\":\"0x28a45972fccdaf0fba75dacc59725521035e177d09dd92174f9f52740bccb025\", \"price_changes\":[{\"asset_id\":\"61819828071723399190623735325323968706432622380635304641786792960078828866875\", \"price\":\"0.79\", \"size\":\"447\", \"side\":\"BUY\", \"hash\":\"84ce6dcb2ce74976ff0c3cc476314ec94a230c58\", \"best_bid\":\"0.86\", \"best_ask\":\"0.87\"}, {\"asset_id\":\"114356653315647913247200886351065428002113119844334520181865067698979836634569\", \"price\":\"0.21\", \"size\":\"447\", \"side\":\"SELL\", \"hash\":\"64cea93ea9f6b0d6e02b4a92cc9c7fb4e68cc8ae\", \"best_bid\":\"0.13\", \"best_ask\":\"0.14\"}], \"timestamp\":\"1789987929614\", \"event_type\":\"price_change\"}","raw_base64":null}
{"received_ms":1789987929635,"monotonic_ns":1019370465549100,"raw":"{\"market\":\"0x28a45972fccdaf0fba75dacc59725521035e177d09dd92174f9f52740bccb025\", \"price_changes\":[{\"asset_id\":\"61819828071723399190623735325323968706432622380635304641786792960078828866875\", \"price\":\"0.8\", \"size\":\"562\", \"side\":\"BUY\", \"hash\":\"84ce6dcb2ce74976ff0c3cc476314ec94a230c58\", \"best_bid\":\"0.86\", \"best_ask\":\"0.87\"}, {\"asset_id\":\"114356653315647913247200886351065428002113119844334520181865067698979836634569\", \"price\":\"0.2\", \"size\":\"562\", \"side\":\"SELL\", \"hash\":\"64cea93ea9f6b0d6e02b4a92cc9c7fb4e68cc8ae\", \"best_bid\":\"0.13\", \"best_ask\":\"0.14\"}], \"timestamp\":\"1789987929614\", \"event_type\":\"price_change\"}","raw_base64":null}
{"received_ms":1789987929661,"monotonic_ns":1019370491720300,"raw":"{\"market\":\"0x28a45972fccdaf0fba75dacc59725521035e177d09dd92174f9f52740bccb025\", \"price_changes\":[{\"asset_id\":\"114356653315647913247200886351065428002113119844334520181865067698979836634569\", \"price\":\"0.12\", \"size\":\"509.34\", \"side\":\"BUY\", \"hash\":\"92dc66f88f12b1c0a9947dec9a63b4f5e22c6529\", \"best_bid\":\"0.13\", \"best_ask\":\"0.14\"}, {\"asset_id\":\"61819828071723399190623735325323968706432622380635304641786792960078828866875\", \"price\":\"0.88\", \"size\":\"509.34\", \"side\":\"SELL\", \"hash\":\"a3cc7bfe33ff32c93002dce24f08c583e7db1aca\", \"best_bid\":\"0.86\", \"best_ask\":\"0.87\"}], \"timestamp\":\"1789987929641\", \"event_type\":\"price_change\"}","raw_base64":null}
{"received_ms":1789987929662,"monotonic_ns":1019370493106400,"raw":"{\"market\":\"0x28a45972fccdaf0fba75dacc59725521035e177d09dd92174f9f52740bccb025\", \"price_changes\":[{\"asset_id\":\"61819828071723399190623735325323968706432622380635304641786792960078828866875\", \"price\":\"0.75\", \"size\":\"520\", \"side\":\"BUY\", \"hash\":\"26e0cec6aa44730b4cd491677aba585354081ab1\", \"best_bid\":\"0.86\", \"best_ask\":\"0.87\"}, {\"asset_id\":\"114356653315647913247200886351065428002113119844334520181865067698979836634569\", \"price\":\"0.25\", \"size\":\"520\", \"side\":\"SELL\", \"hash\":\"42b7547c90d3d0b7060841b61ca61bda0401ea97\", \"best_bid\":\"0.13\", \"best_ask\":\"0.14\"}], \"timestamp\":\"1789987929642\", \"event_type\":\"price_change\"}","raw_base64":null}
{"received_ms":1789987929665,"monotonic_ns":1019370496145900,"raw":"{\"market\":\"0x28a45972fccdaf0fba75dacc59725521035e177d09dd92174f9f52740bccb025\", \"price_changes\":[{\"asset_id\":\"61819828071723399190623735325323968706432622380635304641786792960078828866875\", \"price\":\"0.86\", \"size\":\"3915.97\", \"side\":\"BUY\", \"hash\":\"426c9687954a8a97f420024031bf27ebb5558c61\", \"best_bid\":\"0.86\", \"best_ask\":\"0.87\"}, {\"asset_id\":\"114356653315647913247200886351065428002113119844334520181865067698979836634569\", \"price\":\"0.14\", \"size\":\"3915.97\", \"side\":\"SELL\", \"hash\":\"e2a1ca492d04533cfc9e69965d17c3a2b51f498d\", \"best_bid\":\"0.13\", \"best_ask\":\"0.14\"}], \"timestamp\":\"1789987929644\", \"event_type\":\"price_change\"}","raw_base64":null}
{"received_ms":1789987929665,"monotonic_ns":1019370496203700,"raw":"{\"market\":\"0x28a45972fccdaf0fba75dacc59725521035e177d09dd92174f9f52740bccb025\", \"asset_id\":\"114356653315647913247200886351065428002113119844334520181865067698979836634569\", \"bids\":[{\"price\":\"0.01\", \"size\":\"1689.43\"}, {\"price\":\"0.02\", \"size\":\"574.82\"}, {\"price\":\"0.03\", \"size\":\"4012.57\"}, {\"price\":\"0.04\", \"size\":\"625.48\"}, {\"price\":\"0.05\", \"size\":\"5615\"}, {\"price\":\"0.06\", \"size\":\"5348.67\"}, {\"price\":\"0.07\", \"size\":\"7984.71\"}, {\"price\":\"0.08\", \"size\":\"714.5\"}, {\"price\":\"0.09\", \"size\":\"618.12\"}, {\"price\":\"0.1\", \"size\":\"580\"}, {\"price\":\"0.11\", \"size\":\"118.1\"}, {\"price\":\"0.12\", \"size\":\"509.34\"}, {\"price\":\"0.13\", \"size\":\"265\"}], \"asks\":[{\"price\":\"0.99\", \"size\":\"1491.91\"}, {\"price\":\"0.98\", \"size\":\"385.35\"}, {\"price\":\"0.97\", \"size\":\"1270.08\"}, {\"price\":\"0.96\", \"size\":\"165.3\"}, {\"price\":\"0.95\", \"size\":\"237.01\"}, {\"price\":\"0.94\", \"size\":\"85.67\"}, {\"price\":\"0.93\", \"size\":\"159.29\"}, {\"price\":\"0.92\", \"size\":\"81.51\"}, {\"price\":\"0.91\", \"size\":\"252.12\"}, {\"price\":\"0.9\", \"size\":\"99.01\"}, {\"price\":\"0.89\", \"size\":\"129.1\"}, {\"price\":\"0.88\", \"size\":\"67.34\"}, {\"price\":\"0.87\", \"size\":\"123.7\"}, {\"price\":\"0.86\", \"size\":\"66.15\"}, {\"price\":\"0.85\", \"size\":\"197.39\"}, {\"price\":\"0.84\", \"size\":\"65.25\"}, {\"price\":\"0.83\", \"size\":\"115.89\"}, {\"price\":\"0.82\", \"size\":\"64.56\"}, {\"price\":\"0.81\", \"size\":\"113.27\"}, {\"price\":\"0.8\", \"size\":\"74.81\"}, {\"price\":\"0.79\", \"size\":\"112\"}, {\"price\":\"0.78\", \"size\":\"64\"}, {\"price\":\"0.77\", \"size\":\"111\"}, {\"price\":\"0.76\", \"size\":\"64\"}, {\"price\":\"0.75\", \"size\":\"110\"}, {\"price\":\"0.74\", \"size\":\"250\"}, {\"price\":\"0.73\", \"size\":\"289\"}, {\"price\":\"0.72\", \"size\":\"244\"}, {\"price\":\"0.71\", \"size\":\"297\"}, {\"price\":\"0.7\", \"size\":\"281\"}, {\"price\":\"0.69\", \"size\":\"297\"}, {\"price\":\"0.68\", \"size\":\"267\"}, {\"price\":\"0.67\", \"size\":\"310\"}, {\"price\":\"0.66\", \"size\":\"272.64\"}, {\"price\":\"0.65\", \"size\":\"297\"}, {\"price\":\"0.64\", \"size\":\"285.33\"}, {\"price\":\"0.63\", \"size\":\"297\"}, {\"price\":\"0.62\", \"size\":\"272.05\"}, {\"price\":\"0.61\", \"size\":\"310\"}, {\"price\":\"0.6\", \"size\":\"1067\"}, {\"price\":\"0.59\", \"size\":\"297\"}, {\"price\":\"0.58\", \"size\":\"279\"}, {\"price\":\"0.57\", \"size\":\"297\"}, {\"price\":\"0.56\", \"size\":\"267\"}, {\"price\":\"0.55\", \"size\":\"297\"}, {\"price\":\"0.54\", \"size\":\"267\"}, {\"price\":\"0.53\", \"size\":\"302\"}, {\"price\":\"0.52\", \"size\":\"267\"}, {\"price\":\"0.51\", \"size\":\"297\"}, {\"price\":\"0.5\", \"size\":\"267\"}, {\"price\":\"0.49\", \"size\":\"297\"}, {\"price\":\"0.48\", \"size\":\"267\"}, {\"price\":\"0.47\", \"size\":\"297\"}, {\"price\":\"0.46\", \"size\":\"267\"}, {\"price\":\"0.45\", \"size\":\"297\"}, {\"price\":\"0.44\", \"size\":\"267\"}, {\"price\":\"0.43\", \"size\":\"309\"}, {\"price\":\"0.42\", \"size\":\"267\"}, {\"price\":\"0.41\", \"size\":\"297\"}, {\"price\":\"0.4\", \"size\":\"279\"}, {\"price\":\"0.39\", \"size\":\"297\"}, {\"price\":\"0.38\", \"size\":\"267\"}, {\"price\":\"0.37\", \"size\":\"309\"}, {\"price\":\"0.36\", \"size\":\"267\"}, {\"price\":\"0.35\", \"size\":\"297\"}, {\"price\":\"0.34\", \"size\":\"267\"}, {\"price\":\"0.33\", \"size\":\"322\"}, {\"price\":\"0.32\", \"size\":\"292\"}, {\"price\":\"0.31\", \"size\":\"322\"}, {\"price\":\"0.3\", \"size\":\"292\"}, {\"price\":\"0.29\", \"size\":\"403\"}, {\"price\":\"0.28\", \"size\":\"438.8\"}, {\"price\":\"0.27\", \"size\":\"404\"}, {\"price\":\"0.26\", \"size\":\"455.53\"}, {\"price\":\"0.25\", \"size\":\"520\"}, {\"price\":\"0.24\", \"size\":\"424.91\"}, {\"price\":\"0.23\", \"size\":\"587.49\"}, {\"price\":\"0.22\", \"size\":\"433.82\"}, {\"price\":\"0.21\", \"size\":\"447\"}, {\"price\":\"0.2\", \"size\":\"562\"}, {\"price\":\"0.19\", \"size\":\"590\"}, {\"price\":\"0.18\", \"size\":\"753\"}, {\"price\":\"0.17\", \"size\":\"434\"}, {\"price\":\"0.16\", \"size\":\"3239\"}, {\"price\":\"0.15\", \"size\":\"2777.35\"}, {\"price\":\"0.14\", \"size\":\"3915.97\"}], \"hash\":\"e2a1ca492d04533cfc9e69965d17c3a2b51f498d\", \"timestamp\":\"1789987929644\", \"event_type\":\"book\"}","raw_base64":null}
{"received_ms":1789987929666,"monotonic_ns":1019370497185400,"raw":"{\"market\":\"0x28a45972fccdaf0fba75dacc59725521035e177d09dd92174f9f52740bccb025\", \"asset_id\":\"61819828071723399190623735325323968706432622380635304641786792960078828866875\", \"bids\":[{\"price\":\"0.01\", \"size\":\"1491.91\"}, {\"price\":\"0.02\", \"size\":\"385.35\"}, {\"price\":\"0.03\", \"size\":\"1270.08\"}, {\"price\":\"0.04\", \"size\":\"165.3\"}, {\"price\":\"0.05\", \"size\":\"237.01\"}, {\"price\":\"0.06\", \"size\":\"85.67\"}, {\"price\":\"0.07\", \"size\":\"159.29\"}, {\"price\":\"0.08\", \"size\":\"81.51\"}, {\"price\":\"0.09\", \"size\":\"252.12\"}, {\"price\":\"0.1\", \"size\":\"99.01\"}, {\"price\":\"0.11\", \"size\":\"129.1\"}, {\"price\":\"0.12\", \"size\":\"67.34\"}, {\"price\":\"0.13\", \"size\":\"123.7\"}, {\"price\":\"0.14\", \"size\":\"66.15\"}, {\"price\":\"0.15\", \"size\":\"197.39\"}, {\"price\":\"0.16\", \"size\":\"65.25\"}, {\"price\":\"0.17\", \"size\":\"115.89\"}, {\"price\":\"0.18\", \"size\":\"64.56\"}, {\"price\":\"0.19\", \"size\":\"113.27\"}, {\"price\":\"0.2\", \"size\":\"74.81\"}, {\"price\":\"0.21\", \"size\":\"112\"}, {\"price\":\"0.22\", \"size\":\"64\"}, {\"price\":\"0.23\", \"size\":\"111\"}, {\"price\":\"0.24\", \"size\":\"64\"}, {\"price\":\"0.25\", \"size\":\"110\"}, {\"price\":\"0.26\", \"size\":\"250\"}, {\"price\":\"0.27\", \"size\":\"289\"}, {\"price\":\"0.28\", \"size\":\"244\"}, {\"price\":\"0.29\", \"size\":\"297\"}, {\"price\":\"0.3\", \"size\":\"281\"}, {\"price\":\"0.31\", \"size\":\"297\"}, {\"price\":\"0.32\", \"size\":\"267\"}, {\"price\":\"0.33\", \"size\":\"310\"}, {\"price\":\"0.34\", \"size\":\"272.64\"}, {\"price\":\"0.35\", \"size\":\"297\"}, {\"price\":\"0.36\", \"size\":\"285.33\"}, {\"price\":\"0.37\", \"size\":\"297\"}, {\"price\":\"0.38\", \"size\":\"272.05\"}, {\"price\":\"0.39\", \"size\":\"310\"}, {\"price\":\"0.4\", \"size\":\"1067\"}, {\"price\":\"0.41\", \"size\":\"297\"}, {\"price\":\"0.42\", \"size\":\"279\"}, {\"price\":\"0.43\", \"size\":\"297\"}, {\"price\":\"0.44\", \"size\":\"267\"}, {\"price\":\"0.45\", \"size\":\"297\"}, {\"price\":\"0.46\", \"size\":\"267\"}, {\"price\":\"0.47\", \"size\":\"302\"}, {\"price\":\"0.48\", \"size\":\"267\"}, {\"price\":\"0.49\", \"size\":\"297\"}, {\"price\":\"0.5\", \"size\":\"267\"}, {\"price\":\"0.51\", \"size\":\"297\"}, {\"price\":\"0.52\", \"size\":\"267\"}, {\"price\":\"0.53\", \"size\":\"297\"}, {\"price\":\"0.54\", \"size\":\"267\"}, {\"price\":\"0.55\", \"size\":\"297\"}, {\"price\":\"0.56\", \"size\":\"267\"}, {\"price\":\"0.57\", \"size\":\"309\"}, {\"price\":\"0.58\", \"size\":\"267\"}, {\"price\":\"0.59\", \"size\":\"297\"}, {\"price\":\"0.6\", \"size\":\"279\"}, {\"price\":\"0.61\", \"size\":\"297\"}, {\"price\":\"0.62\", \"size\":\"267\"}, {\"price\":\"0.63\", \"size\":\"309\"}, {\"price\":\"0.64\", \"size\":\"267\"}, {\"price\":\"0.65\", \"size\":\"297\"}, {\"price\":\"0.66\", \"size\":\"267\"}, {\"price\":\"0.67\", \"size\":\"322\"}, {\"price\":\"0.68\", \"size\":\"292\"}, {\"price\":\"0.69\", \"size\":\"322\"}, {\"price\":\"0.7\", \"size\":\"292\"}, {\"price\":\"0.71\", \"size\":\"403\"}, {\"price\":\"0.72\", \"size\":\"438.8\"}, {\"price\":\"0.73\", \"size\":\"404\"}, {\"price\":\"0.74\", \"size\":\"455.53\"}, {\"price\":\"0.75\", \"size\":\"520\"}, {\"price\":\"0.76\", \"size\":\"424.91\"}, {\"price\":\"0.77\", \"size\":\"587.49\"}, {\"price\":\"0.78\", \"size\":\"433.82\"}, {\"price\":\"0.79\", \"size\":\"447\"}, {\"price\":\"0.8\", \"size\":\"562\"}, {\"price\":\"0.81\", \"size\":\"590\"}, {\"price\":\"0.82\", \"size\":\"753\"}, {\"price\":\"0.83\", \"size\":\"434\"}, {\"price\":\"0.84\", \"size\":\"3239\"}, {\"price\":\"0.85\", \"size\":\"2777.35\"}, {\"price\":\"0.86\", \"size\":\"3915.97\"}], \"asks\":[{\"price\":\"0.99\", \"size\":\"1689.43\"}, {\"price\":\"0.98\", \"size\":\"574.82\"}, {\"price\":\"0.97\", \"size\":\"4012.57\"}, {\"price\":\"0.96\", \"size\":\"625.48\"}, {\"price\":\"0.95\", \"size\":\"5615\"}, {\"price\":\"0.94\", \"size\":\"5348.67\"}, {\"price\":\"0.93\", \"size\":\"7984.71\"}, {\"price\":\"0.92\", \"size\":\"714.5\"}, {\"price\":\"0.91\", \"size\":\"618.12\"}, {\"price\":\"0.9\", \"size\":\"580\"}, {\"price\":\"0.89\", \"size\":\"118.1\"}, {\"price\":\"0.88\", \"size\":\"509.34\"}, {\"price\":\"0.87\", \"size\":\"265\"}], \"hash\":\"426c9687954a8a97f420024031bf27ebb5558c61\", \"timestamp\":\"1789987929644\", \"event_type\":\"book\"}","raw_base64":null}
{"received_ms":1789987929669,"monotonic_ns":1019370499642500,"raw":"{\"market\":\"0x28a45972fccdaf0fba75dacc59725521035e177d09dd92174f9f52740bccb025\", \"price_changes\":[{\"asset_id\":\"114356653315647913247200886351065428002113119844334520181865067698979836634569\", \"price\":\"0.11\", \"size\":\"126.1\", \"side\":\"BUY\", \"hash\":\"9826d87f3dbf8ffe85aed1b6898a6fa9fa127a88\", \"best_bid\":\"0.13\", \"best_ask\":\"0.14\"}, {\"asset_id\":\"61819828071723399190623735325323968706432622380635304641786792960078828866875\", \"price\":\"0.89\", \"size\":\"126.1\", \"side\":\"SELL\", \"hash\":\"00e856585ceb2acae6594dace5ea499ca57aad8e\", \"best_bid\":\"0.86\", \"best_ask\":\"0.87\"}], \"timestamp\":\"1789987929648\", \"event_type\":\"price_change\"}","raw_base64":null}
{"received_ms":1789987929671,"monotonic_ns":1019370501521200,"raw":"{\"market\":\"0x28a45972fccdaf0fba75dacc59725521035e177d09dd92174f9f52740bccb025\", \"price_changes\":[{\"asset_id\":\"61819828071723399190623735325323968706432622380635304641786792960078828866875\", \"price\":\"0.86\", \"size\":\"3707.97\", \"side\":\"BUY\", \"hash\":\"4bf58624630d19add123e977bbd35e64356fe82f\", \"best_bid\":\"0.86\", \"best_ask\":\"0.87\"}, {\"asset_id\":\"114356653315647913247200886351065428002113119844334520181865067698979836634569\", \"price\":\"0.14\", \"size\":\"3707.97\", \"side\":\"SELL\", \"hash\":\"562a7e8a80ed35f85d1d366b6bd07aa6c0e978a0\", \"best_bid\":\"0.13\", \"best_ask\":\"0.14\"}], \"timestamp\":\"1789987929649\", \"event_type\":\"price_change\"}","raw_base64":null}
{"received_ms":1789987929671,"monotonic_ns":1019370501604600,"raw":"{\"market\":\"0x28a45972fccdaf0fba75dacc59725521035e177d09dd92174f9f52740bccb025\", \"price_changes\":[{\"asset_id\":\"61819828071723399190623735325323968706432622380635304641786792960078828866875\", \"price\":\"0.75\", \"size\":\"420\", \"side\":\"BUY\", \"hash\":\"48ff61b62cc9507a023c59a043a2ce45668b2ff7\", \"best_bid\":\"0.86\", \"best_ask\":\"0.87\"}, {\"asset_id\":\"114356653315647913247200886351065428002113119844334520181865067698979836634569\", \"price\":\"0.25\", \"size\":\"420\", \"side\":\"SELL\", \"hash\":\"ca20f2bf707fb74ee73add43cb0ec18cdbfefd21\", \"best_bid\":\"0.13\", \"best_ask\":\"0.14\"}], \"timestamp\":\"1789987929649\", \"event_type\":\"price_change\"}","raw_base64":null}
{"received_ms":1789987929672,"monotonic_ns":1019370502590700,"raw":"{\"market\":\"0x28a45972fccdaf0fba75dacc59725521035e177d09dd92174f9f52740bccb025\", \"price_changes\":[{\"asset_id\":\"114356653315647913247200886351065428002113119844334520181865067698979836634569\", \"price\":\"0.09\", \"size\":\"610.12\", \"side\":\"BUY\", \"hash\":\"bf8ecbf51ffac1ab72f195f299ff867cbcb6e2ab\", \"best_bid\":\"0.13\", \"best_ask\":\"0.14\"}, {\"asset_id\":\"61819828071723399190623735325323968706432622380635304641786792960078828866875\", \"price\":\"0.91\", \"size\":\"610.12\", \"side\":\"SELL\", \"hash\":\"7ca2859a14547aa5f8b9a92de2c02eb4333a8791\", \"best_bid\":\"0.86\", \"best_ask\":\"0.87\"}], \"timestamp\":\"1789987929652\", \"event_type\":\"price_change\"}","raw_base64":null}
{"received_ms":1789987929675,"monotonic_ns":1019370505782300,"raw":"{\"market\":\"0x28a45972fccdaf0fba75dacc59725521035e177d09dd92174f9f52740bccb025\", \"price_changes\":[{\"asset_id\":\"114356653315647913247200886351065428002113119844334520181865067698979836634569\", \"price\":\"0.07\", \"size\":\"7964.71\", \"side\":\"BUY\", \"hash\":\"c44836d4de636c14a09bb246051b98c95fdde3d4\", \"best_bid\":\"0.13\", \"best_ask\":\"0.14\"}, {\"asset_id\":\"61819828071723399190623735325323968706432622380635304641786792960078828866875\", \"price\":\"0.93\", \"size\":\"7964.71\", \"side\":\"SELL\", \"hash\":\"767f153a2fd937bd7175e6938050208fc3c8b51c\", \"best_bid\":\"0.86\", \"best_ask\":\"0.87\"}], \"timestamp\":\"1789987929655\", \"event_type\":\"price_change\"}","raw_base64":null}
{"received_ms":1789987929694,"monotonic_ns":1019370524348200,"raw":"{\"market\":\"0x28a45972fccdaf0fba75dacc59725521035e177d09dd92174f9f52740bccb025\", \"asset_id\":\"114356653315647913247200886351065428002113119844334520181865067698979836634569\", \"price\":\"0.14\", \"size\":\"20.2\", \"fee_rate_bps\":\"0\", \"side\":\"BUY\", \"timestamp\":\"1789987929672\", \"event_type\":\"last_trade_price\", \"transaction_hash\":\"0xcfb78b452d01835f6d61b80dcca975e04dd6602a6a452fa9253cc8b7eb839711\"}","raw_base64":null}
{"received_ms":1789987929699,"monotonic_ns":1019370530144200,"raw":"{\"market\":\"0x28a45972fccdaf0fba75dacc59725521035e177d09dd92174f9f52740bccb025\", \"price_changes\":[{\"asset_id\":\"61819828071723399190623735325323968706432622380635304641786792960078828866875\", \"price\":\"0.86\", \"size\":\"3872.97\", \"side\":\"BUY\", \"hash\":\"39e3c81bde8d828479d9e156cefee32ebe69c114\", \"best_bid\":\"0.86\", \"best_ask\":\"0.87\"}, {\"asset_id\":\"114356653315647913247200886351065428002113119844334520181865067698979836634569\", \"price\":\"0.14\", \"size\":\"3872.97\", \"side\":\"SELL\", \"hash\":\"d1767830463b0ace95c8a69d1cb759d402c0a764\", \"best_bid\":\"0.13\", \"best_ask\":\"0.14\"}], \"timestamp\":\"1789987929679\", \"event_type\":\"price_change\"}","raw_base64":null}
{"received_ms":1789987929703,"monotonic_ns":1019370533660600,"raw":"{\"market\":\"0x28a45972fccdaf0fba75dacc59725521035e177d09dd92174f9f52740bccb025\", \"price_changes\":[{\"asset_id\":\"114356653315647913247200886351065428002113119844334520181865067698979836634569\", \"price\":\"0.05\", \"size\":\"5635\", \"side\":\"BUY\", \"hash\":\"4383f40c5fcab991ca5fbe8da519d63d30a8ea14\", \"best_bid\":\"0.13\", \"best_ask\":\"0.14\"}, {\"asset_id\":\"61819828071723399190623735325323968706432622380635304641786792960078828866875\", \"price\":\"0.95\", \"size\":\"5635\", \"side\":\"SELL\", \"hash\":\"4862024e0e7dde1b40b684d55ee3e8412414e71e\", \"best_bid\":\"0.86\", \"best_ask\":\"0.87\"}], \"timestamp\":\"1789987929681\", \"event_type\":\"price_change\"}","raw_base64":null}
{"received_ms":1789987929732,"monotonic_ns":1019370562573600,"raw":"{\"market\":\"0x28a45972fccdaf0fba75dacc59725521035e177d09dd92174f9f52740bccb025\", \"price_changes\":[{\"asset_id\":\"61819828071723399190623735325323968706432622380635304641786792960078828866875\", \"price\":\"0.86\", \"size\":\"3707.97\", \"side\":\"BUY\", \"hash\":\"fd52064f8cffe173c3a181f6f452e2434f9dafd9\", \"best_bid\":\"0.86\", \"best_ask\":\"0.87\"}, {\"asset_id\":\"114356653315647913247200886351065428002113119844334520181865067698979836634569\", \"price\":\"0.14\", \"size\":\"3707.97\", \"side\":\"SELL\", \"hash\":\"7263074ffe612c6275083c1c0e25a55ebc95ff04\", \"best_bid\":\"0.13\", \"best_ask\":\"0.14\"}], \"timestamp\":\"1789987929706\", \"event_type\":\"price_change\"}","raw_base64":null}
{"received_ms":1789987929735,"monotonic_ns":1019370566225400,"raw":"{\"market\":\"0x28a45972fccdaf0fba75dacc59725521035e177d09dd92174f9f52740bccb025\", \"price_changes\":[{\"asset_id\":\"61819828071723399190623735325323968706432622380635304641786792960078828866875\", \"price\":\"0.75\", \"size\":\"520\", \"side\":\"BUY\", \"hash\":\"0edadbe3f08499154a740178067f7f195f938d73\", \"best_bid\":\"0.86\", \"best_ask\":\"0.87\"}, {\"asset_id\":\"114356653315647913247200886351065428002113119844334520181865067698979836634569\", \"price\":\"0.25\", \"size\":\"520\", \"side\":\"SELL\", \"hash\":\"113ac898c944385fc26e77d40f5cc1b3c6315361\", \"best_bid\":\"0.13\", \"best_ask\":\"0.14\"}], \"timestamp\":\"1789987929715\", \"event_type\":\"price_change\"}","raw_base64":null}
{"received_ms":1789987929738,"monotonic_ns":1019370568676300,"raw":"{\"market\":\"0x28a45972fccdaf0fba75dacc59725521035e177d09dd92174f9f52740bccb025\", \"price_changes\":[{\"asset_id\":\"61819828071723399190623735325323968706432622380635304641786792960078828866875\", \"price\":\"0.75\", \"size\":\"420\", \"side\":\"BUY\", \"hash\":\"16e3589b746a11296157ac379f833823866ed6ff\", \"best_bid\":\"0.86\", \"best_ask\":\"0.87\"}, {\"asset_id\":\"114356653315647913247200886351065428002113119844334520181865067698979836634569\", \"price\":\"0.25\", \"size\":\"420\", \"side\":\"SELL\", \"hash\":\"cee3c3bcaf96d1ddf2e6057311b45131285f72e5\", \"best_bid\":\"0.13\", \"best_ask\":\"0.14\"}], \"timestamp\":\"1789987929717\", \"event_type\":\"price_change\"}","raw_base64":null}
{"received_ms":1789987929748,"monotonic_ns":1019370579257400,"raw":"{\"market\":\"0x28a45972fccdaf0fba75dacc59725521035e177d09dd92174f9f52740bccb025\", \"price_changes\":[{\"asset_id\":\"114356653315647913247200886351065428002113119844334520181865067698979836634569\", \"price\":\"0.07\", \"size\":\"6893.71\", \"side\":\"BUY\", \"hash\":\"b1069838f914590f13abe4e951da3debcb4a4d05\", \"best_bid\":\"0.13\", \"best_ask\":\"0.14\"}, {\"asset_id\":\"61819828071723399190623735325323968706432622380635304641786792960078828866875\", \"price\":\"0.93\", \"size\":\"6893.71\", \"side\":\"SELL\", \"hash\":\"940bcc6a92f242c73bfed456da3a53288e92ce8b\", \"best_bid\":\"0.86\", \"best_ask\":\"0.87\"}], \"timestamp\":\"1789987929726\", \"event_type\":\"price_change\"}","raw_base64":null}
{"received_ms":1789987929766,"monotonic_ns":1019370596375600,"raw":"{\"market\":\"0x28a45972fccdaf0fba75dacc59725521035e177d09dd92174f9f52740bccb025\", \"price_changes\":[{\"asset_id\":\"61819828071723399190623735325323968706432622380635304641786792960078828866875\", \"price\":\"0.86\", \"size\":\"3863.97\", \"side\":\"BUY\", \"hash\":\"8c6d51311c819bc53574ee513415ee229ee624a7\", \"best_bid\":\"0.86\", \"best_ask\":\"0.87\"}, {\"asset_id\":\"114356653315647913247200886351065428002113119844334520181865067698979836634569\", \"price\":\"0.14\", \"size\":\"3863.97\", \"side\":\"SELL\", \"hash\":\"15d04cd3874894d3d8566aec5a437ce6760f91dd\", \"best_bid\":\"0.13\", \"best_ask\":\"0.14\"}], \"timestamp\":\"1789987929743\", \"event_type\":\"price_change\"}","raw_base64":null}
{"received_ms":1789987929794,"monotonic_ns":1019370624351900,"raw":"{\"market\":\"0x28a45972fccdaf0fba75dacc59725521035e177d09dd92174f9f52740bccb025\", \"price_changes\":[{\"asset_id\":\"114356653315647913247200886351065428002113119844334520181865067698979836634569\", \"price\":\"0.07\", \"size\":\"7859.71\", \"side\":\"BUY\", \"hash\":\"2d043d5a5d4e89e379f88a2d7beec65e16544b01\", \"best_bid\":\"0.13\", \"best_ask\":\"0.14\"}, {\"asset_id\":\"61819828071723399190623735325323968706432622380635304641786792960078828866875\", \"price\":\"0.93\", \"size\":\"7859.71\", \"side\":\"SELL\", \"hash\":\"9f180b40923a673b12df8aef43ba1c3221dcf5ce\", \"best_bid\":\"0.86\", \"best_ask\":\"0.87\"}], \"timestamp\":\"1789987929773\", \"event_type\":\"price_change\"}","raw_base64":null}
{"received_ms":1789987929801,"monotonic_ns":1019370631586500,"raw":"{\"market\":\"0x28a45972fccdaf0fba75dacc59725521035e177d09dd92174f9f52740bccb025\", \"price_changes\":[{\"asset_id\":\"61819828071723399190623735325323968706432622380635304641786792960078828866875\", \"price\":\"0.86\", \"size\":\"3707.97\", \"side\":\"BUY\", \"hash\":\"1de3ff97650e383b99bb2191e5934f8129ec29c8\", \"best_bid\":\"0.86\", \"best_ask\":\"0.87\"}, {\"asset_id\":\"114356653315647913247200886351065428002113119844334520181865067698979836634569\", \"price\":\"0.14\", \"size\":\"3707.97\", \"side\":\"SELL\", \"hash\":\"9141f90a7e2cdf309af0d02c0f32e24648157e2a\", \"best_bid\":\"0.13\", \"best_ask\":\"0.14\"}], \"timestamp\":\"1789987929780\", \"event_type\":\"price_change\"}","raw_base64":null}
{"received_ms":1789987929806,"monotonic_ns":1019370636948600,"raw":"{\"market\":\"0x28a45972fccdaf0fba75dacc59725521035e177d09dd92174f9f52740bccb025\", \"price_changes\":[{\"asset_id\":\"61819828071723399190623735325323968706432622380635304641786792960078828866875\", \"price\":\"0.75\", \"size\":\"520\", \"side\":\"BUY\", \"hash\":\"96ae296de92a72ac0cd6be3ae983419e364369b4\", \"best_bid\":\"0.86\", \"best_ask\":\"0.87\"}, {\"asset_id\":\"114356653315647913247200886351065428002113119844334520181865067698979836634569\", \"price\":\"0.25\", \"size\":\"520\", \"side\":\"SELL\", \"hash\":\"a032830c8b1a6bd651069c71b4d74a08601a4f58\", \"best_bid\":\"0.13\", \"best_ask\":\"0.14\"}], \"timestamp\":\"1789987929786\", \"event_type\":\"price_change\"}","raw_base64":null}
{"received_ms":1789987929809,"monotonic_ns":1019370639970800,"raw":"{\"market\":\"0x28a45972fccdaf0fba75dacc59725521035e177d09dd92174f9f52740bccb025\", \"price_changes\":[{\"asset_id\":\"61819828071723399190623735325323968706432622380635304641786792960078828866875\", \"price\":\"0.75\", \"size\":\"420\", \"side\":\"BUY\", \"hash\":\"ade7416d1e5b9f31a7bf1ee505cc6b773ff766d9\", \"best_bid\":\"0.86\", \"best_ask\":\"0.87\"}, {\"asset_id\":\"114356653315647913247200886351065428002113119844334520181865067698979836634569\", \"price\":\"0.25\", \"size\":\"420\", \"side\":\"SELL\", \"hash\":\"d0408677617a3ee03b78ddb40974bd3417a06e86\", \"best_bid\":\"0.13\", \"best_ask\":\"0.14\"}], \"timestamp\":\"1789987929789\", \"event_type\":\"price_change\"}","raw_base64":null}
{"received_ms":1789987929833,"monotonic_ns":1019370663573400,"raw":"{\"market\":\"0x28a45972fccdaf0fba75dacc59725521035e177d09dd92174f9f52740bccb025\", \"price_changes\":[{\"asset_id\":\"114356653315647913247200886351065428002113119844334520181865067698979836634569\", \"price\":\"0.12\", \"size\":\"519.34\", \"side\":\"BUY\", \"hash\":\"2dbf1d55a3959cd1dc6bfbe1a7d34d31fb7f09d9\", \"best_bid\":\"0.13\", \"best_ask\":\"0.14\"}, {\"asset_id\":\"61819828071723399190623735325323968706432622380635304641786792960078828866875\", \"price\":\"0.88\", \"size\":\"519.34\", \"side\":\"SELL\", \"hash\":\"4130668bf90d6f5485dfbe561c196bb76ef24545\", \"best_bid\":\"0.86\", \"best_ask\":\"0.87\"}], \"timestamp\":\"1789987929812\", \"event_type\":\"price_change\"}","raw_base64":null}
{"received_ms":1789987929833,"monotonic_ns":1019370663872400,"raw":"{\"market\":\"0x28a45972fccdaf0fba75dacc59725521035e177d09dd92174f9f52740bccb025\", \"price_changes\":[{\"asset_id\":\"61819828071723399190623735325323968706432622380635304641786792960078828866875\", \"price\":\"0.86\", \"size\":\"3725.97\", \"side\":\"BUY\", \"hash\":\"13bdf71c62052aa98a2cc77ba806103f289b4034\", \"best_bid\":\"0.86\", \"best_ask\":\"0.87\"}, {\"asset_id\":\"114356653315647913247200886351065428002113119844334520181865067698979836634569\", \"price\":\"0.14\", \"size\":\"3725.97\", \"side\":\"SELL\", \"hash\":\"43bc965a17caf37008c97d5ab87eeff8fb96c1ec\", \"best_bid\":\"0.13\", \"best_ask\":\"0.14\"}], \"timestamp\":\"1789987929813\", \"event_type\":\"price_change\"}","raw_base64":null}
{"received_ms":1789987929842,"monotonic_ns":1019370672488100,"raw":"{\"market\":\"0x28a45972fccdaf0fba75dacc59725521035e177d09dd92174f9f52740bccb025\", \"price_changes\":[{\"asset_id\":\"61819828071723399190623735325323968706432622380635304641786792960078828866875\", \"price\":\"0.77\", \"size\":\"547.49\", \"side\":\"BUY\", \"hash\":\"efb212afc48d386be7b920bf058bd8374d1f89c8\", \"best_bid\":\"0.86\", \"best_ask\":\"0.87\"}, {\"asset_id\":\"114356653315647913247200886351065428002113119844334520181865067698979836634569\", \"price\":\"0.23\", \"size\":\"547.49\", \"side\":\"SELL\", \"hash\":\"b6438f18b7646749555678bf9cfeea0121eaa29f\", \"best_bid\":\"0.13\", \"best_ask\":\"0.14\"}], \"timestamp\":\"1789987929821\", \"event_type\":\"price_change\"}","raw_base64":null}
{"received_ms":1789987929842,"monotonic_ns":1019370672544900,"raw":"{\"market\":\"0x28a45972fccdaf0fba75dacc59725521035e177d09dd92174f9f52740bccb025\", \"price_changes\":[{\"asset_id\":\"114356653315647913247200886351065428002113119844334520181865067698979836634569\", \"price\":\"0.01\", \"size\":\"1669.43\", \"side\":\"BUY\", \"hash\":\"b6438f18b7646749555678bf9cfeea0121eaa29f\", \"best_bid\":\"0.13\", \"best_ask\":\"0.14\"}, {\"asset_id\":\"61819828071723399190623735325323968706432622380635304641786792960078828866875\", \"price\":\"0.99\", \"size\":\"1669.43\", \"side\":\"SELL\", \"hash\":\"efb212afc48d386be7b920bf058bd8374d1f89c8\", \"best_bid\":\"0.86\", \"best_ask\":\"0.87\"}], \"timestamp\":\"1789987929821\", \"event_type\":\"price_change\"}","raw_base64":null}
{"received_ms":1789987929842,"monotonic_ns":1019370672606600,"raw":"{\"market\":\"0x28a45972fccdaf0fba75dacc59725521035e177d09dd92174f9f52740bccb025\", \"price_changes\":[{\"asset_id\":\"61819828071723399190623735325323968706432622380635304641786792960078828866875\", \"price\":\"0.84\", \"size\":\"3179\", \"side\":\"BUY\", \"hash\":\"efb212afc48d386be7b920bf058bd8374d1f89c8\", \"best_bid\":\"0.86\", \"best_ask\":\"0.87\"}, {\"asset_id\":\"114356653315647913247200886351065428002113119844334520181865067698979836634569\", \"price\":\"0.16\", \"size\":\"3179\", \"side\":\"SELL\", \"hash\":\"b6438f18b7646749555678bf9cfeea0121eaa29f\", \"best_bid\":\"0.13\", \"best_ask\":\"0.14\"}], \"timestamp\":\"1789987929821\", \"event_type\":\"price_change\"}","raw_base64":null}
{"received_ms":1789987929842,"monotonic_ns":1019370672651000,"raw":"{\"market\":\"0x28a45972fccdaf0fba75dacc59725521035e177d09dd92174f9f52740bccb025\", \"price_changes\":[{\"asset_id\":\"114356653315647913247200886351065428002113119844334520181865067698979836634569\", \"price\":\"0.1\", \"size\":\"520\", \"side\":\"BUY\", \"hash\":\"b6438f18b7646749555678bf9cfeea0121eaa29f\", \"best_bid\":\"0.13\", \"best_ask\":\"0.14\"}, {\"asset_id\":\"61819828071723399190623735325323968706432622380635304641786792960078828866875\", \"price\":\"0.9\", \"size\":\"520\", \"side\":\"SELL\", \"hash\":\"efb212afc48d386be7b920bf058bd8374d1f89c8\", \"best_bid\":\"0.86\", \"best_ask\":\"0.87\"}], \"timestamp\":\"1789987929821\", \"event_type\":\"price_change\"}","raw_base64":null}
{"received_ms":1789987929865,"monotonic_ns":1019370696041400,"raw":"{\"market\":\"0x28a45972fccdaf0fba75dacc59725521035e177d09dd92174f9f52740bccb025\", \"price_changes\":[{\"asset_id\":\"61819828071723399190623735325323968706432622380635304641786792960078828866875\", \"price\":\"0.79\", \"size\":\"427\", \"side\":\"BUY\", \"hash\":\"996970529e2b2a1c8a04f3dd672fea805e3f69ba\", \"best_bid\":\"0.86\", \"best_ask\":\"0.87\"}, {\"asset_id\":\"114356653315647913247200886351065428002113119844334520181865067698979836634569\", \"price\":\"0.21\", \"size\":\"427\", \"side\":\"SELL\", \"hash\":\"d932fdafbb9c843f15687a8f50a59e7502a547a6\", \"best_bid\":\"0.13\", \"best_ask\":\"0.14\"}], \"timestamp\":\"1789987929845\", \"event_type\":\"price_change\"}","raw_base64":null}
{"received_ms":1789987929874,"monotonic_ns":1019370704939100,"raw":"{\"market\":\"0x28a45972fccdaf0fba75dacc59725521035e177d09dd92174f9f52740bccb025\", \"price_changes\":[{\"asset_id\":\"61819828071723399190623735325323968706432622380635304641786792960078828866875\", \"price\":\"0.79\", \"size\":\"467\", \"side\":\"BUY\", \"hash\":\"c0933b66608c160b020f3f1cf2d5f86dd1cb4df2\", \"best_bid\":\"0.86\", \"best_ask\":\"0.87\"}, {\"asset_id\":\"114356653315647913247200886351065428002113119844334520181865067698979836634569\", \"price\":\"0.21\", \"size\":\"467\", \"side\":\"SELL\", \"hash\":\"0012bb5990fe8b2ee2b7f0417b05c319beea9ef8\", \"best_bid\":\"0.13\", \"best_ask\":\"0.14\"}], \"timestamp\":\"1789987929854\", \"event_type\":\"price_change\"}","raw_base64":null}
{"received_ms":1789987929875,"monotonic_ns":1019370705273900,"raw":"{\"market\":\"0x28a45972fccdaf0fba75dacc59725521035e177d09dd92174f9f52740bccb025\", \"price_changes\":[{\"asset_id\":\"61819828071723399190623735325323968706432622380635304641786792960078828866875\", \"price\":\"0.83\", \"size\":\"494\", \"side\":\"BUY\", \"hash\":\"931ca5b1ac7793981d2b14775d83195966e38213\", \"best_bid\":\"0.86\", \"best_ask\":\"0.87\"}, {\"asset_id\":\"114356653315647913247200886351065428002113119844334520181865067698979836634569\", \"price\":\"0.17\", \"size\":\"494\", \"side\":\"SELL\", \"hash\":\"bed782eef68a204a80078fc80106ef247ade4561\", \"best_bid\":\"0.13\", \"best_ask\":\"0.14\"}], \"timestamp\":\"1789987929854\", \"event_type\":\"price_change\"}","raw_base64":null}
{"received_ms":1789987929876,"monotonic_ns":1019370706435500,"raw":"{\"market\":\"0x28a45972fccdaf0fba75dacc59725521035e177d09dd92174f9f52740bccb025\", \"price_changes\":[{\"asset_id\":\"114356653315647913247200886351065428002113119844334520181865067698979836634569\", \"price\":\"0.11\", \"size\":\"146.1\", \"side\":\"BUY\", \"hash\":\"b01a5ec417ec874d18f1bc09e7583c41ab3950cf\", \"best_bid\":\"0.13\", \"best_ask\":\"0.14\"}, {\"asset_id\":\"61819828071723399190623735325323968706432622380635304641786792960078828866875\", \"price\":\"0.89\", \"size\":\"146.1\", \"side\":\"SELL\", \"hash\":\"bd72bbc1248967ce020d8b15c56e62b736ad6325\", \"best_bid\":\"0.86\", \"best_ask\":\"0.87\"}], \"timestamp\":\"1789987929856\", \"event_type\":\"price_change\"}","raw_base64":null}
{"received_ms":1789987929877,"monotonic_ns":1019370707385000,"raw":"{\"market\":\"0x28a45972fccdaf0fba75dacc59725521035e177d09dd92174f9f52740bccb025\", \"price_changes\":[{\"asset_id\":\"61819828071723399190623735325323968706432622380635304641786792960078828866875\", \"price\":\"0.79\", \"size\":\"427\", \"side\":\"BUY\", \"hash\":\"3c70a95f9f0caf071a19558790d413ed100b361c\", \"best_bid\":\"0.86\", \"best_ask\":\"0.87\"}, {\"asset_id\":\"114356653315647913247200886351065428002113119844334520181865067698979836634569\", \"price\":\"0.21\", \"size\":\"427\", \"side\":\"SELL\", \"hash\":\"c6391fcff4ce78abb04b852426638a4e06946d36\", \"best_bid\":\"0.13\", \"best_ask\":\"0.14\"}], \"timestamp\":\"1789987929856\", \"event_type\":\"price_change\"}","raw_base64":null}
{"received_ms":1789987929877,"monotonic_ns":1019370707584500,"raw":"{\"market\":\"0x28a45972fccdaf0fba75dacc59725521035e177d09dd92174f9f52740bccb025\", \"price_changes\":[{\"asset_id\":\"114356653315647913247200886351065428002113119844334520181865067698979836634569\", \"price\":\"0.07\", \"size\":\"7879.71\", \"side\":\"BUY\", \"hash\":\"f10c0d82c423342a492f19413e6d36f757c6f48a\", \"best_bid\":\"0.13\", \"best_ask\":\"0.14\"}, {\"asset_id\":\"61819828071723399190623735325323968706432622380635304641786792960078828866875\", \"price\":\"0.93\", \"size\":\"7879.71\", \"side\":\"SELL\", \"hash\":\"4739563ce574559b9a5aa90a3c47931120a92c08\", \"best_bid\":\"0.86\", \"best_ask\":\"0.87\"}], \"timestamp\":\"1789987929857\", \"event_type\":\"price_change\"}","raw_base64":null}
{"received_ms":1789987929908,"monotonic_ns":1019370738365600,"raw":"{\"market\":\"0x28a45972fccdaf0fba75dacc59725521035e177d09dd92174f9f52740bccb025\", \"price_changes\":[{\"asset_id\":\"114356653315647913247200886351065428002113119844334520181865067698979836634569\", \"price\":\"0.05\", \"size\":\"5628\", \"side\":\"BUY\", \"hash\":\"e2a091df07dc4383bdb0e453a493ba73aca52e9c\", \"best_bid\":\"0.13\", \"best_ask\":\"0.14\"}, {\"asset_id\":\"61819828071723399190623735325323968706432622380635304641786792960078828866875\", \"price\":\"0.95\", \"size\":\"5628\", \"side\":\"SELL\", \"hash\":\"74ec647e78f638b59039e8965a74e48f9770d70d\", \"best_bid\":\"0.86\", \"best_ask\":\"0.87\"}], \"timestamp\":\"1789987929887\", \"event_type\":\"price_change\"}","raw_base64":null}
{"received_ms":1789987929910,"monotonic_ns":1019370740296200,"raw":"{\"market\":\"0x28a45972fccdaf0fba75dacc59725521035e177d09dd92174f9f52740bccb025\", \"price_changes\":[{\"asset_id\":\"61819828071723399190623735325323968706432622380635304641786792960078828866875\", \"price\":\"0.73\", \"size\":\"504\", \"side\":\"BUY\", \"hash\":\"5dba4593388552775cf54614c3aed6144c7fcf61\", \"best_bid\":\"0.86\", \"best_ask\":\"0.87\"}, {\"asset_id\":\"114356653315647913247200886351065428002113119844334520181865067698979836634569\", \"price\":\"0.27\", \"size\":\"504\", \"side\":\"SELL\", \"hash\":\"a5a22dc77132844bd3d250ba298509c8235a7d11\", \"best_bid\":\"0.13\", \"best_ask\":\"0.14\"}], \"timestamp\":\"1789987929889\", \"event_type\":\"price_change\"}","raw_base64":null}
{"received_ms":1789987929910,"monotonic_ns":1019370740760700,"raw":"{\"market\":\"0x28a45972fccdaf0fba75dacc59725521035e177d09dd92174f9f52740bccb025\", \"price_changes\":[{\"asset_id\":\"61819828071723399190623735325323968706432622380635304641786792960078828866875\", \"price\":\"0.75\", \"size\":\"500\", \"side\":\"BUY\", \"hash\":\"0c7decee9dca2077828fce58bd119e9c1051326a\", \"best_bid\":\"0.86\", \"best_ask\":\"0.87\"}, {\"asset_id\":\"114356653315647913247200886351065428002113119844334520181865067698979836634569\", \"price\":\"0.25\", \"size\":\"500\", \"side\":\"SELL\", \"hash\":\"70dd452a70c4c34e7b3c2c88a095e6e3a0efc8c6\", \"best_bid\":\"0.13\", \"best_ask\":\"0.14\"}], \"timestamp\":\"1789987929890\", \"event_type\":\"price_change\"}","raw_base64":null}
{"received_ms":1789987929914,"monotonic_ns":1019370744928000,"raw":"{\"market\":\"0x28a45972fccdaf0fba75dacc59725521035e177d09dd92174f9f52740bccb025\", \"price_changes\":[{\"asset_id\":\"61819828071723399190623735325323968706432622380635304641786792960078828866875\", \"price\":\"0.73\", \"size\":\"404\", \"side\":\"BUY\", \"hash\":\"1379f940ec141bbb8f2eb73ad0c80e24a55b9f4b\", \"best_bid\":\"0.86\", \"best_ask\":\"0.87\"}, {\"asset_id\":\"114356653315647913247200886351065428002113119844334520181865067698979836634569\", \"price\":\"0.27\", \"size\":\"404\", \"side\":\"SELL\", \"hash\":\"ae71e9aa10d85b86ffd241616003000105924938\", \"best_bid\":\"0.13\", \"best_ask\":\"0.14\"}], \"timestamp\":\"1789987929894\", \"event_type\":\"price_change\"}","raw_base64":null}
{"received_ms":1789987929934,"monotonic_ns":1019370764600400,"raw":"{\"market\":\"0x28a45972fccdaf0fba75dacc59725521035e177d09dd92174f9f52740bccb025\", \"price_changes\":[{\"asset_id\":\"61819828071723399190623735325323968706432622380635304641786792960078828866875\", \"price\":\"0.86\", \"size\":\"3707.97\", \"side\":\"BUY\", \"hash\":\"e382988954886c0bac0efdce1bf812bcf80e2681\", \"best_bid\":\"0.86\", \"best_ask\":\"0.87\"}, {\"asset_id\":\"114356653315647913247200886351065428002113119844334520181865067698979836634569\", \"price\":\"0.14\", \"size\":\"3707.97\", \"side\":\"SELL\", \"hash\":\"f8d4c34312cb1f6bc78e8f2c83642fe4b2cd28d9\", \"best_bid\":\"0.13\", \"best_ask\":\"0.14\"}], \"timestamp\":\"1789987929914\", \"event_type\":\"price_change\"}","raw_base64":null}
{"received_ms":1789987929962,"monotonic_ns":1019370792727600,"raw":"{\"market\":\"0x28a45972fccdaf0fba75dacc59725521035e177d09dd92174f9f52740bccb025\", \"price_changes\":[{\"asset_id\":\"114356653315647913247200886351065428002113119844334520181865067698979836634569\", \"price\":\"0.11\", \"size\":\"138.1\", \"side\":\"BUY\", \"hash\":\"99047c3eee4a611d9c66f3468c239a550afbd466\", \"best_bid\":\"0.13\", \"best_ask\":\"0.14\"}, {\"asset_id\":\"61819828071723399190623735325323968706432622380635304641786792960078828866875\", \"price\":\"0.89\", \"size\":\"138.1\", \"side\":\"SELL\", \"hash\":\"6cff29fb090e4c4a602529dbf8dd15b9692bde13\", \"best_bid\":\"0.86\", \"best_ask\":\"0.87\"}], \"timestamp\":\"1789987929939\", \"event_type\":\"price_change\"}","raw_base64":null}
{"received_ms":1789987929964,"monotonic_ns":1019370794348700,"raw":"{\"market\":\"0x28a45972fccdaf0fba75dacc59725521035e177d09dd92174f9f52740bccb025\", \"price_changes\":[{\"asset_id\":\"114356653315647913247200886351065428002113119844334520181865067698979836634569\", \"price\":\"0.09\", \"size\":\"618.12\", \"side\":\"BUY\", \"hash\":\"4087f20d6e41e8da8bb9c4ec3c321af3148e2138\", \"best_bid\":\"0.13\", \"best_ask\":\"0.14\"}, {\"asset_id\":\"61819828071723399190623735325323968706432622380635304641786792960078828866875\", \"price\":\"0.91\", \"size\":\"618.12\", \"side\":\"SELL\", \"hash\":\"861556ccf662e817afd6800bd54cf5df4f581413\", \"best_bid\":\"0.86\", \"best_ask\":\"0.87\"}], \"timestamp\":\"1789987929943\", \"event_type\":\"price_change\"}","raw_base64":null}
{"received_ms":1789987929964,"monotonic_ns":1019370794418900,"raw":"{\"market\":\"0x28a45972fccdaf0fba75dacc59725521035e177d09dd92174f9f52740bccb025\", \"price_changes\":[{\"asset_id\":\"114356653315647913247200886351065428002113119844334520181865067698979836634569\", \"price\":\"0.03\", \"size\":\"3992.57\", \"side\":\"BUY\", \"hash\":\"756752484a4cba04e5954db397bc716049bcadbc\", \"best_bid\":\"0.13\", \"best_ask\":\"0.14\"}, {\"asset_id\":\"61819828071723399190623735325323968706432622380635304641786792960078828866875\", \"price\":\"0.97\", \"size\":\"3992.57\", \"side\":\"SELL\", \"hash\":\"c7095225a0b02c8542b1ff8e2b20d13e06cb9340\", \"best_bid\":\"0.86\", \"best_ask\":\"0.87\"}], \"timestamp\":\"1789987929943\", \"event_type\":\"price_change\"}","raw_base64":null}
{"received_ms":1789987929980,"monotonic_ns":1019370810447700,"raw":"{\"market\":\"0x28a45972fccdaf0fba75dacc59725521035e177d09dd92174f9f52740bccb025\", \"price_changes\":[{\"asset_id\":\"61819828071723399190623735325323968706432622380635304641786792960078828866875\", \"price\":\"0.73\", \"size\":\"504\", \"side\":\"BUY\", \"hash\":\"6005cc0b319e532700f223c3dc1a210fd52bb575\", \"best_bid\":\"0.86\", \"best_ask\":\"0.87\"}, {\"asset_id\":\"114356653315647913247200886351065428002113119844334520181865067698979836634569\", \"price\":\"0.27\", \"size\":\"504\", \"side\":\"SELL\", \"hash\":\"08f8a0cff4bc0f591542439d9066be2c958d28c6\", \"best_bid\":\"0.13\", \"best_ask\":\"0.14\"}], \"timestamp\":\"1789987929958\", \"event_type\":\"price_change\"}","raw_base64":null}
{"received_ms":1789987929983,"monotonic_ns":1019370813782700,"raw":"{\"market\":\"0x28a45972fccdaf0fba75dacc59725521035e177d09dd92174f9f52740bccb025\", \"price_changes\":[{\"asset_id\":\"61819828071723399190623735325323968706432622380635304641786792960078828866875\", \"price\":\"0.73\", \"size\":\"404\", \"side\":\"BUY\", \"hash\":\"3509f2bd348d44bb0914843745441cc0d0136229\", \"best_bid\":\"0.86\", \"best_ask\":\"0.87\"}, {\"asset_id\":\"114356653315647913247200886351065428002113119844334520181865067698979836634569\", \"price\":\"0.27\", \"size\":\"404\", \"side\":\"SELL\", \"hash\":\"1ce11bb80165871f951be5d80eaf4133096eb4fb\", \"best_bid\":\"0.13\", \"best_ask\":\"0.14\"}], \"timestamp\":\"1789987929963\", \"event_type\":\"price_change\"}","raw_base64":null}
{"received_ms":1789987929986,"monotonic_ns":1019370816988400,"raw":"{\"market\":\"0x28a45972fccdaf0fba75dacc59725521035e177d09dd92174f9f52740bccb025\", \"price_changes\":[{\"asset_id\":\"114356653315647913247200886351065428002113119844334520181865067698979836634569\", \"price\":\"0.05\", \"size\":\"5633\", \"side\":\"BUY\", \"hash\":\"f8e93393530445bf9bea219266514aa10dfc5b07\", \"best_bid\":\"0.13\", \"best_ask\":\"0.14\"}, {\"asset_id\":\"61819828071723399190623735325323968706432622380635304641786792960078828866875\", \"price\":\"0.95\", \"size\":\"5633\", \"side\":\"SELL\", \"hash\":\"ad73da90f1a9c6fed72cd28cb09d1206f4046b70\", \"best_bid\":\"0.86\", \"best_ask\":\"0.87\"}], \"timestamp\":\"1789987929965\", \"event_type\":\"price_change\"}","raw_base64":null}
{"received_ms":1789987929987,"monotonic_ns":1019370818221000,"raw":"{\"market\":\"0x28a45972fccdaf0fba75dacc59725521035e177d09dd92174f9f52740bccb025\", \"price_changes\":[{\"asset_id\":\"114356653315647913247200886351065428002113119844334520181865067698979836634569\", \"price\":\"0.06\", \"size\":\"5354.67\", \"side\":\"BUY\", \"hash\":\"800e4c51263e3f33914da8f64b7ae3959b3f0c7a\", \"best_bid\":\"0.13\", \"best_ask\":\"0.14\"}, {\"asset_id\":\"61819828071723399190623735325323968706432622380635304641786792960078828866875\", \"price\":\"0.94\", \"size\":\"5354.67\", \"side\":\"SELL\", \"hash\":\"b142c222bfaaee2dc5eb4b188bb71e4f645d086c\", \"best_bid\":\"0.86\", \"best_ask\":\"0.87\"}], \"timestamp\":\"1789987929967\", \"event_type\":\"price_change\"}","raw_base64":null}
{"received_ms":1789987929994,"monotonic_ns":1019370824883800,"raw":"{\"market\":\"0x28a45972fccdaf0fba75dacc59725521035e177d09dd92174f9f52740bccb025\", \"price_changes\":[{\"asset_id\":\"114356653315647913247200886351065428002113119844334520181865067698979836634569\", \"price\":\"0.01\", \"size\":\"1689.43\", \"side\":\"BUY\", \"hash\":\"e916a585cdfde2fcf50233b8b451846a4dd88520\", \"best_bid\":\"0.13\", \"best_ask\":\"0.14\"}, {\"asset_id\":\"61819828071723399190623735325323968706432622380635304641786792960078828866875\", \"price\":\"0.99\", \"size\":\"1689.43\", \"side\":\"SELL\", \"hash\":\"3482c4ef395882f854070e2662f1bfb5d5a4332f\", \"best_bid\":\"0.86\", \"best_ask\":\"0.87\"}], \"timestamp\":\"1789987929974\", \"event_type\":\"price_change\"}","raw_base64":null}
{"received_ms":1789987930018,"monotonic_ns":1019370848862700,"raw":"{\"market\":\"0x28a45972fccdaf0fba75dacc59725521035e177d09dd92174f9f52740bccb025\", \"price_changes\":[{\"asset_id\":\"61819828071723399190623735325323968706432622380635304641786792960078828866875\", \"price\":\"0.86\", \"size\":\"3720.97\", \"side\":\"BUY\", \"hash\":\"a12322b82a863b36523c0bd5878de8dbca613edc\", \"best_bid\":\"0.86\", \"best_ask\":\"0.87\"}, {\"asset_id\":\"114356653315647913247200886351065428002113119844334520181865067698979836634569\", \"price\":\"0.14\", \"size\":\"3720.97\", \"side\":\"SELL\", \"hash\":\"f0f016f6a1a70a95b6206fd4acd395e51c68473a\", \"best_bid\":\"0.13\", \"best_ask\":\"0.14\"}], \"timestamp\":\"1789987929998\", \"event_type\":\"price_change\"}","raw_base64":null}
{"received_ms":1789987930019,"monotonic_ns":1019370849645000,"raw":"{\"market\":\"0x28a45972fccdaf0fba75dacc59725521035e177d09dd92174f9f52740bccb025\", \"price_changes\":[{\"asset_id\":\"61819828071723399190623735325323968706432622380635304641786792960078828866875\", \"price\":\"0.85\", \"size\":\"4777.35\", \"side\":\"BUY\", \"hash\":\"9d95f9ec44b5c23e39c3ffd36646d91ca9008737\", \"best_bid\":\"0.86\", \"best_ask\":\"0.87\"}, {\"asset_id\":\"114356653315647913247200886351065428002113119844334520181865067698979836634569\", \"price\":\"0.15\", \"size\":\"4777.35\", \"side\":\"SELL\", \"hash\":\"d43cb5a52a0804411ae408579740df08a3760b22\", \"best_bid\":\"0.13\", \"best_ask\":\"0.14\"}], \"timestamp\":\"1789987929999\", \"event_type\":\"price_change\"}","raw_base64":null}
{"received_ms":1789987930047,"monotonic_ns":1019370878050400,"raw":"{\"market\":\"0x28a45972fccdaf0fba75dacc59725521035e177d09dd92174f9f52740bccb025\", \"price_changes\":[{\"asset_id\":\"61819828071723399190623735325323968706432622380635304641786792960078828866875\", \"price\":\"0.73\", \"size\":\"504\", \"side\":\"BUY\", \"hash\":\"fad55726b9dca8cc6c014ed05213735f35c4565a\", \"best_bid\":\"0.86\", \"best_ask\":\"0.87\"}, {\"asset_id\":\"114356653315647913247200886351065428002113119844334520181865067698979836634569\", \"price\":\"0.27\", \"size\":\"504\", \"side\":\"SELL\", \"hash\":\"930480091613e344ca6064a44d639c2026e0ee87\", \"best_bid\":\"0.13\", \"best_ask\":\"0.14\"}], \"timestamp\":\"1789987930026\", \"event_type\":\"price_change\"}","raw_base64":null}
{"received_ms":1789987930048,"monotonic_ns":1019370878882400,"raw":"{\"market\":\"0x28a45972fccdaf0fba75dacc59725521035e177d09dd92174f9f52740bccb025\", \"price_changes\":[{\"asset_id\":\"61819828071723399190623735325323968706432622380635304641786792960078828866875\", \"price\":\"0.73\", \"size\":\"404\", \"side\":\"BUY\", \"hash\":\"35e3d6ac5206da48bbbc27f43e3ea80624c34813\", \"best_bid\":\"0.86\", \"best_ask\":\"0.87\"}, {\"asset_id\":\"114356653315647913247200886351065428002113119844334520181865067698979836634569\", \"price\":\"0.27\", \"size\":\"404\", \"side\":\"SELL\", \"hash\":\"ffab3633d7fcc4627a19589d08df0bacc76494f0\", \"best_bid\":\"0.13\", \"best_ask\":\"0.14\"}], \"timestamp\":\"1789987930027\", \"event_type\":\"price_change\"}","raw_base64":null}
{"received_ms":1789987930062,"monotonic_ns":1019370892398800,"raw":"{\"market\":\"0x28a45972fccdaf0fba75dacc59725521035e177d09dd92174f9f52740bccb025\", \"price_changes\":[{\"asset_id\":\"114356653315647913247200886351065428002113119844334520181865067698979836634569\", \"price\":\"0.01\", \"size\":\"1694.43\", \"side\":\"BUY\", \"hash\":\"f6723c7e3071d26c279a76937f8995ed1a7e504b\", \"best_bid\":\"0.13\", \"best_ask\":\"0.14\"}, {\"asset_id\":\"61819828071723399190623735325323968706432622380635304641786792960078828866875\", \"price\":\"0.99\", \"size\":\"1694.43\", \"side\":\"SELL\", \"hash\":\"d9d6b1bc92f7db24e33c36917c8b295721de6560\", \"best_bid\":\"0.86\", \"best_ask\":\"0.87\"}], \"timestamp\":\"1789987930042\", \"event_type\":\"price_change\"}","raw_base64":null}
{"received_ms":1789987930082,"monotonic_ns":1019370912660900,"raw":"{\"market\":\"0x28a45972fccdaf0fba75dacc59725521035e177d09dd92174f9f52740bccb025\", \"price_changes\":[{\"asset_id\":\"61819828071723399190623735325323968706432622380635304641786792960078828866875\", \"price\":\"0.75\", \"size\":\"520\", \"side\":\"BUY\", \"hash\":\"af83b9cc35a12ed3502162f783856daa4caa5bba\", \"best_bid\":\"0.86\", \"best_ask\":\"0.87\"}, {\"asset_id\":\"114356653315647913247200886351065428002113119844334520181865067698979836634569\", \"price\":\"0.25\", \"size\":\"520\", \"side\":\"SELL\", \"hash\":\"4cef0a142e2828ca24f423dea0ee14e374f694f2\", \"best_bid\":\"0.13\", \"best_ask\":\"0.14\"}], \"timestamp\":\"1789987930062\", \"event_type\":\"price_change\"}","raw_base64":null}
{"received_ms":1789987930083,"monotonic_ns":1019370913887600,"raw":"{\"market\":\"0x28a45972fccdaf0fba75dacc59725521035e177d09dd92174f9f52740bccb025\", \"price_changes\":[{\"asset_id\":\"61819828071723399190623735325323968706432622380635304641786792960078828866875\", \"price\":\"0.79\", \"size\":\"487\", \"side\":\"BUY\", \"hash\":\"8fd7c186a73c5e709b7a2ef4eded90598e06a52d\", \"best_bid\":\"0.86\", \"best_ask\":\"0.87\"}, {\"asset_id\":\"114356653315647913247200886351065428002113119844334520181865067698979836634569\", \"price\":\"0.21\", \"size\":\"487\", \"side\":\"SELL\", \"hash\":\"5dbb4835f80fbf97fc5b7e79d7a4dac15bf02a27\", \"best_bid\":\"0.13\", \"best_ask\":\"0.14\"}], \"timestamp\":\"1789987930063\", \"event_type\":\"price_change\"}","raw_base64":null}
{"received_ms":1789987930084,"monotonic_ns":1019370914910800,"raw":"{\"market\":\"0x28a45972fccdaf0fba75dacc59725521035e177d09dd92174f9f52740bccb025\", \"price_changes\":[{\"asset_id\":\"61819828071723399190623735325323968706432622380635304641786792960078828866875\", \"price\":\"0.77\", \"size\":\"567.49\", \"side\":\"BUY\", \"hash\":\"f530876bfb4adcf346b97fde6260ea49c5b2a109\", \"best_bid\":\"0.86\", \"best_ask\":\"0.87\"}, {\"asset_id\":\"114356653315647913247200886351065428002113119844334520181865067698979836634569\", \"price\":\"0.23\", \"size\":\"567.49\", \"side\":\"SELL\", \"hash\":\"12c7cac76cdafe1c3317ed5755011619ca2727aa\", \"best_bid\":\"0.13\", \"best_ask\":\"0.14\"}], \"timestamp\":\"1789987930064\", \"event_type\":\"price_change\"}","raw_base64":null}
{"received_ms":1789987930085,"monotonic_ns":1019370915941500,"raw":"{\"market\":\"0x28a45972fccdaf0fba75dacc59725521035e177d09dd92174f9f52740bccb025\", \"price_changes\":[{\"asset_id\":\"61819828071723399190623735325323968706432622380635304641786792960078828866875\", \"price\":\"0.75\", \"size\":\"500\", \"side\":\"BUY\", \"hash\":\"2099aa928352d1ca065eed866dd1a5de25c22861\", \"best_bid\":\"0.86\", \"best_ask\":\"0.87\"}, {\"asset_id\":\"114356653315647913247200886351065428002113119844334520181865067698979836634569\", \"price\":\"0.25\", \"size\":\"500\", \"side\":\"SELL\", \"hash\":\"5faf1970d64c5955f2eb2ca2cd5be74510551e3e\", \"best_bid\":\"0.13\", \"best_ask\":\"0.14\"}], \"timestamp\":\"1789987930065\", \"event_type\":\"price_change\"}","raw_base64":null}
{"received_ms":1789987930086,"monotonic_ns":1019370916275300,"raw":"{\"market\":\"0x28a45972fccdaf0fba75dacc59725521035e177d09dd92174f9f52740bccb025\", \"price_changes\":[{\"asset_id\":\"61819828071723399190623735325323968706432622380635304641786792960078828866875\", \"price\":\"0.77\", \"size\":\"547.49\", \"side\":\"BUY\", \"hash\":\"2099aa928352d1ca065eed866dd1a5de25c22861\", \"best_bid\":\"0.86\", \"best_ask\":\"0.87\"}, {\"asset_id\":\"114356653315647913247200886351065428002113119844334520181865067698979836634569\", \"price\":\"0.23\", \"size\":\"547.49\", \"side\":\"SELL\", \"hash\":\"5faf1970d64c5955f2eb2ca2cd5be74510551e3e\", \"best_bid\":\"0.13\", \"best_ask\":\"0.14\"}], \"timestamp\":\"1789987930065\", \"event_type\":\"price_change\"}","raw_base64":null}
{"received_ms":1789987930086,"monotonic_ns":1019370916339400,"raw":"{\"market\":\"0x28a45972fccdaf0fba75dacc59725521035e177d09dd92174f9f52740bccb025\", \"price_changes\":[{\"asset_id\":\"61819828071723399190623735325323968706432622380635304641786792960078828866875\", \"price\":\"0.79\", \"size\":\"427\", \"side\":\"BUY\", \"hash\":\"2099aa928352d1ca065eed866dd1a5de25c22861\", \"best_bid\":\"0.86\", \"best_ask\":\"0.87\"}, {\"asset_id\":\"114356653315647913247200886351065428002113119844334520181865067698979836634569\", \"price\":\"0.21\", \"size\":\"427\", \"side\":\"SELL\", \"hash\":\"5faf1970d64c5955f2eb2ca2cd5be74510551e3e\", \"best_bid\":\"0.13\", \"best_ask\":\"0.14\"}], \"timestamp\":\"1789987930065\", \"event_type\":\"price_change\"}","raw_base64":null}
{"received_ms":1789987930099,"monotonic_ns":1019370929640200,"raw":"{\"market\":\"0x28a45972fccdaf0fba75dacc59725521035e177d09dd92174f9f52740bccb025\", \"price_changes\":[{\"asset_id\":\"61819828071723399190623735325323968706432622380635304641786792960078828866875\", \"price\":\"0.01\", \"size\":\"1496.91\", \"side\":\"BUY\", \"hash\":\"5616508a8b3b0620e762048b0af55328a99b91c0\", \"best_bid\":\"0.86\", \"best_ask\":\"0.87\"}, {\"asset_id\":\"114356653315647913247200886351065428002113119844334520181865067698979836634569\", \"price\":\"0.99\", \"size\":\"1496.91\", \"side\":\"SELL\", \"hash\":\"e56016821bac110e784d375cecf5dda20d640846\", \"best_bid\":\"0.13\", \"best_ask\":\"0.14\"}], \"timestamp\":\"1789987930077\", \"event_type\":\"price_change\"}","raw_base64":null}
{"received_ms":1789987930100,"monotonic_ns":1019370930963600,"raw":"{\"market\":\"0x28a45972fccdaf0fba75dacc59725521035e177d09dd92174f9f52740bccb025\", \"price_changes\":[{\"asset_id\":\"114356653315647913247200886351065428002113119844334520181865067698979836634569\", \"price\":\"0.05\", \"size\":\"5628\", \"side\":\"BUY\", \"hash\":\"0bc30b8a3742377fd1a263e4271adc595788eae3\", \"best_bid\":\"0.13\", \"best_ask\":\"0.14\"}, {\"asset_id\":\"61819828071723399190623735325323968706432622380635304641786792960078828866875\", \"price\":\"0.95\", \"size\":\"5628\", \"side\":\"SELL\", \"hash\":\"8d7c3fdf6041374712efc289f5bb55d0ab44cab1\", \"best_bid\":\"0.86\", \"best_ask\":\"0.87\"}], \"timestamp\":\"1789987930080\", \"event_type\":\"price_change\"}","raw_base64":null}
{"received_ms":1789987930106,"monotonic_ns":1019370936738300,"raw":"{\"market\":\"0x28a45972fccdaf0fba75dacc59725521035e177d09dd92174f9f52740bccb025\", \"price_changes\":[{\"asset_id\":\"114356653315647913247200886351065428002113119844334520181865067698979836634569\", \"price\":\"0.07\", \"size\":\"7874.71\", \"side\":\"BUY\", \"hash\":\"c1ad8b981d274aeef71bd9a7541dded9e6e278bc\", \"best_bid\":\"0.13\", \"best_ask\":\"0.14\"}, {\"asset_id\":\"61819828071723399190623735325323968706432622380635304641786792960078828866875\", \"price\":\"0.93\", \"size\":\"7874.71\", \"side\":\"SELL\", \"hash\":\"ca8fff6f7dd96774b5b26227bf88d3fc3aa04142\", \"best_bid\":\"0.86\", \"best_ask\":\"0.87\"}], \"timestamp\":\"1789987930086\", \"event_type\":\"price_change\"}","raw_base64":null}
{"received_ms":1789987930114,"monotonic_ns":1019370945085900,"raw":"{\"market\":\"0x28a45972fccdaf0fba75dacc59725521035e177d09dd92174f9f52740bccb025\", \"price_changes\":[{\"asset_id\":\"61819828071723399190623735325323968706432622380635304641786792960078828866875\", \"price\":\"0.73\", \"size\":\"504\", \"side\":\"BUY\", \"hash\":\"385496d0d3cb8d1968e0ee6a09532852bed90c84\", \"best_bid\":\"0.86\", \"best_ask\":\"0.87\"}, {\"asset_id\":\"114356653315647913247200886351065428002113119844334520181865067698979836634569\", \"price\":\"0.27\", \"size\":\"504\", \"side\":\"SELL\", \"hash\":\"5f04e9c5c42332d5bea515190210acb7f3adcbe0\", \"best_bid\":\"0.13\", \"best_ask\":\"0.14\"}], \"timestamp\":\"1789987930094\", \"event_type\":\"price_change\"}","raw_base64":null}
