{"received_ms":1789987927016,"monotonic_ns":1019367846802500,"raw":"{\"market\":\"0x28a45972fccdaf0fba75dacc59725521035e177d09dd92174f9f52740bccb025\", \"price_changes\":[{\"asset_id\":\"61819828071723399190623735325323968706432622380635304641786792960078828866875\", \"price\":\"0.86\", \"size\":\"5318.17\", \"side\":\"BUY\", \"hash\":\"1add477de9c6ebe72e662cd1363f26c42dca63c0\", \"best_bid\":\"0.86\", \"best_ask\":\"0.87\"}, {\"asset_id\":\"114356653315647913247200886351065428002113119844334520181865067698979836634569\", \"price\":\"0.14\", \"size\":\"5318.17\", \"side\":\"SELL\", \"hash\":\"b0910fcecc8d8e809c3126821b19bf8e5a66ede9\", \"best_bid\":\"0.13\", \"best_ask\":\"0.14\"}], \"timestamp\":\"1789987926992\", \"event_type\":\"price_change\"}","raw_base64":null}
{"received_ms":1789987927032,"monotonic_ns":1019367862977800,"raw":"{\"market\":\"0x28a45972fccdaf0fba75dacc59725521035e177d09dd92174f9f52740bccb025\", \"price_changes\":[{\"asset_id\":\"114356653315647913247200886351065428002113119844334520181865067698979836634569\", \"price\":\"0.13\", \"size\":\"255\", \"side\":\"BUY\", \"hash\":\"973c75f22969cf775c43fdbf27ff3f46115d9b57\", \"best_bid\":\"0.13\", \"best_ask\":\"0.14\"}, {\"asset_id\":\"61819828071723399190623735325323968706432622380635304641786792960078828866875\", \"price\":\"0.87\", \"size\":\"255\", \"side\":\"SELL\", \"hash\":\"ecc0a2dc759722db92e62a2e40126c8abdffa46e\", \"best_bid\":\"0.86\", \"best_ask\":\"0.87\"}], \"timestamp\":\"1789987926993\", \"event_type\":\"price_change\"}","raw_base64":null}
{"received_ms":1789987927032,"monotonic_ns":1019367863024300,"raw":"{\"market\":\"0x28a45972fccdaf0fba75dacc59725521035e177d09dd92174f9f52740bccb025\", \"price_changes\":[{\"asset_id\":\"61819828071723399190623735325323968706432622380635304641786792960078828866875\", \"price\":\"0.8\", \"size\":\"582\", \"side\":\"BUY\", \"hash\":\"d559dd22df0491ed8782d12836acaf8318e1232d\", \"best_bid\":\"0.86\", \"best_ask\":\"0.87\"}, {\"asset_id\":\"114356653315647913247200886351065428002113119844334520181865067698979836634569\", \"price\":\"0.2\", \"size\":\"582\", \"side\":\"SELL\", \"hash\":\"5a9cf5503d055c617b73d7e4f36148dc2ca9a700\", \"best_bid\":\"0.13\", \"best_ask\":\"0.14\"}], \"timestamp\":\"1789987926996\", \"event_type\":\"price_change\"}","raw_base64":null}
{"received_ms":1789987927032,"monotonic_ns":1019367863076200,"raw":"{\"market\":\"0x28a45972fccdaf0fba75dacc59725521035e177d09dd92174f9f52740bccb025\", \"price_changes\":[{\"asset_id\":\"61819828071723399190623735325323968706432622380635304641786792960078828866875\", \"price\":\"0.85\", \"size\":\"4657.35\", \"side\":\"BUY\", \"hash\":\"b047974282261571726c69f53dbab500eeaf65cd\", \"best_bid\":\"0.86\", \"best_ask\":\"0.87\"}, {\"asset_id\":\"114356653315647913247200886351065428002113119844334520181865067698979836634569\", \"price\":\"0.15\", \"size\":\"4657.35\", \"side\":\"SELL\", \"hash\":\"a3d19412d80bd13a36715d3666b1797316d196d9\", \"best_bid\":\"0.13\", \"best_ask\":\"0.14\"}], \"timestamp\":\"1789987927002\", \"event_type\":\"price_change\"}","raw_base64":null}
{"received_ms":1789987927032,"monotonic_ns":1019367863114800,"raw":"{\"market\":\"0x28a45972fccdaf0fba75dacc59725521035e177d09dd92174f9f52740bccb025\", \"price_changes\":[{\"asset_id\":\"114356653315647913247200886351065428002113119844334520181865067698979836634569\", \"price\":\"0.05\", \"size\":\"5714\", \"side\":\"BUY\", \"hash\":\"2911ab4c68d8b8ffb5e0b671a1673c895a6ad6f5\", \"best_bid\":\"0.13\", \"best_ask\":\"0.14\"}, {\"asset_id\":\"61819828071723399190623735325323968706432622380635304641786792960078828866875\", \"price\":\"0.95\", \"size\":\"5714\", \"side\":\"SELL\", \"hash\":\"7d25d812d7628eef0e897768c6c4ee28b60bf097\", \"best_bid\":\"0.86\", \"best_ask\":\"0.87\"}], \"timestamp\":\"1789987927005\", \"event_type\":\"price_change\"}","raw_base64":null}
{"received_ms":1789987927032,"monotonic_ns":1019367863151600,"raw":"{\"market\":\"0x28a45972fccdaf0fba75dacc59725521035e177d09dd92174f9f52740bccb025\", \"price_changes\":[{\"asset_id\":\"114356653315647913247200886351065428002113119844334520181865067698979836634569\", \"price\":\"0.07\", \"size\":\"5594.71\", \"side\":\"BUY\", \"hash\":\"9f85f6b427e3ba6c51d5b6db4c6a1783fe6dac8b\", \"best_bid\":\"0.13\", \"best_ask\":\"0.14\"}, {\"asset_id\":\"61819828071723399190623735325323968706432622380635304641786792960078828866875\", \"price\":\"0.93\", \"size\":\"5594.71\", \"side\":\"SELL\", \"hash\":\"d794d918a8782055d9c378067ec388aafefcd8a2\", \"best_bid\":\"0.86\", \"best_ask\":\"0.87\"}], \"timestamp\":\"1789987927006\", \"event_type\":\"price_change\"}","raw_base64":null}
{"received_ms":1789987927032,"monotonic_ns":1019367863194000,"raw":"{\"market\":\"0x28a45972fccdaf0fba75dacc59725521035e177d09dd92174f9f52740bccb025\", \"price_changes\":[{\"asset_id\":\"114356653315647913247200886351065428002113119844334520181865067698979836634569\", \"price\":\"0.06\", \"size\":\"5946.67\", \"side\":\"BUY\", \"hash\":\"ae704fee917d9ec59abecde446522bd6d6ef9de9\", \"best_bid\":\"0.13\", \"best_ask\":\"0.14\"}, {\"asset_id\":\"61819828071723399190623735325323968706432622380635304641786792960078828866875\", \"price\":\"0.94\", \"size\":\"5946.67\", \"side\":\"SELL\", \"hash\":\"16c1b9b8941732b84ddb3cf1b6e473f53b3c9258\", \"best_bid\":\"0.86\", \"best_ask\":\"0.87\"}], \"timestamp\":\"1789987927006\", \"event_type\":\"price_change\"}","raw_base64":null}
{"received_ms":1789987927033,"monotonic_ns":1019367864152000,"raw":"{\"market\":\"0x28a45972fccdaf0fba75dacc59725521035e177d09dd92174f9f52740bccb025\", \"price_changes\":[{\"asset_id\":\"61819828071723399190623735325323968706432622380635304641786792960078828866875\", \"price\":\"0.79\", \"size\":\"527\", \"side\":\"BUY\", \"hash\":\"e49a688a6450c4c8f3f09e1443ac175741db51eb\", \"best_bid\":\"0.86\", \"best_ask\":\"0.87\"}, {\"asset_id\":\"114356653315647913247200886351065428002113119844334520181865067698979836634569\", \"price\":\"0.21\", \"size\":\"527\", \"side\":\"SELL\", \"hash\":\"63667861f54cf8acd65f93ebb4b0447a5467e303\", \"best_bid\":\"0.13\", \"best_ask\":\"0.14\"}], \"timestamp\":\"1789987927012\", \"event_type\":\"price_change\"}","raw_base64":null}
{"received_ms":1789987927042,"monotonic_ns":1019367872492900,"raw":"{\"market\":\"0x28a45972fccdaf0fba75dacc59725521035e177d09dd92174f9f52740bccb025\", \"price_changes\":[{\"asset_id\":\"61819828071723399190623735325323968706432622380635304641786792960078828866875\", \"price\":\"0.86\", \"size\":\"5283.17\", \"side\":\"BUY\", \"hash\":\"68622e23a7243329249228d3eb8ea7ca111b4f80\", \"best_bid\":\"0.86\", \"best_ask\":\"0.87\"}, {\"asset_id\":\"114356653315647913247200886351065428002113119844334520181865067698979836634569\", \"price\":\"0.14\", \"size\":\"5283.17\", \"side\":\"SELL\", \"hash\":\"48fcdbfc1d5d23cc92a1c9f2215c5872cc6616df\", \"best_bid\":\"0.13\", \"best_ask\":\"0.14\"}], \"timestamp\":\"1789987927021\", \"event_type\":\"price_change\"}","raw_base64":null}
{"received_ms":1789987927062,"monotonic_ns":1019367893263100,"raw":"{\"market\":\"0x28a45972fccdaf0fba75dacc59725521035e177d09dd92174f9f52740bccb025\", \"price_changes\":[{\"asset_id\":\"61819828071723399190623735325323968706432622380635304641786792960078828866875\", \"price\":\"0.01\", \"size\":\"1496.91\", \"side\":\"BUY\", \"hash\":\"2ae6a29b12339122f73c17bd8f2db4aa77855a2e\", \"best_bid\":\"0.86\", \"best_ask\":\"0.87\"}, {\"asset_id\":\"114356653315647913247200886351065428002113119844334520181865067698979836634569\", \"price\":\"0.99\", \"size\":\"1496.91\", \"side\":\"SELL\", \"hash\":\"2d362fffbd944216706f14df0ee9995a544bd244\", \"best_bid\":\"0.13\", \"best_ask\":\"0.14\"}], \"timestamp\":\"1789987927034\", \"event_type\":\"price_change\"}","raw_base64":null}
{"received_ms":1789987927063,"monotonic_ns":1019367893345200,"raw":"{\"market\":\"0x28a45972fccdaf0fba75dacc59725521035e177d09dd92174f9f52740bccb025\", \"price_changes\":[{\"asset_id\":\"114356653315647913247200886351065428002113119844334520181865067698979836634569\", \"price\":\"0.1\", \"size\":\"497\", \"side\":\"BUY\", \"hash\":\"3ffd19b8a7e092f7d6cbd2c179e9caba0e1bb172\", \"best_bid\":\"0.13\", \"best_ask\":\"0.14\"}, {\"asset_id\":\"61819828071723399190623735325323968706432622380635304641786792960078828866875\", \"price\":\"0.9\", \"size\":\"497\", \"side\":\"SELL\", \"hash\":\"2d5cb8005f12a960e91d1dd3fa8cd075bbdb852c\", \"best_bid\":\"0.86\", \"best_ask\":\"0.87\"}], \"timestamp\":\"1789987927036\", \"event_type\":\"price_change\"}","raw_base64":null}
{"received_ms":1789987927063,"monotonic_ns":1019367893389500,"raw":"{\"market\":\"0x28a45972fccdaf0fba75dacc59725521035e177d09dd92174f9f52740bccb025\", \"price_changes\":[{\"asset_id\":\"114356653315647913247200886351065428002113119844334520181865067698979836634569\", \"price\":\"0.06\", \"size\":\"6864.67\", \"side\":\"BUY\", \"hash\":\"cb7cca9ef65f429c6410bd60cf3d5e5aaa9f333e\", \"best_bid\":\"0.13\", \"best_ask\":\"0.14\"}, {\"asset_id\":\"61819828071723399190623735325323968706432622380635304641786792960078828866875\", \"price\":\"0.94\", \"size\":\"6864.67\", \"side\":\"SELL\", \"hash\":\"f8594a3555f60408ecbde55a67512df5f82d7bd6\", \"best_bid\":\"0.86\", \"best_ask\":\"0.87\"}], \"timestamp\":\"1789987927040\", \"event_type\":\"price_change\"}","raw_base64":null}
{"received_ms":1789987927064,"monotonic_ns":1019367894473500,"raw":"{\"market\":\"0x28a45972fccdaf0fba75dacc59725521035e177d09dd92174f9f52740bccb025\", \"price_changes\":[{\"asset_id\":\"114356653315647913247200886351065428002113119844334520181865067698979836634569\", \"price\":\"0.01\", \"size\":\"1694.43\", \"side\":\"BUY\", \"hash\":\"a4676870834a0e1c94c0897826c8259cd30225fa\", \"best_bid\":\"0.13\", \"best_ask\":\"0.14\"}, {\"asset_id\":\"61819828071723399190623735325323968706432622380635304641786792960078828866875\", \"price\":\"0.99\", \"size\":\"1694.43\", \"side\":\"SELL\", \"hash\":\"1b0a3913a3f3bb494e605b864f2c021c4be90d1d\", \"best_bid\":\"0.86\", \"best_ask\":\"0.87\"}], \"timestamp\":\"1789987927041\", \"event_type\":\"price_change\"}","raw_base64":null}
{"received_ms":1789987927064,"monotonic_ns":1019367894559900,"raw":"{\"market\":\"0x28a45972fccdaf0fba75dacc59725521035e177d09dd92174f9f52740bccb025\", \"price_changes\":[{\"asset_id\":\"61819828071723399190623735325323968706432622380635304641786792960078828866875\", \"price\":\"0.85\", \"size\":\"5157.35\", \"side\":\"BUY\", \"hash\":\"3f478cfe600bf1e187614d1620fcb4908e015456\", \"best_bid\":\"0.86\", \"best_ask\":\"0.87\"}, {\"asset_id\":\"114356653315647913247200886351065428002113119844334520181865067698979836634569\", \"price\":\"0.15\", \"size\":\"5157.35\", \"side\":\"SELL\", \"hash\":\"3b049334c7f6ba2762bc52506af01e91591146be\", \"best_bid\":\"0.13\", \"best_ask\":\"0.14\"}], \"timestamp\":\"1789987927042\", \"event_type\":\"price_change\"}","raw_base64":null}
{"received_ms":1789987927065,"monotonic_ns":1019367895782200,"raw":"{\"market\":\"0x28a45972fccdaf0fba75dacc59725521035e177d09dd92174f9f52740bccb025\", \"price_changes\":[{\"asset_id\":\"61819828071723399190623735325323968706432622380635304641786792960078828866875\", \"price\":\"0.86\", \"size\":\"5576.17\", \"side\":\"BUY\", \"hash\":\"25474cddecbc611c96575e4ce9b17ed91ec8a71b\", \"best_bid\":\"0.86\", \"best_ask\":\"0.87\"}, {\"asset_id\":\"114356653315647913247200886351065428002113119844334520181865067698979836634569\", \"price\":\"0.14\", \"size\":\"5576.17\", \"side\":\"SELL\", \"hash\":\"67ae793c37b1c43a093aea4283bcfa52da84eee5\", \"best_bid\":\"0.13\", \"best_ask\":\"0.14\"}], \"timestamp\":\"1789987927043\", \"event_type\":\"price_change\"}","raw_base64":null}
{"received_ms":1789987927065,"monotonic_ns":1019367895871700,"raw":"{\"market\":\"0x28a45972fccdaf0fba75dacc59725521035e177d09dd92174f9f52740bccb025\", \"price_changes\":[{\"asset_id\":\"61819828071723399190623735325323968706432622380635304641786792960078828866875\", \"price\":\"0.84\", \"size\":\"3577\", \"side\":\"BUY\", \"hash\":\"a9662da549c743780472eec7e29815cfdf0b8c2a\", \"best_bid\":\"0.86\", \"best_ask\":\"0.87\"}, {\"asset_id\":\"114356653315647913247200886351065428002113119844334520181865067698979836634569\", \"price\":\"0.16\", \"size\":\"3577\", \"side\":\"SELL\", \"hash\":\"3c38c2f959c8536d1407c2164ad3382d01e7379b\", \"best_bid\":\"0.13\", \"best_ask\":\"0.14\"}], \"timestamp\":\"1789987927044\", \"event_type\":\"price_change\"}","raw_base64":null}
{"received_ms":1789987927069,"monotonic_ns":1019367899760300,"raw":"{\"market\":\"0x28a45972fccdaf0fba75dacc59725521035e177d09dd92174f9f52740bccb025\", \"price_changes\":[{\"asset_id\":\"114356653315647913247200886351065428002113119844334520181865067698979836634569\", \"price\":\"0.07\", \"size\":\"5682.71\", \"side\":\"BUY\", \"hash\":\"351d50bb2176a53770e96dd8c07a095b2a07a92e\", \"best_bid\":\"0.13\", \"best_ask\":\"0.14\"}, {\"asset_id\":\"61819828071723399190623735325323968706432622380635304641786792960078828866875\", \"price\":\"0.93\", \"size\":\"5682.71\", \"side\":\"SELL\", \"hash\":\"4ce04d7f61f54642093532f54d0ca0c5b41a7c55\", \"best_bid\":\"0.86\", \"best_ask\":\"0.87\"}], \"timestamp\":\"1789987927045\", \"event_type\":\"price_change\"}","raw_base64":null}
{"received_ms":1789987927069,"monotonic_ns":1019367899857200,"raw":"{\"market\":\"0x28a45972fccdaf0fba75dacc59725521035e177d09dd92174f9f52740bccb025\", \"price_changes\":[{\"asset_id\":\"61819828071723399190623735325323968706432622380635304641786792960078828866875\", \"price\":\"0.81\", \"size\":\"610\", \"side\":\"BUY\", \"hash\":\"17f5af34d4e51c1a5ca652d01b7e5e75533f5c87\", \"best_bid\":\"0.86\", \"best_ask\":\"0.87\"}, {\"asset_id\":\"114356653315647913247200886351065428002113119844334520181865067698979836634569\", \"price\":\"0.19\", \"size\":\"610\", \"side\":\"SELL\", \"hash\":\"756b0a38182d7743b4131edee71e2f65b0d6c111\", \"best_bid\":\"0.13\", \"best_ask\":\"0.14\"}], \"timestamp\":\"1789987927046\", \"event_type\":\"price_change\"}","raw_base64":null}
{"received_ms":1789987927069,"monotonic_ns":1019367899901600,"raw":"{\"market\":\"0x28a45972fccdaf0fba75dacc59725521035e177d09dd92174f9f52740bccb025\", \"price_changes\":[{\"asset_id\":\"61819828071723399190623735325323968706432622380635304641786792960078828866875\", \"price\":\"0.81\", \"size\":\"590\", \"side\":\"BUY\", \"hash\":\"94ce47a0d439413a80f51a11c4768646f635216b\", \"best_bid\":\"0.86\", \"best_ask\":\"0.87\"}, {\"asset_id\":\"114356653315647913247200886351065428002113119844334520181865067698979836634569\", \"price\":\"0.19\", \"size\":\"590\", \"side\":\"SELL\", \"hash\":\"3ae296bca730948eff0d8a85e8d28ca44587b30d\", \"best_bid\":\"0.13\", \"best_ask\":\"0.14\"}], \"timestamp\":\"1789987927047\", \"event_type\":\"price_change\"}","raw_base64":null}
{"received_ms":1789987927090,"monotonic_ns":1019367920529100,"raw":"{\"market\":\"0x28a45972fccdaf0fba75dacc59725521035e177d09dd92174f9f52740bccb025\", \"price_changes\":[{\"asset_id\":\"114356653315647913247200886351065428002113119844334520181865067698979836634569\", \"price\":\"0.1\", \"size\":\"517\", \"side\":\"BUY\", \"hash\":\"9c947ee61c6a670374d81bf22ca0d8bae92efd3b\", \"best_bid\":\"0.13\", \"best_ask\":\"0.14\"}, {\"asset_id\":\"61819828071723399190623735325323968706432622380635304641786792960078828866875\", \"price\":\"0.9\", \"size\":\"517\", \"side\":\"SELL\", \"hash\":\"d7684c3c7b4844ddf290962f770f075a7c6fd059\", \"best_bid\":\"0.86\", \"best_ask\":\"0.87\"}], \"timestamp\":\"1789987927068\", \"event_type\":\"price_change\"}","raw_base64":null}
{"received_ms":1789987927094,"monotonic_ns":1019367924815400,"raw":"{\"market\":\"0x28a45972fccdaf0fba75dacc59725521035e177d09dd92174f9f52740bccb025\", \"price_changes\":[{\"asset_id\":\"114356653315647913247200886351065428002113119844334520181865067698979836634569\", \"price\":\"0.07\", \"size\":\"5418.71\", \"side\":\"BUY\", \"hash\":\"3662fdc459efc49d849ada955e1f74b74846665c\", \"best_bid\":\"0.13\", \"best_ask\":\"0.14\"}, {\"asset_id\":\"61819828071723399190623735325323968706432622380635304641786792960078828866875\", \"price\":\"0.93\", \"size\":\"5418.71\", \"side\":\"SELL\", \"hash\":\"40b489842d1b8dca9866bbbb509d6d0c8c95613e\", \"best_bid\":\"0.86\", \"best_ask\":\"0.87\"}], \"timestamp\":\"1789987927070\", \"event_type\":\"price_change\"}","raw_base64":null}
{"received_ms":1789987927094,"monotonic_ns":1019367924867200,"raw":"{\"market\":\"0x28a45972fccdaf0fba75dacc59725521035e177d09dd92174f9f52740bccb025\", \"price_changes\":[{\"asset_id\":\"114356653315647913247200886351065428002113119844334520181865067698979836634569\", \"price\":\"0.1\", \"size\":\"497\", \"side\":\"BUY\", \"hash\":\"782ffebe463264ac9c5825a36d86db73030d9a72\", \"best_bid\":\"0.13\", \"best_ask\":\"0.14\"}, {\"asset_id\":\"61819828071723399190623735325323968706432622380635304641786792960078828866875\", \"price\":\"0.9\", \"size\":\"497\", \"side\":\"SELL\", \"hash\":\"2046ef3465a795bdbc8aa159cd636bfc2f1bdbdf\", \"best_bid\":\"0.86\", \"best_ask\":\"0.87\"}], \"timestamp\":\"1789987927073\", \"event_type\":\"price_change\"}","raw_base64":null}
{"received_ms":1789987927094,"monotonic_ns":1019367924910000,"raw":"{\"market\":\"0x28a45972fccdaf0fba75dacc59725521035e177d09dd92174f9f52740bccb025\", \"price_changes\":[{\"asset_id\":\"114356653315647913247200886351065428002113119844334520181865067698979836634569\", \"price\":\"0.07\", \"size\":\"5330.71\", \"side\":\"BUY\", \"hash\":\"8b33c462944565a5fef37338a42bf0069f0548d5\", \"best_bid\":\"0.13\", \"best_ask\":\"0.14\"}, {\"asset_id\":\"61819828071723399190623735325323968706432622380635304641786792960078828866875\", \"price\":\"0.93\", \"size\":\"5330.71\", \"side\":\"SELL\", \"hash\":\"e53c3c67b005f7ed0c519bd2b859f4d9d816b6bc\", \"best_bid\":\"0.86\", \"best_ask\":\"0.87\"}], \"timestamp\":\"1789987927073\", \"event_type\":\"price_change\"}","raw_base64":null}
{"received_ms":1789987927096,"monotonic_ns":1019367926469100,"raw":"{\"market\":\"0x28a45972fccdaf0fba75dacc59725521035e177d09dd92174f9f52740bccb025\", \"price_changes\":[{\"asset_id\":\"114356653315647913247200886351065428002113119844334520181865067698979836634569\", \"price\":\"0.13\", \"size\":\"265\", \"side\":\"BUY\", \"hash\":\"32409e713d7b5e4f8b4b20db9879ed370c9d4df5\", \"best_bid\":\"0.13\", \"best_ask\":\"0.14\"}, {\"asset_id\":\"61819828071723399190623735325323968706432622380635304641786792960078828866875\", \"price\":\"0.87\", \"size\":\"265\", \"side\":\"SELL\", \"hash\":\"6654db21713bd9d9e33f261f2e4ec2c1f9ac147a\", \"best_bid\":\"0.86\", \"best_ask\":\"0.87\"}], \"timestamp\":\"1789987927073\", \"event_type\":\"price_change\"}","raw_base64":null}
{"received_ms":1789987927102,"monotonic_ns":1019367932837900,"raw":"{\"market\":\"0x28a45972fccdaf0fba75dacc59725521035e177d09dd92174f9f52740bccb025\", \"price_changes\":[{\"asset_id\":\"61819828071723399190623735325323968706432622380635304641786792960078828866875\", \"price\":\"0.93\", \"size\":\"5339.71\", \"side\":\"SELL\", \"hash\":\"66b04635847457d4a1d99f822e1b8745ede79b83\", \"best_bid\":\"0.86\", \"best_ask\":\"0.87\"}, {\"asset_id\":\"114356653315647913247200886351065428002113119844334520181865067698979836634569\", \"price\":\"0.07\", \"size\":\"5339.71\", \"side\":\"BUY\", \"hash\":\"be97bddfd97f16ceaeffbec31729d0b6510f5f0e\", \"best_bid\":\"0.13\", \"best_ask\":\"0.14\"}], \"timestamp\":\"1789987927081\", \"event_type\":\"price_change\"}","raw_base64":null}
{"received_ms":1789987927103,"monotonic_ns":1019367933720000,"raw":"{\"market\":\"0x28a45972fccdaf0fba75dacc59725521035e177d09dd92174f9f52740bccb025\", \"price_changes\":[{\"asset_id\":\"61819828071723399190623735325323968706432622380635304641786792960078828866875\", \"price\":\"0.86\", \"size\":\"5283.17\", \"side\":\"BUY\", \"hash\":\"f83dc565c224830d39186551b96dd1c4420f6468\", \"best_bid\":\"0.86\", \"best_ask\":\"0.87\"}, {\"asset_id\":\"114356653315647913247200886351065428002113119844334520181865067698979836634569\", \"price\":\"0.14\", \"size\":\"5283.17\", \"side\":\"SELL\", \"hash\":\"ebbfea68d8344ecc5e9052653f9f396971c50cd1\", \"best_bid\":\"0.13\", \"best_ask\":\"0.14\"}], \"timestamp\":\"1789987927082\", \"event_type\":\"price_change\"}","raw_base64":null}
{"received_ms":1789987927109,"monotonic_ns":1019367940123300,"raw":"{\"market\":\"0x28a45972fccdaf0fba75dacc59725521035e177d09dd92174f9f52740bccb025\", \"price_changes\":[{\"asset_id\":\"114356653315647913247200886351065428002113119844334520181865067698979836634569\", \"price\":\"0.05\", \"size\":\"773\", \"side\":\"BUY\", \"hash\":\"8887207a7e1bcbf62323e60cb38a91099fc237fb\", \"best_bid\":\"0.13\", \"best_ask\":\"0.14\"}, {\"asset_id\":\"61819828071723399190623735325323968706432622380635304641786792960078828866875\", \"price\":\"0.95\", \"size\":\"773\", \"side\":\"SELL\", \"hash\":\"9e4ffd03b4ae057b0e97365e37ac1b1d4371f81e\", \"best_bid\":\"0.86\", \"best_ask\":\"0.87\"}], \"timestamp\":\"1789987927083\", \"event_type\":\"price_change\"}","raw_base64":null}
{"received_ms":1789987927112,"monotonic_ns":1019367943256000,"raw":"{\"market\":\"0x28a45972fccdaf0fba75dacc59725521035e177d09dd92174f9f52740bccb025\", \"price_changes\":[{\"asset_id\":\"61819828071723399190623735325323968706432622380635304641786792960078828866875\", \"price\":\"0.01\", \"size\":\"1491.91\", \"side\":\"BUY\", \"hash\":\"d2aeb99be5e15da7806832c7b70678ae8ee42dfb\", \"best_bid\":\"0.86\", \"best_ask\":\"0.87\"}, {\"asset_id\":\"114356653315647913247200886351065428002113119844334520181865067698979836634569\", \"price\":\"0.99\", \"size\":\"1491.91\", \"side\":\"SELL\", \"hash\":\"99c977cf119b8a3e25c6b6e8da1b810f3b6be944\", \"best_bid\":\"0.13\", \"best_ask\":\"0.14\"}], \"timestamp\":\"1789987927092\", \"event_type\":\"price_change\"}","raw_base64":null}
{"received_ms":1789987927124,"monotonic_ns":1019367954811800,"raw":"{\"market\":\"0x28a45972fccdaf0fba75dacc59725521035e177d09dd92174f9f52740bccb025\", \"price_changes\":[{\"asset_id\":\"114356653315647913247200886351065428002113119844334520181865067698979836634569\", \"price\":\"0.13\", \"size\":\"255\", \"side\":\"BUY\", \"hash\":\"f1fea3405e966b1c92fe1b77ddc4c51d969fb890\", \"best_bid\":\"0.13\", \"best_ask\":\"0.14\"}, {\"asset_id\":\"61819828071723399190623735325323968706432622380635304641786792960078828866875\", \"price\":\"0.87\", \"size\":\"255\", \"side\":\"SELL\", \"hash\":\"d330f95886c89e33044508bcbb7d2d4ca1f4a862\", \"best_bid\":\"0.86\", \"best_ask\":\"0.87\"}], \"timestamp\":\"1789987927103\", \"event_type\":\"price_change\"}","raw_base64":null}
{"received_ms":1789987927133,"monotonic_ns":1019367964112600,"raw":"{\"market\":\"0x28a45972fccdaf0fba75dacc59725521035e177d09dd92174f9f52740bccb025\", \"price_changes\":[{\"asset_id\":\"114356653315647913247200886351065428002113119844334520181865067698979836634569\", \"price\":\"0.06\", \"size\":\"5946.67\", \"side\":\"BUY\", \"hash\":\"9d6baac96dd64b38e10efdc98df867ed09f8b6ce\", \"best_bid\":\"0.13\", \"best_ask\":\"0.14\"}, {\"asset_id\":\"61819828071723399190623735325323968706432622380635304641786792960078828866875\", \"price\":\"0.94\", \"size\":\"5946.67\", \"side\":\"SELL\", \"hash\":\"d19015de368d94cd28b2898632b2e0babbb26b67\", \"best_bid\":\"0.86\", \"best_ask\":\"0.87\"}], \"timestamp\":\"1789987927104\", \"event_type\":\"price_change\"}","raw_base64":null}
{"received_ms":1789987927133,"monotonic_ns":1019367964204200,"raw":"{\"market\":\"0x28a45972fccdaf0fba75dacc59725521035e177d09dd92174f9f52740bccb025\", \"price_changes\":[{\"asset_id\":\"114356653315647913247200886351065428002113119844334520181865067698979836634569\", \"price\":\"0.09\", \"size\":\"670.12\", \"side\":\"BUY\", \"hash\":\"b1b75ef539163a40b817471fcfce7a7f23cb6989\", \"best_bid\":\"0.13\", \"best_ask\":\"0.14\"}, {\"asset_id\":\"61819828071723399190623735325323968706432622380635304641786792960078828866875\", \"price\":\"0.91\", \"size\":\"670.12\", \"side\":\"SELL\", \"hash\":\"dd23e2f9b19cf8eb057cafdf6386d124200f48b2\", \"best_bid\":\"0.86\", \"best_ask\":\"0.87\"}], \"timestamp\":\"1789987927106\", \"event_type\":\"price_change\"}","raw_base64":null}
{"received_ms":1789987927134,"monotonic_ns":1019367965130500,"raw":"{\"market\":\"0x28a45972fccdaf0fba75dacc59725521035e177d09dd92174f9f52740bccb025\", \"price_changes\":[{\"asset_id\":\"61819828071723399190623735325323968706432622380635304641786792960078828866875\", \"price\":\"0.86\", \"size\":\"5574.17\", \"side\":\"BUY\", \"hash\":\"0c71f47242a443db1cb101bf82ae8d38dcc5c981\", \"best_bid\":\"0.86\", \"best_ask\":\"0.87\"}, {\"asset_id\":\"114356653315647913247200886351065428002113119844334520181865067698979836634569\", \"price\":\"0.14\", \"size\":\"5574.17\", \"side\":\"SELL\", \"hash\":\"c03c4cef28e7c69c160ae003bf9ec7e3c9572ff8\", \"best_bid\":\"0.13\", \"best_ask\":\"0.14\"}], \"timestamp\":\"1789987927113\", \"event_type\":\"price_change\"}","raw_base64":null}
{"received_ms":1789987927136,"monotonic_ns":1019367966790100,"raw":"{\"market\":\"0x28a45972fccdaf0fba75dacc59725521035e177d09dd92174f9f52740bccb025\", \"price_changes\":[{\"asset_id\":\"61819828071723399190623735325323968706432622380635304641786792960078828866875\", \"price\":\"0.84\", \"size\":\"3097\", \"side\":\"BUY\", \"hash\":\"afe116fcc541f5e04b266d93fa670028d9d30e0a\", \"best_bid\":\"0.86\", \"best_ask\":\"0.87\"}, {\"asset_id\":\"114356653315647913247200886351065428002113119844334520181865067698979836634569\", \"price\":\"0.16\", \"size\":\"3097\", \"side\":\"SELL\", \"hash\":\"f5c607c558a3b13170ebc15994435bb55c328207\", \"best_bid\":\"0.13\", \"best_ask\":\"0.14\"}], \"timestamp\":\"1789987927115\", \"event_type\":\"price_change\"}","raw_base64":null}
{"received_ms":1789987927143,"monotonic_ns":1019367973838800,"raw":"{\"market\":\"0x28a45972fccdaf0fba75dacc59725521035e177d09dd92174f9f52740bccb025\", \"price_changes\":[{\"asset_id\":\"114356653315647913247200886351065428002113119844334520181865067698979836634569\", \"price\":\"0.11\", \"size\":\"128.1\", \"side\":\"BUY\", \"hash\":\"8c0a48a81eb5e5d0645fc233b691f897963c3d23\", \"best_bid\":\"0.13\", \"best_ask\":\"0.14\"}, {\"asset_id\":\"61819828071723399190623735325323968706432622380635304641786792960078828866875\", \"price\":\"0.89\", \"size\":\"128.1\", \"side\":\"SELL\", \"hash\":\"e59b210078938881dc60193d5b55d90daa4d3f26\", \"best_bid\":\"0.86\", \"best_ask\":\"0.87\"}], \"timestamp\":\"1789987927122\", \"event_type\":\"price_change\"}","raw_base64":null}
{"received_ms":1789987927145,"monotonic_ns":1019367975376900,"raw":"{\"market\":\"0x28a45972fccdaf0fba75dacc59725521035e177d09dd92174f9f52740bccb025\", \"price_changes\":[{\"asset_id\":\"114356653315647913247200886351065428002113119844334520181865067698979836634569\", \"price\":\"0.07\", \"size\":\"5097.71\", \"side\":\"BUY\", \"hash\":\"b7b4dbf29456c7b2569d49b0fe3133aeabb40537\", \"best_bid\":\"0.13\", \"best_ask\":\"0.14\"}, {\"asset_id\":\"61819828071723399190623735325323968706432622380635304641786792960078828866875\", \"price\":\"0.93\", \"size\":\"5097.71\", \"side\":\"SELL\", \"hash\":\"b9694fd7ce987aff56afdc553e17adbae36e883c\", \"best_bid\":\"0.86\", \"best_ask\":\"0.87\"}], \"timestamp\":\"1789987927124\", \"event_type\":\"price_change\"}","raw_base64":null}
{"received_ms":1789987927167,"monotonic_ns":1019367997847000,"raw":"{\"market\":\"0x28a45972fccdaf0fba75dacc59725521035e177d09dd92174f9f52740bccb025\", \"price_changes\":[{\"asset_id\":\"61819828071723399190623735325323968706432622380635304641786792960078828866875\", \"price\":\"0.81\", \"size\":\"630\", \"side\":\"BUY\", \"hash\":\"e769e44465aea288a2b0e28c43c407abbc14bf8b\", \"best_bid\":\"0.86\", \"best_ask\":\"0.87\"}, {\"asset_id\":\"114356653315647913247200886351065428002113119844334520181865067698979836634569\", \"price\":\"0.19\", \"size\":\"630\", \"side\":\"SELL\", \"hash\":\"9bf44d61990b8275314019b62d19781c65681737\", \"best_bid\":\"0.13\", \"best_ask\":\"0.14\"}], \"timestamp\":\"1789987927136\", \"event_type\":\"price_change\"}","raw_base64":null}
{"received_ms":1789987927167,"monotonic_ns":1019367997894600,"raw":"{\"market\":\"0x28a45972fccdaf0fba75dacc59725521035e177d09dd92174f9f52740bccb025\", \"price_changes\":[{\"asset_id\":\"61819828071723399190623735325323968706432622380635304641786792960078828866875\", \"price\":\"0.81\", \"size\":\"590\", \"side\":\"BUY\", \"hash\":\"3f111593f7c7e56496a46781a260f958ece0230b\", \"best_bid\":\"0.86\", \"best_ask\":\"0.87\"}, {\"asset_id\":\"114356653315647913247200886351065428002113119844334520181865067698979836634569\", \"price\":\"0.19\", \"size\":\"590\", \"side\":\"SELL\", \"hash\":\"b4e273a1bd997dd17f03966ae335f15c2d6a5c3c\", \"best_bid\":\"0.13\", \"best_ask\":\"0.14\"}], \"timestamp\":\"1789987927136\", \"event_type\":\"price_change\"}","raw_base64":null}
{"received_ms":1789987927167,"monotonic_ns":1019367997938200,"raw":"{\"market\":\"0x28a45972fccdaf0fba75dacc59725521035e177d09dd92174f9f52740bccb025\", \"price_changes\":[{\"asset_id\":\"114356653315647913247200886351065428002113119844334520181865067698979836634569\", \"price\":\"0.13\", \"size\":\"265\", \"side\":\"BUY\", \"hash\":\"b6b6b03cecba4cff7ada66aef1d45ea1931b3f4f\", \"best_bid\":\"0.13\", \"best_ask\":\"0.14\"}, {\"asset_id\":\"61819828071723399190623735325323968706432622380635304641786792960078828866875\", \"price\":\"0.87\", \"size\":\"265\", \"side\":\"SELL\", \"hash\":\"89a95e48834176fda3cca02cc4e5f4cb0940f7b0\", \"best_bid\":\"0.86\", \"best_ask\":\"0.87\"}], \"timestamp\":\"1789987927145\", \"event_type\":\"price_change\"}","raw_base64":null}
{"received_ms":1789987927167,"monotonic_ns":1019367998101800,"raw":"{\"market\":\"0x28a45972fccdaf0fba75dacc59725521035e177d09dd92174f9f52740bccb025\", \"price_changes\":[{\"asset_id\":\"114356653315647913247200886351065428002113119844334520181865067698979836634569\", \"price\":\"0.05\", \"size\":\"5708\", \"side\":\"BUY\", \"hash\":\"073395ab502406080db2c6df10c9c24019612611\", \"best_bid\":\"0.13\", \"best_ask\":\"0.14\"}, {\"asset_id\":\"61819828071723399190623735325323968706432622380635304641786792960078828866875\", \"price\":\"0.95\", \"size\":\"5708\", \"side\":\"SELL\", \"hash\":\"09c79793a085c37c14ffdb7de2678c48e4fc1444\", \"best_bid\":\"0.86\", \"best_ask\":\"0.87\"}], \"timestamp\":\"1789987927146\", \"event_type\":\"price_change\"}","raw_base64":null}
{"received_ms":1789987927167,"monotonic_ns":1019367998159700,"raw":"{\"market\":\"0x28a45972fccdaf0fba75dacc59725521035e177d09dd92174f9f52740bccb025\", \"price_changes\":[{\"asset_id\":\"61819828071723399190623735325323968706432622380635304641786792960078828866875\", \"price\":\"0.86\", \"size\":\"5283.17\", \"side\":\"BUY\", \"hash\":\"7ad86e6e8ffff5c2be74838b644ca9a745a975a6\", \"best_bid\":\"0.86\", \"best_ask\":\"0.87\"}, {\"asset_id\":\"114356653315647913247200886351065428002113119844334520181865067698979836634569\", \"price\":\"0.14\", \"size\":\"5283.17\", \"side\":\"SELL\", \"hash\":\"e2dc735611f438fd56b6fa771688706b69db113f\", \"best_bid\":\"0.13\", \"best_ask\":\"0.14\"}], \"timestamp\":\"1789987927147\", \"event_type\":\"price_change\"}","raw_base64":null}
{"received_ms":1789987927167,"monotonic_ns":1019367998202400,"raw":"{\"market\":\"0x28a45972fccdaf0fba75dacc59725521035e177d09dd92174f9f52740bccb025\", \"price_changes\":[{\"asset_id\":\"114356653315647913247200886351065428002113119844334520181865067698979836634569\", \"price\":\"0.07\", \"size\":\"5110.71\", \"side\":\"BUY\", \"hash\":\"0d23fcecabb11e9eff6bdf7ab0671c54ef042808\", \"best_bid\":\"0.13\", \"best_ask\":\"0.14\"}, {\"asset_id\":\"61819828071723399190623735325323968706432622380635304641786792960078828866875\", \"price\":\"0.93\", \"size\":\"5110.71\", \"side\":\"SELL\", \"hash\":\"8dcd91ea6aacc51dc88515c46fba286d6e2181f8\", \"best_bid\":\"0.86\", \"best_ask\":\"0.87\"}], \"timestamp\":\"1789987927147\", \"event_type\":\"price_change\"}","raw_base64":null}
{"received_ms":1789987927168,"monotonic_ns":1019367998809000,"raw":"{\"market\":\"0x28a45972fccdaf0fba75dacc59725521035e177d09dd92174f9f52740bccb025\", \"price_changes\":[{\"asset_id\":\"114356653315647913247200886351065428002113119844334520181865067698979836634569\", \"price\":\"0.06\", \"size\":\"7077.67\", \"side\":\"BUY\", \"hash\":\"41e8a09877bcfff540ab342bacdb4d1a936c2575\", \"best_bid\":\"0.13\", \"best_ask\":\"0.14\"}, {\"asset_id\":\"61819828071723399190623735325323968706432622380635304641786792960078828866875\", \"price\":\"0.94\", \"size\":\"7077.67\", \"side\":\"SELL\", \"hash\":\"e1331e7fb33fc8aff648082eace380ca1fda7647\", \"best_bid\":\"0.86\", \"best_ask\":\"0.87\"}], \"timestamp\":\"1789987927148\", \"event_type\":\"price_change\"}","raw_base64":null}
{"received_ms":1789987927171,"monotonic_ns":1019368002062400,"raw":"{\"market\":\"0x28a45972fccdaf0fba75dacc59725521035e177d09dd92174f9f52740bccb025\", \"price_changes\":[{\"asset_id\":\"61819828071723399190623735325323968706432622380635304641786792960078828866875\", \"price\":\"0.8\", \"size\":\"602\", \"side\":\"BUY\", \"hash\":\"8abd4f4ee4fd1357529164401c73a21778726ca5\", \"best_bid\":\"0.86\", \"best_ask\":\"0.87\"}, {\"asset_id\":\"114356653315647913247200886351065428002113119844334520181865067698979836634569\", \"price\":\"0.2\", \"size\":\"602\", \"side\":\"SELL\", \"hash\":\"34e40aeab256ef5a8d12606630acdd01409641fb\", \"best_bid\":\"0.13\", \"best_ask\":\"0.14\"}], \"timestamp\":\"1789987927150\", \"event_type\":\"price_change\"}","raw_base64":null}
{"received_ms":1789987927172,"monotonic_ns":1019368002944800,"raw":"{\"market\":\"0x28a45972fccdaf0fba75dacc59725521035e177d09dd92174f9f52740bccb025\", \"price_changes\":[{\"asset_id\":\"61819828071723399190623735325323968706432622380635304641786792960078828866875\", \"price\":\"0.93\", \"size\":\"5029.71\", \"side\":\"SELL\", \"hash\":\"1fce1c0a17284dfb74cb6d0ac03666985339ecb2\", \"best_bid\":\"0.86\", \"best_ask\":\"0.87\"}, {\"asset_id\":\"114356653315647913247200886351065428002113119844334520181865067698979836634569\", \"price\":\"0.07\", \"size\":\"5029.71\", \"side\":\"BUY\", \"hash\":\"78d83a54572b23aaa57f0eb53110bee1b559ab6e\", \"best_bid\":\"0.13\", \"best_ask\":\"0.14\"}], \"timestamp\":\"1789987927152\", \"event_type\":\"price_change\"}","raw_base64":null}
{"received_ms":1789987927186,"monotonic_ns":1019368016485100,"raw":"{\"market\":\"0x28a45972fccdaf0fba75dacc59725521035e177d09dd92174f9f52740bccb025\", \"price_changes\":[{\"asset_id\":\"61819828071723399190623735325323968706432622380635304641786792960078828866875\", \"price\":\"0.77\", \"size\":\"587.49\", \"side\":\"BUY\", \"hash\":\"5c5981a14b95a9262c1d812b7012344795ef6a8a\", \"best_bid\":\"0.86\", \"best_ask\":\"0.87\"}, {\"asset_id\":\"114356653315647913247200886351065428002113119844334520181865067698979836634569\", \"price\":\"0.23\", \"size\":\"587.49\", \"side\":\"SELL\", \"hash\":\"96e1868031da9e7894127f1dd9e1b6f3d07a8fbb\", \"best_bid\":\"0.13\", \"best_ask\":\"0.14\"}], \"timestamp\":\"1789987927165\", \"event_type\":\"price_change\"}","raw_base64":null}
{"received_ms":1789987927189,"monotonic_ns":1019368019505100,"raw":"{\"market\":\"0x28a45972fccdaf0fba75dacc59725521035e177d09dd92174f9f52740bccb025\", \"price_changes\":[{\"asset_id\":\"114356653315647913247200886351065428002113119844334520181865067698979836634569\", \"price\":\"0.09\", \"size\":\"678.12\", \"side\":\"BUY\", \"hash\":\"5f80e1a6d8c4dcb33535180c47cec26dc114e04f\", \"best_bid\":\"0.13\", \"best_ask\":\"0.14\"}, {\"asset_id\":\"61819828071723399190623735325323968706432622380635304641786792960078828866875\", \"price\":\"0.91\", \"size\":\"678.12\", \"side\":\"SELL\", \"hash\":\"4f59018d63d9df6bb5782357fc90eec8d4d944fa\", \"best_bid\":\"0.86\", \"best_ask\":\"0.87\"}], \"timestamp\":\"1789987927167\", \"event_type\":\"price_change\"}","raw_base64":null}
{"received_ms":1789987927189,"monotonic_ns":1019368019561600,"raw":"{\"market\":\"0x28a45972fccdaf0fba75dacc59725521035e177d09dd92174f9f52740bccb025\", \"price_changes\":[{\"asset_id\":\"61819828071723399190623735325323968706432622380635304641786792960078828866875\", \"price\":\"0.77\", \"size\":\"487.49\", \"side\":\"BUY\", \"hash\":\"4f3c284efe1382a5f52a3ea6ef6115192722830d\", \"best_bid\":\"0.86\", \"best_ask\":\"0.87\"}, {\"asset_id\":\"114356653315647913247200886351065428002113119844334520181865067698979836634569\", \"price\":\"0.23\", \"size\":\"487.49\", \"side\":\"SELL\", \"hash\":\"a7a561f5c7d4894c362529dda0e8024a32931a3d\", \"best_bid\":\"0.13\", \"best_ask\":\"0.14\"}], \"timestamp\":\"1789987927168\", \"event_type\":\"price_change\"}","raw_base64":null}
{"received_ms":1789987927198,"monotonic_ns":1019368028901300,"raw":"{\"market\":\"0x28a45972fccdaf0fba75dacc59725521035e177d09dd92174f9f52740bccb025\", \"price_changes\":[{\"asset_id\":\"114356653315647913247200886351065428002113119844334520181865067698979836634569\", \"price\":\"0.06\", \"size\":\"5946.67\", \"side\":\"BUY\", \"hash\":\"602b577fde59fc8ad762aae803cce76862b69bfb\", \"best_bid\":\"0.13\", \"best_ask\":\"0.14\"}, {\"asset_id\":\"61819828071723399190623735325323968706432622380635304641786792960078828866875\", \"price\":\"0.94\", \"size\":\"5946.67\", \"side\":\"SELL\", \"hash\":\"69b076cac33bfaa5da61efd144a9a78d7f4a145c\", \"best_bid\":\"0.86\", \"best_ask\":\"0.87\"}], \"timestamp\":\"1789987927177\", \"event_type\":\"price_change\"}","raw_base64":null}
{"received_ms":1789987927199,"monotonic_ns":1019368030227800,"raw":"{\"market\":\"0x28a45972fccdaf0fba75dacc59725521035e177d09dd92174f9f52740bccb025\", \"price_changes\":[{\"asset_id\":\"61819828071723399190623735325323968706432622380635304641786792960078828866875\", \"price\":\"0.84\", \"size\":\"3197\", \"side\":\"BUY\", \"hash\":\"3878520f79e470d689f11930aab707315129a616\", \"best_bid\":\"0.86\", \"best_ask\":\"0.87\"}, {\"asset_id\":\"114356653315647913247200886351065428002113119844334520181865067698979836634569\", \"price\":\"0.16\", \"size\":\"3197\", \"side\":\"SELL\", \"hash\":\"56345637fa0ccb4c61e7441a8d4ada1779b72d92\", \"best_bid\":\"0.13\", \"best_ask\":\"0.14\"}], \"timestamp\":\"1789987927179\", \"event_type\":\"price_change\"}","raw_base64":null}
{"received_ms":1789987927200,"monotonic_ns":1019368030745000,"raw":"{\"market\":\"0x28a45972fccdaf0fba75dacc59725521035e177d09dd92174f9f52740bccb025\", \"price_changes\":[{\"asset_id\":\"61819828071723399190623735325323968706432622380635304641786792960078828866875\", \"price\":\"0.86\", \"size\":\"5344.17\", \"side\":\"BUY\", \"hash\":\"ee73fe034650085c973a30c0721ac7d06a853358\", \"best_bid\":\"0.86\", \"best_ask\":\"0.87\"}, {\"asset_id\":\"114356653315647913247200886351065428002113119844334520181865067698979836634569\", \"price\":\"0.14\", \"size\":\"5344.17\", \"side\":\"SELL\", \"hash\":\"06cd754455390b23c61ddacd13a9f04c9f738a1b\", \"best_bid\":\"0.13\", \"best_ask\":\"0.14\"}], \"timestamp\":\"1789987927180\", \"event_type\":\"price_change\"}","raw_base64":null}
{"received_ms":1789987927201,"monotonic_ns":1019368031564700,"raw":"{\"market\":\"0x28a45972fccdaf0fba75dacc59725521035e177d09dd92174f9f52740bccb025\", \"price_changes\":[{\"asset_id\":\"61819828071723399190623735325323968706432622380635304641786792960078828866875\", \"price\":\"0.85\", \"size\":\"5262.35\", \"side\":\"BUY\", \"hash\":\"054eeb2a8e1c9e4c2402c9289eb8d3380271b32c\", \"best_bid\":\"0.86\", \"best_ask\":\"0.87\"}, {\"asset_id\":\"114356653315647913247200886351065428002113119844334520181865067698979836634569\", \"price\":\"0.15\", \"size\":\"5262.35\", \"side\":\"SELL\", \"hash\":\"515f0d9d32120de77613adb9afb0fae4f38c8ed5\", \"best_bid\":\"0.13\", \"best_ask\":\"0.14\"}], \"timestamp\":\"1789987927181\", \"event_type\":\"price_change\"}","raw_base64":null}
{"received_ms":1789987927221,"monotonic_ns":1019368051830700,"raw":"{\"market\":\"0x28a45972fccdaf0fba75dacc59725521035e177d09dd92174f9f52740bccb025\", \"price_changes\":[{\"asset_id\":\"61819828071723399190623735325323968706432622380635304641786792960078828866875\", \"price\":\"0.8\", \"size\":\"662\", \"side\":\"BUY\", \"hash\":\"301953b25151c9bb40689ada28250f0e185ea911\", \"best_bid\":\"0.86\", \"best_ask\":\"0.87\"}, {\"asset_id\":\"114356653315647913247200886351065428002113119844334520181865067698979836634569\", \"price\":\"0.2\", \"size\":\"662\", \"side\":\"SELL\", \"hash\":\"3a84e3339b42f5a8f26dad1d415ee6f6fed4c4e7\", \"best_bid\":\"0.13\", \"best_ask\":\"0.14\"}], \"timestamp\":\"1789987927198\", \"event_type\":\"price_change\"}","raw_base64":null}
{"received_ms":1789987927221,"monotonic_ns":1019368051883200,"raw":"{\"market\":\"0x28a45972fccdaf0fba75dacc59725521035e177d09dd92174f9f52740bccb025\", \"price_changes\":[{\"asset_id\":\"61819828071723399190623735325323968706432622380635304641786792960078828866875\", \"price\":\"0.81\", \"size\":\"630\", \"side\":\"BUY\", \"hash\":\"2d73da3cc334a9642a4980eab050cc8b89720863\", \"best_bid\":\"0.86\", \"best_ask\":\"0.87\"}, {\"asset_id\":\"114356653315647913247200886351065428002113119844334520181865067698979836634569\", \"price\":\"0.19\", \"size\":\"630\", \"side\":\"SELL\", \"hash\":\"631ea03309d9caf45696aced239289dd1fbb906d\", \"best_bid\":\"0.13\", \"best_ask\":\"0.14\"}], \"timestamp\":\"1789987927198\", \"event_type\":\"price_change\"}","raw_base64":null}
{"received_ms":1789987927221,"monotonic_ns":1019368051923100,"raw":"{\"market\":\"0x28a45972fccdaf0fba75dacc59725521035e177d09dd92174f9f52740bccb025\", \"price_changes\":[{\"asset_id\":\"61819828071723399190623735325323968706432622380635304641786792960078828866875\", \"price\":\"0.8\", \"size\":\"602\", \"side\":\"BUY\", \"hash\":\"9664fe0c137e2abfb9733d78b4ff98eefa5ea39b\", \"best_bid\":\"0.86\", \"best_ask\":\"0.87\"}, {\"asset_id\":\"114356653315647913247200886351065428002113119844334520181865067698979836634569\", \"price\":\"0.2\", \"size\":\"602\", \"side\":\"SELL\", \"hash\":\"35eb7a3afaaf5ad16edc3f9b40b5bad40c5fbc8c\", \"best_bid\":\"0.13\", \"best_ask\":\"0.14\"}], \"timestamp\":\"1789987927200\", \"event_type\":\"price_change\"}","raw_base64":null}
{"received_ms":1789987927221,"monotonic_ns":1019368051959400,"raw":"{\"market\":\"0x28a45972fccdaf0fba75dacc59725521035e177d09dd92174f9f52740bccb025\", \"price_changes\":[{\"asset_id\":\"61819828071723399190623735325323968706432622380635304641786792960078828866875\", \"price\":\"0.81\", \"size\":\"590\", \"side\":\"BUY\", \"hash\":\"9664fe0c137e2abfb9733d78b4ff98eefa5ea39b\", \"best_bid\":\"0.86\", \"best_ask\":\"0.87\"}, {\"asset_id\":\"114356653315647913247200886351065428002113119844334520181865067698979836634569\", \"price\":\"0.19\", \"size\":\"590\", \"side\":\"SELL\", \"hash\":\"35eb7a3afaaf5ad16edc3f9b40b5bad40c5fbc8c\", \"best_bid\":\"0.13\", \"best_ask\":\"0.14\"}], \"timestamp\":\"1789987927200\", \"event_type\":\"price_change\"}","raw_base64":null}
{"received_ms":1789987927242,"monotonic_ns":1019368072420700,"raw":"{\"market\":\"0x28a45972fccdaf0fba75dacc59725521035e177d09dd92174f9f52740bccb025\", \"price_changes\":[{\"asset_id\":\"61819828071723399190623735325323968706432622380635304641786792960078828866875\", \"price\":\"0.8\", \"size\":\"582\", \"side\":\"BUY\", \"hash\":\"0abf9158c184e02e08768a2437b306b0e084f6a0\", \"best_bid\":\"0.86\", \"best_ask\":\"0.87\"}, {\"asset_id\":\"114356653315647913247200886351065428002113119844334520181865067698979836634569\", \"price\":\"0.2\", \"size\":\"582\", \"side\":\"SELL\", \"hash\":\"e57cb50c700e6a72cbc1d2eeb55e7504092ff33c\", \"best_bid\":\"0.13\", \"best_ask\":\"0.14\"}], \"timestamp\":\"1789987927208\", \"event_type\":\"price_change\"}","raw_base64":null}
{"received_ms":1789987927242,"monotonic_ns":1019368072473900,"raw":"{\"market\":\"0x28a45972fccdaf0fba75dacc59725521035e177d09dd92174f9f52740bccb025\", \"price_changes\":[{\"asset_id\":\"114356653315647913247200886351065428002113119844334520181865067698979836634569\", \"price\":\"0.09\", \"size\":\"618.12\", \"side\":\"BUY\", \"hash\":\"e57cb50c700e6a72cbc1d2eeb55e7504092ff33c\", \"best_bid\":\"0.13\", \"best_ask\":\"0.14\"}, {\"asset_id\":\"61819828071723399190623735325323968706432622380635304641786792960078828866875\", \"price\":\"0.91\", \"size\":\"618.12\", \"side\":\"SELL\", \"hash\":\"0abf9158c184e02e08768a2437b306b0e084f6a0\", \"best_bid\":\"0.86\", \"best_ask\":\"0.87\"}], \"timestamp\":\"1789987927208\", \"event_type\":\"price_change\"}","raw_base64":null}
{"received_ms":1789987927242,"monotonic_ns":1019368072517600,"raw":"{\"market\":\"0x28a45972fccdaf0fba75dacc59725521035e177d09dd92174f9f52740bccb025\", \"price_changes\":[{\"asset_id\":\"61819828071723399190623735325323968706432622380635304641786792960078828866875\", \"price\":\"0.85\", \"size\":\"5202.35\", \"side\":\"BUY\", \"hash\":\"c604b1d126f1d18bce7dfe0bb0fb5d9c89ac36d5\", \"best_bid\":\"0.86\", \"best_ask\":\"0.87\"}, {\"asset_id\":\"114356653315647913247200886351065428002113119844334520181865067698979836634569\", \"price\":\"0.15\", \"size\":\"5202.35\", \"side\":\"SELL\", \"hash\":\"5a2f1a619163d6ca38d69de6392ccaab2c6152be\", \"best_bid\":\"0.13\", \"best_ask\":\"0.14\"}], \"timestamp\":\"1789987927208\", \"event_type\":\"price_change\"}","raw_base64":null}
{"received_ms":1789987927242,"monotonic_ns":1019368072558700,"raw":"{\"market\":\"0x28a45972fccdaf0fba75dacc59725521035e177d09dd92174f9f52740bccb025\", \"price_changes\":[{\"asset_id\":\"61819828071723399190623735325323968706432622380635304641786792960078828866875\", \"price\":\"0.85\", \"size\":\"5097.35\", \"side\":\"BUY\", \"hash\":\"e5f6f845391f6c9d47c4c3aa541eed19d84df284\", \"best_bid\":\"0.86\", \"best_ask\":\"0.87\"}, {\"asset_id\":\"114356653315647913247200886351065428002113119844334520181865067698979836634569\", \"price\":\"0.15\", \"size\":\"5097.35\", \"side\":\"SELL\", \"hash\":\"d764d4bb3cef037894ed94f214ce056452ad5106\", \"best_bid\":\"0.13\", \"best_ask\":\"0.14\"}], \"timestamp\":\"1789987927211\", \"event_type\":\"price_change\"}","raw_base64":null}
{"received_ms":1789987927242,"monotonic_ns":1019368072598900,"raw":"{\"market\":\"0x28a45972fccdaf0fba75dacc59725521035e177d09dd92174f9f52740bccb025\", \"price_changes\":[{\"asset_id\":\"114356653315647913247200886351065428002113119844334520181865067698979836634569\", \"price\":\"0.06\", \"size\":\"7064.67\", \"side\":\"BUY\", \"hash\":\"f610624f584526fc60dad60b32b620ee7ee61d11\", \"best_bid\":\"0.13\", \"best_ask\":\"0.14\"}, {\"asset_id\":\"61819828071723399190623735325323968706432622380635304641786792960078828866875\", \"price\":\"0.94\", \"size\":\"7064.67\", \"side\":\"SELL\", \"hash\":\"2075707f169490ae448cf1e5b6d9902b21b8d24f\", \"best_bid\":\"0.86\", \"best_ask\":\"0.87\"}], \"timestamp\":\"1789987927211\", \"event_type\":\"price_change\"}","raw_base64":null}
{"received_ms":1789987927242,"monotonic_ns":1019368072638500,"raw":"{\"market\":\"0x28a45972fccdaf0fba75dacc59725521035e177d09dd92174f9f52740bccb025\", \"price_changes\":[{\"asset_id\":\"114356653315647913247200886351065428002113119844334520181865067698979836634569\", \"price\":\"0.07\", \"size\":\"5421.71\", \"side\":\"BUY\", \"hash\":\"8f2ccd8cc79d543af7d2e6400e6e6e4a6abf73c3\", \"best_bid\":\"0.13\", \"best_ask\":\"0.14\"}, {\"asset_id\":\"61819828071723399190623735325323968706432622380635304641786792960078828866875\", \"price\":\"0.93\", \"size\":\"5421.71\", \"side\":\"SELL\", \"hash\":\"1aec3cf086ceae25a00902b9dc165fb763c03187\", \"best_bid\":\"0.86\", \"best_ask\":\"0.87\"}], \"timestamp\":\"1789987927212\", \"event_type\":\"price_change\"}","raw_base64":null}
{"received_ms":1789987927261,"monotonic_ns":1019368092200400,"raw":"{\"market\":\"0x28a45972fccdaf0fba75dacc59725521035e177d09dd92174f9f52740bccb025\", \"price_changes\":[{\"asset_id\":\"61819828071723399190623735325323968706432622380635304641786792960078828866875\", \"price\":\"0.79\", \"size\":\"507\", \"side\":\"BUY\", \"hash\":\"777c471e0316768833c3cf2e2a87b318e2a85427\", \"best_bid\":\"0.86\", \"best_ask\":\"0.87\"}, {\"asset_id\":\"114356653315647913247200886351065428002113119844334520181865067698979836634569\", \"price\":\"0.21\", \"size\":\"507\", \"side\":\"SELL\", \"hash\":\"84949fcfd5c42017cf738a671271a2128db12693\", \"best_bid\":\"0.13\", \"best_ask\":\"0.14\"}], \"timestamp\":\"1789987927230\", \"event_type\":\"price_change\"}","raw_base64":null}
{"received_ms":1789987927261,"monotonic_ns":1019368092266900,"raw":"{\"market\":\"0x28a45972fccdaf0fba75dacc59725521035e177d09dd92174f9f52740bccb025\", \"price_changes\":[{\"asset_id\":\"61819828071723399190623735325323968706432622380635304641786792960078828866875\", \"price\":\"0.8\", \"size\":\"562\", \"side\":\"BUY\", \"hash\":\"777c471e0316768833c3cf2e2a87b318e2a85427\", \"best_bid\":\"0.86\", \"best_ask\":\"0.87\"}, {\"asset_id\":\"114356653315647913247200886351065428002113119844334520181865067698979836634569\", \"price\":\"0.2\", \"size\":\"562\", \"side\":\"SELL\", \"hash\":\"84949fcfd5c42017cf738a671271a2128db12693\", \"best_bid\":\"0.13\", \"best_ask\":\"0.14\"}], \"timestamp\":\"1789987927230\", \"event_type\":\"price_change\"}","raw_base64":null}
{"received_ms":1789987927262,"monotonic_ns":1019368092320400,"raw":"{\"market\":\"0x28a45972fccdaf0fba75dacc59725521035e177d09dd92174f9f52740bccb025\", \"price_changes\":[{\"asset_id\":\"61819828071723399190623735325323968706432622380635304641786792960078828866875\", \"price\":\"0.84\", \"size\":\"3257\", \"side\":\"BUY\", \"hash\":\"07c83d6b3c1f8755e7e47177a94b4856f76dd4cb\", \"best_bid\":\"0.86\", \"best_ask\":\"0.87\"}, {\"asset_id\":\"114356653315647913247200886351065428002113119844334520181865067698979836634569\", \"price\":\"0.16\", \"size\":\"3257\", \"side\":\"SELL\", \"hash\":\"946f596db997695801abe486cbbdcfbe765120fa\", \"best_bid\":\"0.13\", \"best_ask\":\"0.14\"}], \"timestamp\":\"1789987927232\", \"event_type\":\"price_change\"}","raw_base64":null}
{"received_ms":1789987927277,"monotonic_ns":1019368107380500,"raw":"{\"market\":\"0x28a45972fccdaf0fba75dacc59725521035e177d09dd92174f9f52740bccb025\", \"price_changes\":[{\"asset_id\":\"114356653315647913247200886351065428002113119844334520181865067698979836634569\", \"price\":\"0.1\", \"size\":\"517\", \"side\":\"BUY\", \"hash\":\"df2276c398319399bef983a7f662a8984956b0f0\", \"best_bid\":\"0.13\", \"best_ask\":\"0.14\"}, {\"asset_id\":\"61819828071723399190623735325323968706432622380635304641786792960078828866875\", \"price\":\"0.9\", \"size\":\"517\", \"side\":\"SELL\", \"hash\":\"08fc8e0cd22776d72c92c4ff9bf52843695825fa\", \"best_bid\":\"0.86\", \"best_ask\":\"0.87\"}], \"timestamp\":\"1789987927241\", \"event_type\":\"price_change\"}","raw_base64":null}
{"received_ms":1789987927277,"monotonic_ns":1019368107478000,"raw":"{\"market\":\"0x28a45972fccdaf0fba75dacc59725521035e177d09dd92174f9f52740bccb025\", \"price_changes\":[{\"asset_id\":\"61819828071723399190623735325323968706432622380635304641786792960078828866875\", \"price\":\"0.77\", \"size\":\"587.49\", \"side\":\"BUY\", \"hash\":\"b5c3dc15f80f1eba2d0c52f91e66d0f4d770cf9b\", \"best_bid\":\"0.86\", \"best_ask\":\"0.87\"}, {\"asset_id\":\"114356653315647913247200886351065428002113119844334520181865067698979836634569\", \"price\":\"0.23\", \"size\":\"587.49\", \"side\":\"SELL\", \"hash\":\"34f726ee90e2ea8299a7cc36876d498a8aa60d7f\", \"best_bid\":\"0.13\", \"best_ask\":\"0.14\"}], \"timestamp\":\"1789987927242\", \"event_type\":\"price_change\"}","raw_base64":null}
{"received_ms":1789987927277,"monotonic_ns":1019368107530800,"raw":"{\"market\":\"0x28a45972fccdaf0fba75dacc59725521035e177d09dd92174f9f52740bccb025\", \"price_changes\":[{\"asset_id\":\"114356653315647913247200886351065428002113119844334520181865067698979836634569\", \"price\":\"0.07\", \"size\":\"5029.71\", \"side\":\"BUY\", \"hash\":\"464e63f5314e7038cee271018a525b227a70c0e8\", \"best_bid\":\"0.13\", \"best_ask\":\"0.14\"}, {\"asset_id\":\"61819828071723399190623735325323968706432622380635304641786792960078828866875\", \"price\":\"0.93\", \"size\":\"5029.71\", \"side\":\"SELL\", \"hash\":\"f9cd9815a7fb36aa66c0060fc12c9c837da1231d\", \"best_bid\":\"0.86\", \"best_ask\":\"0.87\"}], \"timestamp\":\"1789987927244\", \"event_type\":\"price_change\"}","raw_base64":null}
{"received_ms":1789987927277,"monotonic_ns":1019368107580900,"raw":"{\"market\":\"0x28a45972fccdaf0fba75dacc59725521035e177d09dd92174f9f52740bccb025\", \"price_changes\":[{\"asset_id\":\"114356653315647913247200886351065428002113119844334520181865067698979836634569\", \"price\":\"0.06\", \"size\":\"5946.67\", \"side\":\"BUY\", \"hash\":\"4e46108645618f76c7e4c7b17eb1675e16e25363\", \"best_bid\":\"0.13\", \"best_ask\":\"0.14\"}, {\"asset_id\":\"61819828071723399190623735325323968706432622380635304641786792960078828866875\", \"price\":\"0.94\", \"size\":\"5946.67\", \"side\":\"SELL\", \"hash\":\"482f63abe7e9bb67dfced55ab6ea98c7c7b12ede\", \"best_bid\":\"0.86\", \"best_ask\":\"0.87\"}], \"timestamp\":\"1789987927249\", \"event_type\":\"price_change\"}","raw_base64":null}
{"received_ms":1789987927277,"monotonic_ns":1019368107628700,"raw":"{\"market\":\"0x28a45972fccdaf0fba75dacc59725521035e177d09dd92174f9f52740bccb025\", \"price_changes\":[{\"asset_id\":\"114356653315647913247200886351065428002113119844334520181865067698979836634569\", \"price\":\"0.01\", \"size\":\"1689.43\", \"side\":\"BUY\", \"hash\":\"c1a0a021b93e2c15e2294c81db12310752c048d7\", \"best_bid\":\"0.13\", \"best_ask\":\"0.14\"}, {\"asset_id\":\"61819828071723399190623735325323968706432622380635304641786792960078828866875\", \"price\":\"0.99\", \"size\":\"1689.43\", \"side\":\"SELL\", \"hash\":\"ac88e9950d4740613d3c4e5e4a28128d55678b1c\", \"best_bid\":\"0.86\", \"best_ask\":\"0.87\"}], \"timestamp\":\"1789987927254\", \"event_type\":\"price_change\"}","raw_base64":null}
{"received_ms":1789987927293,"monotonic_ns":1019368123832700,"raw":"{\"market\":\"0x28a45972fccdaf0fba75dacc59725521035e177d09dd92174f9f52740bccb025\", \"price_changes\":[{\"asset_id\":\"114356653315647913247200886351065428002113119844334520181865067698979836634569\", \"price\":\"0.13\", \"size\":\"255\", \"side\":\"BUY\", \"hash\":\"8a63620c649af8fdcdc2846480b587891e26c38b\", \"best_bid\":\"0.13\", \"best_ask\":\"0.14\"}, {\"asset_id\":\"61819828071723399190623735325323968706432622380635304641786792960078828866875\", \"price\":\"0.87\", \"size\":\"255\", \"side\":\"SELL\", \"hash\":\"a3e93bda5180b0bda2c5ee4afc8cf2f8781ce0e4\", \"best_bid\":\"0.86\", \"best_ask\":\"0.87\"}], \"timestamp\":\"1789987927260\", \"event_type\":\"price_change\"}","raw_base64":null}
{"received_ms":1789987927293,"monotonic_ns":1019368123894000,"raw":"{\"market\":\"0x28a45972fccdaf0fba75dacc59725521035e177d09dd92174f9f52740bccb025\", \"price_changes\":[{\"asset_id\":\"61819828071723399190623735325323968706432622380635304641786792960078828866875\", \"price\":\"0.85\", \"size\":\"5182.35\", \"side\":\"BUY\", \"hash\":\"feb050aed6b15d2c38a13862418724016d5a29b5\", \"best_bid\":\"0.86\", \"best_ask\":\"0.87\"}, {\"asset_id\":\"114356653315647913247200886351065428002113119844334520181865067698979836634569\", \"price\":\"0.15\", \"size\":\"5182.35\", \"side\":\"SELL\", \"hash\":\"6dfb4fd8df5aa26d45e915e353b61fd6fac5b018\", \"best_bid\":\"0.13\", \"best_ask\":\"0.14\"}], \"timestamp\":\"1789987927266\", \"event_type\":\"price_change\"}","raw_base64":null}
{"received_ms":1789987927319,"monotonic_ns":1019368149623100,"raw":"{\"market\":\"0x28a45972fccdaf0fba75dacc59725521035e177d09dd92174f9f52740bccb025\", \"price_changes\":[{\"asset_id\":\"61819828071723399190623735325323968706432622380635304641786792960078828866875\", \"price\":\"0.83\", \"size\":\"434\", \"side\":\"BUY\", \"hash\":\"4ddfbc955c9fb101c9c9f1759d3e6c6601317db1\", \"best_bid\":\"0.86\", \"best_ask\":\"0.87\"}, {\"asset_id\":\"114356653315647913247200886351065428002113119844334520181865067698979836634569\", \"price\":\"0.17\", \"size\":\"434\", \"side\":\"SELL\", \"hash\":\"990a1c9bb7956734f752fa675198e7e7a2a4132c\", \"best_bid\":\"0.13\", \"best_ask\":\"0.14\"}], \"timestamp\":\"1789987927288\", \"event_type\":\"price_change\"}","raw_base64":null}
{"received_ms":1789987927319,"monotonic_ns":1019368149691900,"raw":"{\"market\":\"0x28a45972fccdaf0fba75dacc59725521035e177d09dd92174f9f52740bccb025\", \"price_changes\":[{\"asset_id\":\"61819828071723399190623735325323968706432622380635304641786792960078828866875\", \"price\":\"0.84\", \"size\":\"3267\", \"side\":\"BUY\", \"hash\":\"5966b6de7b1310ff3f3b07fd66ad88b63f410f5e\", \"best_bid\":\"0.86\", \"best_ask\":\"0.87\"}, {\"asset_id\":\"114356653315647913247200886351065428002113119844334520181865067698979836634569\", \"price\":\"0.16\", \"size\":\"3267\", \"side\":\"SELL\", \"hash\":\"f12bbd9e3cd8b1ff1a15bae7035cd99b8ce508dc\", \"best_bid\":\"0.13\", \"best_ask\":\"0.14\"}], \"timestamp\":\"1789987927292\", \"event_type\":\"price_change\"}","raw_base64":null}
{"received_ms":1789987927319,"monotonic_ns":1019368149742000,"raw":"{\"market\":\"0x28a45972fccdaf0fba75dacc59725521035e177d09dd92174f9f52740bccb025\", \"price_changes\":[{\"asset_id\":\"114356653315647913247200886351065428002113119844334520181865067698979836634569\", \"price\":\"0.07\", \"size\":\"5448.71\", \"side\":\"BUY\", \"hash\":\"aaa3169cad202f7db809f1a01670193f6d9a702f\", \"best_bid\":\"0.13\", \"best_ask\":\"0.14\"}, {\"asset_id\":\"61819828071723399190623735325323968706432622380635304641786792960078828866875\", \"price\":\"0.93\", \"size\":\"5448.71\", \"side\":\"SELL\", \"hash\":\"2f78a1d4b48972c4ba890f7f08514419cc4c1a2c\", \"best_bid\":\"0.86\", \"best_ask\":\"0.87\"}], \"timestamp\":\"1789987927298\", \"event_type\":\"price_change\"}","raw_base64":null}
{"received_ms":1789987927319,"monotonic_ns":1019368150214200,"raw":"{\"market\":\"0x28a45972fccdaf0fba75dacc59725521035e177d09dd92174f9f52740bccb025\", \"price_changes\":[{\"asset_id\":\"114356653315647913247200886351065428002113119844334520181865067698979836634569\", \"price\":\"0.06\", \"size\":\"6826.67\", \"side\":\"BUY\", \"hash\":\"3c58aeec477a4ffcd14acf835b6f3e4419b8242a\", \"best_bid\":\"0.13\", \"best_ask\":\"0.14\"}, {\"asset_id\":\"61819828071723399190623735325323968706432622380635304641786792960078828866875\", \"price\":\"0.94\", \"size\":\"6826.67\", \"side\":\"SELL\", \"hash\":\"6e085b72e2cb9eccf786a377a482485d42f05b7f\", \"best_bid\":\"0.86\", \"best_ask\":\"0.87\"}], \"timestamp\":\"1789987927298\", \"event_type\":\"price_change\"}","raw_base64":null}
{"received_ms":1789987927352,"monotonic_ns":1019368182667600,"raw":"{\"market\":\"0x28a45972fccdaf0fba75dacc59725521035e177d09dd92174f9f52740bccb025\", \"price_changes\":[{\"asset_id\":\"114356653315647913247200886351065428002113119844334520181865067698979836634569\", \"price\":\"0.07\", \"size\":\"5512.71\", \"side\":\"BUY\", \"hash\":\"7765a130ac8a1cd720292ac0cb5d31791065e992\", \"best_bid\":\"0.13\", \"best_ask\":\"0.14\"}, {\"asset_id\":\"61819828071723399190623735325323968706432622380635304641786792960078828866875\", \"price\":\"0.93\", \"size\":\"5512.71\", \"side\":\"SELL\", \"hash\":\"f394ae086b2d625ec0b3ddebc84b955688248275\", \"best_bid\":\"0.86\", \"best_ask\":\"0.87\"}], \"timestamp\":\"1789987927331\", \"event_type\":\"price_change\"}","raw_base64":null}
{"received_ms":1789987927353,"monotonic_ns":1019368183642700,"raw":"{\"market\":\"0x28a45972fccdaf0fba75dacc59725521035e177d09dd92174f9f52740bccb025\", \"price_changes\":[{\"asset_id\":\"114356653315647913247200886351065428002113119844334520181865067698979836634569\", \"price\":\"0.07\", \"size\":\"5093.71\", \"side\":\"BUY\", \"hash\":\"5d6d5c0f5601da501754716c56360ee0191775ea\", \"best_bid\":\"0.13\", \"best_ask\":\"0.14\"}, {\"asset_id\":\"61819828071723399190623735325323968706432622380635304641786792960078828866875\", \"price\":\"0.93\", \"size\":\"5093.71\", \"side\":\"SELL\", \"hash\":\"3488c7660db49cf576d9970063a6ea3f7f32a733\", \"best_bid\":\"0.86\", \"best_ask\":\"0.87\"}], \"timestamp\":\"1789987927333\", \"event_type\":\"price_change\"}","raw_base64":null}
{"received_ms":1789987927373,"monotonic_ns":1019368203937100,"raw":"{\"market\":\"0x28a45972fccdaf0fba75dacc59725521035e177d09dd92174f9f52740bccb025\", \"price_changes\":[{\"asset_id\":\"61819828071723399190623735325323968706432622380635304641786792960078828866875\", \"price\":\"0.86\", \"size\":\"5283.17\", \"side\":\"BUY\", \"hash\":\"df1c34f81b288a5d447d475a71288ebb0dc62fcd\", \"best_bid\":\"0.86\", \"best_ask\":\"0.87\"}, {\"asset_id\":\"114356653315647913247200886351065428002113119844334520181865067698979836634569\", \"price\":\"0.14\", \"size\":\"5283.17\", \"side\":\"SELL\", \"hash\":\"72edc6ebae1e824377a8626bdebc93aff1aa0c9f\", \"best_bid\":\"0.13\", \"best_ask\":\"0.14\"}], \"timestamp\":\"1789987927352\", \"event_type\":\"price_change\"}","raw_base64":null}
{"received_ms":1789987927373,"monotonic_ns":1019368204047500,"raw":"{\"market\":\"0x28a45972fccdaf0fba75dacc59725521035e177d09dd92174f9f52740bccb025\", \"price_changes\":[{\"asset_id\":\"61819828071723399190623735325323968706432622380635304641786792960078828866875\", \"price\":\"0.86\", \"size\":\"571.17\", \"side\":\"BUY\", \"hash\":\"65bbd5d629c118a948c1607f87e9b94b8e66da36\", \"best_bid\":\"0.86\", \"best_ask\":\"0.87\"}, {\"asset_id\":\"114356653315647913247200886351065428002113119844334520181865067698979836634569\", \"price\":\"0.14\", \"size\":\"571.17\", \"side\":\"SELL\", \"hash\":\"8514a9f9be93cf917d334785f08aabfb15063e33\", \"best_bid\":\"0.13\", \"best_ask\":\"0.14\"}], \"timestamp\":\"1789987927353\", \"event_type\":\"price_change\"}","raw_base64":null}
{"received_ms":1789987927384,"monotonic_ns":1019368214865600,"raw":"{\"market\":\"0x28a45972fccdaf0fba75dacc59725521035e177d09dd92174f9f52740bccb025\", \"price_changes\":[{\"asset_id\":\"114356653315647913247200886351065428002113119844334520181865067698979836634569\", \"price\":\"0.07\", \"size\":\"5647.71\", \"side\":\"BUY\", \"hash\":\"d8c225e5f0c8d9420324bded7867338489c21315\", \"best_bid\":\"0.13\", \"best_ask\":\"0.14\"}, {\"asset_id\":\"61819828071723399190623735325323968706432622380635304641786792960078828866875\", \"price\":\"0.93\", \"size\":\"5647.71\", \"side\":\"SELL\", \"hash\":\"111e9a4e5268444cfc7afcd0e86a57454cbdd497\", \"best_bid\":\"0.86\", \"best_ask\":\"0.87\"}], \"timestamp\":\"1789987927363\", \"event_type\":\"price_change\"}","raw_base64":null}
{"received_ms":1789987927388,"monotonic_ns":1019368219180200,"raw":"{\"market\":\"0x28a45972fccdaf0fba75dacc59725521035e177d09dd92174f9f52740bccb025\", \"price_changes\":[{\"asset_id\":\"61819828071723399190623735325323968706432622380635304641786792960078828866875\", \"price\":\"0.84\", \"size\":\"3207\", \"side\":\"BUY\", \"hash\":\"431b97d6f1881f8106e00878e49ac81a9659b4ce\", \"best_bid\":\"0.86\", \"best_ask\":\"0.87\"}, {\"asset_id\":\"114356653315647913247200886351065428002113119844334520181865067698979836634569\", \"price\":\"0.16\", \"size\":\"3207\", \"side\":\"SELL\", \"hash\":\"798f21952009e2823f55c7c8ed98bb3ef526f28b\", \"best_bid\":\"0.13\", \"best_ask\":\"0.14\"}], \"timestamp\":\"1789987927368\", \"event_type\":\"price_change\"}","raw_base64":null}
{"received_ms":1789987927395,"monotonic_ns":1019368225634500,"raw":"{\"market\":\"0x28a45972fccdaf0fba75dacc59725521035e177d09dd92174f9f52740bccb025\", \"price_changes\":[{\"asset_id\":\"114356653315647913247200886351065428002113119844334520181865067698979836634569\", \"price\":\"0.14\", \"size\":\"556.17\", \"side\":\"SELL\", \"hash\":\"0a962528c2d70f1c09ab30a9c7d0db7e7301a35f\", \"best_bid\":\"0.13\", \"best_ask\":\"0.14\"}, {\"asset_id\":\"61819828071723399190623735325323968706432622380635304641786792960078828866875\", \"price\":\"0.86\", \"size\":\"556.17\", \"side\":\"BUY\", \"hash\":\"29666fe665eab26b9d52b14bfbb3e118d5f8a0b0\", \"best_bid\":\"0.86\", \"best_ask\":\"0.87\"}], \"timestamp\":\"1789987927374\", \"event_type\":\"price_change\"}","raw_base64":null}
{"received_ms":1789987927404,"monotonic_ns":1019368235129200,"raw":"{\"market\":\"0x28a45972fccdaf0fba75dacc59725521035e177d09dd92174f9f52740bccb025\", \"price_changes\":[{\"asset_id\":\"114356653315647913247200886351065428002113119844334520181865067698979836634569\", \"price\":\"0.13\", \"size\":\"265\", \"side\":\"BUY\", \"hash\":\"6155c1b03877aa526429d79e2dc4042a7c237f92\", \"best_bid\":\"0.13\", \"best_ask\":\"0.14\"}, {\"asset_id\":\"61819828071723399190623735325323968706432622380635304641786792960078828866875\", \"price\":\"0.87\", \"size\":\"265\", \"side\":\"SELL\", \"hash\":\"d16d664f9332678bb15b855327636b0e55998650\", \"best_bid\":\"0.86\", \"best_ask\":\"0.87\"}], \"timestamp\":\"1789987927384\", \"event_type\":\"price_change\"}","raw_base64":null}
{"received_ms":1789987927413,"monotonic_ns":1019368243308000,"raw":"{\"market\":\"0x28a45972fccdaf0fba75dacc59725521035e177d09dd92174f9f52740bccb025\", \"price_changes\":[{\"asset_id\":\"61819828071723399190623735325323968706432622380635304641786792960078828866875\", \"price\":\"0.85\", \"size\":\"5355.35\", \"side\":\"BUY\", \"hash\":\"75382c998534b4f032ba075388cc309d6170afdd\", \"best_bid\":\"0.86\", \"best_ask\":\"0.87\"}, {\"asset_id\":\"114356653315647913247200886351065428002113119844334520181865067698979836634569\", \"price\":\"0.15\", \"size\":\"5355.35\", \"side\":\"SELL\", \"hash\":\"200880b0db284947506f1083b9a557371438874f\", \"best_bid\":\"0.13\", \"best_ask\":\"0.14\"}], \"timestamp\":\"1789987927393\", \"event_type\":\"price_change\"}","raw_base64":null}
{"received_ms":1789987927413,"monotonic_ns":1019368244199400,"raw":"{\"market\":\"0x28a45972fccdaf0fba75dacc59725521035e177d09dd92174f9f52740bccb025\", \"price_changes\":[{\"asset_id\":\"61819828071723399190623735325323968706432622380635304641786792960078828866875\", \"price\":\"0.86\", \"size\":\"5091.17\", \"side\":\"BUY\", \"hash\":\"02d02a55647dd00e21d798bc05c6b048fe8bedf2\", \"best_bid\":\"0.86\", \"best_ask\":\"0.87\"}, {\"asset_id\":\"114356653315647913247200886351065428002113119844334520181865067698979836634569\", \"price\":\"0.14\", \"size\":\"5091.17\", \"side\":\"SELL\", \"hash\":\"7fa907f83b59b564e49d2c2d673a044821b89abb\", \"best_bid\":\"0.13\", \"best_ask\":\"0.14\"}], \"timestamp\":\"1789987927393\", \"event_type\":\"price_change\"}","raw_base64":null}
{"received_ms":1789987927425,"monotonic_ns":1019368255726200,"raw":"{\"market\":\"0x28a45972fccdaf0fba75dacc59725521035e177d09dd92174f9f52740bccb025\", \"price_changes\":[{\"asset_id\":\"61819828071723399190623735325323968706432622380635304641786792960078828866875\", \"price\":\"0.84\", \"size\":\"3267\", \"side\":\"BUY\", \"hash\":\"044c52b9def91f43c2145599ac4eaf272a8ab821\", \"best_bid\":\"0.86\", \"best_ask\":\"0.87\"}, {\"asset_id\":\"114356653315647913247200886351065428002113119844334520181865067698979836634569\", \"price\":\"0.16\", \"size\":\"3267\", \"side\":\"SELL\", \"hash\":\"2a0a0b67ef237f62d9074e51dabf9bc7151e03f6\", \"best_bid\":\"0.13\", \"best_ask\":\"0.14\"}], \"timestamp\":\"1789987927405\", \"event_type\":\"price_change\"}","raw_base64":null}
{"received_ms":1789987927426,"monotonic_ns":1019368256384900,"raw":"{\"market\":\"0x28a45972fccdaf0fba75dacc59725521035e177d09dd92174f9f52740bccb025\", \"price_changes\":[{\"asset_id\":\"114356653315647913247200886351065428002113119844334520181865067698979836634569\", \"price\":\"0.06\", \"size\":\"5946.67\", \"side\":\"BUY\", \"hash\":\"5efa5193898f0d7e90d0dc8cd8d77be5b2939c32\", \"best_bid\":\"0.13\", \"best_ask\":\"0.14\"}, {\"asset_id\":\"61819828071723399190623735325323968706432622380635304641786792960078828866875\", \"price\":\"0.94\", \"size\":\"5946.67\", \"side\":\"SELL\", \"hash\":\"e02662afeef541a69490c226f72953f1666fd354\", \"best_bid\":\"0.86\", \"best_ask\":\"0.87\"}], \"timestamp\":\"1789987927406\", \"event_type\":\"price_change\"}","raw_base64":null}
{"received_ms":1789987927431,"monotonic_ns":1019368261950700,"raw":"{\"market\":\"0x28a45972fccdaf0fba75dacc59725521035e177d09dd92174f9f52740bccb025\", \"price_changes\":[{\"asset_id\":\"61819828071723399190623735325323968706432622380635304641786792960078828866875\", \"price\":\"0.86\", \"size\":\"5056\", \"side\":\"BUY\", \"hash\":\"9573af4ae15cda53bedecb686b7f0a8830288896\", \"best_bid\":\"0.86\", \"best_ask\":\"0.87\"}, {\"asset_id\":\"114356653315647913247200886351065428002113119844334520181865067698979836634569\", \"price\":\"0.14\", \"size\":\"5056\", \"side\":\"SELL\", \"hash\":\"84a140a5cb3809ddd5f6d86fe819c1adab870ab3\", \"best_bid\":\"0.13\", \"best_ask\":\"0.14\"}], \"timestamp\":\"1789987927410\", \"event_type\":\"price_change\"}","raw_base64":null}
{"received_ms":1789987927434,"monotonic_ns":1019368264398300,"raw":"{\"market\":\"0x28a45972fccdaf0fba75dacc59725521035e177d09dd92174f9f52740bccb025\", \"price_changes\":[{\"asset_id\":\"61819828071723399190623735325323968706432622380635304641786792960078828866875\", \"price\":\"0.85\", \"size\":\"5175.35\", \"side\":\"BUY\", \"hash\":\"f7f8cf9266161eedd5ecc56f6959e60d929113dc\", \"best_bid\":\"0.86\", \"best_ask\":\"0.87\"}, {\"asset_id\":\"114356653315647913247200886351065428002113119844334520181865067698979836634569\", \"price\":\"0.15\", \"size\":\"5175.35\", \"side\":\"SELL\", \"hash\":\"e1eb43e6c060b325c818369c964405b7ca18b94b\", \"best_bid\":\"0.13\", \"best_ask\":\"0.14\"}], \"timestamp\":\"1789987927412\", \"event_type\":\"price_change\"}","raw_base64":null}
{"received_ms":1789987927449,"monotonic_ns":1019368280226800,"raw":"{\"market\":\"0x28a45972fccdaf0fba75dacc59725521035e177d09dd92174f9f52740bccb025\", \"price_changes\":[{\"asset_id\":\"61819828071723399190623735325323968706432622380635304641786792960078828866875\", \"price\":\"0.84\", \"size\":\"3230\", \"side\":\"BUY\", \"hash\":\"9a21d99dce65daa4cffd731609ec2c2adf1dcb75\", \"best_bid\":\"0.86\", \"best_ask\":\"0.87\"}, {\"asset_id\":\"114356653315647913247200886351065428002113119844334520181865067698979836634569\", \"price\":\"0.16\", \"size\":\"3230\", \"side\":\"SELL\", \"hash\":\"a064f902434476aaca8ef2f9fb9be10eb6e6cf44\", \"best_bid\":\"0.13\", \"best_ask\":\"0.14\"}], \"timestamp\":\"1789987927419\", \"event_type\":\"price_change\"}","raw_base64":null}
{"received_ms":1789987927450,"monotonic_ns":1019368280315000,"raw":"{\"market\":\"0x28a45972fccdaf0fba75dacc59725521035e177d09dd92174f9f52740bccb025\", \"price_changes\":[{\"asset_id\":\"61819828071723399190623735325323968706432622380635304641786792960078828866875\", \"price\":\"0.79\", \"size\":\"447\", \"side\":\"BUY\", \"hash\":\"926f71fb465feceaf0208d74c438d44a3d59edbd\", \"best_bid\":\"0.86\", \"best_ask\":\"0.87\"}, {\"asset_id\":\"114356653315647913247200886351065428002113119844334520181865067698979836634569\", \"price\":\"0.21\", \"size\":\"447\", \"side\":\"SELL\", \"hash\":\"196eb694db64d6f64c23680ebc5dfc6ffa518a7a\", \"best_bid\":\"0.13\", \"best_ask\":\"0.14\"}], \"timestamp\":\"1789987927419\", \"event_type\":\"price_change\"}","raw_base64":null}
{"received_ms":1789987927450,"monotonic_ns":1019368280360100,"raw":"{\"market\":\"0x28a45972fccdaf0fba75dacc59725521035e177d09dd92174f9f52740bccb025\", \"price_changes\":[{\"asset_id\":\"61819828071723399190623735325323968706432622380635304641786792960078828866875\", \"price\":\"0.85\", \"size\":\"5165.35\", \"side\":\"BUY\", \"hash\":\"9360379f5082cc60123bff2b5c20d97748926c23\", \"best_bid\":\"0.86\", \"best_ask\":\"0.87\"}, {\"asset_id\":\"114356653315647913247200886351065428002113119844334520181865067698979836634569\", \"price\":\"0.15\", \"size\":\"5165.35\", \"side\":\"SELL\", \"hash\":\"0f1475d275e1913f15cf2b5d5d119737f7e6ff6f\", \"best_bid\":\"0.13\", \"best_ask\":\"0.14\"}], \"timestamp\":\"1789987927419\", \"event_type\":\"price_change\"}","raw_base64":null}
{"received_ms":1789987927450,"monotonic_ns":1019368280402800,"raw":"{\"market\":\"0x28a45972fccdaf0fba75dacc59725521035e177d09dd92174f9f52740bccb025\", \"price_changes\":[{\"asset_id\":\"114356653315647913247200886351065428002113119844334520181865067698979836634569\", \"price\":\"0.12\", \"size\":\"496\", \"side\":\"BUY\", \"hash\":\"454553106fec0042accc8398074a020fa5ab1bf9\", \"best_bid\":\"0.13\", \"best_ask\":\"0.14\"}, {\"asset_id\":\"61819828071723399190623735325323968706432622380635304641786792960078828866875\", \"price\":\"0.88\", \"size\":\"496\", \"side\":\"SELL\", \"hash\":\"92c606e9d225c0a48c6371de7e831de7ae23ec37\", \"best_bid\":\"0.86\", \"best_ask\":\"0.87\"}], \"timestamp\":\"1789987927420\", \"event_type\":\"price_change\"}","raw_base64":null}
{"received_ms":1789987927450,"monotonic_ns":1019368280445200,"raw":"{\"market\":\"0x28a45972fccdaf0fba75dacc59725521035e177d09dd92174f9f52740bccb025\", \"price_changes\":[{\"asset_id\":\"61819828071723399190623735325323968706432622380635304641786792960078828866875\", \"price\":\"0.86\", \"size\":\"5033\", \"side\":\"BUY\", \"hash\":\"ef2ded36ec7bbffe95702aca2a2215a774616707\", \"best_bid\":\"0.86\", \"best_ask\":\"0.87\"}, {\"asset_id\":\"114356653315647913247200886351065428002113119844334520181865067698979836634569\", \"price\":\"0.14\", \"size\":\"5033\", \"side\":\"SELL\", \"hash\":\"6d4ac28a3155f617b83e50303e8b3eb29ae0f87b\", \"best_bid\":\"0.13\", \"best_ask\":\"0.14\"}], \"timestamp\":\"1789987927421\", \"event_type\":\"price_change\"}","raw_base64":null}
{"received_ms":1789987927450,"monotonic_ns":1019368280492600,"raw":"{\"market\":\"0x28a45972fccdaf0fba75dacc59725521035e177d09dd92174f9f52740bccb025\", \"price_changes\":[{\"asset_id\":\"61819828071723399190623735325323968706432622380635304641786792960078828866875\", \"price\":\"0.85\", \"size\":\"5160.35\", \"side\":\"BUY\", \"hash\":\"67705a3fa514881a13733d000b8a7e620b0334ee\", \"best_bid\":\"0.86\", \"best_ask\":\"0.87\"}, {\"asset_id\":\"114356653315647913247200886351065428002113119844334520181865067698979836634569\", \"price\":\"0.15\", \"size\":\"5160.35\", \"side\":\"SELL\", \"hash\":\"a93e062ce72500fe4d7dbeaa1c257e46c22c108f\", \"best_bid\":\"0.13\", \"best_ask\":\"0.14\"}], \"timestamp\":\"1789987927421\", \"event_type\":\"price_change\"}","raw_base64":null}
{"received_ms":1789987927450,"monotonic_ns":1019368280533500,"raw":"{\"market\":\"0x28a45972fccdaf0fba75dacc59725521035e177d09dd92174f9f52740bccb025\", \"price_changes\":[{\"asset_id\":\"61819828071723399190623735325323968706432622380635304641786792960078828866875\", \"price\":\"0.85\", \"size\":\"5155.35\", \"side\":\"BUY\", \"hash\":\"647fa296df21a33a2c0f851a4a732a4b288feeca\", \"best_bid\":\"0.86\", \"best_ask\":\"0.87\"}, {\"asset_id\":\"114356653315647913247200886351065428002113119844334520181865067698979836634569\", \"price\":\"0.15\", \"size\":\"5155.35\", \"side\":\"SELL\", \"hash\":\"d1f62602f81f8832fe903c2520f4872316746bf0\", \"best_bid\":\"0.13\", \"best_ask\":\"0.14\"}], \"timestamp\":\"1789987927421\", \"event_type\":\"price_change\"}","raw_base64":null}
{"received_ms":1789987927450,"monotonic_ns":1019368280573700,"raw":"{\"market\":\"0x28a45972fccdaf0fba75dacc59725521035e177d09dd92174f9f52740bccb025\", \"price_changes\":[{\"asset_id\":\"114356653315647913247200886351065428002113119844334520181865067698979836634569\", \"price\":\"0.13\", \"size\":\"255\", \"side\":\"BUY\", \"hash\":\"8960545c618d6c699fedd561ce1915ec3262bcd6\", \"best_bid\":\"0.13\", \"best_ask\":\"0.14\"}, {\"asset_id\":\"61819828071723399190623735325323968706432622380635304641786792960078828866875\", \"price\":\"0.87\", \"size\":\"255\", \"side\":\"SELL\", \"hash\":\"1103d16dd93fd13c463e46a0ebc588e9dd2a1968\", \"best_bid\":\"0.86\", \"best_ask\":\"0.87\"}], \"timestamp\":\"1789987927422\", \"event_type\":\"price_change\"}","raw_base64":null}
{"received_ms":1789987927450,"monotonic_ns":1019368280615700,"raw":"{\"market\":\"0x28a45972fccdaf0fba75dacc59725521035e177d09dd92174f9f52740bccb025\", \"price_changes\":[{\"asset_id\":\"61819828071723399190623735325323968706432622380635304641786792960078828866875\", \"price\":\"0.85\", \"size\":\"5145.35\", \"side\":\"BUY\", \"hash\":\"03ea9042cb345d40577df2e9b5ae908e8c3f9da1\", \"best_bid\":\"0.86\", \"best_ask\":\"0.87\"}, {\"asset_id\":\"114356653315647913247200886351065428002113119844334520181865067698979836634569\", \"price\":\"0.15\", \"size\":\"5145.35\", \"side\":\"SELL\", \"hash\":\"47b94605c339836d6f2131c6c35f5979f4b1300d\", \"best_bid\":\"0.13\", \"best_ask\":\"0.14\"}], \"timestamp\":\"1789987927422\", \"event_type\":\"price_change\"}","raw_base64":null}
{"received_ms":1789987927450,"monotonic_ns":1019368280656000,"raw":"{\"market\":\"0x28a45972fccdaf0fba75dacc59725521035e177d09dd92174f9f52740bccb025\", \"price_changes\":[{\"asset_id\":\"114356653315647913247200886351065428002113119844334520181865067698979836634569\", \"price\":\"0.11\", \"size\":\"136.1\", \"side\":\"BUY\", \"hash\":\"d694f08ab2fc0f8c04085e0def499dd76da6d3e9\", \"best_bid\":\"0.13\", \"best_ask\":\"0.14\"}, {\"asset_id\":\"61819828071723399190623735325323968706432622380635304641786792960078828866875\", \"price\":\"0.89\", \"size\":\"136.1\", \"side\":\"SELL\", \"hash\":\"d318ad61ed1cf3a6dc6406d1c873eedc378c1b76\", \"best_bid\":\"0.86\", \"best_ask\":\"0.87\"}], \"timestamp\":\"1789987927422\", \"event_type\":\"price_change\"}","raw_base64":null}
{"received_ms":1789987927450,"monotonic_ns":1019368280698800,"raw":"{\"market\":\"0x28a45972fccdaf0fba75dacc59725521035e177d09dd92174f9f52740bccb025\", \"price_changes\":[{\"asset_id\":\"61819828071723399190623735325323968706432622380635304641786792960078828866875\", \"price\":\"0.85\", \"size\":\"5135.35\", \"side\":\"BUY\", \"hash\":\"fbb566b3aea2e1bc03312d8f19c65e1d9b6bd246\", \"best_bid\":\"0.86\", \"best_ask\":\"0.87\"}, {\"asset_id\":\"114356653315647913247200886351065428002113119844334520181865067698979836634569\", \"price\":\"0.15\", \"size\":\"5135.35\", \"side\":\"SELL\", \"hash\":\"82387b1904c0687178d7c19695b689c3485c90cb\", \"best_bid\":\"0.13\", \"best_ask\":\"0.14\"}], \"timestamp\":\"1789987927423\", \"event_type\":\"price_change\"}","raw_base64":null}
{"received_ms":1789987927450,"monotonic_ns":1019368280739100,"raw":"{\"market\":\"0x28a45972fccdaf0fba75dacc59725521035e177d09dd92174f9f52740bccb025\", \"price_changes\":[{\"asset_id\":\"61819828071723399190623735325323968706432622380635304641786792960078828866875\", \"price\":\"0.75\", \"size\":\"430\", \"side\":\"BUY\", \"hash\":\"8123cc27a9514a44924c17b817fea567efa1dbbc\", \"best_bid\":\"0.86\", \"best_ask\":\"0.87\"}, {\"asset_id\":\"114356653315647913247200886351065428002113119844334520181865067698979836634569\", \"price\":\"0.25\", \"size\":\"430\", \"side\":\"SELL\", \"hash\":\"7224a27e12fa4b5a9e148ac9e23bbc06b93cc590\", \"best_bid\":\"0.13\", \"best_ask\":\"0.14\"}], \"timestamp\":\"1789987927423\", \"event_type\":\"price_change\"}","raw_base64":null}
{"received_ms":1789987927450,"monotonic_ns":1019368281132800,"raw":"{\"market\":\"0x28a45972fccdaf0fba75dacc59725521035e177d09dd92174f9f52740bccb025\", \"price_changes\":[{\"asset_id\":\"114356653315647913247200886351065428002113119844334520181865067698979836634569\", \"price\":\"0.07\", \"size\":\"5093.71\", \"side\":\"BUY\", \"hash\":\"5b4d7addb8c4aa87d68affc99ab8208cfe1a18e2\", \"best_bid\":\"0.13\", \"best_ask\":\"0.14\"}, {\"asset_id\":\"61819828071723399190623735325323968706432622380635304641786792960078828866875\", \"price\":\"0.93\", \"size\":\"5093.71\", \"side\":\"SELL\", \"hash\":\"1d2b36cb836afef10d7b9ba3c83bfc2c4bf86ecf\", \"best_bid\":\"0.86\", \"best_ask\":\"0.87\"}], \"timestamp\":\"1789987927424\", \"event_type\":\"price_change\"}","raw_base64":null}
{"received_ms":1789987927450,"monotonic_ns":1019368281185000,"raw":"{\"market\":\"0x28a45972fccdaf0fba75dacc59725521035e177d09dd92174f9f52740bccb025\", \"price_changes\":[{\"asset_id\":\"114356653315647913247200886351065428002113119844334520181865067698979836634569\", \"price\":\"0.1\", \"size\":\"537\", \"side\":\"BUY\", \"hash\":\"aed65d4ab036fd3fd017e528a3a5db5d4f5a01bf\", \"best_bid\":\"0.13\", \"best_ask\":\"0.14\"}, {\"asset_id\":\"61819828071723399190623735325323968706432622380635304641786792960078828866875\", \"price\":\"0.9\", \"size\":\"537\", \"side\":\"SELL\", \"hash\":\"8c92858c4c46cf21ce4f0436e76289f80c35962e\", \"best_bid\":\"0.86\", \"best_ask\":\"0.87\"}], \"timestamp\":\"1789987927425\", \"event_type\":\"price_change\"}","raw_base64":null}
{"received_ms":1789987927450,"monotonic_ns":1019368281229200,"raw":"{\"market\":\"0x28a45972fccdaf0fba75dacc59725521035e177d09dd92174f9f52740bccb025\", \"price_changes\":[{\"asset_id\":\"114356653315647913247200886351065428002113119844334520181865067698979836634569\", \"price\":\"0.11\", \"size\":\"316.1\", \"side\":\"BUY\", \"hash\":\"a9e4d04cd43cd3f6b19cd3ca02be855cc2644fcc\", \"best_bid\":\"0.13\", \"best_ask\":\"0.14\"}, {\"asset_id\":\"61819828071723399190623735325323968706432622380635304641786792960078828866875\", \"price\":\"0.89\", \"size\":\"316.1\", \"side\":\"SELL\", \"hash\":\"fc5d92333a3d39e632aad0ecdda19233389006cf\", \"best_bid\":\"0.86\", \"best_ask\":\"0.87\"}], \"timestamp\":\"1789987927426\", \"event_type\":\"price_change\"}","raw_base64":null}
{"received_ms":1789987927450,"monotonic_ns":1019368281271100,"raw":"{\"market\":\"0x28a45972fccdaf0fba75dacc59725521035e177d09dd92174f9f52740bccb025\", \"price_changes\":[{\"asset_id\":\"114356653315647913247200886351065428002113119844334520181865067698979836634569\", \"price\":\"0.13\", \"size\":\"270\", \"side\":\"BUY\", \"hash\":\"c1dcde6ec0df075be871faa55e6ee542fabfe87d\", \"best_bid\":\"0.13\", \"best_ask\":\"0.14\"}, {\"asset_id\":\"61819828071723399190623735325323968706432622380635304641786792960078828866875\", \"price\":\"0.87\", \"size\":\"270\", \"side\":\"SELL\", \"hash\":\"787fc91bb7ab3d42aca310bb05403f6ee159bf88\", \"best_bid\":\"0.86\", \"best_ask\":\"0.87\"}], \"timestamp\":\"1789987927427\", \"event_type\":\"price_change\"}","raw_base64":null}
{"received_ms":1789987927456,"monotonic_ns":1019368286858600,"raw":"{\"market\":\"0x28a45972fccdaf0fba75dacc59725521035e177d09dd92174f9f52740bccb025\", \"price_changes\":[{\"asset_id\":\"61819828071723399190623735325323968706432622380635304641786792960078828866875\", \"price\":\"0.82\", \"size\":\"761\", \"side\":\"BUY\", \"hash\":\"ecdc8a1b2218070d76112d859cff1867760cfe90\", \"best_bid\":\"0.86\", \"best_ask\":\"0.87\"}, {\"asset_id\":\"114356653315647913247200886351065428002113119844334520181865067698979836634569\", \"price\":\"0.18\", \"size\":\"761\", \"side\":\"SELL\", \"hash\":\"355c0c44fc190cbf56009f1b8c321ea185690088\", \"best_bid\":\"0.13\", \"best_ask\":\"0.14\"}], \"timestamp\":\"1789987927428\", \"event_type\":\"price_change\"}","raw_base64":null}
{"received_ms":1789987927456,"monotonic_ns":1019368286932400,"raw":"{\"market\":\"0x28a45972fccdaf0fba75dacc59725521035e177d09dd92174f9f52740bccb025\", \"price_changes\":[{\"asset_id\":\"61819828071723399190623735325323968706432622380635304641786792960078828866875\", \"price\":\"0.85\", \"size\":\"5115.35\", \"side\":\"BUY\", \"hash\":\"91ee029cbdbab5d6b03e82e4ac6784e8f0e019af\", \"best_bid\":\"0.86\", \"best_ask\":\"0.87\"}, {\"asset_id\":\"114356653315647913247200886351065428002113119844334520181865067698979836634569\", \"price\":\"0.15\", \"size\":\"5115.35\", \"side\":\"SELL\", \"hash\":\"7a0e27d32997204c056bb2fcc8cb74d69b2acaf6\", \"best_bid\":\"0.13\", \"best_ask\":\"0.14\"}], \"timestamp\":\"1789987927429\", \"event_type\":\"price_change\"}","raw_base64":null}
{"received_ms":1789987927456,"monotonic_ns":1019368286979200,"raw":"{\"market\":\"0x28a45972fccdaf0fba75dacc59725521035e177d09dd92174f9f52740bccb025\", \"price_changes\":[{\"asset_id\":\"61819828071723399190623735325323968706432622380635304641786792960078828866875\", \"price\":\"0.84\", \"size\":\"3220\", \"side\":\"BUY\", \"hash\":\"d38faa6e0103a4ee585b63f336afa50287dbf18e\", \"best_bid\":\"0.86\", \"best_ask\":\"0.87\"}, {\"asset_id\":\"114356653315647913247200886351065428002113119844334520181865067698979836634569\", \"price\":\"0.16\", \"size\":\"3220\", \"side\":\"SELL\", \"hash\":\"d93e1580d43be335d82d18a211acfdec85d69911\", \"best_bid\":\"0.13\", \"best_ask\":\"0.14\"}], \"timestamp\":\"1789987927429\", \"event_type\":\"price_change\"}","raw_base64":null}
{"received_ms":1789987927456,"monotonic_ns":1019368287024900,"raw":"{\"market\":\"0x28a45972fccdaf0fba75dacc59725521035e177d09dd92174f9f52740bccb025\", \"price_changes\":[{\"asset_id\":\"61819828071723399190623735325323968706432622380635304641786792960078828866875\", \"price\":\"0.84\", \"size\":\"3212\", \"side\":\"BUY\", \"hash\":\"5749898ab87fdd9ceb79d0d4ea49b9892231d464\", \"best_bid\":\"0.86\", \"best_ask\":\"0.87\"}, {\"asset_id\":\"114356653315647913247200886351065428002113119844334520181865067698979836634569\", \"price\":\"0.16\", \"size\":\"3212\", \"side\":\"SELL\", \"hash\":\"284edeef44b7115832197fc3b9a13382209cda48\", \"best_bid\":\"0.13\", \"best_ask\":\"0.14\"}], \"timestamp\":\"1789987927430\", \"event_type\":\"price_change\"}","raw_base64":null}
{"received_ms":1789987927456,"monotonic_ns":1019368287077300,"raw":"{\"market\":\"0x28a45972fccdaf0fba75dacc59725521035e177d09dd92174f9f52740bccb025\", \"price_changes\":[{\"asset_id\":\"61819828071723399190623735325323968706432622380635304641786792960078828866875\", \"price\":\"0.86\", \"size\":\"5043\", \"side\":\"BUY\", \"hash\":\"c1c9c5671b52dfce09185eb0bc185d1fc9a2e529\", \"best_bid\":\"0.86\", \"best_ask\":\"0.87\"}, {\"asset_id\":\"114356653315647913247200886351065428002113119844334520181865067698979836634569\", \"price\":\"0.14\", \"size\":\"5043\", \"side\":\"SELL\", \"hash\":\"bf39094d3f5930fb48fa3162f7d285daebae4403\", \"best_bid\":\"0.13\", \"best_ask\":\"0.14\"}], \"timestamp\":\"1789987927430\", \"event_type\":\"price_change\"}","raw_base64":null}
{"received_ms":1789987927456,"monotonic_ns":1019368287120200,"raw":"{\"market\":\"0x28a45972fccdaf0fba75dacc59725521035e177d09dd92174f9f52740bccb025\", \"price_changes\":[{\"asset_id\":\"114356653315647913247200886351065428002113119844334520181865067698979836634569\", \"price\":\"0.09\", \"size\":\"610.12\", \"side\":\"BUY\", \"hash\":\"0ded40dcea41d8f0af345a5f532a83410e8aa387\", \"best_bid\":\"0.13\", \"best_ask\":\"0.14\"}, {\"asset_id\":\"61819828071723399190623735325323968706432622380635304641786792960078828866875\", \"price\":\"0.91\", \"size\":\"610.12\", \"side\":\"SELL\", \"hash\":\"07ea11ebcab043d896b98e62007a813d575e6a2e\", \"best_bid\":\"0.86\", \"best_ask\":\"0.87\"}], \"timestamp\":\"1789987927433\", \"event_type\":\"price_change\"}","raw_base64":null}
{"received_ms":1789987927463,"monotonic_ns":1019368293909800,"raw":"{\"market\":\"0x28a45972fccdaf0fba75dacc59725521035e177d09dd92174f9f52740bccb025\", \"price_changes\":[{\"asset_id\":\"114356653315647913247200886351065428002113119844334520181865067698979836634569\", \"price\":\"0.12\", \"size\":\"676\", \"side\":\"BUY\", \"hash\":\"d09d2986a706de900477191357542a0eab21eedc\", \"best_bid\":\"0.13\", \"best_ask\":\"0.14\"}, {\"asset_id\":\"61819828071723399190623735325323968706432622380635304641786792960078828866875\", \"price\":\"0.88\", \"size\":\"676\", \"side\":\"SELL\", \"hash\":\"0eba9a34b84b69570f90e03e1939f3a81eb07403\", \"best_bid\":\"0.86\", \"best_ask\":\"0.87\"}], \"timestamp\":\"1789987927441\", \"event_type\":\"price_change\"}","raw_base64":null}
{"received_ms":1789987927465,"monotonic_ns":1019368295839300,"raw":"{\"market\":\"0x28a45972fccdaf0fba75dacc59725521035e177d09dd92174f9f52740bccb025\", \"price_changes\":[{\"asset_id\":\"114356653315647913247200886351065428002113119844334520181865067698979836634569\", \"price\":\"0.13\", \"size\":\"260\", \"side\":\"BUY\", \"hash\":\"14decd87a5eba04d2fef66b1a4eea3ded6e3c944\", \"best_bid\":\"0.13\", \"best_ask\":\"0.14\"}, {\"asset_id\":\"61819828071723399190623735325323968706432622380635304641786792960078828866875\", \"price\":\"0.87\", \"size\":\"260\", \"side\":\"SELL\", \"hash\":\"f1423adeb2204f5bab8a2ace685f2b8091f8c64a\", \"best_bid\":\"0.86\", \"best_ask\":\"0.87\"}], \"timestamp\":\"1789987927442\", \"event_type\":\"price_change\"}","raw_base64":null}
{"received_ms":1789987927473,"monotonic_ns":1019368303285700,"raw":"{\"market\":\"0x28a45972fccdaf0fba75dacc59725521035e177d09dd92174f9f52740bccb025\", \"price_changes\":[{\"asset_id\":\"61819828071723399190623735325323968706432622380635304641786792960078828866875\", \"price\":\"0.85\", \"size\":\"4357.35\", \"side\":\"BUY\", \"hash\":\"44f90c3320a0dbb1641f65769dcec0fb68804c0a\", \"best_bid\":\"0.86\", \"best_ask\":\"0.87\"}, {\"asset_id\":\"114356653315647913247200886351065428002113119844334520181865067698979836634569\", \"price\":\"0.15\", \"size\":\"4357.35\", \"side\":\"SELL\", \"hash\":\"21ea181acafc75a0b0f88654264438670be1e575\", \"best_bid\":\"0.13\", \"best_ask\":\"0.14\"}], \"timestamp\":\"1789987927449\", \"event_type\":\"price_change\"}","raw_base64":null}
{"received_ms":1789987927476,"monotonic_ns":1019368307083000,"raw":"{\"market\":\"0x28a45972fccdaf0fba75dacc59725521035e177d09dd92174f9f52740bccb025\", \"price_changes\":[{\"asset_id\":\"114356653315647913247200886351065428002113119844334520181865067698979836634569\", \"price\":\"0.07\", \"size\":\"576.71\", \"side\":\"BUY\", \"hash\":\"5a807cb38cc236f9836d1525efa7ce4f4b5c2cd4\", \"best_bid\":\"0.13\", \"best_ask\":\"0.14\"}, {\"asset_id\":\"61819828071723399190623735325323968706432622380635304641786792960078828866875\", \"price\":\"0.93\", \"size\":\"576.71\", \"side\":\"SELL\", \"hash\":\"a815041f4638c8deaeee0af0766999944ab7522e\", \"best_bid\":\"0.86\", \"best_ask\":\"0.87\"}], \"timestamp\":\"1789987927451\", \"event_type\":\"price_change\"}","raw_base64":null}
{"received_ms":1789987927476,"monotonic_ns":1019368307181100,"raw":"{\"market\":\"0x28a45972fccdaf0fba75dacc59725521035e177d09dd92174f9f52740bccb025\", \"price_changes\":[{\"asset_id\":\"61819828071723399190623735325323968706432622380635304641786792960078828866875\", \"price\":\"0.79\", \"size\":\"507\", \"side\":\"BUY\", \"hash\":\"d7edf0f438e2cf2c36b6c679d1dbe1957fe3c7d9\", \"best_bid\":\"0.86\", \"best_ask\":\"0.87\"}, {\"asset_id\":\"114356653315647913247200886351065428002113119844334520181865067698979836634569\", \"price\":\"0.21\", \"size\":\"507\", \"side\":\"SELL\", \"hash\":\"32bd17638aacb654e4d256c933ff686e819a287b\", \"best_bid\":\"0.13\", \"best_ask\":\"0.14\"}], \"timestamp\":\"1789987927451\", \"event_type\":\"price_change\"}","raw_base64":null}
{"received_ms":1789987927481,"monotonic_ns":1019368311432300,"raw":"{\"market\":\"0x28a45972fccdaf0fba75dacc59725521035e177d09dd92174f9f52740bccb025\", \"price_changes\":[{\"asset_id\":\"61819828071723399190623735325323968706432622380635304641786792960078828866875\", \"price\":\"0.83\", \"size\":\"439\", \"side\":\"BUY\", \"hash\":\"0b34c06c68bbe6f4341f18a2b06f704ce688d2c4\", \"best_bid\":\"0.86\", \"best_ask\":\"0.87\"}, {\"asset_id\":\"114356653315647913247200886351065428002113119844334520181865067698979836634569\", \"price\":\"0.17\", \"size\":\"439\", \"side\":\"SELL\", \"hash\":\"ab9b76c3d4f9c28361308ae01fa008d6b9ae8fa5\", \"best_bid\":\"0.13\", \"best_ask\":\"0.14\"}], \"timestamp\":\"1789987927454\", \"event_type\":\"price_change\"}","raw_base64":null}
{"received_ms":1789987927490,"monotonic_ns":1019368320486800,"raw":"{\"market\":\"0x28a45972fccdaf0fba75dacc59725521035e177d09dd92174f9f52740bccb025\", \"price_changes\":[{\"asset_id\":\"61819828071723399190623735325323968706432622380635304641786792960078828866875\", \"price\":\"0.92\", \"size\":\"694.5\", \"side\":\"SELL\", \"hash\":\"4c7df0b8f51b84acdf96c36348cc68a5c9d2bb24\", \"best_bid\":\"0.86\", \"best_ask\":\"0.87\"}, {\"asset_id\":\"114356653315647913247200886351065428002113119844334520181865067698979836634569\", \"price\":\"0.08\", \"size\":\"694.5\", \"side\":\"BUY\", \"hash\":\"2bab6f86f8cdea05827f66903763118b5749b9b0\", \"best_bid\":\"0.13\", \"best_ask\":\"0.14\"}], \"timestamp\":\"1789987927456\", \"event_type\":\"price_change\"}","raw_base64":null}
{"received_ms":1789987927490,"monotonic_ns":1019368320551700,"raw":"{\"market\":\"0x28a45972fccdaf0fba75dacc59725521035e177d09dd92174f9f52740bccb025\", \"price_changes\":[{\"asset_id\":\"61819828071723399190623735325323968706432622380635304641786792960078828866875\", \"price\":\"0.94\", \"size\":\"5976.67\", \"side\":\"SELL\", \"hash\":\"727be8769209079a4de77ba766a83e84a67fb299\", \"best_bid\":\"0.86\", \"best_ask\":\"0.87\"}, {\"asset_id\":\"114356653315647913247200886351065428002113119844334520181865067698979836634569\", \"price\":\"0.06\", \"size\":\"5976.67\", \"side\":\"BUY\", \"hash\":\"4f4d6d6c851a91f3c8eee565a62673c572933d21\", \"best_bid\":\"0.13\", \"best_ask\":\"0.14\"}], \"timestamp\":\"1789987927456\", \"event_type\":\"price_change\"}","raw_base64":null}
{"received_ms":1789987927490,"monotonic_ns":1019368320602300,"raw":"{\"market\":\"0x28a45972fccdaf0fba75dacc59725521035e177d09dd92174f9f52740bccb025\", \"price_changes\":[{\"asset_id\":\"61819828071723399190623735325323968706432622380635304641786792960078828866875\", \"price\":\"0.82\", \"size\":\"753\", \"side\":\"BUY\", \"hash\":\"362929b4675b1f110f1a4b9a19d974c67b877b3b\", \"best_bid\":\"0.86\", \"best_ask\":\"0.87\"}, {\"asset_id\":\"114356653315647913247200886351065428002113119844334520181865067698979836634569\", \"price\":\"0.18\", \"size\":\"753\", \"side\":\"SELL\", \"hash\":\"293eae1c5baae65c1950036af860518e1720be6e\", \"best_bid\":\"0.13\", \"best_ask\":\"0.14\"}], \"timestamp\":\"1789987927457\", \"event_type\":\"price_change\"}","raw_base64":null}
{"received_ms":1789987927490,"monotonic_ns":1019368320648400,"raw":"{\"market\":\"0x28a45972fccdaf0fba75dacc59725521035e177d09dd92174f9f52740bccb025\", \"price_changes\":[{\"asset_id\":\"61819828071723399190623735325323968706432622380635304641786792960078828866875\", \"price\":\"0.85\", \"size\":\"4257.35\", \"side\":\"BUY\", \"hash\":\"cac0569f789e6c6c18e272d0b3d63ec076ba39e0\", \"best_bid\":\"0.86\", \"best_ask\":\"0.87\"}, {\"asset_id\":\"114356653315647913247200886351065428002113119844334520181865067698979836634569\", \"price\":\"0.15\", \"size\":\"4257.35\", \"side\":\"SELL\", \"hash\":\"4bee5fd213416590d03258a0823e22122d44b151\", \"best_bid\":\"0.13\", \"best_ask\":\"0.14\"}], \"timestamp\":\"1789987927457\", \"event_type\":\"price_change\"}","raw_base64":null}
{"received_ms":1789987927490,"monotonic_ns":1019368320874300,"raw":"{\"market\":\"0x28a45972fccdaf0fba75dacc59725521035e177d09dd92174f9f52740bccb025\", \"price_changes\":[{\"asset_id\":\"114356653315647913247200886351065428002113119844334520181865067698979836634569\", \"price\":\"0.06\", \"size\":\"5951.67\", \"side\":\"BUY\", \"hash\":\"8153cb8da8ed9b60855897d984d7e9b8ded2c05c\", \"best_bid\":\"0.13\", \"best_ask\":\"0.14\"}, {\"asset_id\":\"61819828071723399190623735325323968706432622380635304641786792960078828866875\", \"price\":\"0.94\", \"size\":\"5951.67\", \"side\":\"SELL\", \"hash\":\"74272a6371b84431e1daa9139ea6c7b595387631\", \"best_bid\":\"0.86\", \"best_ask\":\"0.87\"}], \"timestamp\":\"1789987927457\", \"event_type\":\"price_change\"}","raw_base64":null}
{"received_ms":1789987927490,"monotonic_ns":1019368320926200,"raw":"{\"market\":\"0x28a45972fccdaf0fba75dacc59725521035e177d09dd92174f9f52740bccb025\", \"price_changes\":[{\"asset_id\":\"61819828071723399190623735325323968706432622380635304641786792960078828866875\", \"price\":\"0.86\", \"size\":\"5018\", \"side\":\"BUY\", \"hash\":\"1691bfc6ccf45eab8babfef61ddf13fac4d3c67e\", \"best_bid\":\"0.86\", \"best_ask\":\"0.87\"}, {\"asset_id\":\"114356653315647913247200886351065428002113119844334520181865067698979836634569\", \"price\":\"0.14\", \"size\":\"5018\", \"side\":\"SELL\", \"hash\":\"fdd56386c3d264429abd1c1b1cfff5d2fdbe822e\", \"best_bid\":\"0.13\", \"best_ask\":\"0.14\"}], \"timestamp\":\"1789987927457\", \"event_type\":\"price_change\"}","raw_base64":null}
{"received_ms":1789987927490,"monotonic_ns":1019368320985800,"raw":"{\"market\":\"0x28a45972fccdaf0fba75dacc59725521035e177d09dd92174f9f52740bccb025\", \"price_changes\":[{\"asset_id\":\"61819828071723399190623735325323968706432622380635304641786792960078828866875\", \"price\":\"0.79\", \"size\":\"447\", \"side\":\"BUY\", \"hash\":\"0d0230bbfc748d7e26e3bb37c41a3480da9fbcc5\", \"best_bid\":\"0.86\", \"best_ask\":\"0.87\"}, {\"asset_id\":\"114356653315647913247200886351065428002113119844334520181865067698979836634569\", \"price\":\"0.21\", \"size\":\"447\", \"side\":\"SELL\", \"hash\":\"3c99d7142aed160d225800d7fff3a78abc67c7fc\", \"best_bid\":\"0.13\", \"best_ask\":\"0.14\"}], \"timestamp\":\"1789987927458\", \"event_type\":\"price_change\"}","raw_base64":null}
{"received_ms":1789987927490,"monotonic_ns":1019368321028700,"raw":"{\"market\":\"0x28a45972fccdaf0fba75dacc59725521035e177d09dd92174f9f52740bccb025\", \"price_changes\":[{\"asset_id\":\"61819828071723399190623735325323968706432622380635304641786792960078828866875\", \"price\":\"0.85\", \"size\":\"1392.35\", \"side\":\"BUY\", \"hash\":\"90db1bfeb51ce0dce75b0f5a369823c222746ee7\", \"best_bid\":\"0.86\", \"best_ask\":\"0.87\"}, {\"asset_id\":\"114356653315647913247200886351065428002113119844334520181865067698979836634569\", \"price\":\"0.15\", \"size\":\"1392.35\", \"side\":\"SELL\", \"hash\":\"ce33939200efab4ee7cc068ad20da89589f36194\", \"best_bid\":\"0.13\", \"best_ask\":\"0.14\"}], \"timestamp\":\"1789987927458\", \"event_type\":\"price_change\"}","raw_base64":null}
{"received_ms":1789987927490,"monotonic_ns":1019368321076100,"raw":"{\"market\":\"0x28a45972fccdaf0fba75dacc59725521035e177d09dd92174f9f52740bccb025\", \"price_changes\":[{\"asset_id\":\"61819828071723399190623735325323968706432622380635304641786792960078828866875\", \"price\":\"0.86\", \"size\":\"4782\", \"side\":\"BUY\", \"hash\":\"c29a465a8e720ea06c0908805d12df31a448e2f0\", \"best_bid\":\"0.86\", \"best_ask\":\"0.87\"}, {\"asset_id\":\"114356653315647913247200886351065428002113119844334520181865067698979836634569\", \"price\":\"0.14\", \"size\":\"4782\", \"side\":\"SELL\", \"hash\":\"ba67404600425aee2f9678e51c26c03e37f27399\", \"best_bid\":\"0.13\", \"best_ask\":\"0.14\"}], \"timestamp\":\"1789987927458\", \"event_type\":\"price_change\"}","raw_base64":null}
{"received_ms":1789987927490,"monotonic_ns":1019368321117400,"raw":"{\"market\":\"0x28a45972fccdaf0fba75dacc59725521035e177d09dd92174f9f52740bccb025\", \"price_changes\":[{\"asset_id\":\"114356653315647913247200886351065428002113119844334520181865067698979836634569\", \"price\":\"0.05\", \"size\":\"773\", \"side\":\"BUY\", \"hash\":\"d4c1fd724175d4a0d36bb8bdfe0f82190fbf215f\", \"best_bid\":\"0.13\", \"best_ask\":\"0.14\"}, {\"asset_id\":\"61819828071723399190623735325323968706432622380635304641786792960078828866875\", \"price\":\"0.95\", \"size\":\"773\", \"side\":\"SELL\", \"hash\":\"6a6d52af87d71121b2da573c4cc3b30a0d3c0144\", \"best_bid\":\"0.86\", \"best_ask\":\"0.87\"}], \"timestamp\":\"1789987927458\", \"event_type\":\"price_change\"}","raw_base64":null}
{"received_ms":1789987927491,"monotonic_ns":1019368321377800,"raw":"{\"market\":\"0x28a45972fccdaf0fba75dacc59725521035e177d09dd92174f9f52740bccb025\", \"price_changes\":[{\"asset_id\":\"61819828071723399190623735325323968706432622380635304641786792960078828866875\", \"price\":\"0.84\", \"size\":\"3220\", \"side\":\"BUY\", \"hash\":\"0e16964b2376183f0660316e4d8dee6248da6e91\", \"best_bid\":\"0.86\", \"best_ask\":\"0.87\"}, {\"asset_id\":\"114356653315647913247200886351065428002113119844334520181865067698979836634569\", \"price\":\"0.16\", \"size\":\"3220\", \"side\":\"SELL\", \"hash\":\"baabf435f6908e00e9887c475870079b9d79282e\", \"best_bid\":\"0.13\", \"best_ask\":\"0.14\"}], \"timestamp\":\"1789987927459\", \"event_type\":\"price_change\"}","raw_base64":null}
{"received_ms":1789987927491,"monotonic_ns":1019368321441800,"raw":"{\"market\":\"0x28a45972fccdaf0fba75dacc59725521035e177d09dd92174f9f52740bccb025\", \"price_changes\":[{\"asset_id\":\"61819828071723399190623735325323968706432622380635304641786792960078828866875\", \"price\":\"0.75\", \"size\":\"440\", \"side\":\"BUY\", \"hash\":\"eb8c9c41cc0406e64c58484e597b06813714aeb8\", \"best_bid\":\"0.86\", \"best_ask\":\"0.87\"}, {\"asset_id\":\"114356653315647913247200886351065428002113119844334520181865067698979836634569\", \"price\":\"0.25\", \"size\":\"440\", \"side\":\"SELL\", \"hash\":\"9be87e24582a530375e561f0b0411a923f4acdb4\", \"best_bid\":\"0.13\", \"best_ask\":\"0.14\"}], \"timestamp\":\"1789987927461\", \"event_type\":\"price_change\"}","raw_base64":null}
{"received_ms":1789987927491,"monotonic_ns":1019368321492800,"raw":"{\"market\":\"0x28a45972fccdaf0fba75dacc59725521035e177d09dd92174f9f52740bccb025\", \"price_changes\":[{\"asset_id\":\"61819828071723399190623735325323968706432622380635304641786792960078828866875\", \"price\":\"0.86\", \"size\":\"4772\", \"side\":\"BUY\", \"hash\":\"2fc537fa1bf49575970fc0fb9b86ad086f1fe495\", \"best_bid\":\"0.86\", \"best_ask\":\"0.87\"}, {\"asset_id\":\"114356653315647913247200886351065428002113119844334520181865067698979836634569\", \"price\":\"0.14\", \"size\":\"4772\", \"side\":\"SELL\", \"hash\":\"2477cce1130638ec5240aeb413c45c5d0549f8a7\", \"best_bid\":\"0.13\", \"best_ask\":\"0.14\"}], \"timestamp\":\"1789987927462\", \"event_type\":\"price_change\"}","raw_base64":null}
{"received_ms":1789987927491,"monotonic_ns":1019368321542000,"raw":"{\"market\":\"0x28a45972fccdaf0fba75dacc59725521035e177d09dd92174f9f52740bccb025\", \"price_changes\":[{\"asset_id\":\"61819828071723399190623735325323968706432622380635304641786792960078828866875\", \"price\":\"0.86\", \"size\":\"237\", \"side\":\"BUY\", \"hash\":\"aac25d908ab92d8d650c4e6f5e6381a3df9698f6\", \"best_bid\":\"0.86\", \"best_ask\":\"0.87\"}, {\"asset_id\":\"114356653315647913247200886351065428002113119844334520181865067698979836634569\", \"price\":\"0.14\", \"size\":\"237\", \"side\":\"SELL\", \"hash\":\"84750fd22d77890c582dd89b8ff0ab6ca141756b\", \"best_bid\":\"0.13\", \"best_ask\":\"0.14\"}], \"timestamp\":\"1789987927462\", \"event_type\":\"price_change\"}","raw_base64":null}
{"received_ms":1789987927491,"monotonic_ns":1019368322037300,"raw":"{\"market\":\"0x28a45972fccdaf0fba75dacc59725521035e177d09dd92174f9f52740bccb025\", \"price_changes\":[{\"asset_id\":\"61819828071723399190623735325323968706432622380635304641786792960078828866875\", \"price\":\"0.85\", \"size\":\"849.35\", \"side\":\"BUY\", \"hash\":\"37fb20f95201ab8e72c713dffa852ce6665b65e1\", \"best_bid\":\"0.86\", \"best_ask\":\"0.87\"}, {\"asset_id\":\"114356653315647913247200886351065428002113119844334520181865067698979836634569\", \"price\":\"0.15\", \"size\":\"849.35\", \"side\":\"SELL\", \"hash\":\"45c026867006815f4ba52822f48d72719c8fec49\", \"best_bid\":\"0.13\", \"best_ask\":\"0.14\"}], \"timestamp\":\"1789987927462\", \"event_type\":\"price_change\"}","raw_base64":null}
{"received_ms":1789987927491,"monotonic_ns":1019368322103600,"raw":"{\"market\":\"0x28a45972fccdaf0fba75dacc59725521035e177d09dd92174f9f52740bccb025\", \"price_changes\":[{\"asset_id\":\"61819828071723399190623735325323968706432622380635304641786792960078828866875\", \"price\":\"0.85\", \"size\":\"884.52\", \"side\":\"BUY\", \"hash\":\"6fcc377aa4e4ce3ce8d660ba86349a666e51b84c\", \"best_bid\":\"0.86\", \"best_ask\":\"0.87\"}, {\"asset_id\":\"114356653315647913247200886351065428002113119844334520181865067698979836634569\", \"price\":\"0.15\", \"size\":\"884.52\", \"side\":\"SELL\", \"hash\":\"bc9374a66a95a3b96811ac86c6ee1a33fa0a6bce\", \"best_bid\":\"0.13\", \"best_ask\":\"0.14\"}], \"timestamp\":\"1789987927462\", \"event_type\":\"price_change\"}","raw_base64":null}
{"received_ms":1789987927491,"monotonic_ns":1019368322147300,"raw":"{\"market\":\"0x28a45972fccdaf0fba75dacc59725521035e177d09dd92174f9f52740bccb025\", \"price_changes\":[{\"asset_id\":\"114356653315647913247200886351065428002113119844334520181865067698979836634569\", \"price\":\"0.06\", \"size\":\"5833.67\", \"side\":\"BUY\", \"hash\":\"59ca4523ccae900b45b56b057f172418c8f8222a\", \"best_bid\":\"0.13\", \"best_ask\":\"0.14\"}, {\"asset_id\":\"61819828071723399190623735325323968706432622380635304641786792960078828866875\", \"price\":\"0.94\", \"size\":\"5833.67\", \"side\":\"SELL\", \"hash\":\"1db42329033ba99d5683c7cc7734b0d1e4327825\", \"best_bid\":\"0.86\", \"best_ask\":\"0.87\"}], \"timestamp\":\"1789987927463\", \"event_type\":\"price_change\"}","raw_base64":null}
{"received_ms":1789987927491,"monotonic_ns":1019368322188600,"raw":"{\"market\":\"0x28a45972fccdaf0fba75dacc59725521035e177d09dd92174f9f52740bccb025\", \"price_changes\":[{\"asset_id\":\"61819828071723399190623735325323968706432622380635304641786792960078828866875\", \"price\":\"0.71\", \"size\":\"403\", \"side\":\"BUY\", \"hash\":\"a29ea79e4c48573bcd76e535a1b24b1997c3990a\", \"best_bid\":\"0.86\", \"best_ask\":\"0.87\"}, {\"asset_id\":\"114356653315647913247200886351065428002113119844334520181865067698979836634569\", \"price\":\"0.29\", \"size\":\"403\", \"side\":\"SELL\", \"hash\":\"54415504bdfaad125f4e7bab323a9ef2da97f77b\", \"best_bid\":\"0.13\", \"best_ask\":\"0.14\"}], \"timestamp\":\"1789987927465\", \"event_type\":\"price_change\"}","raw_base64":null}
{"received_ms":1789987927491,"monotonic_ns":1019368322230600,"raw":"{\"market\":\"0x28a45972fccdaf0fba75dacc59725521035e177d09dd92174f9f52740bccb025\", \"price_changes\":[{\"asset_id\":\"61819828071723399190623735325323968706432622380635304641786792960078828866875\", \"price\":\"0.92\", \"size\":\"684.5\", \"side\":\"SELL\", \"hash\":\"d2d8b4c7800b5e9fc1f05a7d695702c540a8f956\", \"best_bid\":\"0.86\", \"best_ask\":\"0.87\"}, {\"asset_id\":\"114356653315647913247200886351065428002113119844334520181865067698979836634569\", \"price\":\"0.08\", \"size\":\"684.5\", \"side\":\"BUY\", \"hash\":\"47c76495f09123a7f4213dee732ea6f74b70c0cd\", \"best_bid\":\"0.13\", \"best_ask\":\"0.14\"}], \"timestamp\":\"1789987927466\", \"event_type\":\"price_change\"}","raw_base64":null}
{"received_ms":1789987927492,"monotonic_ns":1019368323151300,"raw":"{\"market\":\"0x28a45972fccdaf0fba75dacc59725521035e177d09dd92174f9f52740bccb025\", \"price_changes\":[{\"asset_id\":\"114356653315647913247200886351065428002113119844334520181865067698979836634569\", \"price\":\"0.06\", \"size\":\"5340.67\", \"side\":\"BUY\", \"hash\":\"67e4fd04b21c11683a1e894963709027ca0cac81\", \"best_bid\":\"0.13\", \"best_ask\":\"0.14\"}, {\"asset_id\":\"61819828071723399190623735325323968706432622380635304641786792960078828866875\", \"price\":\"0.94\", \"size\":\"5340.67\", \"side\":\"SELL\", \"hash\":\"fd17405d4d4161cf8ecc4f4984a29ee8208d9446\", \"best_bid\":\"0.86\", \"best_ask\":\"0.87\"}], \"timestamp\":\"1789987927466\", \"event_type\":\"price_change\"}","raw_base64":null}
{"received_ms":1789987927492,"monotonic_ns":1019368323232600,"raw":"{\"market\":\"0x28a45972fccdaf0fba75dacc59725521035e177d09dd92174f9f52740bccb025\", \"price_changes\":[{\"asset_id\":\"114356653315647913247200886351065428002113119844334520181865067698979836634569\", \"price\":\"0.03\", \"size\":\"4057.57\", \"side\":\"BUY\", \"hash\":\"c09cb40b10a792371d94f468499d298e9650401d\", \"best_bid\":\"0.13\", \"best_ask\":\"0.14\"}, {\"asset_id\":\"61819828071723399190623735325323968706432622380635304641786792960078828866875\", \"price\":\"0.97\", \"size\":\"4057.57\", \"side\":\"SELL\", \"hash\":\"b413403ec53a36fd2659a9672545e18aa4ecd6df\", \"best_bid\":\"0.86\", \"best_ask\":\"0.87\"}], \"timestamp\":\"1789987927467\", \"event_type\":\"price_change\"}","raw_base64":null}
{"received_ms":1789987927493,"monotonic_ns":1019368323798300,"raw":"{\"market\":\"0x28a45972fccdaf0fba75dacc59725521035e177d09dd92174f9f52740bccb025\", \"price_changes\":[{\"asset_id\":\"114356653315647913247200886351065428002113119844334520181865067698979836634569\", \"price\":\"0.06\", \"size\":\"5360.67\", \"side\":\"BUY\", \"hash\":\"4e131919c441b284a22190fbaa4e0ab2da201bc5\", \"best_bid\":\"0.13\", \"best_ask\":\"0.14\"}, {\"asset_id\":\"61819828071723399190623735325323968706432622380635304641786792960078828866875\", \"price\":\"0.94\", \"size\":\"5360.67\", \"side\":\"SELL\", \"hash\":\"73b2ea5ed639eb88109a2387c4f736f8ae74f7ec\", \"best_bid\":\"0.86\", \"best_ask\":\"0.87\"}], \"timestamp\":\"1789987927468\", \"event_type\":\"price_change\"}","raw_base64":null}
{"received_ms":1789987927502,"monotonic_ns":1019368332753700,"raw":"{\"market\":\"0x28a45972fccdaf0fba75dacc59725521035e177d09dd92174f9f52740bccb025\", \"price_changes\":[{\"asset_id\":\"61819828071723399190623735325323968706432622380635304641786792960078828866875\", \"price\":\"0.91\", \"size\":\"620.12\", \"side\":\"SELL\", \"hash\":\"011f40821c39ba82546489201ec3c261e29a945d\", \"best_bid\":\"0.86\", \"best_ask\":\"0.87\"}, {\"asset_id\":\"114356653315647913247200886351065428002113119844334520181865067698979836634569\", \"price\":\"0.09\", \"size\":\"620.12\", \"side\":\"BUY\", \"hash\":\"27021adbd811ddd8037e1cbe1188667a0c1ec551\", \"best_bid\":\"0.13\", \"best_ask\":\"0.14\"}], \"timestamp\":\"1789987927476\", \"event_type\":\"price_change\"}","raw_base64":null}
{"received_ms":1789987927502,"monotonic_ns":1019368332815300,"raw":"{\"market\":\"0x28a45972fccdaf0fba75dacc59725521035e177d09dd92174f9f52740bccb025\", \"price_changes\":[{\"asset_id\":\"114356653315647913247200886351065428002113119844334520181865067698979836634569\", \"price\":\"0.13\", \"size\":\"270\", \"side\":\"BUY\", \"hash\":\"4e0510374f99be5602e74e7bbf0e2b6910139d28\", \"best_bid\":\"0.13\", \"best_ask\":\"0.14\"}, {\"asset_id\":\"61819828071723399190623735325323968706432622380635304641786792960078828866875\", \"price\":\"0.87\", \"size\":\"270\", \"side\":\"SELL\", \"hash\":\"471cef8fba087dbc488a17160c1b6057a14cc164\", \"best_bid\":\"0.86\", \"best_ask\":\"0.87\"}], \"timestamp\":\"1789987927477\", \"event_type\":\"price_change\"}","raw_base64":null}
{"received_ms":1789987927502,"monotonic_ns":1019368332860400,"raw":"{\"market\":\"0x28a45972fccdaf0fba75dacc59725521035e177d09dd92174f9f52740bccb025\", \"price_changes\":[{\"asset_id\":\"61819828071723399190623735325323968706432622380635304641786792960078828866875\", \"price\":\"0.84\", \"size\":\"3120\", \"side\":\"BUY\", \"hash\":\"442eab60d2135e277eb018229a0f7ad4126b1d5f\", \"best_bid\":\"0.86\", \"best_ask\":\"0.87\"}, {\"asset_id\":\"114356653315647913247200886351065428002113119844334520181865067698979836634569\", \"price\":\"0.16\", \"size\":\"3120\", \"side\":\"SELL\", \"hash\":\"d185a894fcdd846f24a8e51472690b43363c8205\", \"best_bid\":\"0.13\", \"best_ask\":\"0.14\"}], \"timestamp\":\"1789987927478\", \"event_type\":\"price_change\"}","raw_base64":null}
{"received_ms":1789987927504,"monotonic_ns":1019368335068000,"raw":"{\"market\":\"0x28a45972fccdaf0fba75dacc59725521035e177d09dd92174f9f52740bccb025\", \"price_changes\":[{\"asset_id\":\"61819828071723399190623735325323968706432622380635304641786792960078828866875\", \"price\":\"0.84\", \"size\":\"3220\", \"side\":\"BUY\", \"hash\":\"974388b70439fe9750f7defd68f1d374db4b7aca\", \"best_bid\":\"0.86\", \"best_ask\":\"0.87\"}, {\"asset_id\":\"114356653315647913247200886351065428002113119844334520181865067698979836634569\", \"price\":\"0.16\", \"size\":\"3220\", \"side\":\"SELL\", \"hash\":\"6a44d264efa6897a414970edd44b23f1683cb380\", \"best_bid\":\"0.13\", \"best_ask\":\"0.14\"}], \"timestamp\":\"1789987927480\", \"event_type\":\"price_change\"}","raw_base64":null}
{"received_ms":1789987927504,"monotonic_ns":1019368335145200,"raw":"{\"market\":\"0x28a45972fccdaf0fba75dacc59725521035e177d09dd92174f9f52740bccb025\", \"price_changes\":[{\"asset_id\":\"61819828071723399190623735325323968706432622380635304641786792960078828866875\", \"price\":\"0.86\", \"size\":\"137\", \"side\":\"BUY\", \"hash\":\"2c4c803fb3627842c094d2d08c4e5eaf9a69c29c\", \"best_bid\":\"0.86\", \"best_ask\":\"0.87\"}, {\"asset_id\":\"114356653315647913247200886351065428002113119844334520181865067698979836634569\", \"price\":\"0.14\", \"size\":\"137\", \"side\":\"SELL\", \"hash\":\"95a8be32100e8f5581fc18546d662b59569a3328\", \"best_bid\":\"0.13\", \"best_ask\":\"0.14\"}], \"timestamp\":\"1789987927481\", \"event_type\":\"price_change\"}","raw_base64":null}
{"received_ms":1789987927504,"monotonic_ns":1019368335196100,"raw":"{\"market\":\"0x28a45972fccdaf0fba75dacc59725521035e177d09dd92174f9f52740bccb025\", \"price_changes\":[{\"asset_id\":\"114356653315647913247200886351065428002113119844334520181865067698979836634569\", \"price\":\"0.13\", \"size\":\"280\", \"side\":\"BUY\", \"hash\":\"3e237eb849c2b1c55394badaaddac07b05e8d40a\", \"best_bid\":\"0.13\", \"best_ask\":\"0.14\"}, {\"asset_id\":\"61819828071723399190623735325323968706432622380635304641786792960078828866875\", \"price\":\"0.87\", \"size\":\"280\", \"side\":\"SELL\", \"hash\":\"cf5e647c8b04520ac828f7a1f2d347a57b28ad3c\", \"best_bid\":\"0.86\", \"best_ask\":\"0.87\"}], \"timestamp\":\"1789987927481\", \"event_type\":\"price_change\"}","raw_base64":null}
{"received_ms":1789987927510,"monotonic_ns":1019368340415900,"raw":"{\"market\":\"0x28a45972fccdaf0fba75dacc59725521035e177d09dd92174f9f52740bccb025\", \"price_changes\":[{\"asset_id\":\"61819828071723399190623735325323968706432622380635304641786792960078828866875\", \"price\":\"0.75\", \"size\":\"430\", \"side\":\"BUY\", \"hash\":\"fe24b946236d59c2835081fc1387a1301238318b\", \"best_bid\":\"0.86\", \"best_ask\":\"0.87\"}, {\"asset_id\":\"114356653315647913247200886351065428002113119844334520181865067698979836634569\", \"price\":\"0.25\", \"size\":\"430\", \"side\":\"SELL\", \"hash\":\"1cc36d9307553b0707636155c7745776f1ee9aad\", \"best_bid\":\"0.13\", \"best_ask\":\"0.14\"}], \"timestamp\":\"1789987927486\", \"event_type\":\"price_change\"}","raw_base64":null}
{"received_ms":1789987927510,"monotonic_ns":1019368340470400,"raw":"{\"market\":\"0x28a45972fccdaf0fba75dacc59725521035e177d09dd92174f9f52740bccb025\", \"price_changes\":[{\"asset_id\":\"114356653315647913247200886351065428002113119844334520181865067698979836634569\", \"price\":\"0.13\", \"size\":\"270\", \"side\":\"BUY\", \"hash\":\"0aba25bcfab7925539742cfc41e3e997773d83ce\", \"best_bid\":\"0.13\", \"best_ask\":\"0.14\"}, {\"asset_id\":\"61819828071723399190623735325323968706432622380635304641786792960078828866875\", \"price\":\"0.87\", \"size\":\"270\", \"side\":\"SELL\", \"hash\":\"6540137892475955f90e1106904a76af78125e4d\", \"best_bid\":\"0.86\", \"best_ask\":\"0.87\"}], \"timestamp\":\"1789987927487\", \"event_type\":\"price_change\"}","raw_base64":null}
{"received_ms":1789987927515,"monotonic_ns":1019368345857200,"raw":"{\"market\":\"0x28a45972fccdaf0fba75dacc59725521035e177d09dd92174f9f52740bccb025\", \"price_changes\":[{\"asset_id\":\"114356653315647913247200886351065428002113119844334520181865067698979836634569\", \"price\":\"0.07\", \"size\":\"601.71\", \"side\":\"BUY\", \"hash\":\"1d35153c12d6286ab128dcea3a59862577f2486d\", \"best_bid\":\"0.13\", \"best_ask\":\"0.14\"}, {\"asset_id\":\"61819828071723399190623735325323968706432622380635304641786792960078828866875\", \"price\":\"0.93\", \"size\":\"601.71\", \"side\":\"SELL\", \"hash\":\"5cbdcbd43b0c28c472a9c1f6d2c747afbfba4af0\", \"best_bid\":\"0.86\", \"best_ask\":\"0.87\"}], \"timestamp\":\"1789987927488\", \"event_type\":\"price_change\"}","raw_base64":null}
{"received_ms":1789987927515,"monotonic_ns":1019368345934900,"raw":"{\"market\":\"0x28a45972fccdaf0fba75dacc59725521035e177d09dd92174f9f52740bccb025\", \"price_changes\":[{\"asset_id\":\"61819828071723399190623735325323968706432622380635304641786792960078828866875\", \"price\":\"0.86\", \"size\":\"162\", \"side\":\"BUY\", \"hash\":\"7493c5e2db209380c37a307935648da71c2b427e\", \"best_bid\":\"0.86\", \"best_ask\":\"0.87\"}, {\"asset_id\":\"114356653315647913247200886351065428002113119844334520181865067698979836634569\", \"price\":\"0.14\", \"size\":\"162\", \"side\":\"SELL\", \"hash\":\"96ee9c7d9d03205dbba6e2bbe15dda92f3aa9110\", \"best_bid\":\"0.13\", \"best_ask\":\"0.14\"}], \"timestamp\":\"1789987927489\", \"event_type\":\"price_change\"}","raw_base64":null}
{"received_ms":1789987927515,"monotonic_ns":1019368345988200,"raw":"{\"market\":\"0x28a45972fccdaf0fba75dacc59725521035e177d09dd92174f9f52740bccb025\", \"price_changes\":[{\"asset_id\":\"114356653315647913247200886351065428002113119844334520181865067698979836634569\", \"price\":\"0.05\", \"size\":\"5608\", \"side\":\"BUY\", \"hash\":\"1aee87cd5564e7a038dddd95a3e9de10514764cc\", \"best_bid\":\"0.13\", \"best_ask\":\"0.14\"}, {\"asset_id\":\"61819828071723399190623735325323968706432622380635304641786792960078828866875\", \"price\":\"0.95\", \"size\":\"5608\", \"side\":\"SELL\", \"hash\":\"4a3443578fcebea37ef25f34dd733da28eec3c4a\", \"best_bid\":\"0.86\", \"best_ask\":\"0.87\"}], \"timestamp\":\"1789987927491\", \"event_type\":\"price_change\"}","raw_base64":null}
{"received_ms":1789987927515,"monotonic_ns":1019368346031600,"raw":"{\"market\":\"0x28a45972fccdaf0fba75dacc59725521035e177d09dd92174f9f52740bccb025\", \"price_changes\":[{\"asset_id\":\"61819828071723399190623735325323968706432622380635304641786792960078828866875\", \"price\":\"0.85\", \"size\":\"894.52\", \"side\":\"BUY\", \"hash\":\"e0551c5949391e6573ee0551240bac43821e5697\", \"best_bid\":\"0.86\", \"best_ask\":\"0.87\"}, {\"asset_id\":\"114356653315647913247200886351065428002113119844334520181865067698979836634569\", \"price\":\"0.15\", \"size\":\"894.52\", \"side\":\"SELL\", \"hash\":\"152c4f5005dc4d6cee6c5a1badaa8020a2c21cb6\", \"best_bid\":\"0.13\", \"best_ask\":\"0.14\"}], \"timestamp\":\"1789987927491\", \"event_type\":\"price_change\"}","raw_base64":null}
{"received_ms":1789987927515,"monotonic_ns":1019368346176500,"raw":"{\"market\":\"0x28a45972fccdaf0fba75dacc59725521035e177d09dd92174f9f52740bccb025\", \"price_changes\":[{\"asset_id\":\"114356653315647913247200886351065428002113119844334520181865067698979836634569\", \"price\":\"0.07\", \"size\":\"5432.71\", \"side\":\"BUY\", \"hash\":\"b28a9a881255aec24f5ed080bf040ec21211e5be\", \"best_bid\":\"0.13\", \"best_ask\":\"0.14\"}, {\"asset_id\":\"61819828071723399190623735325323968706432622380635304641786792960078828866875\", \"price\":\"0.93\", \"size\":\"5432.71\", \"side\":\"SELL\", \"hash\":\"cc9a6d125c56865f4052c431747ffaeba21719fd\", \"best_bid\":\"0.86\", \"best_ask\":\"0.87\"}], \"timestamp\":\"1789987927492\", \"event_type\":\"price_change\"}","raw_base64":null}
{"received_ms":1789987927515,"monotonic_ns":1019368346227800,"raw":"{\"market\":\"0x28a45972fccdaf0fba75dacc59725521035e177d09dd92174f9f52740bccb025\", \"price_changes\":[{\"asset_id\":\"114356653315647913247200886351065428002113119844334520181865067698979836634569\", \"price\":\"0.06\", \"size\":\"5436.67\", \"side\":\"BUY\", \"hash\":\"ff41114d302ba85ff8f3cc97267ea02518a668ea\", \"best_bid\":\"0.13\", \"best_ask\":\"0.14\"}, {\"asset_id\":\"61819828071723399190623735325323968706432622380635304641786792960078828866875\", \"price\":\"0.94\", \"size\":\"5436.67\", \"side\":\"SELL\", \"hash\":\"fafbea32dc86f674cb3a11eb9ca40d45aa106c3a\", \"best_bid\":\"0.86\", \"best_ask\":\"0.87\"}], \"timestamp\":\"1789987927493\", \"event_type\":\"price_change\"}","raw_base64":null}
{"received_ms":1789987927522,"monotonic_ns":1019368352647600,"raw":"{\"market\":\"0x28a45972fccdaf0fba75dacc59725521035e177d09dd92174f9f52740bccb025\", \"price_changes\":[{\"asset_id\":\"114356653315647913247200886351065428002113119844334520181865067698979836634569\", \"price\":\"0.12\", \"size\":\"496\", \"side\":\"BUY\", \"hash\":\"bb787fce8836ff653cad3c1bb5286b5aea96103a\", \"best_bid\":\"0.13\", \"best_ask\":\"0.14\"}, {\"asset_id\":\"61819828071723399190623735325323968706432622380635304641786792960078828866875\", \"price\":\"0.88\", \"size\":\"496\", \"side\":\"SELL\", \"hash\":\"b2f2d0cddf82c44d83dbc1a957579fbedd12eb74\", \"best_bid\":\"0.86\", \"best_ask\":\"0.87\"}], \"timestamp\":\"1789987927499\", \"event_type\":\"price_change\"}","raw_base64":null}
{"received_ms":1789987927530,"monotonic_ns":1019368360458000,"raw":"{\"market\":\"0x28a45972fccdaf0fba75dacc59725521035e177d09dd92174f9f52740bccb025\", \"price_changes\":[{\"asset_id\":\"61819828071723399190623735325323968706432622380635304641786792960078828866875\", \"price\":\"0.85\", \"size\":\"834.52\", \"side\":\"BUY\", \"hash\":\"8f42c57a96d8fa0a528c977f7f977cdfd485411c\", \"best_bid\":\"0.86\", \"best_ask\":\"0.87\"}, {\"asset_id\":\"114356653315647913247200886351065428002113119844334520181865067698979836634569\", \"price\":\"0.15\", \"size\":\"834.52\", \"side\":\"SELL\", \"hash\":\"10b7b2c9ebf2ca36bad7b846b3a74586a246d4f4\", \"best_bid\":\"0.13\", \"best_ask\":\"0.14\"}], \"timestamp\":\"1789987927509\", \"event_type\":\"price_change\"}","raw_base64":null}
{"received_ms":1789987927536,"monotonic_ns":1019368366583100,"raw":"{\"market\":\"0x28a45972fccdaf0fba75dacc59725521035e177d09dd92174f9f52740bccb025\", \"price_changes\":[{\"asset_id\":\"61819828071723399190623735325323968706432622380635304641786792960078828866875\", \"price\":\"0.84\", \"size\":\"2363\", \"side\":\"BUY\", \"hash\":\"7b436baa469cd9e76edf87a066d6a3789481d840\", \"best_bid\":\"0.86\", \"best_ask\":\"0.87\"}, {\"asset_id\":\"114356653315647913247200886351065428002113119844334520181865067698979836634569\", \"price\":\"0.16\", \"size\":\"2363\", \"side\":\"SELL\", \"hash\":\"1a969358a472f50a3a257ccfc993015f00b7ba2e\", \"best_bid\":\"0.13\", \"best_ask\":\"0.14\"}], \"timestamp\":\"1789987927515\", \"event_type\":\"price_change\"}","raw_base64":null}
{"received_ms":1789987927539,"monotonic_ns":1019368370115700,"raw":"{\"market\":\"0x28a45972fccdaf0fba75dacc59725521035e177d09dd92174f9f52740bccb025\", \"price_changes\":[{\"asset_id\":\"61819828071723399190623735325323968706432622380635304641786792960078828866875\", \"price\":\"0.79\", \"size\":\"467\", \"side\":\"BUY\", \"hash\":\"823b986807d362b0ead82bbf51ffcde024b50631\", \"best_bid\":\"0.86\", \"best_ask\":\"0.87\"}, {\"asset_id\":\"114356653315647913247200886351065428002113119844334520181865067698979836634569\", \"price\":\"0.21\", \"size\":\"467\", \"side\":\"SELL\", \"hash\":\"1cf2cc2ff5c304dce8b37f587dc709a4246c5f55\", \"best_bid\":\"0.13\", \"best_ask\":\"0.14\"}], \"timestamp\":\"1789987927519\", \"event_type\":\"price_change\"}","raw_base64":null}
{"received_ms":1789987927541,"monotonic_ns":1019368371343000,"raw":"{\"market\":\"0x28a45972fccdaf0fba75dacc59725521035e177d09dd92174f9f52740bccb025\", \"price_changes\":[{\"asset_id\":\"114356653315647913247200886351065428002113119844334520181865067698979836634569\", \"price\":\"0.13\", \"size\":\"280\", \"side\":\"BUY\", \"hash\":\"169a5f18bbe7e17ccfafff2ba9f536af03414130\", \"best_bid\":\"0.13\", \"best_ask\":\"0.14\"}, {\"asset_id\":\"61819828071723399190623735325323968706432622380635304641786792960078828866875\", \"price\":\"0.87\", \"size\":\"280\", \"side\":\"SELL\", \"hash\":\"b77b480ceaf01a1780c434ff7041705e4640b101\", \"best_bid\":\"0.86\", \"best_ask\":\"0.87\"}], \"timestamp\":\"1789987927520\", \"event_type\":\"price_change\"}","raw_base64":null}
{"received_ms":1789987927541,"monotonic_ns":1019368371399100,"raw":"{\"market\":\"0x28a45972fccdaf0fba75dacc59725521035e177d09dd92174f9f52740bccb025\", \"price_changes\":[{\"asset_id\":\"61819828071723399190623735325323968706432622380635304641786792960078828866875\", \"price\":\"0.83\", \"size\":\"434\", \"side\":\"BUY\", \"hash\":\"91c42bb5b77cd8e669ab8a0889401bb4b7cec0c3\", \"best_bid\":\"0.86\", \"best_ask\":\"0.87\"}, {\"asset_id\":\"114356653315647913247200886351065428002113119844334520181865067698979836634569\", \"price\":\"0.17\", \"size\":\"434\", \"side\":\"SELL\", \"hash\":\"4b4710e7680b58311eea481d255feea4c20af8a3\", \"best_bid\":\"0.13\", \"best_ask\":\"0.14\"}], \"timestamp\":\"1789987927521\", \"event_type\":\"price_change\"}","raw_base64":null}
{"received_ms":1789987927547,"monotonic_ns":1019368377991500,"raw":"{\"market\":\"0x28a45972fccdaf0fba75dacc59725521035e177d09dd92174f9f52740bccb025\", \"price_changes\":[{\"asset_id\":\"114356653315647913247200886351065428002113119844334520181865067698979836634569\", \"price\":\"0.05\", \"size\":\"773\", \"side\":\"BUY\", \"hash\":\"ca1cf3dd5b341b525d0c441c8343a7873499f89f\", \"best_bid\":\"0.13\", \"best_ask\":\"0.14\"}, {\"asset_id\":\"61819828071723399190623735325323968706432622380635304641786792960078828866875\", \"price\":\"0.95\", \"size\":\"773\", \"side\":\"SELL\", \"hash\":\"d81a803e7aea62b3c50e7045f915dcd9b42ff8c1\", \"best_bid\":\"0.86\", \"best_ask\":\"0.87\"}], \"timestamp\":\"1789987927525\", \"event_type\":\"price_change\"}","raw_base64":null}
{"received_ms":1789987927556,"monotonic_ns":1019368386308700,"raw":"{\"market\":\"0x28a45972fccdaf0fba75dacc59725521035e177d09dd92174f9f52740bccb025\", \"price_changes\":[{\"asset_id\":\"61819828071723399190623735325323968706432622380635304641786792960078828866875\", \"price\":\"0.85\", \"size\":\"839.52\", \"side\":\"BUY\", \"hash\":\"28f29d8a3f4c712fac497edee8c18ec88c54ae56\", \"best_bid\":\"0.86\", \"best_ask\":\"0.87\"}, {\"asset_id\":\"114356653315647913247200886351065428002113119844334520181865067698979836634569\", \"price\":\"0.15\", \"size\":\"839.52\", \"side\":\"SELL\", \"hash\":\"37ff5984a836552fbf83e363a3be59b0385e0313\", \"best_bid\":\"0.13\", \"best_ask\":\"0.14\"}], \"timestamp\":\"1789987927534\", \"event_type\":\"price_change\"}","raw_base64":null}
{"received_ms":1789987927570,"monotonic_ns":1019368400476900,"raw":"{\"market\":\"0x28a45972fccdaf0fba75dacc59725521035e177d09dd92174f9f52740bccb025\", \"price_changes\":[{\"asset_id\":\"61819828071723399190623735325323968706432622380635304641786792960078828866875\", \"price\":\"0.85\", \"size\":\"2546.52\", \"side\":\"BUY\", \"hash\":\"ba1bbb3299c8bcb67fde107eefd47a05c3a681ad\", \"best_bid\":\"0.86\", \"best_ask\":\"0.87\"}, {\"asset_id\":\"114356653315647913247200886351065428002113119844334520181865067698979836634569\", \"price\":\"0.15\", \"size\":\"2546.52\", \"side\":\"SELL\", \"hash\":\"33d9d2967a75b2b867ffcbbeed23cbe318b5790b\", \"best_bid\":\"0.13\", \"best_ask\":\"0.14\"}], \"timestamp\":\"1789987927549\", \"event_type\":\"price_change\"}","raw_base64":null}
{"received_ms":1789987927570,"monotonic_ns":1019368400683800,"raw":"{\"market\":\"0x28a45972fccdaf0fba75dacc59725521035e177d09dd92174f9f52740bccb025\", \"price_changes\":[{\"asset_id\":\"61819828071723399190623735325323968706432622380635304641786792960078828866875\", \"price\":\"0.84\", \"size\":\"2971\", \"side\":\"BUY\", \"hash\":\"8ea4d40e4793ba4834606a4d50ecba787e0e2839\", \"best_bid\":\"0.86\", \"best_ask\":\"0.87\"}, {\"asset_id\":\"114356653315647913247200886351065428002113119844334520181865067698979836634569\", \"price\":\"0.16\", \"size\":\"2971\", \"side\":\"SELL\", \"hash\":\"6a5db6d68f740e8719c55a968064d93e941259dd\", \"best_bid\":\"0.13\", \"best_ask\":\"0.14\"}], \"timestamp\":\"1789987927550\", \"event_type\":\"price_change\"}","raw_base64":null}
{"received_ms":1789987927571,"monotonic_ns":1019368402234400,"raw":"{\"market\":\"0x28a45972fccdaf0fba75dacc59725521035e177d09dd92174f9f52740bccb025\", \"price_changes\":[{\"asset_id\":\"61819828071723399190623735325323968706432622380635304641786792960078828866875\", \"price\":\"0.86\", \"size\":\"1754\", \"side\":\"BUY\", \"hash\":\"560e77f1ec340403cb3bdae3b6a430f01502d2c3\", \"best_bid\":\"0.86\", \"best_ask\":\"0.87\"}, {\"asset_id\":\"114356653315647913247200886351065428002113119844334520181865067698979836634569\", \"price\":\"0.14\", \"size\":\"1754\", \"side\":\"SELL\", \"hash\":\"6ad0e3ae8ff8471a0adfe1018db2ecca453d9b6d\", \"best_bid\":\"0.13\", \"best_ask\":\"0.14\"}], \"timestamp\":\"1789987927551\", \"event_type\":\"price_change\"}","raw_base64":null}
{"received_ms":1789987927580,"monotonic_ns":1019368411241700,"raw":"{\"market\":\"0x28a45972fccdaf0fba75dacc59725521035e177d09dd92174f9f52740bccb025\", \"price_changes\":[{\"asset_id\":\"61819828071723399190623735325323968706432622380635304641786792960078828866875\", \"price\":\"0.85\", \"size\":\"2536.52\", \"side\":\"BUY\", \"hash\":\"3492c232cf716210376410d5cc09f610c2c3847f\", \"best_bid\":\"0.86\", \"best_ask\":\"0.87\"}, {\"asset_id\":\"114356653315647913247200886351065428002113119844334520181865067698979836634569\", \"price\":\"0.15\", \"size\":\"2536.52\", \"side\":\"SELL\", \"hash\":\"c8f0ae0cf09cfa30cf9566c55a418f9b49aaa53d\", \"best_bid\":\"0.13\", \"best_ask\":\"0.14\"}], \"timestamp\":\"1789987927560\", \"event_type\":\"price_change\"}","raw_base64":null}
{"received_ms":1789987927584,"monotonic_ns":1019368415015300,"raw":"{\"market\":\"0x28a45972fccdaf0fba75dacc59725521035e177d09dd92174f9f52740bccb025\", \"price_changes\":[{\"asset_id\":\"114356653315647913247200886351065428002113119844334520181865067698979836634569\", \"price\":\"0.1\", \"size\":\"557\", \"side\":\"BUY\", \"hash\":\"c00644c4476078d32d8bc569375baf9ddcd6a540\", \"best_bid\":\"0.13\", \"best_ask\":\"0.14\"}, {\"asset_id\":\"61819828071723399190623735325323968706432622380635304641786792960078828866875\", \"price\":\"0.9\", \"size\":\"557\", \"side\":\"SELL\", \"hash\":\"91226b4d62aeeff4f1fafd7365ce73a6edf66c4c\", \"best_bid\":\"0.86\", \"best_ask\":\"0.87\"}], \"timestamp\":\"1789987927563\", \"event_type\":\"price_change\"}","raw_base64":null}
{"received_ms":1789987927588,"monotonic_ns":1019368418874700,"raw":"{\"market\":\"0x28a45972fccdaf0fba75dacc59725521035e177d09dd92174f9f52740bccb025\", \"price_changes\":[{\"asset_id\":\"61819828071723399190623735325323968706432622380635304641786792960078828866875\", \"price\":\"0.82\", \"size\":\"761\", \"side\":\"BUY\", \"hash\":\"22c6a708a9a1f9c7d001ba74c722268f0676b4ad\", \"best_bid\":\"0.86\", \"best_ask\":\"0.87\"}, {\"asset_id\":\"114356653315647913247200886351065428002113119844334520181865067698979836634569\", \"price\":\"0.18\", \"size\":\"761\", \"side\":\"SELL\", \"hash\":\"808244d3a064874dfbaee3d5ec5ee8ed3080a705\", \"best_bid\":\"0.13\", \"best_ask\":\"0.14\"}], \"timestamp\":\"1789987927566\", \"event_type\":\"price_change\"}","raw_base64":null}
{"received_ms":1789987927588,"monotonic_ns":1019368418953600,"raw":"{\"market\":\"0x28a45972fccdaf0fba75dacc59725521035e177d09dd92174f9f52740bccb025\", \"price_changes\":[{\"asset_id\":\"61819828071723399190623735325323968706432622380635304641786792960078828866875\", \"price\":\"0.84\", \"size\":\"2963\", \"side\":\"BUY\", \"hash\":\"aba0a74fab4dab932ef624565e30b240e0d9eeb9\", \"best_bid\":\"0.86\", \"best_ask\":\"0.87\"}, {\"asset_id\":\"114356653315647913247200886351065428002113119844334520181865067698979836634569\", \"price\":\"0.16\", \"size\":\"2963\", \"side\":\"SELL\", \"hash\":\"5a8013c2365549e02ab3f3fd62561cd50f51bf27\", \"best_bid\":\"0.13\", \"best_ask\":\"0.14\"}], \"timestamp\":\"1789987927567\", \"event_type\":\"price_change\"}","raw_base64":null}
{"received_ms":1789987927588,"monotonic_ns":1019368418991900,"raw":"{\"market\":\"0x28a45972fccdaf0fba75dacc59725521035e177d09dd92174f9f52740bccb025\", \"price_changes\":[{\"asset_id\":\"61819828071723399190623735325323968706432622380635304641786792960078828866875\", \"price\":\"0.86\", \"size\":\"1777\", \"side\":\"BUY\", \"hash\":\"237bd94e866a43ffb32a1f659b291996a3e9b651\", \"best_bid\":\"0.86\", \"best_ask\":\"0.87\"}, {\"asset_id\":\"114356653315647913247200886351065428002113119844334520181865067698979836634569\", \"price\":\"0.14\", \"size\":\"1777\", \"side\":\"SELL\", \"hash\":\"bb1dd90155c05a3314738016c6387c6c5b595820\", \"best_bid\":\"0.13\", \"best_ask\":\"0.14\"}], \"timestamp\":\"1789987927567\", \"event_type\":\"price_change\"}","raw_base64":null}
{"received_ms":1789987927592,"monotonic_ns":1019368423186000,"raw":"{\"market\":\"0x28a45972fccdaf0fba75dacc59725521035e177d09dd92174f9f52740bccb025\", \"price_changes\":[{\"asset_id\":\"61819828071723399190623735325323968706432622380635304641786792960078828866875\", \"price\":\"0.75\", \"size\":\"440\", \"side\":\"BUY\", \"hash\":\"7a284c9bafda49fa08fa4f6688940d6fb0e622b9\", \"best_bid\":\"0.86\", \"best_ask\":\"0.87\"}, {\"asset_id\":\"114356653315647913247200886351065428002113119844334520181865067698979836634569\", \"price\":\"0.25\", \"size\":\"440\", \"side\":\"SELL\", \"hash\":\"eff5d607b7b8c1ac6136d8b9aa16a8cf41dd5f61\", \"best_bid\":\"0.13\", \"best_ask\":\"0.14\"}], \"timestamp\":\"1789987927571\", \"event_type\":\"price_change\"}","raw_base64":null}
{"received_ms":1789987927596,"monotonic_ns":1019368426559100,"raw":"{\"market\":\"0x28a45972fccdaf0fba75dacc59725521035e177d09dd92174f9f52740bccb025\", \"price_changes\":[{\"asset_id\":\"61819828071723399190623735325323968706432622380635304641786792960078828866875\", \"price\":\"0.85\", \"size\":\"2596.52\", \"side\":\"BUY\", \"hash\":\"e602611f09267a78fc3a820fd5fb485b07948ff6\", \"best_bid\":\"0.86\", \"best_ask\":\"0.87\"}, {\"asset_id\":\"114356653315647913247200886351065428002113119844334520181865067698979836634569\", \"price\":\"0.15\", \"size\":\"2596.52\", \"side\":\"SELL\", \"hash\":\"d999df4c175ce322328b8b6808931c6db545927f\", \"best_bid\":\"0.13\", \"best_ask\":\"0.14\"}], \"timestamp\":\"1789987927575\", \"event_type\":\"price_change\"}","raw_base64":null}
{"received_ms":1789987927597,"monotonic_ns":1019368427868000,"raw":"{\"market\":\"0x28a45972fccdaf0fba75dacc59725521035e177d09dd92174f9f52740bccb025\", \"price_changes\":[{\"asset_id\":\"61819828071723399190623735325323968706432622380635304641786792960078828866875\", \"price\":\"0.84\", \"size\":\"2355\", \"side\":\"BUY\", \"hash\":\"2d6e428d10b9e22ab715bd27f0b2a7a15e133da4\", \"best_bid\":\"0.86\", \"best_ask\":\"0.87\"}, {\"asset_id\":\"114356653315647913247200886351065428002113119844334520181865067698979836634569\", \"price\":\"0.16\", \"size\":\"2355\", \"side\":\"SELL\", \"hash\":\"caf96b66e70cdb4844e0d6aa44c2ee8efe88021d\", \"best_bid\":\"0.13\", \"best_ask\":\"0.14\"}], \"timestamp\":\"1789987927576\", \"event_type\":\"price_change\"}","raw_base64":null}
{"received_ms":1789987927602,"monotonic_ns":1019368432653800,"raw":"{\"market\":\"0x28a45972fccdaf0fba75dacc59725521035e177d09dd92174f9f52740bccb025\", \"price_changes\":[{\"asset_id\":\"61819828071723399190623735325323968706432622380635304641786792960078828866875\", \"price\":\"0.77\", \"size\":\"487.49\", \"side\":\"BUY\", \"hash\":\"ec5593c4fa982ff70537eb67952c50ae60f6eaeb\", \"best_bid\":\"0.86\", \"best_ask\":\"0.87\"}, {\"asset_id\":\"114356653315647913247200886351065428002113119844334520181865067698979836634569\", \"price\":\"0.23\", \"size\":\"487.49\", \"side\":\"SELL\", \"hash\":\"cee8058a8f3788bf45dcc1ba2c30aeaac9c1615f\", \"best_bid\":\"0.13\", \"best_ask\":\"0.14\"}], \"timestamp\":\"1789987927581\", \"event_type\":\"price_change\"}","raw_base64":null}
{"received_ms":1789987927602,"monotonic_ns":1019368432697400,"raw":"{\"market\":\"0x28a45972fccdaf0fba75dacc59725521035e177d09dd92174f9f52740bccb025\", \"price_changes\":[{\"asset_id\":\"61819828071723399190623735325323968706432622380635304641786792960078828866875\", \"price\":\"0.79\", \"size\":\"427\", \"side\":\"BUY\", \"hash\":\"ec5593c4fa982ff70537eb67952c50ae60f6eaeb\", \"best_bid\":\"0.86\", \"best_ask\":\"0.87\"}, {\"asset_id\":\"114356653315647913247200886351065428002113119844334520181865067698979836634569\", \"price\":\"0.21\", \"size\":\"427\", \"side\":\"SELL\", \"hash\":\"cee8058a8f3788bf45dcc1ba2c30aeaac9c1615f\", \"best_bid\":\"0.13\", \"best_ask\":\"0.14\"}], \"timestamp\":\"1789987927581\", \"event_type\":\"price_change\"}","raw_base64":null}
{"received_ms":1789987927602,"monotonic_ns":1019368432731800,"raw":"{\"market\":\"0x28a45972fccdaf0fba75dacc59725521035e177d09dd92174f9f52740bccb025\", \"price_changes\":[{\"asset_id\":\"61819828071723399190623735325323968706432622380635304641786792960078828866875\", \"price\":\"0.84\", \"size\":\"2295\", \"side\":\"BUY\", \"hash\":\"ec5593c4fa982ff70537eb67952c50ae60f6eaeb\", \"best_bid\":\"0.86\", \"best_ask\":\"0.87\"}, {\"asset_id\":\"114356653315647913247200886351065428002113119844334520181865067698979836634569\", \"price\":\"0.16\", \"size\":\"2295\", \"side\":\"SELL\", \"hash\":\"cee8058a8f3788bf45dcc1ba2c30aeaac9c1615f\", \"best_bid\":\"0.13\", \"best_ask\":\"0.14\"}], \"timestamp\":\"1789987927581\", \"event_type\":\"price_change\"}","raw_base64":null}
{"received_ms":1789987927605,"monotonic_ns":1019368435515500,"raw":"{\"market\":\"0x28a45972fccdaf0fba75dacc59725521035e177d09dd92174f9f52740bccb025\", \"price_changes\":[{\"asset_id\":\"114356653315647913247200886351065428002113119844334520181865067698979836634569\", \"price\":\"0.05\", \"size\":\"5603\", \"side\":\"BUY\", \"hash\":\"a5826a0b23a172bf4c5f81ba397c1aead001dae1\", \"best_bid\":\"0.13\", \"best_ask\":\"0.14\"}, {\"asset_id\":\"61819828071723399190623735325323968706432622380635304641786792960078828866875\", \"price\":\"0.95\", \"size\":\"5603\", \"side\":\"SELL\", \"hash\":\"a0b8a6203aa63310bf60d6b889e0ec5ab91c4cc2\", \"best_bid\":\"0.86\", \"best_ask\":\"0.87\"}], \"timestamp\":\"1789987927583\", \"event_type\":\"price_change\"}","raw_base64":null}
{"received_ms":1789987927605,"monotonic_ns":1019368435558500,"raw":"{\"market\":\"0x28a45972fccdaf0fba75dacc59725521035e177d09dd92174f9f52740bccb025\", \"price_changes\":[{\"asset_id\":\"114356653315647913247200886351065428002113119844334520181865067698979836634569\", \"price\":\"0.06\", \"size\":\"6049.67\", \"side\":\"BUY\", \"hash\":\"e34b1880d7321620d00584ac156b97bce26ae406\", \"best_bid\":\"0.13\", \"best_ask\":\"0.14\"}, {\"asset_id\":\"61819828071723399190623735325323968706432622380635304641786792960078828866875\", \"price\":\"0.94\", \"size\":\"6049.67\", \"side\":\"SELL\", \"hash\":\"18429cc8f201c6fa4ff5349b0966fa0fbf2b7b0d\", \"best_bid\":\"0.86\", \"best_ask\":\"0.87\"}], \"timestamp\":\"1789987927584\", \"event_type\":\"price_change\"}","raw_base64":null}
{"received_ms":1789987927605,"monotonic_ns":1019368436027400,"raw":"{\"market\":\"0x28a45972fccdaf0fba75dacc59725521035e177d09dd92174f9f52740bccb025\", \"price_changes\":[{\"asset_id\":\"114356653315647913247200886351065428002113119844334520181865067698979836634569\", \"price\":\"0.07\", \"size\":\"6446.71\", \"side\":\"BUY\", \"hash\":\"0c1d9a76f04c6173e7d22562c6f9bb01c1dc3ecc\", \"best_bid\":\"0.13\", \"best_ask\":\"0.14\"}, {\"asset_id\":\"61819828071723399190623735325323968706432622380635304641786792960078828866875\", \"price\":\"0.93\", \"size\":\"6446.71\", \"side\":\"SELL\", \"hash\":\"62156bf4853f864712a2e3b253e59368bd10ac7d\", \"best_bid\":\"0.86\", \"best_ask\":\"0.87\"}], \"timestamp\":\"1789987927585\", \"event_type\":\"price_change\"}","raw_base64":null}
{"received_ms":1789987927612,"monotonic_ns":1019368442503000,"raw":"{\"market\":\"0x28a45972fccdaf0fba75dacc59725521035e177d09dd92174f9f52740bccb025\", \"price_changes\":[{\"asset_id\":\"61819828071723399190623735325323968706432622380635304641786792960078828866875\", \"price\":\"0.85\", \"size\":\"889.52\", \"side\":\"BUY\", \"hash\":\"4b2b39a2f600b8535469b789c9ff3d34d7ebd53e\", \"best_bid\":\"0.86\", \"best_ask\":\"0.87\"}, {\"asset_id\":\"114356653315647913247200886351065428002113119844334520181865067698979836634569\", \"price\":\"0.15\", \"size\":\"889.52\", \"side\":\"SELL\", \"hash\":\"dae7e0996456b3fd123466f820ec6a5aa0795744\", \"best_bid\":\"0.13\", \"best_ask\":\"0.14\"}], \"timestamp\":\"1789987927591\", \"event_type\":\"price_change\"}","raw_base64":null}
{"received_ms":1789987927622,"monotonic_ns":1019368452295100,"raw":"{\"market\":\"0x28a45972fccdaf0fba75dacc59725521035e177d09dd92174f9f52740bccb025\", \"price_changes\":[{\"asset_id\":\"61819828071723399190623735325323968706432622380635304641786792960078828866875\", \"price\":\"0.84\", \"size\":\"2303\", \"side\":\"BUY\", \"hash\":\"079f558fd4f302033e9859bb3a7c1cb794a59c71\", \"best_bid\":\"0.86\", \"best_ask\":\"0.87\"}, {\"asset_id\":\"114356653315647913247200886351065428002113119844334520181865067698979836634569\", \"price\":\"0.16\", \"size\":\"2303\", \"side\":\"SELL\", \"hash\":\"e42ff7bcaa6368ad276790534d0f209fd7dc2d5e\", \"best_bid\":\"0.13\", \"best_ask\":\"0.14\"}], \"timestamp\":\"1789987927600\", \"event_type\":\"price_change\"}","raw_base64":null}
{"received_ms":1789987927622,"monotonic_ns":1019368452340100,"raw":"{\"market\":\"0x28a45972fccdaf0fba75dacc59725521035e177d09dd92174f9f52740bccb025\", \"price_changes\":[{\"asset_id\":\"61819828071723399190623735325323968706432622380635304641786792960078828866875\", \"price\":\"0.82\", \"size\":\"753\", \"side\":\"BUY\", \"hash\":\"b621b0035f5b7734cc64e48199ccf880987caddf\", \"best_bid\":\"0.86\", \"best_ask\":\"0.87\"}, {\"asset_id\":\"114356653315647913247200886351065428002113119844334520181865067698979836634569\", \"price\":\"0.18\", \"size\":\"753\", \"side\":\"SELL\", \"hash\":\"dd17ecefcff73eb3547d6f8dbce15d67df2e2bfd\", \"best_bid\":\"0.13\", \"best_ask\":\"0.14\"}], \"timestamp\":\"1789987927601\", \"event_type\":\"price_change\"}","raw_base64":null}
{"received_ms":1789987927628,"monotonic_ns":1019368458435000,"raw":"{\"market\":\"0x28a45972fccdaf0fba75dacc59725521035e177d09dd92174f9f52740bccb025\", \"price_changes\":[{\"asset_id\":\"61819828071723399190623735325323968706432622380635304641786792960078828866875\", \"price\":\"0.83\", \"size\":\"494\", \"side\":\"BUY\", \"hash\":\"0dda8e10652c118f0a49e41d5fc811b9af06369f\", \"best_bid\":\"0.86\", \"best_ask\":\"0.87\"}, {\"asset_id\":\"114356653315647913247200886351065428002113119844334520181865067698979836634569\", \"price\":\"0.17\", \"size\":\"494\", \"side\":\"SELL\", \"hash\":\"8dbb1246f4c765351a53a44ff5e8fc0590068c53\", \"best_bid\":\"0.13\", \"best_ask\":\"0.14\"}], \"timestamp\":\"1789987927607\", \"event_type\":\"price_change\"}","raw_base64":null}
{"received_ms":1789987927629,"monotonic_ns":1019368460074900,"raw":"{\"market\":\"0x28a45972fccdaf0fba75dacc59725521035e177d09dd92174f9f52740bccb025\", \"price_changes\":[{\"asset_id\":\"114356653315647913247200886351065428002113119844334520181865067698979836634569\", \"price\":\"0.12\", \"size\":\"504.34\", \"side\":\"BUY\", \"hash\":\"b2c932cce3da188eaf6efbded5047e29cafe97b5\", \"best_bid\":\"0.13\", \"best_ask\":\"0.14\"}, {\"asset_id\":\"61819828071723399190623735325323968706432622380635304641786792960078828866875\", \"price\":\"0.88\", \"size\":\"504.34\", \"side\":\"SELL\", \"hash\":\"a548a504fcad5f71489bfe58809d88f06a3b9cfc\", \"best_bid\":\"0.86\", \"best_ask\":\"0.87\"}], \"timestamp\":\"1789987927609\", \"event_type\":\"price_change\"}","raw_base64":null}
{"received_ms":1789987927632,"monotonic_ns":1019368462632800,"raw":"{\"market\":\"0x28a45972fccdaf0fba75dacc59725521035e177d09dd92174f9f52740bccb025\", \"price_changes\":[{\"asset_id\":\"61819828071723399190623735325323968706432622380635304641786792960078828866875\", \"price\":\"0.73\", \"size\":\"509\", \"side\":\"BUY\", \"hash\":\"6b8c31c446194b823deb716074f1f5c03973cbb4\", \"best_bid\":\"0.86\", \"best_ask\":\"0.87\"}, {\"asset_id\":\"114356653315647913247200886351065428002113119844334520181865067698979836634569\", \"price\":\"0.27\", \"size\":\"509\", \"side\":\"SELL\", \"hash\":\"ea70a952be935bead14547637d198746d5624d59\", \"best_bid\":\"0.13\", \"best_ask\":\"0.14\"}], \"timestamp\":\"1789987927611\", \"event_type\":\"price_change\"}","raw_base64":null}
{"received_ms":1789987927633,"monotonic_ns":1019368463549000,"raw":"{\"market\":\"0x28a45972fccdaf0fba75dacc59725521035e177d09dd92174f9f52740bccb025\", \"price_changes\":[{\"asset_id\":\"61819828071723399190623735325323968706432622380635304641786792960078828866875\", \"price\":\"0.75\", \"size\":\"540\", \"side\":\"BUY\", \"hash\":\"f9e9d38e796fc372dff9c7919895a9100f69feab\", \"best_bid\":\"0.86\", \"best_ask\":\"0.87\"}, {\"asset_id\":\"114356653315647913247200886351065428002113119844334520181865067698979836634569\", \"price\":\"0.25\", \"size\":\"540\", \"side\":\"SELL\", \"hash\":\"aebeebc41c1a6403aeb2c83cba886db8bad75037\", \"best_bid\":\"0.13\", \"best_ask\":\"0.14\"}], \"timestamp\":\"1789987927613\", \"event_type\":\"price_change\"}","raw_base64":null}
{"received_ms":1789987927633,"monotonic_ns":1019368464150100,"raw":"{\"market\":\"0x28a45972fccdaf0fba75dacc59725521035e177d09dd92174f9f52740bccb025\", \"price_changes\":[{\"asset_id\":\"114356653315647913247200886351065428002113119844334520181865067698979836634569\", \"price\":\"0.06\", \"size\":\"5436.67\", \"side\":\"BUY\", \"hash\":\"a366e63adc9bec7fba917ea9f280c7711abdffdc\", \"best_bid\":\"0.13\", \"best_ask\":\"0.14\"}, {\"asset_id\":\"61819828071723399190623735325323968706432622380635304641786792960078828866875\", \"price\":\"0.94\", \"size\":\"5436.67\", \"side\":\"SELL\", \"hash\":\"36cce88d38f2e89145ab0edc51cf42d9c9598651\", \"best_bid\":\"0.86\", \"best_ask\":\"0.87\"}], \"timestamp\":\"1789987927613\", \"event_type\":\"price_change\"}","raw_base64":null}
{"received_ms":1789987927633,"monotonic_ns":1019368464194100,"raw":"{\"market\":\"0x28a45972fccdaf0fba75dacc59725521035e177d09dd92174f9f52740bccb025\", \"price_changes\":[{\"asset_id\":\"61819828071723399190623735325323968706432622380635304641786792960078828866875\", \"price\":\"0.77\", \"size\":\"547.49\", \"side\":\"BUY\", \"hash\":\"9dca88e964abc833c981bdaed4bdaed4d434acd6\", \"best_bid\":\"0.86\", \"best_ask\":\"0.87\"}, {\"asset_id\":\"114356653315647913247200886351065428002113119844334520181865067698979836634569\", \"price\":\"0.23\", \"size\":\"547.49\", \"side\":\"SELL\", \"hash\":\"f29ad604ff91310473103eb49940966fc73e87c3\", \"best_bid\":\"0.13\", \"best_ask\":\"0.14\"}], \"timestamp\":\"1789987927613\", \"event_type\":\"price_change\"}","raw_base64":null}
{"received_ms":1789987927634,"monotonic_ns":1019368464727000,"raw":"{\"market\":\"0x28a45972fccdaf0fba75dacc59725521035e177d09dd92174f9f52740bccb025\", \"price_changes\":[{\"asset_id\":\"61819828071723399190623735325323968706432622380635304641786792960078828866875\", \"price\":\"0.76\", \"size\":\"410\", \"side\":\"BUY\", \"hash\":\"029ec49828c1f687337465586ee3884ad10ae79c\", \"best_bid\":\"0.86\", \"best_ask\":\"0.87\"}, {\"asset_id\":\"114356653315647913247200886351065428002113119844334520181865067698979836634569\", \"price\":\"0.24\", \"size\":\"410\", \"side\":\"SELL\", \"hash\":\"1c21c00ddf3680e9bdd1f5ad246a4135b760abd3\", \"best_bid\":\"0.13\", \"best_ask\":\"0.14\"}], \"timestamp\":\"1789987927614\", \"event_type\":\"price_change\"}","raw_base64":null}
{"received_ms":1789987927636,"monotonic_ns":1019368467010500,"raw":"{\"market\":\"0x28a45972fccdaf0fba75dacc59725521035e177d09dd92174f9f52740bccb025\", \"price_changes\":[{\"asset_id\":\"61819828071723399190623735325323968706432622380635304641786792960078828866875\", \"price\":\"0.73\", \"size\":\"409\", \"side\":\"BUY\", \"hash\":\"883e6e6aa7d0e95f04d3afcacd32ae1920619eb1\", \"best_bid\":\"0.86\", \"best_ask\":\"0.87\"}, {\"asset_id\":\"114356653315647913247200886351065428002113119844334520181865067698979836634569\", \"price\":\"0.27\", \"size\":\"409\", \"side\":\"SELL\", \"hash\":\"914f3cc7d62821b2d65dc809ca71511008f8ac34\", \"best_bid\":\"0.13\", \"best_ask\":\"0.14\"}], \"timestamp\":\"1789987927616\", \"event_type\":\"price_change\"}","raw_base64":null}
{"received_ms":1789987927641,"monotonic_ns":1019368472143700,"raw":"{\"market\":\"0x28a45972fccdaf0fba75dacc59725521035e177d09dd92174f9f52740bccb025\", \"price_changes\":[{\"asset_id\":\"114356653315647913247200886351065428002113119844334520181865067698979836634569\", \"price\":\"0.05\", \"size\":\"5583\", \"side\":\"BUY\", \"hash\":\"b044c2683bced0bcc9965d7f22babb92e82f5659\", \"best_bid\":\"0.13\", \"best_ask\":\"0.14\"}, {\"asset_id\":\"61819828071723399190623735325323968706432622380635304641786792960078828866875\", \"price\":\"0.95\", \"size\":\"5583\", \"side\":\"SELL\", \"hash\":\"397da174e575721d13d4c7ccb70fa88b0f643df4\", \"best_bid\":\"0.86\", \"best_ask\":\"0.87\"}], \"timestamp\":\"1789987927621\", \"event_type\":\"price_change\"}","raw_base64":null}
{"received_ms":1789987927641,"monotonic_ns":1019368472190700,"raw":"{\"market\":\"0x28a45972fccdaf0fba75dacc59725521035e177d09dd92174f9f52740bccb025\", \"price_changes\":[{\"asset_id\":\"114356653315647913247200886351065428002113119844334520181865067698979836634569\", \"price\":\"0.1\", \"size\":\"497\", \"side\":\"BUY\", \"hash\":\"b044c2683bced0bcc9965d7f22babb92e82f5659\", \"best_bid\":\"0.13\", \"best_ask\":\"0.14\"}, {\"asset_id\":\"61819828071723399190623735325323968706432622380635304641786792960078828866875\", \"price\":\"0.9\", \"size\":\"497\", \"side\":\"SELL\", \"hash\":\"397da174e575721d13d4c7ccb70fa88b0f643df4\", \"best_bid\":\"0.86\", \"best_ask\":\"0.87\"}], \"timestamp\":\"1789987927621\", \"event_type\":\"price_change\"}","raw_base64":null}
{"received_ms":1789987927645,"monotonic_ns":1019368475494800,"raw":"{\"market\":\"0x28a45972fccdaf0fba75dacc59725521035e177d09dd92174f9f52740bccb025\", \"price_changes\":[{\"asset_id\":\"61819828071723399190623735325323968706432622380635304641786792960078828866875\", \"price\":\"0.83\", \"size\":\"499\", \"side\":\"BUY\", \"hash\":\"6dea0ac0a9c2d9af6664979548093ee50ab1ae7d\", \"best_bid\":\"0.86\", \"best_ask\":\"0.87\"}, {\"asset_id\":\"114356653315647913247200886351065428002113119844334520181865067698979836634569\", \"price\":\"0.17\", \"size\":\"499\", \"side\":\"SELL\", \"hash\":\"d1f637b2f6f2f3bd6ffd5962bf3c9ff043a5f8e8\", \"best_bid\":\"0.13\", \"best_ask\":\"0.14\"}], \"timestamp\":\"1789987927625\", \"event_type\":\"price_change\"}","raw_base64":null}
{"received_ms":1789987927649,"monotonic_ns":1019368479846900,"raw":"{\"market\":\"0x28a45972fccdaf0fba75dacc59725521035e177d09dd92174f9f52740bccb025\", \"price_changes\":[{\"asset_id\":\"61819828071723399190623735325323968706432622380635304641786792960078828866875\", \"price\":\"0.86\", \"size\":\"1909\", \"side\":\"BUY\", \"hash\":\"f89ec8b4b99f2bf26f043041b96cdeeb11babbc8\", \"best_bid\":\"0.86\", \"best_ask\":\"0.87\"}, {\"asset_id\":\"114356653315647913247200886351065428002113119844334520181865067698979836634569\", \"price\":\"0.14\", \"size\":\"1909\", \"side\":\"SELL\", \"hash\":\"9b42f3486b6ef3161d23211990cd39203ae05176\", \"best_bid\":\"0.13\", \"best_ask\":\"0.14\"}], \"timestamp\":\"1789987927628\", \"event_type\":\"price_change\"}","raw_base64":null}
{"received_ms":1789987927651,"monotonic_ns":1019368482092000,"raw":"{\"market\":\"0x28a45972fccdaf0fba75dacc59725521035e177d09dd92174f9f52740bccb025\", \"price_changes\":[{\"asset_id\":\"61819828071723399190623735325323968706432622380635304641786792960078828866875\", \"price\":\"0.85\", \"size\":\"2516.52\", \"side\":\"BUY\", \"hash\":\"68f38dbc23dfb183a242ed4c1920010bc0d7d618\", \"best_bid\":\"0.86\", \"best_ask\":\"0.87\"}, {\"asset_id\":\"114356653315647913247200886351065428002113119844334520181865067698979836634569\", \"price\":\"0.15\", \"size\":\"2516.52\", \"side\":\"SELL\", \"hash\":\"455ce777557dbda880ed799c4a0587ecc8a79140\", \"best_bid\":\"0.13\", \"best_ask\":\"0.14\"}], \"timestamp\":\"1789987927631\", \"event_type\":\"price_change\"}","raw_base64":null}
{"received_ms":1789987927653,"monotonic_ns":1019368483956400,"raw":"{\"market\":\"0x28a45972fccdaf0fba75dacc59725521035e177d09dd92174f9f52740bccb025\", \"price_changes\":[{\"asset_id\":\"61819828071723399190623735325323968706432622380635304641786792960078828866875\", \"price\":\"0.84\", \"size\":\"2863\", \"side\":\"BUY\", \"hash\":\"07e53d96a5d0c4f474671d69a1e63afecc19bceb\", \"best_bid\":\"0.86\", \"best_ask\":\"0.87\"}, {\"asset_id\":\"114356653315647913247200886351065428002113119844334520181865067698979836634569\", \"price\":\"0.16\", \"size\":\"2863\", \"side\":\"SELL\", \"hash\":\"0c4d5a9d39fedb4df0a70a1f787a85d91d4b4749\", \"best_bid\":\"0.13\", \"best_ask\":\"0.14\"}], \"timestamp\":\"1789987927633\", \"event_type\":\"price_change\"}","raw_base64":null}
{"received_ms":1789987927654,"monotonic_ns":1019368484769600,"raw":"{\"market\":\"0x28a45972fccdaf0fba75dacc59725521035e177d09dd92174f9f52740bccb025\", \"price_changes\":[{\"asset_id\":\"61819828071723399190623735325323968706432622380635304641786792960078828866875\", \"price\":\"0.73\", \"size\":\"404\", \"side\":\"BUY\", \"hash\":\"881416aacbf0da6d345b0324de75c56a4b4c316e\", \"best_bid\":\"0.86\", \"best_ask\":\"0.87\"}, {\"asset_id\":\"114356653315647913247200886351065428002113119844334520181865067698979836634569\", \"price\":\"0.27\", \"size\":\"404\", \"side\":\"SELL\", \"hash\":\"4f1aa2ec4975ae4396ad2059bd4b1d370b13a117\", \"best_bid\":\"0.13\", \"best_ask\":\"0.14\"}], \"timestamp\":\"1789987927634\", \"event_type\":\"price_change\"}","raw_base64":null}
{"received_ms":1789987927657,"monotonic_ns":1019368487348600,"raw":"{\"market\":\"0x28a45972fccdaf0fba75dacc59725521035e177d09dd92174f9f52740bccb025\", \"price_changes\":[{\"asset_id\":\"114356653315647913247200886351065428002113119844334520181865067698979836634569\", \"price\":\"0.07\", \"size\":\"6426.71\", \"side\":\"BUY\", \"hash\":\"d004bd0c79acfdca4d0e64061cbc81ffb03b3500\", \"best_bid\":\"0.13\", \"best_ask\":\"0.14\"}, {\"asset_id\":\"61819828071723399190623735325323968706432622380635304641786792960078828866875\", \"price\":\"0.93\", \"size\":\"6426.71\", \"side\":\"SELL\", \"hash\":\"d0d94d48d6684b809db5079806971494c7cef484\", \"best_bid\":\"0.86\", \"best_ask\":\"0.87\"}], \"timestamp\":\"1789987927637\", \"event_type\":\"price_change\"}","raw_base64":null}
{"received_ms":1789987927666,"monotonic_ns":1019368496604100,"raw":"{\"market\":\"0x28a45972fccdaf0fba75dacc59725521035e177d09dd92174f9f52740bccb025\", \"price_changes\":[{\"asset_id\":\"61819828071723399190623735325323968706432622380635304641786792960078828866875\", \"price\":\"0.86\", \"size\":\"1809\", \"side\":\"BUY\", \"hash\":\"f90c7905aab07140bc78f1c24f7a40404b2318bf\", \"best_bid\":\"0.86\", \"best_ask\":\"0.87\"}, {\"asset_id\":\"114356653315647913247200886351065428002113119844334520181865067698979836634569\", \"price\":\"0.14\", \"size\":\"1809\", \"side\":\"SELL\", \"hash\":\"50397587004830bb0d8c9e9fe8cd64c1ac5784b9\", \"best_bid\":\"0.13\", \"best_ask\":\"0.14\"}], \"timestamp\":\"1789987927645\", \"event_type\":\"price_change\"}","raw_base64":null}
{"received_ms":1789987927668,"monotonic_ns":1019368498543400,"raw":"{\"market\":\"0x28a45972fccdaf0fba75dacc59725521035e177d09dd92174f9f52740bccb025\", \"price_changes\":[{\"asset_id\":\"61819828071723399190623735325323968706432622380635304641786792960078828866875\", \"price\":\"0.01\", \"size\":\"1496.91\", \"side\":\"BUY\", \"hash\":\"19bf884248f676e92a2d2e8f9bd2359b01ffeae3\", \"best_bid\":\"0.86\", \"best_ask\":\"0.87\"}, {\"asset_id\":\"114356653315647913247200886351065428002113119844334520181865067698979836634569\", \"price\":\"0.99\", \"size\":\"1496.91\", \"side\":\"SELL\", \"hash\":\"79e8a13d80768f4d5cab18080c9e59cfb297b89a\", \"best_bid\":\"0.13\", \"best_ask\":\"0.14\"}], \"timestamp\":\"1789987927648\", \"event_type\":\"price_change\"}","raw_base64":null}
{"received_ms":1789987927670,"monotonic_ns":1019368500900000,"raw":"{\"market\":\"0x28a45972fccdaf0fba75dacc59725521035e177d09dd92174f9f52740bccb025\", \"price_changes\":[{\"asset_id\":\"61819828071723399190623735325323968706432622380635304641786792960078828866875\", \"price\":\"0.84\", \"size\":\"2963\", \"side\":\"BUY\", \"hash\":\"e2b3aa7be9d3f77ae00afa85f89611356ed46ee3\", \"best_bid\":\"0.86\", \"best_ask\":\"0.87\"}, {\"asset_id\":\"114356653315647913247200886351065428002113119844334520181865067698979836634569\", \"price\":\"0.16\", \"size\":\"2963\", \"side\":\"SELL\", \"hash\":\"c7713e5b42b1dbdb168bbc02dbcefd4becbe4ce2\", \"best_bid\":\"0.13\", \"best_ask\":\"0.14\"}], \"timestamp\":\"1789987927650\", \"event_type\":\"price_change\"}","raw_base64":null}
{"received_ms":1789987927676,"monotonic_ns":1019368506489200,"raw":"{\"market\":\"0x28a45972fccdaf0fba75dacc59725521035e177d09dd92174f9f52740bccb025\", \"price_changes\":[{\"asset_id\":\"114356653315647913247200886351065428002113119844334520181865067698979836634569\", \"price\":\"0.11\", \"size\":\"336.1\", \"side\":\"BUY\", \"hash\":\"b9c733c2ef1efbde13bb40d1ad132532ea7a5c71\", \"best_bid\":\"0.13\", \"best_ask\":\"0.14\"}, {\"asset_id\":\"61819828071723399190623735325323968706432622380635304641786792960078828866875\", \"price\":\"0.89\", \"size\":\"336.1\", \"side\":\"SELL\", \"hash\":\"f87f9f41abc68495eb9b13d8b4f2fd367f89246c\", \"best_bid\":\"0.86\", \"best_ask\":\"0.87\"}], \"timestamp\":\"1789987927656\", \"event_type\":\"price_change\"}","raw_base64":null}
{"received_ms":1789987927684,"monotonic_ns":1019368514423300,"raw":"{\"market\":\"0x28a45972fccdaf0fba75dacc59725521035e177d09dd92174f9f52740bccb025\", \"price_changes\":[{\"asset_id\":\"61819828071723399190623735325323968706432622380635304641786792960078828866875\", \"price\":\"0.77\", \"size\":\"487.49\", \"side\":\"BUY\", \"hash\":\"efb4cabfcdf8b758112e6f2723659ff421361166\", \"best_bid\":\"0.86\", \"best_ask\":\"0.87\"}, {\"asset_id\":\"114356653315647913247200886351065428002113119844334520181865067698979836634569\", \"price\":\"0.23\", \"size\":\"487.49\", \"side\":\"SELL\", \"hash\":\"1dca375bdbcd9878ab274e9926d87b257de44ec1\", \"best_bid\":\"0.13\", \"best_ask\":\"0.14\"}], \"timestamp\":\"1789987927663\", \"event_type\":\"price_change\"}","raw_base64":null}
{"received_ms":1789987927684,"monotonic_ns":1019368514628800,"raw":"{\"market\":\"0x28a45972fccdaf0fba75dacc59725521035e177d09dd92174f9f52740bccb025\", \"price_changes\":[{\"asset_id\":\"61819828071723399190623735325323968706432622380635304641786792960078828866875\", \"price\":\"0.84\", \"size\":\"2403\", \"side\":\"BUY\", \"hash\":\"0458e7310bb39b182baf44ec4ab7ff0dc422cd3f\", \"best_bid\":\"0.86\", \"best_ask\":\"0.87\"}, {\"asset_id\":\"114356653315647913247200886351065428002113119844334520181865067698979836634569\", \"price\":\"0.16\", \"size\":\"2403\", \"side\":\"SELL\", \"hash\":\"e5e44a2a5c6b0344e16075b9717b375a9253438a\", \"best_bid\":\"0.13\", \"best_ask\":\"0.14\"}], \"timestamp\":\"1789987927664\", \"event_type\":\"price_change\"}","raw_base64":null}
{"received_ms":1789987927685,"monotonic_ns":1019368516145600,"raw":"{\"market\":\"0x28a45972fccdaf0fba75dacc59725521035e177d09dd92174f9f52740bccb025\", \"price_changes\":[{\"asset_id\":\"114356653315647913247200886351065428002113119844334520181865067698979836634569\", \"price\":\"0.07\", \"size\":\"6484.71\", \"side\":\"BUY\", \"hash\":\"40c55d3ff99645653151da097e920a0810036779\", \"best_bid\":\"0.13\", \"best_ask\":\"0.14\"}, {\"asset_id\":\"61819828071723399190623735325323968706432622380635304641786792960078828866875\", \"price\":\"0.93\", \"size\":\"6484.71\", \"side\":\"SELL\", \"hash\":\"20d187c02463d75a64785da9bab2fd36efd72470\", \"best_bid\":\"0.86\", \"best_ask\":\"0.87\"}], \"timestamp\":\"1789987927665\", \"event_type\":\"price_change\"}","raw_base64":null}
{"received_ms":1789987927687,"monotonic_ns":1019368517364200,"raw":"{\"market\":\"0x28a45972fccdaf0fba75dacc59725521035e177d09dd92174f9f52740bccb025\", \"price_changes\":[{\"asset_id\":\"114356653315647913247200886351065428002113119844334520181865067698979836634569\", \"price\":\"0.06\", \"size\":\"5949.67\", \"side\":\"BUY\", \"hash\":\"5a5c29a9b0e9eeaa91ba7f96d081514335e767f2\", \"best_bid\":\"0.13\", \"best_ask\":\"0.14\"}, {\"asset_id\":\"61819828071723399190623735325323968706432622380635304641786792960078828866875\", \"price\":\"0.94\", \"size\":\"5949.67\", \"side\":\"SELL\", \"hash\":\"06c6b05ffb8b6786a97891e1781e368b0142c364\", \"best_bid\":\"0.86\", \"best_ask\":\"0.87\"}], \"timestamp\":\"1789987927666\", \"event_type\":\"price_change\"}","raw_base64":null}
{"received_ms":1789987927693,"monotonic_ns":1019368524216100,"raw":"{\"market\":\"0x28a45972fccdaf0fba75dacc59725521035e177d09dd92174f9f52740bccb025\", \"price_changes\":[{\"asset_id\":\"114356653315647913247200886351065428002113119844334520181865067698979836634569\", \"price\":\"0.11\", \"size\":\"356.1\", \"side\":\"BUY\", \"hash\":\"f09cd74844ea833acb741c70feb16f4d28c340bf\", \"best_bid\":\"0.13\", \"best_ask\":\"0.14\"}, {\"asset_id\":\"61819828071723399190623735325323968706432622380635304641786792960078828866875\", \"price\":\"0.89\", \"size\":\"356.1\", \"side\":\"SELL\", \"hash\":\"ae0cdb5d2080b00afe5c18b174399b977e0bb25c\", \"best_bid\":\"0.86\", \"best_ask\":\"0.87\"}], \"timestamp\":\"1789987927674\", \"event_type\":\"price_change\"}","raw_base64":null}
{"received_ms":1789987927702,"monotonic_ns":1019368533208900,"raw":"{\"market\":\"0x28a45972fccdaf0fba75dacc59725521035e177d09dd92174f9f52740bccb025\", \"price_changes\":[{\"asset_id\":\"61819828071723399190623735325323968706432622380635304641786792960078828866875\", \"price\":\"0.85\", \"size\":\"889.52\", \"side\":\"BUY\", \"hash\":\"bf2a92bfa5d1106057ae9c072a95d94de4b071fc\", \"best_bid\":\"0.86\", \"best_ask\":\"0.87\"}, {\"asset_id\":\"114356653315647913247200886351065428002113119844334520181865067698979836634569\", \"price\":\"0.15\", \"size\":\"889.52\", \"side\":\"SELL\", \"hash\":\"7d6bfc2dff4d8d201f524cf11beeb39dde058e27\", \"best_bid\":\"0.13\", \"best_ask\":\"0.14\"}], \"timestamp\":\"1789987927681\", \"event_type\":\"price_change\"}","raw_base64":null}
{"received_ms":1789987927703,"monotonic_ns":1019368533315100,"raw":"{\"market\":\"0x28a45972fccdaf0fba75dacc59725521035e177d09dd92174f9f52740bccb025\", \"price_changes\":[{\"asset_id\":\"114356653315647913247200886351065428002113119844334520181865067698979836634569\", \"price\":\"0.05\", \"size\":\"5603\", \"side\":\"BUY\", \"hash\":\"4cd1bbaede7beefcd3c1d747801bbf6301b27812\", \"best_bid\":\"0.13\", \"best_ask\":\"0.14\"}, {\"asset_id\":\"61819828071723399190623735325323968706432622380635304641786792960078828866875\", \"price\":\"0.95\", \"size\":\"5603\", \"side\":\"SELL\", \"hash\":\"7d18212eb87aa17a5858556f42c4f3d203724e91\", \"best_bid\":\"0.86\", \"best_ask\":\"0.87\"}], \"timestamp\":\"1789987927681\", \"event_type\":\"price_change\"}","raw_base64":null}
{"received_ms":1789987927706,"monotonic_ns":1019368536313300,"raw":"{\"market\":\"0x28a45972fccdaf0fba75dacc59725521035e177d09dd92174f9f52740bccb025\", \"price_changes\":[{\"asset_id\":\"61819828071723399190623735325323968706432622380635304641786792960078828866875\", \"price\":\"0.82\", \"size\":\"761\", \"side\":\"BUY\", \"hash\":\"b94da47a6d9960aa88a7c8fb0febcc253bab4826\", \"best_bid\":\"0.86\", \"best_ask\":\"0.87\"}, {\"asset_id\":\"114356653315647913247200886351065428002113119844334520181865067698979836634569\", \"price\":\"0.18\", \"size\":\"761\", \"side\":\"SELL\", \"hash\":\"363425212d1bfc6e331ad62a50b7948996890d00\", \"best_bid\":\"0.13\", \"best_ask\":\"0.14\"}], \"timestamp\":\"1789987927684\", \"event_type\":\"price_change\"}","raw_base64":null}
{"received_ms":1789987927706,"monotonic_ns":1019368536368400,"raw":"{\"market\":\"0x28a45972fccdaf0fba75dacc59725521035e177d09dd92174f9f52740bccb025\", \"price_changes\":[{\"asset_id\":\"61819828071723399190623735325323968706432622380635304641786792960078828866875\", \"price\":\"0.84\", \"size\":\"2395\", \"side\":\"BUY\", \"hash\":\"d7abe0320eb30ad87b99a43144519e472a0a8ce3\", \"best_bid\":\"0.86\", \"best_ask\":\"0.87\"}, {\"asset_id\":\"114356653315647913247200886351065428002113119844334520181865067698979836634569\", \"price\":\"0.16\", \"size\":\"2395\", \"side\":\"SELL\", \"hash\":\"7deb667973dc927baeb07a86f5def0a8758fc83c\", \"best_bid\":\"0.13\", \"best_ask\":\"0.14\"}], \"timestamp\":\"1789987927685\", \"event_type\":\"price_change\"}","raw_base64":null}
{"received_ms":1789987927710,"monotonic_ns":1019368540412900,"raw":"{\"market\":\"0x28a45972fccdaf0fba75dacc59725521035e177d09dd92174f9f52740bccb025\", \"price_changes\":[{\"asset_id\":\"61819828071723399190623735325323968706432622380635304641786792960078828866875\", \"price\":\"0.77\", \"size\":\"527.49\", \"side\":\"BUY\", \"hash\":\"bb2c0b7c1a5de198a3e63d4745bee0f60de62ef2\", \"best_bid\":\"0.86\", \"best_ask\":\"0.87\"}, {\"asset_id\":\"114356653315647913247200886351065428002113119844334520181865067698979836634569\", \"price\":\"0.23\", \"size\":\"527.49\", \"side\":\"SELL\", \"hash\":\"160551e3b514760b9f202602379f51484ea4eb82\", \"best_bid\":\"0.13\", \"best_ask\":\"0.14\"}], \"timestamp\":\"1789987927689\", \"event_type\":\"price_change\"}","raw_base64":null}
{"received_ms":1789987927710,"monotonic_ns":1019368540481300,"raw":"{\"market\":\"0x28a45972fccdaf0fba75dacc59725521035e177d09dd92174f9f52740bccb025\", \"price_changes\":[{\"asset_id\":\"61819828071723399190623735325323968706432622380635304641786792960078828866875\", \"price\":\"0.79\", \"size\":\"467\", \"side\":\"BUY\", \"hash\":\"25007c9fa8dea80fca581de71dd148cff36e4004\", \"best_bid\":\"0.86\", \"best_ask\":\"0.87\"}, {\"asset_id\":\"114356653315647913247200886351065428002113119844334520181865067698979836634569\", \"price\":\"0.21\", \"size\":\"467\", \"side\":\"SELL\", \"hash\":\"b8c861c10298ea5214e31c51d2ba802ec8dfdf5a\", \"best_bid\":\"0.13\", \"best_ask\":\"0.14\"}], \"timestamp\":\"1789987927690\", \"event_type\":\"price_change\"}","raw_base64":null}
{"received_ms":1789987927711,"monotonic_ns":1019368541292100,"raw":"{\"market\":\"0x28a45972fccdaf0fba75dacc59725521035e177d09dd92174f9f52740bccb025\", \"price_changes\":[{\"asset_id\":\"61819828071723399190623735325323968706432622380635304641786792960078828866875\", \"price\":\"0.77\", \"size\":\"487.49\", \"side\":\"BUY\", \"hash\":\"d7e824f7456c806da959e8caac032af4c9889553\", \"best_bid\":\"0.86\", \"best_ask\":\"0.87\"}, {\"asset_id\":\"114356653315647913247200886351065428002113119844334520181865067698979836634569\", \"price\":\"0.23\", \"size\":\"487.49\", \"side\":\"SELL\", \"hash\":\"c6d986585b3c9cadaf4cbf2ebc31476142d49737\", \"best_bid\":\"0.13\", \"best_ask\":\"0.14\"}], \"timestamp\":\"1789987927691\", \"event_type\":\"price_change\"}","raw_base64":null}
{"received_ms":1789987927711,"monotonic_ns":1019368541344900,"raw":"{\"market\":\"0x28a45972fccdaf0fba75dacc59725521035e177d09dd92174f9f52740bccb025\", \"price_changes\":[{\"asset_id\":\"61819828071723399190623735325323968706432622380635304641786792960078828866875\", \"price\":\"0.79\", \"size\":\"427\", \"side\":\"BUY\", \"hash\":\"d7e824f7456c806da959e8caac032af4c9889553\", \"best_bid\":\"0.86\", \"best_ask\":\"0.87\"}, {\"asset_id\":\"114356653315647913247200886351065428002113119844334520181865067698979836634569\", \"price\":\"0.21\", \"size\":\"427\", \"side\":\"SELL\", \"hash\":\"c6d986585b3c9cadaf4cbf2ebc31476142d49737\", \"best_bid\":\"0.13\", \"best_ask\":\"0.14\"}], \"timestamp\":\"1789987927691\", \"event_type\":\"price_change\"}","raw_base64":null}
{"received_ms":1789987927714,"monotonic_ns":1019368544759000,"raw":"{\"market\":\"0x28a45972fccdaf0fba75dacc59725521035e177d09dd92174f9f52740bccb025\", \"price_changes\":[{\"asset_id\":\"114356653315647913247200886351065428002113119844334520181865067698979836634569\", \"price\":\"0.11\", \"size\":\"336.1\", \"side\":\"BUY\", \"hash\":\"b4812a37f4340d8485cc66e4733f574ca2732689\", \"best_bid\":\"0.13\", \"best_ask\":\"0.14\"}, {\"asset_id\":\"61819828071723399190623735325323968706432622380635304641786792960078828866875\", \"price\":\"0.89\", \"size\":\"336.1\", \"side\":\"SELL\", \"hash\":\"b211eb7615381365bf0738893d8df06e70b6ced4\", \"best_bid\":\"0.86\", \"best_ask\":\"0.87\"}], \"timestamp\":\"1789987927694\", \"event_type\":\"price_change\"}","raw_base64":null}
{"received_ms":1789987927718,"monotonic_ns":1019368549229200,"raw":"{\"market\":\"0x28a45972fccdaf0fba75dacc59725521035e177d09dd92174f9f52740bccb025\", \"price_changes\":[{\"asset_id\":\"61819828071723399190623735325323968706432622380635304641786792960078828866875\", \"price\":\"0.01\", \"size\":\"1491.91\", \"side\":\"BUY\", \"hash\":\"050533d5a3d7357b98f7843d631f32d823d2f736\", \"best_bid\":\"0.86\", \"best_ask\":\"0.87\"}, {\"asset_id\":\"114356653315647913247200886351065428002113119844334520181865067698979836634569\", \"price\":\"0.99\", \"size\":\"1491.91\", \"side\":\"SELL\", \"hash\":\"b66e5068352a140e2c8b548346e1348993c859ef\", \"best_bid\":\"0.13\", \"best_ask\":\"0.14\"}], \"timestamp\":\"1789987927698\", \"event_type\":\"price_change\"}","raw_base64":null}
{"received_ms":1789987927721,"monotonic_ns":1019368552067500,"raw":"{\"market\":\"0x28a45972fccdaf0fba75dacc59725521035e177d09dd92174f9f52740bccb025\", \"price_changes\":[{\"asset_id\":\"61819828071723399190623735325323968706432622380635304641786792960078828866875\", \"price\":\"0.86\", \"size\":\"1677\", \"side\":\"BUY\", \"hash\":\"de2f49351e4791a4239a25ea238ea141a59af077\", \"best_bid\":\"0.86\", \"best_ask\":\"0.87\"}, {\"asset_id\":\"114356653315647913247200886351065428002113119844334520181865067698979836634569\", \"price\":\"0.14\", \"size\":\"1677\", \"side\":\"SELL\", \"hash\":\"9ccfcdfdea012e72808e3b103f9db57f7ffa371e\", \"best_bid\":\"0.13\", \"best_ask\":\"0.14\"}], \"timestamp\":\"1789987927701\", \"event_type\":\"price_change\"}","raw_base64":null}
{"received_ms":1789987927726,"monotonic_ns":1019368556816900,"raw":"{\"market\":\"0x28a45972fccdaf0fba75dacc59725521035e177d09dd92174f9f52740bccb025\", \"price_changes\":[{\"asset_id\":\"61819828071723399190623735325323968706432622380635304641786792960078828866875\", \"price\":\"0.84\", \"size\":\"2215\", \"side\":\"BUY\", \"hash\":\"c8bf981204977a096bdcbe4554be54147bb67e20\", \"best_bid\":\"0.86\", \"best_ask\":\"0.87\"}, {\"asset_id\":\"114356653315647913247200886351065428002113119844334520181865067698979836634569\", \"price\":\"0.16\", \"size\":\"2215\", \"side\":\"SELL\", \"hash\":\"e145493abf3cd26037792cb5386c6411109eb507\", \"best_bid\":\"0.13\", \"best_ask\":\"0.14\"}], \"timestamp\":\"1789987927705\", \"event_type\":\"price_change\"}","raw_base64":null}
{"received_ms":1789987927727,"monotonic_ns":1019368557886900,"raw":"{\"market\":\"0x28a45972fccdaf0fba75dacc59725521035e177d09dd92174f9f52740bccb025\", \"price_changes\":[{\"asset_id\":\"61819828071723399190623735325323968706432622380635304641786792960078828866875\", \"price\":\"0.86\", \"size\":\"1654\", \"side\":\"BUY\", \"hash\":\"a13ea5e36d423ff68d560f9445a13503d8127e8d\", \"best_bid\":\"0.86\", \"best_ask\":\"0.87\"}, {\"asset_id\":\"114356653315647913247200886351065428002113119844334520181865067698979836634569\", \"price\":\"0.14\", \"size\":\"1654\", \"side\":\"SELL\", \"hash\":\"2c5883c39cd9968a9178672ba04af8a58f45d08f\", \"best_bid\":\"0.13\", \"best_ask\":\"0.14\"}], \"timestamp\":\"1789987927706\", \"event_type\":\"price_change\"}","raw_base64":null}
{"received_ms":1789987927729,"monotonic_ns":1019368560008100,"raw":"{\"market\":\"0x28a45972fccdaf0fba75dacc59725521035e177d09dd92174f9f52740bccb025\", \"price_changes\":[{\"asset_id\":\"61819828071723399190623735325323968706432622380635304641786792960078828866875\", \"price\":\"0.85\", \"size\":\"866.52\", \"side\":\"BUY\", \"hash\":\"40fecdf59d436610fbfcba5387e5e5be49713088\", \"best_bid\":\"0.86\", \"best_ask\":\"0.87\"}, {\"asset_id\":\"114356653315647913247200886351065428002113119844334520181865067698979836634569\", \"price\":\"0.15\", \"size\":\"866.52\", \"side\":\"SELL\", \"hash\":\"ff3a392aa216be27392a697f4fcfacbd0bfa464b\", \"best_bid\":\"0.13\", \"best_ask\":\"0.14\"}], \"timestamp\":\"1789987927708\", \"event_type\":\"price_change\"}","raw_base64":null}
{"received_ms":1789987927734,"monotonic_ns":1019368565196600,"raw":"{\"market\":\"0x28a45972fccdaf0fba75dacc59725521035e177d09dd92174f9f52740bccb025\", \"price_changes\":[{\"asset_id\":\"114356653315647913247200886351065428002113119844334520181865067698979836634569\", \"price\":\"0.1\", \"size\":\"520\", \"side\":\"BUY\", \"hash\":\"05197646328864c3bd3602a0928473acd3e26ba3\", \"best_bid\":\"0.13\", \"best_ask\":\"0.14\"}, {\"asset_id\":\"61819828071723399190623735325323968706432622380635304641786792960078828866875\", \"price\":\"0.9\", \"size\":\"520\", \"side\":\"SELL\", \"hash\":\"7f89e308a13256e299d5bc14ba084d0fc3679377\", \"best_bid\":\"0.86\", \"best_ask\":\"0.87\"}], \"timestamp\":\"1789987927714\", \"event_type\":\"price_change\"}","raw_base64":null}
{"received_ms":1789987927735,"monotonic_ns":1019368565860400,"raw":"{\"market\":\"0x28a45972fccdaf0fba75dacc59725521035e177d09dd92174f9f52740bccb025\", \"price_changes\":[{\"asset_id\":\"114356653315647913247200886351065428002113119844334520181865067698979836634569\", \"price\":\"0.07\", \"size\":\"6426.71\", \"side\":\"BUY\", \"hash\":\"3dd74317604172d73015bf8c86a13e60d5c6003c\", \"best_bid\":\"0.13\", \"best_ask\":\"0.14\"}, {\"asset_id\":\"61819828071723399190623735325323968706432622380635304641786792960078828866875\", \"price\":\"0.93\", \"size\":\"6426.71\", \"side\":\"SELL\", \"hash\":\"4392e239f03baaef9ecc271b4abc6e31d2f8be0c\", \"best_bid\":\"0.86\", \"best_ask\":\"0.87\"}], \"timestamp\":\"1789987927714\", \"event_type\":\"price_change\"}","raw_base64":null}
{"received_ms":1789987927735,"monotonic_ns":1019368565937700,"raw":"{\"market\":\"0x28a45972fccdaf0fba75dacc59725521035e177d09dd92174f9f52740bccb025\", \"price_changes\":[{\"asset_id\":\"61819828071723399190623735325323968706432622380635304641786792960078828866875\", \"price\":\"0.86\", \"size\":\"62\", \"side\":\"BUY\", \"hash\":\"783aac1c871528cbc48016c6a4d21ac1c3db6c55\", \"best_bid\":\"0.86\", \"best_ask\":\"0.87\"}, {\"asset_id\":\"114356653315647913247200886351065428002113119844334520181865067698979836634569\", \"price\":\"0.14\", \"size\":\"62\", \"side\":\"SELL\", \"hash\":\"a5974cf4ce051834c6315bb1fb0bc2e20887179b\", \"best_bid\":\"0.13\", \"best_ask\":\"0.14\"}], \"timestamp\":\"1789987927715\", \"event_type\":\"price_change\"}","raw_base64":null}
{"received_ms":1789987927736,"monotonic_ns":1019368566414900,"raw":"{\"market\":\"0x28a45972fccdaf0fba75dacc59725521035e177d09dd92174f9f52740bccb025\", \"price_changes\":[{\"asset_id\":\"61819828071723399190623735325323968706432622380635304641786792960078828866875\", \"price\":\"0.84\", \"size\":\"2223\", \"side\":\"BUY\", \"hash\":\"756be9a3cd8e1ab9720f5f9949bc539567c5f4ad\", \"best_bid\":\"0.86\", \"best_ask\":\"0.87\"}, {\"asset_id\":\"114356653315647913247200886351065428002113119844334520181865067698979836634569\", \"price\":\"0.16\", \"size\":\"2223\", \"side\":\"SELL\", \"hash\":\"29961bf47791f4646cc786cc143996f344fea74c\", \"best_bid\":\"0.13\", \"best_ask\":\"0.14\"}], \"timestamp\":\"1789987927716\", \"event_type\":\"price_change\"}","raw_base64":null}
{"received_ms":1789987927737,"monotonic_ns":1019368567854200,"raw":"{\"market\":\"0x28a45972fccdaf0fba75dacc59725521035e177d09dd92174f9f52740bccb025\", \"price_changes\":[{\"asset_id\":\"61819828071723399190623735325323968706432622380635304641786792960078828866875\", \"price\":\"0.82\", \"size\":\"753\", \"side\":\"BUY\", \"hash\":\"346185ee80d011b823b84d1f6fbe4828aa28bc0c\", \"best_bid\":\"0.86\", \"best_ask\":\"0.87\"}, {\"asset_id\":\"114356653315647913247200886351065428002113119844334520181865067698979836634569\", \"price\":\"0.18\", \"size\":\"753\", \"side\":\"SELL\", \"hash\":\"1bfedb4067f7d4e429c2b3dcb645dec5b3f0c556\", \"best_bid\":\"0.13\", \"best_ask\":\"0.14\"}], \"timestamp\":\"1789987927717\", \"event_type\":\"price_change\"}","raw_base64":null}
{"received_ms":1789987927738,"monotonic_ns":1019368569131000,"raw":"{\"market\":\"0x28a45972fccdaf0fba75dacc59725521035e177d09dd92174f9f52740bccb025\", \"price_changes\":[{\"asset_id\":\"61819828071723399190623735325323968706432622380635304641786792960078828866875\", \"price\":\"0.85\", \"size\":\"876.52\", \"side\":\"BUY\", \"hash\":\"ff747640fbdd60b1bff7181f898bf64a31cf283d\", \"best_bid\":\"0.86\", \"best_ask\":\"0.87\"}, {\"asset_id\":\"114356653315647913247200886351065428002113119844334520181865067698979836634569\", \"price\":\"0.15\", \"size\":\"876.52\", \"side\":\"SELL\", \"hash\":\"1d97ba75a12c932590de2b715ebdbc30a28be9e9\", \"best_bid\":\"0.13\", \"best_ask\":\"0.14\"}], \"timestamp\":\"1789987927717\", \"event_type\":\"price_change\"}","raw_base64":null}
{"received_ms":1789987927748,"monotonic_ns":1019368579254000,"raw":"{\"market\":\"0x28a45972fccdaf0fba75dacc59725521035e177d09dd92174f9f52740bccb025\", \"price_changes\":[{\"asset_id\":\"114356653315647913247200886351065428002113119844334520181865067698979836634569\", \"price\":\"0.12\", \"size\":\"684.34\", \"side\":\"BUY\", \"hash\":\"95c3ac8b606c996af16b913d17c08ea786af2d79\", \"best_bid\":\"0.13\", \"best_ask\":\"0.14\"}, {\"asset_id\":\"61819828071723399190623735325323968706432622380635304641786792960078828866875\", \"price\":\"0.88\", \"size\":\"684.34\", \"side\":\"SELL\", \"hash\":\"4fe3bc208f78336185944bb0d74fdd327f68de1a\", \"best_bid\":\"0.86\", \"best_ask\":\"0.87\"}], \"timestamp\":\"1789987927718\", \"event_type\":\"price_change\"}","raw_base64":null}
{"received_ms":1789987927749,"monotonic_ns":1019368579316200,"raw":"{\"market\":\"0x28a45972fccdaf0fba75dacc59725521035e177d09dd92174f9f52740bccb025\", \"price_changes\":[{\"asset_id\":\"114356653315647913247200886351065428002113119844334520181865067698979836634569\", \"price\":\"0.05\", \"size\":\"5583\", \"side\":\"BUY\", \"hash\":\"8df0a3d93b0c601422d1c5ac3829b406e296d056\", \"best_bid\":\"0.13\", \"best_ask\":\"0.14\"}, {\"asset_id\":\"61819828071723399190623735325323968706432622380635304641786792960078828866875\", \"price\":\"0.95\", \"size\":\"5583\", \"side\":\"SELL\", \"hash\":\"0ae959d397235890ee4fb23d23c89b795176bdd2\", \"best_bid\":\"0.86\", \"best_ask\":\"0.87\"}], \"timestamp\":\"1789987927719\", \"event_type\":\"price_change\"}","raw_base64":null}
{"received_ms":1789987927749,"monotonic_ns":1019368579366800,"raw":"{\"market\":\"0x28a45972fccdaf0fba75dacc59725521035e177d09dd92174f9f52740bccb025\", \"price_changes\":[{\"asset_id\":\"114356653315647913247200886351065428002113119844334520181865067698979836634569\", \"price\":\"0.13\", \"size\":\"270\", \"side\":\"BUY\", \"hash\":\"45365224636426e05df4c6a7dfd26f2b8f4980a5\", \"best_bid\":\"0.13\", \"best_ask\":\"0.14\"}, {\"asset_id\":\"61819828071723399190623735325323968706432622380635304641786792960078828866875\", \"price\":\"0.87\", \"size\":\"270\", \"side\":\"SELL\", \"hash\":\"883e3ac5158324d97f4a74fa202a27a72f3afa11\", \"best_bid\":\"0.86\", \"best_ask\":\"0.87\"}], \"timestamp\":\"1789987927721\", \"event_type\":\"price_change\"}","raw_base64":null}
{"received_ms":1789987927767,"monotonic_ns":1019368597829200,"raw":"{\"market\":\"0x28a45972fccdaf0fba75dacc59725521035e177d09dd92174f9f52740bccb025\", \"price_changes\":[{\"asset_id\":\"61819828071723399190623735325323968706432622380635304641786792960078828866875\", \"price\":\"0.83\", \"size\":\"494\", \"side\":\"BUY\", \"hash\":\"ea99cefadc5bc03b2e81e601e3ca58dbc0412dc3\", \"best_bid\":\"0.86\", \"best_ask\":\"0.87\"}, {\"asset_id\":\"114356653315647913247200886351065428002113119844334520181865067698979836634569\", \"price\":\"0.17\", \"size\":\"494\", \"side\":\"SELL\", \"hash\":\"c4251b1afe9875ef689b8c1915a1fe03ba8c0c85\", \"best_bid\":\"0.13\", \"best_ask\":\"0.14\"}], \"timestamp\":\"1789987927721\", \"event_type\":\"price_change\"}","raw_base64":null}
{"received_ms":1789987927767,"monotonic_ns":1019368597904700,"raw":"{\"market\":\"0x28a45972fccdaf0fba75dacc59725521035e177d09dd92174f9f52740bccb025\", \"price_changes\":[{\"asset_id\":\"61819828071723399190623735325323968706432622380635304641786792960078828866875\", \"price\":\"0.76\", \"size\":\"400\", \"side\":\"BUY\", \"hash\":\"2aa8fc906bb1e4113032858c595b699aa6b9ea52\", \"best_bid\":\"0.86\", \"best_ask\":\"0.87\"}, {\"asset_id\":\"114356653315647913247200886351065428002113119844334520181865067698979836634569\", \"price\":\"0.24\", \"size\":\"400\", \"side\":\"SELL\", \"hash\":\"932b421a727d34e1ea7ac03de3936d48c9e4e1ce\", \"best_bid\":\"0.13\", \"best_ask\":\"0.14\"}], \"timestamp\":\"1789987927723\", \"event_type\":\"price_change\"}","raw_base64":null}
{"received_ms":1789987927767,"monotonic_ns":1019368597951200,"raw":"{\"market\":\"0x28a45972fccdaf0fba75dacc59725521035e177d09dd92174f9f52740bccb025\", \"price_changes\":[{\"asset_id\":\"61819828071723399190623735325323968706432622380635304641786792960078828866875\", \"price\":\"0.85\", \"size\":\"861.52\", \"side\":\"BUY\", \"hash\":\"f6b6d651c85ae2de8c89d4b63af5d1adaa0ac267\", \"best_bid\":\"0.86\", \"best_ask\":\"0.87\"}, {\"asset_id\":\"114356653315647913247200886351065428002113119844334520181865067698979836634569\", \"price\":\"0.15\", \"size\":\"861.52\", \"side\":\"SELL\", \"hash\":\"a6a7b40d298fee2ff26f455723c8862b235f6fba\", \"best_bid\":\"0.13\", \"best_ask\":\"0.14\"}], \"timestamp\":\"1789987927725\", \"event_type\":\"price_change\"}","raw_base64":null}
{"received_ms":1789987927767,"monotonic_ns":1019368597995200,"raw":"{\"market\":\"0x28a45972fccdaf0fba75dacc59725521035e177d09dd92174f9f52740bccb025\", \"price_changes\":[{\"asset_id\":\"61819828071723399190623735325323968706432622380635304641786792960078828866875\", \"price\":\"0.75\", \"size\":\"530\", \"side\":\"BUY\", \"hash\":\"84fdbc46c3d6010069e912e3c02dde0407bba6e6\", \"best_bid\":\"0.86\", \"best_ask\":\"0.87\"}, {\"asset_id\":\"114356653315647913247200886351065428002113119844334520181865067698979836634569\", \"price\":\"0.25\", \"size\":\"530\", \"side\":\"SELL\", \"hash\":\"8a4668eaa1902bf616ab90278428a1e0bece5963\", \"best_bid\":\"0.13\", \"best_ask\":\"0.14\"}], \"timestamp\":\"1789987927726\", \"event_type\":\"price_change\"}","raw_base64":null}
{"received_ms":1789987927767,"monotonic_ns":1019368598038300,"raw":"{\"market\":\"0x28a45972fccdaf0fba75dacc59725521035e177d09dd92174f9f52740bccb025\", \"price_changes\":[{\"asset_id\":\"61819828071723399190623735325323968706432622380635304641786792960078828866875\", \"price\":\"0.86\", \"size\":\"298\", \"side\":\"BUY\", \"hash\":\"72cda6d440f63f487333045c642f9455c165ec46\", \"best_bid\":\"0.86\", \"best_ask\":\"0.87\"}, {\"asset_id\":\"114356653315647913247200886351065428002113119844334520181865067698979836634569\", \"price\":\"0.14\", \"size\":\"298\", \"side\":\"SELL\", \"hash\":\"8740f336f2afb1956cf0a207738904f7d23e2292\", \"best_bid\":\"0.13\", \"best_ask\":\"0.14\"}], \"timestamp\":\"1789987927727\", \"event_type\":\"price_change\"}","raw_base64":null}
{"received_ms":1789987927767,"monotonic_ns":1019368598080600,"raw":"{\"market\":\"0x28a45972fccdaf0fba75dacc59725521035e177d09dd92174f9f52740bccb025\", \"price_changes\":[{\"asset_id\":\"61819828071723399190623735325323968706432622380635304641786792960078828866875\", \"price\":\"0.85\", \"size\":\"801.52\", \"side\":\"BUY\", \"hash\":\"3a1f08987ac92ee1aca154f8fde1428986368bed\", \"best_bid\":\"0.86\", \"best_ask\":\"0.87\"}, {\"asset_id\":\"114356653315647913247200886351065428002113119844334520181865067698979836634569\", \"price\":\"0.15\", \"size\":\"801.52\", \"side\":\"SELL\", \"hash\":\"7d5ae3cf0d943b246ad8330eb4ae75fb42875080\", \"best_bid\":\"0.13\", \"best_ask\":\"0.14\"}], \"timestamp\":\"1789987927733\", \"event_type\":\"price_change\"}","raw_base64":null}
{"received_ms":1789987927767,"monotonic_ns":1019368598137700,"raw":"{\"market\":\"0x28a45972fccdaf0fba75dacc59725521035e177d09dd92174f9f52740bccb025\", \"price_changes\":[{\"asset_id\":\"61819828071723399190623735325323968706432622380635304641786792960078828866875\", \"price\":\"0.77\", \"size\":\"527.49\", \"side\":\"BUY\", \"hash\":\"66762d93c9ea9b939625b925f870e50828214a05\", \"best_bid\":\"0.86\", \"best_ask\":\"0.87\"}, {\"asset_id\":\"114356653315647913247200886351065428002113119844334520181865067698979836634569\", \"price\":\"0.23\", \"size\":\"527.49\", \"side\":\"SELL\", \"hash\":\"eb402c6fb1f868fcc037dc942d4fc87c22d76437\", \"best_bid\":\"0.13\", \"best_ask\":\"0.14\"}], \"timestamp\":\"1789987927735\", \"event_type\":\"price_change\"}","raw_base64":null}
{"received_ms":1789987927767,"monotonic_ns":1019368598180000,"raw":"{\"market\":\"0x28a45972fccdaf0fba75dacc59725521035e177d09dd92174f9f52740bccb025\", \"price_changes\":[{\"asset_id\":\"114356653315647913247200886351065428002113119844334520181865067698979836634569\", \"price\":\"0.06\", \"size\":\"4766.67\", \"side\":\"BUY\", \"hash\":\"1422818d3bb6e61c77817dbac1c381c2baa54fb5\", \"best_bid\":\"0.13\", \"best_ask\":\"0.14\"}, {\"asset_id\":\"61819828071723399190623735325323968706432622380635304641786792960078828866875\", \"price\":\"0.94\", \"size\":\"4766.67\", \"side\":\"SELL\", \"hash\":\"fee2b37e07bde6e0f3ee6e837ee8e8ec329c558c\", \"best_bid\":\"0.86\", \"best_ask\":\"0.87\"}], \"timestamp\":\"1789987927737\", \"event_type\":\"price_change\"}","raw_base64":null}
{"received_ms":1789987927767,"monotonic_ns":1019368598228900,"raw":"{\"market\":\"0x28a45972fccdaf0fba75dacc59725521035e177d09dd92174f9f52740bccb025\", \"price_changes\":[{\"asset_id\":\"61819828071723399190623735325323968706432622380635304641786792960078828866875\", \"price\":\"0.86\", \"size\":\"273\", \"side\":\"BUY\", \"hash\":\"6a97a2faeed94bc5e7fae3677b0765cf3c7931b4\", \"best_bid\":\"0.86\", \"best_ask\":\"0.87\"}, {\"asset_id\":\"114356653315647913247200886351065428002113119844334520181865067698979836634569\", \"price\":\"0.14\", \"size\":\"273\", \"side\":\"SELL\", \"hash\":\"6eb93f4fa668ea91e60dfad634bf449fd7e7dd94\", \"best_bid\":\"0.13\", \"best_ask\":\"0.14\"}], \"timestamp\":\"1789987927741\", \"event_type\":\"price_change\"}","raw_base64":null}
{"received_ms":1789987927767,"monotonic_ns":1019368598271100,"raw":"{\"market\":\"0x28a45972fccdaf0fba75dacc59725521035e177d09dd92174f9f52740bccb025\", \"price_changes\":[{\"asset_id\":\"114356653315647913247200886351065428002113119844334520181865067698979836634569\", \"price\":\"0.07\", \"size\":\"6401.71\", \"side\":\"BUY\", \"hash\":\"b0d5d0a27016001597ca1b754d760ea24ecb7469\", \"best_bid\":\"0.13\", \"best_ask\":\"0.14\"}, {\"asset_id\":\"61819828071723399190623735325323968706432622380635304641786792960078828866875\", \"price\":\"0.93\", \"size\":\"6401.71\", \"side\":\"SELL\", \"hash\":\"4d6804b87a2a9c509e4edb6977dcf897414ad16e\", \"best_bid\":\"0.86\", \"best_ask\":\"0.87\"}], \"timestamp\":\"1789987927742\", \"event_type\":\"price_change\"}","raw_base64":null}
{"received_ms":1789987927769,"monotonic_ns":1019368599668200,"raw":"{\"market\":\"0x28a45972fccdaf0fba75dacc59725521035e177d09dd92174f9f52740bccb025\", \"price_changes\":[{\"asset_id\":\"114356653315647913247200886351065428002113119844334520181865067698979836634569\", \"price\":\"0.07\", \"size\":\"6451.71\", \"side\":\"BUY\", \"hash\":\"335e0c5002105ef51e3dfa6d2dbd5f6f6d50e483\", \"best_bid\":\"0.13\", \"best_ask\":\"0.14\"}, {\"asset_id\":\"61819828071723399190623735325323968706432622380635304641786792960078828866875\", \"price\":\"0.93\", \"size\":\"6451.71\", \"side\":\"SELL\", \"hash\":\"bcb1716f1158805a171308899b32bd1ca6cfe121\", \"best_bid\":\"0.86\", \"best_ask\":\"0.87\"}], \"timestamp\":\"1789987927747\", \"event_type\":\"price_change\"}","raw_base64":null}
{"received_ms":1789987927772,"monotonic_ns":1019368602909700,"raw":"{\"market\":\"0x28a45972fccdaf0fba75dacc59725521035e177d09dd92174f9f52740bccb025\", \"price_changes\":[{\"asset_id\":\"114356653315647913247200886351065428002113119844334520181865067698979836634569\", \"price\":\"0.07\", \"size\":\"5437.71\", \"side\":\"BUY\", \"hash\":\"2804fcdbbc6e46cda950bb53cd66b5be0076d38f\", \"best_bid\":\"0.13\", \"best_ask\":\"0.14\"}, {\"asset_id\":\"61819828071723399190623735325323968706432622380635304641786792960078828866875\", \"price\":\"0.93\", \"size\":\"5437.71\", \"side\":\"SELL\", \"hash\":\"0861182a15934e80d5e160c2e465dc93fe111917\", \"best_bid\":\"0.86\", \"best_ask\":\"0.87\"}], \"timestamp\":\"1789987927748\", \"event_type\":\"price_change\"}","raw_base64":null}
{"received_ms":1789987927773,"monotonic_ns":1019368603748600,"raw":"{\"market\":\"0x28a45972fccdaf0fba75dacc59725521035e177d09dd92174f9f52740bccb025\", \"price_changes\":[{\"asset_id\":\"61819828071723399190623735325323968706432622380635304641786792960078828866875\", \"price\":\"0.84\", \"size\":\"2711\", \"side\":\"BUY\", \"hash\":\"54f4abdce5110c47cb05acb823681b24e536f8ec\", \"best_bid\":\"0.86\", \"best_ask\":\"0.87\"}, {\"asset_id\":\"114356653315647913247200886351065428002113119844334520181865067698979836634569\", \"price\":\"0.16\", \"size\":\"2711\", \"side\":\"SELL\", \"hash\":\"a5da48044026b6ecbcf6c3564f578c914806f058\", \"best_bid\":\"0.13\", \"best_ask\":\"0.14\"}], \"timestamp\":\"1789987927748\", \"event_type\":\"price_change\"}","raw_base64":null}
{"received_ms":1789987927773,"monotonic_ns":1019368603800100,"raw":"{\"market\":\"0x28a45972fccdaf0fba75dacc59725521035e177d09dd92174f9f52740bccb025\", \"price_changes\":[{\"asset_id\":\"61819828071723399190623735325323968706432622380635304641786792960078828866875\", \"price\":\"0.86\", \"size\":\"1808\", \"side\":\"BUY\", \"hash\":\"9aebeb035e393735ac7fd1bc91956c26a9a67ead\", \"best_bid\":\"0.86\", \"best_ask\":\"0.87\"}, {\"asset_id\":\"114356653315647913247200886351065428002113119844334520181865067698979836634569\", \"price\":\"0.14\", \"size\":\"1808\", \"side\":\"SELL\", \"hash\":\"5f2dbecbba35e66b7b1a794979a3643638489177\", \"best_bid\":\"0.13\", \"best_ask\":\"0.14\"}], \"timestamp\":\"1789987927749\", \"event_type\":\"price_change\"}","raw_base64":null}
{"received_ms":1789987927775,"monotonic_ns":1019368605829200,"raw":"{\"market\":\"0x28a45972fccdaf0fba75dacc59725521035e177d09dd92174f9f52740bccb025\", \"price_changes\":[{\"asset_id\":\"61819828071723399190623735325323968706432622380635304641786792960078828866875\", \"price\":\"0.85\", \"size\":\"2078.52\", \"side\":\"BUY\", \"hash\":\"d7c296227709818df208d689eb2d6894d38bc8b9\", \"best_bid\":\"0.86\", \"best_ask\":\"0.87\"}, {\"asset_id\":\"114356653315647913247200886351065428002113119844334520181865067698979836634569\", \"price\":\"0.15\", \"size\":\"2078.52\", \"side\":\"SELL\", \"hash\":\"b49b36c7d4a76af0df67744a43bfc4fe0ff51df1\", \"best_bid\":\"0.13\", \"best_ask\":\"0.14\"}], \"timestamp\":\"1789987927750\", \"event_type\":\"price_change\"}","raw_base64":null}
{"received_ms":1789987927776,"monotonic_ns":1019368606546200,"raw":"{\"market\":\"0x28a45972fccdaf0fba75dacc59725521035e177d09dd92174f9f52740bccb025\", \"price_changes\":[{\"asset_id\":\"114356653315647913247200886351065428002113119844334520181865067698979836634569\", \"price\":\"0.14\", \"size\":\"1803\", \"side\":\"SELL\", \"hash\":\"8e23e1b28576aa5c517dddb0c6810c05f8a9c7be\", \"best_bid\":\"0.13\", \"best_ask\":\"0.14\"}, {\"asset_id\":\"61819828071723399190623735325323968706432622380635304641786792960078828866875\", \"price\":\"0.86\", \"size\":\"1803\", \"side\":\"BUY\", \"hash\":\"5791be22ae14a05059a4125a058e6c5d2bc5b5b9\", \"best_bid\":\"0.86\", \"best_ask\":\"0.87\"}], \"timestamp\":\"1789987927754\", \"event_type\":\"price_change\"}","raw_base64":null}
{"received_ms":1789987927776,"monotonic_ns":1019368606599800,"raw":"{\"market\":\"0x28a45972fccdaf0fba75dacc59725521035e177d09dd92174f9f52740bccb025\", \"price_changes\":[{\"asset_id\":\"61819828071723399190623735325323968706432622380635304641786792960078828866875\", \"price\":\"0.85\", \"size\":\"2068.52\", \"side\":\"BUY\", \"hash\":\"5be7045e372e4ffc4e4ded9a8cc0fa394326ede0\", \"best_bid\":\"0.86\", \"best_ask\":\"0.87\"}, {\"asset_id\":\"114356653315647913247200886351065428002113119844334520181865067698979836634569\", \"price\":\"0.15\", \"size\":\"2068.52\", \"side\":\"SELL\", \"hash\":\"ed0c2c2fcffc5f228a18c2e0da8dc42a35bb0488\", \"best_bid\":\"0.13\", \"best_ask\":\"0.14\"}], \"timestamp\":\"1789987927754\", \"event_type\":\"price_change\"}","raw_base64":null}
{"received_ms":1789987927782,"monotonic_ns":1019368613248500,"raw":"{\"market\":\"0x28a45972fccdaf0fba75dacc59725521035e177d09dd92174f9f52740bccb025\", \"price_changes\":[{\"asset_id\":\"61819828071723399190623735325323968706432622380635304641786792960078828866875\", \"price\":\"0.85\", \"size\":\"1974.52\", \"side\":\"BUY\", \"hash\":\"3b5bea6d12a55db31b1b208370059e154a7eac8e\", \"best_bid\":\"0.86\", \"best_ask\":\"0.87\"}, {\"asset_id\":\"114356653315647913247200886351065428002113119844334520181865067698979836634569\", \"price\":\"0.15\", \"size\":\"1974.52\", \"side\":\"SELL\", \"hash\":\"40915d4c8b29353ab34bc5c817edf381859e0bb9\", \"best_bid\":\"0.13\", \"best_ask\":\"0.14\"}], \"timestamp\":\"1789987927760\", \"event_type\":\"price_change\"}","raw_base64":null}
{"received_ms":1789987927784,"monotonic_ns":1019368614338000,"raw":"{\"market\":\"0x28a45972fccdaf0fba75dacc59725521035e177d09dd92174f9f52740bccb025\", \"price_changes\":[{\"asset_id\":\"61819828071723399190623735325323968706432622380635304641786792960078828866875\", \"price\":\"0.75\", \"size\":\"540\", \"side\":\"BUY\", \"hash\":\"62aebbef03717e2e762a2b357aa9b999277d16e4\", \"best_bid\":\"0.86\", \"best_ask\":\"0.87\"}, {\"asset_id\":\"114356653315647913247200886351065428002113119844334520181865067698979836634569\", \"price\":\"0.25\", \"size\":\"540\", \"side\":\"SELL\", \"hash\":\"6fc90a38b12f046aee2df1e3a190c9f81c1b98a5\", \"best_bid\":\"0.13\", \"best_ask\":\"0.14\"}], \"timestamp\":\"1789987927762\", \"event_type\":\"price_change\"}","raw_base64":null}
{"received_ms":1789987927789,"monotonic_ns":1019368619739800,"raw":"{\"market\":\"0x28a45972fccdaf0fba75dacc59725521035e177d09dd92174f9f52740bccb025\", \"price_changes\":[{\"asset_id\":\"61819828071723399190623735325323968706432622380635304641786792960078828866875\", \"price\":\"0.77\", \"size\":\"587.49\", \"side\":\"BUY\", \"hash\":\"2372980f3c01dc948a9a7b8f31bf15304bdf0724\", \"best_bid\":\"0.86\", \"best_ask\":\"0.87\"}, {\"asset_id\":\"114356653315647913247200886351065428002113119844334520181865067698979836634569\", \"price\":\"0.23\", \"size\":\"587.49\", \"side\":\"SELL\", \"hash\":\"5985bc27fa49974e9b2095dafb9aef0a88399c4e\", \"best_bid\":\"0.13\", \"best_ask\":\"0.14\"}], \"timestamp\":\"1789987927763\", \"event_type\":\"price_change\"}","raw_base64":null}
{"received_ms":1789987927789,"monotonic_ns":1019368619799800,"raw":"{\"market\":\"0x28a45972fccdaf0fba75dacc59725521035e177d09dd92174f9f52740bccb025\", \"price_changes\":[{\"asset_id\":\"61819828071723399190623735325323968706432622380635304641786792960078828866875\", \"price\":\"0.79\", \"size\":\"487\", \"side\":\"BUY\", \"hash\":\"2a79f54905241209ff8136a1bcb558dffa055164\", \"best_bid\":\"0.86\", \"best_ask\":\"0.87\"}, {\"asset_id\":\"114356653315647913247200886351065428002113119844334520181865067698979836634569\", \"price\":\"0.21\", \"size\":\"487\", \"side\":\"SELL\", \"hash\":\"45bf7185e28ffb37ae03902dbae99751dea6ad7c\", \"best_bid\":\"0.13\", \"best_ask\":\"0.14\"}], \"timestamp\":\"1789987927764\", \"event_type\":\"price_change\"}","raw_base64":null}
{"received_ms":1789987927789,"monotonic_ns":1019368619843900,"raw":"{\"market\":\"0x28a45972fccdaf0fba75dacc59725521035e177d09dd92174f9f52740bccb025\", \"price_changes\":[{\"asset_id\":\"61819828071723399190623735325323968706432622380635304641786792960078828866875\", \"price\":\"0.77\", \"size\":\"527.49\", \"side\":\"BUY\", \"hash\":\"9533cd8d0e82a67aec5c2ae59a0424fb3479061f\", \"best_bid\":\"0.86\", \"best_ask\":\"0.87\"}, {\"asset_id\":\"114356653315647913247200886351065428002113119844334520181865067698979836634569\", \"price\":\"0.23\", \"size\":\"527.49\", \"side\":\"SELL\", \"hash\":\"b76be8fc208f09b56cc1688a2f645e2058a5d6e1\", \"best_bid\":\"0.13\", \"best_ask\":\"0.14\"}], \"timestamp\":\"1789987927765\", \"event_type\":\"price_change\"}","raw_base64":null}
{"received_ms":1789987927789,"monotonic_ns":1019368619887200,"raw":"{\"market\":\"0x28a45972fccdaf0fba75dacc59725521035e177d09dd92174f9f52740bccb025\", \"price_changes\":[{\"asset_id\":\"61819828071723399190623735325323968706432622380635304641786792960078828866875\", \"price\":\"0.79\", \"size\":\"427\", \"side\":\"BUY\", \"hash\":\"9533cd8d0e82a67aec5c2ae59a0424fb3479061f\", \"best_bid\":\"0.86\", \"best_ask\":\"0.87\"}, {\"asset_id\":\"114356653315647913247200886351065428002113119844334520181865067698979836634569\", \"price\":\"0.21\", \"size\":\"427\", \"side\":\"SELL\", \"hash\":\"b76be8fc208f09b56cc1688a2f645e2058a5d6e1\", \"best_bid\":\"0.13\", \"best_ask\":\"0.14\"}], \"timestamp\":\"1789987927765\", \"event_type\":\"price_change\"}","raw_base64":null}
{"received_ms":1789987927792,"monotonic_ns":1019368622433600,"raw":"{\"market\":\"0x28a45972fccdaf0fba75dacc59725521035e177d09dd92174f9f52740bccb025\", \"price_changes\":[{\"asset_id\":\"114356653315647913247200886351065428002113119844334520181865067698979836634569\", \"price\":\"0.11\", \"size\":\"316.1\", \"side\":\"BUY\", \"hash\":\"1b9a9acf403eb0f3bc3dde70c31d4eae58f2db17\", \"best_bid\":\"0.13\", \"best_ask\":\"0.14\"}, {\"asset_id\":\"61819828071723399190623735325323968706432622380635304641786792960078828866875\", \"price\":\"0.89\", \"size\":\"316.1\", \"side\":\"SELL\", \"hash\":\"31c4e14401dd944c6b41199995646567f711e19c\", \"best_bid\":\"0.86\", \"best_ask\":\"0.87\"}], \"timestamp\":\"1789987927771\", \"event_type\":\"price_change\"}","raw_base64":null}
{"received_ms":1789987927797,"monotonic_ns":1019368627318700,"raw":"{\"market\":\"0x28a45972fccdaf0fba75dacc59725521035e177d09dd92174f9f52740bccb025\", \"price_changes\":[{\"asset_id\":\"61819828071723399190623735325323968706432622380635304641786792960078828866875\", \"price\":\"0.85\", \"size\":\"1989.52\", \"side\":\"BUY\", \"hash\":\"6938d3246a41b479502787090e101f69a3a0c2ea\", \"best_bid\":\"0.86\", \"best_ask\":\"0.87\"}, {\"asset_id\":\"114356653315647913247200886351065428002113119844334520181865067698979836634569\", \"price\":\"0.15\", \"size\":\"1989.52\", \"side\":\"SELL\", \"hash\":\"c92bffff401cdf99cd3f5d09a3505988df8356e2\", \"best_bid\":\"0.13\", \"best_ask\":\"0.14\"}], \"timestamp\":\"1789987927775\", \"event_type\":\"price_change\"}","raw_base64":null}
{"received_ms":1789987927798,"monotonic_ns":1019368628686300,"raw":"{\"market\":\"0x28a45972fccdaf0fba75dacc59725521035e177d09dd92174f9f52740bccb025\", \"price_changes\":[{\"asset_id\":\"61819828071723399190623735325323968706432622380635304641786792960078828866875\", \"price\":\"0.85\", \"size\":\"2049.52\", \"side\":\"BUY\", \"hash\":\"b84559f3e82a3f9cc49a1fc50342437a8d80ab92\", \"best_bid\":\"0.86\", \"best_ask\":\"0.87\"}, {\"asset_id\":\"114356653315647913247200886351065428002113119844334520181865067698979836634569\", \"price\":\"0.15\", \"size\":\"2049.52\", \"side\":\"SELL\", \"hash\":\"125599e50e3be57304fa90c441fb94396dab0514\", \"best_bid\":\"0.13\", \"best_ask\":\"0.14\"}], \"timestamp\":\"1789987927776\", \"event_type\":\"price_change\"}","raw_base64":null}
{"received_ms":1789987927802,"monotonic_ns":1019368632317600,"raw":"{\"market\":\"0x28a45972fccdaf0fba75dacc59725521035e177d09dd92174f9f52740bccb025\", \"price_changes\":[{\"asset_id\":\"61819828071723399190623735325323968706432622380635304641786792960078828866875\", \"price\":\"0.84\", \"size\":\"2611\", \"side\":\"BUY\", \"hash\":\"33758393dbf9abd0453c8193f744e6f3e4932ed8\", \"best_bid\":\"0.86\", \"best_ask\":\"0.87\"}, {\"asset_id\":\"114356653315647913247200886351065428002113119844334520181865067698979836634569\", \"price\":\"0.16\", \"size\":\"2611\", \"side\":\"SELL\", \"hash\":\"f926d55fa2fc1caac3f33e26f9e6a65513997fbc\", \"best_bid\":\"0.13\", \"best_ask\":\"0.14\"}], \"timestamp\":\"1789987927779\", \"event_type\":\"price_change\"}","raw_base64":null}
{"received_ms":1789987927802,"monotonic_ns":1019368632368500,"raw":"{\"market\":\"0x28a45972fccdaf0fba75dacc59725521035e177d09dd92174f9f52740bccb025\", \"price_changes\":[{\"asset_id\":\"61819828071723399190623735325323968706432622380635304641786792960078828866875\", \"price\":\"0.86\", \"size\":\"268\", \"side\":\"BUY\", \"hash\":\"1e958e6d69d100730a069a5d0fc95d0ac02037a3\", \"best_bid\":\"0.86\", \"best_ask\":\"0.87\"}, {\"asset_id\":\"114356653315647913247200886351065428002113119844334520181865067698979836634569\", \"price\":\"0.14\", \"size\":\"268\", \"side\":\"SELL\", \"hash\":\"fee5df635b4d419c66aa55caf96e65e59b06e82b\", \"best_bid\":\"0.13\", \"best_ask\":\"0.14\"}], \"timestamp\":\"1789987927780\", \"event_type\":\"price_change\"}","raw_base64":null}
{"received_ms":1789987927802,"monotonic_ns":1019368632409800,"raw":"{\"market\":\"0x28a45972fccdaf0fba75dacc59725521035e177d09dd92174f9f52740bccb025\", \"price_changes\":[{\"asset_id\":\"114356653315647913247200886351065428002113119844334520181865067698979836634569\", \"price\":\"0.06\", \"size\":\"5080.67\", \"side\":\"BUY\", \"hash\":\"8921ad224ec56f2b2761d7eebf1e1cd1ac7188ff\", \"best_bid\":\"0.13\", \"best_ask\":\"0.14\"}, {\"asset_id\":\"61819828071723399190623735325323968706432622380635304641786792960078828866875\", \"price\":\"0.94\", \"size\":\"5080.67\", \"side\":\"SELL\", \"hash\":\"763b789d583238152872485b592cd5dea9369f74\", \"best_bid\":\"0.86\", \"best_ask\":\"0.87\"}], \"timestamp\":\"1789987927780\", \"event_type\":\"price_change\"}","raw_base64":null}
