{"received_ms":1789987931146,"monotonic_ns":1019371976536700,"raw":"{\"market\":\"0x28a45972fccdaf0fba75dacc59725521035e177d09dd92174f9f52740bccb025\", \"price_changes\":[{\"asset_id\":\"61819828071723399190623735325323968706432622380635304641786792960078828866875\", \"price\":\"0.8\", \"size\":\"587\", \"side\":\"BUY\", \"hash\":\"3be7268b5444d50d85cffbf88343e78988953488\", \"best_bid\":\"0.86\", \"best_ask\":\"0.87\"}, {\"asset_id\":\"114356653315647913247200886351065428002113119844334520181865067698979836634569\", \"price\":\"0.2\", \"size\":\"587\", \"side\":\"SELL\", \"hash\":\"d7d47cd247a4c9b4aba19df1ae5e9e2b9e04ee76\", \"best_bid\":\"0.13\", \"best_ask\":\"0.14\"}], \"timestamp\":\"1789987931125\", \"event_type\":\"price_change\"}","raw_base64":null}
{"received_ms":1789987931155,"monotonic_ns":1019371985611800,"raw":"{\"market\":\"0x28a45972fccdaf0fba75dacc59725521035e177d09dd92174f9f52740bccb025\", \"price_changes\":[{\"asset_id\":\"114356653315647913247200886351065428002113119844334520181865067698979836634569\", \"price\":\"0.06\", \"size\":\"4856.67\", \"side\":\"BUY\", \"hash\":\"f02af262cc86d7a00363c33f62382e9b9593d319\", \"best_bid\":\"0.13\", \"best_ask\":\"0.14\"}, {\"asset_id\":\"61819828071723399190623735325323968706432622380635304641786792960078828866875\", \"price\":\"0.94\", \"size\":\"4856.67\", \"side\":\"SELL\", \"hash\":\"641234cb7bedfb78fa098f4cbf3095903f980952\", \"best_bid\":\"0.86\", \"best_ask\":\"0.87\"}], \"timestamp\":\"1789987931135\", \"event_type\":\"price_change\"}","raw_base64":null}
{"received_ms":1789987931157,"monotonic_ns":1019371987441100,"raw":"{\"market\":\"0x28a45972fccdaf0fba75dacc59725521035e177d09dd92174f9f52740bccb025\", \"price_changes\":[{\"asset_id\":\"61819828071723399190623735325323968706432622380635304641786792960078828866875\", \"price\":\"0.84\", \"size\":\"2471\", \"side\":\"BUY\", \"hash\":\"005dace4a1959b79c67d3fc3f1736e02e996d5a5\", \"best_bid\":\"0.86\", \"best_ask\":\"0.87\"}, {\"asset_id\":\"114356653315647913247200886351065428002113119844334520181865067698979836634569\", \"price\":\"0.16\", \"size\":\"2471\", \"side\":\"SELL\", \"hash\":\"09d8d17967df28511ab5501ea550796724c1f239\", \"best_bid\":\"0.13\", \"best_ask\":\"0.14\"}], \"timestamp\":\"1789987931137\", \"event_type\":\"price_change\"}","raw_base64":null}
{"received_ms":1789987931157,"monotonic_ns":1019371987773200,"raw":"{\"market\":\"0x28a45972fccdaf0fba75dacc59725521035e177d09dd92174f9f52740bccb025\", \"price_changes\":[{\"asset_id\":\"61819828071723399190623735325323968706432622380635304641786792960078828866875\", \"price\":\"0.86\", \"size\":\"118\", \"side\":\"BUY\", \"hash\":\"0daa6c36891b508c8ff931f5d24febad5bd3f8a8\", \"best_bid\":\"0.86\", \"best_ask\":\"0.87\"}, {\"asset_id\":\"114356653315647913247200886351065428002113119844334520181865067698979836634569\", \"price\":\"0.14\", \"size\":\"118\", \"side\":\"SELL\", \"hash\":\"b05332f6141590ebcc967f7bd51d8cada0dc48a8\", \"best_bid\":\"0.13\", \"best_ask\":\"0.14\"}], \"timestamp\":\"1789987931137\", \"event_type\":\"price_change\"}","raw_base64":null}
{"received_ms":1789987931158,"monotonic_ns":1019371988908300,"raw":"{\"market\":\"0x28a45972fccdaf0fba75dacc59725521035e177d09dd92174f9f52740bccb025\", \"price_changes\":[{\"asset_id\":\"114356653315647913247200886351065428002113119844334520181865067698979836634569\", \"price\":\"0.03\", \"size\":\"4057.57\", \"side\":\"BUY\", \"hash\":\"5731264a8eb49321d6474cc22cf134d1c45a7e3e\", \"best_bid\":\"0.13\", \"best_ask\":\"0.14\"}, {\"asset_id\":\"61819828071723399190623735325323968706432622380635304641786792960078828866875\", \"price\":\"0.97\", \"size\":\"4057.57\", \"side\":\"SELL\", \"hash\":\"1aa8815df0eefdc8fe7897be478dbd2657e9601f\", \"best_bid\":\"0.86\", \"best_ask\":\"0.87\"}], \"timestamp\":\"1789987931138\", \"event_type\":\"price_change\"}","raw_base64":null}
{"received_ms":1789987931161,"monotonic_ns":1019371991471600,"raw":"{\"market\":\"0x28a45972fccdaf0fba75dacc59725521035e177d09dd92174f9f52740bccb025\", \"price_changes\":[{\"asset_id\":\"61819828071723399190623735325323968706432622380635304641786792960078828866875\", \"price\":\"0.81\", \"size\":\"583\", \"side\":\"BUY\", \"hash\":\"4315072ccf03317383d1d49cf84667de7ef480d1\", \"best_bid\":\"0.86\", \"best_ask\":\"0.87\"}, {\"asset_id\":\"114356653315647913247200886351065428002113119844334520181865067698979836634569\", \"price\":\"0.19\", \"size\":\"583\", \"side\":\"SELL\", \"hash\":\"8581fbc6250048fa20e4e9b6ddf78b27acae47eb\", \"best_bid\":\"0.13\", \"best_ask\":\"0.14\"}], \"timestamp\":\"1789987931140\", \"event_type\":\"price_change\"}","raw_base64":null}
{"received_ms":1789987931162,"monotonic_ns":1019371992595100,"raw":"{\"market\":\"0x28a45972fccdaf0fba75dacc59725521035e177d09dd92174f9f52740bccb025\", \"price_changes\":[{\"asset_id\":\"61819828071723399190623735325323968706432622380635304641786792960078828866875\", \"price\":\"0.85\", \"size\":\"3075.52\", \"side\":\"BUY\", \"hash\":\"976909f86f5a712338779a0b1fd683ed88800dea\", \"best_bid\":\"0.86\", \"best_ask\":\"0.87\"}, {\"asset_id\":\"114356653315647913247200886351065428002113119844334520181865067698979836634569\", \"price\":\"0.15\", \"size\":\"3075.52\", \"side\":\"SELL\", \"hash\":\"b789938971f5188c0169d68457fb3e98f98b9001\", \"best_bid\":\"0.13\", \"best_ask\":\"0.14\"}], \"timestamp\":\"1789987931142\", \"event_type\":\"price_change\"}","raw_base64":null}
{"received_ms":1789987931164,"monotonic_ns":1019371994584000,"raw":"{\"market\":\"0x28a45972fccdaf0fba75dacc59725521035e177d09dd92174f9f52740bccb025\", \"price_changes\":[{\"asset_id\":\"61819828071723399190623735325323968706432622380635304641786792960078828866875\", \"price\":\"0.83\", \"size\":\"536\", \"side\":\"BUY\", \"hash\":\"aab7868997087f971df8f90a42f969c8e4b26715\", \"best_bid\":\"0.86\", \"best_ask\":\"0.87\"}, {\"asset_id\":\"114356653315647913247200886351065428002113119844334520181865067698979836634569\", \"price\":\"0.17\", \"size\":\"536\", \"side\":\"SELL\", \"hash\":\"488269ebbb3a5ed0485fecc844b1f32ff9897773\", \"best_bid\":\"0.13\", \"best_ask\":\"0.14\"}], \"timestamp\":\"1789987931144\", \"event_type\":\"price_change\"}","raw_base64":null}
{"received_ms":1789987931178,"monotonic_ns":1019372008628500,"raw":"{\"market\":\"0x28a45972fccdaf0fba75dacc59725521035e177d09dd92174f9f52740bccb025\", \"price_changes\":[{\"asset_id\":\"61819828071723399190623735325323968706432622380635304641786792960078828866875\", \"price\":\"0.75\", \"size\":\"540\", \"side\":\"BUY\", \"hash\":\"3b95a5d037e18ce3055aaf07da03da914a9792c4\", \"best_bid\":\"0.86\", \"best_ask\":\"0.87\"}, {\"asset_id\":\"114356653315647913247200886351065428002113119844334520181865067698979836634569\", \"price\":\"0.25\", \"size\":\"540\", \"side\":\"SELL\", \"hash\":\"367d1c5a503b26c09d98ce3a479b1da0d45b6fe9\", \"best_bid\":\"0.13\", \"best_ask\":\"0.14\"}], \"timestamp\":\"1789987931158\", \"event_type\":\"price_change\"}","raw_base64":null}
{"received_ms":1789987931178,"monotonic_ns":1019372009198000,"raw":"{\"market\":\"0x28a45972fccdaf0fba75dacc59725521035e177d09dd92174f9f52740bccb025\", \"price_changes\":[{\"asset_id\":\"61819828071723399190623735325323968706432622380635304641786792960078828866875\", \"price\":\"0.73\", \"size\":\"484\", \"side\":\"BUY\", \"hash\":\"0130971812e84965e6636d09a2b8b67f9c202a1d\", \"best_bid\":\"0.86\", \"best_ask\":\"0.87\"}, {\"asset_id\":\"114356653315647913247200886351065428002113119844334520181865067698979836634569\", \"price\":\"0.27\", \"size\":\"484\", \"side\":\"SELL\", \"hash\":\"3c179940db161fb92c3dc359a4a178f99927bfdc\", \"best_bid\":\"0.13\", \"best_ask\":\"0.14\"}], \"timestamp\":\"1789987931159\", \"event_type\":\"price_change\"}","raw_base64":null}
{"received_ms":1789987931184,"monotonic_ns":1019372015223000,"raw":"{\"market\":\"0x28a45972fccdaf0fba75dacc59725521035e177d09dd92174f9f52740bccb025\", \"price_changes\":[{\"asset_id\":\"114356653315647913247200886351065428002113119844334520181865067698979836634569\", \"price\":\"0.2\", \"size\":\"592\", \"side\":\"SELL\", \"hash\":\"fc163b59fcd7d13907155fb0950e171d5751ae42\", \"best_bid\":\"0.13\", \"best_ask\":\"0.14\"}, {\"asset_id\":\"61819828071723399190623735325323968706432622380635304641786792960078828866875\", \"price\":\"0.8\", \"size\":\"592\", \"side\":\"BUY\", \"hash\":\"dae27f8a439dce325950f0792af0262de05548f0\", \"best_bid\":\"0.86\", \"best_ask\":\"0.87\"}], \"timestamp\":\"1789987931163\", \"event_type\":\"price_change\"}","raw_base64":null}
{"received_ms":1789987931185,"monotonic_ns":1019372015288700,"raw":"{\"market\":\"0x28a45972fccdaf0fba75dacc59725521035e177d09dd92174f9f52740bccb025\", \"price_changes\":[{\"asset_id\":\"61819828071723399190623735325323968706432622380635304641786792960078828866875\", \"price\":\"0.75\", \"size\":\"520\", \"side\":\"BUY\", \"hash\":\"1f17e236481d26c65c784d5bb2c80dd22e91e176\", \"best_bid\":\"0.86\", \"best_ask\":\"0.87\"}, {\"asset_id\":\"114356653315647913247200886351065428002113119844334520181865067698979836634569\", \"price\":\"0.25\", \"size\":\"520\", \"side\":\"SELL\", \"hash\":\"f3293792bbd6e86424deb97ec554dd69a239ef5f\", \"best_bid\":\"0.13\", \"best_ask\":\"0.14\"}], \"timestamp\":\"1789987931164\", \"event_type\":\"price_change\"}","raw_base64":null}
{"received_ms":1789987931185,"monotonic_ns":1019372015410000,"raw":"{\"market\":\"0x28a45972fccdaf0fba75dacc59725521035e177d09dd92174f9f52740bccb025\", \"price_changes\":[{\"asset_id\":\"61819828071723399190623735325323968706432622380635304641786792960078828866875\", \"price\":\"0.73\", \"size\":\"404\", \"side\":\"BUY\", \"hash\":\"1f17e236481d26c65c784d5bb2c80dd22e91e176\", \"best_bid\":\"0.86\", \"best_ask\":\"0.87\"}, {\"asset_id\":\"114356653315647913247200886351065428002113119844334520181865067698979836634569\", \"price\":\"0.27\", \"size\":\"404\", \"side\":\"SELL\", \"hash\":\"f3293792bbd6e86424deb97ec554dd69a239ef5f\", \"best_bid\":\"0.13\", \"best_ask\":\"0.14\"}], \"timestamp\":\"1789987931164\", \"event_type\":\"price_change\"}","raw_base64":null}
{"received_ms":1789987931190,"monotonic_ns":1019372020758400,"raw":"{\"market\":\"0x28a45972fccdaf0fba75dacc59725521035e177d09dd92174f9f52740bccb025\", \"price_changes\":[{\"asset_id\":\"61819828071723399190623735325323968706432622380635304641786792960078828866875\", \"price\":\"0.86\", \"size\":\"25\", \"side\":\"BUY\", \"hash\":\"d2773439a065d6d0c2a9205074e79407d8fbe537\", \"best_bid\":\"0.86\", \"best_ask\":\"0.87\"}, {\"asset_id\":\"114356653315647913247200886351065428002113119844334520181865067698979836634569\", \"price\":\"0.14\", \"size\":\"25\", \"side\":\"SELL\", \"hash\":\"404f630f163d396fdfb67fb9ea28c2d29b590c89\", \"best_bid\":\"0.13\", \"best_ask\":\"0.14\"}], \"timestamp\":\"1789987931169\", \"event_type\":\"price_change\"}","raw_base64":null}
{"received_ms":1789987931191,"monotonic_ns":1019372021819000,"raw":"{\"market\":\"0x28a45972fccdaf0fba75dacc59725521035e177d09dd92174f9f52740bccb025\", \"price_changes\":[{\"asset_id\":\"114356653315647913247200886351065428002113119844334520181865067698979836634569\", \"price\":\"0.06\", \"size\":\"4974.67\", \"side\":\"BUY\", \"hash\":\"36e75b200c41bbad0b21428f29d11bfff2070ba5\", \"best_bid\":\"0.13\", \"best_ask\":\"0.14\"}, {\"asset_id\":\"61819828071723399190623735325323968706432622380635304641786792960078828866875\", \"price\":\"0.94\", \"size\":\"4974.67\", \"side\":\"SELL\", \"hash\":\"33a3c131eff87b6014ab2ecc113f4c50578c9eb9\", \"best_bid\":\"0.86\", \"best_ask\":\"0.87\"}], \"timestamp\":\"1789987931171\", \"event_type\":\"price_change\"}","raw_base64":null}
{"received_ms":1789987931192,"monotonic_ns":1019372023036800,"raw":"{\"market\":\"0x28a45972fccdaf0fba75dacc59725521035e177d09dd92174f9f52740bccb025\", \"price_changes\":[{\"asset_id\":\"114356653315647913247200886351065428002113119844334520181865067698979836634569\", \"price\":\"0.07\", \"size\":\"8203.71\", \"side\":\"BUY\", \"hash\":\"abced42430a1ccc0b79d637977a896c9746600e8\", \"best_bid\":\"0.13\", \"best_ask\":\"0.14\"}, {\"asset_id\":\"61819828071723399190623735325323968706432622380635304641786792960078828866875\", \"price\":\"0.93\", \"size\":\"8203.71\", \"side\":\"SELL\", \"hash\":\"c6b12b6900ac6968a67014f61cf01810b9aa2a6b\", \"best_bid\":\"0.86\", \"best_ask\":\"0.87\"}], \"timestamp\":\"1789987931172\", \"event_type\":\"price_change\"}","raw_base64":null}
{"received_ms":1789987931218,"monotonic_ns":1019372048861600,"raw":"{\"market\":\"0x28a45972fccdaf0fba75dacc59725521035e177d09dd92174f9f52740bccb025\", \"price_changes\":[{\"asset_id\":\"61819828071723399190623735325323968706432622380635304641786792960078828866875\", \"price\":\"0.77\", \"size\":\"587.49\", \"side\":\"BUY\", \"hash\":\"2667c5f5e9ae75de17afc7af5480ebc544df1f02\", \"best_bid\":\"0.86\", \"best_ask\":\"0.87\"}, {\"asset_id\":\"114356653315647913247200886351065428002113119844334520181865067698979836634569\", \"price\":\"0.23\", \"size\":\"587.49\", \"side\":\"SELL\", \"hash\":\"43bb25968311b0554579e7c1bd3beb31d3bee0a3\", \"best_bid\":\"0.13\", \"best_ask\":\"0.14\"}], \"timestamp\":\"1789987931193\", \"event_type\":\"price_change\"}","raw_base64":null}
{"received_ms":1789987931218,"monotonic_ns":1019372048968700,"raw":"{\"market\":\"0x28a45972fccdaf0fba75dacc59725521035e177d09dd92174f9f52740bccb025\", \"price_changes\":[{\"asset_id\":\"61819828071723399190623735325323968706432622380635304641786792960078828866875\", \"price\":\"0.79\", \"size\":\"442\", \"side\":\"BUY\", \"hash\":\"8400c0d785ee8a82c7789a2c6bbd68ad3c959766\", \"best_bid\":\"0.86\", \"best_ask\":\"0.87\"}, {\"asset_id\":\"114356653315647913247200886351065428002113119844334520181865067698979836634569\", \"price\":\"0.21\", \"size\":\"442\", \"side\":\"SELL\", \"hash\":\"be8e3e8b3274a700b19b7ea95221351d0750a97b\", \"best_bid\":\"0.13\", \"best_ask\":\"0.14\"}], \"timestamp\":\"1789987931197\", \"event_type\":\"price_change\"}","raw_base64":null}
{"received_ms":1789987931219,"monotonic_ns":1019372049998600,"raw":"{\"market\":\"0x28a45972fccdaf0fba75dacc59725521035e177d09dd92174f9f52740bccb025\", \"price_changes\":[{\"asset_id\":\"61819828071723399190623735325323968706432622380635304641786792960078828866875\", \"price\":\"0.77\", \"size\":\"507.49\", \"side\":\"BUY\", \"hash\":\"2102209ccf2fb32a95a5dd280dceb2be7aca01e8\", \"best_bid\":\"0.86\", \"best_ask\":\"0.87\"}, {\"asset_id\":\"114356653315647913247200886351065428002113119844334520181865067698979836634569\", \"price\":\"0.23\", \"size\":\"507.49\", \"side\":\"SELL\", \"hash\":\"6771dddc17a93dc409ae90d87572369b2f181cc5\", \"best_bid\":\"0.13\", \"best_ask\":\"0.14\"}], \"timestamp\":\"1789987931199\", \"event_type\":\"price_change\"}","raw_base64":null}
{"received_ms":1789987931235,"monotonic_ns":1019372065377000,"raw":"{\"market\":\"0x28a45972fccdaf0fba75dacc59725521035e177d09dd92174f9f52740bccb025\", \"price_changes\":[{\"asset_id\":\"61819828071723399190623735325323968706432622380635304641786792960078828866875\", \"price\":\"0.84\", \"size\":\"3471\", \"side\":\"BUY\", \"hash\":\"1f4240d13d8e71ea79a42d5b0cf3a567409503d6\", \"best_bid\":\"0.86\", \"best_ask\":\"0.87\"}, {\"asset_id\":\"114356653315647913247200886351065428002113119844334520181865067698979836634569\", \"price\":\"0.16\", \"size\":\"3471\", \"side\":\"SELL\", \"hash\":\"3bb024dbc4ea35b9bc65f7b5d45b4d0988a80125\", \"best_bid\":\"0.13\", \"best_ask\":\"0.14\"}], \"timestamp\":\"1789987931203\", \"event_type\":\"price_change\"}","raw_base64":null}
{"received_ms":1789987931235,"monotonic_ns":1019372065437900,"raw":"{\"market\":\"0x28a45972fccdaf0fba75dacc59725521035e177d09dd92174f9f52740bccb025\", \"price_changes\":[{\"asset_id\":\"61819828071723399190623735325323968706432622380635304641786792960078828866875\", \"price\":\"0.79\", \"size\":\"422\", \"side\":\"BUY\", \"hash\":\"c92c97d34ca1b054d20feab2e2d2eea2c5e9032a\", \"best_bid\":\"0.86\", \"best_ask\":\"0.87\"}, {\"asset_id\":\"114356653315647913247200886351065428002113119844334520181865067698979836634569\", \"price\":\"0.21\", \"size\":\"422\", \"side\":\"SELL\", \"hash\":\"eb0410738d4f1d35c2026cadc4423245c0d99df1\", \"best_bid\":\"0.13\", \"best_ask\":\"0.14\"}], \"timestamp\":\"1789987931203\", \"event_type\":\"price_change\"}","raw_base64":null}
{"received_ms":1789987931235,"monotonic_ns":1019372065488000,"raw":"{\"market\":\"0x28a45972fccdaf0fba75dacc59725521035e177d09dd92174f9f52740bccb025\", \"price_changes\":[{\"asset_id\":\"61819828071723399190623735325323968706432622380635304641786792960078828866875\", \"price\":\"0.86\", \"size\":\"32\", \"side\":\"BUY\", \"hash\":\"237942694a596fe5eebf196bfc78a204c4d679ef\", \"best_bid\":\"0.86\", \"best_ask\":\"0.87\"}, {\"asset_id\":\"114356653315647913247200886351065428002113119844334520181865067698979836634569\", \"price\":\"0.14\", \"size\":\"32\", \"side\":\"SELL\", \"hash\":\"f299b9c3273b6876048cdb74ddb8e9e8cd069981\", \"best_bid\":\"0.13\", \"best_ask\":\"0.14\"}], \"timestamp\":\"1789987931204\", \"event_type\":\"price_change\"}","raw_base64":null}
{"received_ms":1789987931248,"monotonic_ns":1019372078381700,"raw":"{\"market\":\"0x28a45972fccdaf0fba75dacc59725521035e177d09dd92174f9f52740bccb025\", \"price_changes\":[{\"asset_id\":\"61819828071723399190623735325323968706432622380635304641786792960078828866875\", \"price\":\"0.84\", \"size\":\"3291\", \"side\":\"BUY\", \"hash\":\"f0ebe8ddee284b53c14145aeb46b83bccb856fe6\", \"best_bid\":\"0.86\", \"best_ask\":\"0.87\"}, {\"asset_id\":\"114356653315647913247200886351065428002113119844334520181865067698979836634569\", \"price\":\"0.16\", \"size\":\"3291\", \"side\":\"SELL\", \"hash\":\"bf0abb6c759cc365ac6dc9716692a2e725840264\", \"best_bid\":\"0.13\", \"best_ask\":\"0.14\"}], \"timestamp\":\"1789987931206\", \"event_type\":\"price_change\"}","raw_base64":null}
{"received_ms":1789987931248,"monotonic_ns":1019372078479900,"raw":"{\"market\":\"0x28a45972fccdaf0fba75dacc59725521035e177d09dd92174f9f52740bccb025\", \"price_changes\":[{\"asset_id\":\"61819828071723399190623735325323968706432622380635304641786792960078828866875\", \"price\":\"0.85\", \"size\":\"3052.52\", \"side\":\"BUY\", \"hash\":\"3643a6cf5e8ca04515751f7861649715eb7bee1a\", \"best_bid\":\"0.86\", \"best_ask\":\"0.87\"}, {\"asset_id\":\"114356653315647913247200886351065428002113119844334520181865067698979836634569\", \"price\":\"0.15\", \"size\":\"3052.52\", \"side\":\"SELL\", \"hash\":\"2edf05316456c398a7d55f5752e2ff7203dc04e0\", \"best_bid\":\"0.13\", \"best_ask\":\"0.14\"}], \"timestamp\":\"1789987931208\", \"event_type\":\"price_change\"}","raw_base64":null}
{"received_ms":1789987931248,"monotonic_ns":1019372078540500,"raw":"{\"market\":\"0x28a45972fccdaf0fba75dacc59725521035e177d09dd92174f9f52740bccb025\", \"price_changes\":[{\"asset_id\":\"61819828071723399190623735325323968706432622380635304641786792960078828866875\", \"price\":\"0.91\", \"size\":\"523.12\", \"side\":\"SELL\", \"hash\":\"bf828ced06dd6c6e7d60595a61a65cdf26023f50\", \"best_bid\":\"0.86\", \"best_ask\":\"0.87\"}, {\"asset_id\":\"114356653315647913247200886351065428002113119844334520181865067698979836634569\", \"price\":\"0.09\", \"size\":\"523.12\", \"side\":\"BUY\", \"hash\":\"5f1fbea0a982b57d47749b154a8bc2a747881227\", \"best_bid\":\"0.13\", \"best_ask\":\"0.14\"}], \"timestamp\":\"1789987931212\", \"event_type\":\"price_change\"}","raw_base64":null}
{"received_ms":1789987931248,"monotonic_ns":1019372078592400,"raw":"{\"market\":\"0x28a45972fccdaf0fba75dacc59725521035e177d09dd92174f9f52740bccb025\", \"price_changes\":[{\"asset_id\":\"61819828071723399190623735325323968706432622380635304641786792960078828866875\", \"price\":\"0.84\", \"size\":\"3281\", \"side\":\"BUY\", \"hash\":\"befdd29e91dd14034ba8248622678a773e565465\", \"best_bid\":\"0.86\", \"best_ask\":\"0.87\"}, {\"asset_id\":\"114356653315647913247200886351065428002113119844334520181865067698979836634569\", \"price\":\"0.16\", \"size\":\"3281\", \"side\":\"SELL\", \"hash\":\"38d541f8c24190b08134bd4e6c11d0e02dcf07c2\", \"best_bid\":\"0.13\", \"best_ask\":\"0.14\"}], \"timestamp\":\"1789987931214\", \"event_type\":\"price_change\"}","raw_base64":null}
{"received_ms":1789987931248,"monotonic_ns":1019372078662100,"raw":"{\"market\":\"0x28a45972fccdaf0fba75dacc59725521035e177d09dd92174f9f52740bccb025\", \"price_changes\":[{\"asset_id\":\"61819828071723399190623735325323968706432622380635304641786792960078828866875\", \"price\":\"0.9\", \"size\":\"520\", \"side\":\"SELL\", \"hash\":\"4cff9278301df05390bcee86cfc516befa3f6e98\", \"best_bid\":\"0.86\", \"best_ask\":\"0.87\"}, {\"asset_id\":\"114356653315647913247200886351065428002113119844334520181865067698979836634569\", \"price\":\"0.1\", \"size\":\"520\", \"side\":\"BUY\", \"hash\":\"f2dd512efea8a9783730fe2d3abb528fb7f398e3\", \"best_bid\":\"0.13\", \"best_ask\":\"0.14\"}], \"timestamp\":\"1789987931214\", \"event_type\":\"price_change\"}","raw_base64":null}
{"received_ms":1789987931248,"monotonic_ns":1019372078713500,"raw":"{\"market\":\"0x28a45972fccdaf0fba75dacc59725521035e177d09dd92174f9f52740bccb025\", \"price_changes\":[{\"asset_id\":\"61819828071723399190623735325323968706432622380635304641786792960078828866875\", \"price\":\"0.83\", \"size\":\"487\", \"side\":\"BUY\", \"hash\":\"8dfa7919bc1e9d1b1a0b43f9c3e504afd3130531\", \"best_bid\":\"0.86\", \"best_ask\":\"0.87\"}, {\"asset_id\":\"114356653315647913247200886351065428002113119844334520181865067698979836634569\", \"price\":\"0.17\", \"size\":\"487\", \"side\":\"SELL\", \"hash\":\"7591440ee39de9b9e0c9e9c5f4d1158772afe724\", \"best_bid\":\"0.13\", \"best_ask\":\"0.14\"}], \"timestamp\":\"1789987931214\", \"event_type\":\"price_change\"}","raw_base64":null}
{"received_ms":1789987931252,"monotonic_ns":1019372082893500,"raw":"{\"market\":\"0x28a45972fccdaf0fba75dacc59725521035e177d09dd92174f9f52740bccb025\", \"price_changes\":[{\"asset_id\":\"61819828071723399190623735325323968706432622380635304641786792960078828866875\", \"price\":\"0.84\", \"size\":\"3258\", \"side\":\"BUY\", \"hash\":\"d9925cd3d5545ba8d684fcc4703252f3f3e5787b\", \"best_bid\":\"0.86\", \"best_ask\":\"0.87\"}, {\"asset_id\":\"114356653315647913247200886351065428002113119844334520181865067698979836634569\", \"price\":\"0.16\", \"size\":\"3258\", \"side\":\"SELL\", \"hash\":\"725036d29ccb03df6a4cd3da11113b3048146739\", \"best_bid\":\"0.13\", \"best_ask\":\"0.14\"}], \"timestamp\":\"1789987931216\", \"event_type\":\"price_change\"}","raw_base64":null}
{"received_ms":1789987931252,"monotonic_ns":1019372082976700,"raw":"{\"market\":\"0x28a45972fccdaf0fba75dacc59725521035e177d09dd92174f9f52740bccb025\", \"price_changes\":[{\"asset_id\":\"61819828071723399190623735325323968706432622380635304641786792960078828866875\", \"price\":\"0.83\", \"size\":\"307\", \"side\":\"BUY\", \"hash\":\"f7ccededad2bc51062965bc4901b0d026c1cf20e\", \"best_bid\":\"0.86\", \"best_ask\":\"0.87\"}, {\"asset_id\":\"114356653315647913247200886351065428002113119844334520181865067698979836634569\", \"price\":\"0.17\", \"size\":\"307\", \"side\":\"SELL\", \"hash\":\"53af01007d70a7b5511fdfabcc93d051ddafa9c9\", \"best_bid\":\"0.13\", \"best_ask\":\"0.14\"}], \"timestamp\":\"1789987931216\", \"event_type\":\"price_change\"}","raw_base64":null}
{"received_ms":1789987931252,"monotonic_ns":1019372083026700,"raw":"{\"market\":\"0x28a45972fccdaf0fba75dacc59725521035e177d09dd92174f9f52740bccb025\", \"price_changes\":[{\"asset_id\":\"114356653315647913247200886351065428002113119844334520181865067698979836634569\", \"price\":\"0.11\", \"size\":\"346.1\", \"side\":\"BUY\", \"hash\":\"449c9d94b56ba19468c6deb5522f172bf82698b4\", \"best_bid\":\"0.13\", \"best_ask\":\"0.14\"}, {\"asset_id\":\"61819828071723399190623735325323968706432622380635304641786792960078828866875\", \"price\":\"0.89\", \"size\":\"346.1\", \"side\":\"SELL\", \"hash\":\"46e37d19d31a619c537e9a6c1125fed5a2486337\", \"best_bid\":\"0.86\", \"best_ask\":\"0.87\"}], \"timestamp\":\"1789987931216\", \"event_type\":\"price_change\"}","raw_base64":null}
{"received_ms":1789987931252,"monotonic_ns":1019372083075900,"raw":"{\"market\":\"0x28a45972fccdaf0fba75dacc59725521035e177d09dd92174f9f52740bccb025\", \"price_changes\":[{\"asset_id\":\"61819828071723399190623735325323968706432622380635304641786792960078828866875\", \"price\":\"0.82\", \"size\":\"717\", \"side\":\"BUY\", \"hash\":\"1a648b1a2f20e1cbb9251ba3633c5b1215a023f0\", \"best_bid\":\"0.86\", \"best_ask\":\"0.87\"}, {\"asset_id\":\"114356653315647913247200886351065428002113119844334520181865067698979836634569\", \"price\":\"0.18\", \"size\":\"717\", \"side\":\"SELL\", \"hash\":\"c2690314659de49c07d50ba61e4afb4c77e8fb68\", \"best_bid\":\"0.13\", \"best_ask\":\"0.14\"}], \"timestamp\":\"1789987931217\", \"event_type\":\"price_change\"}","raw_base64":null}
{"received_ms":1789987931252,"monotonic_ns":1019372083123500,"raw":"{\"market\":\"0x28a45972fccdaf0fba75dacc59725521035e177d09dd92174f9f52740bccb025\", \"price_changes\":[{\"asset_id\":\"61819828071723399190623735325323968706432622380635304641786792960078828866875\", \"price\":\"0.85\", \"size\":\"3037.52\", \"side\":\"BUY\", \"hash\":\"3af56d4f16e5aa8c7d3765500969b052f8a4b4d6\", \"best_bid\":\"0.86\", \"best_ask\":\"0.87\"}, {\"asset_id\":\"114356653315647913247200886351065428002113119844334520181865067698979836634569\", \"price\":\"0.15\", \"size\":\"3037.52\", \"side\":\"SELL\", \"hash\":\"a58d1695e62fcd48359d32bfc07d471d28f4bf2b\", \"best_bid\":\"0.13\", \"best_ask\":\"0.14\"}], \"timestamp\":\"1789987931217\", \"event_type\":\"price_change\"}","raw_base64":null}
{"received_ms":1789987931252,"monotonic_ns":1019372083178400,"raw":"{\"market\":\"0x28a45972fccdaf0fba75dacc59725521035e177d09dd92174f9f52740bccb025\", \"price_changes\":[{\"asset_id\":\"61819828071723399190623735325323968706432622380635304641786792960078828866875\", \"price\":\"0.83\", \"size\":\"270\", \"side\":\"BUY\", \"hash\":\"97e9da7c25d5ded2ec0860107893b5313cb2dfd5\", \"best_bid\":\"0.86\", \"best_ask\":\"0.87\"}, {\"asset_id\":\"114356653315647913247200886351065428002113119844334520181865067698979836634569\", \"price\":\"0.17\", \"size\":\"270\", \"side\":\"SELL\", \"hash\":\"9190b637c4c0e0b8b6b3aa3018f0dc1e7d1c76cc\", \"best_bid\":\"0.13\", \"best_ask\":\"0.14\"}], \"timestamp\":\"1789987931218\", \"event_type\":\"price_change\"}","raw_base64":null}
{"received_ms":1789987931252,"monotonic_ns":1019372083226700,"raw":"{\"market\":\"0x28a45972fccdaf0fba75dacc59725521035e177d09dd92174f9f52740bccb025\", \"price_changes\":[{\"asset_id\":\"61819828071723399190623735325323968706432622380635304641786792960078828866875\", \"price\":\"0.84\", \"size\":\"3253\", \"side\":\"BUY\", \"hash\":\"33835207b172f3cc8111f8a3f22902c8fc802f20\", \"best_bid\":\"0.86\", \"best_ask\":\"0.87\"}, {\"asset_id\":\"114356653315647913247200886351065428002113119844334520181865067698979836634569\", \"price\":\"0.16\", \"size\":\"3253\", \"side\":\"SELL\", \"hash\":\"516d25e9ec0dc9edbd9287cfbd96ca07426b3a86\", \"best_bid\":\"0.13\", \"best_ask\":\"0.14\"}], \"timestamp\":\"1789987931219\", \"event_type\":\"price_change\"}","raw_base64":null}
{"received_ms":1789987931280,"monotonic_ns":1019372110723100,"raw":"{\"market\":\"0x28a45972fccdaf0fba75dacc59725521035e177d09dd92174f9f52740bccb025\", \"price_changes\":[{\"asset_id\":\"61819828071723399190623735325323968706432622380635304641786792960078828866875\", \"price\":\"0.84\", \"size\":\"3243\", \"side\":\"BUY\", \"hash\":\"3adb56766dfc7387ed1f80335f131b49827b3469\", \"best_bid\":\"0.86\", \"best_ask\":\"0.87\"}, {\"asset_id\":\"114356653315647913247200886351065428002113119844334520181865067698979836634569\", \"price\":\"0.16\", \"size\":\"3243\", \"side\":\"SELL\", \"hash\":\"5c91c0caceb78dd9a3cc1f8707bba28028ce1ca0\", \"best_bid\":\"0.13\", \"best_ask\":\"0.14\"}], \"timestamp\":\"1789987931219\", \"event_type\":\"price_change\"}","raw_base64":null}
{"received_ms":1789987931280,"monotonic_ns":1019372110812200,"raw":"{\"market\":\"0x28a45972fccdaf0fba75dacc59725521035e177d09dd92174f9f52740bccb025\", \"price_changes\":[{\"asset_id\":\"61819828071723399190623735325323968706432622380635304641786792960078828866875\", \"price\":\"0.73\", \"size\":\"409\", \"side\":\"BUY\", \"hash\":\"bc9ba9a5fa9ad3dc94d6f2705df5ef2ddf1d0480\", \"best_bid\":\"0.86\", \"best_ask\":\"0.87\"}, {\"asset_id\":\"114356653315647913247200886351065428002113119844334520181865067698979836634569\", \"price\":\"0.27\", \"size\":\"409\", \"side\":\"SELL\", \"hash\":\"4ff6a9a3a4cebcb339dfaf5d3de9979ffcc25dd8\", \"best_bid\":\"0.13\", \"best_ask\":\"0.14\"}], \"timestamp\":\"1789987931219\", \"event_type\":\"price_change\"}","raw_base64":null}
{"received_ms":1789987931280,"monotonic_ns":1019372110871900,"raw":"{\"market\":\"0x28a45972fccdaf0fba75dacc59725521035e177d09dd92174f9f52740bccb025\", \"price_changes\":[{\"asset_id\":\"61819828071723399190623735325323968706432622380635304641786792960078828866875\", \"price\":\"0.9\", \"size\":\"530\", \"side\":\"SELL\", \"hash\":\"77a7e92adf33033650b7b9384244bb96ed3370e4\", \"best_bid\":\"0.86\", \"best_ask\":\"0.87\"}, {\"asset_id\":\"114356653315647913247200886351065428002113119844334520181865067698979836634569\", \"price\":\"0.1\", \"size\":\"530\", \"side\":\"BUY\", \"hash\":\"2a57e1eea5603cc3823af310420e83c1e78f4b99\", \"best_bid\":\"0.13\", \"best_ask\":\"0.14\"}], \"timestamp\":\"1789987931221\", \"event_type\":\"price_change\"}","raw_base64":null}
{"received_ms":1789987931280,"monotonic_ns":1019372110916600,"raw":"{\"market\":\"0x28a45972fccdaf0fba75dacc59725521035e177d09dd92174f9f52740bccb025\", \"price_changes\":[{\"asset_id\":\"61819828071723399190623735325323968706432622380635304641786792960078828866875\", \"price\":\"0.82\", \"size\":\"725\", \"side\":\"BUY\", \"hash\":\"8dec80b3c7aee10a25d62887b71af9e0f26d088c\", \"best_bid\":\"0.86\", \"best_ask\":\"0.87\"}, {\"asset_id\":\"114356653315647913247200886351065428002113119844334520181865067698979836634569\", \"price\":\"0.18\", \"size\":\"725\", \"side\":\"SELL\", \"hash\":\"15f51a0d7b188f8074d2181ea1e66904af6ada2d\", \"best_bid\":\"0.13\", \"best_ask\":\"0.14\"}], \"timestamp\":\"1789987931221\", \"event_type\":\"price_change\"}","raw_base64":null}
{"received_ms":1789987931280,"monotonic_ns":1019372110958400,"raw":"{\"market\":\"0x28a45972fccdaf0fba75dacc59725521035e177d09dd92174f9f52740bccb025\", \"price_changes\":[{\"asset_id\":\"114356653315647913247200886351065428002113119844334520181865067698979836634569\", \"price\":\"0.07\", \"size\":\"8183.71\", \"side\":\"BUY\", \"hash\":\"d57f96f684d07d541caee9d9962bdcd71f3ac163\", \"best_bid\":\"0.13\", \"best_ask\":\"0.14\"}, {\"asset_id\":\"61819828071723399190623735325323968706432622380635304641786792960078828866875\", \"price\":\"0.93\", \"size\":\"8183.71\", \"side\":\"SELL\", \"hash\":\"ac13ca86ca7c52c76cc2ce4e233fb288983fb6f5\", \"best_bid\":\"0.86\", \"best_ask\":\"0.87\"}], \"timestamp\":\"1789987931222\", \"event_type\":\"price_change\"}","raw_base64":null}
