{"received_ms":1789987930119,"monotonic_ns":1019370949795300,"raw":"{\"market\":\"0x28a45972fccdaf0fba75dacc59725521035e177d09dd92174f9f52740bccb025\", \"price_changes\":[{\"asset_id\":\"61819828071723399190623735325323968706432622380635304641786792960078828866875\", \"price\":\"0.73\", \"size\":\"404\", \"side\":\"BUY\", \"hash\":\"d55d65bd4d4b6c03d3b5250e1e3bb5443a1534aa\", \"best_bid\":\"0.86\", \"best_ask\":\"0.87\"}, {\"asset_id\":\"114356653315647913247200886351065428002113119844334520181865067698979836634569\", \"price\":\"0.27\", \"size\":\"404\", \"side\":\"SELL\", \"hash\":\"fa047cb8e2f30cd8ff0100a1129a9dba0e8a694e\", \"best_bid\":\"0.13\", \"best_ask\":\"0.14\"}], \"timestamp\":\"1789987930099\", \"event_type\":\"price_change\"}","raw_base64":null}
{"received_ms":1789987930140,"monotonic_ns":1019370970708900,"raw":"{\"market\":\"0x28a45972fccdaf0fba75dacc59725521035e177d09dd92174f9f52740bccb025\", \"price_changes\":[{\"asset_id\":\"61819828071723399190623735325323968706432622380635304641786792960078828866875\", \"price\":\"0.01\", \"size\":\"1491.91\", \"side\":\"BUY\", \"hash\":\"d55c2c291bc112b5068ec1531bf39309a44887b7\", \"best_bid\":\"0.86\", \"best_ask\":\"0.87\"}, {\"asset_id\":\"114356653315647913247200886351065428002113119844334520181865067698979836634569\", \"price\":\"0.99\", \"size\":\"1491.91\", \"side\":\"SELL\", \"hash\":\"9a7f556d6b76b8c92564efb556a66a81dd165f3b\", \"best_bid\":\"0.13\", \"best_ask\":\"0.14\"}], \"timestamp\":\"1789987930113\", \"event_type\":\"price_change\"}","raw_base64":null}
{"received_ms":1789987930146,"monotonic_ns":1019370976308800,"raw":"{\"market\":\"0x28a45972fccdaf0fba75dacc59725521035e177d09dd92174f9f52740bccb025\", \"price_changes\":[{\"asset_id\":\"114356653315647913247200886351065428002113119844334520181865067698979836634569\", \"price\":\"0.01\", \"size\":\"1699.43\", \"side\":\"BUY\", \"hash\":\"da38d06d1d0c601c5f47aa20c5aee148f30432ee\", \"best_bid\":\"0.13\", \"best_ask\":\"0.14\"}, {\"asset_id\":\"61819828071723399190623735325323968706432622380635304641786792960078828866875\", \"price\":\"0.99\", \"size\":\"1699.43\", \"side\":\"SELL\", \"hash\":\"8e3fd38bd9e691a0548f2386c5b2f6dcdc4615f4\", \"best_bid\":\"0.86\", \"best_ask\":\"0.87\"}], \"timestamp\":\"1789987930121\", \"event_type\":\"price_change\"}","raw_base64":null}
{"received_ms":1789987930147,"monotonic_ns":1019370977431800,"raw":"{\"market\":\"0x28a45972fccdaf0fba75dacc59725521035e177d09dd92174f9f52740bccb025\", \"price_changes\":[{\"asset_id\":\"114356653315647913247200886351065428002113119844334520181865067698979836634569\", \"price\":\"0.01\", \"size\":\"1679.43\", \"side\":\"BUY\", \"hash\":\"95b43827f12d94b49e477055986da2a9d57a37d8\", \"best_bid\":\"0.13\", \"best_ask\":\"0.14\"}, {\"asset_id\":\"61819828071723399190623735325323968706432622380635304641786792960078828866875\", \"price\":\"0.99\", \"size\":\"1679.43\", \"side\":\"SELL\", \"hash\":\"110e4733f1759da87d1e1804125ce5ab9eeb1966\", \"best_bid\":\"0.86\", \"best_ask\":\"0.87\"}], \"timestamp\":\"1789987930125\", \"event_type\":\"price_change\"}","raw_base64":null}
{"received_ms":1789987930168,"monotonic_ns":1019370999097000,"raw":"{\"market\":\"0x28a45972fccdaf0fba75dacc59725521035e177d09dd92174f9f52740bccb025\", \"price_changes\":[{\"asset_id\":\"61819828071723399190623735325323968706432622380635304641786792960078828866875\", \"price\":\"0.77\", \"size\":\"527.49\", \"side\":\"BUY\", \"hash\":\"169279552b49a7c3976848a91d38f8853b874af3\", \"best_bid\":\"0.86\", \"best_ask\":\"0.87\"}, {\"asset_id\":\"114356653315647913247200886351065428002113119844334520181865067698979836634569\", \"price\":\"0.23\", \"size\":\"527.49\", \"side\":\"SELL\", \"hash\":\"e9b38132c396ae1fdaefeb2b3c94ca98eef0a379\", \"best_bid\":\"0.13\", \"best_ask\":\"0.14\"}], \"timestamp\":\"1789987930147\", \"event_type\":\"price_change\"}","raw_base64":null}
{"received_ms":1789987930172,"monotonic_ns":1019371002980700,"raw":"{\"market\":\"0x28a45972fccdaf0fba75dacc59725521035e177d09dd92174f9f52740bccb025\", \"price_changes\":[{\"asset_id\":\"61819828071723399190623735325323968706432622380635304641786792960078828866875\", \"price\":\"0.86\", \"size\":\"1870.97\", \"side\":\"BUY\", \"hash\":\"0fc52ef83dbc2776202f937b1898cdd0e694b13d\", \"best_bid\":\"0.86\", \"best_ask\":\"0.87\"}, {\"asset_id\":\"114356653315647913247200886351065428002113119844334520181865067698979836634569\", \"price\":\"0.14\", \"size\":\"1870.97\", \"side\":\"SELL\", \"hash\":\"fc4e7504d8f4366dac8abf775f4b812a3c33bda0\", \"best_bid\":\"0.13\", \"best_ask\":\"0.14\"}], \"timestamp\":\"1789987930152\", \"event_type\":\"price_change\"}","raw_base64":null}
{"received_ms":1789987930177,"monotonic_ns":1019371007623400,"raw":"{\"market\":\"0x28a45972fccdaf0fba75dacc59725521035e177d09dd92174f9f52740bccb025\", \"price_changes\":[{\"asset_id\":\"114356653315647913247200886351065428002113119844334520181865067698979836634569\", \"price\":\"0.12\", \"size\":\"511\", \"side\":\"BUY\", \"hash\":\"deb9652c68ac20cd3296fc47a66fdb5057cde7e2\", \"best_bid\":\"0.13\", \"best_ask\":\"0.14\"}, {\"asset_id\":\"61819828071723399190623735325323968706432622380635304641786792960078828866875\", \"price\":\"0.88\", \"size\":\"511\", \"side\":\"SELL\", \"hash\":\"01a4bf3a09d59b9fab18481c9987b743f4ac7ebc\", \"best_bid\":\"0.86\", \"best_ask\":\"0.87\"}], \"timestamp\":\"1789987930157\", \"event_type\":\"price_change\"}","raw_base64":null}
{"received_ms":1789987930182,"monotonic_ns":1019371012380300,"raw":"{\"market\":\"0x28a45972fccdaf0fba75dacc59725521035e177d09dd92174f9f52740bccb025\", \"price_changes\":[{\"asset_id\":\"114356653315647913247200886351065428002113119844334520181865067698979836634569\", \"price\":\"0.03\", \"size\":\"4012.57\", \"side\":\"BUY\", \"hash\":\"6db21eea8c846e5d0ba59cb886da6bd41788224a\", \"best_bid\":\"0.13\", \"best_ask\":\"0.14\"}, {\"asset_id\":\"61819828071723399190623735325323968706432622380635304641786792960078828866875\", \"price\":\"0.97\", \"size\":\"4012.57\", \"side\":\"SELL\", \"hash\":\"c5862987287ee6e9a8399445896037f7520e216d\", \"best_bid\":\"0.86\", \"best_ask\":\"0.87\"}], \"timestamp\":\"1789987930162\", \"event_type\":\"price_change\"}","raw_base64":null}
{"received_ms":1789987930191,"monotonic_ns":1019371021733100,"raw":"{\"market\":\"0x28a45972fccdaf0fba75dacc59725521035e177d09dd92174f9f52740bccb025\", \"price_changes\":[{\"asset_id\":\"61819828071723399190623735325323968706432622380635304641786792960078828866875\", \"price\":\"0.75\", \"size\":\"520\", \"side\":\"BUY\", \"hash\":\"176ab9ce7525d23a5e5331d0e5ae115dc24481f4\", \"best_bid\":\"0.86\", \"best_ask\":\"0.87\"}, {\"asset_id\":\"114356653315647913247200886351065428002113119844334520181865067698979836634569\", \"price\":\"0.25\", \"size\":\"520\", \"side\":\"SELL\", \"hash\":\"8e5a4a5cb00485fa945bef3d666ca89e862fba9f\", \"best_bid\":\"0.13\", \"best_ask\":\"0.14\"}], \"timestamp\":\"1789987930171\", \"event_type\":\"price_change\"}","raw_base64":null}
{"received_ms":1789987930196,"monotonic_ns":1019371027241300,"raw":"{\"market\":\"0x28a45972fccdaf0fba75dacc59725521035e177d09dd92174f9f52740bccb025\", \"price_changes\":[{\"asset_id\":\"61819828071723399190623735325323968706432622380635304641786792960078828866875\", \"price\":\"0.77\", \"size\":\"547.49\", \"side\":\"BUY\", \"hash\":\"625fc784fd0ab97cc7f73ee65fa0ec95452f3c6c\", \"best_bid\":\"0.86\", \"best_ask\":\"0.87\"}, {\"asset_id\":\"114356653315647913247200886351065428002113119844334520181865067698979836634569\", \"price\":\"0.23\", \"size\":\"547.49\", \"side\":\"SELL\", \"hash\":\"12fafef4f750d2b5b2f64d2d592aae55c2cf967d\", \"best_bid\":\"0.13\", \"best_ask\":\"0.14\"}], \"timestamp\":\"1789987930177\", \"event_type\":\"price_change\"}","raw_base64":null}
{"received_ms":1789987930206,"monotonic_ns":1019371036632000,"raw":"{\"market\":\"0x28a45972fccdaf0fba75dacc59725521035e177d09dd92174f9f52740bccb025\", \"price_changes\":[{\"asset_id\":\"61819828071723399190623735325323968706432622380635304641786792960078828866875\", \"price\":\"0.77\", \"size\":\"527.49\", \"side\":\"BUY\", \"hash\":\"de5d8e76c2341dd1704070c5c4b4159102c22dc9\", \"best_bid\":\"0.86\", \"best_ask\":\"0.87\"}, {\"asset_id\":\"114356653315647913247200886351065428002113119844334520181865067698979836634569\", \"price\":\"0.23\", \"size\":\"527.49\", \"side\":\"SELL\", \"hash\":\"b4b476942a47fa28babd09a3020c69f1cbb879be\", \"best_bid\":\"0.13\", \"best_ask\":\"0.14\"}], \"timestamp\":\"1789987930185\", \"event_type\":\"price_change\"}","raw_base64":null}
{"received_ms":1789987930234,"monotonic_ns":1019371065002900,"raw":"{\"market\":\"0x28a45972fccdaf0fba75dacc59725521035e177d09dd92174f9f52740bccb025\", \"price_changes\":[{\"asset_id\":\"114356653315647913247200886351065428002113119844334520181865067698979836634569\", \"price\":\"0.01\", \"size\":\"1674.43\", \"side\":\"BUY\", \"hash\":\"72334fec6cc6c01560fc0c2931fbd2447aa3f4b4\", \"best_bid\":\"0.13\", \"best_ask\":\"0.14\"}, {\"asset_id\":\"61819828071723399190623735325323968706432622380635304641786792960078828866875\", \"price\":\"0.99\", \"size\":\"1674.43\", \"side\":\"SELL\", \"hash\":\"ec5926a9b70437e34d3b1408c5311df687da2a39\", \"best_bid\":\"0.86\", \"best_ask\":\"0.87\"}], \"timestamp\":\"1789987930200\", \"event_type\":\"price_change\"}","raw_base64":null}
{"received_ms":1789987930234,"monotonic_ns":1019371065082100,"raw":"{\"market\":\"0x28a45972fccdaf0fba75dacc59725521035e177d09dd92174f9f52740bccb025\", \"price_changes\":[{\"asset_id\":\"61819828071723399190623735325323968706432622380635304641786792960078828866875\", \"price\":\"0.86\", \"size\":\"3328.97\", \"side\":\"BUY\", \"hash\":\"f2266548a88428a5179a69b2ac9092d7ef66b9a0\", \"best_bid\":\"0.86\", \"best_ask\":\"0.87\"}, {\"asset_id\":\"114356653315647913247200886351065428002113119844334520181865067698979836634569\", \"price\":\"0.14\", \"size\":\"3328.97\", \"side\":\"SELL\", \"hash\":\"c088b6252ea5964bc4ee7d6a750b5b6c90e5ae8f\", \"best_bid\":\"0.13\", \"best_ask\":\"0.14\"}], \"timestamp\":\"1789987930201\", \"event_type\":\"price_change\"}","raw_base64":null}
{"received_ms":1789987930234,"monotonic_ns":1019371065139600,"raw":"{\"market\":\"0x28a45972fccdaf0fba75dacc59725521035e177d09dd92174f9f52740bccb025\", \"price_changes\":[{\"asset_id\":\"114356653315647913247200886351065428002113119844334520181865067698979836634569\", \"price\":\"0.01\", \"size\":\"1669.43\", \"side\":\"BUY\", \"hash\":\"0f3d6b8484fb14993991eca0ea53365e9e3e0338\", \"best_bid\":\"0.13\", \"best_ask\":\"0.14\"}, {\"asset_id\":\"61819828071723399190623735325323968706432622380635304641786792960078828866875\", \"price\":\"0.99\", \"size\":\"1669.43\", \"side\":\"SELL\", \"hash\":\"a42b1eca353a1e13900f7d395e075b45e4f0df61\", \"best_bid\":\"0.86\", \"best_ask\":\"0.87\"}], \"timestamp\":\"1789987930206\", \"event_type\":\"price_change\"}","raw_base64":null}
{"received_ms":1789987930234,"monotonic_ns":1019371065198400,"raw":"{\"market\":\"0x28a45972fccdaf0fba75dacc59725521035e177d09dd92174f9f52740bccb025\", \"price_changes\":[{\"asset_id\":\"61819828071723399190623735325323968706432622380635304641786792960078828866875\", \"price\":\"0.73\", \"size\":\"504\", \"side\":\"BUY\", \"hash\":\"a8a13b8ab0f114bba43203094ca509af77ac6ad2\", \"best_bid\":\"0.86\", \"best_ask\":\"0.87\"}, {\"asset_id\":\"114356653315647913247200886351065428002113119844334520181865067698979836634569\", \"price\":\"0.27\", \"size\":\"504\", \"side\":\"SELL\", \"hash\":\"d74db32f46e79c590183b39afdf2e5c1f5fb7bf5\", \"best_bid\":\"0.13\", \"best_ask\":\"0.14\"}], \"timestamp\":\"1789987930213\", \"event_type\":\"price_change\"}","raw_base64":null}
{"received_ms":1789987930250,"monotonic_ns":1019371081232700,"raw":"{\"market\":\"0x28a45972fccdaf0fba75dacc59725521035e177d09dd92174f9f52740bccb025\", \"price_changes\":[{\"asset_id\":\"61819828071723399190623735325323968706432622380635304641786792960078828866875\", \"price\":\"0.73\", \"size\":\"404\", \"side\":\"BUY\", \"hash\":\"77b99f0e6e996741969828cb960f7eabf661a0d0\", \"best_bid\":\"0.86\", \"best_ask\":\"0.87\"}, {\"asset_id\":\"114356653315647913247200886351065428002113119844334520181865067698979836634569\", \"price\":\"0.27\", \"size\":\"404\", \"side\":\"SELL\", \"hash\":\"3bf869a9c4e45d90a886bdef704ad009e1130989\", \"best_bid\":\"0.13\", \"best_ask\":\"0.14\"}], \"timestamp\":\"1789987930225\", \"event_type\":\"price_change\"}","raw_base64":null}
{"received_ms":1789987930264,"monotonic_ns":1019371094834000,"raw":"{\"market\":\"0x28a45972fccdaf0fba75dacc59725521035e177d09dd92174f9f52740bccb025\", \"price_changes\":[{\"asset_id\":\"61819828071723399190623735325323968706432622380635304641786792960078828866875\", \"price\":\"0.94\", \"size\":\"5324.67\", \"side\":\"SELL\", \"hash\":\"d779c15e06c76160f8679b6921afb67f09eb5e0f\", \"best_bid\":\"0.86\", \"best_ask\":\"0.87\"}, {\"asset_id\":\"114356653315647913247200886351065428002113119844334520181865067698979836634569\", \"price\":\"0.06\", \"size\":\"5324.67\", \"side\":\"BUY\", \"hash\":\"05e51f3a563fa2d178a595c2538945eb8c743ae0\", \"best_bid\":\"0.13\", \"best_ask\":\"0.14\"}], \"timestamp\":\"1789987930230\", \"event_type\":\"price_change\"}","raw_base64":null}
{"received_ms":1789987930264,"monotonic_ns":1019371094886200,"raw":"{\"market\":\"0x28a45972fccdaf0fba75dacc59725521035e177d09dd92174f9f52740bccb025\", \"price_changes\":[{\"asset_id\":\"114356653315647913247200886351065428002113119844334520181865067698979836634569\", \"price\":\"0.07\", \"size\":\"6908.71\", \"side\":\"BUY\", \"hash\":\"ebbcc2af4a4867a6c3b69236a7090dcd0fe1e137\", \"best_bid\":\"0.13\", \"best_ask\":\"0.14\"}, {\"asset_id\":\"61819828071723399190623735325323968706432622380635304641786792960078828866875\", \"price\":\"0.93\", \"size\":\"6908.71\", \"side\":\"SELL\", \"hash\":\"ce59ff58012ad6009dff6240e6d35614281df1fb\", \"best_bid\":\"0.86\", \"best_ask\":\"0.87\"}], \"timestamp\":\"1789987930234\", \"event_type\":\"price_change\"}","raw_base64":null}
{"received_ms":1789987930264,"monotonic_ns":1019371094933800,"raw":"{\"market\":\"0x28a45972fccdaf0fba75dacc59725521035e177d09dd92174f9f52740bccb025\", \"price_changes\":[{\"asset_id\":\"61819828071723399190623735325323968706432622380635304641786792960078828866875\", \"price\":\"0.86\", \"size\":\"1870.97\", \"side\":\"BUY\", \"hash\":\"8ad5f3704bd9ad84f50a5f0400d7f7eb9f60448b\", \"best_bid\":\"0.86\", \"best_ask\":\"0.87\"}, {\"asset_id\":\"114356653315647913247200886351065428002113119844334520181865067698979836634569\", \"price\":\"0.14\", \"size\":\"1870.97\", \"side\":\"SELL\", \"hash\":\"b7528ceb600b1c27d2e3174528aab3ac52b4469f\", \"best_bid\":\"0.13\", \"best_ask\":\"0.14\"}], \"timestamp\":\"1789987930234\", \"event_type\":\"price_change\"}","raw_base64":null}
{"received_ms":1789987930264,"monotonic_ns":1019371094979500,"raw":"{\"market\":\"0x28a45972fccdaf0fba75dacc59725521035e177d09dd92174f9f52740bccb025\", \"price_changes\":[{\"asset_id\":\"114356653315647913247200886351065428002113119844334520181865067698979836634569\", \"price\":\"0.07\", \"size\":\"6858.71\", \"side\":\"BUY\", \"hash\":\"2da694e96f374d4bdad4843cfb84e421e3cb0474\", \"best_bid\":\"0.13\", \"best_ask\":\"0.14\"}, {\"asset_id\":\"61819828071723399190623735325323968706432622380635304641786792960078828866875\", \"price\":\"0.93\", \"size\":\"6858.71\", \"side\":\"SELL\", \"hash\":\"2b55ee2cb469605f5deb3ab385950bf76ca9ab8e\", \"best_bid\":\"0.86\", \"best_ask\":\"0.87\"}], \"timestamp\":\"1789987930238\", \"event_type\":\"price_change\"}","raw_base64":null}
{"received_ms":1789987930275,"monotonic_ns":1019371105528100,"raw":"{\"market\":\"0x28a45972fccdaf0fba75dacc59725521035e177d09dd92174f9f52740bccb025\", \"price_changes\":[{\"asset_id\":\"61819828071723399190623735325323968706432622380635304641786792960078828866875\", \"price\":\"0.86\", \"size\":\"1852.97\", \"side\":\"BUY\", \"hash\":\"b7e1ddbea144373bf1c3057b0de14c0deff6cdbe\", \"best_bid\":\"0.86\", \"best_ask\":\"0.87\"}, {\"asset_id\":\"114356653315647913247200886351065428002113119844334520181865067698979836634569\", \"price\":\"0.14\", \"size\":\"1852.97\", \"side\":\"SELL\", \"hash\":\"bf0d3e52f43503ace9b3af049f2ad75b1f0d48fe\", \"best_bid\":\"0.13\", \"best_ask\":\"0.14\"}], \"timestamp\":\"1789987930254\", \"event_type\":\"price_change\"}","raw_base64":null}
{"received_ms":1789987930276,"monotonic_ns":1019371106450500,"raw":"{\"market\":\"0x28a45972fccdaf0fba75dacc59725521035e177d09dd92174f9f52740bccb025\", \"asset_id\":\"114356653315647913247200886351065428002113119844334520181865067698979836634569\", \"bids\":[{\"price\":\"0.01\", \"size\":\"1669.43\"}, {\"price\":\"0.02\", \"size\":\"574.82\"}, {\"price\":\"0.03\", \"size\":\"4012.57\"}, {\"price\":\"0.04\", \"size\":\"625.48\"}, {\"price\":\"0.05\", \"size\":\"5628\"}, {\"price\":\"0.06\", \"size\":\"5324.67\"}, {\"price\":\"0.07\", \"size\":\"6858.71\"}, {\"price\":\"0.08\", \"size\":\"714.5\"}, {\"price\":\"0.09\", \"size\":\"618.12\"}, {\"price\":\"0.1\", \"size\":\"520\"}, {\"price\":\"0.11\", \"size\":\"138.1\"}, {\"price\":\"0.12\", \"size\":\"511\"}, {\"price\":\"0.13\", \"size\":\"265\"}], \"asks\":[{\"price\":\"0.99\", \"size\":\"1491.91\"}, {\"price\":\"0.98\", \"size\":\"385.35\"}, {\"price\":\"0.97\", \"size\":\"1270.08\"}, {\"price\":\"0.96\", \"size\":\"165.3\"}, {\"price\":\"0.95\", \"size\":\"237.01\"}, {\"price\":\"0.94\", \"size\":\"85.67\"}, {\"price\":\"0.93\", \"size\":\"159.29\"}, {\"price\":\"0.92\", \"size\":\"81.51\"}, {\"price\":\"0.91\", \"size\":\"252.12\"}, {\"price\":\"0.9\", \"size\":\"99.01\"}, {\"price\":\"0.89\", \"size\":\"129.1\"}, {\"price\":\"0.88\", \"size\":\"67.34\"}, {\"price\":\"0.87\", \"size\":\"123.7\"}, {\"price\":\"0.86\", \"size\":\"66.15\"}, {\"price\":\"0.85\", \"size\":\"197.39\"}, {\"price\":\"0.84\", \"size\":\"65.25\"}, {\"price\":\"0.83\", \"size\":\"115.89\"}, {\"price\":\"0.82\", \"size\":\"64.56\"}, {\"price\":\"0.81\", \"size\":\"113.27\"}, {\"price\":\"0.8\", \"size\":\"74.81\"}, {\"price\":\"0.79\", \"size\":\"112\"}, {\"price\":\"0.78\", \"size\":\"64\"}, {\"price\":\"0.77\", \"size\":\"111\"}, {\"price\":\"0.76\", \"size\":\"64\"}, {\"price\":\"0.75\", \"size\":\"110\"}, {\"price\":\"0.74\", \"size\":\"250\"}, {\"price\":\"0.73\", \"size\":\"289\"}, {\"price\":\"0.72\", \"size\":\"244\"}, {\"price\":\"0.71\", \"size\":\"297\"}, {\"price\":\"0.7\", \"size\":\"281\"}, {\"price\":\"0.69\", \"size\":\"297\"}, {\"price\":\"0.68\", \"size\":\"267\"}, {\"price\":\"0.67\", \"size\":\"310\"}, {\"price\":\"0.66\", \"size\":\"272.64\"}, {\"price\":\"0.65\", \"size\":\"297\"}, {\"price\":\"0.64\", \"size\":\"285.33\"}, {\"price\":\"0.63\", \"size\":\"297\"}, {\"price\":\"0.62\", \"size\":\"272.05\"}, {\"price\":\"0.61\", \"size\":\"310\"}, {\"price\":\"0.6\", \"size\":\"1067\"}, {\"price\":\"0.59\", \"size\":\"297\"}, {\"price\":\"0.58\", \"size\":\"279\"}, {\"price\":\"0.57\", \"size\":\"297\"}, {\"price\":\"0.56\", \"size\":\"267\"}, {\"price\":\"0.55\", \"size\":\"297\"}, {\"price\":\"0.54\", \"size\":\"267\"}, {\"price\":\"0.53\", \"size\":\"302\"}, {\"price\":\"0.52\", \"size\":\"267\"}, {\"price\":\"0.51\", \"size\":\"297\"}, {\"price\":\"0.5\", \"size\":\"267\"}, {\"price\":\"0.49\", \"size\":\"297\"}, {\"price\":\"0.48\", \"size\":\"267\"}, {\"price\":\"0.47\", \"size\":\"297\"}, {\"price\":\"0.46\", \"size\":\"267\"}, {\"price\":\"0.45\", \"size\":\"297\"}, {\"price\":\"0.44\", \"size\":\"267\"}, {\"price\":\"0.43\", \"size\":\"309\"}, {\"price\":\"0.42\", \"size\":\"267\"}, {\"price\":\"0.41\", \"size\":\"297\"}, {\"price\":\"0.4\", \"size\":\"279\"}, {\"price\":\"0.39\", \"size\":\"297\"}, {\"price\":\"0.38\", \"size\":\"267\"}, {\"price\":\"0.37\", \"size\":\"309\"}, {\"price\":\"0.36\", \"size\":\"267\"}, {\"price\":\"0.35\", \"size\":\"297\"}, {\"price\":\"0.34\", \"size\":\"267\"}, {\"price\":\"0.33\", \"size\":\"322\"}, {\"price\":\"0.32\", \"size\":\"292\"}, {\"price\":\"0.31\", \"size\":\"322\"}, {\"price\":\"0.3\", \"size\":\"292\"}, {\"price\":\"0.29\", \"size\":\"403\"}, {\"price\":\"0.28\", \"size\":\"438.8\"}, {\"price\":\"0.27\", \"size\":\"404\"}, {\"price\":\"0.26\", \"size\":\"455.53\"}, {\"price\":\"0.25\", \"size\":\"520\"}, {\"price\":\"0.24\", \"size\":\"424.91\"}, {\"price\":\"0.23\", \"size\":\"527.49\"}, {\"price\":\"0.22\", \"size\":\"433.82\"}, {\"price\":\"0.21\", \"size\":\"427\"}, {\"price\":\"0.2\", \"size\":\"562\"}, {\"price\":\"0.19\", \"size\":\"590\"}, {\"price\":\"0.18\", \"size\":\"753\"}, {\"price\":\"0.17\", \"size\":\"494\"}, {\"price\":\"0.16\", \"size\":\"3179\"}, {\"price\":\"0.15\", \"size\":\"4777.35\"}, {\"price\":\"0.14\", \"size\":\"1852.97\"}], \"hash\":\"bf0d3e52f43503ace9b3af049f2ad75b1f0d48fe\", \"timestamp\":\"1789987930254\", \"event_type\":\"book\"}","raw_base64":null}
{"received_ms":1789987930277,"monotonic_ns":1019371107523600,"raw":"{\"market\":\"0x28a45972fccdaf0fba75dacc59725521035e177d09dd92174f9f52740bccb025\", \"asset_id\":\"61819828071723399190623735325323968706432622380635304641786792960078828866875\", \"bids\":[{\"price\":\"0.01\", \"size\":\"1491.91\"}, {\"price\":\"0.02\", \"size\":\"385.35\"}, {\"price\":\"0.03\", \"size\":\"1270.08\"}, {\"price\":\"0.04\", \"size\":\"165.3\"}, {\"price\":\"0.05\", \"size\":\"237.01\"}, {\"price\":\"0.06\", \"size\":\"85.67\"}, {\"price\":\"0.07\", \"size\":\"159.29\"}, {\"price\":\"0.08\", \"size\":\"81.51\"}, {\"price\":\"0.09\", \"size\":\"252.12\"}, {\"price\":\"0.1\", \"size\":\"99.01\"}, {\"price\":\"0.11\", \"size\":\"129.1\"}, {\"price\":\"0.12\", \"size\":\"67.34\"}, {\"price\":\"0.13\", \"size\":\"123.7\"}, {\"price\":\"0.14\", \"size\":\"66.15\"}, {\"price\":\"0.15\", \"size\":\"197.39\"}, {\"price\":\"0.16\", \"size\":\"65.25\"}, {\"price\":\"0.17\", \"size\":\"115.89\"}, {\"price\":\"0.18\", \"size\":\"64.56\"}, {\"price\":\"0.19\", \"size\":\"113.27\"}, {\"price\":\"0.2\", \"size\":\"74.81\"}, {\"price\":\"0.21\", \"size\":\"112\"}, {\"price\":\"0.22\", \"size\":\"64\"}, {\"price\":\"0.23\", \"size\":\"111\"}, {\"price\":\"0.24\", \"size\":\"64\"}, {\"price\":\"0.25\", \"size\":\"110\"}, {\"price\":\"0.26\", \"size\":\"250\"}, {\"price\":\"0.27\", \"size\":\"289\"}, {\"price\":\"0.28\", \"size\":\"244\"}, {\"price\":\"0.29\", \"size\":\"297\"}, {\"price\":\"0.3\", \"size\":\"281\"}, {\"price\":\"0.31\", \"size\":\"297\"}, {\"price\":\"0.32\", \"size\":\"267\"}, {\"price\":\"0.33\", \"size\":\"310\"}, {\"price\":\"0.34\", \"size\":\"272.64\"}, {\"price\":\"0.35\", \"size\":\"297\"}, {\"price\":\"0.36\", \"size\":\"285.33\"}, {\"price\":\"0.37\", \"size\":\"297\"}, {\"price\":\"0.38\", \"size\":\"272.05\"}, {\"price\":\"0.39\", \"size\":\"310\"}, {\"price\":\"0.4\", \"size\":\"1067\"}, {\"price\":\"0.41\", \"size\":\"297\"}, {\"price\":\"0.42\", \"size\":\"279\"}, {\"price\":\"0.43\", \"size\":\"297\"}, {\"price\":\"0.44\", \"size\":\"267\"}, {\"price\":\"0.45\", \"size\":\"297\"}, {\"price\":\"0.46\", \"size\":\"267\"}, {\"price\":\"0.47\", \"size\":\"302\"}, {\"price\":\"0.48\", \"size\":\"267\"}, {\"price\":\"0.49\", \"size\":\"297\"}, {\"price\":\"0.5\", \"size\":\"267\"}, {\"price\":\"0.51\", \"size\":\"297\"}, {\"price\":\"0.52\", \"size\":\"267\"}, {\"price\":\"0.53\", \"size\":\"297\"}, {\"price\":\"0.54\", \"size\":\"267\"}, {\"price\":\"0.55\", \"size\":\"297\"}, {\"price\":\"0.56\", \"size\":\"267\"}, {\"price\":\"0.57\", \"size\":\"309\"}, {\"price\":\"0.58\", \"size\":\"267\"}, {\"price\":\"0.59\", \"size\":\"297\"}, {\"price\":\"0.6\", \"size\":\"279\"}, {\"price\":\"0.61\", \"size\":\"297\"}, {\"price\":\"0.62\", \"size\":\"267\"}, {\"price\":\"0.63\", \"size\":\"309\"}, {\"price\":\"0.64\", \"size\":\"267\"}, {\"price\":\"0.65\", \"size\":\"297\"}, {\"price\":\"0.66\", \"size\":\"267\"}, {\"price\":\"0.67\", \"size\":\"322\"}, {\"price\":\"0.68\", \"size\":\"292\"}, {\"price\":\"0.69\", \"size\":\"322\"}, {\"price\":\"0.7\", \"size\":\"292\"}, {\"price\":\"0.71\", \"size\":\"403\"}, {\"price\":\"0.72\", \"size\":\"438.8\"}, {\"price\":\"0.73\", \"size\":\"404\"}, {\"price\":\"0.74\", \"size\":\"455.53\"}, {\"price\":\"0.75\", \"size\":\"520\"}, {\"price\":\"0.76\", \"size\":\"424.91\"}, {\"price\":\"0.77\", \"size\":\"527.49\"}, {\"price\":\"0.78\", \"size\":\"433.82\"}, {\"price\":\"0.79\", \"size\":\"427\"}, {\"price\":\"0.8\", \"size\":\"562\"}, {\"price\":\"0.81\", \"size\":\"590\"}, {\"price\":\"0.82\", \"size\":\"753\"}, {\"price\":\"0.83\", \"size\":\"494\"}, {\"price\":\"0.84\", \"size\":\"3179\"}, {\"price\":\"0.85\", \"size\":\"4777.35\"}, {\"price\":\"0.86\", \"size\":\"1852.97\"}], \"asks\":[{\"price\":\"0.99\", \"size\":\"1669.43\"}, {\"price\":\"0.98\", \"size\":\"574.82\"}, {\"price\":\"0.97\", \"size\":\"4012.57\"}, {\"price\":\"0.96\", \"size\":\"625.48\"}, {\"price\":\"0.95\", \"size\":\"5628\"}, {\"price\":\"0.94\", \"size\":\"5324.67\"}, {\"price\":\"0.93\", \"size\":\"6858.71\"}, {\"price\":\"0.92\", \"size\":\"714.5\"}, {\"price\":\"0.91\", \"size\":\"618.12\"}, {\"price\":\"0.9\", \"size\":\"520\"}, {\"price\":\"0.89\", \"size\":\"138.1\"}, {\"price\":\"0.88\", \"size\":\"511\"}, {\"price\":\"0.87\", \"size\":\"265\"}], \"hash\":\"b7e1ddbea144373bf1c3057b0de14c0deff6cdbe\", \"timestamp\":\"1789987930254\", \"event_type\":\"book\"}","raw_base64":null}
{"received_ms":1789987930293,"monotonic_ns":1019371123935800,"raw":"{\"market\":\"0x28a45972fccdaf0fba75dacc59725521035e177d09dd92174f9f52740bccb025\", \"price_changes\":[{\"asset_id\":\"61819828071723399190623735325323968706432622380635304641786792960078828866875\", \"price\":\"0.77\", \"size\":\"587.49\", \"side\":\"BUY\", \"hash\":\"2d49c833e95b680eb48083250d77d9a19f0ea0a8\", \"best_bid\":\"0.86\", \"best_ask\":\"0.87\"}, {\"asset_id\":\"114356653315647913247200886351065428002113119844334520181865067698979836634569\", \"price\":\"0.23\", \"size\":\"587.49\", \"side\":\"SELL\", \"hash\":\"1c65f0333118d66adbadbc87c2a1743a3881f76f\", \"best_bid\":\"0.13\", \"best_ask\":\"0.14\"}], \"timestamp\":\"1789987930259\", \"event_type\":\"price_change\"}","raw_base64":null}
{"received_ms":1789987930293,"monotonic_ns":1019371124041500,"raw":"{\"market\":\"0x28a45972fccdaf0fba75dacc59725521035e177d09dd92174f9f52740bccb025\", \"price_changes\":[{\"asset_id\":\"61819828071723399190623735325323968706432622380635304641786792960078828866875\", \"price\":\"0.77\", \"size\":\"527.49\", \"side\":\"BUY\", \"hash\":\"2768298403d12a0c95ca93482965d8eb9c5b7185\", \"best_bid\":\"0.86\", \"best_ask\":\"0.87\"}, {\"asset_id\":\"114356653315647913247200886351065428002113119844334520181865067698979836634569\", \"price\":\"0.23\", \"size\":\"527.49\", \"side\":\"SELL\", \"hash\":\"dfe55a14ab7d8e069964375198933d2aa16b7c78\", \"best_bid\":\"0.13\", \"best_ask\":\"0.14\"}], \"timestamp\":\"1789987930259\", \"event_type\":\"price_change\"}","raw_base64":null}
{"received_ms":1789987930293,"monotonic_ns":1019371124082700,"raw":"{\"market\":\"0x28a45972fccdaf0fba75dacc59725521035e177d09dd92174f9f52740bccb025\", \"price_changes\":[{\"asset_id\":\"114356653315647913247200886351065428002113119844334520181865067698979836634569\", \"price\":\"0.07\", \"size\":\"7820.71\", \"side\":\"BUY\", \"hash\":\"d5468b2a0fdc8c0f707fae413f1dbafb7517d23f\", \"best_bid\":\"0.13\", \"best_ask\":\"0.14\"}, {\"asset_id\":\"61819828071723399190623735325323968706432622380635304641786792960078828866875\", \"price\":\"0.93\", \"size\":\"7820.71\", \"side\":\"SELL\", \"hash\":\"f8fb213d28f39df33e371b40c770da2623738370\", \"best_bid\":\"0.86\", \"best_ask\":\"0.87\"}], \"timestamp\":\"1789987930267\", \"event_type\":\"price_change\"}","raw_base64":null}
{"received_ms":1789987930310,"monotonic_ns":1019371140776300,"raw":"{\"market\":\"0x28a45972fccdaf0fba75dacc59725521035e177d09dd92174f9f52740bccb025\", \"asset_id\":\"114356653315647913247200886351065428002113119844334520181865067698979836634569\", \"price\":\"0.14\", \"size\":\"18\", \"fee_rate_bps\":\"0\", \"side\":\"BUY\", \"timestamp\":\"1789987930283\", \"event_type\":\"last_trade_price\", \"transaction_hash\":\"0xd2c9175c22d358c846ebc3f6a15c24a90289711cce62b3df2b2040f528fcf391\"}","raw_base64":null}
{"received_ms":1789987930329,"monotonic_ns":1019371159528100,"raw":"{\"market\":\"0x28a45972fccdaf0fba75dacc59725521035e177d09dd92174f9f52740bccb025\", \"price_changes\":[{\"asset_id\":\"61819828071723399190623735325323968706432622380635304641786792960078828866875\", \"price\":\"0.73\", \"size\":\"504\", \"side\":\"BUY\", \"hash\":\"8d8c3032036801330c2435494a0eff966df14545\", \"best_bid\":\"0.86\", \"best_ask\":\"0.87\"}, {\"asset_id\":\"114356653315647913247200886351065428002113119844334520181865067698979836634569\", \"price\":\"0.27\", \"size\":\"504\", \"side\":\"SELL\", \"hash\":\"834c64e38895c2f99f7d7b10c0a598f0bdb765ee\", \"best_bid\":\"0.13\", \"best_ask\":\"0.14\"}], \"timestamp\":\"1789987930293\", \"event_type\":\"price_change\"}","raw_base64":null}
{"received_ms":1789987930329,"monotonic_ns":1019371159610300,"raw":"{\"market\":\"0x28a45972fccdaf0fba75dacc59725521035e177d09dd92174f9f52740bccb025\", \"price_changes\":[{\"asset_id\":\"61819828071723399190623735325323968706432622380635304641786792960078828866875\", \"price\":\"0.73\", \"size\":\"404\", \"side\":\"BUY\", \"hash\":\"5cdec7d481572e3b74b4cb9ce9b9193a536b9f2a\", \"best_bid\":\"0.86\", \"best_ask\":\"0.87\"}, {\"asset_id\":\"114356653315647913247200886351065428002113119844334520181865067698979836634569\", \"price\":\"0.27\", \"size\":\"404\", \"side\":\"SELL\", \"hash\":\"fef6d5f34b7b457373698e19c74097f80c84199c\", \"best_bid\":\"0.13\", \"best_ask\":\"0.14\"}], \"timestamp\":\"1789987930296\", \"event_type\":\"price_change\"}","raw_base64":null}
{"received_ms":1789987930329,"monotonic_ns":1019371159658200,"raw":"{\"market\":\"0x28a45972fccdaf0fba75dacc59725521035e177d09dd92174f9f52740bccb025\", \"price_changes\":[{\"asset_id\":\"61819828071723399190623735325323968706432622380635304641786792960078828866875\", \"price\":\"0.86\", \"size\":\"3309.97\", \"side\":\"BUY\", \"hash\":\"b384a52dd5c8b229f3c4130f007ae6797ab0f66a\", \"best_bid\":\"0.86\", \"best_ask\":\"0.87\"}, {\"asset_id\":\"114356653315647913247200886351065428002113119844334520181865067698979836634569\", \"price\":\"0.14\", \"size\":\"3309.97\", \"side\":\"SELL\", \"hash\":\"cce1affc035554b0a10ea71388c12b2640dff440\", \"best_bid\":\"0.13\", \"best_ask\":\"0.14\"}], \"timestamp\":\"1789987930301\", \"event_type\":\"price_change\"}","raw_base64":null}
{"received_ms":1789987930333,"monotonic_ns":1019371163702600,"raw":"{\"market\":\"0x28a45972fccdaf0fba75dacc59725521035e177d09dd92174f9f52740bccb025\", \"price_changes\":[{\"asset_id\":\"114356653315647913247200886351065428002113119844334520181865067698979836634569\", \"price\":\"0.04\", \"size\":\"630.48\", \"side\":\"BUY\", \"hash\":\"0edb0aeb4da4c6829db18903ff2b512c3743b259\", \"best_bid\":\"0.13\", \"best_ask\":\"0.14\"}, {\"asset_id\":\"61819828071723399190623735325323968706432622380635304641786792960078828866875\", \"price\":\"0.96\", \"size\":\"630.48\", \"side\":\"SELL\", \"hash\":\"de521d0bc2de598c980fcaa5bbe3bfff17673abd\", \"best_bid\":\"0.86\", \"best_ask\":\"0.87\"}], \"timestamp\":\"1789987930310\", \"event_type\":\"price_change\"}","raw_base64":null}
{"received_ms":1789987930347,"monotonic_ns":1019371177304100,"raw":"{\"market\":\"0x28a45972fccdaf0fba75dacc59725521035e177d09dd92174f9f52740bccb025\", \"price_changes\":[{\"asset_id\":\"61819828071723399190623735325323968706432622380635304641786792960078828866875\", \"price\":\"0.77\", \"size\":\"587.49\", \"side\":\"BUY\", \"hash\":\"8c9325ca1d21b59152b28e1dba025e0a7c4ab760\", \"best_bid\":\"0.86\", \"best_ask\":\"0.87\"}, {\"asset_id\":\"114356653315647913247200886351065428002113119844334520181865067698979836634569\", \"price\":\"0.23\", \"size\":\"587.49\", \"side\":\"SELL\", \"hash\":\"1b9613fb65ec272272451cde7f19df45bc4c64d9\", \"best_bid\":\"0.13\", \"best_ask\":\"0.14\"}], \"timestamp\":\"1789987930327\", \"event_type\":\"price_change\"}","raw_base64":null}
{"received_ms":1789987930347,"monotonic_ns":1019371178105900,"raw":"{\"market\":\"0x28a45972fccdaf0fba75dacc59725521035e177d09dd92174f9f52740bccb025\", \"price_changes\":[{\"asset_id\":\"61819828071723399190623735325323968706432622380635304641786792960078828866875\", \"price\":\"0.79\", \"size\":\"467\", \"side\":\"BUY\", \"hash\":\"6abc6b823d05f1dfd03c7b06dfd5c62c8a4ec064\", \"best_bid\":\"0.86\", \"best_ask\":\"0.87\"}, {\"asset_id\":\"114356653315647913247200886351065428002113119844334520181865067698979836634569\", \"price\":\"0.21\", \"size\":\"467\", \"side\":\"SELL\", \"hash\":\"721d97fc95ef5fbf623d98729beb37e8dcacce52\", \"best_bid\":\"0.13\", \"best_ask\":\"0.14\"}], \"timestamp\":\"1789987930327\", \"event_type\":\"price_change\"}","raw_base64":null}
{"received_ms":1789987930350,"monotonic_ns":1019371180266900,"raw":"{\"market\":\"0x28a45972fccdaf0fba75dacc59725521035e177d09dd92174f9f52740bccb025\", \"price_changes\":[{\"asset_id\":\"61819828071723399190623735325323968706432622380635304641786792960078828866875\", \"price\":\"0.77\", \"size\":\"527.49\", \"side\":\"BUY\", \"hash\":\"4768d9c8095263664a966761d83eabe993c5bed4\", \"best_bid\":\"0.86\", \"best_ask\":\"0.87\"}, {\"asset_id\":\"114356653315647913247200886351065428002113119844334520181865067698979836634569\", \"price\":\"0.23\", \"size\":\"527.49\", \"side\":\"SELL\", \"hash\":\"d5e4c350f9c3cb776feb0248f9b075a144773a80\", \"best_bid\":\"0.13\", \"best_ask\":\"0.14\"}], \"timestamp\":\"1789987930329\", \"event_type\":\"price_change\"}","raw_base64":null}
{"received_ms":1789987930350,"monotonic_ns":1019371181033600,"raw":"{\"market\":\"0x28a45972fccdaf0fba75dacc59725521035e177d09dd92174f9f52740bccb025\", \"price_changes\":[{\"asset_id\":\"61819828071723399190623735325323968706432622380635304641786792960078828866875\", \"price\":\"0.79\", \"size\":\"427\", \"side\":\"BUY\", \"hash\":\"4768d9c8095263664a966761d83eabe993c5bed4\", \"best_bid\":\"0.86\", \"best_ask\":\"0.87\"}, {\"asset_id\":\"114356653315647913247200886351065428002113119844334520181865067698979836634569\", \"price\":\"0.21\", \"size\":\"427\", \"side\":\"SELL\", \"hash\":\"d5e4c350f9c3cb776feb0248f9b075a144773a80\", \"best_bid\":\"0.13\", \"best_ask\":\"0.14\"}], \"timestamp\":\"1789987930329\", \"event_type\":\"price_change\"}","raw_base64":null}
{"received_ms":1789987930369,"monotonic_ns":1019371200178100,"raw":"{\"market\":\"0x28a45972fccdaf0fba75dacc59725521035e177d09dd92174f9f52740bccb025\", \"price_changes\":[{\"asset_id\":\"61819828071723399190623735325323968706432622380635304641786792960078828866875\", \"price\":\"0.86\", \"size\":\"1852.97\", \"side\":\"BUY\", \"hash\":\"dd02f003ed02b239cd257fc5b4ff8f6e4ad98752\", \"best_bid\":\"0.86\", \"best_ask\":\"0.87\"}, {\"asset_id\":\"114356653315647913247200886351065428002113119844334520181865067698979836634569\", \"price\":\"0.14\", \"size\":\"1852.97\", \"side\":\"SELL\", \"hash\":\"88a3cb90417c458b47896530f0fa9fe0e0c9e2a5\", \"best_bid\":\"0.13\", \"best_ask\":\"0.14\"}], \"timestamp\":\"1789987930349\", \"event_type\":\"price_change\"}","raw_base64":null}
{"received_ms":1789987930374,"monotonic_ns":1019371204483800,"raw":"{\"market\":\"0x28a45972fccdaf0fba75dacc59725521035e177d09dd92174f9f52740bccb025\", \"price_changes\":[{\"asset_id\":\"61819828071723399190623735325323968706432622380635304641786792960078828866875\", \"price\":\"0.83\", \"size\":\"524\", \"side\":\"BUY\", \"hash\":\"af1ea326f189e577169a8a487a715ea6e3540c01\", \"best_bid\":\"0.86\", \"best_ask\":\"0.87\"}, {\"asset_id\":\"114356653315647913247200886351065428002113119844334520181865067698979836634569\", \"price\":\"0.17\", \"size\":\"524\", \"side\":\"SELL\", \"hash\":\"fcbefee7a28e1729dd58df3c2e2f9c16e4ab2ae8\", \"best_bid\":\"0.13\", \"best_ask\":\"0.14\"}], \"timestamp\":\"1789987930353\", \"event_type\":\"price_change\"}","raw_base64":null}
{"received_ms":1789987930382,"monotonic_ns":1019371212461700,"raw":"{\"market\":\"0x28a45972fccdaf0fba75dacc59725521035e177d09dd92174f9f52740bccb025\", \"price_changes\":[{\"asset_id\":\"61819828071723399190623735325323968706432622380635304641786792960078828866875\", \"price\":\"0.73\", \"size\":\"504\", \"side\":\"BUY\", \"hash\":\"e0f55fca354db54390dc15af72607ff5a76d512a\", \"best_bid\":\"0.86\", \"best_ask\":\"0.87\"}, {\"asset_id\":\"114356653315647913247200886351065428002113119844334520181865067698979836634569\", \"price\":\"0.27\", \"size\":\"504\", \"side\":\"SELL\", \"hash\":\"69af3a81e7fe28442eaed57c1fbcaa2d26711609\", \"best_bid\":\"0.13\", \"best_ask\":\"0.14\"}], \"timestamp\":\"1789987930360\", \"event_type\":\"price_change\"}","raw_base64":null}
{"received_ms":1789987930384,"monotonic_ns":1019371214741400,"raw":"{\"market\":\"0x28a45972fccdaf0fba75dacc59725521035e177d09dd92174f9f52740bccb025\", \"price_changes\":[{\"asset_id\":\"61819828071723399190623735325323968706432622380635304641786792960078828866875\", \"price\":\"0.73\", \"size\":\"404\", \"side\":\"BUY\", \"hash\":\"132c5813abdac29822c34b9274329475698f28f0\", \"best_bid\":\"0.86\", \"best_ask\":\"0.87\"}, {\"asset_id\":\"114356653315647913247200886351065428002113119844334520181865067698979836634569\", \"price\":\"0.27\", \"size\":\"404\", \"side\":\"SELL\", \"hash\":\"dea5553c56ef8690f8f5b78505dd7861e7a6869e\", \"best_bid\":\"0.13\", \"best_ask\":\"0.14\"}], \"timestamp\":\"1789987930364\", \"event_type\":\"price_change\"}","raw_base64":null}
{"received_ms":1789987930397,"monotonic_ns":1019371227407300,"raw":"{\"market\":\"0x28a45972fccdaf0fba75dacc59725521035e177d09dd92174f9f52740bccb025\", \"price_changes\":[{\"asset_id\":\"114356653315647913247200886351065428002113119844334520181865067698979836634569\", \"price\":\"0.07\", \"size\":\"7991.71\", \"side\":\"BUY\", \"hash\":\"ad32b32f556a4a351e7f162e9898399da0289cda\", \"best_bid\":\"0.13\", \"best_ask\":\"0.14\"}, {\"asset_id\":\"61819828071723399190623735325323968706432622380635304641786792960078828866875\", \"price\":\"0.93\", \"size\":\"7991.71\", \"side\":\"SELL\", \"hash\":\"2f92e54d12208188c40663ddb2a9d0f2078bc7db\", \"best_bid\":\"0.86\", \"best_ask\":\"0.87\"}], \"timestamp\":\"1789987930376\", \"event_type\":\"price_change\"}","raw_base64":null}
{"received_ms":1789987930431,"monotonic_ns":1019371261833700,"raw":"{\"market\":\"0x28a45972fccdaf0fba75dacc59725521035e177d09dd92174f9f52740bccb025\", \"price_changes\":[{\"asset_id\":\"61819828071723399190623735325323968706432622380635304641786792960078828866875\", \"price\":\"0.86\", \"size\":\"3276.97\", \"side\":\"BUY\", \"hash\":\"295ea8b9b8bb5b6bfb1755fe2b420019f2196bdc\", \"best_bid\":\"0.86\", \"best_ask\":\"0.87\"}, {\"asset_id\":\"114356653315647913247200886351065428002113119844334520181865067698979836634569\", \"price\":\"0.14\", \"size\":\"3276.97\", \"side\":\"SELL\", \"hash\":\"2147d88f1cbcc2fb79c600cfad99acb32cdcf181\", \"best_bid\":\"0.13\", \"best_ask\":\"0.14\"}], \"timestamp\":\"1789987930411\", \"event_type\":\"price_change\"}","raw_base64":null}
{"received_ms":1789987930433,"monotonic_ns":1019371263621000,"raw":"{\"market\":\"0x28a45972fccdaf0fba75dacc59725521035e177d09dd92174f9f52740bccb025\", \"price_changes\":[{\"asset_id\":\"114356653315647913247200886351065428002113119844334520181865067698979836634569\", \"price\":\"0.05\", \"size\":\"5652\", \"side\":\"BUY\", \"hash\":\"4e91da9d9c2cabcba575ccd9169b42e544dfd689\", \"best_bid\":\"0.13\", \"best_ask\":\"0.14\"}, {\"asset_id\":\"61819828071723399190623735325323968706432622380635304641786792960078828866875\", \"price\":\"0.95\", \"size\":\"5652\", \"side\":\"SELL\", \"hash\":\"13844058094ace03d14f5faf21357ecbf99d3772\", \"best_bid\":\"0.86\", \"best_ask\":\"0.87\"}], \"timestamp\":\"1789987930412\", \"event_type\":\"price_change\"}","raw_base64":null}
{"received_ms":1789987930466,"monotonic_ns":1019371297247800,"raw":"{\"market\":\"0x28a45972fccdaf0fba75dacc59725521035e177d09dd92174f9f52740bccb025\", \"price_changes\":[{\"asset_id\":\"61819828071723399190623735325323968706432622380635304641786792960078828866875\", \"price\":\"0.73\", \"size\":\"504\", \"side\":\"BUY\", \"hash\":\"924aaa0167fe680ca20ddf5542d2e9ef784b3a05\", \"best_bid\":\"0.86\", \"best_ask\":\"0.87\"}, {\"asset_id\":\"114356653315647913247200886351065428002113119844334520181865067698979836634569\", \"price\":\"0.27\", \"size\":\"504\", \"side\":\"SELL\", \"hash\":\"015088e7a0c29ce1904204f3ffdcd76dbe90d3a5\", \"best_bid\":\"0.13\", \"best_ask\":\"0.14\"}], \"timestamp\":\"1789987930445\", \"event_type\":\"price_change\"}","raw_base64":null}
{"received_ms":1789987930467,"monotonic_ns":1019371297355000,"raw":"{\"market\":\"0x28a45972fccdaf0fba75dacc59725521035e177d09dd92174f9f52740bccb025\", \"price_changes\":[{\"asset_id\":\"114356653315647913247200886351065428002113119844334520181865067698979836634569\", \"price\":\"0.07\", \"size\":\"7029.71\", \"side\":\"BUY\", \"hash\":\"4b703590b8b8c4c0987229be5a43ea1112dca6bc\", \"best_bid\":\"0.13\", \"best_ask\":\"0.14\"}, {\"asset_id\":\"61819828071723399190623735325323968706432622380635304641786792960078828866875\", \"price\":\"0.93\", \"size\":\"7029.71\", \"side\":\"SELL\", \"hash\":\"8c49ee6dc032fd8452cd49f773094d3664afc25b\", \"best_bid\":\"0.86\", \"best_ask\":\"0.87\"}], \"timestamp\":\"1789987930446\", \"event_type\":\"price_change\"}","raw_base64":null}
{"received_ms":1789987930467,"monotonic_ns":1019371297518900,"raw":"{\"market\":\"0x28a45972fccdaf0fba75dacc59725521035e177d09dd92174f9f52740bccb025\", \"price_changes\":[{\"asset_id\":\"114356653315647913247200886351065428002113119844334520181865067698979836634569\", \"price\":\"0.07\", \"size\":\"6858.71\", \"side\":\"BUY\", \"hash\":\"1710dcf14326e40aad5e2f9ba6b3186accc75745\", \"best_bid\":\"0.13\", \"best_ask\":\"0.14\"}, {\"asset_id\":\"61819828071723399190623735325323968706432622380635304641786792960078828866875\", \"price\":\"0.93\", \"size\":\"6858.71\", \"side\":\"SELL\", \"hash\":\"5208e099de34d3e6cd2fd0ada3a08a33a4ecffab\", \"best_bid\":\"0.86\", \"best_ask\":\"0.87\"}], \"timestamp\":\"1789987930447\", \"event_type\":\"price_change\"}","raw_base64":null}
{"received_ms":1789987930476,"monotonic_ns":1019371306940300,"raw":"{\"market\":\"0x28a45972fccdaf0fba75dacc59725521035e177d09dd92174f9f52740bccb025\", \"price_changes\":[{\"asset_id\":\"61819828071723399190623735325323968706432622380635304641786792960078828866875\", \"price\":\"0.73\", \"size\":\"404\", \"side\":\"BUY\", \"hash\":\"d3233356d691ce9d604539a049e9feade5aa1e38\", \"best_bid\":\"0.86\", \"best_ask\":\"0.87\"}, {\"asset_id\":\"114356653315647913247200886351065428002113119844334520181865067698979836634569\", \"price\":\"0.27\", \"size\":\"404\", \"side\":\"SELL\", \"hash\":\"13e36ad00748f0d596d87a1901dd93dace67e711\", \"best_bid\":\"0.13\", \"best_ask\":\"0.14\"}], \"timestamp\":\"1789987930455\", \"event_type\":\"price_change\"}","raw_base64":null}
{"received_ms":1789987930496,"monotonic_ns":1019371327240200,"raw":"{\"market\":\"0x28a45972fccdaf0fba75dacc59725521035e177d09dd92174f9f52740bccb025\", \"price_changes\":[{\"asset_id\":\"114356653315647913247200886351065428002113119844334520181865067698979836634569\", \"price\":\"0.06\", \"size\":\"5644.67\", \"side\":\"BUY\", \"hash\":\"8c063629d3d0cd7f3d7f7f5ae7ffc6aba8f77ae7\", \"best_bid\":\"0.13\", \"best_ask\":\"0.14\"}, {\"asset_id\":\"61819828071723399190623735325323968706432622380635304641786792960078828866875\", \"price\":\"0.94\", \"size\":\"5644.67\", \"side\":\"SELL\", \"hash\":\"44cbb82aaa9cce38c9492b185d083982a4473f01\", \"best_bid\":\"0.86\", \"best_ask\":\"0.87\"}], \"timestamp\":\"1789987930477\", \"event_type\":\"price_change\"}","raw_base64":null}
{"received_ms":1789987930499,"monotonic_ns":1019371330105300,"raw":"{\"market\":\"0x28a45972fccdaf0fba75dacc59725521035e177d09dd92174f9f52740bccb025\", \"price_changes\":[{\"asset_id\":\"114356653315647913247200886351065428002113119844334520181865067698979836634569\", \"price\":\"0.07\", \"size\":\"7473.71\", \"side\":\"BUY\", \"hash\":\"44a0b4862f06d7a17be2106000cb3647e050e5d6\", \"best_bid\":\"0.13\", \"best_ask\":\"0.14\"}, {\"asset_id\":\"61819828071723399190623735325323968706432622380635304641786792960078828866875\", \"price\":\"0.93\", \"size\":\"7473.71\", \"side\":\"SELL\", \"hash\":\"194dbbbc525505903d8394dbb625724bd6cd7a74\", \"best_bid\":\"0.86\", \"best_ask\":\"0.87\"}], \"timestamp\":\"1789987930479\", \"event_type\":\"price_change\"}","raw_base64":null}
{"received_ms":1789987930509,"monotonic_ns":1019371339580100,"raw":"{\"market\":\"0x28a45972fccdaf0fba75dacc59725521035e177d09dd92174f9f52740bccb025\", \"price_changes\":[{\"asset_id\":\"61819828071723399190623735325323968706432622380635304641786792960078828866875\", \"price\":\"0.77\", \"size\":\"587.49\", \"side\":\"BUY\", \"hash\":\"fed379058155d687daeba325984e258709ca54fb\", \"best_bid\":\"0.86\", \"best_ask\":\"0.87\"}, {\"asset_id\":\"114356653315647913247200886351065428002113119844334520181865067698979836634569\", \"price\":\"0.23\", \"size\":\"587.49\", \"side\":\"SELL\", \"hash\":\"170e591bdf63ca9de6ea2e45425538cbd9403394\", \"best_bid\":\"0.13\", \"best_ask\":\"0.14\"}], \"timestamp\":\"1789987930488\", \"event_type\":\"price_change\"}","raw_base64":null}
{"received_ms":1789987930509,"monotonic_ns":1019371340055000,"raw":"{\"market\":\"0x28a45972fccdaf0fba75dacc59725521035e177d09dd92174f9f52740bccb025\", \"price_changes\":[{\"asset_id\":\"61819828071723399190623735325323968706432622380635304641786792960078828866875\", \"price\":\"0.79\", \"size\":\"467\", \"side\":\"BUY\", \"hash\":\"5346f8ec5c6b238b0c4c5b42a36dd40d0f6c339c\", \"best_bid\":\"0.86\", \"best_ask\":\"0.87\"}, {\"asset_id\":\"114356653315647913247200886351065428002113119844334520181865067698979836634569\", \"price\":\"0.21\", \"size\":\"467\", \"side\":\"SELL\", \"hash\":\"967b254d7043ccf4ab8eb8c91b5b4c0e14d9d978\", \"best_bid\":\"0.13\", \"best_ask\":\"0.14\"}], \"timestamp\":\"1789987930489\", \"event_type\":\"price_change\"}","raw_base64":null}
{"received_ms":1789987930512,"monotonic_ns":1019371342669400,"raw":"{\"market\":\"0x28a45972fccdaf0fba75dacc59725521035e177d09dd92174f9f52740bccb025\", \"price_changes\":[{\"asset_id\":\"61819828071723399190623735325323968706432622380635304641786792960078828866875\", \"price\":\"0.77\", \"size\":\"527.49\", \"side\":\"BUY\", \"hash\":\"e10bddde3caa8d7ac063879ed0584f04d073d9be\", \"best_bid\":\"0.86\", \"best_ask\":\"0.87\"}, {\"asset_id\":\"114356653315647913247200886351065428002113119844334520181865067698979836634569\", \"price\":\"0.23\", \"size\":\"527.49\", \"side\":\"SELL\", \"hash\":\"bf89beb1bfbcf093c635d922e06e0573a6e59a88\", \"best_bid\":\"0.13\", \"best_ask\":\"0.14\"}], \"timestamp\":\"1789987930492\", \"event_type\":\"price_change\"}","raw_base64":null}
{"received_ms":1789987930512,"monotonic_ns":1019371342732700,"raw":"{\"market\":\"0x28a45972fccdaf0fba75dacc59725521035e177d09dd92174f9f52740bccb025\", \"price_changes\":[{\"asset_id\":\"61819828071723399190623735325323968706432622380635304641786792960078828866875\", \"price\":\"0.79\", \"size\":\"427\", \"side\":\"BUY\", \"hash\":\"e10bddde3caa8d7ac063879ed0584f04d073d9be\", \"best_bid\":\"0.86\", \"best_ask\":\"0.87\"}, {\"asset_id\":\"114356653315647913247200886351065428002113119844334520181865067698979836634569\", \"price\":\"0.21\", \"size\":\"427\", \"side\":\"SELL\", \"hash\":\"bf89beb1bfbcf093c635d922e06e0573a6e59a88\", \"best_bid\":\"0.13\", \"best_ask\":\"0.14\"}], \"timestamp\":\"1789987930492\", \"event_type\":\"price_change\"}","raw_base64":null}
{"received_ms":1789987930528,"monotonic_ns":1019371358488400,"raw":"{\"market\":\"0x28a45972fccdaf0fba75dacc59725521035e177d09dd92174f9f52740bccb025\", \"price_changes\":[{\"asset_id\":\"61819828071723399190623735325323968706432622380635304641786792960078828866875\", \"price\":\"0.75\", \"size\":\"500\", \"side\":\"BUY\", \"hash\":\"3a391df688c17c48a700f649db4565b086a02e59\", \"best_bid\":\"0.86\", \"best_ask\":\"0.87\"}, {\"asset_id\":\"114356653315647913247200886351065428002113119844334520181865067698979836634569\", \"price\":\"0.25\", \"size\":\"500\", \"side\":\"SELL\", \"hash\":\"0f3b8c3b35b6c13899d1609da0ee8b0e923a5d66\", \"best_bid\":\"0.13\", \"best_ask\":\"0.14\"}], \"timestamp\":\"1789987930501\", \"event_type\":\"price_change\"}","raw_base64":null}
{"received_ms":1789987930528,"monotonic_ns":1019371358577700,"raw":"{\"market\":\"0x28a45972fccdaf0fba75dacc59725521035e177d09dd92174f9f52740bccb025\", \"price_changes\":[{\"asset_id\":\"61819828071723399190623735325323968706432622380635304641786792960078828866875\", \"price\":\"0.86\", \"size\":\"1852.97\", \"side\":\"BUY\", \"hash\":\"be0a281f63027dfed13ea322811d472a9fca08d8\", \"best_bid\":\"0.86\", \"best_ask\":\"0.87\"}, {\"asset_id\":\"114356653315647913247200886351065428002113119844334520181865067698979836634569\", \"price\":\"0.14\", \"size\":\"1852.97\", \"side\":\"SELL\", \"hash\":\"72877d270cc9091ddf7ecda15ead205b4bdbcbdb\", \"best_bid\":\"0.13\", \"best_ask\":\"0.14\"}], \"timestamp\":\"1789987930505\", \"event_type\":\"price_change\"}","raw_base64":null}
{"received_ms":1789987930528,"monotonic_ns":1019371358954300,"raw":"{\"market\":\"0x28a45972fccdaf0fba75dacc59725521035e177d09dd92174f9f52740bccb025\", \"price_changes\":[{\"asset_id\":\"114356653315647913247200886351065428002113119844334520181865067698979836634569\", \"price\":\"0.06\", \"size\":\"5324.67\", \"side\":\"BUY\", \"hash\":\"982bd8feb9b60095256fe4ea7bc4304b921d41a6\", \"best_bid\":\"0.13\", \"best_ask\":\"0.14\"}, {\"asset_id\":\"61819828071723399190623735325323968706432622380635304641786792960078828866875\", \"price\":\"0.94\", \"size\":\"5324.67\", \"side\":\"SELL\", \"hash\":\"e61b740586b7a6e1994ca9c0aad15fcf3f647aff\", \"best_bid\":\"0.86\", \"best_ask\":\"0.87\"}], \"timestamp\":\"1789987930506\", \"event_type\":\"price_change\"}","raw_base64":null}
{"received_ms":1789987930542,"monotonic_ns":1019371373185900,"raw":"{\"market\":\"0x28a45972fccdaf0fba75dacc59725521035e177d09dd92174f9f52740bccb025\", \"price_changes\":[{\"asset_id\":\"61819828071723399190623735325323968706432622380635304641786792960078828866875\", \"price\":\"0.77\", \"size\":\"547.49\", \"side\":\"BUY\", \"hash\":\"25cdb3d2ef9571c3e9fda58c806c02c4f3a8f758\", \"best_bid\":\"0.86\", \"best_ask\":\"0.87\"}, {\"asset_id\":\"114356653315647913247200886351065428002113119844334520181865067698979836634569\", \"price\":\"0.23\", \"size\":\"547.49\", \"side\":\"SELL\", \"hash\":\"03d895ac3964f5d1297927f9e1862876e604506b\", \"best_bid\":\"0.13\", \"best_ask\":\"0.14\"}], \"timestamp\":\"1789987930522\", \"event_type\":\"price_change\"}","raw_base64":null}
{"received_ms":1789987930568,"monotonic_ns":1019371398482400,"raw":"{\"market\":\"0x28a45972fccdaf0fba75dacc59725521035e177d09dd92174f9f52740bccb025\", \"price_changes\":[{\"asset_id\":\"61819828071723399190623735325323968706432622380635304641786792960078828866875\", \"price\":\"0.84\", \"size\":\"3204\", \"side\":\"BUY\", \"hash\":\"b2f5eef32e1d55655fd268dc61219b99f095e3fd\", \"best_bid\":\"0.86\", \"best_ask\":\"0.87\"}, {\"asset_id\":\"114356653315647913247200886351065428002113119844334520181865067698979836634569\", \"price\":\"0.16\", \"size\":\"3204\", \"side\":\"SELL\", \"hash\":\"bbbde289731ceb1402e137c6047d6e1506a3f443\", \"best_bid\":\"0.13\", \"best_ask\":\"0.14\"}], \"timestamp\":\"1789987930547\", \"event_type\":\"price_change\"}","raw_base64":null}
{"received_ms":1789987930569,"monotonic_ns":1019371399300900,"raw":"{\"market\":\"0x28a45972fccdaf0fba75dacc59725521035e177d09dd92174f9f52740bccb025\", \"price_changes\":[{\"asset_id\":\"61819828071723399190623735325323968706432622380635304641786792960078828866875\", \"price\":\"0.86\", \"size\":\"3259.97\", \"side\":\"BUY\", \"hash\":\"c2cf92f017efac5e186a6ff4584c572a17a12017\", \"best_bid\":\"0.86\", \"best_ask\":\"0.87\"}, {\"asset_id\":\"114356653315647913247200886351065428002113119844334520181865067698979836634569\", \"price\":\"0.14\", \"size\":\"3259.97\", \"side\":\"SELL\", \"hash\":\"257979c0abde56f1df6fd300a03fb6191ab2400b\", \"best_bid\":\"0.13\", \"best_ask\":\"0.14\"}], \"timestamp\":\"1789987930548\", \"event_type\":\"price_change\"}","raw_base64":null}
{"received_ms":1789987930597,"monotonic_ns":1019371427473700,"raw":"{\"market\":\"0x28a45972fccdaf0fba75dacc59725521035e177d09dd92174f9f52740bccb025\", \"price_changes\":[{\"asset_id\":\"114356653315647913247200886351065428002113119844334520181865067698979836634569\", \"price\":\"0.07\", \"size\":\"6858.71\", \"side\":\"BUY\", \"hash\":\"6f40e3ce28e38fcabf95335a8c7e7efa8ef62c58\", \"best_bid\":\"0.13\", \"best_ask\":\"0.14\"}, {\"asset_id\":\"61819828071723399190623735325323968706432622380635304641786792960078828866875\", \"price\":\"0.93\", \"size\":\"6858.71\", \"side\":\"SELL\", \"hash\":\"5da787d8b4680529d270ec23dc99b2a1a00bc3fd\", \"best_bid\":\"0.86\", \"best_ask\":\"0.87\"}], \"timestamp\":\"1789987930577\", \"event_type\":\"price_change\"}","raw_base64":null}
{"received_ms":1789987930597,"monotonic_ns":1019371428224700,"raw":"{\"market\":\"0x28a45972fccdaf0fba75dacc59725521035e177d09dd92174f9f52740bccb025\", \"price_changes\":[{\"asset_id\":\"114356653315647913247200886351065428002113119844334520181865067698979836634569\", \"price\":\"0.07\", \"size\":\"7029.71\", \"side\":\"BUY\", \"hash\":\"8dfe9c108415e62f767376e63845fec55dfe4e51\", \"best_bid\":\"0.13\", \"best_ask\":\"0.14\"}, {\"asset_id\":\"61819828071723399190623735325323968706432622380635304641786792960078828866875\", \"price\":\"0.93\", \"size\":\"7029.71\", \"side\":\"SELL\", \"hash\":\"6d33374d5c9197bca680370689e59c7e467da767\", \"best_bid\":\"0.86\", \"best_ask\":\"0.87\"}], \"timestamp\":\"1789987930577\", \"event_type\":\"price_change\"}","raw_base64":null}
{"received_ms":1789987930599,"monotonic_ns":1019371429848900,"raw":"{\"market\":\"0x28a45972fccdaf0fba75dacc59725521035e177d09dd92174f9f52740bccb025\", \"price_changes\":[{\"asset_id\":\"114356653315647913247200886351065428002113119844334520181865067698979836634569\", \"price\":\"0.06\", \"size\":\"5626.67\", \"side\":\"BUY\", \"hash\":\"87c0caccd3c6ddf7bb9a86c3e54ee2ff8fcf3092\", \"best_bid\":\"0.13\", \"best_ask\":\"0.14\"}, {\"asset_id\":\"61819828071723399190623735325323968706432622380635304641786792960078828866875\", \"price\":\"0.94\", \"size\":\"5626.67\", \"side\":\"SELL\", \"hash\":\"cbd892de2e5287f0488e848d1d70448aae7600d2\", \"best_bid\":\"0.86\", \"best_ask\":\"0.87\"}], \"timestamp\":\"1789987930579\", \"event_type\":\"price_change\"}","raw_base64":null}
{"received_ms":1789987930630,"monotonic_ns":1019371460317300,"raw":"{\"market\":\"0x28a45972fccdaf0fba75dacc59725521035e177d09dd92174f9f52740bccb025\", \"price_changes\":[{\"asset_id\":\"61819828071723399190623735325323968706432622380635304641786792960078828866875\", \"price\":\"0.79\", \"size\":\"487\", \"side\":\"BUY\", \"hash\":\"5dc631bcfd6e74f14f8af1031764edcad0040ccc\", \"best_bid\":\"0.86\", \"best_ask\":\"0.87\"}, {\"asset_id\":\"114356653315647913247200886351065428002113119844334520181865067698979836634569\", \"price\":\"0.21\", \"size\":\"487\", \"side\":\"SELL\", \"hash\":\"e059be036500874c918885c9522eefd01685a8a9\", \"best_bid\":\"0.13\", \"best_ask\":\"0.14\"}], \"timestamp\":\"1789987930606\", \"event_type\":\"price_change\"}","raw_base64":null}
{"received_ms":1789987930630,"monotonic_ns":1019371460410600,"raw":"{\"market\":\"0x28a45972fccdaf0fba75dacc59725521035e177d09dd92174f9f52740bccb025\", \"price_changes\":[{\"asset_id\":\"61819828071723399190623735325323968706432622380635304641786792960078828866875\", \"price\":\"0.75\", \"size\":\"520\", \"side\":\"BUY\", \"hash\":\"81583594bb61d43fe41f7a5544240aafe14e6a58\", \"best_bid\":\"0.86\", \"best_ask\":\"0.87\"}, {\"asset_id\":\"114356653315647913247200886351065428002113119844334520181865067698979836634569\", \"price\":\"0.25\", \"size\":\"520\", \"side\":\"SELL\", \"hash\":\"c54d5bd152924e9d8cfeb5a69647f9dd7bd7cb7b\", \"best_bid\":\"0.13\", \"best_ask\":\"0.14\"}], \"timestamp\":\"1789987930606\", \"event_type\":\"price_change\"}","raw_base64":null}
{"received_ms":1789987930630,"monotonic_ns":1019371460452200,"raw":"{\"market\":\"0x28a45972fccdaf0fba75dacc59725521035e177d09dd92174f9f52740bccb025\", \"price_changes\":[{\"asset_id\":\"61819828071723399190623735325323968706432622380635304641786792960078828866875\", \"price\":\"0.77\", \"size\":\"567.49\", \"side\":\"BUY\", \"hash\":\"dfe75fa71abf8ecf57578fe16fae810a4d0fa619\", \"best_bid\":\"0.86\", \"best_ask\":\"0.87\"}, {\"asset_id\":\"114356653315647913247200886351065428002113119844334520181865067698979836634569\", \"price\":\"0.23\", \"size\":\"567.49\", \"side\":\"SELL\", \"hash\":\"ca9c70082f588256344140534064554b67dfddbf\", \"best_bid\":\"0.13\", \"best_ask\":\"0.14\"}], \"timestamp\":\"1789987930607\", \"event_type\":\"price_change\"}","raw_base64":null}
{"received_ms":1789987930630,"monotonic_ns":1019371460491200,"raw":"{\"market\":\"0x28a45972fccdaf0fba75dacc59725521035e177d09dd92174f9f52740bccb025\", \"price_changes\":[{\"asset_id\":\"61819828071723399190623735325323968706432622380635304641786792960078828866875\", \"price\":\"0.77\", \"size\":\"547.49\", \"side\":\"BUY\", \"hash\":\"1bc505339a4f0a4e4070c74a6f3b362b3acbe76a\", \"best_bid\":\"0.86\", \"best_ask\":\"0.87\"}, {\"asset_id\":\"114356653315647913247200886351065428002113119844334520181865067698979836634569\", \"price\":\"0.23\", \"size\":\"547.49\", \"side\":\"SELL\", \"hash\":\"88541fbac47206e6d79b08ab9e1312210a9e4c82\", \"best_bid\":\"0.13\", \"best_ask\":\"0.14\"}], \"timestamp\":\"1789987930608\", \"event_type\":\"price_change\"}","raw_base64":null}
{"received_ms":1789987930630,"monotonic_ns":1019371460528400,"raw":"{\"market\":\"0x28a45972fccdaf0fba75dacc59725521035e177d09dd92174f9f52740bccb025\", \"price_changes\":[{\"asset_id\":\"61819828071723399190623735325323968706432622380635304641786792960078828866875\", \"price\":\"0.75\", \"size\":\"500\", \"side\":\"BUY\", \"hash\":\"1bc505339a4f0a4e4070c74a6f3b362b3acbe76a\", \"best_bid\":\"0.86\", \"best_ask\":\"0.87\"}, {\"asset_id\":\"114356653315647913247200886351065428002113119844334520181865067698979836634569\", \"price\":\"0.25\", \"size\":\"500\", \"side\":\"SELL\", \"hash\":\"88541fbac47206e6d79b08ab9e1312210a9e4c82\", \"best_bid\":\"0.13\", \"best_ask\":\"0.14\"}], \"timestamp\":\"1789987930608\", \"event_type\":\"price_change\"}","raw_base64":null}
{"received_ms":1789987930630,"monotonic_ns":1019371460565600,"raw":"{\"market\":\"0x28a45972fccdaf0fba75dacc59725521035e177d09dd92174f9f52740bccb025\", \"price_changes\":[{\"asset_id\":\"61819828071723399190623735325323968706432622380635304641786792960078828866875\", \"price\":\"0.79\", \"size\":\"427\", \"side\":\"BUY\", \"hash\":\"1bc505339a4f0a4e4070c74a6f3b362b3acbe76a\", \"best_bid\":\"0.86\", \"best_ask\":\"0.87\"}, {\"asset_id\":\"114356653315647913247200886351065428002113119844334520181865067698979836634569\", \"price\":\"0.21\", \"size\":\"427\", \"side\":\"SELL\", \"hash\":\"88541fbac47206e6d79b08ab9e1312210a9e4c82\", \"best_bid\":\"0.13\", \"best_ask\":\"0.14\"}], \"timestamp\":\"1789987930608\", \"event_type\":\"price_change\"}","raw_base64":null}
{"received_ms":1789987930631,"monotonic_ns":1019371461449700,"raw":"{\"market\":\"0x28a45972fccdaf0fba75dacc59725521035e177d09dd92174f9f52740bccb025\", \"price_changes\":[{\"asset_id\":\"114356653315647913247200886351065428002113119844334520181865067698979836634569\", \"price\":\"0.07\", \"size\":\"7323.71\", \"side\":\"BUY\", \"hash\":\"6474bb47de65d6b6affd1bd57a2bb7ff4f9e3898\", \"best_bid\":\"0.13\", \"best_ask\":\"0.14\"}, {\"asset_id\":\"61819828071723399190623735325323968706432622380635304641786792960078828866875\", \"price\":\"0.93\", \"size\":\"7323.71\", \"side\":\"SELL\", \"hash\":\"82fefffacc5beacb3fe1c6a7eaf5a2efe5d509e0\", \"best_bid\":\"0.86\", \"best_ask\":\"0.87\"}], \"timestamp\":\"1789987930610\", \"event_type\":\"price_change\"}","raw_base64":null}
{"received_ms":1789987930642,"monotonic_ns":1019371472645100,"raw":"{\"market\":\"0x28a45972fccdaf0fba75dacc59725521035e177d09dd92174f9f52740bccb025\", \"price_changes\":[{\"asset_id\":\"61819828071723399190623735325323968706432622380635304641786792960078828866875\", \"price\":\"0.77\", \"size\":\"527.49\", \"side\":\"BUY\", \"hash\":\"22135b9297fcadf3533f48e60c9ce8f32940476c\", \"best_bid\":\"0.86\", \"best_ask\":\"0.87\"}, {\"asset_id\":\"114356653315647913247200886351065428002113119844334520181865067698979836634569\", \"price\":\"0.23\", \"size\":\"527.49\", \"side\":\"SELL\", \"hash\":\"6afcd35d4d75d147fd32c8f0d8336fcff03fd998\", \"best_bid\":\"0.13\", \"best_ask\":\"0.14\"}], \"timestamp\":\"1789987930620\", \"event_type\":\"price_change\"}","raw_base64":null}
{"received_ms":1789987930652,"monotonic_ns":1019371483242800,"raw":"{\"market\":\"0x28a45972fccdaf0fba75dacc59725521035e177d09dd92174f9f52740bccb025\", \"price_changes\":[{\"asset_id\":\"114356653315647913247200886351065428002113119844334520181865067698979836634569\", \"price\":\"0.03\", \"size\":\"3992.57\", \"side\":\"BUY\", \"hash\":\"06f99ab41562a3c657abe165a4ec3bb84b126ed4\", \"best_bid\":\"0.13\", \"best_ask\":\"0.14\"}, {\"asset_id\":\"61819828071723399190623735325323968706432622380635304641786792960078828866875\", \"price\":\"0.97\", \"size\":\"3992.57\", \"side\":\"SELL\", \"hash\":\"3945dbeda93ae4999cd7b4c956dc30934e579b7d\", \"best_bid\":\"0.86\", \"best_ask\":\"0.87\"}], \"timestamp\":\"1789987930632\", \"event_type\":\"price_change\"}","raw_base64":null}
{"received_ms":1789987930657,"monotonic_ns":1019371487911600,"raw":"{\"market\":\"0x28a45972fccdaf0fba75dacc59725521035e177d09dd92174f9f52740bccb025\", \"price_changes\":[{\"asset_id\":\"61819828071723399190623735325323968706432622380635304641786792960078828866875\", \"price\":\"0.73\", \"size\":\"504\", \"side\":\"BUY\", \"hash\":\"2ebd59ce4ba46601506fabc8d5946fdc52d766bc\", \"best_bid\":\"0.86\", \"best_ask\":\"0.87\"}, {\"asset_id\":\"114356653315647913247200886351065428002113119844334520181865067698979836634569\", \"price\":\"0.27\", \"size\":\"504\", \"side\":\"SELL\", \"hash\":\"d84de566cd26a442c019e3074d0cbebaf6a3d7dd\", \"best_bid\":\"0.13\", \"best_ask\":\"0.14\"}], \"timestamp\":\"1789987930636\", \"event_type\":\"price_change\"}","raw_base64":null}
{"received_ms":1789987930663,"monotonic_ns":1019371493265500,"raw":"{\"market\":\"0x28a45972fccdaf0fba75dacc59725521035e177d09dd92174f9f52740bccb025\", \"price_changes\":[{\"asset_id\":\"61819828071723399190623735325323968706432622380635304641786792960078828866875\", \"price\":\"0.73\", \"size\":\"404\", \"side\":\"BUY\", \"hash\":\"ae9bbb105de7f2da11248d837a2f1af5a22e5d77\", \"best_bid\":\"0.86\", \"best_ask\":\"0.87\"}, {\"asset_id\":\"114356653315647913247200886351065428002113119844334520181865067698979836634569\", \"price\":\"0.27\", \"size\":\"404\", \"side\":\"SELL\", \"hash\":\"8cf17020a0ae0032fbf764cc7bb92966db257479\", \"best_bid\":\"0.13\", \"best_ask\":\"0.14\"}], \"timestamp\":\"1789987930642\", \"event_type\":\"price_change\"}","raw_base64":null}
{"received_ms":1789987930680,"monotonic_ns":1019371510264500,"raw":"{\"market\":\"0x28a45972fccdaf0fba75dacc59725521035e177d09dd92174f9f52740bccb025\", \"price_changes\":[{\"asset_id\":\"61819828071723399190623735325323968706432622380635304641786792960078828866875\", \"price\":\"0.75\", \"size\":\"520\", \"side\":\"BUY\", \"hash\":\"aa26e77b08a09eeb81171a3d793ce4b92bcd1ca9\", \"best_bid\":\"0.86\", \"best_ask\":\"0.87\"}, {\"asset_id\":\"114356653315647913247200886351065428002113119844334520181865067698979836634569\", \"price\":\"0.25\", \"size\":\"520\", \"side\":\"SELL\", \"hash\":\"668d5fc01cf1dee9b0f011b0dcf754a7f0d82c80\", \"best_bid\":\"0.13\", \"best_ask\":\"0.14\"}], \"timestamp\":\"1789987930658\", \"event_type\":\"price_change\"}","raw_base64":null}
{"received_ms":1789987930691,"monotonic_ns":1019371521702600,"raw":"{\"market\":\"0x28a45972fccdaf0fba75dacc59725521035e177d09dd92174f9f52740bccb025\", \"price_changes\":[{\"asset_id\":\"114356653315647913247200886351065428002113119844334520181865067698979836634569\", \"price\":\"0.01\", \"size\":\"1689.43\", \"side\":\"BUY\", \"hash\":\"4a2dc8b82f088f17e4b417638be4b34dc161b357\", \"best_bid\":\"0.13\", \"best_ask\":\"0.14\"}, {\"asset_id\":\"61819828071723399190623735325323968706432622380635304641786792960078828866875\", \"price\":\"0.99\", \"size\":\"1689.43\", \"side\":\"SELL\", \"hash\":\"c88605f1e3ab78c54aa199507056557b55fe1570\", \"best_bid\":\"0.86\", \"best_ask\":\"0.87\"}], \"timestamp\":\"1789987930664\", \"event_type\":\"price_change\"}","raw_base64":null}
{"received_ms":1789987930691,"monotonic_ns":1019371521797000,"raw":"{\"market\":\"0x28a45972fccdaf0fba75dacc59725521035e177d09dd92174f9f52740bccb025\", \"price_changes\":[{\"asset_id\":\"61819828071723399190623735325323968706432622380635304641786792960078828866875\", \"price\":\"0.75\", \"size\":\"500\", \"side\":\"BUY\", \"hash\":\"371a3fa0cf15611d6aefd4a48149b3214ed0d5b7\", \"best_bid\":\"0.86\", \"best_ask\":\"0.87\"}, {\"asset_id\":\"114356653315647913247200886351065428002113119844334520181865067698979836634569\", \"price\":\"0.25\", \"size\":\"500\", \"side\":\"SELL\", \"hash\":\"0989357ba373f3fac628255b5923b5bcb850b99b\", \"best_bid\":\"0.13\", \"best_ask\":\"0.14\"}], \"timestamp\":\"1789987930665\", \"event_type\":\"price_change\"}","raw_base64":null}
{"received_ms":1789987930693,"monotonic_ns":1019371524133000,"raw":"{\"market\":\"0x28a45972fccdaf0fba75dacc59725521035e177d09dd92174f9f52740bccb025\", \"price_changes\":[{\"asset_id\":\"61819828071723399190623735325323968706432622380635304641786792960078828866875\", \"price\":\"0.79\", \"size\":\"487\", \"side\":\"BUY\", \"hash\":\"21d35bebf712d840793425bc65e261026196e388\", \"best_bid\":\"0.86\", \"best_ask\":\"0.87\"}, {\"asset_id\":\"114356653315647913247200886351065428002113119844334520181865067698979836634569\", \"price\":\"0.21\", \"size\":\"487\", \"side\":\"SELL\", \"hash\":\"4929d947955c444c9e33854df6710692b6bc80a8\", \"best_bid\":\"0.13\", \"best_ask\":\"0.14\"}], \"timestamp\":\"1789987930670\", \"event_type\":\"price_change\"}","raw_base64":null}
{"received_ms":1789987930693,"monotonic_ns":1019371524220100,"raw":"{\"market\":\"0x28a45972fccdaf0fba75dacc59725521035e177d09dd92174f9f52740bccb025\", \"price_changes\":[{\"asset_id\":\"61819828071723399190623735325323968706432622380635304641786792960078828866875\", \"price\":\"0.77\", \"size\":\"567.49\", \"side\":\"BUY\", \"hash\":\"bcf304ea7a4fee2b7659a4977330ca771ec6efce\", \"best_bid\":\"0.86\", \"best_ask\":\"0.87\"}, {\"asset_id\":\"114356653315647913247200886351065428002113119844334520181865067698979836634569\", \"price\":\"0.23\", \"size\":\"567.49\", \"side\":\"SELL\", \"hash\":\"0cf5608578992b98b692798a54cc136ccf80ec2d\", \"best_bid\":\"0.13\", \"best_ask\":\"0.14\"}], \"timestamp\":\"1789987930671\", \"event_type\":\"price_change\"}","raw_base64":null}
{"received_ms":1789987930694,"monotonic_ns":1019371524267700,"raw":"{\"market\":\"0x28a45972fccdaf0fba75dacc59725521035e177d09dd92174f9f52740bccb025\", \"price_changes\":[{\"asset_id\":\"61819828071723399190623735325323968706432622380635304641786792960078828866875\", \"price\":\"0.77\", \"size\":\"527.49\", \"side\":\"BUY\", \"hash\":\"5531ada789da6c679d9f1982be35c47d8aaf5ec1\", \"best_bid\":\"0.86\", \"best_ask\":\"0.87\"}, {\"asset_id\":\"114356653315647913247200886351065428002113119844334520181865067698979836634569\", \"price\":\"0.23\", \"size\":\"527.49\", \"side\":\"SELL\", \"hash\":\"6285e28e13258b8d6bc3fb80c703b34367e00dc7\", \"best_bid\":\"0.13\", \"best_ask\":\"0.14\"}], \"timestamp\":\"1789987930673\", \"event_type\":\"price_change\"}","raw_base64":null}
{"received_ms":1789987930694,"monotonic_ns":1019371524323100,"raw":"{\"market\":\"0x28a45972fccdaf0fba75dacc59725521035e177d09dd92174f9f52740bccb025\", \"price_changes\":[{\"asset_id\":\"61819828071723399190623735325323968706432622380635304641786792960078828866875\", \"price\":\"0.79\", \"size\":\"427\", \"side\":\"BUY\", \"hash\":\"5531ada789da6c679d9f1982be35c47d8aaf5ec1\", \"best_bid\":\"0.86\", \"best_ask\":\"0.87\"}, {\"asset_id\":\"114356653315647913247200886351065428002113119844334520181865067698979836634569\", \"price\":\"0.21\", \"size\":\"427\", \"side\":\"SELL\", \"hash\":\"6285e28e13258b8d6bc3fb80c703b34367e00dc7\", \"best_bid\":\"0.13\", \"best_ask\":\"0.14\"}], \"timestamp\":\"1789987930673\", \"event_type\":\"price_change\"}","raw_base64":null}
{"received_ms":1789987930709,"monotonic_ns":1019371539699800,"raw":"{\"market\":\"0x28a45972fccdaf0fba75dacc59725521035e177d09dd92174f9f52740bccb025\", \"price_changes\":[{\"asset_id\":\"114356653315647913247200886351065428002113119844334520181865067698979836634569\", \"price\":\"0.07\", \"size\":\"7029.71\", \"side\":\"BUY\", \"hash\":\"57c072e3134d33da84dfaa1301a4576cac50e9e3\", \"best_bid\":\"0.13\", \"best_ask\":\"0.14\"}, {\"asset_id\":\"61819828071723399190623735325323968706432622380635304641786792960078828866875\", \"price\":\"0.93\", \"size\":\"7029.71\", \"side\":\"SELL\", \"hash\":\"7776a55a3379cd1c2903b025837bc943379d527f\", \"best_bid\":\"0.86\", \"best_ask\":\"0.87\"}], \"timestamp\":\"1789987930687\", \"event_type\":\"price_change\"}","raw_base64":null}
{"received_ms":1789987930723,"monotonic_ns":1019371553755700,"raw":"{\"market\":\"0x28a45972fccdaf0fba75dacc59725521035e177d09dd92174f9f52740bccb025\", \"price_changes\":[{\"asset_id\":\"61819828071723399190623735325323968706432622380635304641786792960078828866875\", \"price\":\"0.86\", \"size\":\"1852.97\", \"side\":\"BUY\", \"hash\":\"ecff81e124e4f1d9cc028dfc0ec69527104ccaf8\", \"best_bid\":\"0.86\", \"best_ask\":\"0.87\"}, {\"asset_id\":\"114356653315647913247200886351065428002113119844334520181865067698979836634569\", \"price\":\"0.14\", \"size\":\"1852.97\", \"side\":\"SELL\", \"hash\":\"a2a160dc2c87907da8501d1a2909debff0d7a909\", \"best_bid\":\"0.13\", \"best_ask\":\"0.14\"}], \"timestamp\":\"1789987930695\", \"event_type\":\"price_change\"}","raw_base64":null}
{"received_ms":1789987930723,"monotonic_ns":1019371553821700,"raw":"{\"market\":\"0x28a45972fccdaf0fba75dacc59725521035e177d09dd92174f9f52740bccb025\", \"price_changes\":[{\"asset_id\":\"61819828071723399190623735325323968706432622380635304641786792960078828866875\", \"price\":\"0.01\", \"size\":\"1496.91\", \"side\":\"BUY\", \"hash\":\"18c7e79943391c9476da1877d5f7eee85f3b780b\", \"best_bid\":\"0.86\", \"best_ask\":\"0.87\"}, {\"asset_id\":\"114356653315647913247200886351065428002113119844334520181865067698979836634569\", \"price\":\"0.99\", \"size\":\"1496.91\", \"side\":\"SELL\", \"hash\":\"6a89721cd6e45fb8e66fc821d4a88c28de7b17ec\", \"best_bid\":\"0.13\", \"best_ask\":\"0.14\"}], \"timestamp\":\"1789987930697\", \"event_type\":\"price_change\"}","raw_base64":null}
{"received_ms":1789987930723,"monotonic_ns":1019371553872700,"raw":"{\"market\":\"0x28a45972fccdaf0fba75dacc59725521035e177d09dd92174f9f52740bccb025\", \"price_changes\":[{\"asset_id\":\"61819828071723399190623735325323968706432622380635304641786792960078828866875\", \"price\":\"0.77\", \"size\":\"547.49\", \"side\":\"BUY\", \"hash\":\"db047fa1c8428f8ef3aac9781345de7094e38833\", \"best_bid\":\"0.86\", \"best_ask\":\"0.87\"}, {\"asset_id\":\"114356653315647913247200886351065428002113119844334520181865067698979836634569\", \"price\":\"0.23\", \"size\":\"547.49\", \"side\":\"SELL\", \"hash\":\"795c1ccea6a036a85a5b15977f74eda55bd503ba\", \"best_bid\":\"0.13\", \"best_ask\":\"0.14\"}], \"timestamp\":\"1789987930701\", \"event_type\":\"price_change\"}","raw_base64":null}
{"received_ms":1789987930723,"monotonic_ns":1019371553921300,"raw":"{\"market\":\"0x28a45972fccdaf0fba75dacc59725521035e177d09dd92174f9f52740bccb025\", \"price_changes\":[{\"asset_id\":\"61819828071723399190623735325323968706432622380635304641786792960078828866875\", \"price\":\"0.73\", \"size\":\"504\", \"side\":\"BUY\", \"hash\":\"7909d67b647a0bbd8ad5e60301e7570f463329d1\", \"best_bid\":\"0.86\", \"best_ask\":\"0.87\"}, {\"asset_id\":\"114356653315647913247200886351065428002113119844334520181865067698979836634569\", \"price\":\"0.27\", \"size\":\"504\", \"side\":\"SELL\", \"hash\":\"c1e55d3cc52afeebc6f2edf0f91abdfedcad296e\", \"best_bid\":\"0.13\", \"best_ask\":\"0.14\"}], \"timestamp\":\"1789987930702\", \"event_type\":\"price_change\"}","raw_base64":null}
{"received_ms":1789987930727,"monotonic_ns":1019371558075400,"raw":"{\"market\":\"0x28a45972fccdaf0fba75dacc59725521035e177d09dd92174f9f52740bccb025\", \"price_changes\":[{\"asset_id\":\"61819828071723399190623735325323968706432622380635304641786792960078828866875\", \"price\":\"0.73\", \"size\":\"404\", \"side\":\"BUY\", \"hash\":\"768d5f4ce5ddba5e9b9ef8e812617c2782bde07a\", \"best_bid\":\"0.86\", \"best_ask\":\"0.87\"}, {\"asset_id\":\"114356653315647913247200886351065428002113119844334520181865067698979836634569\", \"price\":\"0.27\", \"size\":\"404\", \"side\":\"SELL\", \"hash\":\"840ccef5fb6af46c20459478192587cab9236385\", \"best_bid\":\"0.13\", \"best_ask\":\"0.14\"}], \"timestamp\":\"1789987930707\", \"event_type\":\"price_change\"}","raw_base64":null}
{"received_ms":1789987930743,"monotonic_ns":1019371574209500,"raw":"{\"market\":\"0x28a45972fccdaf0fba75dacc59725521035e177d09dd92174f9f52740bccb025\", \"price_changes\":[{\"asset_id\":\"61819828071723399190623735325323968706432622380635304641786792960078828866875\", \"price\":\"0.86\", \"size\":\"3231.97\", \"side\":\"BUY\", \"hash\":\"4a03609deb53ac84b1280a5319983579862d52af\", \"best_bid\":\"0.86\", \"best_ask\":\"0.87\"}, {\"asset_id\":\"114356653315647913247200886351065428002113119844334520181865067698979836634569\", \"price\":\"0.14\", \"size\":\"3231.97\", \"side\":\"SELL\", \"hash\":\"3ef6ddf53cb00804cd41b569365d849afc49ddd8\", \"best_bid\":\"0.13\", \"best_ask\":\"0.14\"}], \"timestamp\":\"1789987930723\", \"event_type\":\"price_change\"}","raw_base64":null}
{"received_ms":1789987930752,"monotonic_ns":1019371582355000,"raw":"{\"market\":\"0x28a45972fccdaf0fba75dacc59725521035e177d09dd92174f9f52740bccb025\", \"price_changes\":[{\"asset_id\":\"61819828071723399190623735325323968706432622380635304641786792960078828866875\", \"price\":\"0.01\", \"size\":\"1491.91\", \"side\":\"BUY\", \"hash\":\"52424b31afd46b4c483885bbe084b091e5b3a37f\", \"best_bid\":\"0.86\", \"best_ask\":\"0.87\"}, {\"asset_id\":\"114356653315647913247200886351065428002113119844334520181865067698979836634569\", \"price\":\"0.99\", \"size\":\"1491.91\", \"side\":\"SELL\", \"hash\":\"c350ba284a52102d70d0f4044b92149530bb836a\", \"best_bid\":\"0.13\", \"best_ask\":\"0.14\"}], \"timestamp\":\"1789987930728\", \"event_type\":\"price_change\"}","raw_base64":null}
{"received_ms":1789987930774,"monotonic_ns":1019371604631700,"raw":"{\"market\":\"0x28a45972fccdaf0fba75dacc59725521035e177d09dd92174f9f52740bccb025\", \"price_changes\":[{\"asset_id\":\"114356653315647913247200886351065428002113119844334520181865067698979836634569\", \"price\":\"0.07\", \"size\":\"7314.71\", \"side\":\"BUY\", \"hash\":\"a3fedd3714b149b54b111a3d7b23ebb73b7b2e18\", \"best_bid\":\"0.13\", \"best_ask\":\"0.14\"}, {\"asset_id\":\"61819828071723399190623735325323968706432622380635304641786792960078828866875\", \"price\":\"0.93\", \"size\":\"7314.71\", \"side\":\"SELL\", \"hash\":\"e20d7b096039accce34cd398710afb68d414e32d\", \"best_bid\":\"0.86\", \"best_ask\":\"0.87\"}], \"timestamp\":\"1789987930753\", \"event_type\":\"price_change\"}","raw_base64":null}
{"received_ms":1789987930815,"monotonic_ns":1019371646250800,"raw":"{\"market\":\"0x28a45972fccdaf0fba75dacc59725521035e177d09dd92174f9f52740bccb025\", \"price_changes\":[{\"asset_id\":\"61819828071723399190623735325323968706432622380635304641786792960078828866875\", \"price\":\"0.84\", \"size\":\"3040\", \"side\":\"BUY\", \"hash\":\"e5fce36a74bcfa644847f12c06904cdb754fe1f7\", \"best_bid\":\"0.86\", \"best_ask\":\"0.87\"}, {\"asset_id\":\"114356653315647913247200886351065428002113119844334520181865067698979836634569\", \"price\":\"0.16\", \"size\":\"3040\", \"side\":\"SELL\", \"hash\":\"5d4626e358d230f20fa2967b4eb94b154c14e350\", \"best_bid\":\"0.13\", \"best_ask\":\"0.14\"}], \"timestamp\":\"1789987930791\", \"event_type\":\"price_change\"}","raw_base64":null}
{"received_ms":1789987930816,"monotonic_ns":1019371646298000,"raw":"{\"market\":\"0x28a45972fccdaf0fba75dacc59725521035e177d09dd92174f9f52740bccb025\", \"price_changes\":[{\"asset_id\":\"61819828071723399190623735325323968706432622380635304641786792960078828866875\", \"price\":\"0.84\", \"size\":\"3015\", \"side\":\"BUY\", \"hash\":\"8b7210f70b4f3e24812d56cfa3fd0499b3554744\", \"best_bid\":\"0.86\", \"best_ask\":\"0.87\"}, {\"asset_id\":\"114356653315647913247200886351065428002113119844334520181865067698979836634569\", \"price\":\"0.16\", \"size\":\"3015\", \"side\":\"SELL\", \"hash\":\"9248b3c07f86bef7a95d58f72a1bd8cb3d67b1ac\", \"best_bid\":\"0.13\", \"best_ask\":\"0.14\"}], \"timestamp\":\"1789987930793\", \"event_type\":\"price_change\"}","raw_base64":null}
{"received_ms":1789987930827,"monotonic_ns":1019371657266100,"raw":"{\"market\":\"0x28a45972fccdaf0fba75dacc59725521035e177d09dd92174f9f52740bccb025\", \"price_changes\":[{\"asset_id\":\"61819828071723399190623735325323968706432622380635304641786792960078828866875\", \"price\":\"0.86\", \"size\":\"1852.97\", \"side\":\"BUY\", \"hash\":\"3cd65c35499cee203eecd8c69f4842e042adf1fe\", \"best_bid\":\"0.86\", \"best_ask\":\"0.87\"}, {\"asset_id\":\"114356653315647913247200886351065428002113119844334520181865067698979836634569\", \"price\":\"0.14\", \"size\":\"1852.97\", \"side\":\"SELL\", \"hash\":\"76c2a674ccd9884f0789cacd494b565c5de8b190\", \"best_bid\":\"0.13\", \"best_ask\":\"0.14\"}], \"timestamp\":\"1789987930805\", \"event_type\":\"price_change\"}","raw_base64":null}
{"received_ms":1789987930828,"monotonic_ns":1019371658459300,"raw":"{\"market\":\"0x28a45972fccdaf0fba75dacc59725521035e177d09dd92174f9f52740bccb025\", \"price_changes\":[{\"asset_id\":\"114356653315647913247200886351065428002113119844334520181865067698979836634569\", \"price\":\"0.06\", \"size\":\"5862.67\", \"side\":\"BUY\", \"hash\":\"56bab897796840ce8e8caab3cb73b46e636e26dd\", \"best_bid\":\"0.13\", \"best_ask\":\"0.14\"}, {\"asset_id\":\"61819828071723399190623735325323968706432622380635304641786792960078828866875\", \"price\":\"0.94\", \"size\":\"5862.67\", \"side\":\"SELL\", \"hash\":\"f6cf131afd62703ee39a106cf398b18eca77d256\", \"best_bid\":\"0.86\", \"best_ask\":\"0.87\"}], \"timestamp\":\"1789987930806\", \"event_type\":\"price_change\"}","raw_base64":null}
{"received_ms":1789987930846,"monotonic_ns":1019371676867100,"raw":"{\"market\":\"0x28a45972fccdaf0fba75dacc59725521035e177d09dd92174f9f52740bccb025\", \"price_changes\":[{\"asset_id\":\"114356653315647913247200886351065428002113119844334520181865067698979836634569\", \"price\":\"0.07\", \"size\":\"7029.71\", \"side\":\"BUY\", \"hash\":\"89255bd2a8b16deb5f964bded7d9189b3c2f8fa9\", \"best_bid\":\"0.13\", \"best_ask\":\"0.14\"}, {\"asset_id\":\"61819828071723399190623735325323968706432622380635304641786792960078828866875\", \"price\":\"0.93\", \"size\":\"7029.71\", \"side\":\"SELL\", \"hash\":\"f63be462cb778a7f22c4f260dc801b97d195f658\", \"best_bid\":\"0.86\", \"best_ask\":\"0.87\"}], \"timestamp\":\"1789987930819\", \"event_type\":\"price_change\"}","raw_base64":null}
{"received_ms":1789987930846,"monotonic_ns":1019371676916600,"raw":"{\"market\":\"0x28a45972fccdaf0fba75dacc59725521035e177d09dd92174f9f52740bccb025\", \"price_changes\":[{\"asset_id\":\"61819828071723399190623735325323968706432622380635304641786792960078828866875\", \"price\":\"0.92\", \"size\":\"719.5\", \"side\":\"SELL\", \"hash\":\"26b793d4ba0120d7ba92282766411e8bfd1ed2d2\", \"best_bid\":\"0.86\", \"best_ask\":\"0.87\"}, {\"asset_id\":\"114356653315647913247200886351065428002113119844334520181865067698979836634569\", \"price\":\"0.08\", \"size\":\"719.5\", \"side\":\"BUY\", \"hash\":\"c49c954abfb08ea684186ffbf21df275248d09c7\", \"best_bid\":\"0.13\", \"best_ask\":\"0.14\"}], \"timestamp\":\"1789987930822\", \"event_type\":\"price_change\"}","raw_base64":null}
{"received_ms":1789987930854,"monotonic_ns":1019371684538300,"raw":"{\"market\":\"0x28a45972fccdaf0fba75dacc59725521035e177d09dd92174f9f52740bccb025\", \"price_changes\":[{\"asset_id\":\"61819828071723399190623735325323968706432622380635304641786792960078828866875\", \"price\":\"0.86\", \"size\":\"1842.97\", \"side\":\"BUY\", \"hash\":\"f6a422ad98206f3395a4605bcb0c48515b396ac6\", \"best_bid\":\"0.86\", \"best_ask\":\"0.87\"}, {\"asset_id\":\"114356653315647913247200886351065428002113119844334520181865067698979836634569\", \"price\":\"0.14\", \"size\":\"1842.97\", \"side\":\"SELL\", \"hash\":\"cb474c182de559dec33f35437967257d4062bb7f\", \"best_bid\":\"0.13\", \"best_ask\":\"0.14\"}], \"timestamp\":\"1789987930833\", \"event_type\":\"price_change\"}","raw_base64":null}
{"received_ms":1789987930857,"monotonic_ns":1019371687737900,"raw":"{\"market\":\"0x28a45972fccdaf0fba75dacc59725521035e177d09dd92174f9f52740bccb025\", \"price_changes\":[{\"asset_id\":\"61819828071723399190623735325323968706432622380635304641786792960078828866875\", \"price\":\"0.86\", \"size\":\"1827.8\", \"side\":\"BUY\", \"hash\":\"6647af8a47ba4373a5ff0fa1b93ac54f29090b3a\", \"best_bid\":\"0.86\", \"best_ask\":\"0.87\"}, {\"asset_id\":\"114356653315647913247200886351065428002113119844334520181865067698979836634569\", \"price\":\"0.14\", \"size\":\"1827.8\", \"side\":\"SELL\", \"hash\":\"36f9f51f13d3099e5f7df5b1d0112b8debfe8ace\", \"best_bid\":\"0.13\", \"best_ask\":\"0.14\"}], \"timestamp\":\"1789987930837\", \"event_type\":\"price_change\"}","raw_base64":null}
{"received_ms":1789987930859,"monotonic_ns":1019371690090500,"raw":"{\"market\":\"0x28a45972fccdaf0fba75dacc59725521035e177d09dd92174f9f52740bccb025\", \"price_changes\":[{\"asset_id\":\"61819828071723399190623735325323968706432622380635304641786792960078828866875\", \"price\":\"0.84\", \"size\":\"3040\", \"side\":\"BUY\", \"hash\":\"745cb9f804a8401210406f4ccd96a5088dd785d3\", \"best_bid\":\"0.86\", \"best_ask\":\"0.87\"}, {\"asset_id\":\"114356653315647913247200886351065428002113119844334520181865067698979836634569\", \"price\":\"0.16\", \"size\":\"3040\", \"side\":\"SELL\", \"hash\":\"cecdb00f5c3a771d8719297ec7c97ec828d8a229\", \"best_bid\":\"0.13\", \"best_ask\":\"0.14\"}], \"timestamp\":\"1789987930838\", \"event_type\":\"price_change\"}","raw_base64":null}
{"received_ms":1789987930859,"monotonic_ns":1019371690172000,"raw":"{\"market\":\"0x28a45972fccdaf0fba75dacc59725521035e177d09dd92174f9f52740bccb025\", \"price_changes\":[{\"asset_id\":\"61819828071723399190623735325323968706432622380635304641786792960078828866875\", \"price\":\"0.86\", \"size\":\"4479.8\", \"side\":\"BUY\", \"hash\":\"8b101f2b5c3743483e0dc1c0051b64f384dd6062\", \"best_bid\":\"0.86\", \"best_ask\":\"0.87\"}, {\"asset_id\":\"114356653315647913247200886351065428002113119844334520181865067698979836634569\", \"price\":\"0.14\", \"size\":\"4479.8\", \"side\":\"SELL\", \"hash\":\"aac114f91d1d5f0aa75ebc2e1344c931ddbf398a\", \"best_bid\":\"0.13\", \"best_ask\":\"0.14\"}], \"timestamp\":\"1789987930839\", \"event_type\":\"price_change\"}","raw_base64":null}
{"received_ms":1789987930862,"monotonic_ns":1019371692494100,"raw":"{\"market\":\"0x28a45972fccdaf0fba75dacc59725521035e177d09dd92174f9f52740bccb025\", \"price_changes\":[{\"asset_id\":\"61819828071723399190623735325323968706432622380635304641786792960078828866875\", \"price\":\"0.85\", \"size\":\"4904.35\", \"side\":\"BUY\", \"hash\":\"85b926ff467b7dfd7f84990692b28011536088a0\", \"best_bid\":\"0.86\", \"best_ask\":\"0.87\"}, {\"asset_id\":\"114356653315647913247200886351065428002113119844334520181865067698979836634569\", \"price\":\"0.15\", \"size\":\"4904.35\", \"side\":\"SELL\", \"hash\":\"8fae8c7df538dd38b0c9a690b8e0601b776eb5bf\", \"best_bid\":\"0.13\", \"best_ask\":\"0.14\"}], \"timestamp\":\"1789987930840\", \"event_type\":\"price_change\"}","raw_base64":null}
{"received_ms":1789987930862,"monotonic_ns":1019371692581500,"raw":"{\"market\":\"0x28a45972fccdaf0fba75dacc59725521035e177d09dd92174f9f52740bccb025\", \"price_changes\":[{\"asset_id\":\"61819828071723399190623735325323968706432622380635304641786792960078828866875\", \"price\":\"0.86\", \"size\":\"4474.8\", \"side\":\"BUY\", \"hash\":\"7c30c7632f9029f04bfc9f87145b5d30dc85a343\", \"best_bid\":\"0.86\", \"best_ask\":\"0.87\"}, {\"asset_id\":\"114356653315647913247200886351065428002113119844334520181865067698979836634569\", \"price\":\"0.14\", \"size\":\"4474.8\", \"side\":\"SELL\", \"hash\":\"557b16861f934060cfa78275df3421bca293c33f\", \"best_bid\":\"0.13\", \"best_ask\":\"0.14\"}], \"timestamp\":\"1789987930840\", \"event_type\":\"price_change\"}","raw_base64":null}
{"received_ms":1789987930876,"monotonic_ns":1019371706530500,"raw":"{\"market\":\"0x28a45972fccdaf0fba75dacc59725521035e177d09dd92174f9f52740bccb025\", \"price_changes\":[{\"asset_id\":\"61819828071723399190623735325323968706432622380635304641786792960078828866875\", \"price\":\"0.76\", \"size\":\"434.91\", \"side\":\"BUY\", \"hash\":\"f7756eee3182d04bf2f9a246098eed0519c10f83\", \"best_bid\":\"0.86\", \"best_ask\":\"0.87\"}, {\"asset_id\":\"114356653315647913247200886351065428002113119844334520181865067698979836634569\", \"price\":\"0.24\", \"size\":\"434.91\", \"side\":\"SELL\", \"hash\":\"bc911084636aa15b3617fed7db88be54dbca1495\", \"best_bid\":\"0.13\", \"best_ask\":\"0.14\"}], \"timestamp\":\"1789987930854\", \"event_type\":\"price_change\"}","raw_base64":null}
{"received_ms":1789987930881,"monotonic_ns":1019371711516700,"raw":"{\"market\":\"0x28a45972fccdaf0fba75dacc59725521035e177d09dd92174f9f52740bccb025\", \"price_changes\":[{\"asset_id\":\"61819828071723399190623735325323968706432622380635304641786792960078828866875\", \"price\":\"0.86\", \"size\":\"4454.8\", \"side\":\"BUY\", \"hash\":\"4d81ebef490266ecdadd3f75fe0aee874a11ac69\", \"best_bid\":\"0.86\", \"best_ask\":\"0.87\"}, {\"asset_id\":\"114356653315647913247200886351065428002113119844334520181865067698979836634569\", \"price\":\"0.14\", \"size\":\"4454.8\", \"side\":\"SELL\", \"hash\":\"f242e5c0dc113415d4421db7f18bd4ba5eee1447\", \"best_bid\":\"0.13\", \"best_ask\":\"0.14\"}], \"timestamp\":\"1789987930859\", \"event_type\":\"price_change\"}","raw_base64":null}
{"received_ms":1789987930881,"monotonic_ns":1019371711604000,"raw":"{\"market\":\"0x28a45972fccdaf0fba75dacc59725521035e177d09dd92174f9f52740bccb025\", \"asset_id\":\"114356653315647913247200886351065428002113119844334520181865067698979836634569\", \"bids\":[{\"price\":\"0.01\", \"size\":\"1689.43\"}, {\"price\":\"0.02\", \"size\":\"574.82\"}, {\"price\":\"0.03\", \"size\":\"3992.57\"}, {\"price\":\"0.04\", \"size\":\"630.48\"}, {\"price\":\"0.05\", \"size\":\"5652\"}, {\"price\":\"0.06\", \"size\":\"5862.67\"}, {\"price\":\"0.07\", \"size\":\"7029.71\"}, {\"price\":\"0.08\", \"size\":\"719.5\"}, {\"price\":\"0.09\", \"size\":\"618.12\"}, {\"price\":\"0.1\", \"size\":\"520\"}, {\"price\":\"0.11\", \"size\":\"138.1\"}, {\"price\":\"0.12\", \"size\":\"511\"}, {\"price\":\"0.13\", \"size\":\"265\"}], \"asks\":[{\"price\":\"0.99\", \"size\":\"1491.91\"}, {\"price\":\"0.98\", \"size\":\"385.35\"}, {\"price\":\"0.97\", \"size\":\"1270.08\"}, {\"price\":\"0.96\", \"size\":\"165.3\"}, {\"price\":\"0.95\", \"size\":\"237.01\"}, {\"price\":\"0.94\", \"size\":\"85.67\"}, {\"price\":\"0.93\", \"size\":\"159.29\"}, {\"price\":\"0.92\", \"size\":\"81.51\"}, {\"price\":\"0.91\", \"size\":\"252.12\"}, {\"price\":\"0.9\", \"size\":\"99.01\"}, {\"price\":\"0.89\", \"size\":\"129.1\"}, {\"price\":\"0.88\", \"size\":\"67.34\"}, {\"price\":\"0.87\", \"size\":\"123.7\"}, {\"price\":\"0.86\", \"size\":\"66.15\"}, {\"price\":\"0.85\", \"size\":\"197.39\"}, {\"price\":\"0.84\", \"size\":\"65.25\"}, {\"price\":\"0.83\", \"size\":\"115.89\"}, {\"price\":\"0.82\", \"size\":\"64.56\"}, {\"price\":\"0.81\", \"size\":\"113.27\"}, {\"price\":\"0.8\", \"size\":\"74.81\"}, {\"price\":\"0.79\", \"size\":\"112\"}, {\"price\":\"0.78\", \"size\":\"64\"}, {\"price\":\"0.77\", \"size\":\"111\"}, {\"price\":\"0.76\", \"size\":\"64\"}, {\"price\":\"0.75\", \"size\":\"110\"}, {\"price\":\"0.74\", \"size\":\"250\"}, {\"price\":\"0.73\", \"size\":\"289\"}, {\"price\":\"0.72\", \"size\":\"244\"}, {\"price\":\"0.71\", \"size\":\"297\"}, {\"price\":\"0.7\", \"size\":\"281\"}, {\"price\":\"0.69\", \"size\":\"297\"}, {\"price\":\"0.68\", \"size\":\"267\"}, {\"price\":\"0.67\", \"size\":\"310\"}, {\"price\":\"0.66\", \"size\":\"272.64\"}, {\"price\":\"0.65\", \"size\":\"297\"}, {\"price\":\"0.64\", \"size\":\"285.33\"}, {\"price\":\"0.63\", \"size\":\"297\"}, {\"price\":\"0.62\", \"size\":\"272.05\"}, {\"price\":\"0.61\", \"size\":\"310\"}, {\"price\":\"0.6\", \"size\":\"1067\"}, {\"price\":\"0.59\", \"size\":\"297\"}, {\"price\":\"0.58\", \"size\":\"279\"}, {\"price\":\"0.57\", \"size\":\"297\"}, {\"price\":\"0.56\", \"size\":\"267\"}, {\"price\":\"0.55\", \"size\":\"297\"}, {\"price\":\"0.54\", \"size\":\"267\"}, {\"price\":\"0.53\", \"size\":\"302\"}, {\"price\":\"0.52\", \"size\":\"267\"}, {\"price\":\"0.51\", \"size\":\"297\"}, {\"price\":\"0.5\", \"size\":\"267\"}, {\"price\":\"0.49\", \"size\":\"297\"}, {\"price\":\"0.48\", \"size\":\"267\"}, {\"price\":\"0.47\", \"size\":\"297\"}, {\"price\":\"0.46\", \"size\":\"267\"}, {\"price\":\"0.45\", \"size\":\"297\"}, {\"price\":\"0.44\", \"size\":\"267\"}, {\"price\":\"0.43\", \"size\":\"309\"}, {\"price\":\"0.42\", \"size\":\"267\"}, {\"price\":\"0.41\", \"size\":\"297\"}, {\"price\":\"0.4\", \"size\":\"279\"}, {\"price\":\"0.39\", \"size\":\"297\"}, {\"price\":\"0.38\", \"size\":\"267\"}, {\"price\":\"0.37\", \"size\":\"309\"}, {\"price\":\"0.36\", \"size\":\"267\"}, {\"price\":\"0.35\", \"size\":\"297\"}, {\"price\":\"0.34\", \"size\":\"267\"}, {\"price\":\"0.33\", \"size\":\"322\"}, {\"price\":\"0.32\", \"size\":\"292\"}, {\"price\":\"0.31\", \"size\":\"322\"}, {\"price\":\"0.3\", \"size\":\"292\"}, {\"price\":\"0.29\", \"size\":\"403\"}, {\"price\":\"0.28\", \"size\":\"438.8\"}, {\"price\":\"0.27\", \"size\":\"404\"}, {\"price\":\"0.26\", \"size\":\"455.53\"}, {\"price\":\"0.25\", \"size\":\"500\"}, {\"price\":\"0.24\", \"size\":\"434.91\"}, {\"price\":\"0.23\", \"size\":\"547.49\"}, {\"price\":\"0.22\", \"size\":\"433.82\"}, {\"price\":\"0.21\", \"size\":\"427\"}, {\"price\":\"0.2\", \"size\":\"562\"}, {\"price\":\"0.19\", \"size\":\"590\"}, {\"price\":\"0.18\", \"size\":\"753\"}, {\"price\":\"0.17\", \"size\":\"524\"}, {\"price\":\"0.16\", \"size\":\"3040\"}, {\"price\":\"0.15\", \"size\":\"4904.35\"}, {\"price\":\"0.14\", \"size\":\"4454.8\"}], \"hash\":\"f242e5c0dc113415d4421db7f18bd4ba5eee1447\", \"timestamp\":\"1789987930859\", \"event_type\":\"book\"}","raw_base64":null}
{"received_ms":1789987930881,"monotonic_ns":1019371712175100,"raw":"{\"market\":\"0x28a45972fccdaf0fba75dacc59725521035e177d09dd92174f9f52740bccb025\", \"asset_id\":\"61819828071723399190623735325323968706432622380635304641786792960078828866875\", \"bids\":[{\"price\":\"0.01\", \"size\":\"1491.91\"}, {\"price\":\"0.02\", \"size\":\"385.35\"}, {\"price\":\"0.03\", \"size\":\"1270.08\"}, {\"price\":\"0.04\", \"size\":\"165.3\"}, {\"price\":\"0.05\", \"size\":\"237.01\"}, {\"price\":\"0.06\", \"size\":\"85.67\"}, {\"price\":\"0.07\", \"size\":\"159.29\"}, {\"price\":\"0.08\", \"size\":\"81.51\"}, {\"price\":\"0.09\", \"size\":\"252.12\"}, {\"price\":\"0.1\", \"size\":\"99.01\"}, {\"price\":\"0.11\", \"size\":\"129.1\"}, {\"price\":\"0.12\", \"size\":\"67.34\"}, {\"price\":\"0.13\", \"size\":\"123.7\"}, {\"price\":\"0.14\", \"size\":\"66.15\"}, {\"price\":\"0.15\", \"size\":\"197.39\"}, {\"price\":\"0.16\", \"size\":\"65.25\"}, {\"price\":\"0.17\", \"size\":\"115.89\"}, {\"price\":\"0.18\", \"size\":\"64.56\"}, {\"price\":\"0.19\", \"size\":\"113.27\"}, {\"price\":\"0.2\", \"size\":\"74.81\"}, {\"price\":\"0.21\", \"size\":\"112\"}, {\"price\":\"0.22\", \"size\":\"64\"}, {\"price\":\"0.23\", \"size\":\"111\"}, {\"price\":\"0.24\", \"size\":\"64\"}, {\"price\":\"0.25\", \"size\":\"110\"}, {\"price\":\"0.26\", \"size\":\"250\"}, {\"price\":\"0.27\", \"size\":\"289\"}, {\"price\":\"0.28\", \"size\":\"244\"}, {\"price\":\"0.29\", \"size\":\"297\"}, {\"price\":\"0.3\", \"size\":\"281\"}, {\"price\":\"0.31\", \"size\":\"297\"}, {\"price\":\"0.32\", \"size\":\"267\"}, {\"price\":\"0.33\", \"size\":\"310\"}, {\"price\":\"0.34\", \"size\":\"272.64\"}, {\"price\":\"0.35\", \"size\":\"297\"}, {\"price\":\"0.36\", \"size\":\"285.33\"}, {\"price\":\"0.37\", \"size\":\"297\"}, {\"price\":\"0.38\", \"size\":\"272.05\"}, {\"price\":\"0.39\", \"size\":\"310\"}, {\"price\":\"0.4\", \"size\":\"1067\"}, {\"price\":\"0.41\", \"size\":\"297\"}, {\"price\":\"0.42\", \"size\":\"279\"}, {\"price\":\"0.43\", \"size\":\"297\"}, {\"price\":\"0.44\", \"size\":\"267\"}, {\"price\":\"0.45\", \"size\":\"297\"}, {\"price\":\"0.46\", \"size\":\"267\"}, {\"price\":\"0.47\", \"size\":\"302\"}, {\"price\":\"0.48\", \"size\":\"267\"}, {\"price\":\"0.49\", \"size\":\"297\"}, {\"price\":\"0.5\", \"size\":\"267\"}, {\"price\":\"0.51\", \"size\":\"297\"}, {\"price\":\"0.52\", \"size\":\"267\"}, {\"price\":\"0.53\", \"size\":\"297\"}, {\"price\":\"0.54\", \"size\":\"267\"}, {\"price\":\"0.55\", \"size\":\"297\"}, {\"price\":\"0.56\", \"size\":\"267\"}, {\"price\":\"0.57\", \"size\":\"309\"}, {\"price\":\"0.58\", \"size\":\"267\"}, {\"price\":\"0.59\", \"size\":\"297\"}, {\"price\":\"0.6\", \"size\":\"279\"}, {\"price\":\"0.61\", \"size\":\"297\"}, {\"price\":\"0.62\", \"size\":\"267\"}, {\"price\":\"0.63\", \"size\":\"309\"}, {\"price\":\"0.64\", \"size\":\"267\"}, {\"price\":\"0.65\", \"size\":\"297\"}, {\"price\":\"0.66\", \"size\":\"267\"}, {\"price\":\"0.67\", \"size\":\"322\"}, {\"price\":\"0.68\", \"size\":\"292\"}, {\"price\":\"0.69\", \"size\":\"322\"}, {\"price\":\"0.7\", \"size\":\"292\"}, {\"price\":\"0.71\", \"size\":\"403\"}, {\"price\":\"0.72\", \"size\":\"438.8\"}, {\"price\":\"0.73\", \"size\":\"404\"}, {\"price\":\"0.74\", \"size\":\"455.53\"}, {\"price\":\"0.75\", \"size\":\"500\"}, {\"price\":\"0.76\", \"size\":\"434.91\"}, {\"price\":\"0.77\", \"size\":\"547.49\"}, {\"price\":\"0.78\", \"size\":\"433.82\"}, {\"price\":\"0.79\", \"size\":\"427\"}, {\"price\":\"0.8\", \"size\":\"562\"}, {\"price\":\"0.81\", \"size\":\"590\"}, {\"price\":\"0.82\", \"size\":\"753\"}, {\"price\":\"0.83\", \"size\":\"524\"}, {\"price\":\"0.84\", \"size\":\"3040\"}, {\"price\":\"0.85\", \"size\":\"4904.35\"}, {\"price\":\"0.86\", \"size\":\"4454.8\"}], \"asks\":[{\"price\":\"0.99\", \"size\":\"1689.43\"}, {\"price\":\"0.98\", \"size\":\"574.82\"}, {\"price\":\"0.97\", \"size\":\"3992.57\"}, {\"price\":\"0.96\", \"size\":\"630.48\"}, {\"price\":\"0.95\", \"size\":\"5652\"}, {\"price\":\"0.94\", \"size\":\"5862.67\"}, {\"price\":\"0.93\", \"size\":\"7029.71\"}, {\"price\":\"0.92\", \"size\":\"719.5\"}, {\"price\":\"0.91\", \"size\":\"618.12\"}, {\"price\":\"0.9\", \"size\":\"520\"}, {\"price\":\"0.89\", \"size\":\"138.1\"}, {\"price\":\"0.88\", \"size\":\"511\"}, {\"price\":\"0.87\", \"size\":\"265\"}], \"hash\":\"4d81ebef490266ecdadd3f75fe0aee874a11ac69\", \"timestamp\":\"1789987930859\", \"event_type\":\"book\"}","raw_base64":null}
{"received_ms":1789987930889,"monotonic_ns":1019371719826600,"raw":"{\"market\":\"0x28a45972fccdaf0fba75dacc59725521035e177d09dd92174f9f52740bccb025\", \"price_changes\":[{\"asset_id\":\"61819828071723399190623735325323968706432622380635304641786792960078828866875\", \"price\":\"0.76\", \"size\":\"424.91\", \"side\":\"BUY\", \"hash\":\"6218af532406665c397e7280b5f5ab39865b088b\", \"best_bid\":\"0.86\", \"best_ask\":\"0.87\"}, {\"asset_id\":\"114356653315647913247200886351065428002113119844334520181865067698979836634569\", \"price\":\"0.24\", \"size\":\"424.91\", \"side\":\"SELL\", \"hash\":\"36efd2da92569fe29d53a2cc746ef972bb876d1f\", \"best_bid\":\"0.13\", \"best_ask\":\"0.14\"}], \"timestamp\":\"1789987930863\", \"event_type\":\"price_change\"}","raw_base64":null}
{"received_ms":1789987930889,"monotonic_ns":1019371719935700,"raw":"{\"market\":\"0x28a45972fccdaf0fba75dacc59725521035e177d09dd92174f9f52740bccb025\", \"price_changes\":[{\"asset_id\":\"61819828071723399190623735325323968706432622380635304641786792960078828866875\", \"price\":\"0.86\", \"size\":\"4464.8\", \"side\":\"BUY\", \"hash\":\"a2647354ebb6794403e543cffbef78d30999ed73\", \"best_bid\":\"0.86\", \"best_ask\":\"0.87\"}, {\"asset_id\":\"114356653315647913247200886351065428002113119844334520181865067698979836634569\", \"price\":\"0.14\", \"size\":\"4464.8\", \"side\":\"SELL\", \"hash\":\"f53dd5001ba7fabef4eeb43d5d4a2f90a58296e4\", \"best_bid\":\"0.13\", \"best_ask\":\"0.14\"}], \"timestamp\":\"1789987930866\", \"event_type\":\"price_change\"}","raw_base64":null}
{"received_ms":1789987930889,"monotonic_ns":1019371719989500,"raw":"{\"market\":\"0x28a45972fccdaf0fba75dacc59725521035e177d09dd92174f9f52740bccb025\", \"price_changes\":[{\"asset_id\":\"61819828071723399190623735325323968706432622380635304641786792960078828866875\", \"price\":\"0.86\", \"size\":\"4479.97\", \"side\":\"BUY\", \"hash\":\"024d902964e67418ead2dfa0c2724e24679bf016\", \"best_bid\":\"0.86\", \"best_ask\":\"0.87\"}, {\"asset_id\":\"114356653315647913247200886351065428002113119844334520181865067698979836634569\", \"price\":\"0.14\", \"size\":\"4479.97\", \"side\":\"SELL\", \"hash\":\"120af2e28d6688322b08a3aaa90e93733b745afa\", \"best_bid\":\"0.13\", \"best_ask\":\"0.14\"}], \"timestamp\":\"1789987930868\", \"event_type\":\"price_change\"}","raw_base64":null}
{"received_ms":1789987930896,"monotonic_ns":1019371727041600,"raw":"{\"market\":\"0x28a45972fccdaf0fba75dacc59725521035e177d09dd92174f9f52740bccb025\", \"price_changes\":[{\"asset_id\":\"61819828071723399190623735325323968706432622380635304641786792960078828866875\", \"price\":\"0.86\", \"size\":\"4484.97\", \"side\":\"BUY\", \"hash\":\"f3831dc8823dd11e3010fda1b44e3f5d1f0dc41a\", \"best_bid\":\"0.86\", \"best_ask\":\"0.87\"}, {\"asset_id\":\"114356653315647913247200886351065428002113119844334520181865067698979836634569\", \"price\":\"0.14\", \"size\":\"4484.97\", \"side\":\"SELL\", \"hash\":\"53bdb0ac0877f94f7652154d204ea120d79b775d\", \"best_bid\":\"0.13\", \"best_ask\":\"0.14\"}], \"timestamp\":\"1789987930876\", \"event_type\":\"price_change\"}","raw_base64":null}
{"received_ms":1789987930899,"monotonic_ns":1019371729574700,"raw":"{\"market\":\"0x28a45972fccdaf0fba75dacc59725521035e177d09dd92174f9f52740bccb025\", \"price_changes\":[{\"asset_id\":\"114356653315647913247200886351065428002113119844334520181865067698979836634569\", \"price\":\"0.07\", \"size\":\"7254.71\", \"side\":\"BUY\", \"hash\":\"5219bb7eb61180df4f6faa2da1049c58428cd22c\", \"best_bid\":\"0.13\", \"best_ask\":\"0.14\"}, {\"asset_id\":\"61819828071723399190623735325323968706432622380635304641786792960078828866875\", \"price\":\"0.93\", \"size\":\"7254.71\", \"side\":\"SELL\", \"hash\":\"374120c0d6709ee24c5bc3242226f53cee681dfc\", \"best_bid\":\"0.86\", \"best_ask\":\"0.87\"}], \"timestamp\":\"1789987930879\", \"event_type\":\"price_change\"}","raw_base64":null}
{"received_ms":1789987930902,"monotonic_ns":1019371732675300,"raw":"{\"market\":\"0x28a45972fccdaf0fba75dacc59725521035e177d09dd92174f9f52740bccb025\", \"price_changes\":[{\"asset_id\":\"61819828071723399190623735325323968706432622380635304641786792960078828866875\", \"price\":\"0.75\", \"size\":\"520\", \"side\":\"BUY\", \"hash\":\"991c602e49c21d608b0763a1d6e5e64c34bbb670\", \"best_bid\":\"0.86\", \"best_ask\":\"0.87\"}, {\"asset_id\":\"114356653315647913247200886351065428002113119844334520181865067698979836634569\", \"price\":\"0.25\", \"size\":\"520\", \"side\":\"SELL\", \"hash\":\"f3814d5d0a946b0ea4f04215dedabc5d6098cdb2\", \"best_bid\":\"0.13\", \"best_ask\":\"0.14\"}], \"timestamp\":\"1789987930879\", \"event_type\":\"price_change\"}","raw_base64":null}
{"received_ms":1789987930902,"monotonic_ns":1019371732760600,"raw":"{\"market\":\"0x28a45972fccdaf0fba75dacc59725521035e177d09dd92174f9f52740bccb025\", \"price_changes\":[{\"asset_id\":\"61819828071723399190623735325323968706432622380635304641786792960078828866875\", \"price\":\"0.77\", \"size\":\"567.49\", \"side\":\"BUY\", \"hash\":\"096d0137b6884f5908207e0a858e018e7c200f69\", \"best_bid\":\"0.86\", \"best_ask\":\"0.87\"}, {\"asset_id\":\"114356653315647913247200886351065428002113119844334520181865067698979836634569\", \"price\":\"0.23\", \"size\":\"567.49\", \"side\":\"SELL\", \"hash\":\"0edb6d47b03feb07ef39fb98e8422be4e3475b1c\", \"best_bid\":\"0.13\", \"best_ask\":\"0.14\"}], \"timestamp\":\"1789987930880\", \"event_type\":\"price_change\"}","raw_base64":null}
{"received_ms":1789987930902,"monotonic_ns":1019371732804300,"raw":"{\"market\":\"0x28a45972fccdaf0fba75dacc59725521035e177d09dd92174f9f52740bccb025\", \"price_changes\":[{\"asset_id\":\"61819828071723399190623735325323968706432622380635304641786792960078828866875\", \"price\":\"0.79\", \"size\":\"487\", \"side\":\"BUY\", \"hash\":\"20b176a259aa598bfea7aeb9a56b6f93b8fe4700\", \"best_bid\":\"0.86\", \"best_ask\":\"0.87\"}, {\"asset_id\":\"114356653315647913247200886351065428002113119844334520181865067698979836634569\", \"price\":\"0.21\", \"size\":\"487\", \"side\":\"SELL\", \"hash\":\"0b79f5db5b8330972c2e4379b153b14ffcd86a81\", \"best_bid\":\"0.13\", \"best_ask\":\"0.14\"}], \"timestamp\":\"1789987930881\", \"event_type\":\"price_change\"}","raw_base64":null}
{"received_ms":1789987930902,"monotonic_ns":1019371732844200,"raw":"{\"market\":\"0x28a45972fccdaf0fba75dacc59725521035e177d09dd92174f9f52740bccb025\", \"asset_id\":\"114356653315647913247200886351065428002113119844334520181865067698979836634569\", \"price\":\"0.14\", \"size\":\"20\", \"fee_rate_bps\":\"0\", \"side\":\"BUY\", \"timestamp\":\"1789987930880\", \"event_type\":\"last_trade_price\", \"transaction_hash\":\"0xc3187651a003bee8868d4538c51cf6a0ccfe96d58517a80287c3aaa48543cf6e\"}","raw_base64":null}
{"received_ms":1789987930902,"monotonic_ns":1019371732908600,"raw":"{\"market\":\"0x28a45972fccdaf0fba75dacc59725521035e177d09dd92174f9f52740bccb025\", \"price_changes\":[{\"asset_id\":\"61819828071723399190623735325323968706432622380635304641786792960078828866875\", \"price\":\"0.77\", \"size\":\"547.49\", \"side\":\"BUY\", \"hash\":\"842d372a3d574508e7babe603947a30545c7dbd4\", \"best_bid\":\"0.86\", \"best_ask\":\"0.87\"}, {\"asset_id\":\"114356653315647913247200886351065428002113119844334520181865067698979836634569\", \"price\":\"0.23\", \"size\":\"547.49\", \"side\":\"SELL\", \"hash\":\"37f6d655e175578a966c0cb1d21400d711a37a60\", \"best_bid\":\"0.13\", \"best_ask\":\"0.14\"}], \"timestamp\":\"1789987930881\", \"event_type\":\"price_change\"}","raw_base64":null}
{"received_ms":1789987930902,"monotonic_ns":1019371733088900,"raw":"{\"market\":\"0x28a45972fccdaf0fba75dacc59725521035e177d09dd92174f9f52740bccb025\", \"price_changes\":[{\"asset_id\":\"61819828071723399190623735325323968706432622380635304641786792960078828866875\", \"price\":\"0.75\", \"size\":\"500\", \"side\":\"BUY\", \"hash\":\"842d372a3d574508e7babe603947a30545c7dbd4\", \"best_bid\":\"0.86\", \"best_ask\":\"0.87\"}, {\"asset_id\":\"114356653315647913247200886351065428002113119844334520181865067698979836634569\", \"price\":\"0.25\", \"size\":\"500\", \"side\":\"SELL\", \"hash\":\"37f6d655e175578a966c0cb1d21400d711a37a60\", \"best_bid\":\"0.13\", \"best_ask\":\"0.14\"}], \"timestamp\":\"1789987930881\", \"event_type\":\"price_change\"}","raw_base64":null}
{"received_ms":1789987930902,"monotonic_ns":1019371733136100,"raw":"{\"market\":\"0x28a45972fccdaf0fba75dacc59725521035e177d09dd92174f9f52740bccb025\", \"price_changes\":[{\"asset_id\":\"61819828071723399190623735325323968706432622380635304641786792960078828866875\", \"price\":\"0.79\", \"size\":\"427\", \"side\":\"BUY\", \"hash\":\"842d372a3d574508e7babe603947a30545c7dbd4\", \"best_bid\":\"0.86\", \"best_ask\":\"0.87\"}, {\"asset_id\":\"114356653315647913247200886351065428002113119844334520181865067698979836634569\", \"price\":\"0.21\", \"size\":\"427\", \"side\":\"SELL\", \"hash\":\"37f6d655e175578a966c0cb1d21400d711a37a60\", \"best_bid\":\"0.13\", \"best_ask\":\"0.14\"}], \"timestamp\":\"1789987930881\", \"event_type\":\"price_change\"}","raw_base64":null}
{"received_ms":1789987930934,"monotonic_ns":1019371764730000,"raw":"{\"market\":\"0x28a45972fccdaf0fba75dacc59725521035e177d09dd92174f9f52740bccb025\", \"price_changes\":[{\"asset_id\":\"114356653315647913247200886351065428002113119844334520181865067698979836634569\", \"price\":\"0.01\", \"size\":\"1669.43\", \"side\":\"BUY\", \"hash\":\"21c2e81b73df94443dde62e55ee1baff06745823\", \"best_bid\":\"0.13\", \"best_ask\":\"0.14\"}, {\"asset_id\":\"61819828071723399190623735325323968706432622380635304641786792960078828866875\", \"price\":\"0.99\", \"size\":\"1669.43\", \"side\":\"SELL\", \"hash\":\"8f6d914ac0f4a5ac3333b8fe9c1f64ec6eebf58c\", \"best_bid\":\"0.86\", \"best_ask\":\"0.87\"}], \"timestamp\":\"1789987930907\", \"event_type\":\"price_change\"}","raw_base64":null}
{"received_ms":1789987930934,"monotonic_ns":1019371764825700,"raw":"{\"market\":\"0x28a45972fccdaf0fba75dacc59725521035e177d09dd92174f9f52740bccb025\", \"price_changes\":[{\"asset_id\":\"114356653315647913247200886351065428002113119844334520181865067698979836634569\", \"price\":\"0.07\", \"size\":\"7029.71\", \"side\":\"BUY\", \"hash\":\"47701fa73e7e171f858c3fdd7230e730c74dc764\", \"best_bid\":\"0.13\", \"best_ask\":\"0.14\"}, {\"asset_id\":\"61819828071723399190623735325323968706432622380635304641786792960078828866875\", \"price\":\"0.93\", \"size\":\"7029.71\", \"side\":\"SELL\", \"hash\":\"fae2f3189e8aefc550af6d0d2d354445758dddd5\", \"best_bid\":\"0.86\", \"best_ask\":\"0.87\"}], \"timestamp\":\"1789987930907\", \"event_type\":\"price_change\"}","raw_base64":null}
{"received_ms":1789987930934,"monotonic_ns":1019371764870500,"raw":"{\"market\":\"0x28a45972fccdaf0fba75dacc59725521035e177d09dd92174f9f52740bccb025\", \"price_changes\":[{\"asset_id\":\"61819828071723399190623735325323968706432622380635304641786792960078828866875\", \"price\":\"0.73\", \"size\":\"504\", \"side\":\"BUY\", \"hash\":\"8d760fce056834a9e7bd9c5fbf82e90af99731c4\", \"best_bid\":\"0.86\", \"best_ask\":\"0.87\"}, {\"asset_id\":\"114356653315647913247200886351065428002113119844334520181865067698979836634569\", \"price\":\"0.27\", \"size\":\"504\", \"side\":\"SELL\", \"hash\":\"c9d0a41e03840fef039f479130584d9cc0a89b2e\", \"best_bid\":\"0.13\", \"best_ask\":\"0.14\"}], \"timestamp\":\"1789987930911\", \"event_type\":\"price_change\"}","raw_base64":null}
{"received_ms":1789987930934,"monotonic_ns":1019371764910800,"raw":"{\"market\":\"0x28a45972fccdaf0fba75dacc59725521035e177d09dd92174f9f52740bccb025\", \"price_changes\":[{\"asset_id\":\"61819828071723399190623735325323968706432622380635304641786792960078828866875\", \"price\":\"0.92\", \"size\":\"709.5\", \"side\":\"SELL\", \"hash\":\"46648c4d0ca31c9e04cac54f07d91491fcfb712b\", \"best_bid\":\"0.86\", \"best_ask\":\"0.87\"}, {\"asset_id\":\"114356653315647913247200886351065428002113119844334520181865067698979836634569\", \"price\":\"0.08\", \"size\":\"709.5\", \"side\":\"BUY\", \"hash\":\"66ce369729072b8f881f4a7e69df212c8d85ebf4\", \"best_bid\":\"0.13\", \"best_ask\":\"0.14\"}], \"timestamp\":\"1789987930912\", \"event_type\":\"price_change\"}","raw_base64":null}
{"received_ms":1789987930935,"monotonic_ns":1019371766204700,"raw":"{\"market\":\"0x28a45972fccdaf0fba75dacc59725521035e177d09dd92174f9f52740bccb025\", \"price_changes\":[{\"asset_id\":\"61819828071723399190623735325323968706432622380635304641786792960078828866875\", \"price\":\"0.73\", \"size\":\"404\", \"side\":\"BUY\", \"hash\":\"82c1540b96aa9c47f04c1412d4b0a959a789e242\", \"best_bid\":\"0.86\", \"best_ask\":\"0.87\"}, {\"asset_id\":\"114356653315647913247200886351065428002113119844334520181865067698979836634569\", \"price\":\"0.27\", \"size\":\"404\", \"side\":\"SELL\", \"hash\":\"4f4c892d109236392998053fae174be2755f64cd\", \"best_bid\":\"0.13\", \"best_ask\":\"0.14\"}], \"timestamp\":\"1789987930913\", \"event_type\":\"price_change\"}","raw_base64":null}
{"received_ms":1789987930950,"monotonic_ns":1019371780476800,"raw":"{\"market\":\"0x28a45972fccdaf0fba75dacc59725521035e177d09dd92174f9f52740bccb025\", \"price_changes\":[{\"asset_id\":\"61819828071723399190623735325323968706432622380635304641786792960078828866875\", \"price\":\"0.91\", \"size\":\"628.12\", \"side\":\"SELL\", \"hash\":\"4e51c7dd3c8a54dde55d3ef6db521f3466db1be2\", \"best_bid\":\"0.86\", \"best_ask\":\"0.87\"}, {\"asset_id\":\"114356653315647913247200886351065428002113119844334520181865067698979836634569\", \"price\":\"0.09\", \"size\":\"628.12\", \"side\":\"BUY\", \"hash\":\"7266af5044175307b18e7a83dcfeb8d4b51f9a2f\", \"best_bid\":\"0.13\", \"best_ask\":\"0.14\"}], \"timestamp\":\"1789987930926\", \"event_type\":\"price_change\"}","raw_base64":null}
{"received_ms":1789987930950,"monotonic_ns":1019371780523700,"raw":"{\"market\":\"0x28a45972fccdaf0fba75dacc59725521035e177d09dd92174f9f52740bccb025\", \"price_changes\":[{\"asset_id\":\"61819828071723399190623735325323968706432622380635304641786792960078828866875\", \"price\":\"0.86\", \"size\":\"4469.8\", \"side\":\"BUY\", \"hash\":\"be68a06ae75548970f690a7d00d7564faaad85fa\", \"best_bid\":\"0.86\", \"best_ask\":\"0.87\"}, {\"asset_id\":\"114356653315647913247200886351065428002113119844334520181865067698979836634569\", \"price\":\"0.14\", \"size\":\"4469.8\", \"side\":\"SELL\", \"hash\":\"f2eac90f2c9e2d031fdebb435a3f60db370c70d8\", \"best_bid\":\"0.13\", \"best_ask\":\"0.14\"}], \"timestamp\":\"1789987930928\", \"event_type\":\"price_change\"}","raw_base64":null}
{"received_ms":1789987930950,"monotonic_ns":1019371780561100,"raw":"{\"market\":\"0x28a45972fccdaf0fba75dacc59725521035e177d09dd92174f9f52740bccb025\", \"price_changes\":[{\"asset_id\":\"61819828071723399190623735325323968706432622380635304641786792960078828866875\", \"price\":\"0.86\", \"size\":\"4464.8\", \"side\":\"BUY\", \"hash\":\"3388c5ee7c32cf48d63c67a17b82b13378b0f40c\", \"best_bid\":\"0.86\", \"best_ask\":\"0.87\"}, {\"asset_id\":\"114356653315647913247200886351065428002113119844334520181865067698979836634569\", \"price\":\"0.14\", \"size\":\"4464.8\", \"side\":\"SELL\", \"hash\":\"99bb727cef5e7cb9e105035285fee93256664586\", \"best_bid\":\"0.13\", \"best_ask\":\"0.14\"}], \"timestamp\":\"1789987930928\", \"event_type\":\"price_change\"}","raw_base64":null}
{"received_ms":1789987930952,"monotonic_ns":1019371782885400,"raw":"{\"market\":\"0x28a45972fccdaf0fba75dacc59725521035e177d09dd92174f9f52740bccb025\", \"price_changes\":[{\"asset_id\":\"61819828071723399190623735325323968706432622380635304641786792960078828866875\", \"price\":\"0.76\", \"size\":\"434.91\", \"side\":\"BUY\", \"hash\":\"f32e2599fadeb5dbad02d844ad5b54ab96304aa3\", \"best_bid\":\"0.86\", \"best_ask\":\"0.87\"}, {\"asset_id\":\"114356653315647913247200886351065428002113119844334520181865067698979836634569\", \"price\":\"0.24\", \"size\":\"434.91\", \"side\":\"SELL\", \"hash\":\"ea8f690322cd7322619e7883c0bba134bb5aeaf8\", \"best_bid\":\"0.13\", \"best_ask\":\"0.14\"}], \"timestamp\":\"1789987930929\", \"event_type\":\"price_change\"}","raw_base64":null}
{"received_ms":1789987930952,"monotonic_ns":1019371782932400,"raw":"{\"market\":\"0x28a45972fccdaf0fba75dacc59725521035e177d09dd92174f9f52740bccb025\", \"price_changes\":[{\"asset_id\":\"61819828071723399190623735325323968706432622380635304641786792960078828866875\", \"price\":\"0.86\", \"size\":\"4454.8\", \"side\":\"BUY\", \"hash\":\"d6981702f4d3e0f2c386358e2806a379bb03fff0\", \"best_bid\":\"0.86\", \"best_ask\":\"0.87\"}, {\"asset_id\":\"114356653315647913247200886351065428002113119844334520181865067698979836634569\", \"price\":\"0.14\", \"size\":\"4454.8\", \"side\":\"SELL\", \"hash\":\"4a24be463ee7fce55898f1f6c540e78e675faf7e\", \"best_bid\":\"0.13\", \"best_ask\":\"0.14\"}], \"timestamp\":\"1789987930930\", \"event_type\":\"price_change\"}","raw_base64":null}
{"received_ms":1789987930957,"monotonic_ns":1019371788103500,"raw":"{\"market\":\"0x28a45972fccdaf0fba75dacc59725521035e177d09dd92174f9f52740bccb025\", \"price_changes\":[{\"asset_id\":\"114356653315647913247200886351065428002113119844334520181865067698979836634569\", \"price\":\"0.03\", \"size\":\"4012.57\", \"side\":\"BUY\", \"hash\":\"a60db4ad0f5d71f559c3826cf1e754e107bfd3c6\", \"best_bid\":\"0.13\", \"best_ask\":\"0.14\"}, {\"asset_id\":\"61819828071723399190623735325323968706432622380635304641786792960078828866875\", \"price\":\"0.97\", \"size\":\"4012.57\", \"side\":\"SELL\", \"hash\":\"c2579670e9eaf73d85fee3ac54077e25da7ca1e3\", \"best_bid\":\"0.86\", \"best_ask\":\"0.87\"}], \"timestamp\":\"1789987930932\", \"event_type\":\"price_change\"}","raw_base64":null}
{"received_ms":1789987930957,"monotonic_ns":1019371788181100,"raw":"{\"market\":\"0x28a45972fccdaf0fba75dacc59725521035e177d09dd92174f9f52740bccb025\", \"price_changes\":[{\"asset_id\":\"114356653315647913247200886351065428002113119844334520181865067698979836634569\", \"price\":\"0.07\", \"size\":\"6464.71\", \"side\":\"BUY\", \"hash\":\"bdc8c3fe05e35572e45d76efefb08ca446174fa0\", \"best_bid\":\"0.13\", \"best_ask\":\"0.14\"}, {\"asset_id\":\"61819828071723399190623735325323968706432622380635304641786792960078828866875\", \"price\":\"0.93\", \"size\":\"6464.71\", \"side\":\"SELL\", \"hash\":\"d7134af11a02b2af592242fa14796faac9aad5d6\", \"best_bid\":\"0.86\", \"best_ask\":\"0.87\"}], \"timestamp\":\"1789987930933\", \"event_type\":\"price_change\"}","raw_base64":null}
{"received_ms":1789987930957,"monotonic_ns":1019371788221300,"raw":"{\"market\":\"0x28a45972fccdaf0fba75dacc59725521035e177d09dd92174f9f52740bccb025\", \"price_changes\":[{\"asset_id\":\"114356653315647913247200886351065428002113119844334520181865067698979836634569\", \"price\":\"0.07\", \"size\":\"6293.71\", \"side\":\"BUY\", \"hash\":\"b6b0abde7afb872e6aa2379a978eae8569c6d3d1\", \"best_bid\":\"0.13\", \"best_ask\":\"0.14\"}, {\"asset_id\":\"61819828071723399190623735325323968706432622380635304641786792960078828866875\", \"price\":\"0.93\", \"size\":\"6293.71\", \"side\":\"SELL\", \"hash\":\"14f2642172584931d51636b651854b3cbbfcecfb\", \"best_bid\":\"0.86\", \"best_ask\":\"0.87\"}], \"timestamp\":\"1789987930935\", \"event_type\":\"price_change\"}","raw_base64":null}
{"received_ms":1789987930958,"monotonic_ns":1019371788266500,"raw":"{\"market\":\"0x28a45972fccdaf0fba75dacc59725521035e177d09dd92174f9f52740bccb025\", \"price_changes\":[{\"asset_id\":\"114356653315647913247200886351065428002113119844334520181865067698979836634569\", \"price\":\"0.11\", \"size\":\"146.1\", \"side\":\"BUY\", \"hash\":\"2e34b868a968b6153a495ffc5b48e24a596cdcd3\", \"best_bid\":\"0.13\", \"best_ask\":\"0.14\"}, {\"asset_id\":\"61819828071723399190623735325323968706432622380635304641786792960078828866875\", \"price\":\"0.89\", \"size\":\"146.1\", \"side\":\"SELL\", \"hash\":\"2dd98275645642ecf543c7fb2e966be543464512\", \"best_bid\":\"0.86\", \"best_ask\":\"0.87\"}], \"timestamp\":\"1789987930935\", \"event_type\":\"price_change\"}","raw_base64":null}
{"received_ms":1789987930958,"monotonic_ns":1019371788303300,"raw":"{\"market\":\"0x28a45972fccdaf0fba75dacc59725521035e177d09dd92174f9f52740bccb025\", \"price_changes\":[{\"asset_id\":\"61819828071723399190623735325323968706432622380635304641786792960078828866875\", \"price\":\"0.91\", \"size\":\"541.12\", \"side\":\"SELL\", \"hash\":\"6468c6baba7bd6745b6e46f957b5acf2b7f732ca\", \"best_bid\":\"0.86\", \"best_ask\":\"0.87\"}, {\"asset_id\":\"114356653315647913247200886351065428002113119844334520181865067698979836634569\", \"price\":\"0.09\", \"size\":\"541.12\", \"side\":\"BUY\", \"hash\":\"a09e3ebcd0d6ed2f67621095b722aff4753f75e5\", \"best_bid\":\"0.13\", \"best_ask\":\"0.14\"}], \"timestamp\":\"1789987930936\", \"event_type\":\"price_change\"}","raw_base64":null}
{"received_ms":1789987930967,"monotonic_ns":1019371797994600,"raw":"{\"market\":\"0x28a45972fccdaf0fba75dacc59725521035e177d09dd92174f9f52740bccb025\", \"price_changes\":[{\"asset_id\":\"61819828071723399190623735325323968706432622380635304641786792960078828866875\", \"price\":\"0.77\", \"size\":\"527.49\", \"side\":\"BUY\", \"hash\":\"da39c32c530593c5b8b01b5efa8eb6e6fb92f57f\", \"best_bid\":\"0.86\", \"best_ask\":\"0.87\"}, {\"asset_id\":\"114356653315647913247200886351065428002113119844334520181865067698979836634569\", \"price\":\"0.23\", \"size\":\"527.49\", \"side\":\"SELL\", \"hash\":\"87bfd96ea04184c36c5b62cdda7774e979cb45c4\", \"best_bid\":\"0.13\", \"best_ask\":\"0.14\"}], \"timestamp\":\"1789987930937\", \"event_type\":\"price_change\"}","raw_base64":null}
{"received_ms":1789987930967,"monotonic_ns":1019371798084700,"raw":"{\"market\":\"0x28a45972fccdaf0fba75dacc59725521035e177d09dd92174f9f52740bccb025\", \"price_changes\":[{\"asset_id\":\"114356653315647913247200886351065428002113119844334520181865067698979836634569\", \"price\":\"0.01\", \"size\":\"1689.43\", \"side\":\"BUY\", \"hash\":\"f4c617d23fc7c47d0dc2d3f285c17a70a76bb7e9\", \"best_bid\":\"0.13\", \"best_ask\":\"0.14\"}, {\"asset_id\":\"61819828071723399190623735325323968706432622380635304641786792960078828866875\", \"price\":\"0.99\", \"size\":\"1689.43\", \"side\":\"SELL\", \"hash\":\"cf00e4045189b0f6b9cd3d169d0c402a009689f7\", \"best_bid\":\"0.86\", \"best_ask\":\"0.87\"}], \"timestamp\":\"1789987930937\", \"event_type\":\"price_change\"}","raw_base64":null}
{"received_ms":1789987930967,"monotonic_ns":1019371798126900,"raw":"{\"market\":\"0x28a45972fccdaf0fba75dacc59725521035e177d09dd92174f9f52740bccb025\", \"price_changes\":[{\"asset_id\":\"61819828071723399190623735325323968706432622380635304641786792960078828866875\", \"price\":\"0.85\", \"size\":\"4894.35\", \"side\":\"BUY\", \"hash\":\"0f0ae11f06561e68a18e1d290644787cf2c1cfe4\", \"best_bid\":\"0.86\", \"best_ask\":\"0.87\"}, {\"asset_id\":\"114356653315647913247200886351065428002113119844334520181865067698979836634569\", \"price\":\"0.15\", \"size\":\"4894.35\", \"side\":\"SELL\", \"hash\":\"78c82952c5a425b923a8ccac638651b78bf35cc5\", \"best_bid\":\"0.13\", \"best_ask\":\"0.14\"}], \"timestamp\":\"1789987930938\", \"event_type\":\"price_change\"}","raw_base64":null}
{"received_ms":1789987930967,"monotonic_ns":1019371798165400,"raw":"{\"market\":\"0x28a45972fccdaf0fba75dacc59725521035e177d09dd92174f9f52740bccb025\", \"price_changes\":[{\"asset_id\":\"61819828071723399190623735325323968706432622380635304641786792960078828866875\", \"price\":\"0.84\", \"size\":\"3023\", \"side\":\"BUY\", \"hash\":\"9e7b09d945956e924eae02ee8079701abee64cfa\", \"best_bid\":\"0.86\", \"best_ask\":\"0.87\"}, {\"asset_id\":\"114356653315647913247200886351065428002113119844334520181865067698979836634569\", \"price\":\"0.16\", \"size\":\"3023\", \"side\":\"SELL\", \"hash\":\"a0921d769b243f8b804ced7bee38ca2b6657dd54\", \"best_bid\":\"0.13\", \"best_ask\":\"0.14\"}], \"timestamp\":\"1789987930939\", \"event_type\":\"price_change\"}","raw_base64":null}
{"received_ms":1789987930968,"monotonic_ns":1019371798492400,"raw":"{\"market\":\"0x28a45972fccdaf0fba75dacc59725521035e177d09dd92174f9f52740bccb025\", \"price_changes\":[{\"asset_id\":\"114356653315647913247200886351065428002113119844334520181865067698979836634569\", \"price\":\"0.13\", \"size\":\"275\", \"side\":\"BUY\", \"hash\":\"170b7dff793d75730ded2dcaf5c19f2bb0d49906\", \"best_bid\":\"0.13\", \"best_ask\":\"0.14\"}, {\"asset_id\":\"61819828071723399190623735325323968706432622380635304641786792960078828866875\", \"price\":\"0.87\", \"size\":\"275\", \"side\":\"SELL\", \"hash\":\"40939c1490ca62c569a91481df0e2bec0c9d1e8e\", \"best_bid\":\"0.86\", \"best_ask\":\"0.87\"}], \"timestamp\":\"1789987930940\", \"event_type\":\"price_change\"}","raw_base64":null}
{"received_ms":1789987930968,"monotonic_ns":1019371798556200,"raw":"{\"market\":\"0x28a45972fccdaf0fba75dacc59725521035e177d09dd92174f9f52740bccb025\", \"price_changes\":[{\"asset_id\":\"61819828071723399190623735325323968706432622380635304641786792960078828866875\", \"price\":\"0.75\", \"size\":\"510\", \"side\":\"BUY\", \"hash\":\"7875aa0c98f73a4814997a612558f256a7449ecc\", \"best_bid\":\"0.86\", \"best_ask\":\"0.87\"}, {\"asset_id\":\"114356653315647913247200886351065428002113119844334520181865067698979836634569\", \"price\":\"0.25\", \"size\":\"510\", \"side\":\"SELL\", \"hash\":\"9c0de41e8f6bd62dcf77d470fbac57e044f8d762\", \"best_bid\":\"0.13\", \"best_ask\":\"0.14\"}], \"timestamp\":\"1789987930941\", \"event_type\":\"price_change\"}","raw_base64":null}
{"received_ms":1789987930968,"monotonic_ns":1019371798600200,"raw":"{\"market\":\"0x28a45972fccdaf0fba75dacc59725521035e177d09dd92174f9f52740bccb025\", \"price_changes\":[{\"asset_id\":\"114356653315647913247200886351065428002113119844334520181865067698979836634569\", \"price\":\"0.09\", \"size\":\"533.12\", \"side\":\"BUY\", \"hash\":\"4a0b40fbeb3f4525244acf86ddd42ba319b55b38\", \"best_bid\":\"0.13\", \"best_ask\":\"0.14\"}, {\"asset_id\":\"61819828071723399190623735325323968706432622380635304641786792960078828866875\", \"price\":\"0.91\", \"size\":\"533.12\", \"side\":\"SELL\", \"hash\":\"6fd1d9a73414dd7a4dda897b1edd745ab213d557\", \"best_bid\":\"0.86\", \"best_ask\":\"0.87\"}], \"timestamp\":\"1789987930942\", \"event_type\":\"price_change\"}","raw_base64":null}
{"received_ms":1789987930968,"monotonic_ns":1019371798640700,"raw":"{\"market\":\"0x28a45972fccdaf0fba75dacc59725521035e177d09dd92174f9f52740bccb025\", \"price_changes\":[{\"asset_id\":\"61819828071723399190623735325323968706432622380635304641786792960078828866875\", \"price\":\"0.86\", \"size\":\"4514.8\", \"side\":\"BUY\", \"hash\":\"e96b827321458dd4144b35a758cf78c625cb6a36\", \"best_bid\":\"0.86\", \"best_ask\":\"0.87\"}, {\"asset_id\":\"114356653315647913247200886351065428002113119844334520181865067698979836634569\", \"price\":\"0.14\", \"size\":\"4514.8\", \"side\":\"SELL\", \"hash\":\"caa8a883095d2a71a10a1e7ee3aa169f546ca496\", \"best_bid\":\"0.13\", \"best_ask\":\"0.14\"}], \"timestamp\":\"1789987930942\", \"event_type\":\"price_change\"}","raw_base64":null}
{"received_ms":1789987930968,"monotonic_ns":1019371798679700,"raw":"{\"market\":\"0x28a45972fccdaf0fba75dacc59725521035e177d09dd92174f9f52740bccb025\", \"price_changes\":[{\"asset_id\":\"61819828071723399190623735325323968706432622380635304641786792960078828866875\", \"price\":\"0.86\", \"size\":\"4414.8\", \"side\":\"BUY\", \"hash\":\"a08dc93b2a4a2cb8116c3e325955e5652d10e9b6\", \"best_bid\":\"0.86\", \"best_ask\":\"0.87\"}, {\"asset_id\":\"114356653315647913247200886351065428002113119844334520181865067698979836634569\", \"price\":\"0.14\", \"size\":\"4414.8\", \"side\":\"SELL\", \"hash\":\"f2c6ecedeaf10c4d3c189f0544ca6016a047bef7\", \"best_bid\":\"0.13\", \"best_ask\":\"0.14\"}], \"timestamp\":\"1789987930945\", \"event_type\":\"price_change\"}","raw_base64":null}
{"received_ms":1789987930968,"monotonic_ns":1019371798717100,"raw":"{\"market\":\"0x28a45972fccdaf0fba75dacc59725521035e177d09dd92174f9f52740bccb025\", \"price_changes\":[{\"asset_id\":\"61819828071723399190623735325323968706432622380635304641786792960078828866875\", \"price\":\"0.84\", \"size\":\"3123\", \"side\":\"BUY\", \"hash\":\"b28f0ff8c916228eda0c73b89bbbe862e0ed4852\", \"best_bid\":\"0.86\", \"best_ask\":\"0.87\"}, {\"asset_id\":\"114356653315647913247200886351065428002113119844334520181865067698979836634569\", \"price\":\"0.16\", \"size\":\"3123\", \"side\":\"SELL\", \"hash\":\"69fb2175bc862de2278ae2bfd5f565c94233eb0d\", \"best_bid\":\"0.13\", \"best_ask\":\"0.14\"}], \"timestamp\":\"1789987930945\", \"event_type\":\"price_change\"}","raw_base64":null}
{"received_ms":1789987930968,"monotonic_ns":1019371798753000,"raw":"{\"market\":\"0x28a45972fccdaf0fba75dacc59725521035e177d09dd92174f9f52740bccb025\", \"price_changes\":[{\"asset_id\":\"61819828071723399190623735325323968706432622380635304641786792960078828866875\", \"price\":\"0.77\", \"size\":\"567.49\", \"side\":\"BUY\", \"hash\":\"b00c71c2770dc4099f84e92fbc64b04d1d61af28\", \"best_bid\":\"0.86\", \"best_ask\":\"0.87\"}, {\"asset_id\":\"114356653315647913247200886351065428002113119844334520181865067698979836634569\", \"price\":\"0.23\", \"size\":\"567.49\", \"side\":\"SELL\", \"hash\":\"1efd92b918eda13aafa4595f46dbeefce20f4430\", \"best_bid\":\"0.13\", \"best_ask\":\"0.14\"}], \"timestamp\":\"1789987930946\", \"event_type\":\"price_change\"}","raw_base64":null}
{"received_ms":1789987930968,"monotonic_ns":1019371798793900,"raw":"{\"market\":\"0x28a45972fccdaf0fba75dacc59725521035e177d09dd92174f9f52740bccb025\", \"price_changes\":[{\"asset_id\":\"61819828071723399190623735325323968706432622380635304641786792960078828866875\", \"price\":\"0.75\", \"size\":\"530\", \"side\":\"BUY\", \"hash\":\"6f17390788e324f03811b321265f65f46c6e34a0\", \"best_bid\":\"0.86\", \"best_ask\":\"0.87\"}, {\"asset_id\":\"114356653315647913247200886351065428002113119844334520181865067698979836634569\", \"price\":\"0.25\", \"size\":\"530\", \"side\":\"SELL\", \"hash\":\"97a6b618372965fdfa380d28325ac24a6531b7c2\", \"best_bid\":\"0.13\", \"best_ask\":\"0.14\"}], \"timestamp\":\"1789987930946\", \"event_type\":\"price_change\"}","raw_base64":null}
{"received_ms":1789987930969,"monotonic_ns":1019371800155600,"raw":"{\"market\":\"0x28a45972fccdaf0fba75dacc59725521035e177d09dd92174f9f52740bccb025\", \"price_changes\":[{\"asset_id\":\"61819828071723399190623735325323968706432622380635304641786792960078828866875\", \"price\":\"0.77\", \"size\":\"527.49\", \"side\":\"BUY\", \"hash\":\"4700775c0c0eeb59c763c55c6a4dc71b2321fb98\", \"best_bid\":\"0.86\", \"best_ask\":\"0.87\"}, {\"asset_id\":\"114356653315647913247200886351065428002113119844334520181865067698979836634569\", \"price\":\"0.23\", \"size\":\"527.49\", \"side\":\"SELL\", \"hash\":\"4fd087848907d6d7842b060b3fa68ef3a3b30b9d\", \"best_bid\":\"0.13\", \"best_ask\":\"0.14\"}], \"timestamp\":\"1789987930947\", \"event_type\":\"price_change\"}","raw_base64":null}
{"received_ms":1789987930969,"monotonic_ns":1019371800241100,"raw":"{\"market\":\"0x28a45972fccdaf0fba75dacc59725521035e177d09dd92174f9f52740bccb025\", \"price_changes\":[{\"asset_id\":\"61819828071723399190623735325323968706432622380635304641786792960078828866875\", \"price\":\"0.83\", \"size\":\"573\", \"side\":\"BUY\", \"hash\":\"a87d5d3e5d2ddd453a91dc3ea6b39e413c7d1a7a\", \"best_bid\":\"0.86\", \"best_ask\":\"0.87\"}, {\"asset_id\":\"114356653315647913247200886351065428002113119844334520181865067698979836634569\", \"price\":\"0.17\", \"size\":\"573\", \"side\":\"SELL\", \"hash\":\"0e7925ed9aa8f80d580eb017d2ff4663c73681a7\", \"best_bid\":\"0.13\", \"best_ask\":\"0.14\"}], \"timestamp\":\"1789987930947\", \"event_type\":\"price_change\"}","raw_base64":null}
{"received_ms":1789987930970,"monotonic_ns":1019371800611100,"raw":"{\"market\":\"0x28a45972fccdaf0fba75dacc59725521035e177d09dd92174f9f52740bccb025\", \"price_changes\":[{\"asset_id\":\"114356653315647913247200886351065428002113119844334520181865067698979836634569\", \"price\":\"0.01\", \"size\":\"1669.43\", \"side\":\"BUY\", \"hash\":\"6b688393bf481e4e33a8133f88b4d9d415a4bc42\", \"best_bid\":\"0.13\", \"best_ask\":\"0.14\"}, {\"asset_id\":\"61819828071723399190623735325323968706432622380635304641786792960078828866875\", \"price\":\"0.99\", \"size\":\"1669.43\", \"side\":\"SELL\", \"hash\":\"27bc9905a6ec0425674db6c7821bc2bd30b16863\", \"best_bid\":\"0.86\", \"best_ask\":\"0.87\"}], \"timestamp\":\"1789987930949\", \"event_type\":\"price_change\"}","raw_base64":null}
{"received_ms":1789987930970,"monotonic_ns":1019371800695400,"raw":"{\"market\":\"0x28a45972fccdaf0fba75dacc59725521035e177d09dd92174f9f52740bccb025\", \"price_changes\":[{\"asset_id\":\"61819828071723399190623735325323968706432622380635304641786792960078828866875\", \"price\":\"0.77\", \"size\":\"487.49\", \"side\":\"BUY\", \"hash\":\"27bc9905a6ec0425674db6c7821bc2bd30b16863\", \"best_bid\":\"0.86\", \"best_ask\":\"0.87\"}, {\"asset_id\":\"114356653315647913247200886351065428002113119844334520181865067698979836634569\", \"price\":\"0.23\", \"size\":\"487.49\", \"side\":\"SELL\", \"hash\":\"6b688393bf481e4e33a8133f88b4d9d415a4bc42\", \"best_bid\":\"0.13\", \"best_ask\":\"0.14\"}], \"timestamp\":\"1789987930949\", \"event_type\":\"price_change\"}","raw_base64":null}
{"received_ms":1789987930975,"monotonic_ns":1019371805506700,"raw":"{\"market\":\"0x28a45972fccdaf0fba75dacc59725521035e177d09dd92174f9f52740bccb025\", \"price_changes\":[{\"asset_id\":\"61819828071723399190623735325323968706432622380635304641786792960078828866875\", \"price\":\"0.9\", \"size\":\"599\", \"side\":\"SELL\", \"hash\":\"08112831919e9d8c879f2e96da35e21809e19e43\", \"best_bid\":\"0.86\", \"best_ask\":\"0.87\"}, {\"asset_id\":\"114356653315647913247200886351065428002113119844334520181865067698979836634569\", \"price\":\"0.1\", \"size\":\"599\", \"side\":\"BUY\", \"hash\":\"7b4cd5bc5c6d899a335cd85cee96c1f3bb86f24b\", \"best_bid\":\"0.13\", \"best_ask\":\"0.14\"}], \"timestamp\":\"1789987930952\", \"event_type\":\"price_change\"}","raw_base64":null}
{"received_ms":1789987930975,"monotonic_ns":1019371805555200,"raw":"{\"market\":\"0x28a45972fccdaf0fba75dacc59725521035e177d09dd92174f9f52740bccb025\", \"price_changes\":[{\"asset_id\":\"61819828071723399190623735325323968706432622380635304641786792960078828866875\", \"price\":\"0.92\", \"size\":\"704.5\", \"side\":\"SELL\", \"hash\":\"fd9938316729662cc47bc43370652cf6f067fe35\", \"best_bid\":\"0.86\", \"best_ask\":\"0.87\"}, {\"asset_id\":\"114356653315647913247200886351065428002113119844334520181865067698979836634569\", \"price\":\"0.08\", \"size\":\"704.5\", \"side\":\"BUY\", \"hash\":\"d535896c9bb5ccc635ba156c17edcde15cbc52d2\", \"best_bid\":\"0.13\", \"best_ask\":\"0.14\"}], \"timestamp\":\"1789987930953\", \"event_type\":\"price_change\"}","raw_base64":null}
{"received_ms":1789987930981,"monotonic_ns":1019371812169900,"raw":"{\"market\":\"0x28a45972fccdaf0fba75dacc59725521035e177d09dd92174f9f52740bccb025\", \"price_changes\":[{\"asset_id\":\"61819828071723399190623735325323968706432622380635304641786792960078828866875\", \"price\":\"0.85\", \"size\":\"2767.35\", \"side\":\"BUY\", \"hash\":\"7e78c33d9063ed182ce3101a6d9dc685e8a4648f\", \"best_bid\":\"0.86\", \"best_ask\":\"0.87\"}, {\"asset_id\":\"114356653315647913247200886351065428002113119844334520181865067698979836634569\", \"price\":\"0.15\", \"size\":\"2767.35\", \"side\":\"SELL\", \"hash\":\"f9a243c83ac7652f52a6df1c27d19d0212ced6be\", \"best_bid\":\"0.13\", \"best_ask\":\"0.14\"}], \"timestamp\":\"1789987930958\", \"event_type\":\"price_change\"}","raw_base64":null}
{"received_ms":1789987930981,"monotonic_ns":1019371812241400,"raw":"{\"market\":\"0x28a45972fccdaf0fba75dacc59725521035e177d09dd92174f9f52740bccb025\", \"price_changes\":[{\"asset_id\":\"61819828071723399190623735325323968706432622380635304641786792960078828866875\", \"price\":\"0.86\", \"size\":\"1762.8\", \"side\":\"BUY\", \"hash\":\"7e78c33d9063ed182ce3101a6d9dc685e8a4648f\", \"best_bid\":\"0.86\", \"best_ask\":\"0.87\"}, {\"asset_id\":\"114356653315647913247200886351065428002113119844334520181865067698979836634569\", \"price\":\"0.14\", \"size\":\"1762.8\", \"side\":\"SELL\", \"hash\":\"f9a243c83ac7652f52a6df1c27d19d0212ced6be\", \"best_bid\":\"0.13\", \"best_ask\":\"0.14\"}], \"timestamp\":\"1789987930958\", \"event_type\":\"price_change\"}","raw_base64":null}
{"received_ms":1789987930982,"monotonic_ns":1019371812279600,"raw":"{\"market\":\"0x28a45972fccdaf0fba75dacc59725521035e177d09dd92174f9f52740bccb025\", \"price_changes\":[{\"asset_id\":\"61819828071723399190623735325323968706432622380635304641786792960078828866875\", \"price\":\"0.85\", \"size\":\"2746.35\", \"side\":\"BUY\", \"hash\":\"32cfaa09c8abeff8eb47c4c60e6dfa70aeb261ad\", \"best_bid\":\"0.86\", \"best_ask\":\"0.87\"}, {\"asset_id\":\"114356653315647913247200886351065428002113119844334520181865067698979836634569\", \"price\":\"0.15\", \"size\":\"2746.35\", \"side\":\"SELL\", \"hash\":\"1cf0211bd83712fd75f5c2779128501f00bcb1e5\", \"best_bid\":\"0.13\", \"best_ask\":\"0.14\"}], \"timestamp\":\"1789987930958\", \"event_type\":\"price_change\"}","raw_base64":null}
{"received_ms":1789987930982,"monotonic_ns":1019371812315700,"raw":"{\"market\":\"0x28a45972fccdaf0fba75dacc59725521035e177d09dd92174f9f52740bccb025\", \"price_changes\":[{\"asset_id\":\"61819828071723399190623735325323968706432622380635304641786792960078828866875\", \"price\":\"0.85\", \"size\":\"2741.35\", \"side\":\"BUY\", \"hash\":\"f7dbc4127f2e535d4f0173217d71551455254d82\", \"best_bid\":\"0.86\", \"best_ask\":\"0.87\"}, {\"asset_id\":\"114356653315647913247200886351065428002113119844334520181865067698979836634569\", \"price\":\"0.15\", \"size\":\"2741.35\", \"side\":\"SELL\", \"hash\":\"30303a85352ef1fc11ce1a6c83ef72c643154d46\", \"best_bid\":\"0.13\", \"best_ask\":\"0.14\"}], \"timestamp\":\"1789987930958\", \"event_type\":\"price_change\"}","raw_base64":null}
{"received_ms":1789987930982,"monotonic_ns":1019371812357500,"raw":"{\"market\":\"0x28a45972fccdaf0fba75dacc59725521035e177d09dd92174f9f52740bccb025\", \"price_changes\":[{\"asset_id\":\"61819828071723399190623735325323968706432622380635304641786792960078828866875\", \"price\":\"0.85\", \"size\":\"2756.52\", \"side\":\"BUY\", \"hash\":\"89ea501e3549c624ee07ef68af9b6ba7c6085560\", \"best_bid\":\"0.86\", \"best_ask\":\"0.87\"}, {\"asset_id\":\"114356653315647913247200886351065428002113119844334520181865067698979836634569\", \"price\":\"0.15\", \"size\":\"2756.52\", \"side\":\"SELL\", \"hash\":\"2dae02dea9c2a350f3fc8c206c0c57651954cc11\", \"best_bid\":\"0.13\", \"best_ask\":\"0.14\"}], \"timestamp\":\"1789987930959\", \"event_type\":\"price_change\"}","raw_base64":null}
{"received_ms":1789987930982,"monotonic_ns":1019371812392700,"raw":"{\"market\":\"0x28a45972fccdaf0fba75dacc59725521035e177d09dd92174f9f52740bccb025\", \"price_changes\":[{\"asset_id\":\"61819828071723399190623735325323968706432622380635304641786792960078828866875\", \"price\":\"0.85\", \"size\":\"815.52\", \"side\":\"BUY\", \"hash\":\"42964fc06514f10ece319541a1c145be47b9d417\", \"best_bid\":\"0.86\", \"best_ask\":\"0.87\"}, {\"asset_id\":\"114356653315647913247200886351065428002113119844334520181865067698979836634569\", \"price\":\"0.15\", \"size\":\"815.52\", \"side\":\"SELL\", \"hash\":\"473c5f126cb4fc112d18e683addad03b6854e2b2\", \"best_bid\":\"0.13\", \"best_ask\":\"0.14\"}], \"timestamp\":\"1789987930959\", \"event_type\":\"price_change\"}","raw_base64":null}
{"received_ms":1789987930982,"monotonic_ns":1019371812427500,"raw":"{\"market\":\"0x28a45972fccdaf0fba75dacc59725521035e177d09dd92174f9f52740bccb025\", \"price_changes\":[{\"asset_id\":\"61819828071723399190623735325323968706432622380635304641786792960078828866875\", \"price\":\"0.86\", \"size\":\"218.8\", \"side\":\"BUY\", \"hash\":\"98dde46d9a7b2b163ccf63e461fb9615d585c028\", \"best_bid\":\"0.86\", \"best_ask\":\"0.87\"}, {\"asset_id\":\"114356653315647913247200886351065428002113119844334520181865067698979836634569\", \"price\":\"0.14\", \"size\":\"218.8\", \"side\":\"SELL\", \"hash\":\"54529b6a17db94c3707d2c0f35d7139449bca982\", \"best_bid\":\"0.13\", \"best_ask\":\"0.14\"}], \"timestamp\":\"1789987930960\", \"event_type\":\"price_change\"}","raw_base64":null}
{"received_ms":1789987930982,"monotonic_ns":1019371812640300,"raw":"{\"market\":\"0x28a45972fccdaf0fba75dacc59725521035e177d09dd92174f9f52740bccb025\", \"price_changes\":[{\"asset_id\":\"61819828071723399190623735325323968706432622380635304641786792960078828866875\", \"price\":\"0.86\", \"size\":\"168.8\", \"side\":\"BUY\", \"hash\":\"e814d7e60b0927c1db29b09bfaf61cd9370f50db\", \"best_bid\":\"0.86\", \"best_ask\":\"0.87\"}, {\"asset_id\":\"114356653315647913247200886351065428002113119844334520181865067698979836634569\", \"price\":\"0.14\", \"size\":\"168.8\", \"side\":\"SELL\", \"hash\":\"02fd970bc037b2fa820e2a58955ed7109513f542\", \"best_bid\":\"0.13\", \"best_ask\":\"0.14\"}], \"timestamp\":\"1789987930961\", \"event_type\":\"price_change\"}","raw_base64":null}
{"received_ms":1789987930987,"monotonic_ns":1019371817792300,"raw":"{\"market\":\"0x28a45972fccdaf0fba75dacc59725521035e177d09dd92174f9f52740bccb025\", \"price_changes\":[{\"asset_id\":\"114356653315647913247200886351065428002113119844334520181865067698979836634569\", \"price\":\"0.12\", \"size\":\"275\", \"side\":\"BUY\", \"hash\":\"e7ad0cdbc22ade26d7b4fdba907432f27fe948de\", \"best_bid\":\"0.13\", \"best_ask\":\"0.14\"}, {\"asset_id\":\"61819828071723399190623735325323968706432622380635304641786792960078828866875\", \"price\":\"0.88\", \"size\":\"275\", \"side\":\"SELL\", \"hash\":\"cc96addad33403ccad4e5cd9cf4cf701344dbd22\", \"best_bid\":\"0.86\", \"best_ask\":\"0.87\"}], \"timestamp\":\"1789987930963\", \"event_type\":\"price_change\"}","raw_base64":null}
{"received_ms":1789987930987,"monotonic_ns":1019371817840800,"raw":"{\"market\":\"0x28a45972fccdaf0fba75dacc59725521035e177d09dd92174f9f52740bccb025\", \"price_changes\":[{\"asset_id\":\"61819828071723399190623735325323968706432622380635304641786792960078828866875\", \"price\":\"0.84\", \"size\":\"2775\", \"side\":\"BUY\", \"hash\":\"65614ffc72ffd84b019e58662020535eaba351b0\", \"best_bid\":\"0.86\", \"best_ask\":\"0.87\"}, {\"asset_id\":\"114356653315647913247200886351065428002113119844334520181865067698979836634569\", \"price\":\"0.16\", \"size\":\"2775\", \"side\":\"SELL\", \"hash\":\"4d95acfde919aa79c1c64412734e81e806368ca2\", \"best_bid\":\"0.13\", \"best_ask\":\"0.14\"}], \"timestamp\":\"1789987930965\", \"event_type\":\"price_change\"}","raw_base64":null}
{"received_ms":1789987930987,"monotonic_ns":1019371817878200,"raw":"{\"market\":\"0x28a45972fccdaf0fba75dacc59725521035e177d09dd92174f9f52740bccb025\", \"price_changes\":[{\"asset_id\":\"114356653315647913247200886351065428002113119844334520181865067698979836634569\", \"price\":\"0.06\", \"size\":\"5626.67\", \"side\":\"BUY\", \"hash\":\"403ebf65fdda3a2c5696b9df4359a2a1945ff50a\", \"best_bid\":\"0.13\", \"best_ask\":\"0.14\"}, {\"asset_id\":\"61819828071723399190623735325323968706432622380635304641786792960078828866875\", \"price\":\"0.94\", \"size\":\"5626.67\", \"side\":\"SELL\", \"hash\":\"382a73426534d99d5318df038bae35c3e6d92baa\", \"best_bid\":\"0.86\", \"best_ask\":\"0.87\"}], \"timestamp\":\"1789987930965\", \"event_type\":\"price_change\"}","raw_base64":null}
{"received_ms":1789987930987,"monotonic_ns":1019371818125200,"raw":"{\"market\":\"0x28a45972fccdaf0fba75dacc59725521035e177d09dd92174f9f52740bccb025\", \"price_changes\":[{\"asset_id\":\"114356653315647913247200886351065428002113119844334520181865067698979836634569\", \"price\":\"0.05\", \"size\":\"793\", \"side\":\"BUY\", \"hash\":\"3460d77cce74af1d246d7eda149daf19ea3d9963\", \"best_bid\":\"0.13\", \"best_ask\":\"0.14\"}, {\"asset_id\":\"61819828071723399190623735325323968706432622380635304641786792960078828866875\", \"price\":\"0.95\", \"size\":\"793\", \"side\":\"SELL\", \"hash\":\"da90e8d18d1c608cc49c9a876e53ed637c2a6e44\", \"best_bid\":\"0.86\", \"best_ask\":\"0.87\"}], \"timestamp\":\"1789987930966\", \"event_type\":\"price_change\"}","raw_base64":null}
{"received_ms":1789987930987,"monotonic_ns":1019371818171700,"raw":"{\"market\":\"0x28a45972fccdaf0fba75dacc59725521035e177d09dd92174f9f52740bccb025\", \"price_changes\":[{\"asset_id\":\"114356653315647913247200886351065428002113119844334520181865067698979836634569\", \"price\":\"0.06\", \"size\":\"5324.67\", \"side\":\"BUY\", \"hash\":\"401db53c0d71ec33a4f4f91e3d377607188946bf\", \"best_bid\":\"0.13\", \"best_ask\":\"0.14\"}, {\"asset_id\":\"61819828071723399190623735325323968706432622380635304641786792960078828866875\", \"price\":\"0.94\", \"size\":\"5324.67\", \"side\":\"SELL\", \"hash\":\"0db3e97ec6a2981b652ac117b065f73217c47684\", \"best_bid\":\"0.86\", \"best_ask\":\"0.87\"}], \"timestamp\":\"1789987930966\", \"event_type\":\"price_change\"}","raw_base64":null}
{"received_ms":1789987930990,"monotonic_ns":1019371820515500,"raw":"{\"market\":\"0x28a45972fccdaf0fba75dacc59725521035e177d09dd92174f9f52740bccb025\", \"price_changes\":[{\"asset_id\":\"61819828071723399190623735325323968706432622380635304641786792960078828866875\", \"price\":\"0.84\", \"size\":\"2703\", \"side\":\"BUY\", \"hash\":\"e3293852a3cf4ca4659dca3125bb3cb0108e296f\", \"best_bid\":\"0.86\", \"best_ask\":\"0.87\"}, {\"asset_id\":\"114356653315647913247200886351065428002113119844334520181865067698979836634569\", \"price\":\"0.16\", \"size\":\"2703\", \"side\":\"SELL\", \"hash\":\"7ce46b391b4d3059ca7db0b5365f641eba280044\", \"best_bid\":\"0.13\", \"best_ask\":\"0.14\"}], \"timestamp\":\"1789987930969\", \"event_type\":\"price_change\"}","raw_base64":null}
{"received_ms":1789987930990,"monotonic_ns":1019371821212200,"raw":"{\"market\":\"0x28a45972fccdaf0fba75dacc59725521035e177d09dd92174f9f52740bccb025\", \"price_changes\":[{\"asset_id\":\"61819828071723399190623735325323968706432622380635304641786792960078828866875\", \"price\":\"0.85\", \"size\":\"756.52\", \"side\":\"BUY\", \"hash\":\"b200c47594d8fe478acad30bd5986dcbda1b9ef4\", \"best_bid\":\"0.86\", \"best_ask\":\"0.87\"}, {\"asset_id\":\"114356653315647913247200886351065428002113119844334520181865067698979836634569\", \"price\":\"0.15\", \"size\":\"756.52\", \"side\":\"SELL\", \"hash\":\"70d94a009aaec8012cc46742944e2a12426135e9\", \"best_bid\":\"0.13\", \"best_ask\":\"0.14\"}], \"timestamp\":\"1789987930969\", \"event_type\":\"price_change\"}","raw_base64":null}
{"received_ms":1789987931007,"monotonic_ns":1019371837802400,"raw":"{\"market\":\"0x28a45972fccdaf0fba75dacc59725521035e177d09dd92174f9f52740bccb025\", \"price_changes\":[{\"asset_id\":\"61819828071723399190623735325323968706432622380635304641786792960078828866875\", \"price\":\"0.86\", \"size\":\"108.8\", \"side\":\"BUY\", \"hash\":\"bd965a4e688aa892f3a7df02809903de558beb8e\", \"best_bid\":\"0.86\", \"best_ask\":\"0.87\"}, {\"asset_id\":\"114356653315647913247200886351065428002113119844334520181865067698979836634569\", \"price\":\"0.14\", \"size\":\"108.8\", \"side\":\"SELL\", \"hash\":\"6b3188c21013aa4f782707f2cdc2330c9952c10d\", \"best_bid\":\"0.13\", \"best_ask\":\"0.14\"}], \"timestamp\":\"1789987930972\", \"event_type\":\"price_change\"}","raw_base64":null}
{"received_ms":1789987931007,"monotonic_ns":1019371837890100,"raw":"{\"market\":\"0x28a45972fccdaf0fba75dacc59725521035e177d09dd92174f9f52740bccb025\", \"price_changes\":[{\"asset_id\":\"61819828071723399190623735325323968706432622380635304641786792960078828866875\", \"price\":\"0.86\", \"size\":\"35\", \"side\":\"BUY\", \"hash\":\"90237e35b229326e2254c62330c96d9b828ada45\", \"best_bid\":\"0.86\", \"best_ask\":\"0.87\"}, {\"asset_id\":\"114356653315647913247200886351065428002113119844334520181865067698979836634569\", \"price\":\"0.14\", \"size\":\"35\", \"side\":\"SELL\", \"hash\":\"ddb9acb0c764cd8f447201b28811c38ea37a4f29\", \"best_bid\":\"0.13\", \"best_ask\":\"0.14\"}], \"timestamp\":\"1789987930975\", \"event_type\":\"price_change\"}","raw_base64":null}
{"received_ms":1789987931007,"monotonic_ns":1019371837941700,"raw":"{\"market\":\"0x28a45972fccdaf0fba75dacc59725521035e177d09dd92174f9f52740bccb025\", \"price_changes\":[{\"asset_id\":\"114356653315647913247200886351065428002113119844334520181865067698979836634569\", \"price\":\"0.07\", \"size\":\"6298.71\", \"side\":\"BUY\", \"hash\":\"d041888705429088fefbbc7ff14cfaf2c1e710d7\", \"best_bid\":\"0.13\", \"best_ask\":\"0.14\"}, {\"asset_id\":\"61819828071723399190623735325323968706432622380635304641786792960078828866875\", \"price\":\"0.93\", \"size\":\"6298.71\", \"side\":\"SELL\", \"hash\":\"5d15dda6de9e840287615d8c0033a63cb6a0bdbc\", \"best_bid\":\"0.86\", \"best_ask\":\"0.87\"}], \"timestamp\":\"1789987930979\", \"event_type\":\"price_change\"}","raw_base64":null}
{"received_ms":1789987931007,"monotonic_ns":1019371837983500,"raw":"{\"market\":\"0x28a45972fccdaf0fba75dacc59725521035e177d09dd92174f9f52740bccb025\", \"price_changes\":[{\"asset_id\":\"61819828071723399190623735325323968706432622380635304641786792960078828866875\", \"price\":\"0.73\", \"size\":\"484\", \"side\":\"BUY\", \"hash\":\"00d3d51194356c3b154bffc78f1f741ab32927c3\", \"best_bid\":\"0.86\", \"best_ask\":\"0.87\"}, {\"asset_id\":\"114356653315647913247200886351065428002113119844334520181865067698979836634569\", \"price\":\"0.27\", \"size\":\"484\", \"side\":\"SELL\", \"hash\":\"035e472722d09168a33579179386f78edc8370e5\", \"best_bid\":\"0.13\", \"best_ask\":\"0.14\"}], \"timestamp\":\"1789987930980\", \"event_type\":\"price_change\"}","raw_base64":null}
{"received_ms":1789987931007,"monotonic_ns":1019371838022600,"raw":"{\"market\":\"0x28a45972fccdaf0fba75dacc59725521035e177d09dd92174f9f52740bccb025\", \"price_changes\":[{\"asset_id\":\"114356653315647913247200886351065428002113119844334520181865067698979836634569\", \"price\":\"0.11\", \"size\":\"166.1\", \"side\":\"BUY\", \"hash\":\"afd1a0ab7ce93ba3e1a00bb61e63359d95ce9b0e\", \"best_bid\":\"0.13\", \"best_ask\":\"0.14\"}, {\"asset_id\":\"61819828071723399190623735325323968706432622380635304641786792960078828866875\", \"price\":\"0.89\", \"size\":\"166.1\", \"side\":\"SELL\", \"hash\":\"90f90ade2f33ac6eb71c037681b658d5f6c768a3\", \"best_bid\":\"0.86\", \"best_ask\":\"0.87\"}], \"timestamp\":\"1789987930981\", \"event_type\":\"price_change\"}","raw_base64":null}
{"received_ms":1789987931007,"monotonic_ns":1019371838060300,"raw":"{\"market\":\"0x28a45972fccdaf0fba75dacc59725521035e177d09dd92174f9f52740bccb025\", \"price_changes\":[{\"asset_id\":\"114356653315647913247200886351065428002113119844334520181865067698979836634569\", \"price\":\"0.11\", \"size\":\"146.1\", \"side\":\"BUY\", \"hash\":\"e6e4dad78b37a23b19d82bb9f157cd2b39510e0e\", \"best_bid\":\"0.13\", \"best_ask\":\"0.14\"}, {\"asset_id\":\"61819828071723399190623735325323968706432622380635304641786792960078828866875\", \"price\":\"0.89\", \"size\":\"146.1\", \"side\":\"SELL\", \"hash\":\"b4ef3c1d11ffea581ecf68df1dc7766a25be9a23\", \"best_bid\":\"0.86\", \"best_ask\":\"0.87\"}], \"timestamp\":\"1789987930981\", \"event_type\":\"price_change\"}","raw_base64":null}
{"received_ms":1789987931007,"monotonic_ns":1019371838096500,"raw":"{\"market\":\"0x28a45972fccdaf0fba75dacc59725521035e177d09dd92174f9f52740bccb025\", \"price_changes\":[{\"asset_id\":\"61819828071723399190623735325323968706432622380635304641786792960078828866875\", \"price\":\"0.73\", \"size\":\"404\", \"side\":\"BUY\", \"hash\":\"c79826ea1ebf51cd7dc7a0263470a30fac84c7d0\", \"best_bid\":\"0.86\", \"best_ask\":\"0.87\"}, {\"asset_id\":\"114356653315647913247200886351065428002113119844334520181865067698979836634569\", \"price\":\"0.27\", \"size\":\"404\", \"side\":\"SELL\", \"hash\":\"a363c58817a507089575b1424f6f1e6ae03958e3\", \"best_bid\":\"0.13\", \"best_ask\":\"0.14\"}], \"timestamp\":\"1789987930982\", \"event_type\":\"price_change\"}","raw_base64":null}
{"received_ms":1789987931007,"monotonic_ns":1019371838132300,"raw":"{\"market\":\"0x28a45972fccdaf0fba75dacc59725521035e177d09dd92174f9f52740bccb025\", \"price_changes\":[{\"asset_id\":\"61819828071723399190623735325323968706432622380635304641786792960078828866875\", \"price\":\"0.84\", \"size\":\"2803\", \"side\":\"BUY\", \"hash\":\"61830261ec337da3ce5756da27d899055d0ffd51\", \"best_bid\":\"0.86\", \"best_ask\":\"0.87\"}, {\"asset_id\":\"114356653315647913247200886351065428002113119844334520181865067698979836634569\", \"price\":\"0.16\", \"size\":\"2803\", \"side\":\"SELL\", \"hash\":\"67ecf610bae9036b98ab42bfbc4e38bdcd08ddb3\", \"best_bid\":\"0.13\", \"best_ask\":\"0.14\"}], \"timestamp\":\"1789987930983\", \"event_type\":\"price_change\"}","raw_base64":null}
{"received_ms":1789987931014,"monotonic_ns":1019371844549900,"raw":"{\"market\":\"0x28a45972fccdaf0fba75dacc59725521035e177d09dd92174f9f52740bccb025\", \"price_changes\":[{\"asset_id\":\"114356653315647913247200886351065428002113119844334520181865067698979836634569\", \"price\":\"0.13\", \"size\":\"511\", \"side\":\"BUY\", \"hash\":\"4df0566dcdd9be286f153edb3fa0a95b44ce1ac0\", \"best_bid\":\"0.13\", \"best_ask\":\"0.14\"}, {\"asset_id\":\"61819828071723399190623735325323968706432622380635304641786792960078828866875\", \"price\":\"0.87\", \"size\":\"511\", \"side\":\"SELL\", \"hash\":\"1e756a46ce5e639b5b95394ea77d272c5773e4cb\", \"best_bid\":\"0.86\", \"best_ask\":\"0.87\"}], \"timestamp\":\"1789987930984\", \"event_type\":\"price_change\"}","raw_base64":null}
{"received_ms":1789987931014,"monotonic_ns":1019371844611100,"raw":"{\"market\":\"0x28a45972fccdaf0fba75dacc59725521035e177d09dd92174f9f52740bccb025\", \"price_changes\":[{\"asset_id\":\"114356653315647913247200886351065428002113119844334520181865067698979836634569\", \"price\":\"0.06\", \"size\":\"4806.67\", \"side\":\"BUY\", \"hash\":\"6275e433a90ba70353987ff1252539e5426608ba\", \"best_bid\":\"0.13\", \"best_ask\":\"0.14\"}, {\"asset_id\":\"61819828071723399190623735325323968706432622380635304641786792960078828866875\", \"price\":\"0.94\", \"size\":\"4806.67\", \"side\":\"SELL\", \"hash\":\"00989ac981346e0b59221f71b9ffcbae8cab64b7\", \"best_bid\":\"0.86\", \"best_ask\":\"0.87\"}], \"timestamp\":\"1789987930985\", \"event_type\":\"price_change\"}","raw_base64":null}
{"received_ms":1789987931014,"monotonic_ns":1019371844683800,"raw":"{\"market\":\"0x28a45972fccdaf0fba75dacc59725521035e177d09dd92174f9f52740bccb025\", \"price_changes\":[{\"asset_id\":\"61819828071723399190623735325323968706432622380635304641786792960078828866875\", \"price\":\"0.86\", \"size\":\"55\", \"side\":\"BUY\", \"hash\":\"f818cb2ca26e0ac53466ffe2e7d5f26c5bb99d25\", \"best_bid\":\"0.86\", \"best_ask\":\"0.87\"}, {\"asset_id\":\"114356653315647913247200886351065428002113119844334520181865067698979836634569\", \"price\":\"0.14\", \"size\":\"55\", \"side\":\"SELL\", \"hash\":\"955c4e626ac0bdcbfa072527623f1247ba93ee6e\", \"best_bid\":\"0.13\", \"best_ask\":\"0.14\"}], \"timestamp\":\"1789987930985\", \"event_type\":\"price_change\"}","raw_base64":null}
{"received_ms":1789987931014,"monotonic_ns":1019371844738900,"raw":"{\"market\":\"0x28a45972fccdaf0fba75dacc59725521035e177d09dd92174f9f52740bccb025\", \"price_changes\":[{\"asset_id\":\"61819828071723399190623735325323968706432622380635304641786792960078828866875\", \"price\":\"0.85\", \"size\":\"696.52\", \"side\":\"BUY\", \"hash\":\"eb16912f84e97e27a7798bcf1561cab4f4a11fcf\", \"best_bid\":\"0.86\", \"best_ask\":\"0.87\"}, {\"asset_id\":\"114356653315647913247200886351065428002113119844334520181865067698979836634569\", \"price\":\"0.15\", \"size\":\"696.52\", \"side\":\"SELL\", \"hash\":\"bf200a273a757f922a99ddd4e4ff704bc86408b4\", \"best_bid\":\"0.13\", \"best_ask\":\"0.14\"}], \"timestamp\":\"1789987930986\", \"event_type\":\"price_change\"}","raw_base64":null}
{"received_ms":1789987931014,"monotonic_ns":1019371844780100,"raw":"{\"market\":\"0x28a45972fccdaf0fba75dacc59725521035e177d09dd92174f9f52740bccb025\", \"price_changes\":[{\"asset_id\":\"114356653315647913247200886351065428002113119844334520181865067698979836634569\", \"price\":\"0.06\", \"size\":\"4826.67\", \"side\":\"BUY\", \"hash\":\"222287ad24ec7deaf926b977ec525a67e23f9df7\", \"best_bid\":\"0.13\", \"best_ask\":\"0.14\"}, {\"asset_id\":\"61819828071723399190623735325323968706432622380635304641786792960078828866875\", \"price\":\"0.94\", \"size\":\"4826.67\", \"side\":\"SELL\", \"hash\":\"a369217a8d9653bb934d6cc8c5bce85e7f6631d7\", \"best_bid\":\"0.86\", \"best_ask\":\"0.87\"}], \"timestamp\":\"1789987930986\", \"event_type\":\"price_change\"}","raw_base64":null}
{"received_ms":1789987931014,"monotonic_ns":1019371844818300,"raw":"{\"market\":\"0x28a45972fccdaf0fba75dacc59725521035e177d09dd92174f9f52740bccb025\", \"price_changes\":[{\"asset_id\":\"114356653315647913247200886351065428002113119844334520181865067698979836634569\", \"price\":\"0.03\", \"size\":\"4057.57\", \"side\":\"BUY\", \"hash\":\"a64469d94ee31e34a898d960b9308b061bb2a333\", \"best_bid\":\"0.13\", \"best_ask\":\"0.14\"}, {\"asset_id\":\"61819828071723399190623735325323968706432622380635304641786792960078828866875\", \"price\":\"0.97\", \"size\":\"4057.57\", \"side\":\"SELL\", \"hash\":\"9213932712c4e422cb1b9c620d820c44734a7e91\", \"best_bid\":\"0.86\", \"best_ask\":\"0.87\"}], \"timestamp\":\"1789987930987\", \"event_type\":\"price_change\"}","raw_base64":null}
{"received_ms":1789987931014,"monotonic_ns":1019371844855300,"raw":"{\"market\":\"0x28a45972fccdaf0fba75dacc59725521035e177d09dd92174f9f52740bccb025\", \"price_changes\":[{\"asset_id\":\"61819828071723399190623735325323968706432622380635304641786792960078828866875\", \"price\":\"0.83\", \"size\":\"673\", \"side\":\"BUY\", \"hash\":\"b9e40cdee45c47211484eef2f2288b9a7fff24ce\", \"best_bid\":\"0.86\", \"best_ask\":\"0.87\"}, {\"asset_id\":\"114356653315647913247200886351065428002113119844334520181865067698979836634569\", \"price\":\"0.17\", \"size\":\"673\", \"side\":\"SELL\", \"hash\":\"65e129fb4ae156487245716ace9142d936392ab3\", \"best_bid\":\"0.13\", \"best_ask\":\"0.14\"}], \"timestamp\":\"1789987930988\", \"event_type\":\"price_change\"}","raw_base64":null}
{"received_ms":1789987931014,"monotonic_ns":1019371844891900,"raw":"{\"market\":\"0x28a45972fccdaf0fba75dacc59725521035e177d09dd92174f9f52740bccb025\", \"price_changes\":[{\"asset_id\":\"61819828071723399190623735325323968706432622380635304641786792960078828866875\", \"price\":\"0.85\", \"size\":\"596.52\", \"side\":\"BUY\", \"hash\":\"53442f2aed6ea29a6dbb1f6f27c3d80c3ab585b7\", \"best_bid\":\"0.86\", \"best_ask\":\"0.87\"}, {\"asset_id\":\"114356653315647913247200886351065428002113119844334520181865067698979836634569\", \"price\":\"0.15\", \"size\":\"596.52\", \"side\":\"SELL\", \"hash\":\"7f39863894174de1251811d48a7c796af7bf0a58\", \"best_bid\":\"0.13\", \"best_ask\":\"0.14\"}], \"timestamp\":\"1789987930989\", \"event_type\":\"price_change\"}","raw_base64":null}
{"received_ms":1789987931015,"monotonic_ns":1019371845337600,"raw":"{\"market\":\"0x28a45972fccdaf0fba75dacc59725521035e177d09dd92174f9f52740bccb025\", \"price_changes\":[{\"asset_id\":\"61819828071723399190623735325323968706432622380635304641786792960078828866875\", \"price\":\"0.84\", \"size\":\"3145\", \"side\":\"BUY\", \"hash\":\"f90231d57a0ef1b808b24c16b1ee26918c535275\", \"best_bid\":\"0.86\", \"best_ask\":\"0.87\"}, {\"asset_id\":\"114356653315647913247200886351065428002113119844334520181865067698979836634569\", \"price\":\"0.16\", \"size\":\"3145\", \"side\":\"SELL\", \"hash\":\"0d1d7a9aa972ed3b9de58148df56d1eba18d782e\", \"best_bid\":\"0.13\", \"best_ask\":\"0.14\"}], \"timestamp\":\"1789987930989\", \"event_type\":\"price_change\"}","raw_base64":null}
{"received_ms":1789987931031,"monotonic_ns":1019371861401500,"raw":"{\"market\":\"0x28a45972fccdaf0fba75dacc59725521035e177d09dd92174f9f52740bccb025\", \"price_changes\":[{\"asset_id\":\"61819828071723399190623735325323968706432622380635304641786792960078828866875\", \"price\":\"0.86\", \"size\":\"139\", \"side\":\"BUY\", \"hash\":\"b6416b3ba42b7f85bfd1ad849014292ad636521b\", \"best_bid\":\"0.86\", \"best_ask\":\"0.87\"}, {\"asset_id\":\"114356653315647913247200886351065428002113119844334520181865067698979836634569\", \"price\":\"0.14\", \"size\":\"139\", \"side\":\"SELL\", \"hash\":\"6537336ed95297ee737a3bc9129419b770d422d2\", \"best_bid\":\"0.13\", \"best_ask\":\"0.14\"}], \"timestamp\":\"1789987930990\", \"event_type\":\"price_change\"}","raw_base64":null}
{"received_ms":1789987931031,"monotonic_ns":1019371861491500,"raw":"{\"market\":\"0x28a45972fccdaf0fba75dacc59725521035e177d09dd92174f9f52740bccb025\", \"price_changes\":[{\"asset_id\":\"61819828071723399190623735325323968706432622380635304641786792960078828866875\", \"price\":\"0.85\", \"size\":\"1707.52\", \"side\":\"BUY\", \"hash\":\"cb4dc73be0e442a820dcf41d36d9b12fc1d2d3c5\", \"best_bid\":\"0.86\", \"best_ask\":\"0.87\"}, {\"asset_id\":\"114356653315647913247200886351065428002113119844334520181865067698979836634569\", \"price\":\"0.15\", \"size\":\"1707.52\", \"side\":\"SELL\", \"hash\":\"31d8ddb6ebb3ffa035afb2511f5ab986d95c559c\", \"best_bid\":\"0.13\", \"best_ask\":\"0.14\"}], \"timestamp\":\"1789987930991\", \"event_type\":\"price_change\"}","raw_base64":null}
{"received_ms":1789987931031,"monotonic_ns":1019371861535000,"raw":"{\"market\":\"0x28a45972fccdaf0fba75dacc59725521035e177d09dd92174f9f52740bccb025\", \"price_changes\":[{\"asset_id\":\"61819828071723399190623735325323968706432622380635304641786792960078828866875\", \"price\":\"0.94\", \"size\":\"4856.67\", \"side\":\"SELL\", \"hash\":\"a0916f3f0c5435d37966635dfa0d7aba1a6dd5dc\", \"best_bid\":\"0.86\", \"best_ask\":\"0.87\"}, {\"asset_id\":\"114356653315647913247200886351065428002113119844334520181865067698979836634569\", \"price\":\"0.06\", \"size\":\"4856.67\", \"side\":\"BUY\", \"hash\":\"b32ce6b519fd01b5f9ac9076992768e4132d8ace\", \"best_bid\":\"0.13\", \"best_ask\":\"0.14\"}], \"timestamp\":\"1789987930992\", \"event_type\":\"price_change\"}","raw_base64":null}
{"received_ms":1789987931031,"monotonic_ns":1019371861574400,"raw":"{\"market\":\"0x28a45972fccdaf0fba75dacc59725521035e177d09dd92174f9f52740bccb025\", \"price_changes\":[{\"asset_id\":\"61819828071723399190623735325323968706432622380635304641786792960078828866875\", \"price\":\"0.85\", \"size\":\"1697.52\", \"side\":\"BUY\", \"hash\":\"ba5d69db677f1ee190a170c56201ee1e25a52dc2\", \"best_bid\":\"0.86\", \"best_ask\":\"0.87\"}, {\"asset_id\":\"114356653315647913247200886351065428002113119844334520181865067698979836634569\", \"price\":\"0.15\", \"size\":\"1697.52\", \"side\":\"SELL\", \"hash\":\"ed0f95f35cf0060d7f3fa24a393fff74dbd65fb1\", \"best_bid\":\"0.13\", \"best_ask\":\"0.14\"}], \"timestamp\":\"1789987930993\", \"event_type\":\"price_change\"}","raw_base64":null}
{"received_ms":1789987931031,"monotonic_ns":1019371861611700,"raw":"{\"market\":\"0x28a45972fccdaf0fba75dacc59725521035e177d09dd92174f9f52740bccb025\", \"price_changes\":[{\"asset_id\":\"61819828071723399190623735325323968706432622380635304641786792960078828866875\", \"price\":\"0.86\", \"size\":\"134\", \"side\":\"BUY\", \"hash\":\"9365604447a6e06af8e9bac6540a36b71936d074\", \"best_bid\":\"0.86\", \"best_ask\":\"0.87\"}, {\"asset_id\":\"114356653315647913247200886351065428002113119844334520181865067698979836634569\", \"price\":\"0.14\", \"size\":\"134\", \"side\":\"SELL\", \"hash\":\"6ed7268c108be4f5d0631ba038034eb6cebd5ac3\", \"best_bid\":\"0.13\", \"best_ask\":\"0.14\"}], \"timestamp\":\"1789987930993\", \"event_type\":\"price_change\"}","raw_base64":null}
{"received_ms":1789987931031,"monotonic_ns":1019371861655600,"raw":"{\"market\":\"0x28a45972fccdaf0fba75dacc59725521035e177d09dd92174f9f52740bccb025\", \"price_changes\":[{\"asset_id\":\"114356653315647913247200886351065428002113119844334520181865067698979836634569\", \"price\":\"0.12\", \"size\":\"334\", \"side\":\"BUY\", \"hash\":\"9edb4d414afee0e42306045a365127198828fa20\", \"best_bid\":\"0.13\", \"best_ask\":\"0.14\"}, {\"asset_id\":\"61819828071723399190623735325323968706432622380635304641786792960078828866875\", \"price\":\"0.88\", \"size\":\"334\", \"side\":\"SELL\", \"hash\":\"0c05e626f3188213673ca7f1bc50b20a29e6a72b\", \"best_bid\":\"0.86\", \"best_ask\":\"0.87\"}], \"timestamp\":\"1789987930998\", \"event_type\":\"price_change\"}","raw_base64":null}
{"received_ms":1789987931031,"monotonic_ns":1019371861692300,"raw":"{\"market\":\"0x28a45972fccdaf0fba75dacc59725521035e177d09dd92174f9f52740bccb025\", \"price_changes\":[{\"asset_id\":\"61819828071723399190623735325323968706432622380635304641786792960078828866875\", \"price\":\"0.77\", \"size\":\"507.49\", \"side\":\"BUY\", \"hash\":\"7fb33d99367ae31277badf7dc90993dc19d52f96\", \"best_bid\":\"0.86\", \"best_ask\":\"0.87\"}, {\"asset_id\":\"114356653315647913247200886351065428002113119844334520181865067698979836634569\", \"price\":\"0.23\", \"size\":\"507.49\", \"side\":\"SELL\", \"hash\":\"dc92734f82e2964a36dff000ed9922f726b98408\", \"best_bid\":\"0.13\", \"best_ask\":\"0.14\"}], \"timestamp\":\"1789987931005\", \"event_type\":\"price_change\"}","raw_base64":null}
{"received_ms":1789987931031,"monotonic_ns":1019371861727700,"raw":"{\"market\":\"0x28a45972fccdaf0fba75dacc59725521035e177d09dd92174f9f52740bccb025\", \"price_changes\":[{\"asset_id\":\"61819828071723399190623735325323968706432622380635304641786792960078828866875\", \"price\":\"0.75\", \"size\":\"510\", \"side\":\"BUY\", \"hash\":\"1ead3089259e2e5f617cb831e2df657af940931e\", \"best_bid\":\"0.86\", \"best_ask\":\"0.87\"}, {\"asset_id\":\"114356653315647913247200886351065428002113119844334520181865067698979836634569\", \"price\":\"0.25\", \"size\":\"510\", \"side\":\"SELL\", \"hash\":\"6a5bdf9bc13a32bbbcf59d3adf7269bc79450ef0\", \"best_bid\":\"0.13\", \"best_ask\":\"0.14\"}], \"timestamp\":\"1789987931006\", \"event_type\":\"price_change\"}","raw_base64":null}
{"received_ms":1789987931031,"monotonic_ns":1019371861762900,"raw":"{\"market\":\"0x28a45972fccdaf0fba75dacc59725521035e177d09dd92174f9f52740bccb025\", \"price_changes\":[{\"asset_id\":\"114356653315647913247200886351065428002113119844334520181865067698979836634569\", \"price\":\"0.07\", \"size\":\"6278.71\", \"side\":\"BUY\", \"hash\":\"6a5bdf9bc13a32bbbcf59d3adf7269bc79450ef0\", \"best_bid\":\"0.13\", \"best_ask\":\"0.14\"}, {\"asset_id\":\"61819828071723399190623735325323968706432622380635304641786792960078828866875\", \"price\":\"0.93\", \"size\":\"6278.71\", \"side\":\"SELL\", \"hash\":\"1ead3089259e2e5f617cb831e2df657af940931e\", \"best_bid\":\"0.86\", \"best_ask\":\"0.87\"}], \"timestamp\":\"1789987931006\", \"event_type\":\"price_change\"}","raw_base64":null}
{"received_ms":1789987931037,"monotonic_ns":1019371867453700,"raw":"{\"market\":\"0x28a45972fccdaf0fba75dacc59725521035e177d09dd92174f9f52740bccb025\", \"price_changes\":[{\"asset_id\":\"114356653315647913247200886351065428002113119844334520181865067698979836634569\", \"price\":\"0.12\", \"size\":\"342.34\", \"side\":\"BUY\", \"hash\":\"bfe8a7cf9587e9584a7452093447ca0810db4ffe\", \"best_bid\":\"0.13\", \"best_ask\":\"0.14\"}, {\"asset_id\":\"61819828071723399190623735325323968706432622380635304641786792960078828866875\", \"price\":\"0.88\", \"size\":\"342.34\", \"side\":\"SELL\", \"hash\":\"6df055ca179c4155522e7955bad38d775cb08272\", \"best_bid\":\"0.86\", \"best_ask\":\"0.87\"}], \"timestamp\":\"1789987931008\", \"event_type\":\"price_change\"}","raw_base64":null}
{"received_ms":1789987931039,"monotonic_ns":1019371869947300,"raw":"{\"market\":\"0x28a45972fccdaf0fba75dacc59725521035e177d09dd92174f9f52740bccb025\", \"price_changes\":[{\"asset_id\":\"114356653315647913247200886351065428002113119844334520181865067698979836634569\", \"price\":\"0.13\", \"size\":\"526.5\", \"side\":\"BUY\", \"hash\":\"ce6d88c2e0548282e4549ac629a7dd010a86dbf2\", \"best_bid\":\"0.13\", \"best_ask\":\"0.14\"}, {\"asset_id\":\"61819828071723399190623735325323968706432622380635304641786792960078828866875\", \"price\":\"0.87\", \"size\":\"526.5\", \"side\":\"SELL\", \"hash\":\"bb70142c3116574d3148251aa6fbf06bb620e53c\", \"best_bid\":\"0.86\", \"best_ask\":\"0.87\"}], \"timestamp\":\"1789987931016\", \"event_type\":\"price_change\"}","raw_base64":null}
{"received_ms":1789987931040,"monotonic_ns":1019371870968800,"raw":"{\"market\":\"0x28a45972fccdaf0fba75dacc59725521035e177d09dd92174f9f52740bccb025\", \"price_changes\":[{\"asset_id\":\"114356653315647913247200886351065428002113119844334520181865067698979836634569\", \"price\":\"0.07\", \"size\":\"6253.71\", \"side\":\"BUY\", \"hash\":\"0d6bc1bf7c569586dbd9810a1c8e10d9031baac1\", \"best_bid\":\"0.13\", \"best_ask\":\"0.14\"}, {\"asset_id\":\"61819828071723399190623735325323968706432622380635304641786792960078828866875\", \"price\":\"0.93\", \"size\":\"6253.71\", \"side\":\"SELL\", \"hash\":\"50a313b291e6c0fb4947fc45dff35370a164e23a\", \"best_bid\":\"0.86\", \"best_ask\":\"0.87\"}], \"timestamp\":\"1789987931019\", \"event_type\":\"price_change\"}","raw_base64":null}
{"received_ms":1789987931041,"monotonic_ns":1019371872022800,"raw":"{\"market\":\"0x28a45972fccdaf0fba75dacc59725521035e177d09dd92174f9f52740bccb025\", \"price_changes\":[{\"asset_id\":\"61819828071723399190623735325323968706432622380635304641786792960078828866875\", \"price\":\"0.77\", \"size\":\"527.49\", \"side\":\"BUY\", \"hash\":\"40602c69b7da17c73ddc918fee2da6519c6bdf95\", \"best_bid\":\"0.86\", \"best_ask\":\"0.87\"}, {\"asset_id\":\"114356653315647913247200886351065428002113119844334520181865067698979836634569\", \"price\":\"0.23\", \"size\":\"527.49\", \"side\":\"SELL\", \"hash\":\"de2bdfd29b8cbb414ded43b3b57ce0f1ab790b20\", \"best_bid\":\"0.13\", \"best_ask\":\"0.14\"}], \"timestamp\":\"1789987931019\", \"event_type\":\"price_change\"}","raw_base64":null}
{"received_ms":1789987931041,"monotonic_ns":1019371872107700,"raw":"{\"market\":\"0x28a45972fccdaf0fba75dacc59725521035e177d09dd92174f9f52740bccb025\", \"price_changes\":[{\"asset_id\":\"61819828071723399190623735325323968706432622380635304641786792960078828866875\", \"price\":\"0.86\", \"size\":\"50\", \"side\":\"BUY\", \"hash\":\"2737bc217d2d37050241a595207bdd719f6b9062\", \"best_bid\":\"0.86\", \"best_ask\":\"0.87\"}, {\"asset_id\":\"114356653315647913247200886351065428002113119844334520181865067698979836634569\", \"price\":\"0.14\", \"size\":\"50\", \"side\":\"SELL\", \"hash\":\"9e817a4b70e3bc544f8730d6eff94a22e78f47af\", \"best_bid\":\"0.13\", \"best_ask\":\"0.14\"}], \"timestamp\":\"1789987931020\", \"event_type\":\"price_change\"}","raw_base64":null}
{"received_ms":1789987931045,"monotonic_ns":1019371875792800,"raw":"{\"market\":\"0x28a45972fccdaf0fba75dacc59725521035e177d09dd92174f9f52740bccb025\", \"price_changes\":[{\"asset_id\":\"114356653315647913247200886351065428002113119844334520181865067698979836634569\", \"price\":\"0.07\", \"size\":\"7837.71\", \"side\":\"BUY\", \"hash\":\"3500a1bab22d766cd14821f3d3a41de78fb9ad7f\", \"best_bid\":\"0.13\", \"best_ask\":\"0.14\"}, {\"asset_id\":\"61819828071723399190623735325323968706432622380635304641786792960078828866875\", \"price\":\"0.93\", \"size\":\"7837.71\", \"side\":\"SELL\", \"hash\":\"895e48ee6375d753275d4156ead10137f5492354\", \"best_bid\":\"0.86\", \"best_ask\":\"0.87\"}], \"timestamp\":\"1789987931023\", \"event_type\":\"price_change\"}","raw_base64":null}
{"received_ms":1789987931045,"monotonic_ns":1019371875836100,"raw":"{\"market\":\"0x28a45972fccdaf0fba75dacc59725521035e177d09dd92174f9f52740bccb025\", \"price_changes\":[{\"asset_id\":\"61819828071723399190623735325323968706432622380635304641786792960078828866875\", \"price\":\"0.86\", \"size\":\"25\", \"side\":\"BUY\", \"hash\":\"44aec3a27cd091d86b9887832f6a3c9ab19f0b8e\", \"best_bid\":\"0.86\", \"best_ask\":\"0.87\"}, {\"asset_id\":\"114356653315647913247200886351065428002113119844334520181865067698979836634569\", \"price\":\"0.14\", \"size\":\"25\", \"side\":\"SELL\", \"hash\":\"f55526cfeacc508244b4c6cbc990280fff6ffc3e\", \"best_bid\":\"0.13\", \"best_ask\":\"0.14\"}], \"timestamp\":\"1789987931024\", \"event_type\":\"price_change\"}","raw_base64":null}
{"received_ms":1789987931048,"monotonic_ns":1019371878385200,"raw":"{\"market\":\"0x28a45972fccdaf0fba75dacc59725521035e177d09dd92174f9f52740bccb025\", \"price_changes\":[{\"asset_id\":\"114356653315647913247200886351065428002113119844334520181865067698979836634569\", \"price\":\"0.06\", \"size\":\"5076.67\", \"side\":\"BUY\", \"hash\":\"81b56e6ba4d3eac6d3895fc52f6036f5a8fe009a\", \"best_bid\":\"0.13\", \"best_ask\":\"0.14\"}, {\"asset_id\":\"61819828071723399190623735325323968706432622380635304641786792960078828866875\", \"price\":\"0.94\", \"size\":\"5076.67\", \"side\":\"SELL\", \"hash\":\"146c6b3380dde9c0af1fbf7072cc49fd3529cb8e\", \"best_bid\":\"0.86\", \"best_ask\":\"0.87\"}], \"timestamp\":\"1789987931024\", \"event_type\":\"price_change\"}","raw_base64":null}
{"received_ms":1789987931048,"monotonic_ns":1019371878487700,"raw":"{\"market\":\"0x28a45972fccdaf0fba75dacc59725521035e177d09dd92174f9f52740bccb025\", \"price_changes\":[{\"asset_id\":\"114356653315647913247200886351065428002113119844334520181865067698979836634569\", \"price\":\"0.11\", \"size\":\"166.1\", \"side\":\"BUY\", \"hash\":\"70f7b52cbc54a3f4d1bd512abd4fd9820453c0d8\", \"best_bid\":\"0.13\", \"best_ask\":\"0.14\"}, {\"asset_id\":\"61819828071723399190623735325323968706432622380635304641786792960078828866875\", \"price\":\"0.89\", \"size\":\"166.1\", \"side\":\"SELL\", \"hash\":\"abd1935e472cdb77013b03168ba87cb73201ff98\", \"best_bid\":\"0.86\", \"best_ask\":\"0.87\"}], \"timestamp\":\"1789987931025\", \"event_type\":\"price_change\"}","raw_base64":null}
{"received_ms":1789987931048,"monotonic_ns":1019371878532300,"raw":"{\"market\":\"0x28a45972fccdaf0fba75dacc59725521035e177d09dd92174f9f52740bccb025\", \"price_changes\":[{\"asset_id\":\"114356653315647913247200886351065428002113119844334520181865067698979836634569\", \"price\":\"0.05\", \"size\":\"5652\", \"side\":\"BUY\", \"hash\":\"0793310b74bf0ae051ee90d24b3880b005307d67\", \"best_bid\":\"0.13\", \"best_ask\":\"0.14\"}, {\"asset_id\":\"61819828071723399190623735325323968706432622380635304641786792960078828866875\", \"price\":\"0.95\", \"size\":\"5652\", \"side\":\"SELL\", \"hash\":\"b467bc3c5b3d7954cdfdee19bc388c3011b4b1f3\", \"best_bid\":\"0.86\", \"best_ask\":\"0.87\"}], \"timestamp\":\"1789987931025\", \"event_type\":\"price_change\"}","raw_base64":null}
{"received_ms":1789987931051,"monotonic_ns":1019371881397800,"raw":"{\"market\":\"0x28a45972fccdaf0fba75dacc59725521035e177d09dd92174f9f52740bccb025\", \"price_changes\":[{\"asset_id\":\"61819828071723399190623735325323968706432622380635304641786792960078828866875\", \"price\":\"0.83\", \"size\":\"573\", \"side\":\"BUY\", \"hash\":\"b9c1baa1301cd570685b9978215ae5ea92ff988d\", \"best_bid\":\"0.86\", \"best_ask\":\"0.87\"}, {\"asset_id\":\"114356653315647913247200886351065428002113119844334520181865067698979836634569\", \"price\":\"0.17\", \"size\":\"573\", \"side\":\"SELL\", \"hash\":\"517fad82580310bdbf15428385c6e5f30a38416d\", \"best_bid\":\"0.13\", \"best_ask\":\"0.14\"}], \"timestamp\":\"1789987931028\", \"event_type\":\"price_change\"}","raw_base64":null}
{"received_ms":1789987931060,"monotonic_ns":1019371890754700,"raw":"{\"market\":\"0x28a45972fccdaf0fba75dacc59725521035e177d09dd92174f9f52740bccb025\", \"price_changes\":[{\"asset_id\":\"61819828071723399190623735325323968706432622380635304641786792960078828866875\", \"price\":\"0.85\", \"size\":\"1797.52\", \"side\":\"BUY\", \"hash\":\"cac8cad75839dbd333891d37b94b9560d175fcac\", \"best_bid\":\"0.86\", \"best_ask\":\"0.87\"}, {\"asset_id\":\"114356653315647913247200886351065428002113119844334520181865067698979836634569\", \"price\":\"0.15\", \"size\":\"1797.52\", \"side\":\"SELL\", \"hash\":\"bf6c6d47dff11fc1771737b140773f15d95639ee\", \"best_bid\":\"0.13\", \"best_ask\":\"0.14\"}], \"timestamp\":\"1789987931029\", \"event_type\":\"price_change\"}","raw_base64":null}
{"received_ms":1789987931060,"monotonic_ns":1019371890792900,"raw":"{\"market\":\"0x28a45972fccdaf0fba75dacc59725521035e177d09dd92174f9f52740bccb025\", \"price_changes\":[{\"asset_id\":\"61819828071723399190623735325323968706432622380635304641786792960078828866875\", \"price\":\"0.77\", \"size\":\"507.49\", \"side\":\"BUY\", \"hash\":\"1779e34a3c1772723ec6e9cc2ba5edcc89e7b9b3\", \"best_bid\":\"0.86\", \"best_ask\":\"0.87\"}, {\"asset_id\":\"114356653315647913247200886351065428002113119844334520181865067698979836634569\", \"price\":\"0.23\", \"size\":\"507.49\", \"side\":\"SELL\", \"hash\":\"fc091c20c3fb4187d6f14991cf6c3d7ab18536ee\", \"best_bid\":\"0.13\", \"best_ask\":\"0.14\"}], \"timestamp\":\"1789987931032\", \"event_type\":\"price_change\"}","raw_base64":null}
{"received_ms":1789987931063,"monotonic_ns":1019371893265800,"raw":"{\"market\":\"0x28a45972fccdaf0fba75dacc59725521035e177d09dd92174f9f52740bccb025\", \"price_changes\":[{\"asset_id\":\"114356653315647913247200886351065428002113119844334520181865067698979836634569\", \"price\":\"0.07\", \"size\":\"7857.71\", \"side\":\"BUY\", \"hash\":\"3c383b7ae8b2f498410d37d2e8c586ff74b1bb84\", \"best_bid\":\"0.13\", \"best_ask\":\"0.14\"}, {\"asset_id\":\"61819828071723399190623735325323968706432622380635304641786792960078828866875\", \"price\":\"0.93\", \"size\":\"7857.71\", \"side\":\"SELL\", \"hash\":\"ccd5f4070859693e594986ce602abdfbe2c997e1\", \"best_bid\":\"0.86\", \"best_ask\":\"0.87\"}], \"timestamp\":\"1789987931038\", \"event_type\":\"price_change\"}","raw_base64":null}
{"received_ms":1789987931067,"monotonic_ns":1019371897887000,"raw":"{\"market\":\"0x28a45972fccdaf0fba75dacc59725521035e177d09dd92174f9f52740bccb025\", \"price_changes\":[{\"asset_id\":\"114356653315647913247200886351065428002113119844334520181865067698979836634569\", \"price\":\"0.01\", \"size\":\"1674.43\", \"side\":\"BUY\", \"hash\":\"6573fd08867b53f95c0fabd9dddd415329876ae4\", \"best_bid\":\"0.13\", \"best_ask\":\"0.14\"}, {\"asset_id\":\"61819828071723399190623735325323968706432622380635304641786792960078828866875\", \"price\":\"0.99\", \"size\":\"1674.43\", \"side\":\"SELL\", \"hash\":\"3b966deb4117e89cf58681aa51f041d05d43abd1\", \"best_bid\":\"0.86\", \"best_ask\":\"0.87\"}], \"timestamp\":\"1789987931045\", \"event_type\":\"price_change\"}","raw_base64":null}
{"received_ms":1789987931068,"monotonic_ns":1019371899073900,"raw":"{\"market\":\"0x28a45972fccdaf0fba75dacc59725521035e177d09dd92174f9f52740bccb025\", \"price_changes\":[{\"asset_id\":\"114356653315647913247200886351065428002113119844334520181865067698979836634569\", \"price\":\"0.07\", \"size\":\"7837.71\", \"side\":\"BUY\", \"hash\":\"9af3ddc9c5dd9c1b60acf142850bc577d1cf9bf8\", \"best_bid\":\"0.13\", \"best_ask\":\"0.14\"}, {\"asset_id\":\"61819828071723399190623735325323968706432622380635304641786792960078828866875\", \"price\":\"0.93\", \"size\":\"7837.71\", \"side\":\"SELL\", \"hash\":\"d154d2946eb3cf7da37c14c49936da1520f7a492\", \"best_bid\":\"0.86\", \"best_ask\":\"0.87\"}], \"timestamp\":\"1789987931046\", \"event_type\":\"price_change\"}","raw_base64":null}
{"received_ms":1789987931068,"monotonic_ns":1019371899155600,"raw":"{\"market\":\"0x28a45972fccdaf0fba75dacc59725521035e177d09dd92174f9f52740bccb025\", \"price_changes\":[{\"asset_id\":\"61819828071723399190623735325323968706432622380635304641786792960078828866875\", \"price\":\"0.83\", \"size\":\"513\", \"side\":\"BUY\", \"hash\":\"d154d2946eb3cf7da37c14c49936da1520f7a492\", \"best_bid\":\"0.86\", \"best_ask\":\"0.87\"}, {\"asset_id\":\"114356653315647913247200886351065428002113119844334520181865067698979836634569\", \"price\":\"0.17\", \"size\":\"513\", \"side\":\"SELL\", \"hash\":\"9af3ddc9c5dd9c1b60acf142850bc577d1cf9bf8\", \"best_bid\":\"0.13\", \"best_ask\":\"0.14\"}], \"timestamp\":\"1789987931046\", \"event_type\":\"price_change\"}","raw_base64":null}
{"received_ms":1789987931070,"monotonic_ns":1019371900489700,"raw":"{\"market\":\"0x28a45972fccdaf0fba75dacc59725521035e177d09dd92174f9f52740bccb025\", \"price_changes\":[{\"asset_id\":\"114356653315647913247200886351065428002113119844334520181865067698979836634569\", \"price\":\"0.13\", \"size\":\"551.5\", \"side\":\"BUY\", \"hash\":\"4106e24425a65f63f55fb2cf9d21f9c70e09a098\", \"best_bid\":\"0.13\", \"best_ask\":\"0.14\"}, {\"asset_id\":\"61819828071723399190623735325323968706432622380635304641786792960078828866875\", \"price\":\"0.87\", \"size\":\"551.5\", \"side\":\"SELL\", \"hash\":\"5d0bf4984d92374db0ce5bcb9d817a2f8e03e0f1\", \"best_bid\":\"0.86\", \"best_ask\":\"0.87\"}], \"timestamp\":\"1789987931049\", \"event_type\":\"price_change\"}","raw_base64":null}
{"received_ms":1789987931073,"monotonic_ns":1019371903804300,"raw":"{\"market\":\"0x28a45972fccdaf0fba75dacc59725521035e177d09dd92174f9f52740bccb025\", \"price_changes\":[{\"asset_id\":\"61819828071723399190623735325323968706432622380635304641786792960078828866875\", \"price\":\"0.85\", \"size\":\"1792.52\", \"side\":\"BUY\", \"hash\":\"71433d7014578200602872659cb734717a3ac037\", \"best_bid\":\"0.86\", \"best_ask\":\"0.87\"}, {\"asset_id\":\"114356653315647913247200886351065428002113119844334520181865067698979836634569\", \"price\":\"0.15\", \"size\":\"1792.52\", \"side\":\"SELL\", \"hash\":\"764a3ba0c50e17b51fb5c826a80c8b3ef2687544\", \"best_bid\":\"0.13\", \"best_ask\":\"0.14\"}], \"timestamp\":\"1789987931051\", \"event_type\":\"price_change\"}","raw_base64":null}
{"received_ms":1789987931073,"monotonic_ns":1019371904164400,"raw":"{\"market\":\"0x28a45972fccdaf0fba75dacc59725521035e177d09dd92174f9f52740bccb025\", \"price_changes\":[{\"asset_id\":\"61819828071723399190623735325323968706432622380635304641786792960078828866875\", \"price\":\"0.85\", \"size\":\"1782.52\", \"side\":\"BUY\", \"hash\":\"c18610fe76681804bd7b001b12ab6ad15cac62a4\", \"best_bid\":\"0.86\", \"best_ask\":\"0.87\"}, {\"asset_id\":\"114356653315647913247200886351065428002113119844334520181865067698979836634569\", \"price\":\"0.15\", \"size\":\"1782.52\", \"side\":\"SELL\", \"hash\":\"1bf79d172948587dc529aa66b837e4a5c680e231\", \"best_bid\":\"0.13\", \"best_ask\":\"0.14\"}], \"timestamp\":\"1789987931052\", \"event_type\":\"price_change\"}","raw_base64":null}
{"received_ms":1789987931074,"monotonic_ns":1019371904308300,"raw":"{\"market\":\"0x28a45972fccdaf0fba75dacc59725521035e177d09dd92174f9f52740bccb025\", \"price_changes\":[{\"asset_id\":\"61819828071723399190623735325323968706432622380635304641786792960078828866875\", \"price\":\"0.85\", \"size\":\"1767.35\", \"side\":\"BUY\", \"hash\":\"fb7c17739ae0ba2551afc06460d82933b6ab7d2a\", \"best_bid\":\"0.86\", \"best_ask\":\"0.87\"}, {\"asset_id\":\"114356653315647913247200886351065428002113119844334520181865067698979836634569\", \"price\":\"0.15\", \"size\":\"1767.35\", \"side\":\"SELL\", \"hash\":\"d2e27fc22414f9ed35ca27c200ad8aa35bf1737f\", \"best_bid\":\"0.13\", \"best_ask\":\"0.14\"}], \"timestamp\":\"1789987931053\", \"event_type\":\"price_change\"}","raw_base64":null}
{"received_ms":1789987931076,"monotonic_ns":1019371907181700,"raw":"{\"market\":\"0x28a45972fccdaf0fba75dacc59725521035e177d09dd92174f9f52740bccb025\", \"price_changes\":[{\"asset_id\":\"114356653315647913247200886351065428002113119844334520181865067698979836634569\", \"price\":\"0.05\", \"size\":\"793\", \"side\":\"BUY\", \"hash\":\"9c93090cadc1a29753c2f6f9746ab0c482c2dcfc\", \"best_bid\":\"0.13\", \"best_ask\":\"0.14\"}, {\"asset_id\":\"61819828071723399190623735325323968706432622380635304641786792960078828866875\", \"price\":\"0.95\", \"size\":\"793\", \"side\":\"SELL\", \"hash\":\"a26a264b3c605edd59e3fd3d5b96cc919842fc53\", \"best_bid\":\"0.86\", \"best_ask\":\"0.87\"}], \"timestamp\":\"1789987931054\", \"event_type\":\"price_change\"}","raw_base64":null}
{"received_ms":1789987931079,"monotonic_ns":1019371909916900,"raw":"{\"market\":\"0x28a45972fccdaf0fba75dacc59725521035e177d09dd92174f9f52740bccb025\", \"price_changes\":[{\"asset_id\":\"61819828071723399190623735325323968706432622380635304641786792960078828866875\", \"price\":\"0.86\", \"size\":\"207\", \"side\":\"BUY\", \"hash\":\"9b5a75335ab52cfb4ef0b02463269a1a6b31136b\", \"best_bid\":\"0.86\", \"best_ask\":\"0.87\"}, {\"asset_id\":\"114356653315647913247200886351065428002113119844334520181865067698979836634569\", \"price\":\"0.14\", \"size\":\"207\", \"side\":\"SELL\", \"hash\":\"3b00790d2c074e8ac17f38e1d6b80144299fb6af\", \"best_bid\":\"0.13\", \"best_ask\":\"0.14\"}], \"timestamp\":\"1789987931056\", \"event_type\":\"price_change\"}","raw_base64":null}
{"received_ms":1789987931079,"monotonic_ns":1019371910011800,"raw":"{\"market\":\"0x28a45972fccdaf0fba75dacc59725521035e177d09dd92174f9f52740bccb025\", \"price_changes\":[{\"asset_id\":\"61819828071723399190623735325323968706432622380635304641786792960078828866875\", \"price\":\"0.85\", \"size\":\"1747.35\", \"side\":\"BUY\", \"hash\":\"7114f29f642fe517b9150f0e87435a942cac8083\", \"best_bid\":\"0.86\", \"best_ask\":\"0.87\"}, {\"asset_id\":\"114356653315647913247200886351065428002113119844334520181865067698979836634569\", \"price\":\"0.15\", \"size\":\"1747.35\", \"side\":\"SELL\", \"hash\":\"7a130f460e1a6b66300d5e4afb03873c92e2ea64\", \"best_bid\":\"0.13\", \"best_ask\":\"0.14\"}], \"timestamp\":\"1789987931056\", \"event_type\":\"price_change\"}","raw_base64":null}
{"received_ms":1789987931079,"monotonic_ns":1019371910053000,"raw":"{\"market\":\"0x28a45972fccdaf0fba75dacc59725521035e177d09dd92174f9f52740bccb025\", \"price_changes\":[{\"asset_id\":\"114356653315647913247200886351065428002113119844334520181865067698979836634569\", \"price\":\"0.03\", \"size\":\"4037.57\", \"side\":\"BUY\", \"hash\":\"5bfbcec3822b84cc4746df4d4ecea351d8546253\", \"best_bid\":\"0.13\", \"best_ask\":\"0.14\"}, {\"asset_id\":\"61819828071723399190623735325323968706432622380635304641786792960078828866875\", \"price\":\"0.97\", \"size\":\"4037.57\", \"side\":\"SELL\", \"hash\":\"b92020ab34fa98ea16eee56b6a5c02bdaef70484\", \"best_bid\":\"0.86\", \"best_ask\":\"0.87\"}], \"timestamp\":\"1789987931057\", \"event_type\":\"price_change\"}","raw_base64":null}
{"received_ms":1789987931079,"monotonic_ns":1019371910098200,"raw":"{\"market\":\"0x28a45972fccdaf0fba75dacc59725521035e177d09dd92174f9f52740bccb025\", \"price_changes\":[{\"asset_id\":\"61819828071723399190623735325323968706432622380635304641786792960078828866875\", \"price\":\"0.75\", \"size\":\"430\", \"side\":\"BUY\", \"hash\":\"b92020ab34fa98ea16eee56b6a5c02bdaef70484\", \"best_bid\":\"0.86\", \"best_ask\":\"0.87\"}, {\"asset_id\":\"114356653315647913247200886351065428002113119844334520181865067698979836634569\", \"price\":\"0.25\", \"size\":\"430\", \"side\":\"SELL\", \"hash\":\"5bfbcec3822b84cc4746df4d4ecea351d8546253\", \"best_bid\":\"0.13\", \"best_ask\":\"0.14\"}], \"timestamp\":\"1789987931057\", \"event_type\":\"price_change\"}","raw_base64":null}
{"received_ms":1789987931079,"monotonic_ns":1019371910135700,"raw":"{\"market\":\"0x28a45972fccdaf0fba75dacc59725521035e177d09dd92174f9f52740bccb025\", \"price_changes\":[{\"asset_id\":\"114356653315647913247200886351065428002113119844334520181865067698979836634569\", \"price\":\"0.21\", \"size\":\"422\", \"side\":\"SELL\", \"hash\":\"a795fe1448a8569efedc7e8bfac39796a60f03af\", \"best_bid\":\"0.13\", \"best_ask\":\"0.14\"}, {\"asset_id\":\"61819828071723399190623735325323968706432622380635304641786792960078828866875\", \"price\":\"0.79\", \"size\":\"422\", \"side\":\"BUY\", \"hash\":\"dbdbfab5e9e1d8578f6214efce0d7957808c7354\", \"best_bid\":\"0.86\", \"best_ask\":\"0.87\"}], \"timestamp\":\"1789987931058\", \"event_type\":\"price_change\"}","raw_base64":null}
{"received_ms":1789987931081,"monotonic_ns":1019371912048500,"raw":"{\"market\":\"0x28a45972fccdaf0fba75dacc59725521035e177d09dd92174f9f52740bccb025\", \"price_changes\":[{\"asset_id\":\"61819828071723399190623735325323968706432622380635304641786792960078828866875\", \"price\":\"0.75\", \"size\":\"440\", \"side\":\"BUY\", \"hash\":\"2101819f61825bc22928ca519c05a0339856c37a\", \"best_bid\":\"0.86\", \"best_ask\":\"0.87\"}, {\"asset_id\":\"114356653315647913247200886351065428002113119844334520181865067698979836634569\", \"price\":\"0.25\", \"size\":\"440\", \"side\":\"SELL\", \"hash\":\"ec61e4d3e8d69d4bd1e12263cfe4ffe246326803\", \"best_bid\":\"0.13\", \"best_ask\":\"0.14\"}], \"timestamp\":\"1789987931060\", \"event_type\":\"price_change\"}","raw_base64":null}
{"received_ms":1789987931085,"monotonic_ns":1019371915330700,"raw":"{\"market\":\"0x28a45972fccdaf0fba75dacc59725521035e177d09dd92174f9f52740bccb025\", \"price_changes\":[{\"asset_id\":\"61819828071723399190623735325323968706432622380635304641786792960078828866875\", \"price\":\"0.8\", \"size\":\"587\", \"side\":\"BUY\", \"hash\":\"42c286f7239caf30061b5600d46e669ba11b4f3b\", \"best_bid\":\"0.86\", \"best_ask\":\"0.87\"}, {\"asset_id\":\"114356653315647913247200886351065428002113119844334520181865067698979836634569\", \"price\":\"0.2\", \"size\":\"587\", \"side\":\"SELL\", \"hash\":\"297d55f8d121fae2ef0e9462db3a79542c32df84\", \"best_bid\":\"0.13\", \"best_ask\":\"0.14\"}], \"timestamp\":\"1789987931063\", \"event_type\":\"price_change\"}","raw_base64":null}
{"received_ms":1789987931087,"monotonic_ns":1019371917340700,"raw":"{\"market\":\"0x28a45972fccdaf0fba75dacc59725521035e177d09dd92174f9f52740bccb025\", \"price_changes\":[{\"asset_id\":\"61819828071723399190623735325323968706432622380635304641786792960078828866875\", \"price\":\"0.84\", \"size\":\"3566\", \"side\":\"BUY\", \"hash\":\"7e8221eda2760450ca893f104d06cfa05f270a2d\", \"best_bid\":\"0.86\", \"best_ask\":\"0.87\"}, {\"asset_id\":\"114356653315647913247200886351065428002113119844334520181865067698979836634569\", \"price\":\"0.16\", \"size\":\"3566\", \"side\":\"SELL\", \"hash\":\"66e60dece783e24435921b8800084c6994d0157b\", \"best_bid\":\"0.13\", \"best_ask\":\"0.14\"}], \"timestamp\":\"1789987931065\", \"event_type\":\"price_change\"}","raw_base64":null}
{"received_ms":1789987931087,"monotonic_ns":1019371917433200,"raw":"{\"market\":\"0x28a45972fccdaf0fba75dacc59725521035e177d09dd92174f9f52740bccb025\", \"price_changes\":[{\"asset_id\":\"61819828071723399190623735325323968706432622380635304641786792960078828866875\", \"price\":\"0.85\", \"size\":\"3047.35\", \"side\":\"BUY\", \"hash\":\"aab0371543dd2352b8ffe1f6d4b146aeadc0ff01\", \"best_bid\":\"0.86\", \"best_ask\":\"0.87\"}, {\"asset_id\":\"114356653315647913247200886351065428002113119844334520181865067698979836634569\", \"price\":\"0.15\", \"size\":\"3047.35\", \"side\":\"SELL\", \"hash\":\"cca73ecf7c65e34d056b2cde041fa772bc2bc3af\", \"best_bid\":\"0.13\", \"best_ask\":\"0.14\"}], \"timestamp\":\"1789987931065\", \"event_type\":\"price_change\"}","raw_base64":null}
{"received_ms":1789987931105,"monotonic_ns":1019371935726900,"raw":"{\"market\":\"0x28a45972fccdaf0fba75dacc59725521035e177d09dd92174f9f52740bccb025\", \"price_changes\":[{\"asset_id\":\"61819828071723399190623735325323968706432622380635304641786792960078828866875\", \"price\":\"0.84\", \"size\":\"2886\", \"side\":\"BUY\", \"hash\":\"9a647f1cf368e1eccd6841ad784fa684c2987467\", \"best_bid\":\"0.86\", \"best_ask\":\"0.87\"}, {\"asset_id\":\"114356653315647913247200886351065428002113119844334520181865067698979836634569\", \"price\":\"0.16\", \"size\":\"2886\", \"side\":\"SELL\", \"hash\":\"3a59713c2459755543fd2e57fe9eb79eab128927\", \"best_bid\":\"0.13\", \"best_ask\":\"0.14\"}], \"timestamp\":\"1789987931083\", \"event_type\":\"price_change\"}","raw_base64":null}
{"received_ms":1789987931107,"monotonic_ns":1019371937792700,"raw":"{\"market\":\"0x28a45972fccdaf0fba75dacc59725521035e177d09dd92174f9f52740bccb025\", \"price_changes\":[{\"asset_id\":\"61819828071723399190623735325323968706432622380635304641786792960078828866875\", \"price\":\"0.77\", \"size\":\"527.49\", \"side\":\"BUY\", \"hash\":\"57daa81306b71a9b4ed87025fabc8de7340da459\", \"best_bid\":\"0.86\", \"best_ask\":\"0.87\"}, {\"asset_id\":\"114356653315647913247200886351065428002113119844334520181865067698979836634569\", \"price\":\"0.23\", \"size\":\"527.49\", \"side\":\"SELL\", \"hash\":\"e16ea015e995fdfc31f5fe70f85176df55f8c5c3\", \"best_bid\":\"0.13\", \"best_ask\":\"0.14\"}], \"timestamp\":\"1789987931087\", \"event_type\":\"price_change\"}","raw_base64":null}
{"received_ms":1789987931111,"monotonic_ns":1019371941481100,"raw":"{\"market\":\"0x28a45972fccdaf0fba75dacc59725521035e177d09dd92174f9f52740bccb025\", \"price_changes\":[{\"asset_id\":\"61819828071723399190623735325323968706432622380635304641786792960078828866875\", \"price\":\"0.85\", \"size\":\"3082.52\", \"side\":\"BUY\", \"hash\":\"278c019b4d3f0788a28c6dcdc5d5ada7b8024024\", \"best_bid\":\"0.86\", \"best_ask\":\"0.87\"}, {\"asset_id\":\"114356653315647913247200886351065428002113119844334520181865067698979836634569\", \"price\":\"0.15\", \"size\":\"3082.52\", \"side\":\"SELL\", \"hash\":\"cde32302e6f26dd3a0cf08f2572eee86a5c130e5\", \"best_bid\":\"0.13\", \"best_ask\":\"0.14\"}], \"timestamp\":\"1789987931087\", \"event_type\":\"price_change\"}","raw_base64":null}
{"received_ms":1789987931111,"monotonic_ns":1019371941541300,"raw":"{\"market\":\"0x28a45972fccdaf0fba75dacc59725521035e177d09dd92174f9f52740bccb025\", \"price_changes\":[{\"asset_id\":\"61819828071723399190623735325323968706432622380635304641786792960078828866875\", \"price\":\"0.83\", \"size\":\"573\", \"side\":\"BUY\", \"hash\":\"a6b7eb003c91c1f71d0422ecc66d848b6f612b1c\", \"best_bid\":\"0.86\", \"best_ask\":\"0.87\"}, {\"asset_id\":\"114356653315647913247200886351065428002113119844334520181865067698979836634569\", \"price\":\"0.17\", \"size\":\"573\", \"side\":\"SELL\", \"hash\":\"5a584baf69727f1990ff76fd59b6581113d6fcb9\", \"best_bid\":\"0.13\", \"best_ask\":\"0.14\"}], \"timestamp\":\"1789987931088\", \"event_type\":\"price_change\"}","raw_base64":null}
{"received_ms":1789987931115,"monotonic_ns":1019371945335300,"raw":"{\"market\":\"0x28a45972fccdaf0fba75dacc59725521035e177d09dd92174f9f52740bccb025\", \"price_changes\":[{\"asset_id\":\"61819828071723399190623735325323968706432622380635304641786792960078828866875\", \"price\":\"0.8\", \"size\":\"607\", \"side\":\"BUY\", \"hash\":\"79f802214f6397f9adec8fae95bc570ac44ae4e1\", \"best_bid\":\"0.86\", \"best_ask\":\"0.87\"}, {\"asset_id\":\"114356653315647913247200886351065428002113119844334520181865067698979836634569\", \"price\":\"0.2\", \"size\":\"607\", \"side\":\"SELL\", \"hash\":\"a5dd2167aeb1d93c18ea1ac04e9396ca2188d3c3\", \"best_bid\":\"0.13\", \"best_ask\":\"0.14\"}], \"timestamp\":\"1789987931093\", \"event_type\":\"price_change\"}","raw_base64":null}
{"received_ms":1789987931116,"monotonic_ns":1019371946803200,"raw":"{\"market\":\"0x28a45972fccdaf0fba75dacc59725521035e177d09dd92174f9f52740bccb025\", \"price_changes\":[{\"asset_id\":\"61819828071723399190623735325323968706432622380635304641786792960078828866875\", \"price\":\"0.83\", \"size\":\"543\", \"side\":\"BUY\", \"hash\":\"30bea7d3b776855fa894eff938511caa0aebf467\", \"best_bid\":\"0.86\", \"best_ask\":\"0.87\"}, {\"asset_id\":\"114356653315647913247200886351065428002113119844334520181865067698979836634569\", \"price\":\"0.17\", \"size\":\"543\", \"side\":\"SELL\", \"hash\":\"42377b3340d54d6b50c947406b56578fee321e88\", \"best_bid\":\"0.13\", \"best_ask\":\"0.14\"}], \"timestamp\":\"1789987931094\", \"event_type\":\"price_change\"}","raw_base64":null}
{"received_ms":1789987931118,"monotonic_ns":1019371948570600,"raw":"{\"market\":\"0x28a45972fccdaf0fba75dacc59725521035e177d09dd92174f9f52740bccb025\", \"price_changes\":[{\"asset_id\":\"114356653315647913247200886351065428002113119844334520181865067698979836634569\", \"price\":\"0.07\", \"size\":\"7857.71\", \"side\":\"BUY\", \"hash\":\"54a84d5b80555c15b0e23516674a819ea408abec\", \"best_bid\":\"0.13\", \"best_ask\":\"0.14\"}, {\"asset_id\":\"61819828071723399190623735325323968706432622380635304641786792960078828866875\", \"price\":\"0.93\", \"size\":\"7857.71\", \"side\":\"SELL\", \"hash\":\"226a92010ef9cde2aa5107752a5e6a3ddfd87adb\", \"best_bid\":\"0.86\", \"best_ask\":\"0.87\"}], \"timestamp\":\"1789987931097\", \"event_type\":\"price_change\"}","raw_base64":null}
{"received_ms":1789987931119,"monotonic_ns":1019371949766900,"raw":"{\"market\":\"0x28a45972fccdaf0fba75dacc59725521035e177d09dd92174f9f52740bccb025\", \"price_changes\":[{\"asset_id\":\"61819828071723399190623735325323968706432622380635304641786792960078828866875\", \"price\":\"0.77\", \"size\":\"587.49\", \"side\":\"BUY\", \"hash\":\"a62e8b9de6a813ebe47d8d7f2acd3a74e473ef06\", \"best_bid\":\"0.86\", \"best_ask\":\"0.87\"}, {\"asset_id\":\"114356653315647913247200886351065428002113119844334520181865067698979836634569\", \"price\":\"0.23\", \"size\":\"587.49\", \"side\":\"SELL\", \"hash\":\"108f49ddeb448d3593cff8345452491608080cc2\", \"best_bid\":\"0.13\", \"best_ask\":\"0.14\"}], \"timestamp\":\"1789987931098\", \"event_type\":\"price_change\"}","raw_base64":null}
{"received_ms":1789987931121,"monotonic_ns":1019371951319500,"raw":"{\"market\":\"0x28a45972fccdaf0fba75dacc59725521035e177d09dd92174f9f52740bccb025\", \"price_changes\":[{\"asset_id\":\"114356653315647913247200886351065428002113119844334520181865067698979836634569\", \"price\":\"0.07\", \"size\":\"7957.71\", \"side\":\"BUY\", \"hash\":\"4360646f3195d8aa9ac9c8a43562716637c255c6\", \"best_bid\":\"0.13\", \"best_ask\":\"0.14\"}, {\"asset_id\":\"61819828071723399190623735325323968706432622380635304641786792960078828866875\", \"price\":\"0.93\", \"size\":\"7957.71\", \"side\":\"SELL\", \"hash\":\"98ba878eacb504f69b45b11fa0ef504e94b67760\", \"best_bid\":\"0.86\", \"best_ask\":\"0.87\"}], \"timestamp\":\"1789987931099\", \"event_type\":\"price_change\"}","raw_base64":null}
{"received_ms":1789987931121,"monotonic_ns":1019371951432900,"raw":"{\"market\":\"0x28a45972fccdaf0fba75dacc59725521035e177d09dd92174f9f52740bccb025\", \"price_changes\":[{\"asset_id\":\"61819828071723399190623735325323968706432622380635304641786792960078828866875\", \"price\":\"0.84\", \"size\":\"2465\", \"side\":\"BUY\", \"hash\":\"aa610c4961c79e753004e9a5f214390e22d6f600\", \"best_bid\":\"0.86\", \"best_ask\":\"0.87\"}, {\"asset_id\":\"114356653315647913247200886351065428002113119844334520181865067698979836634569\", \"price\":\"0.16\", \"size\":\"2465\", \"side\":\"SELL\", \"hash\":\"60e1b69f69e4744a81e24def362acaba10d4847b\", \"best_bid\":\"0.13\", \"best_ask\":\"0.14\"}], \"timestamp\":\"1789987931099\", \"event_type\":\"price_change\"}","raw_base64":null}
{"received_ms":1789987931121,"monotonic_ns":1019371951478600,"raw":"{\"market\":\"0x28a45972fccdaf0fba75dacc59725521035e177d09dd92174f9f52740bccb025\", \"price_changes\":[{\"asset_id\":\"61819828071723399190623735325323968706432622380635304641786792960078828866875\", \"price\":\"0.86\", \"size\":\"25\", \"side\":\"BUY\", \"hash\":\"2377009ec9dedb28cb6ab8af5c9ca50cc5885021\", \"best_bid\":\"0.86\", \"best_ask\":\"0.87\"}, {\"asset_id\":\"114356653315647913247200886351065428002113119844334520181865067698979836634569\", \"price\":\"0.14\", \"size\":\"25\", \"side\":\"SELL\", \"hash\":\"3795333e782105fbf1dd6442802b49e30d2f3fbf\", \"best_bid\":\"0.13\", \"best_ask\":\"0.14\"}], \"timestamp\":\"1789987931100\", \"event_type\":\"price_change\"}","raw_base64":null}
{"received_ms":1789987931121,"monotonic_ns":1019371951520200,"raw":"{\"market\":\"0x28a45972fccdaf0fba75dacc59725521035e177d09dd92174f9f52740bccb025\", \"price_changes\":[{\"asset_id\":\"114356653315647913247200886351065428002113119844334520181865067698979836634569\", \"price\":\"0.05\", \"size\":\"5649\", \"side\":\"BUY\", \"hash\":\"eeda0da4d117892cea715c87f7736f79b2505b74\", \"best_bid\":\"0.13\", \"best_ask\":\"0.14\"}, {\"asset_id\":\"61819828071723399190623735325323968706432622380635304641786792960078828866875\", \"price\":\"0.95\", \"size\":\"5649\", \"side\":\"SELL\", \"hash\":\"5335c4146af56d67e6a9513f83c4eaa273286b05\", \"best_bid\":\"0.86\", \"best_ask\":\"0.87\"}], \"timestamp\":\"1789987931100\", \"event_type\":\"price_change\"}","raw_base64":null}
{"received_ms":1789987931123,"monotonic_ns":1019371953329100,"raw":"{\"market\":\"0x28a45972fccdaf0fba75dacc59725521035e177d09dd92174f9f52740bccb025\", \"price_changes\":[{\"asset_id\":\"114356653315647913247200886351065428002113119844334520181865067698979836634569\", \"price\":\"0.06\", \"size\":\"5181.67\", \"side\":\"BUY\", \"hash\":\"18815c3eb1ea5e609da03538a00b933fb3efba20\", \"best_bid\":\"0.13\", \"best_ask\":\"0.14\"}, {\"asset_id\":\"61819828071723399190623735325323968706432622380635304641786792960078828866875\", \"price\":\"0.94\", \"size\":\"5181.67\", \"side\":\"SELL\", \"hash\":\"48398beda0df057836c2798b9e81c2e5cd7d5376\", \"best_bid\":\"0.86\", \"best_ask\":\"0.87\"}], \"timestamp\":\"1789987931101\", \"event_type\":\"price_change\"}","raw_base64":null}
{"received_ms":1789987931123,"monotonic_ns":1019371953376900,"raw":"{\"market\":\"0x28a45972fccdaf0fba75dacc59725521035e177d09dd92174f9f52740bccb025\", \"price_changes\":[{\"asset_id\":\"114356653315647913247200886351065428002113119844334520181865067698979836634569\", \"price\":\"0.01\", \"size\":\"1694.43\", \"side\":\"BUY\", \"hash\":\"0efffcb13da9781598481d3582a8aa543e0f92d2\", \"best_bid\":\"0.13\", \"best_ask\":\"0.14\"}, {\"asset_id\":\"61819828071723399190623735325323968706432622380635304641786792960078828866875\", \"price\":\"0.99\", \"size\":\"1694.43\", \"side\":\"SELL\", \"hash\":\"e963a3ac9c0b312caf4661de092f5d1cd6ae7b94\", \"best_bid\":\"0.86\", \"best_ask\":\"0.87\"}], \"timestamp\":\"1789987931102\", \"event_type\":\"price_change\"}","raw_base64":null}
{"received_ms":1789987931127,"monotonic_ns":1019371957586800,"raw":"{\"market\":\"0x28a45972fccdaf0fba75dacc59725521035e177d09dd92174f9f52740bccb025\", \"price_changes\":[{\"asset_id\":\"114356653315647913247200886351065428002113119844334520181865067698979836634569\", \"price\":\"0.01\", \"size\":\"1674.43\", \"side\":\"BUY\", \"hash\":\"09a472dd56d98bcd4acf6605578ca89b9c31e3fd\", \"best_bid\":\"0.13\", \"best_ask\":\"0.14\"}, {\"asset_id\":\"61819828071723399190623735325323968706432622380635304641786792960078828866875\", \"price\":\"0.99\", \"size\":\"1674.43\", \"side\":\"SELL\", \"hash\":\"710404e78cf4f0164c104086da6a3b49c3444d82\", \"best_bid\":\"0.86\", \"best_ask\":\"0.87\"}], \"timestamp\":\"1789987931107\", \"event_type\":\"price_change\"}","raw_base64":null}
{"received_ms":1789987931141,"monotonic_ns":1019371971708000,"raw":"{\"market\":\"0x28a45972fccdaf0fba75dacc59725521035e177d09dd92174f9f52740bccb025\", \"price_changes\":[{\"asset_id\":\"114356653315647913247200886351065428002113119844334520181865067698979836634569\", \"price\":\"0.06\", \"size\":\"4961.67\", \"side\":\"BUY\", \"hash\":\"1707c70af42387c94a9bb96a49f4b9d6df06205a\", \"best_bid\":\"0.13\", \"best_ask\":\"0.14\"}, {\"asset_id\":\"61819828071723399190623735325323968706432622380635304641786792960078828866875\", \"price\":\"0.94\", \"size\":\"4961.67\", \"side\":\"SELL\", \"hash\":\"8a41b6d08b91c4f1b3b1e7d58923a6ecf7da4636\", \"best_bid\":\"0.86\", \"best_ask\":\"0.87\"}], \"timestamp\":\"1789987931120\", \"event_type\":\"price_change\"}","raw_base64":null}
{"received_ms":1789987931144,"monotonic_ns":1019371975138200,"raw":"{\"market\":\"0x28a45972fccdaf0fba75dacc59725521035e177d09dd92174f9f52740bccb025\", \"price_changes\":[{\"asset_id\":\"61819828071723399190623735325323968706432622380635304641786792960078828866875\", \"price\":\"0.75\", \"size\":\"520\", \"side\":\"BUY\", \"hash\":\"178cfccedc1899ee6b303235b05a5593f3b04e4f\", \"best_bid\":\"0.86\", \"best_ask\":\"0.87\"}, {\"asset_id\":\"114356653315647913247200886351065428002113119844334520181865067698979836634569\", \"price\":\"0.25\", \"size\":\"520\", \"side\":\"SELL\", \"hash\":\"89cc630a1eae05be7359b91aaa8e3cd630c32337\", \"best_bid\":\"0.13\", \"best_ask\":\"0.14\"}], \"timestamp\":\"1789987931124\", \"event_type\":\"price_change\"}","raw_base64":null}
{"received_ms":1789987931146,"monotonic_ns":1019371976482700,"raw":"{\"market\":\"0x28a45972fccdaf0fba75dacc59725521035e177d09dd92174f9f52740bccb025\", \"price_changes\":[{\"asset_id\":\"61819828071723399190623735325323968706432622380635304641786792960078828866875\", \"price\":\"0.77\", \"size\":\"507.49\", \"side\":\"BUY\", \"hash\":\"3be7268b5444d50d85cffbf88343e78988953488\", \"best_bid\":\"0.86\", \"best_ask\":\"0.87\"}, {\"asset_id\":\"114356653315647913247200886351065428002113119844334520181865067698979836634569\", \"price\":\"0.23\", \"size\":\"507.49\", \"side\":\"SELL\", \"hash\":\"d7d47cd247a4c9b4aba19df1ae5e9e2b9e04ee76\", \"best_bid\":\"0.13\", \"best_ask\":\"0.14\"}], \"timestamp\":\"1789987931125\", \"event_type\":\"price_change\"}","raw_base64":null}
