{"received_ms":1789987927802,"monotonic_ns":1019368632639300,"raw":"{\"market\":\"0x28a45972fccdaf0fba75dacc59725521035e177d09dd92174f9f52740bccb025\", \"price_changes\":[{\"asset_id\":\"114356653315647913247200886351065428002113119844334520181865067698979836634569\", \"price\":\"0.07\", \"size\":\"6859.71\", \"side\":\"BUY\", \"hash\":\"0acf0cf1d0dcc5ec2b154abb813bc739620a849b\", \"best_bid\":\"0.13\", \"best_ask\":\"0.14\"}, {\"asset_id\":\"61819828071723399190623735325323968706432622380635304641786792960078828866875\", \"price\":\"0.93\", \"size\":\"6859.71\", \"side\":\"SELL\", \"hash\":\"07ad4c39fe4f646233088d2308da7416aa9dd360\", \"best_bid\":\"0.86\", \"best_ask\":\"0.87\"}], \"timestamp\":\"1789987927781\", \"event_type\":\"price_change\"}","raw_base64":null}
{"received_ms":1789987927804,"monotonic_ns":1019368634556600,"raw":"{\"market\":\"0x28a45972fccdaf0fba75dacc59725521035e177d09dd92174f9f52740bccb025\", \"price_changes\":[{\"asset_id\":\"114356653315647913247200886351065428002113119844334520181865067698979836634569\", \"price\":\"0.13\", \"size\":\"280\", \"side\":\"BUY\", \"hash\":\"95a0157b14367a0148152ab56d6a5edf27763561\", \"best_bid\":\"0.13\", \"best_ask\":\"0.14\"}, {\"asset_id\":\"61819828071723399190623735325323968706432622380635304641786792960078828866875\", \"price\":\"0.87\", \"size\":\"280\", \"side\":\"SELL\", \"hash\":\"888cd9d07a5620e9b4e9944b6621221224095d44\", \"best_bid\":\"0.86\", \"best_ask\":\"0.87\"}], \"timestamp\":\"1789987927781\", \"event_type\":\"price_change\"}","raw_base64":null}
{"received_ms":1789987927804,"monotonic_ns":1019368634606400,"raw":"{\"market\":\"0x28a45972fccdaf0fba75dacc59725521035e177d09dd92174f9f52740bccb025\", \"price_changes\":[{\"asset_id\":\"61819828071723399190623735325323968706432622380635304641786792960078828866875\", \"price\":\"0.85\", \"size\":\"772.52\", \"side\":\"BUY\", \"hash\":\"c29536174773e93447146dbadb4c70357c1eb6df\", \"best_bid\":\"0.86\", \"best_ask\":\"0.87\"}, {\"asset_id\":\"114356653315647913247200886351065428002113119844334520181865067698979836634569\", \"price\":\"0.15\", \"size\":\"772.52\", \"side\":\"SELL\", \"hash\":\"4f7e05551a7b06510a8155f0aa55f347432c34fe\", \"best_bid\":\"0.13\", \"best_ask\":\"0.14\"}], \"timestamp\":\"1789987927782\", \"event_type\":\"price_change\"}","raw_base64":null}
{"received_ms":1789987927804,"monotonic_ns":1019368634647100,"raw":"{\"market\":\"0x28a45972fccdaf0fba75dacc59725521035e177d09dd92174f9f52740bccb025\", \"price_changes\":[{\"asset_id\":\"61819828071723399190623735325323968706432622380635304641786792960078828866875\", \"price\":\"0.86\", \"size\":\"368\", \"side\":\"BUY\", \"hash\":\"3e7a8df0b0740ed80505296606bedbff0c6dd47f\", \"best_bid\":\"0.86\", \"best_ask\":\"0.87\"}, {\"asset_id\":\"114356653315647913247200886351065428002113119844334520181865067698979836634569\", \"price\":\"0.14\", \"size\":\"368\", \"side\":\"SELL\", \"hash\":\"1a486d3c59dbe885f08ff1080b90d3a3ed72912f\", \"best_bid\":\"0.13\", \"best_ask\":\"0.14\"}], \"timestamp\":\"1789987927782\", \"event_type\":\"price_change\"}","raw_base64":null}
{"received_ms":1789987927804,"monotonic_ns":1019368634686800,"raw":"{\"market\":\"0x28a45972fccdaf0fba75dacc59725521035e177d09dd92174f9f52740bccb025\", \"price_changes\":[{\"asset_id\":\"61819828071723399190623735325323968706432622380635304641786792960078828866875\", \"price\":\"0.8\", \"size\":\"587\", \"side\":\"BUY\", \"hash\":\"3a5e2dcbe08982ead866f93b581fa1514d893c56\", \"best_bid\":\"0.86\", \"best_ask\":\"0.87\"}, {\"asset_id\":\"114356653315647913247200886351065428002113119844334520181865067698979836634569\", \"price\":\"0.2\", \"size\":\"587\", \"side\":\"SELL\", \"hash\":\"292e7d36ecaf1d60bb218858c2d44c696c9bcc30\", \"best_bid\":\"0.13\", \"best_ask\":\"0.14\"}], \"timestamp\":\"1789987927783\", \"event_type\":\"price_change\"}","raw_base64":null}
{"received_ms":1789987927805,"monotonic_ns":1019368635628500,"raw":"{\"market\":\"0x28a45972fccdaf0fba75dacc59725521035e177d09dd92174f9f52740bccb025\", \"price_changes\":[{\"asset_id\":\"114356653315647913247200886351065428002113119844334520181865067698979836634569\", \"price\":\"0.13\", \"size\":\"305\", \"side\":\"BUY\", \"hash\":\"9655729f45f4fd710e92f913c7e6647cd9011d60\", \"best_bid\":\"0.13\", \"best_ask\":\"0.14\"}, {\"asset_id\":\"61819828071723399190623735325323968706432622380635304641786792960078828866875\", \"price\":\"0.87\", \"size\":\"305\", \"side\":\"SELL\", \"hash\":\"046601e182d5b85707b9bbbbc8ef14f65e63ccca\", \"best_bid\":\"0.86\", \"best_ask\":\"0.87\"}], \"timestamp\":\"1789987927784\", \"event_type\":\"price_change\"}","raw_base64":null}
{"received_ms":1789987927810,"monotonic_ns":1019368640497500,"raw":"{\"market\":\"0x28a45972fccdaf0fba75dacc59725521035e177d09dd92174f9f52740bccb025\", \"price_changes\":[{\"asset_id\":\"114356653315647913247200886351065428002113119844334520181865067698979836634569\", \"price\":\"0.01\", \"size\":\"1589.43\", \"side\":\"BUY\", \"hash\":\"be81cb2d403693dfa426cf2eb2b2461baf26f0bf\", \"best_bid\":\"0.13\", \"best_ask\":\"0.14\"}, {\"asset_id\":\"61819828071723399190623735325323968706432622380635304641786792960078828866875\", \"price\":\"0.99\", \"size\":\"1589.43\", \"side\":\"SELL\", \"hash\":\"1e3640e32a4c60f6130fbde6bcc94511d3aca547\", \"best_bid\":\"0.86\", \"best_ask\":\"0.87\"}], \"timestamp\":\"1789987927789\", \"event_type\":\"price_change\"}","raw_base64":null}
{"received_ms":1789987927817,"monotonic_ns":1019368647802300,"raw":"{\"market\":\"0x28a45972fccdaf0fba75dacc59725521035e177d09dd92174f9f52740bccb025\", \"price_changes\":[{\"asset_id\":\"114356653315647913247200886351065428002113119844334520181865067698979836634569\", \"price\":\"0.05\", \"size\":\"5603\", \"side\":\"BUY\", \"hash\":\"8f927610606a2ff116b554b56a637f0978105056\", \"best_bid\":\"0.13\", \"best_ask\":\"0.14\"}, {\"asset_id\":\"61819828071723399190623735325323968706432622380635304641786792960078828866875\", \"price\":\"0.95\", \"size\":\"5603\", \"side\":\"SELL\", \"hash\":\"eca64962bed260543f2c8d86bfc7fc9c661d1427\", \"best_bid\":\"0.86\", \"best_ask\":\"0.87\"}], \"timestamp\":\"1789987927797\", \"event_type\":\"price_change\"}","raw_base64":null}
{"received_ms":1789987927827,"monotonic_ns":1019368657783700,"raw":"{\"market\":\"0x28a45972fccdaf0fba75dacc59725521035e177d09dd92174f9f52740bccb025\", \"price_changes\":[{\"asset_id\":\"61819828071723399190623735325323968706432622380635304641786792960078828866875\", \"price\":\"0.84\", \"size\":\"2791\", \"side\":\"BUY\", \"hash\":\"9513a7d75202f44e0b92e3608787272c919db9d3\", \"best_bid\":\"0.86\", \"best_ask\":\"0.87\"}, {\"asset_id\":\"114356653315647913247200886351065428002113119844334520181865067698979836634569\", \"price\":\"0.16\", \"size\":\"2791\", \"side\":\"SELL\", \"hash\":\"7eea7744b44671a9aa62696742e8417acbd1278a\", \"best_bid\":\"0.13\", \"best_ask\":\"0.14\"}], \"timestamp\":\"1789987927805\", \"event_type\":\"price_change\"}","raw_base64":null}
{"received_ms":1789987927828,"monotonic_ns":1019368658739600,"raw":"{\"market\":\"0x28a45972fccdaf0fba75dacc59725521035e177d09dd92174f9f52740bccb025\", \"price_changes\":[{\"asset_id\":\"61819828071723399190623735325323968706432622380635304641786792960078828866875\", \"price\":\"0.85\", \"size\":\"795.52\", \"side\":\"BUY\", \"hash\":\"6e3e18cae87ce8e40136d10542f01a301ae3aa1c\", \"best_bid\":\"0.86\", \"best_ask\":\"0.87\"}, {\"asset_id\":\"114356653315647913247200886351065428002113119844334520181865067698979836634569\", \"price\":\"0.15\", \"size\":\"795.52\", \"side\":\"SELL\", \"hash\":\"4c72d8c6c13ccc1e6848a80373e73db01c34e6c0\", \"best_bid\":\"0.13\", \"best_ask\":\"0.14\"}], \"timestamp\":\"1789987927808\", \"event_type\":\"price_change\"}","raw_base64":null}
{"received_ms":1789987927833,"monotonic_ns":1019368663868000,"raw":"{\"market\":\"0x28a45972fccdaf0fba75dacc59725521035e177d09dd92174f9f52740bccb025\", \"price_changes\":[{\"asset_id\":\"61819828071723399190623735325323968706432622380635304641786792960078828866875\", \"price\":\"0.84\", \"size\":\"2823\", \"side\":\"BUY\", \"hash\":\"1448da3a16c9265f63bb91e137525ff75aadde67\", \"best_bid\":\"0.86\", \"best_ask\":\"0.87\"}, {\"asset_id\":\"114356653315647913247200886351065428002113119844334520181865067698979836634569\", \"price\":\"0.16\", \"size\":\"2823\", \"side\":\"SELL\", \"hash\":\"ac9eda3a2244fabbfff7a7642223303d734ddd24\", \"best_bid\":\"0.13\", \"best_ask\":\"0.14\"}], \"timestamp\":\"1789987927812\", \"event_type\":\"price_change\"}","raw_base64":null}
{"received_ms":1789987927833,"monotonic_ns":1019368664054700,"raw":"{\"market\":\"0x28a45972fccdaf0fba75dacc59725521035e177d09dd92174f9f52740bccb025\", \"price_changes\":[{\"asset_id\":\"61819828071723399190623735325323968706432622380635304641786792960078828866875\", \"price\":\"0.86\", \"size\":\"1912\", \"side\":\"BUY\", \"hash\":\"583f6b0682a1a08bf85873edac2b99fd160b9778\", \"best_bid\":\"0.86\", \"best_ask\":\"0.87\"}, {\"asset_id\":\"114356653315647913247200886351065428002113119844334520181865067698979836634569\", \"price\":\"0.14\", \"size\":\"1912\", \"side\":\"SELL\", \"hash\":\"3d75ff1b8b5c41172f02876dde8db917eda8592c\", \"best_bid\":\"0.13\", \"best_ask\":\"0.14\"}], \"timestamp\":\"1789987927813\", \"event_type\":\"price_change\"}","raw_base64":null}
{"received_ms":1789987927834,"monotonic_ns":1019368664664200,"raw":"{\"market\":\"0x28a45972fccdaf0fba75dacc59725521035e177d09dd92174f9f52740bccb025\", \"price_changes\":[{\"asset_id\":\"61819828071723399190623735325323968706432622380635304641786792960078828866875\", \"price\":\"0.85\", \"size\":\"2109.52\", \"side\":\"BUY\", \"hash\":\"3b7c1d06ef70e9c1acb0c31b49684c572a1f7d1b\", \"best_bid\":\"0.86\", \"best_ask\":\"0.87\"}, {\"asset_id\":\"114356653315647913247200886351065428002113119844334520181865067698979836634569\", \"price\":\"0.15\", \"size\":\"2109.52\", \"side\":\"SELL\", \"hash\":\"0ef669861527acbf4e60c4b49d4bad8c3ef1390e\", \"best_bid\":\"0.13\", \"best_ask\":\"0.14\"}], \"timestamp\":\"1789987927814\", \"event_type\":\"price_change\"}","raw_base64":null}
{"received_ms":1789987927835,"monotonic_ns":1019368666204400,"raw":"{\"market\":\"0x28a45972fccdaf0fba75dacc59725521035e177d09dd92174f9f52740bccb025\", \"price_changes\":[{\"asset_id\":\"114356653315647913247200886351065428002113119844334520181865067698979836634569\", \"price\":\"0.13\", \"size\":\"295\", \"side\":\"BUY\", \"hash\":\"c3bf384b7a2df93bd2a56a630d177e07df175a54\", \"best_bid\":\"0.13\", \"best_ask\":\"0.14\"}, {\"asset_id\":\"61819828071723399190623735325323968706432622380635304641786792960078828866875\", \"price\":\"0.87\", \"size\":\"295\", \"side\":\"SELL\", \"hash\":\"e825d45e4384c6b1beb7c52e87b405352a48efdc\", \"best_bid\":\"0.86\", \"best_ask\":\"0.87\"}], \"timestamp\":\"1789987927815\", \"event_type\":\"price_change\"}","raw_base64":null}
{"received_ms":1789987927835,"monotonic_ns":1019368666250600,"raw":"{\"market\":\"0x28a45972fccdaf0fba75dacc59725521035e177d09dd92174f9f52740bccb025\", \"price_changes\":[{\"asset_id\":\"114356653315647913247200886351065428002113119844334520181865067698979836634569\", \"price\":\"0.06\", \"size\":\"5961.67\", \"side\":\"BUY\", \"hash\":\"21aa4ebe65fe18fa300f4b5af25d698c58f2f247\", \"best_bid\":\"0.13\", \"best_ask\":\"0.14\"}, {\"asset_id\":\"61819828071723399190623735325323968706432622380635304641786792960078828866875\", \"price\":\"0.94\", \"size\":\"5961.67\", \"side\":\"SELL\", \"hash\":\"66b366b19c95ca8f2af9a0efa5188c59e6db6415\", \"best_bid\":\"0.86\", \"best_ask\":\"0.87\"}], \"timestamp\":\"1789987927815\", \"event_type\":\"price_change\"}","raw_base64":null}
{"received_ms":1789987927836,"monotonic_ns":1019368667082500,"raw":"{\"market\":\"0x28a45972fccdaf0fba75dacc59725521035e177d09dd92174f9f52740bccb025\", \"price_changes\":[{\"asset_id\":\"114356653315647913247200886351065428002113119844334520181865067698979836634569\", \"price\":\"0.1\", \"size\":\"580\", \"side\":\"BUY\", \"hash\":\"e15d462be5eece4839245c8f8577be45eb2ebafe\", \"best_bid\":\"0.13\", \"best_ask\":\"0.14\"}, {\"asset_id\":\"61819828071723399190623735325323968706432622380635304641786792960078828866875\", \"price\":\"0.9\", \"size\":\"580\", \"side\":\"SELL\", \"hash\":\"83e5ec43ee032c674a41991de339c993fe9b626a\", \"best_bid\":\"0.86\", \"best_ask\":\"0.87\"}], \"timestamp\":\"1789987927816\", \"event_type\":\"price_change\"}","raw_base64":null}
{"received_ms":1789987927837,"monotonic_ns":1019368667764200,"raw":"{\"market\":\"0x28a45972fccdaf0fba75dacc59725521035e177d09dd92174f9f52740bccb025\", \"price_changes\":[{\"asset_id\":\"114356653315647913247200886351065428002113119844334520181865067698979836634569\", \"price\":\"0.07\", \"size\":\"7109.71\", \"side\":\"BUY\", \"hash\":\"f69f4edcdf6a786dffca5d64938893591e961834\", \"best_bid\":\"0.13\", \"best_ask\":\"0.14\"}, {\"asset_id\":\"61819828071723399190623735325323968706432622380635304641786792960078828866875\", \"price\":\"0.93\", \"size\":\"7109.71\", \"side\":\"SELL\", \"hash\":\"16618317c48a6cc53058d295685f228a1269ce6a\", \"best_bid\":\"0.86\", \"best_ask\":\"0.87\"}], \"timestamp\":\"1789987927817\", \"event_type\":\"price_change\"}","raw_base64":null}
{"received_ms":1789987927839,"monotonic_ns":1019368669972200,"raw":"{\"market\":\"0x28a45972fccdaf0fba75dacc59725521035e177d09dd92174f9f52740bccb025\", \"price_changes\":[{\"asset_id\":\"61819828071723399190623735325323968706432622380635304641786792960078828866875\", \"price\":\"0.77\", \"size\":\"547.49\", \"side\":\"BUY\", \"hash\":\"ba928c94e4149356fabefaa24fb0c367157544e1\", \"best_bid\":\"0.86\", \"best_ask\":\"0.87\"}, {\"asset_id\":\"114356653315647913247200886351065428002113119844334520181865067698979836634569\", \"price\":\"0.23\", \"size\":\"547.49\", \"side\":\"SELL\", \"hash\":\"4af71232801218b9a5abc7fe177dcb51d664dd94\", \"best_bid\":\"0.13\", \"best_ask\":\"0.14\"}], \"timestamp\":\"1789987927819\", \"event_type\":\"price_change\"}","raw_base64":null}
{"received_ms":1789987927840,"monotonic_ns":1019368671046300,"raw":"{\"market\":\"0x28a45972fccdaf0fba75dacc59725521035e177d09dd92174f9f52740bccb025\", \"price_changes\":[{\"asset_id\":\"114356653315647913247200886351065428002113119844334520181865067698979836634569\", \"price\":\"0.07\", \"size\":\"7129.71\", \"side\":\"BUY\", \"hash\":\"7a399e97e814506a742a87b9a4962dd4e33b8460\", \"best_bid\":\"0.13\", \"best_ask\":\"0.14\"}, {\"asset_id\":\"61819828071723399190623735325323968706432622380635304641786792960078828866875\", \"price\":\"0.93\", \"size\":\"7129.71\", \"side\":\"SELL\", \"hash\":\"471f7021822e81b5af59548d811a120b62b62015\", \"best_bid\":\"0.86\", \"best_ask\":\"0.87\"}], \"timestamp\":\"1789987927819\", \"event_type\":\"price_change\"}","raw_base64":null}
{"received_ms":1789987927840,"monotonic_ns":1019368671234700,"raw":"{\"market\":\"0x28a45972fccdaf0fba75dacc59725521035e177d09dd92174f9f52740bccb025\", \"price_changes\":[{\"asset_id\":\"61819828071723399190623735325323968706432622380635304641786792960078828866875\", \"price\":\"0.75\", \"size\":\"530\", \"side\":\"BUY\", \"hash\":\"582da7416f8a06e639c047780bb3e452df1740d0\", \"best_bid\":\"0.86\", \"best_ask\":\"0.87\"}, {\"asset_id\":\"114356653315647913247200886351065428002113119844334520181865067698979836634569\", \"price\":\"0.25\", \"size\":\"530\", \"side\":\"SELL\", \"hash\":\"ac8fe4e049cffb07e03b162af1d1fdcacc0759e4\", \"best_bid\":\"0.13\", \"best_ask\":\"0.14\"}], \"timestamp\":\"1789987927820\", \"event_type\":\"price_change\"}","raw_base64":null}
{"received_ms":1789987927841,"monotonic_ns":1019368671279000,"raw":"{\"market\":\"0x28a45972fccdaf0fba75dacc59725521035e177d09dd92174f9f52740bccb025\", \"price_changes\":[{\"asset_id\":\"61819828071723399190623735325323968706432622380635304641786792960078828866875\", \"price\":\"0.85\", \"size\":\"2119.52\", \"side\":\"BUY\", \"hash\":\"f05dff37b3d2fb7999419d09664ec63fc6dc462b\", \"best_bid\":\"0.86\", \"best_ask\":\"0.87\"}, {\"asset_id\":\"114356653315647913247200886351065428002113119844334520181865067698979836634569\", \"price\":\"0.15\", \"size\":\"2119.52\", \"side\":\"SELL\", \"hash\":\"686dfad863674654529e1733d196140a7beac6ca\", \"best_bid\":\"0.13\", \"best_ask\":\"0.14\"}], \"timestamp\":\"1789987927820\", \"event_type\":\"price_change\"}","raw_base64":null}
{"received_ms":1789987927843,"monotonic_ns":1019368673337000,"raw":"{\"market\":\"0x28a45972fccdaf0fba75dacc59725521035e177d09dd92174f9f52740bccb025\", \"price_changes\":[{\"asset_id\":\"114356653315647913247200886351065428002113119844334520181865067698979836634569\", \"price\":\"0.12\", \"size\":\"504.34\", \"side\":\"BUY\", \"hash\":\"3332a6f856fd14de8a58d0d6e48daa3b7d7ea997\", \"best_bid\":\"0.13\", \"best_ask\":\"0.14\"}, {\"asset_id\":\"61819828071723399190623735325323968706432622380635304641786792960078828866875\", \"price\":\"0.88\", \"size\":\"504.34\", \"side\":\"SELL\", \"hash\":\"d2b2bba546cc35c627cda585169c770622918729\", \"best_bid\":\"0.86\", \"best_ask\":\"0.87\"}], \"timestamp\":\"1789987927822\", \"event_type\":\"price_change\"}","raw_base64":null}
{"received_ms":1789987927851,"monotonic_ns":1019368682110800,"raw":"{\"market\":\"0x28a45972fccdaf0fba75dacc59725521035e177d09dd92174f9f52740bccb025\", \"price_changes\":[{\"asset_id\":\"114356653315647913247200886351065428002113119844334520181865067698979836634569\", \"price\":\"0.01\", \"size\":\"1609.43\", \"side\":\"BUY\", \"hash\":\"00dd094a8e9bef9adfee869f8ab061869bec1f7b\", \"best_bid\":\"0.13\", \"best_ask\":\"0.14\"}, {\"asset_id\":\"61819828071723399190623735325323968706432622380635304641786792960078828866875\", \"price\":\"0.99\", \"size\":\"1609.43\", \"side\":\"SELL\", \"hash\":\"1fa68f7c2593c6fdd8267cb5f2b0b1bb6c3b6223\", \"best_bid\":\"0.86\", \"best_ask\":\"0.87\"}], \"timestamp\":\"1789987927830\", \"event_type\":\"price_change\"}","raw_base64":null}
{"received_ms":1789987927855,"monotonic_ns":1019368685824300,"raw":"{\"market\":\"0x28a45972fccdaf0fba75dacc59725521035e177d09dd92174f9f52740bccb025\", \"price_changes\":[{\"asset_id\":\"114356653315647913247200886351065428002113119844334520181865067698979836634569\", \"price\":\"0.01\", \"size\":\"1689.43\", \"side\":\"BUY\", \"hash\":\"5dee6d695b06bf6bb5a013127fee35153d13ce9f\", \"best_bid\":\"0.13\", \"best_ask\":\"0.14\"}, {\"asset_id\":\"61819828071723399190623735325323968706432622380635304641786792960078828866875\", \"price\":\"0.99\", \"size\":\"1689.43\", \"side\":\"SELL\", \"hash\":\"4b76b14beffacab3dfb320ef0305be5ca77df7c0\", \"best_bid\":\"0.86\", \"best_ask\":\"0.87\"}], \"timestamp\":\"1789987927834\", \"event_type\":\"price_change\"}","raw_base64":null}
{"received_ms":1789987927864,"monotonic_ns":1019368695235900,"raw":"{\"market\":\"0x28a45972fccdaf0fba75dacc59725521035e177d09dd92174f9f52740bccb025\", \"price_changes\":[{\"asset_id\":\"114356653315647913247200886351065428002113119844334520181865067698979836634569\", \"price\":\"0.05\", \"size\":\"5583\", \"side\":\"BUY\", \"hash\":\"e378b07642e9c43e43a35efb04c53d35ec8073e2\", \"best_bid\":\"0.13\", \"best_ask\":\"0.14\"}, {\"asset_id\":\"61819828071723399190623735325323968706432622380635304641786792960078828866875\", \"price\":\"0.95\", \"size\":\"5583\", \"side\":\"SELL\", \"hash\":\"8379b1a001e33c600607b5b47a9ce863edd6c354\", \"best_bid\":\"0.86\", \"best_ask\":\"0.87\"}], \"timestamp\":\"1789987927843\", \"event_type\":\"price_change\"}","raw_base64":null}
{"received_ms":1789987927865,"monotonic_ns":1019368695290500,"raw":"{\"market\":\"0x28a45972fccdaf0fba75dacc59725521035e177d09dd92174f9f52740bccb025\", \"price_changes\":[{\"asset_id\":\"114356653315647913247200886351065428002113119844334520181865067698979836634569\", \"price\":\"0.1\", \"size\":\"520\", \"side\":\"BUY\", \"hash\":\"e378b07642e9c43e43a35efb04c53d35ec8073e2\", \"best_bid\":\"0.13\", \"best_ask\":\"0.14\"}, {\"asset_id\":\"61819828071723399190623735325323968706432622380635304641786792960078828866875\", \"price\":\"0.9\", \"size\":\"520\", \"side\":\"SELL\", \"hash\":\"8379b1a001e33c600607b5b47a9ce863edd6c354\", \"best_bid\":\"0.86\", \"best_ask\":\"0.87\"}], \"timestamp\":\"1789987927843\", \"event_type\":\"price_change\"}","raw_base64":null}
{"received_ms":1789987927866,"monotonic_ns":1019368697072600,"raw":"{\"market\":\"0x28a45972fccdaf0fba75dacc59725521035e177d09dd92174f9f52740bccb025\", \"price_changes\":[{\"asset_id\":\"61819828071723399190623735325323968706432622380635304641786792960078828866875\", \"price\":\"0.85\", \"size\":\"2187.52\", \"side\":\"BUY\", \"hash\":\"9e227c5da68686ff99fd3b93fecb8a083eb550b5\", \"best_bid\":\"0.86\", \"best_ask\":\"0.87\"}, {\"asset_id\":\"114356653315647913247200886351065428002113119844334520181865067698979836634569\", \"price\":\"0.15\", \"size\":\"2187.52\", \"side\":\"SELL\", \"hash\":\"39bac8a1d1406d979d2a531c17ec784b1f563f19\", \"best_bid\":\"0.13\", \"best_ask\":\"0.14\"}], \"timestamp\":\"1789987927846\", \"event_type\":\"price_change\"}","raw_base64":null}
{"received_ms":1789987927869,"monotonic_ns":1019368699946900,"raw":"{\"market\":\"0x28a45972fccdaf0fba75dacc59725521035e177d09dd92174f9f52740bccb025\", \"price_changes\":[{\"asset_id\":\"114356653315647913247200886351065428002113119844334520181865067698979836634569\", \"price\":\"0.07\", \"size\":\"7136.71\", \"side\":\"BUY\", \"hash\":\"816204a868a7595ffb0a9317ff3e638fd2a191b1\", \"best_bid\":\"0.13\", \"best_ask\":\"0.14\"}, {\"asset_id\":\"61819828071723399190623735325323968706432622380635304641786792960078828866875\", \"price\":\"0.93\", \"size\":\"7136.71\", \"side\":\"SELL\", \"hash\":\"21ec590a2d980e135c6d0a6728c736d94b276757\", \"best_bid\":\"0.86\", \"best_ask\":\"0.87\"}], \"timestamp\":\"1789987927849\", \"event_type\":\"price_change\"}","raw_base64":null}
{"received_ms":1789987927870,"monotonic_ns":1019368700668900,"raw":"{\"market\":\"0x28a45972fccdaf0fba75dacc59725521035e177d09dd92174f9f52740bccb025\", \"price_changes\":[{\"asset_id\":\"61819828071723399190623735325323968706432622380635304641786792960078828866875\", \"price\":\"0.86\", \"size\":\"1962\", \"side\":\"BUY\", \"hash\":\"b1697f55be01b4cab94a44da88030161b9511eae\", \"best_bid\":\"0.86\", \"best_ask\":\"0.87\"}, {\"asset_id\":\"114356653315647913247200886351065428002113119844334520181865067698979836634569\", \"price\":\"0.14\", \"size\":\"1962\", \"side\":\"SELL\", \"hash\":\"6bc22b2105a16ea34d24550dff2b19f2de7a3c90\", \"best_bid\":\"0.13\", \"best_ask\":\"0.14\"}], \"timestamp\":\"1789987927850\", \"event_type\":\"price_change\"}","raw_base64":null}
{"received_ms":1789987927871,"monotonic_ns":1019368702064400,"raw":"{\"market\":\"0x28a45972fccdaf0fba75dacc59725521035e177d09dd92174f9f52740bccb025\", \"price_changes\":[{\"asset_id\":\"114356653315647913247200886351065428002113119844334520181865067698979836634569\", \"price\":\"0.13\", \"size\":\"305\", \"side\":\"BUY\", \"hash\":\"cefdd036a2159b62341944328b4418ecfa430cea\", \"best_bid\":\"0.13\", \"best_ask\":\"0.14\"}, {\"asset_id\":\"61819828071723399190623735325323968706432622380635304641786792960078828866875\", \"price\":\"0.87\", \"size\":\"305\", \"side\":\"SELL\", \"hash\":\"da287ade79f255136d857867efcc2a48059928b5\", \"best_bid\":\"0.86\", \"best_ask\":\"0.87\"}], \"timestamp\":\"1789987927851\", \"event_type\":\"price_change\"}","raw_base64":null}
{"received_ms":1789987927872,"monotonic_ns":1019368702735000,"raw":"{\"market\":\"0x28a45972fccdaf0fba75dacc59725521035e177d09dd92174f9f52740bccb025\", \"price_changes\":[{\"asset_id\":\"61819828071723399190623735325323968706432622380635304641786792960078828866875\", \"price\":\"0.84\", \"size\":\"2855\", \"side\":\"BUY\", \"hash\":\"0930f70712d2a8be07ebe16c20773151e4452144\", \"best_bid\":\"0.86\", \"best_ask\":\"0.87\"}, {\"asset_id\":\"114356653315647913247200886351065428002113119844334520181865067698979836634569\", \"price\":\"0.16\", \"size\":\"2855\", \"side\":\"SELL\", \"hash\":\"912cbe0b6abad2bc53cb9dd5326fac45329e6214\", \"best_bid\":\"0.13\", \"best_ask\":\"0.14\"}], \"timestamp\":\"1789987927852\", \"event_type\":\"price_change\"}","raw_base64":null}
{"received_ms":1789987927879,"monotonic_ns":1019368710190000,"raw":"{\"market\":\"0x28a45972fccdaf0fba75dacc59725521035e177d09dd92174f9f52740bccb025\", \"price_changes\":[{\"asset_id\":\"61819828071723399190623735325323968706432622380635304641786792960078828866875\", \"price\":\"0.84\", \"size\":\"2823\", \"side\":\"BUY\", \"hash\":\"bbf5164d4c92d25c92e69f60ce11ef78c952029f\", \"best_bid\":\"0.86\", \"best_ask\":\"0.87\"}, {\"asset_id\":\"114356653315647913247200886351065428002113119844334520181865067698979836634569\", \"price\":\"0.16\", \"size\":\"2823\", \"side\":\"SELL\", \"hash\":\"18ed9ef9168881c1eb498c01b8427529f02c3687\", \"best_bid\":\"0.13\", \"best_ask\":\"0.14\"}], \"timestamp\":\"1789987927859\", \"event_type\":\"price_change\"}","raw_base64":null}
{"received_ms":1789987927882,"monotonic_ns":1019368712511800,"raw":"{\"market\":\"0x28a45972fccdaf0fba75dacc59725521035e177d09dd92174f9f52740bccb025\", \"price_changes\":[{\"asset_id\":\"61819828071723399190623735325323968706432622380635304641786792960078828866875\", \"price\":\"0.84\", \"size\":\"2335\", \"side\":\"BUY\", \"hash\":\"a39af5b213dfe5ae97a2ffa7779a2912a691a55b\", \"best_bid\":\"0.86\", \"best_ask\":\"0.87\"}, {\"asset_id\":\"114356653315647913247200886351065428002113119844334520181865067698979836634569\", \"price\":\"0.16\", \"size\":\"2335\", \"side\":\"SELL\", \"hash\":\"d2361df54d68ec30c6f694d225ddc045b3e27ecd\", \"best_bid\":\"0.13\", \"best_ask\":\"0.14\"}], \"timestamp\":\"1789987927862\", \"event_type\":\"price_change\"}","raw_base64":null}
{"received_ms":1789987927893,"monotonic_ns":1019368723398000,"raw":"{\"market\":\"0x28a45972fccdaf0fba75dacc59725521035e177d09dd92174f9f52740bccb025\", \"price_changes\":[{\"asset_id\":\"114356653315647913247200886351065428002113119844334520181865067698979836634569\", \"price\":\"0.11\", \"size\":\"336.1\", \"side\":\"BUY\", \"hash\":\"c3d41e742856d1227c4bab379ec37bd28c0ea049\", \"best_bid\":\"0.13\", \"best_ask\":\"0.14\"}, {\"asset_id\":\"61819828071723399190623735325323968706432622380635304641786792960078828866875\", \"price\":\"0.89\", \"size\":\"336.1\", \"side\":\"SELL\", \"hash\":\"40f9ab08ab39356a8a212d7ddc7ca63bf371732b\", \"best_bid\":\"0.86\", \"best_ask\":\"0.87\"}], \"timestamp\":\"1789987927872\", \"event_type\":\"price_change\"}","raw_base64":null}
{"received_ms":1789987927906,"monotonic_ns":1019368736609000,"raw":"{\"market\":\"0x28a45972fccdaf0fba75dacc59725521035e177d09dd92174f9f52740bccb025\", \"price_changes\":[{\"asset_id\":\"61819828071723399190623735325323968706432622380635304641786792960078828866875\", \"price\":\"0.73\", \"size\":\"504\", \"side\":\"BUY\", \"hash\":\"257e3d6161cd308587db3baa2d6297a4a89c4d2b\", \"best_bid\":\"0.86\", \"best_ask\":\"0.87\"}, {\"asset_id\":\"114356653315647913247200886351065428002113119844334520181865067698979836634569\", \"price\":\"0.27\", \"size\":\"504\", \"side\":\"SELL\", \"hash\":\"ef87744f408272cbcdf7d168bd5a4ee7c7af669d\", \"best_bid\":\"0.13\", \"best_ask\":\"0.14\"}], \"timestamp\":\"1789987927886\", \"event_type\":\"price_change\"}","raw_base64":null}
{"received_ms":1789987927906,"monotonic_ns":1019368737157800,"raw":"{\"market\":\"0x28a45972fccdaf0fba75dacc59725521035e177d09dd92174f9f52740bccb025\", \"price_changes\":[{\"asset_id\":\"114356653315647913247200886351065428002113119844334520181865067698979836634569\", \"price\":\"0.13\", \"size\":\"280\", \"side\":\"BUY\", \"hash\":\"bb5d42cbcd9e60e94bcbb44142983be1e2e5e3ea\", \"best_bid\":\"0.13\", \"best_ask\":\"0.14\"}, {\"asset_id\":\"61819828071723399190623735325323968706432622380635304641786792960078828866875\", \"price\":\"0.87\", \"size\":\"280\", \"side\":\"SELL\", \"hash\":\"242428ae2f9c0560fd9651d9e5c5948bec674fab\", \"best_bid\":\"0.86\", \"best_ask\":\"0.87\"}], \"timestamp\":\"1789987927886\", \"event_type\":\"price_change\"}","raw_base64":null}
{"received_ms":1789987927908,"monotonic_ns":1019368738944000,"raw":"{\"market\":\"0x28a45972fccdaf0fba75dacc59725521035e177d09dd92174f9f52740bccb025\", \"price_changes\":[{\"asset_id\":\"61819828071723399190623735325323968706432622380635304641786792960078828866875\", \"price\":\"0.8\", \"size\":\"562\", \"side\":\"BUY\", \"hash\":\"2e0f6ebb0caa642c84d3a9a7c9ca90578519b98b\", \"best_bid\":\"0.86\", \"best_ask\":\"0.87\"}, {\"asset_id\":\"114356653315647913247200886351065428002113119844334520181865067698979836634569\", \"price\":\"0.2\", \"size\":\"562\", \"side\":\"SELL\", \"hash\":\"abe8167cf9846aa8047c7991315ce65960056f5a\", \"best_bid\":\"0.13\", \"best_ask\":\"0.14\"}], \"timestamp\":\"1789987927888\", \"event_type\":\"price_change\"}","raw_base64":null}
{"received_ms":1789987927909,"monotonic_ns":1019368739400000,"raw":"{\"market\":\"0x28a45972fccdaf0fba75dacc59725521035e177d09dd92174f9f52740bccb025\", \"price_changes\":[{\"asset_id\":\"61819828071723399190623735325323968706432622380635304641786792960078828866875\", \"price\":\"0.84\", \"size\":\"2367\", \"side\":\"BUY\", \"hash\":\"00aa8436a306b8c938695a1f27536f8497ed0d8c\", \"best_bid\":\"0.86\", \"best_ask\":\"0.87\"}, {\"asset_id\":\"114356653315647913247200886351065428002113119844334520181865067698979836634569\", \"price\":\"0.16\", \"size\":\"2367\", \"side\":\"SELL\", \"hash\":\"7ddc15f9b983ff4e369d60b3a12584c9b29880a7\", \"best_bid\":\"0.13\", \"best_ask\":\"0.14\"}], \"timestamp\":\"1789987927888\", \"event_type\":\"price_change\"}","raw_base64":null}
{"received_ms":1789987927911,"monotonic_ns":1019368741982800,"raw":"{\"market\":\"0x28a45972fccdaf0fba75dacc59725521035e177d09dd92174f9f52740bccb025\", \"price_changes\":[{\"asset_id\":\"61819828071723399190623735325323968706432622380635304641786792960078828866875\", \"price\":\"0.73\", \"size\":\"404\", \"side\":\"BUY\", \"hash\":\"029e82551520fc44791e6234392c2c0e1a7b292e\", \"best_bid\":\"0.86\", \"best_ask\":\"0.87\"}, {\"asset_id\":\"114356653315647913247200886351065428002113119844334520181865067698979836634569\", \"price\":\"0.27\", \"size\":\"404\", \"side\":\"SELL\", \"hash\":\"557ef46d0083c86cdad25fb8048e64b299f6fac1\", \"best_bid\":\"0.13\", \"best_ask\":\"0.14\"}], \"timestamp\":\"1789987927891\", \"event_type\":\"price_change\"}","raw_base64":null}
{"received_ms":1789987927914,"monotonic_ns":1019368744703200,"raw":"{\"market\":\"0x28a45972fccdaf0fba75dacc59725521035e177d09dd92174f9f52740bccb025\", \"price_changes\":[{\"asset_id\":\"61819828071723399190623735325323968706432622380635304641786792960078828866875\", \"price\":\"0.86\", \"size\":\"1726\", \"side\":\"BUY\", \"hash\":\"4b0b6584e43ace580a2636e75625366a71f467e0\", \"best_bid\":\"0.86\", \"best_ask\":\"0.87\"}, {\"asset_id\":\"114356653315647913247200886351065428002113119844334520181865067698979836634569\", \"price\":\"0.14\", \"size\":\"1726\", \"side\":\"SELL\", \"hash\":\"539f06b9843e26ede1edc872ad62aa0dc2bc86e8\", \"best_bid\":\"0.13\", \"best_ask\":\"0.14\"}], \"timestamp\":\"1789987927893\", \"event_type\":\"price_change\"}","raw_base64":null}
{"received_ms":1789987927914,"monotonic_ns":1019368744886900,"raw":"{\"market\":\"0x28a45972fccdaf0fba75dacc59725521035e177d09dd92174f9f52740bccb025\", \"price_changes\":[{\"asset_id\":\"114356653315647913247200886351065428002113119844334520181865067698979836634569\", \"price\":\"0.07\", \"size\":\"7116.71\", \"side\":\"BUY\", \"hash\":\"035eae0ede649fa2d957f9c903ff28fa9a410d96\", \"best_bid\":\"0.13\", \"best_ask\":\"0.14\"}, {\"asset_id\":\"61819828071723399190623735325323968706432622380635304641786792960078828866875\", \"price\":\"0.93\", \"size\":\"7116.71\", \"side\":\"SELL\", \"hash\":\"9ed85f90daba0b11ae8e8e1cc7cf757d0c37f837\", \"best_bid\":\"0.86\", \"best_ask\":\"0.87\"}], \"timestamp\":\"1789987927894\", \"event_type\":\"price_change\"}","raw_base64":null}
{"received_ms":1789987927917,"monotonic_ns":1019368747657600,"raw":"{\"market\":\"0x28a45972fccdaf0fba75dacc59725521035e177d09dd92174f9f52740bccb025\", \"price_changes\":[{\"asset_id\":\"61819828071723399190623735325323968706432622380635304641786792960078828866875\", \"price\":\"0.85\", \"size\":\"2152.35\", \"side\":\"BUY\", \"hash\":\"6681cf958237106b43587ebb7917e1fb8314d119\", \"best_bid\":\"0.86\", \"best_ask\":\"0.87\"}, {\"asset_id\":\"114356653315647913247200886351065428002113119844334520181865067698979836634569\", \"price\":\"0.15\", \"size\":\"2152.35\", \"side\":\"SELL\", \"hash\":\"8c08660bcd1db2f8f828d23410039cb2b6b173c4\", \"best_bid\":\"0.13\", \"best_ask\":\"0.14\"}], \"timestamp\":\"1789987927897\", \"event_type\":\"price_change\"}","raw_base64":null}
{"received_ms":1789987927918,"monotonic_ns":1019368749060100,"raw":"{\"market\":\"0x28a45972fccdaf0fba75dacc59725521035e177d09dd92174f9f52740bccb025\", \"price_changes\":[{\"asset_id\":\"61819828071723399190623735325323968706432622380635304641786792960078828866875\", \"price\":\"0.85\", \"size\":\"2172.35\", \"side\":\"BUY\", \"hash\":\"aa6d19b6ca20921544246c95396880291cbb124d\", \"best_bid\":\"0.86\", \"best_ask\":\"0.87\"}, {\"asset_id\":\"114356653315647913247200886351065428002113119844334520181865067698979836634569\", \"price\":\"0.15\", \"size\":\"2172.35\", \"side\":\"SELL\", \"hash\":\"774050204fc9f9f9c8734be5299dbf415420f720\", \"best_bid\":\"0.13\", \"best_ask\":\"0.14\"}], \"timestamp\":\"1789987927898\", \"event_type\":\"price_change\"}","raw_base64":null}
{"received_ms":1789987927922,"monotonic_ns":1019368752808100,"raw":"{\"market\":\"0x28a45972fccdaf0fba75dacc59725521035e177d09dd92174f9f52740bccb025\", \"price_changes\":[{\"asset_id\":\"114356653315647913247200886351065428002113119844334520181865067698979836634569\", \"price\":\"0.11\", \"size\":\"316.1\", \"side\":\"BUY\", \"hash\":\"b1616edcbd6d77e0f9eacdfd75da497287703f16\", \"best_bid\":\"0.13\", \"best_ask\":\"0.14\"}, {\"asset_id\":\"61819828071723399190623735325323968706432622380635304641786792960078828866875\", \"price\":\"0.89\", \"size\":\"316.1\", \"side\":\"SELL\", \"hash\":\"6e7e628f4b3167197e8eac5801eb85809553c2fb\", \"best_bid\":\"0.86\", \"best_ask\":\"0.87\"}], \"timestamp\":\"1789987927901\", \"event_type\":\"price_change\"}","raw_base64":null}
{"received_ms":1789987927928,"monotonic_ns":1019368759043400,"raw":"{\"market\":\"0x28a45972fccdaf0fba75dacc59725521035e177d09dd92174f9f52740bccb025\", \"price_changes\":[{\"asset_id\":\"114356653315647913247200886351065428002113119844334520181865067698979836634569\", \"price\":\"0.06\", \"size\":\"5080.67\", \"side\":\"BUY\", \"hash\":\"669683e2fd95be234d0dbaaa44d5ef19727e01a1\", \"best_bid\":\"0.13\", \"best_ask\":\"0.14\"}, {\"asset_id\":\"61819828071723399190623735325323968706432622380635304641786792960078828866875\", \"price\":\"0.94\", \"size\":\"5080.67\", \"side\":\"SELL\", \"hash\":\"9f038542f0118d3745e233c1ab1985768addfb36\", \"best_bid\":\"0.86\", \"best_ask\":\"0.87\"}], \"timestamp\":\"1789987927908\", \"event_type\":\"price_change\"}","raw_base64":null}
{"received_ms":1789987927934,"monotonic_ns":1019368764398400,"raw":"{\"market\":\"0x28a45972fccdaf0fba75dacc59725521035e177d09dd92174f9f52740bccb025\", \"price_changes\":[{\"asset_id\":\"114356653315647913247200886351065428002113119844334520181865067698979836634569\", \"price\":\"0.1\", \"size\":\"580\", \"side\":\"BUY\", \"hash\":\"3d784808dd1bf76d6ccd580d47d1ae3ad6b2ee9d\", \"best_bid\":\"0.13\", \"best_ask\":\"0.14\"}, {\"asset_id\":\"61819828071723399190623735325323968706432622380635304641786792960078828866875\", \"price\":\"0.9\", \"size\":\"580\", \"side\":\"SELL\", \"hash\":\"fa05670320d13146c272df378fddae8b73c6eb57\", \"best_bid\":\"0.86\", \"best_ask\":\"0.87\"}], \"timestamp\":\"1789987927913\", \"event_type\":\"price_change\"}","raw_base64":null}
{"received_ms":1789987927935,"monotonic_ns":1019368765367400,"raw":"{\"market\":\"0x28a45972fccdaf0fba75dacc59725521035e177d09dd92174f9f52740bccb025\", \"price_changes\":[{\"asset_id\":\"114356653315647913247200886351065428002113119844334520181865067698979836634569\", \"price\":\"0.07\", \"size\":\"7141.71\", \"side\":\"BUY\", \"hash\":\"5dff6e225a74f8771117e98b1ee77b9e222c89e0\", \"best_bid\":\"0.13\", \"best_ask\":\"0.14\"}, {\"asset_id\":\"61819828071723399190623735325323968706432622380635304641786792960078828866875\", \"price\":\"0.93\", \"size\":\"7141.71\", \"side\":\"SELL\", \"hash\":\"608645d3a7117b5eaff05259a77f73d1935ea5db\", \"best_bid\":\"0.86\", \"best_ask\":\"0.87\"}], \"timestamp\":\"1789987927915\", \"event_type\":\"price_change\"}","raw_base64":null}
{"received_ms":1789987927935,"monotonic_ns":1019368765775600,"raw":"{\"market\":\"0x28a45972fccdaf0fba75dacc59725521035e177d09dd92174f9f52740bccb025\", \"price_changes\":[{\"asset_id\":\"61819828071723399190623735325323968706432622380635304641786792960078828866875\", \"price\":\"0.86\", \"size\":\"1751\", \"side\":\"BUY\", \"hash\":\"fb896b99076d23e1f4db9bb2a914899a934706a5\", \"best_bid\":\"0.86\", \"best_ask\":\"0.87\"}, {\"asset_id\":\"114356653315647913247200886351065428002113119844334520181865067698979836634569\", \"price\":\"0.14\", \"size\":\"1751\", \"side\":\"SELL\", \"hash\":\"9b07a676269797eba934eb3fa1bf48cdb4238df6\", \"best_bid\":\"0.13\", \"best_ask\":\"0.14\"}], \"timestamp\":\"1789987927915\", \"event_type\":\"price_change\"}","raw_base64":null}
{"received_ms":1789987927946,"monotonic_ns":1019368776639300,"raw":"{\"market\":\"0x28a45972fccdaf0fba75dacc59725521035e177d09dd92174f9f52740bccb025\", \"price_changes\":[{\"asset_id\":\"61819828071723399190623735325323968706432622380635304641786792960078828866875\", \"price\":\"0.86\", \"size\":\"1931\", \"side\":\"BUY\", \"hash\":\"d1bb572b2c38a3e6e3b0e6139aecf705315dd4a6\", \"best_bid\":\"0.86\", \"best_ask\":\"0.87\"}, {\"asset_id\":\"114356653315647913247200886351065428002113119844334520181865067698979836634569\", \"price\":\"0.14\", \"size\":\"1931\", \"side\":\"SELL\", \"hash\":\"6dca272133cb2f11a89a100b842ca2d4f2e8b8c3\", \"best_bid\":\"0.13\", \"best_ask\":\"0.14\"}], \"timestamp\":\"1789987927918\", \"event_type\":\"price_change\"}","raw_base64":null}
{"received_ms":1789987927946,"monotonic_ns":1019368776700600,"raw":"{\"market\":\"0x28a45972fccdaf0fba75dacc59725521035e177d09dd92174f9f52740bccb025\", \"price_changes\":[{\"asset_id\":\"61819828071723399190623735325323968706432622380635304641786792960078828866875\", \"price\":\"0.84\", \"size\":\"2855\", \"side\":\"BUY\", \"hash\":\"9a1c501a7d1ea1630b6cc9d5b1d24b0b14ec7ab1\", \"best_bid\":\"0.86\", \"best_ask\":\"0.87\"}, {\"asset_id\":\"114356653315647913247200886351065428002113119844334520181865067698979836634569\", \"price\":\"0.16\", \"size\":\"2855\", \"side\":\"SELL\", \"hash\":\"fd11793f2694c6a2713b6d11ab6fb9d9990a4c8b\", \"best_bid\":\"0.13\", \"best_ask\":\"0.14\"}], \"timestamp\":\"1789987927920\", \"event_type\":\"price_change\"}","raw_base64":null}
{"received_ms":1789987927946,"monotonic_ns":1019368776760400,"raw":"{\"market\":\"0x28a45972fccdaf0fba75dacc59725521035e177d09dd92174f9f52740bccb025\", \"price_changes\":[{\"asset_id\":\"114356653315647913247200886351065428002113119844334520181865067698979836634569\", \"price\":\"0.07\", \"size\":\"7161.71\", \"side\":\"BUY\", \"hash\":\"cdc3534ea82bd4404a0bb7324d1e4ea64c2fb2dc\", \"best_bid\":\"0.13\", \"best_ask\":\"0.14\"}, {\"asset_id\":\"61819828071723399190623735325323968706432622380635304641786792960078828866875\", \"price\":\"0.93\", \"size\":\"7161.71\", \"side\":\"SELL\", \"hash\":\"2f89d19061a889507a504d2602494aa910f390ef\", \"best_bid\":\"0.86\", \"best_ask\":\"0.87\"}], \"timestamp\":\"1789987927925\", \"event_type\":\"price_change\"}","raw_base64":null}
{"received_ms":1789987927953,"monotonic_ns":1019368783901200,"raw":"{\"market\":\"0x28a45972fccdaf0fba75dacc59725521035e177d09dd92174f9f52740bccb025\", \"price_changes\":[{\"asset_id\":\"61819828071723399190623735325323968706432622380635304641786792960078828866875\", \"price\":\"0.85\", \"size\":\"2187.52\", \"side\":\"BUY\", \"hash\":\"f17d5b21b1cdb598c5945250c0317660f2d065e2\", \"best_bid\":\"0.86\", \"best_ask\":\"0.87\"}, {\"asset_id\":\"114356653315647913247200886351065428002113119844334520181865067698979836634569\", \"price\":\"0.15\", \"size\":\"2187.52\", \"side\":\"SELL\", \"hash\":\"373056c6a033885aac25919aac0ec1548c86d969\", \"best_bid\":\"0.13\", \"best_ask\":\"0.14\"}], \"timestamp\":\"1789987927927\", \"event_type\":\"price_change\"}","raw_base64":null}
{"received_ms":1789987927953,"monotonic_ns":1019368783958400,"raw":"{\"market\":\"0x28a45972fccdaf0fba75dacc59725521035e177d09dd92174f9f52740bccb025\", \"price_changes\":[{\"asset_id\":\"114356653315647913247200886351065428002113119844334520181865067698979836634569\", \"price\":\"0.05\", \"size\":\"5603\", \"side\":\"BUY\", \"hash\":\"fcc15ad3a86dafc785b679f8d12217d3b16d7b01\", \"best_bid\":\"0.13\", \"best_ask\":\"0.14\"}, {\"asset_id\":\"61819828071723399190623735325323968706432622380635304641786792960078828866875\", \"price\":\"0.95\", \"size\":\"5603\", \"side\":\"SELL\", \"hash\":\"af49479b058c9d5eb53a1cedf36ba844e14efc7d\", \"best_bid\":\"0.86\", \"best_ask\":\"0.87\"}], \"timestamp\":\"1789987927928\", \"event_type\":\"price_change\"}","raw_base64":null}
{"received_ms":1789987927953,"monotonic_ns":1019368784003800,"raw":"{\"market\":\"0x28a45972fccdaf0fba75dacc59725521035e177d09dd92174f9f52740bccb025\", \"price_changes\":[{\"asset_id\":\"114356653315647913247200886351065428002113119844334520181865067698979836634569\", \"price\":\"0.07\", \"size\":\"7154.71\", \"side\":\"BUY\", \"hash\":\"f0df87663e4d08bf8e0f4c6c18f383bd9e4394ec\", \"best_bid\":\"0.13\", \"best_ask\":\"0.14\"}, {\"asset_id\":\"61819828071723399190623735325323968706432622380635304641786792960078828866875\", \"price\":\"0.93\", \"size\":\"7154.71\", \"side\":\"SELL\", \"hash\":\"3b309337eca6b5ba067776777d3869bb2ee7d508\", \"best_bid\":\"0.86\", \"best_ask\":\"0.87\"}], \"timestamp\":\"1789987927929\", \"event_type\":\"price_change\"}","raw_base64":null}
{"received_ms":1789987927953,"monotonic_ns":1019368784048000,"raw":"{\"market\":\"0x28a45972fccdaf0fba75dacc59725521035e177d09dd92174f9f52740bccb025\", \"price_changes\":[{\"asset_id\":\"114356653315647913247200886351065428002113119844334520181865067698979836634569\", \"price\":\"0.07\", \"size\":\"6904.71\", \"side\":\"BUY\", \"hash\":\"1a998aa105351e2930491ecd89b745098ad16efd\", \"best_bid\":\"0.13\", \"best_ask\":\"0.14\"}, {\"asset_id\":\"61819828071723399190623735325323968706432622380635304641786792960078828866875\", \"price\":\"0.93\", \"size\":\"6904.71\", \"side\":\"SELL\", \"hash\":\"7b1d30afa9dca93efd63c3d82ceff109906cf4b9\", \"best_bid\":\"0.86\", \"best_ask\":\"0.87\"}], \"timestamp\":\"1789987927930\", \"event_type\":\"price_change\"}","raw_base64":null}
{"received_ms":1789987927953,"monotonic_ns":1019368784090600,"raw":"{\"market\":\"0x28a45972fccdaf0fba75dacc59725521035e177d09dd92174f9f52740bccb025\", \"price_changes\":[{\"asset_id\":\"114356653315647913247200886351065428002113119844334520181865067698979836634569\", \"price\":\"0.07\", \"size\":\"6884.71\", \"side\":\"BUY\", \"hash\":\"b9cac845b9d6b1df4b8af5fd243f282d0a216db6\", \"best_bid\":\"0.13\", \"best_ask\":\"0.14\"}, {\"asset_id\":\"61819828071723399190623735325323968706432622380635304641786792960078828866875\", \"price\":\"0.93\", \"size\":\"6884.71\", \"side\":\"SELL\", \"hash\":\"1940766591185ea20d06446aad6fc92cff562683\", \"best_bid\":\"0.86\", \"best_ask\":\"0.87\"}], \"timestamp\":\"1789987927930\", \"event_type\":\"price_change\"}","raw_base64":null}
{"received_ms":1789987927953,"monotonic_ns":1019368784138500,"raw":"{\"market\":\"0x28a45972fccdaf0fba75dacc59725521035e177d09dd92174f9f52740bccb025\", \"price_changes\":[{\"asset_id\":\"114356653315647913247200886351065428002113119844334520181865067698979836634569\", \"price\":\"0.1\", \"size\":\"520\", \"side\":\"BUY\", \"hash\":\"b9cac845b9d6b1df4b8af5fd243f282d0a216db6\", \"best_bid\":\"0.13\", \"best_ask\":\"0.14\"}, {\"asset_id\":\"61819828071723399190623735325323968706432622380635304641786792960078828866875\", \"price\":\"0.9\", \"size\":\"520\", \"side\":\"SELL\", \"hash\":\"1940766591185ea20d06446aad6fc92cff562683\", \"best_bid\":\"0.86\", \"best_ask\":\"0.87\"}], \"timestamp\":\"1789987927930\", \"event_type\":\"price_change\"}","raw_base64":null}
{"received_ms":1789987927953,"monotonic_ns":1019368784180700,"raw":"{\"market\":\"0x28a45972fccdaf0fba75dacc59725521035e177d09dd92174f9f52740bccb025\", \"price_changes\":[{\"asset_id\":\"61819828071723399190623735325323968706432622380635304641786792960078828866875\", \"price\":\"0.83\", \"size\":\"504\", \"side\":\"BUY\", \"hash\":\"4e6aae8d40dc55ffca14ece2363b711e00253ba2\", \"best_bid\":\"0.86\", \"best_ask\":\"0.87\"}, {\"asset_id\":\"114356653315647913247200886351065428002113119844334520181865067698979836634569\", \"price\":\"0.17\", \"size\":\"504\", \"side\":\"SELL\", \"hash\":\"873fd9b517b28238a26b77cc083dda4dc57b2d94\", \"best_bid\":\"0.13\", \"best_ask\":\"0.14\"}], \"timestamp\":\"1789987927932\", \"event_type\":\"price_change\"}","raw_base64":null}
{"received_ms":1789987927965,"monotonic_ns":1019368795977900,"raw":"{\"market\":\"0x28a45972fccdaf0fba75dacc59725521035e177d09dd92174f9f52740bccb025\", \"price_changes\":[{\"asset_id\":\"61819828071723399190623735325323968706432622380635304641786792960078828866875\", \"price\":\"0.86\", \"size\":\"1751\", \"side\":\"BUY\", \"hash\":\"99639abd1c2597dd47d9a96b0388ebab780c23b5\", \"best_bid\":\"0.86\", \"best_ask\":\"0.87\"}, {\"asset_id\":\"114356653315647913247200886351065428002113119844334520181865067698979836634569\", \"price\":\"0.14\", \"size\":\"1751\", \"side\":\"SELL\", \"hash\":\"573420d3a719750d8cb4b069d1fea0d98b38de3b\", \"best_bid\":\"0.13\", \"best_ask\":\"0.14\"}], \"timestamp\":\"1789987927944\", \"event_type\":\"price_change\"}","raw_base64":null}
{"received_ms":1789987927970,"monotonic_ns":1019368800819900,"raw":"{\"market\":\"0x28a45972fccdaf0fba75dacc59725521035e177d09dd92174f9f52740bccb025\", \"price_changes\":[{\"asset_id\":\"114356653315647913247200886351065428002113119844334520181865067698979836634569\", \"price\":\"0.05\", \"size\":\"5583\", \"side\":\"BUY\", \"hash\":\"e655e96768f12c6ee90581809e0208c92abba858\", \"best_bid\":\"0.13\", \"best_ask\":\"0.14\"}, {\"asset_id\":\"61819828071723399190623735325323968706432622380635304641786792960078828866875\", \"price\":\"0.95\", \"size\":\"5583\", \"side\":\"SELL\", \"hash\":\"b6b670f33395bb5baed2b917d3ec4a817dd8ab2d\", \"best_bid\":\"0.86\", \"best_ask\":\"0.87\"}], \"timestamp\":\"1789987927948\", \"event_type\":\"price_change\"}","raw_base64":null}
{"received_ms":1789987927970,"monotonic_ns":1019368800874100,"raw":"{\"market\":\"0x28a45972fccdaf0fba75dacc59725521035e177d09dd92174f9f52740bccb025\", \"price_changes\":[{\"asset_id\":\"61819828071723399190623735325323968706432622380635304641786792960078828866875\", \"price\":\"0.84\", \"size\":\"2367\", \"side\":\"BUY\", \"hash\":\"a7285c3b7a4ccc45736f169d0327182c3ad574e1\", \"best_bid\":\"0.86\", \"best_ask\":\"0.87\"}, {\"asset_id\":\"114356653315647913247200886351065428002113119844334520181865067698979836634569\", \"price\":\"0.16\", \"size\":\"2367\", \"side\":\"SELL\", \"hash\":\"883130be0ddf158f62624004fd07ab1326c2c86c\", \"best_bid\":\"0.13\", \"best_ask\":\"0.14\"}], \"timestamp\":\"1789987927950\", \"event_type\":\"price_change\"}","raw_base64":null}
{"received_ms":1789987927979,"monotonic_ns":1019368809513800,"raw":"{\"market\":\"0x28a45972fccdaf0fba75dacc59725521035e177d09dd92174f9f52740bccb025\", \"price_changes\":[{\"asset_id\":\"61819828071723399190623735325323968706432622380635304641786792960078828866875\", \"price\":\"0.84\", \"size\":\"2372\", \"side\":\"BUY\", \"hash\":\"22af2bf7a3379a400fef63910bea4d697f850773\", \"best_bid\":\"0.86\", \"best_ask\":\"0.87\"}, {\"asset_id\":\"114356653315647913247200886351065428002113119844334520181865067698979836634569\", \"price\":\"0.16\", \"size\":\"2372\", \"side\":\"SELL\", \"hash\":\"9653daa2d9059733363ffeeb5588f301446d866d\", \"best_bid\":\"0.13\", \"best_ask\":\"0.14\"}], \"timestamp\":\"1789987927958\", \"event_type\":\"price_change\"}","raw_base64":null}
{"received_ms":1789987927981,"monotonic_ns":1019368811750700,"raw":"{\"market\":\"0x28a45972fccdaf0fba75dacc59725521035e177d09dd92174f9f52740bccb025\", \"price_changes\":[{\"asset_id\":\"61819828071723399190623735325323968706432622380635304641786792960078828866875\", \"price\":\"0.73\", \"size\":\"504\", \"side\":\"BUY\", \"hash\":\"2c337342191a8618201468cabdc1fd41d0ff86a4\", \"best_bid\":\"0.86\", \"best_ask\":\"0.87\"}, {\"asset_id\":\"114356653315647913247200886351065428002113119844334520181865067698979836634569\", \"price\":\"0.27\", \"size\":\"504\", \"side\":\"SELL\", \"hash\":\"1501e3cd94d233ca6d74322fd207432e44f30678\", \"best_bid\":\"0.13\", \"best_ask\":\"0.14\"}], \"timestamp\":\"1789987927961\", \"event_type\":\"price_change\"}","raw_base64":null}
{"received_ms":1789987927981,"monotonic_ns":1019368812046400,"raw":"{\"market\":\"0x28a45972fccdaf0fba75dacc59725521035e177d09dd92174f9f52740bccb025\", \"price_changes\":[{\"asset_id\":\"61819828071723399190623735325323968706432622380635304641786792960078828866875\", \"price\":\"0.73\", \"size\":\"404\", \"side\":\"BUY\", \"hash\":\"41577c31a86b3c630978fbf195a3cf599062938e\", \"best_bid\":\"0.86\", \"best_ask\":\"0.87\"}, {\"asset_id\":\"114356653315647913247200886351065428002113119844334520181865067698979836634569\", \"price\":\"0.27\", \"size\":\"404\", \"side\":\"SELL\", \"hash\":\"17deb6f143566b9da6f0e4721a4dbafed7b731c6\", \"best_bid\":\"0.13\", \"best_ask\":\"0.14\"}], \"timestamp\":\"1789987927961\", \"event_type\":\"price_change\"}","raw_base64":null}
{"received_ms":1789987927986,"monotonic_ns":1019368817106300,"raw":"{\"market\":\"0x28a45972fccdaf0fba75dacc59725521035e177d09dd92174f9f52740bccb025\", \"price_changes\":[{\"asset_id\":\"114356653315647913247200886351065428002113119844334520181865067698979836634569\", \"price\":\"0.11\", \"size\":\"336.1\", \"side\":\"BUY\", \"hash\":\"6f7c2c8364e6583cbd1f0b1d8423f12daab1aeb8\", \"best_bid\":\"0.13\", \"best_ask\":\"0.14\"}, {\"asset_id\":\"61819828071723399190623735325323968706432622380635304641786792960078828866875\", \"price\":\"0.89\", \"size\":\"336.1\", \"side\":\"SELL\", \"hash\":\"3ae20ab3503c3cfa23833c22451703df6c7272e0\", \"best_bid\":\"0.86\", \"best_ask\":\"0.87\"}], \"timestamp\":\"1789987927966\", \"event_type\":\"price_change\"}","raw_base64":null}
{"received_ms":1789987928000,"monotonic_ns":1019368831266100,"raw":"{\"market\":\"0x28a45972fccdaf0fba75dacc59725521035e177d09dd92174f9f52740bccb025\", \"price_changes\":[{\"asset_id\":\"114356653315647913247200886351065428002113119844334520181865067698979836634569\", \"price\":\"0.07\", \"size\":\"6904.71\", \"side\":\"BUY\", \"hash\":\"74cbb81d245c704e1c27b5d41542119a8368ea53\", \"best_bid\":\"0.13\", \"best_ask\":\"0.14\"}, {\"asset_id\":\"61819828071723399190623735325323968706432622380635304641786792960078828866875\", \"price\":\"0.93\", \"size\":\"6904.71\", \"side\":\"SELL\", \"hash\":\"ca616f31537b16bbc96701bb4ed25c84c5c56c3a\", \"best_bid\":\"0.86\", \"best_ask\":\"0.87\"}], \"timestamp\":\"1789987927980\", \"event_type\":\"price_change\"}","raw_base64":null}
{"received_ms":1789987928002,"monotonic_ns":1019368832577100,"raw":"{\"market\":\"0x28a45972fccdaf0fba75dacc59725521035e177d09dd92174f9f52740bccb025\", \"price_changes\":[{\"asset_id\":\"114356653315647913247200886351065428002113119844334520181865067698979836634569\", \"price\":\"0.06\", \"size\":\"5163.67\", \"side\":\"BUY\", \"hash\":\"331e8762b3c9162d99c99ec09d88b73e6661c054\", \"best_bid\":\"0.13\", \"best_ask\":\"0.14\"}, {\"asset_id\":\"61819828071723399190623735325323968706432622380635304641786792960078828866875\", \"price\":\"0.94\", \"size\":\"5163.67\", \"side\":\"SELL\", \"hash\":\"5e5280086a911fb8fc46bb1fc07c726209eb75f9\", \"best_bid\":\"0.86\", \"best_ask\":\"0.87\"}], \"timestamp\":\"1789987927981\", \"event_type\":\"price_change\"}","raw_base64":null}
{"received_ms":1789987928009,"monotonic_ns":1019368839820800,"raw":"{\"market\":\"0x28a45972fccdaf0fba75dacc59725521035e177d09dd92174f9f52740bccb025\", \"price_changes\":[{\"asset_id\":\"114356653315647913247200886351065428002113119844334520181865067698979836634569\", \"price\":\"0.07\", \"size\":\"7126.71\", \"side\":\"BUY\", \"hash\":\"63c2c220c58780d8841857e4da0a9dfe3560afb0\", \"best_bid\":\"0.13\", \"best_ask\":\"0.14\"}, {\"asset_id\":\"61819828071723399190623735325323968706432622380635304641786792960078828866875\", \"price\":\"0.93\", \"size\":\"7126.71\", \"side\":\"SELL\", \"hash\":\"1834c494843eccf7416e38fa297c5b72aec830cb\", \"best_bid\":\"0.86\", \"best_ask\":\"0.87\"}], \"timestamp\":\"1789987927989\", \"event_type\":\"price_change\"}","raw_base64":null}
{"received_ms":1789987928034,"monotonic_ns":1019368864305100,"raw":"{\"market\":\"0x28a45972fccdaf0fba75dacc59725521035e177d09dd92174f9f52740bccb025\", \"price_changes\":[{\"asset_id\":\"61819828071723399190623735325323968706432622380635304641786792960078828866875\", \"price\":\"0.83\", \"size\":\"494\", \"side\":\"BUY\", \"hash\":\"382e2ef9c6d444157efe4fdea572bc52f1372077\", \"best_bid\":\"0.86\", \"best_ask\":\"0.87\"}, {\"asset_id\":\"114356653315647913247200886351065428002113119844334520181865067698979836634569\", \"price\":\"0.17\", \"size\":\"494\", \"side\":\"SELL\", \"hash\":\"7797bd436ee9a70346fa51e7590b43947009eb75\", \"best_bid\":\"0.13\", \"best_ask\":\"0.14\"}], \"timestamp\":\"1789987928012\", \"event_type\":\"price_change\"}","raw_base64":null}
{"received_ms":1789987928035,"monotonic_ns":1019368865805300,"raw":"{\"market\":\"0x28a45972fccdaf0fba75dacc59725521035e177d09dd92174f9f52740bccb025\", \"price_changes\":[{\"asset_id\":\"114356653315647913247200886351065428002113119844334520181865067698979836634569\", \"price\":\"0.13\", \"size\":\"270\", \"side\":\"BUY\", \"hash\":\"9b5ec7a0e6a24ef1710b097b34be38973c2427d9\", \"best_bid\":\"0.13\", \"best_ask\":\"0.14\"}, {\"asset_id\":\"61819828071723399190623735325323968706432622380635304641786792960078828866875\", \"price\":\"0.87\", \"size\":\"270\", \"side\":\"SELL\", \"hash\":\"d2aed57130ab5f3484dacb0fa96cc741abb46631\", \"best_bid\":\"0.86\", \"best_ask\":\"0.87\"}], \"timestamp\":\"1789987928014\", \"event_type\":\"price_change\"}","raw_base64":null}
{"received_ms":1789987928038,"monotonic_ns":1019368869068200,"raw":"{\"market\":\"0x28a45972fccdaf0fba75dacc59725521035e177d09dd92174f9f52740bccb025\", \"price_changes\":[{\"asset_id\":\"61819828071723399190623735325323968706432622380635304641786792960078828866875\", \"price\":\"0.84\", \"size\":\"2382\", \"side\":\"BUY\", \"hash\":\"3183157e9a8c69c27a1531a1ed54d9ada881a1fd\", \"best_bid\":\"0.86\", \"best_ask\":\"0.87\"}, {\"asset_id\":\"114356653315647913247200886351065428002113119844334520181865067698979836634569\", \"price\":\"0.16\", \"size\":\"2382\", \"side\":\"SELL\", \"hash\":\"151643792b0da644f557559d358b88956ed3ee63\", \"best_bid\":\"0.13\", \"best_ask\":\"0.14\"}], \"timestamp\":\"1789987928018\", \"event_type\":\"price_change\"}","raw_base64":null}
{"received_ms":1789987928041,"monotonic_ns":1019368872025500,"raw":"{\"market\":\"0x28a45972fccdaf0fba75dacc59725521035e177d09dd92174f9f52740bccb025\", \"price_changes\":[{\"asset_id\":\"61819828071723399190623735325323968706432622380635304641786792960078828866875\", \"price\":\"0.85\", \"size\":\"2687.52\", \"side\":\"BUY\", \"hash\":\"38cda8257c932a10dc004c96265685cef74152c4\", \"best_bid\":\"0.86\", \"best_ask\":\"0.87\"}, {\"asset_id\":\"114356653315647913247200886351065428002113119844334520181865067698979836634569\", \"price\":\"0.15\", \"size\":\"2687.52\", \"side\":\"SELL\", \"hash\":\"238da407ad4053e50800a0c0ba28f5de3d5d2d20\", \"best_bid\":\"0.13\", \"best_ask\":\"0.14\"}], \"timestamp\":\"1789987928021\", \"event_type\":\"price_change\"}","raw_base64":null}
{"received_ms":1789987928043,"monotonic_ns":1019368874031200,"raw":"{\"market\":\"0x28a45972fccdaf0fba75dacc59725521035e177d09dd92174f9f52740bccb025\", \"price_changes\":[{\"asset_id\":\"114356653315647913247200886351065428002113119844334520181865067698979836634569\", \"price\":\"0.06\", \"size\":\"5972.67\", \"side\":\"BUY\", \"hash\":\"d85e15e0119de78ef09a3ebf62ecd6a146a6d077\", \"best_bid\":\"0.13\", \"best_ask\":\"0.14\"}, {\"asset_id\":\"61819828071723399190623735325323968706432622380635304641786792960078828866875\", \"price\":\"0.94\", \"size\":\"5972.67\", \"side\":\"SELL\", \"hash\":\"fab4a2ea1965c18a26b02a4f24eccc93002ea55f\", \"best_bid\":\"0.86\", \"best_ask\":\"0.87\"}], \"timestamp\":\"1789987928022\", \"event_type\":\"price_change\"}","raw_base64":null}
{"received_ms":1789987928044,"monotonic_ns":1019368874871100,"raw":"{\"market\":\"0x28a45972fccdaf0fba75dacc59725521035e177d09dd92174f9f52740bccb025\", \"price_changes\":[{\"asset_id\":\"61819828071723399190623735325323968706432622380635304641786792960078828866875\", \"price\":\"0.86\", \"size\":\"1934\", \"side\":\"BUY\", \"hash\":\"ddc4efd6d2f90bd6b9a8fcba5e2f81ec893890b2\", \"best_bid\":\"0.86\", \"best_ask\":\"0.87\"}, {\"asset_id\":\"114356653315647913247200886351065428002113119844334520181865067698979836634569\", \"price\":\"0.14\", \"size\":\"1934\", \"side\":\"SELL\", \"hash\":\"699140c5c8d3f89674003a83b505f129487d393a\", \"best_bid\":\"0.13\", \"best_ask\":\"0.14\"}], \"timestamp\":\"1789987928023\", \"event_type\":\"price_change\"}","raw_base64":null}
{"received_ms":1789987928044,"monotonic_ns":1019368874943500,"raw":"{\"market\":\"0x28a45972fccdaf0fba75dacc59725521035e177d09dd92174f9f52740bccb025\", \"price_changes\":[{\"asset_id\":\"61819828071723399190623735325323968706432622380635304641786792960078828866875\", \"price\":\"0.84\", \"size\":\"2855\", \"side\":\"BUY\", \"hash\":\"545c7cc140c906d3d4f9c85020ff379119453d58\", \"best_bid\":\"0.86\", \"best_ask\":\"0.87\"}, {\"asset_id\":\"114356653315647913247200886351065428002113119844334520181865067698979836634569\", \"price\":\"0.16\", \"size\":\"2855\", \"side\":\"SELL\", \"hash\":\"832ffbc72cd1b903d02f6e84976d4f3d43988b49\", \"best_bid\":\"0.13\", \"best_ask\":\"0.14\"}], \"timestamp\":\"1789987928024\", \"event_type\":\"price_change\"}","raw_base64":null}
{"received_ms":1789987928049,"monotonic_ns":1019368879581000,"raw":"{\"market\":\"0x28a45972fccdaf0fba75dacc59725521035e177d09dd92174f9f52740bccb025\", \"price_changes\":[{\"asset_id\":\"61819828071723399190623735325323968706432622380635304641786792960078828866875\", \"price\":\"0.73\", \"size\":\"504\", \"side\":\"BUY\", \"hash\":\"882301805618fb00fc2aa0635426e25d59cd5a89\", \"best_bid\":\"0.86\", \"best_ask\":\"0.87\"}, {\"asset_id\":\"114356653315647913247200886351065428002113119844334520181865067698979836634569\", \"price\":\"0.27\", \"size\":\"504\", \"side\":\"SELL\", \"hash\":\"f0fd036a0736f547aa469f34159336ee832f349b\", \"best_bid\":\"0.13\", \"best_ask\":\"0.14\"}], \"timestamp\":\"1789987928027\", \"event_type\":\"price_change\"}","raw_base64":null}
{"received_ms":1789987928050,"monotonic_ns":1019368881092000,"raw":"{\"market\":\"0x28a45972fccdaf0fba75dacc59725521035e177d09dd92174f9f52740bccb025\", \"price_changes\":[{\"asset_id\":\"61819828071723399190623735325323968706432622380635304641786792960078828866875\", \"price\":\"0.73\", \"size\":\"404\", \"side\":\"BUY\", \"hash\":\"477ba9bd034c8a4303686e1d9786e9cda883dc6d\", \"best_bid\":\"0.86\", \"best_ask\":\"0.87\"}, {\"asset_id\":\"114356653315647913247200886351065428002113119844334520181865067698979836634569\", \"price\":\"0.27\", \"size\":\"404\", \"side\":\"SELL\", \"hash\":\"0551e3939d9250497cbe83f096b22377adbeb42e\", \"best_bid\":\"0.13\", \"best_ask\":\"0.14\"}], \"timestamp\":\"1789987928029\", \"event_type\":\"price_change\"}","raw_base64":null}
{"received_ms":1789987928055,"monotonic_ns":1019368885483900,"raw":"{\"market\":\"0x28a45972fccdaf0fba75dacc59725521035e177d09dd92174f9f52740bccb025\", \"price_changes\":[{\"asset_id\":\"114356653315647913247200886351065428002113119844334520181865067698979836634569\", \"price\":\"0.01\", \"size\":\"1694.43\", \"side\":\"BUY\", \"hash\":\"91a33c2bd5791a2d1f86a44b349b594f45d31516\", \"best_bid\":\"0.13\", \"best_ask\":\"0.14\"}, {\"asset_id\":\"61819828071723399190623735325323968706432622380635304641786792960078828866875\", \"price\":\"0.99\", \"size\":\"1694.43\", \"side\":\"SELL\", \"hash\":\"89c1f9360064ce00cdf1e96d9deafde8b510a512\", \"best_bid\":\"0.86\", \"best_ask\":\"0.87\"}], \"timestamp\":\"1789987928033\", \"event_type\":\"price_change\"}","raw_base64":null}
{"received_ms":1789987928070,"monotonic_ns":1019368900503400,"raw":"{\"market\":\"0x28a45972fccdaf0fba75dacc59725521035e177d09dd92174f9f52740bccb025\", \"price_changes\":[{\"asset_id\":\"114356653315647913247200886351065428002113119844334520181865067698979836634569\", \"price\":\"0.06\", \"size\":\"5163.67\", \"side\":\"BUY\", \"hash\":\"f780893f53212d763bf9a4d8f5009ec041dd973f\", \"best_bid\":\"0.13\", \"best_ask\":\"0.14\"}, {\"asset_id\":\"61819828071723399190623735325323968706432622380635304641786792960078828866875\", \"price\":\"0.94\", \"size\":\"5163.67\", \"side\":\"SELL\", \"hash\":\"2ee559b8808c02db227554e71ce4ca7513af2b5e\", \"best_bid\":\"0.86\", \"best_ask\":\"0.87\"}], \"timestamp\":\"1789987928049\", \"event_type\":\"price_change\"}","raw_base64":null}
{"received_ms":1789987928072,"monotonic_ns":1019368902523300,"raw":"{\"market\":\"0x28a45972fccdaf0fba75dacc59725521035e177d09dd92174f9f52740bccb025\", \"price_changes\":[{\"asset_id\":\"61819828071723399190623735325323968706432622380635304641786792960078828866875\", \"price\":\"0.86\", \"size\":\"1751\", \"side\":\"BUY\", \"hash\":\"0b964e9ce24a7fa6b7a4dd9f5e84a80a42949560\", \"best_bid\":\"0.86\", \"best_ask\":\"0.87\"}, {\"asset_id\":\"114356653315647913247200886351065428002113119844334520181865067698979836634569\", \"price\":\"0.14\", \"size\":\"1751\", \"side\":\"SELL\", \"hash\":\"aef88c6e5dd02d55236432cdd24aee7ed1be1be8\", \"best_bid\":\"0.13\", \"best_ask\":\"0.14\"}], \"timestamp\":\"1789987928051\", \"event_type\":\"price_change\"}","raw_base64":null}
{"received_ms":1789987928113,"monotonic_ns":1019368943292500,"raw":"{\"market\":\"0x28a45972fccdaf0fba75dacc59725521035e177d09dd92174f9f52740bccb025\", \"price_changes\":[{\"asset_id\":\"61819828071723399190623735325323968706432622380635304641786792960078828866875\", \"price\":\"0.84\", \"size\":\"2382\", \"side\":\"BUY\", \"hash\":\"21bc45900271b67885df70dd68f8b3ba2d36ea64\", \"best_bid\":\"0.86\", \"best_ask\":\"0.87\"}, {\"asset_id\":\"114356653315647913247200886351065428002113119844334520181865067698979836634569\", \"price\":\"0.16\", \"size\":\"2382\", \"side\":\"SELL\", \"hash\":\"f0618f89358c85f9d4fd9226b77931f04485610e\", \"best_bid\":\"0.13\", \"best_ask\":\"0.14\"}], \"timestamp\":\"1789987928093\", \"event_type\":\"price_change\"}","raw_base64":null}
{"received_ms":1789987928113,"monotonic_ns":1019368944269500,"raw":"{\"market\":\"0x28a45972fccdaf0fba75dacc59725521035e177d09dd92174f9f52740bccb025\", \"price_changes\":[{\"asset_id\":\"114356653315647913247200886351065428002113119844334520181865067698979836634569\", \"price\":\"0.06\", \"size\":\"5971.67\", \"side\":\"BUY\", \"hash\":\"11795343a55082880177dc4c17b5573b8a1c8fe0\", \"best_bid\":\"0.13\", \"best_ask\":\"0.14\"}, {\"asset_id\":\"61819828071723399190623735325323968706432622380635304641786792960078828866875\", \"price\":\"0.94\", \"size\":\"5971.67\", \"side\":\"SELL\", \"hash\":\"867fd0a7208904269408032e8780ce3caeeb2767\", \"best_bid\":\"0.86\", \"best_ask\":\"0.87\"}], \"timestamp\":\"1789987928093\", \"event_type\":\"price_change\"}","raw_base64":null}
{"received_ms":1789987928115,"monotonic_ns":1019368945606400,"raw":"{\"market\":\"0x28a45972fccdaf0fba75dacc59725521035e177d09dd92174f9f52740bccb025\", \"price_changes\":[{\"asset_id\":\"114356653315647913247200886351065428002113119844334520181865067698979836634569\", \"price\":\"0.05\", \"size\":\"5588\", \"side\":\"BUY\", \"hash\":\"3becc6f36de4ca62178a24e93690ee966ddf2345\", \"best_bid\":\"0.13\", \"best_ask\":\"0.14\"}, {\"asset_id\":\"61819828071723399190623735325323968706432622380635304641786792960078828866875\", \"price\":\"0.95\", \"size\":\"5588\", \"side\":\"SELL\", \"hash\":\"ae90002a141a100b896c974cd9f97d86714a16b2\", \"best_bid\":\"0.86\", \"best_ask\":\"0.87\"}], \"timestamp\":\"1789987928094\", \"event_type\":\"price_change\"}","raw_base64":null}
{"received_ms":1789987928119,"monotonic_ns":1019368949489000,"raw":"{\"market\":\"0x28a45972fccdaf0fba75dacc59725521035e177d09dd92174f9f52740bccb025\", \"price_changes\":[{\"asset_id\":\"114356653315647913247200886351065428002113119844334520181865067698979836634569\", \"price\":\"0.07\", \"size\":\"7198.71\", \"side\":\"BUY\", \"hash\":\"1d90bcd418500e88c3d1927a64b0f0053decb9a6\", \"best_bid\":\"0.13\", \"best_ask\":\"0.14\"}, {\"asset_id\":\"61819828071723399190623735325323968706432622380635304641786792960078828866875\", \"price\":\"0.93\", \"size\":\"7198.71\", \"side\":\"SELL\", \"hash\":\"aba1f21d93e6c604b0441df8ed6cd60f255a2e2b\", \"best_bid\":\"0.86\", \"best_ask\":\"0.87\"}], \"timestamp\":\"1789987928099\", \"event_type\":\"price_change\"}","raw_base64":null}
{"received_ms":1789987928120,"monotonic_ns":1019368950772200,"raw":"{\"market\":\"0x28a45972fccdaf0fba75dacc59725521035e177d09dd92174f9f52740bccb025\", \"price_changes\":[{\"asset_id\":\"61819828071723399190623735325323968706432622380635304641786792960078828866875\", \"price\":\"0.73\", \"size\":\"504\", \"side\":\"BUY\", \"hash\":\"be017b42d3f7c4929206eb9b087cafcab4e616b2\", \"best_bid\":\"0.86\", \"best_ask\":\"0.87\"}, {\"asset_id\":\"114356653315647913247200886351065428002113119844334520181865067698979836634569\", \"price\":\"0.27\", \"size\":\"504\", \"side\":\"SELL\", \"hash\":\"2025b74e1edf173a1899728361a4d1ad23df601b\", \"best_bid\":\"0.13\", \"best_ask\":\"0.14\"}], \"timestamp\":\"1789987928100\", \"event_type\":\"price_change\"}","raw_base64":null}
{"received_ms":1789987928124,"monotonic_ns":1019368954661500,"raw":"{\"market\":\"0x28a45972fccdaf0fba75dacc59725521035e177d09dd92174f9f52740bccb025\", \"price_changes\":[{\"asset_id\":\"61819828071723399190623735325323968706432622380635304641786792960078828866875\", \"price\":\"0.73\", \"size\":\"404\", \"side\":\"BUY\", \"hash\":\"b8db611a81e2a0bcee38b9c3ecb2cb89ffe3a6e2\", \"best_bid\":\"0.86\", \"best_ask\":\"0.87\"}, {\"asset_id\":\"114356653315647913247200886351065428002113119844334520181865067698979836634569\", \"price\":\"0.27\", \"size\":\"404\", \"side\":\"SELL\", \"hash\":\"ba45686da257c2c9bad92e0cf24fc170bca6698a\", \"best_bid\":\"0.13\", \"best_ask\":\"0.14\"}], \"timestamp\":\"1789987928104\", \"event_type\":\"price_change\"}","raw_base64":null}
{"received_ms":1789987928129,"monotonic_ns":1019368960020400,"raw":"{\"market\":\"0x28a45972fccdaf0fba75dacc59725521035e177d09dd92174f9f52740bccb025\", \"price_changes\":[{\"asset_id\":\"114356653315647913247200886351065428002113119844334520181865067698979836634569\", \"price\":\"0.07\", \"size\":\"7178.71\", \"side\":\"BUY\", \"hash\":\"7fbd1ad6db4fb100273f5d567ba1cb861d05e1ea\", \"best_bid\":\"0.13\", \"best_ask\":\"0.14\"}, {\"asset_id\":\"61819828071723399190623735325323968706432622380635304641786792960078828866875\", \"price\":\"0.93\", \"size\":\"7178.71\", \"side\":\"SELL\", \"hash\":\"af42ffe93d723221fc861aca7aea4f71c3806942\", \"best_bid\":\"0.86\", \"best_ask\":\"0.87\"}], \"timestamp\":\"1789987928109\", \"event_type\":\"price_change\"}","raw_base64":null}
{"received_ms":1789987928153,"monotonic_ns":1019368984107100,"raw":"{\"market\":\"0x28a45972fccdaf0fba75dacc59725521035e177d09dd92174f9f52740bccb025\", \"price_changes\":[{\"asset_id\":\"61819828071723399190623735325323968706432622380635304641786792960078828866875\", \"price\":\"0.84\", \"size\":\"2705\", \"side\":\"BUY\", \"hash\":\"e6cf9792ffe967aef8dff5093ea55fcb5899e13e\", \"best_bid\":\"0.86\", \"best_ask\":\"0.87\"}, {\"asset_id\":\"114356653315647913247200886351065428002113119844334520181865067698979836634569\", \"price\":\"0.16\", \"size\":\"2705\", \"side\":\"SELL\", \"hash\":\"2c1b3a978ade3066465e351da21e3a829a35493e\", \"best_bid\":\"0.13\", \"best_ask\":\"0.14\"}], \"timestamp\":\"1789987928133\", \"event_type\":\"price_change\"}","raw_base64":null}
{"received_ms":1789987928154,"monotonic_ns":1019368984708600,"raw":"{\"market\":\"0x28a45972fccdaf0fba75dacc59725521035e177d09dd92174f9f52740bccb025\", \"price_changes\":[{\"asset_id\":\"61819828071723399190623735325323968706432622380635304641786792960078828866875\", \"price\":\"0.77\", \"size\":\"587.49\", \"side\":\"BUY\", \"hash\":\"96af3100fd02dcb91be8f085a6adf7f8ed813a87\", \"best_bid\":\"0.86\", \"best_ask\":\"0.87\"}, {\"asset_id\":\"114356653315647913247200886351065428002113119844334520181865067698979836634569\", \"price\":\"0.23\", \"size\":\"587.49\", \"side\":\"SELL\", \"hash\":\"c4e83aab5c706c1caf92af7238ae755d7cfe81a7\", \"best_bid\":\"0.13\", \"best_ask\":\"0.14\"}], \"timestamp\":\"1789987928134\", \"event_type\":\"price_change\"}","raw_base64":null}
{"received_ms":1789987928155,"monotonic_ns":1019368985907900,"raw":"{\"market\":\"0x28a45972fccdaf0fba75dacc59725521035e177d09dd92174f9f52740bccb025\", \"price_changes\":[{\"asset_id\":\"61819828071723399190623735325323968706432622380635304641786792960078828866875\", \"price\":\"0.79\", \"size\":\"487\", \"side\":\"BUY\", \"hash\":\"23528d1f9df88ae900667ba15bac614ce5ef5123\", \"best_bid\":\"0.86\", \"best_ask\":\"0.87\"}, {\"asset_id\":\"114356653315647913247200886351065428002113119844334520181865067698979836634569\", \"price\":\"0.21\", \"size\":\"487\", \"side\":\"SELL\", \"hash\":\"0563cbb5b0185ed9c649f012bcbe324a5972a8bb\", \"best_bid\":\"0.13\", \"best_ask\":\"0.14\"}], \"timestamp\":\"1789987928135\", \"event_type\":\"price_change\"}","raw_base64":null}
{"received_ms":1789987928156,"monotonic_ns":1019368986654700,"raw":"{\"market\":\"0x28a45972fccdaf0fba75dacc59725521035e177d09dd92174f9f52740bccb025\", \"price_changes\":[{\"asset_id\":\"61819828071723399190623735325323968706432622380635304641786792960078828866875\", \"price\":\"0.86\", \"size\":\"3407\", \"side\":\"BUY\", \"hash\":\"b23bdd486dddc25c3b7e9eb9a43eecb1255c77fc\", \"best_bid\":\"0.86\", \"best_ask\":\"0.87\"}, {\"asset_id\":\"114356653315647913247200886351065428002113119844334520181865067698979836634569\", \"price\":\"0.14\", \"size\":\"3407\", \"side\":\"SELL\", \"hash\":\"2e8f51726587f4edfb62f0be3fa424c817815a32\", \"best_bid\":\"0.13\", \"best_ask\":\"0.14\"}], \"timestamp\":\"1789987928136\", \"event_type\":\"price_change\"}","raw_base64":null}
{"received_ms":1789987928160,"monotonic_ns":1019368990342000,"raw":"{\"market\":\"0x28a45972fccdaf0fba75dacc59725521035e177d09dd92174f9f52740bccb025\", \"price_changes\":[{\"asset_id\":\"114356653315647913247200886351065428002113119844334520181865067698979836634569\", \"price\":\"0.05\", \"size\":\"5608\", \"side\":\"BUY\", \"hash\":\"e076f40255e06d56b8c2a29c800f9abff8f002c5\", \"best_bid\":\"0.13\", \"best_ask\":\"0.14\"}, {\"asset_id\":\"61819828071723399190623735325323968706432622380635304641786792960078828866875\", \"price\":\"0.95\", \"size\":\"5608\", \"side\":\"SELL\", \"hash\":\"277a0d6bb527d6d67defe53a3f3b7f6f89ebf72a\", \"best_bid\":\"0.86\", \"best_ask\":\"0.87\"}], \"timestamp\":\"1789987928139\", \"event_type\":\"price_change\"}","raw_base64":null}
{"received_ms":1789987928162,"monotonic_ns":1019368992601100,"raw":"{\"market\":\"0x28a45972fccdaf0fba75dacc59725521035e177d09dd92174f9f52740bccb025\", \"price_changes\":[{\"asset_id\":\"61819828071723399190623735325323968706432622380635304641786792960078828866875\", \"price\":\"0.77\", \"size\":\"547.49\", \"side\":\"BUY\", \"hash\":\"bce0b1c90faf964f0bafc27fec4f1b5916dc1192\", \"best_bid\":\"0.86\", \"best_ask\":\"0.87\"}, {\"asset_id\":\"114356653315647913247200886351065428002113119844334520181865067698979836634569\", \"price\":\"0.23\", \"size\":\"547.49\", \"side\":\"SELL\", \"hash\":\"cf6c14efebfdabce9755e63637a445a221e208b3\", \"best_bid\":\"0.13\", \"best_ask\":\"0.14\"}], \"timestamp\":\"1789987928142\", \"event_type\":\"price_change\"}","raw_base64":null}
{"received_ms":1789987928162,"monotonic_ns":1019368992652300,"raw":"{\"market\":\"0x28a45972fccdaf0fba75dacc59725521035e177d09dd92174f9f52740bccb025\", \"price_changes\":[{\"asset_id\":\"61819828071723399190623735325323968706432622380635304641786792960078828866875\", \"price\":\"0.79\", \"size\":\"427\", \"side\":\"BUY\", \"hash\":\"bce0b1c90faf964f0bafc27fec4f1b5916dc1192\", \"best_bid\":\"0.86\", \"best_ask\":\"0.87\"}, {\"asset_id\":\"114356653315647913247200886351065428002113119844334520181865067698979836634569\", \"price\":\"0.21\", \"size\":\"427\", \"side\":\"SELL\", \"hash\":\"cf6c14efebfdabce9755e63637a445a221e208b3\", \"best_bid\":\"0.13\", \"best_ask\":\"0.14\"}], \"timestamp\":\"1789987928142\", \"event_type\":\"price_change\"}","raw_base64":null}
{"received_ms":1789987928166,"monotonic_ns":1019368997246800,"raw":"{\"market\":\"0x28a45972fccdaf0fba75dacc59725521035e177d09dd92174f9f52740bccb025\", \"price_changes\":[{\"asset_id\":\"114356653315647913247200886351065428002113119844334520181865067698979836634569\", \"price\":\"0.11\", \"size\":\"316.1\", \"side\":\"BUY\", \"hash\":\"07d2e47bd27026ed5fe8a4198ee5120b78156bb7\", \"best_bid\":\"0.13\", \"best_ask\":\"0.14\"}, {\"asset_id\":\"61819828071723399190623735325323968706432622380635304641786792960078828866875\", \"price\":\"0.89\", \"size\":\"316.1\", \"side\":\"SELL\", \"hash\":\"e915090d85b298a39b34d4ffade981a4475bd7b6\", \"best_bid\":\"0.86\", \"best_ask\":\"0.87\"}], \"timestamp\":\"1789987928146\", \"event_type\":\"price_change\"}","raw_base64":null}
{"received_ms":1789987928169,"monotonic_ns":1019369000010200,"raw":"{\"market\":\"0x28a45972fccdaf0fba75dacc59725521035e177d09dd92174f9f52740bccb025\", \"price_changes\":[{\"asset_id\":\"114356653315647913247200886351065428002113119844334520181865067698979836634569\", \"price\":\"0.1\", \"size\":\"580\", \"side\":\"BUY\", \"hash\":\"18d13d0199d716a57c03feb60b2ebff3306a9c47\", \"best_bid\":\"0.13\", \"best_ask\":\"0.14\"}, {\"asset_id\":\"61819828071723399190623735325323968706432622380635304641786792960078828866875\", \"price\":\"0.9\", \"size\":\"580\", \"side\":\"SELL\", \"hash\":\"d1fcb44a8f0757869d5ce680162dc8360e45236b\", \"best_bid\":\"0.86\", \"best_ask\":\"0.87\"}], \"timestamp\":\"1789987928148\", \"event_type\":\"price_change\"}","raw_base64":null}
{"received_ms":1789987928184,"monotonic_ns":1019369014553700,"raw":"{\"market\":\"0x28a45972fccdaf0fba75dacc59725521035e177d09dd92174f9f52740bccb025\", \"price_changes\":[{\"asset_id\":\"114356653315647913247200886351065428002113119844334520181865067698979836634569\", \"price\":\"0.13\", \"size\":\"280\", \"side\":\"BUY\", \"hash\":\"bd0382abd79eb45ba0ed0ac96942c2e3820f7bfa\", \"best_bid\":\"0.13\", \"best_ask\":\"0.14\"}, {\"asset_id\":\"61819828071723399190623735325323968706432622380635304641786792960078828866875\", \"price\":\"0.87\", \"size\":\"280\", \"side\":\"SELL\", \"hash\":\"f4f85142716de6d3c6fab64c840fb270451a0fdf\", \"best_bid\":\"0.86\", \"best_ask\":\"0.87\"}], \"timestamp\":\"1789987928163\", \"event_type\":\"price_change\"}","raw_base64":null}
{"received_ms":1789987928189,"monotonic_ns":1019369019840800,"raw":"{\"market\":\"0x28a45972fccdaf0fba75dacc59725521035e177d09dd92174f9f52740bccb025\", \"price_changes\":[{\"asset_id\":\"114356653315647913247200886351065428002113119844334520181865067698979836634569\", \"price\":\"0.13\", \"size\":\"270\", \"side\":\"BUY\", \"hash\":\"ef5d4ce5681a2b18560bb92c373e32dc5ee8f603\", \"best_bid\":\"0.13\", \"best_ask\":\"0.14\"}, {\"asset_id\":\"61819828071723399190623735325323968706432622380635304641786792960078828866875\", \"price\":\"0.87\", \"size\":\"270\", \"side\":\"SELL\", \"hash\":\"80d48daa4326cfdb6e45af587e3919e9f06b75dc\", \"best_bid\":\"0.86\", \"best_ask\":\"0.87\"}], \"timestamp\":\"1789987928168\", \"event_type\":\"price_change\"}","raw_base64":null}
{"received_ms":1789987928189,"monotonic_ns":1019369019897600,"raw":"{\"market\":\"0x28a45972fccdaf0fba75dacc59725521035e177d09dd92174f9f52740bccb025\", \"price_changes\":[{\"asset_id\":\"61819828071723399190623735325323968706432622380635304641786792960078828866875\", \"price\":\"0.84\", \"size\":\"2720\", \"side\":\"BUY\", \"hash\":\"7fdd1b083605671b21f3466906d8186108ed72c6\", \"best_bid\":\"0.86\", \"best_ask\":\"0.87\"}, {\"asset_id\":\"114356653315647913247200886351065428002113119844334520181865067698979836634569\", \"price\":\"0.16\", \"size\":\"2720\", \"side\":\"SELL\", \"hash\":\"271472cd5274dcb036e065bacd4443d42734e4ec\", \"best_bid\":\"0.13\", \"best_ask\":\"0.14\"}], \"timestamp\":\"1789987928169\", \"event_type\":\"price_change\"}","raw_base64":null}
{"received_ms":1789987928199,"monotonic_ns":1019369029453200,"raw":"{\"market\":\"0x28a45972fccdaf0fba75dacc59725521035e177d09dd92174f9f52740bccb025\", \"price_changes\":[{\"asset_id\":\"114356653315647913247200886351065428002113119844334520181865067698979836634569\", \"price\":\"0.07\", \"size\":\"7198.71\", \"side\":\"BUY\", \"hash\":\"b42c8910e459295f24d11bee499479bd90215f3d\", \"best_bid\":\"0.13\", \"best_ask\":\"0.14\"}, {\"asset_id\":\"61819828071723399190623735325323968706432622380635304641786792960078828866875\", \"price\":\"0.93\", \"size\":\"7198.71\", \"side\":\"SELL\", \"hash\":\"7747ff0378fed647f5b491afdf919907c4cb867f\", \"best_bid\":\"0.86\", \"best_ask\":\"0.87\"}], \"timestamp\":\"1789987928178\", \"event_type\":\"price_change\"}","raw_base64":null}
{"received_ms":1789987928211,"monotonic_ns":1019369041371100,"raw":"{\"market\":\"0x28a45972fccdaf0fba75dacc59725521035e177d09dd92174f9f52740bccb025\", \"price_changes\":[{\"asset_id\":\"61819828071723399190623735325323968706432622380635304641786792960078828866875\", \"price\":\"0.85\", \"size\":\"2697.52\", \"side\":\"BUY\", \"hash\":\"aa9a59ede0595625e0f10a427183d3268bb5cc9d\", \"best_bid\":\"0.86\", \"best_ask\":\"0.87\"}, {\"asset_id\":\"114356653315647913247200886351065428002113119844334520181865067698979836634569\", \"price\":\"0.15\", \"size\":\"2697.52\", \"side\":\"SELL\", \"hash\":\"9c5ce2647f4c3f3044509a33691c5eb8b2fc7357\", \"best_bid\":\"0.13\", \"best_ask\":\"0.14\"}], \"timestamp\":\"1789987928190\", \"event_type\":\"price_change\"}","raw_base64":null}
{"received_ms":1789987928230,"monotonic_ns":1019369061251400,"raw":"{\"market\":\"0x28a45972fccdaf0fba75dacc59725521035e177d09dd92174f9f52740bccb025\", \"price_changes\":[{\"asset_id\":\"114356653315647913247200886351065428002113119844334520181865067698979836634569\", \"price\":\"0.07\", \"size\":\"7178.71\", \"side\":\"BUY\", \"hash\":\"01b4ed8ec2cc736ac8940253d6aa8e7995258fb0\", \"best_bid\":\"0.13\", \"best_ask\":\"0.14\"}, {\"asset_id\":\"61819828071723399190623735325323968706432622380635304641786792960078828866875\", \"price\":\"0.93\", \"size\":\"7178.71\", \"side\":\"SELL\", \"hash\":\"a3ff9ae5798efe146b513463f1a4503fd80c7b08\", \"best_bid\":\"0.86\", \"best_ask\":\"0.87\"}], \"timestamp\":\"1789987928207\", \"event_type\":\"price_change\"}","raw_base64":null}
{"received_ms":1789987928231,"monotonic_ns":1019369061312400,"raw":"{\"market\":\"0x28a45972fccdaf0fba75dacc59725521035e177d09dd92174f9f52740bccb025\", \"price_changes\":[{\"asset_id\":\"114356653315647913247200886351065428002113119844334520181865067698979836634569\", \"price\":\"0.1\", \"size\":\"520\", \"side\":\"BUY\", \"hash\":\"01b4ed8ec2cc736ac8940253d6aa8e7995258fb0\", \"best_bid\":\"0.13\", \"best_ask\":\"0.14\"}, {\"asset_id\":\"61819828071723399190623735325323968706432622380635304641786792960078828866875\", \"price\":\"0.9\", \"size\":\"520\", \"side\":\"SELL\", \"hash\":\"a3ff9ae5798efe146b513463f1a4503fd80c7b08\", \"best_bid\":\"0.86\", \"best_ask\":\"0.87\"}], \"timestamp\":\"1789987928207\", \"event_type\":\"price_change\"}","raw_base64":null}
{"received_ms":1789987928246,"monotonic_ns":1019369076734000,"raw":"{\"market\":\"0x28a45972fccdaf0fba75dacc59725521035e177d09dd92174f9f52740bccb025\", \"price_changes\":[{\"asset_id\":\"61819828071723399190623735325323968706432622380635304641786792960078828866875\", \"price\":\"0.79\", \"size\":\"487\", \"side\":\"BUY\", \"hash\":\"260bea22a99f315d154b061502edf6d00b7cc7b4\", \"best_bid\":\"0.86\", \"best_ask\":\"0.87\"}, {\"asset_id\":\"114356653315647913247200886351065428002113119844334520181865067698979836634569\", \"price\":\"0.21\", \"size\":\"487\", \"side\":\"SELL\", \"hash\":\"32a500a0d41c1b235751d82d0b72b147c058b555\", \"best_bid\":\"0.13\", \"best_ask\":\"0.14\"}], \"timestamp\":\"1789987928214\", \"event_type\":\"price_change\"}","raw_base64":null}
{"received_ms":1789987928246,"monotonic_ns":1019369076794500,"raw":"{\"market\":\"0x28a45972fccdaf0fba75dacc59725521035e177d09dd92174f9f52740bccb025\", \"price_changes\":[{\"asset_id\":\"61819828071723399190623735325323968706432622380635304641786792960078828866875\", \"price\":\"0.77\", \"size\":\"587.49\", \"side\":\"BUY\", \"hash\":\"35955db6e63524c867bc54a792cbf7e59963c42e\", \"best_bid\":\"0.86\", \"best_ask\":\"0.87\"}, {\"asset_id\":\"114356653315647913247200886351065428002113119844334520181865067698979836634569\", \"price\":\"0.23\", \"size\":\"587.49\", \"side\":\"SELL\", \"hash\":\"e3fad8a708bb669b41bbcbf02f274bb781280051\", \"best_bid\":\"0.13\", \"best_ask\":\"0.14\"}], \"timestamp\":\"1789987928215\", \"event_type\":\"price_change\"}","raw_base64":null}
{"received_ms":1789987928246,"monotonic_ns":1019369076847800,"raw":"{\"market\":\"0x28a45972fccdaf0fba75dacc59725521035e177d09dd92174f9f52740bccb025\", \"price_changes\":[{\"asset_id\":\"114356653315647913247200886351065428002113119844334520181865067698979836634569\", \"price\":\"0.01\", \"size\":\"1689.43\", \"side\":\"BUY\", \"hash\":\"56764ce28dcc03f4cc89941a63d96eb38ef5592f\", \"best_bid\":\"0.13\", \"best_ask\":\"0.14\"}, {\"asset_id\":\"61819828071723399190623735325323968706432622380635304641786792960078828866875\", \"price\":\"0.99\", \"size\":\"1689.43\", \"side\":\"SELL\", \"hash\":\"cc0855cf6acbe5e7792d73334ec4dce2388e5286\", \"best_bid\":\"0.86\", \"best_ask\":\"0.87\"}], \"timestamp\":\"1789987928216\", \"event_type\":\"price_change\"}","raw_base64":null}
{"received_ms":1789987928246,"monotonic_ns":1019369076897500,"raw":"{\"market\":\"0x28a45972fccdaf0fba75dacc59725521035e177d09dd92174f9f52740bccb025\", \"price_changes\":[{\"asset_id\":\"61819828071723399190623735325323968706432622380635304641786792960078828866875\", \"price\":\"0.77\", \"size\":\"547.49\", \"side\":\"BUY\", \"hash\":\"1159e5406b83687410b24b52dc6fb8fe240b3592\", \"best_bid\":\"0.86\", \"best_ask\":\"0.87\"}, {\"asset_id\":\"114356653315647913247200886351065428002113119844334520181865067698979836634569\", \"price\":\"0.23\", \"size\":\"547.49\", \"side\":\"SELL\", \"hash\":\"6ef1f9d2077925bac0f30f0d475578cf47f67858\", \"best_bid\":\"0.13\", \"best_ask\":\"0.14\"}], \"timestamp\":\"1789987928216\", \"event_type\":\"price_change\"}","raw_base64":null}
{"received_ms":1789987928246,"monotonic_ns":1019369076945900,"raw":"{\"market\":\"0x28a45972fccdaf0fba75dacc59725521035e177d09dd92174f9f52740bccb025\", \"price_changes\":[{\"asset_id\":\"61819828071723399190623735325323968706432622380635304641786792960078828866875\", \"price\":\"0.79\", \"size\":\"427\", \"side\":\"BUY\", \"hash\":\"1159e5406b83687410b24b52dc6fb8fe240b3592\", \"best_bid\":\"0.86\", \"best_ask\":\"0.87\"}, {\"asset_id\":\"114356653315647913247200886351065428002113119844334520181865067698979836634569\", \"price\":\"0.21\", \"size\":\"427\", \"side\":\"SELL\", \"hash\":\"6ef1f9d2077925bac0f30f0d475578cf47f67858\", \"best_bid\":\"0.13\", \"best_ask\":\"0.14\"}], \"timestamp\":\"1789987928216\", \"event_type\":\"price_change\"}","raw_base64":null}
{"received_ms":1789987928246,"monotonic_ns":1019369077266400,"raw":"{\"market\":\"0x28a45972fccdaf0fba75dacc59725521035e177d09dd92174f9f52740bccb025\", \"price_changes\":[{\"asset_id\":\"114356653315647913247200886351065428002113119844334520181865067698979836634569\", \"price\":\"0.05\", \"size\":\"5588\", \"side\":\"BUY\", \"hash\":\"6eb0c74395c54b6e68630b2d7e5ad69d29a8d6a0\", \"best_bid\":\"0.13\", \"best_ask\":\"0.14\"}, {\"asset_id\":\"61819828071723399190623735325323968706432622380635304641786792960078828866875\", \"price\":\"0.95\", \"size\":\"5588\", \"side\":\"SELL\", \"hash\":\"24ef919ab2d0843fbb24896b7bd5ae7d4a698a5b\", \"best_bid\":\"0.86\", \"best_ask\":\"0.87\"}], \"timestamp\":\"1789987928226\", \"event_type\":\"price_change\"}","raw_base64":null}
{"received_ms":1789987928266,"monotonic_ns":1019369096313000,"raw":"{\"market\":\"0x28a45972fccdaf0fba75dacc59725521035e177d09dd92174f9f52740bccb025\", \"price_changes\":[{\"asset_id\":\"61819828071723399190623735325323968706432622380635304641786792960078828866875\", \"price\":\"0.01\", \"size\":\"1496.91\", \"side\":\"BUY\", \"hash\":\"1e08e7f1945e497c54b3d2fd5e24ada02be6edff\", \"best_bid\":\"0.86\", \"best_ask\":\"0.87\"}, {\"asset_id\":\"114356653315647913247200886351065428002113119844334520181865067698979836634569\", \"price\":\"0.99\", \"size\":\"1496.91\", \"side\":\"SELL\", \"hash\":\"b00a6fca05b72af0376a8a44f41cabffdaf79a46\", \"best_bid\":\"0.13\", \"best_ask\":\"0.14\"}], \"timestamp\":\"1789987928238\", \"event_type\":\"price_change\"}","raw_base64":null}
{"received_ms":1789987928266,"monotonic_ns":1019369096373100,"raw":"{\"market\":\"0x28a45972fccdaf0fba75dacc59725521035e177d09dd92174f9f52740bccb025\", \"price_changes\":[{\"asset_id\":\"114356653315647913247200886351065428002113119844334520181865067698979836634569\", \"price\":\"0.11\", \"size\":\"336.1\", \"side\":\"BUY\", \"hash\":\"0665cfdbab36a8d8e28b49b243c1d61ac4f4c54f\", \"best_bid\":\"0.13\", \"best_ask\":\"0.14\"}, {\"asset_id\":\"61819828071723399190623735325323968706432622380635304641786792960078828866875\", \"price\":\"0.89\", \"size\":\"336.1\", \"side\":\"SELL\", \"hash\":\"c653278c9bc7c30e989ddf5137f2fa2a9a0d9efc\", \"best_bid\":\"0.86\", \"best_ask\":\"0.87\"}], \"timestamp\":\"1789987928239\", \"event_type\":\"price_change\"}","raw_base64":null}
{"received_ms":1789987928280,"monotonic_ns":1019369111034200,"raw":"{\"market\":\"0x28a45972fccdaf0fba75dacc59725521035e177d09dd92174f9f52740bccb025\", \"price_changes\":[{\"asset_id\":\"114356653315647913247200886351065428002113119844334520181865067698979836634569\", \"price\":\"0.07\", \"size\":\"7106.71\", \"side\":\"BUY\", \"hash\":\"90acfe0108a00e677e8f12240662a4102dd053fb\", \"best_bid\":\"0.13\", \"best_ask\":\"0.14\"}, {\"asset_id\":\"61819828071723399190623735325323968706432622380635304641786792960078828866875\", \"price\":\"0.93\", \"size\":\"7106.71\", \"side\":\"SELL\", \"hash\":\"c06fef67e9c89d8f7cd464891bcecbc292600f24\", \"best_bid\":\"0.86\", \"best_ask\":\"0.87\"}], \"timestamp\":\"1789987928244\", \"event_type\":\"price_change\"}","raw_base64":null}
{"received_ms":1789987928280,"monotonic_ns":1019369111084100,"raw":"{\"market\":\"0x28a45972fccdaf0fba75dacc59725521035e177d09dd92174f9f52740bccb025\", \"price_changes\":[{\"asset_id\":\"114356653315647913247200886351065428002113119844334520181865067698979836634569\", \"price\":\"0.07\", \"size\":\"6884.71\", \"side\":\"BUY\", \"hash\":\"abc5fb927541ef890fb9ae37ae9478ef18e98a80\", \"best_bid\":\"0.13\", \"best_ask\":\"0.14\"}, {\"asset_id\":\"61819828071723399190623735325323968706432622380635304641786792960078828866875\", \"price\":\"0.93\", \"size\":\"6884.71\", \"side\":\"SELL\", \"hash\":\"85200df42fc47ed4844e837c9f5f6e9f9c52ccf7\", \"best_bid\":\"0.86\", \"best_ask\":\"0.87\"}], \"timestamp\":\"1789987928245\", \"event_type\":\"price_change\"}","raw_base64":null}
{"received_ms":1789987928281,"monotonic_ns":1019369111444800,"raw":"{\"market\":\"0x28a45972fccdaf0fba75dacc59725521035e177d09dd92174f9f52740bccb025\", \"price_changes\":[{\"asset_id\":\"114356653315647913247200886351065428002113119844334520181865067698979836634569\", \"price\":\"0.07\", \"size\":\"6904.71\", \"side\":\"BUY\", \"hash\":\"0829952bcfdae51bfbcae5b2727bf354eb9c3ef5\", \"best_bid\":\"0.13\", \"best_ask\":\"0.14\"}, {\"asset_id\":\"61819828071723399190623735325323968706432622380635304641786792960078828866875\", \"price\":\"0.93\", \"size\":\"6904.71\", \"side\":\"SELL\", \"hash\":\"f774104558c3453b9dd15ce023c91874e94518a0\", \"best_bid\":\"0.86\", \"best_ask\":\"0.87\"}], \"timestamp\":\"1789987928255\", \"event_type\":\"price_change\"}","raw_base64":null}
{"received_ms":1789987928281,"monotonic_ns":1019369111513700,"raw":"{\"market\":\"0x28a45972fccdaf0fba75dacc59725521035e177d09dd92174f9f52740bccb025\", \"price_changes\":[{\"asset_id\":\"114356653315647913247200886351065428002113119844334520181865067698979836634569\", \"price\":\"0.07\", \"size\":\"7177.71\", \"side\":\"BUY\", \"hash\":\"8d596ef0de071a22162bb80f356211a65ed87bef\", \"best_bid\":\"0.13\", \"best_ask\":\"0.14\"}, {\"asset_id\":\"61819828071723399190623735325323968706432622380635304641786792960078828866875\", \"price\":\"0.93\", \"size\":\"7177.71\", \"side\":\"SELL\", \"hash\":\"d7be59a32b41949c01717e5479543a6f94af9ef1\", \"best_bid\":\"0.86\", \"best_ask\":\"0.87\"}], \"timestamp\":\"1789987928258\", \"event_type\":\"price_change\"}","raw_base64":null}
{"received_ms":1789987928291,"monotonic_ns":1019369122097100,"raw":"{\"market\":\"0x28a45972fccdaf0fba75dacc59725521035e177d09dd92174f9f52740bccb025\", \"price_changes\":[{\"asset_id\":\"114356653315647913247200886351065428002113119844334520181865067698979836634569\", \"price\":\"0.07\", \"size\":\"7157.71\", \"side\":\"BUY\", \"hash\":\"638977d387241b8b16947355653512950e7d0542\", \"best_bid\":\"0.13\", \"best_ask\":\"0.14\"}, {\"asset_id\":\"61819828071723399190623735325323968706432622380635304641786792960078828866875\", \"price\":\"0.93\", \"size\":\"7157.71\", \"side\":\"SELL\", \"hash\":\"12c553511ae903eefae3fafdd3161b6fc10d2c27\", \"best_bid\":\"0.86\", \"best_ask\":\"0.87\"}], \"timestamp\":\"1789987928269\", \"event_type\":\"price_change\"}","raw_base64":null}
{"received_ms":1789987928306,"monotonic_ns":1019369136628900,"raw":"{\"market\":\"0x28a45972fccdaf0fba75dacc59725521035e177d09dd92174f9f52740bccb025\", \"price_changes\":[{\"asset_id\":\"61819828071723399190623735325323968706432622380635304641786792960078828866875\", \"price\":\"0.01\", \"size\":\"1491.91\", \"side\":\"BUY\", \"hash\":\"802f50e1f0f59a249a49b6d8c895f2b8242992da\", \"best_bid\":\"0.86\", \"best_ask\":\"0.87\"}, {\"asset_id\":\"114356653315647913247200886351065428002113119844334520181865067698979836634569\", \"price\":\"0.99\", \"size\":\"1491.91\", \"side\":\"SELL\", \"hash\":\"e89c676f0ac2ce652ea61d5de0723d8c48011219\", \"best_bid\":\"0.13\", \"best_ask\":\"0.14\"}], \"timestamp\":\"1789987928271\", \"event_type\":\"price_change\"}","raw_base64":null}
{"received_ms":1789987928306,"monotonic_ns":1019369136731900,"raw":"{\"market\":\"0x28a45972fccdaf0fba75dacc59725521035e177d09dd92174f9f52740bccb025\", \"price_changes\":[{\"asset_id\":\"114356653315647913247200886351065428002113119844334520181865067698979836634569\", \"price\":\"0.11\", \"size\":\"316.1\", \"side\":\"BUY\", \"hash\":\"694dd316af9d1c8fed7ef4afeb21bd11ce7c85dd\", \"best_bid\":\"0.13\", \"best_ask\":\"0.14\"}, {\"asset_id\":\"61819828071723399190623735325323968706432622380635304641786792960078828866875\", \"price\":\"0.89\", \"size\":\"316.1\", \"side\":\"SELL\", \"hash\":\"191fe284012080a62959d856108e525273c7911b\", \"best_bid\":\"0.86\", \"best_ask\":\"0.87\"}], \"timestamp\":\"1789987928279\", \"event_type\":\"price_change\"}","raw_base64":null}
{"received_ms":1789987928307,"monotonic_ns":1019369138033200,"raw":"{\"market\":\"0x28a45972fccdaf0fba75dacc59725521035e177d09dd92174f9f52740bccb025\", \"price_changes\":[{\"asset_id\":\"61819828071723399190623735325323968706432622380635304641786792960078828866875\", \"price\":\"0.77\", \"size\":\"587.49\", \"side\":\"BUY\", \"hash\":\"877168e3246487e78599a43427375804803dffbe\", \"best_bid\":\"0.86\", \"best_ask\":\"0.87\"}, {\"asset_id\":\"114356653315647913247200886351065428002113119844334520181865067698979836634569\", \"price\":\"0.23\", \"size\":\"587.49\", \"side\":\"SELL\", \"hash\":\"5cd6e34983aa0d2638dc9d5c8ae59ce41ef3b132\", \"best_bid\":\"0.13\", \"best_ask\":\"0.14\"}], \"timestamp\":\"1789987928284\", \"event_type\":\"price_change\"}","raw_base64":null}
{"received_ms":1789987928307,"monotonic_ns":1019369138099200,"raw":"{\"market\":\"0x28a45972fccdaf0fba75dacc59725521035e177d09dd92174f9f52740bccb025\", \"price_changes\":[{\"asset_id\":\"61819828071723399190623735325323968706432622380635304641786792960078828866875\", \"price\":\"0.79\", \"size\":\"487\", \"side\":\"BUY\", \"hash\":\"ff199e0e9def0473d4e1d0a0891d76eb7d3d082b\", \"best_bid\":\"0.86\", \"best_ask\":\"0.87\"}, {\"asset_id\":\"114356653315647913247200886351065428002113119844334520181865067698979836634569\", \"price\":\"0.21\", \"size\":\"487\", \"side\":\"SELL\", \"hash\":\"452a861bf6b581bba00a88baebd6219177cc646e\", \"best_bid\":\"0.13\", \"best_ask\":\"0.14\"}], \"timestamp\":\"1789987928285\", \"event_type\":\"price_change\"}","raw_base64":null}
{"received_ms":1789987928322,"monotonic_ns":1019369152349200,"raw":"{\"market\":\"0x28a45972fccdaf0fba75dacc59725521035e177d09dd92174f9f52740bccb025\", \"price_changes\":[{\"asset_id\":\"61819828071723399190623735325323968706432622380635304641786792960078828866875\", \"price\":\"0.77\", \"size\":\"547.49\", \"side\":\"BUY\", \"hash\":\"398c435dce11f24d5cf3e2e230c35ccf03848e68\", \"best_bid\":\"0.86\", \"best_ask\":\"0.87\"}, {\"asset_id\":\"114356653315647913247200886351065428002113119844334520181865067698979836634569\", \"price\":\"0.23\", \"size\":\"547.49\", \"side\":\"SELL\", \"hash\":\"982b5f3280db54cc6936e8ab95b9dc1b8d9d1c59\", \"best_bid\":\"0.13\", \"best_ask\":\"0.14\"}], \"timestamp\":\"1789987928286\", \"event_type\":\"price_change\"}","raw_base64":null}
{"received_ms":1789987928322,"monotonic_ns":1019369152423900,"raw":"{\"market\":\"0x28a45972fccdaf0fba75dacc59725521035e177d09dd92174f9f52740bccb025\", \"price_changes\":[{\"asset_id\":\"61819828071723399190623735325323968706432622380635304641786792960078828866875\", \"price\":\"0.79\", \"size\":\"427\", \"side\":\"BUY\", \"hash\":\"398c435dce11f24d5cf3e2e230c35ccf03848e68\", \"best_bid\":\"0.86\", \"best_ask\":\"0.87\"}, {\"asset_id\":\"114356653315647913247200886351065428002113119844334520181865067698979836634569\", \"price\":\"0.21\", \"size\":\"427\", \"side\":\"SELL\", \"hash\":\"982b5f3280db54cc6936e8ab95b9dc1b8d9d1c59\", \"best_bid\":\"0.13\", \"best_ask\":\"0.14\"}], \"timestamp\":\"1789987928286\", \"event_type\":\"price_change\"}","raw_base64":null}
{"received_ms":1789987928322,"monotonic_ns":1019369152470900,"raw":"{\"market\":\"0x28a45972fccdaf0fba75dacc59725521035e177d09dd92174f9f52740bccb025\", \"price_changes\":[{\"asset_id\":\"114356653315647913247200886351065428002113119844334520181865067698979836634569\", \"price\":\"0.1\", \"size\":\"580\", \"side\":\"BUY\", \"hash\":\"0ca3a4d6575ebd3e734ae7681d6327fc723dbfd4\", \"best_bid\":\"0.13\", \"best_ask\":\"0.14\"}, {\"asset_id\":\"61819828071723399190623735325323968706432622380635304641786792960078828866875\", \"price\":\"0.9\", \"size\":\"580\", \"side\":\"SELL\", \"hash\":\"2e88fcc8f76a0cbb5aafa5979e8cea338420d651\", \"best_bid\":\"0.86\", \"best_ask\":\"0.87\"}], \"timestamp\":\"1789987928289\", \"event_type\":\"price_change\"}","raw_base64":null}
{"received_ms":1789987928322,"monotonic_ns":1019369152506800,"raw":"{\"market\":\"0x28a45972fccdaf0fba75dacc59725521035e177d09dd92174f9f52740bccb025\", \"price_changes\":[{\"asset_id\":\"114356653315647913247200886351065428002113119844334520181865067698979836634569\", \"price\":\"0.07\", \"size\":\"7200.71\", \"side\":\"BUY\", \"hash\":\"a0c4380fccc66adf3b134b3932fde03b89ed7975\", \"best_bid\":\"0.13\", \"best_ask\":\"0.14\"}, {\"asset_id\":\"61819828071723399190623735325323968706432622380635304641786792960078828866875\", \"price\":\"0.93\", \"size\":\"7200.71\", \"side\":\"SELL\", \"hash\":\"b2d7db8a16630d34c7e63b4b6d5818a710183460\", \"best_bid\":\"0.86\", \"best_ask\":\"0.87\"}], \"timestamp\":\"1789987928289\", \"event_type\":\"price_change\"}","raw_base64":null}
{"received_ms":1789987928322,"monotonic_ns":1019369152540100,"raw":"{\"market\":\"0x28a45972fccdaf0fba75dacc59725521035e177d09dd92174f9f52740bccb025\", \"price_changes\":[{\"asset_id\":\"61819828071723399190623735325323968706432622380635304641786792960078828866875\", \"price\":\"0.85\", \"size\":\"2756.52\", \"side\":\"BUY\", \"hash\":\"d6979583314abb5e8315751877989170495a04b8\", \"best_bid\":\"0.86\", \"best_ask\":\"0.87\"}, {\"asset_id\":\"114356653315647913247200886351065428002113119844334520181865067698979836634569\", \"price\":\"0.15\", \"size\":\"2756.52\", \"side\":\"SELL\", \"hash\":\"f28bfa933300d4a8ce6488334a94b8b4aecc2d4d\", \"best_bid\":\"0.13\", \"best_ask\":\"0.14\"}], \"timestamp\":\"1789987928291\", \"event_type\":\"price_change\"}","raw_base64":null}
{"received_ms":1789987928322,"monotonic_ns":1019369152572400,"raw":"{\"market\":\"0x28a45972fccdaf0fba75dacc59725521035e177d09dd92174f9f52740bccb025\", \"price_changes\":[{\"asset_id\":\"61819828071723399190623735325323968706432622380635304641786792960078828866875\", \"price\":\"0.86\", \"size\":\"3470\", \"side\":\"BUY\", \"hash\":\"b7a2b2f4d754e307f7576051013bd7bf5e6dd2cb\", \"best_bid\":\"0.86\", \"best_ask\":\"0.87\"}, {\"asset_id\":\"114356653315647913247200886351065428002113119844334520181865067698979836634569\", \"price\":\"0.14\", \"size\":\"3470\", \"side\":\"SELL\", \"hash\":\"075e7bb419758409a67baddc4a8fb2a8d534f806\", \"best_bid\":\"0.13\", \"best_ask\":\"0.14\"}], \"timestamp\":\"1789987928291\", \"event_type\":\"price_change\"}","raw_base64":null}
{"received_ms":1789987928322,"monotonic_ns":1019369152604700,"raw":"{\"market\":\"0x28a45972fccdaf0fba75dacc59725521035e177d09dd92174f9f52740bccb025\", \"price_changes\":[{\"asset_id\":\"114356653315647913247200886351065428002113119844334520181865067698979836634569\", \"price\":\"0.06\", \"size\":\"6051.67\", \"side\":\"BUY\", \"hash\":\"3179414607f8f72d0798cb15d3f05e3263cba33e\", \"best_bid\":\"0.13\", \"best_ask\":\"0.14\"}, {\"asset_id\":\"61819828071723399190623735325323968706432622380635304641786792960078828866875\", \"price\":\"0.94\", \"size\":\"6051.67\", \"side\":\"SELL\", \"hash\":\"2c7c1f3aff2c7684f9e4f6eb2dea6b3c7927d190\", \"best_bid\":\"0.86\", \"best_ask\":\"0.87\"}], \"timestamp\":\"1789987928293\", \"event_type\":\"price_change\"}","raw_base64":null}
{"received_ms":1789987928322,"monotonic_ns":1019369152635800,"raw":"{\"market\":\"0x28a45972fccdaf0fba75dacc59725521035e177d09dd92174f9f52740bccb025\", \"price_changes\":[{\"asset_id\":\"114356653315647913247200886351065428002113119844334520181865067698979836634569\", \"price\":\"0.07\", \"size\":\"7220.71\", \"side\":\"BUY\", \"hash\":\"aa881d1f54fc244e24e365cf6103903c78e71a14\", \"best_bid\":\"0.13\", \"best_ask\":\"0.14\"}, {\"asset_id\":\"61819828071723399190623735325323968706432622380635304641786792960078828866875\", \"price\":\"0.93\", \"size\":\"7220.71\", \"side\":\"SELL\", \"hash\":\"d4d7047fd4de43c2a89d721948309ec034329bdd\", \"best_bid\":\"0.86\", \"best_ask\":\"0.87\"}], \"timestamp\":\"1789987928295\", \"event_type\":\"price_change\"}","raw_base64":null}
{"received_ms":1789987928330,"monotonic_ns":1019369160603700,"raw":"{\"market\":\"0x28a45972fccdaf0fba75dacc59725521035e177d09dd92174f9f52740bccb025\", \"price_changes\":[{\"asset_id\":\"114356653315647913247200886351065428002113119844334520181865067698979836634569\", \"price\":\"0.05\", \"size\":\"5608\", \"side\":\"BUY\", \"hash\":\"8424d0e9a70a40eeb69706d6e29747a032ea8921\", \"best_bid\":\"0.13\", \"best_ask\":\"0.14\"}, {\"asset_id\":\"61819828071723399190623735325323968706432622380635304641786792960078828866875\", \"price\":\"0.95\", \"size\":\"5608\", \"side\":\"SELL\", \"hash\":\"5d0f977a7cd79528a023d10f0199532c968d52a3\", \"best_bid\":\"0.86\", \"best_ask\":\"0.87\"}], \"timestamp\":\"1789987928309\", \"event_type\":\"price_change\"}","raw_base64":null}
{"received_ms":1789987928330,"monotonic_ns":1019369160667700,"raw":"{\"market\":\"0x28a45972fccdaf0fba75dacc59725521035e177d09dd92174f9f52740bccb025\", \"price_changes\":[{\"asset_id\":\"114356653315647913247200886351065428002113119844334520181865067698979836634569\", \"price\":\"0.07\", \"size\":\"5798.71\", \"side\":\"BUY\", \"hash\":\"69a1b8ced13a4fc82de663efbd2afc924e855c52\", \"best_bid\":\"0.13\", \"best_ask\":\"0.14\"}, {\"asset_id\":\"61819828071723399190623735325323968706432622380635304641786792960078828866875\", \"price\":\"0.93\", \"size\":\"5798.71\", \"side\":\"SELL\", \"hash\":\"9f610c2e5dfb89c98c2ac7c3725280563b8d7dcc\", \"best_bid\":\"0.86\", \"best_ask\":\"0.87\"}], \"timestamp\":\"1789987928310\", \"event_type\":\"price_change\"}","raw_base64":null}
{"received_ms":1789987928330,"monotonic_ns":1019369160939200,"raw":"{\"market\":\"0x28a45972fccdaf0fba75dacc59725521035e177d09dd92174f9f52740bccb025\", \"price_changes\":[{\"asset_id\":\"114356653315647913247200886351065428002113119844334520181865067698979836634569\", \"price\":\"0.07\", \"size\":\"5525.71\", \"side\":\"BUY\", \"hash\":\"212fa7a0b82e94cf89d49e970362a4f77fa3bd6b\", \"best_bid\":\"0.13\", \"best_ask\":\"0.14\"}, {\"asset_id\":\"61819828071723399190623735325323968706432622380635304641786792960078828866875\", \"price\":\"0.93\", \"size\":\"5525.71\", \"side\":\"SELL\", \"hash\":\"fac8f8ceb9651315198b38aa69d68b0dab5fa627\", \"best_bid\":\"0.86\", \"best_ask\":\"0.87\"}], \"timestamp\":\"1789987928310\", \"event_type\":\"price_change\"}","raw_base64":null}
{"received_ms":1789987928338,"monotonic_ns":1019369168354700,"raw":"{\"market\":\"0x28a45972fccdaf0fba75dacc59725521035e177d09dd92174f9f52740bccb025\", \"price_changes\":[{\"asset_id\":\"114356653315647913247200886351065428002113119844334520181865067698979836634569\", \"price\":\"0.07\", \"size\":\"5482.71\", \"side\":\"BUY\", \"hash\":\"720914f66fd1566cf6795273e4fc14af81978596\", \"best_bid\":\"0.13\", \"best_ask\":\"0.14\"}, {\"asset_id\":\"61819828071723399190623735325323968706432622380635304641786792960078828866875\", \"price\":\"0.93\", \"size\":\"5482.71\", \"side\":\"SELL\", \"hash\":\"859a911415478fb5a0af58a833e1b39e00b48625\", \"best_bid\":\"0.86\", \"best_ask\":\"0.87\"}], \"timestamp\":\"1789987928318\", \"event_type\":\"price_change\"}","raw_base64":null}
{"received_ms":1789987928338,"monotonic_ns":1019369168726300,"raw":"{\"market\":\"0x28a45972fccdaf0fba75dacc59725521035e177d09dd92174f9f52740bccb025\", \"price_changes\":[{\"asset_id\":\"61819828071723399190623735325323968706432622380635304641786792960078828866875\", \"price\":\"0.73\", \"size\":\"504\", \"side\":\"BUY\", \"hash\":\"fc35db27e445f7f26c72b4034147696d382f9534\", \"best_bid\":\"0.86\", \"best_ask\":\"0.87\"}, {\"asset_id\":\"114356653315647913247200886351065428002113119844334520181865067698979836634569\", \"price\":\"0.27\", \"size\":\"504\", \"side\":\"SELL\", \"hash\":\"da3a5d31635e48134f3e5fa11ed5ff8b83ed5806\", \"best_bid\":\"0.13\", \"best_ask\":\"0.14\"}], \"timestamp\":\"1789987928318\", \"event_type\":\"price_change\"}","raw_base64":null}
{"received_ms":1789987928340,"monotonic_ns":1019369170748000,"raw":"{\"market\":\"0x28a45972fccdaf0fba75dacc59725521035e177d09dd92174f9f52740bccb025\", \"price_changes\":[{\"asset_id\":\"61819828071723399190623735325323968706432622380635304641786792960078828866875\", \"price\":\"0.73\", \"size\":\"404\", \"side\":\"BUY\", \"hash\":\"e299811bcdcf7007ab5392a3273a1ace574bc37d\", \"best_bid\":\"0.86\", \"best_ask\":\"0.87\"}, {\"asset_id\":\"114356653315647913247200886351065428002113119844334520181865067698979836634569\", \"price\":\"0.27\", \"size\":\"404\", \"side\":\"SELL\", \"hash\":\"d17ed68316be18bb379757010a78e77892e31ec4\", \"best_bid\":\"0.13\", \"best_ask\":\"0.14\"}], \"timestamp\":\"1789987928320\", \"event_type\":\"price_change\"}","raw_base64":null}
{"received_ms":1789987928348,"monotonic_ns":1019369179273300,"raw":"{\"market\":\"0x28a45972fccdaf0fba75dacc59725521035e177d09dd92174f9f52740bccb025\", \"price_changes\":[{\"asset_id\":\"114356653315647913247200886351065428002113119844334520181865067698979836634569\", \"price\":\"0.06\", \"size\":\"5971.67\", \"side\":\"BUY\", \"hash\":\"ada6469d7a161aa6cd93cdb51d24818aec4f77ef\", \"best_bid\":\"0.13\", \"best_ask\":\"0.14\"}, {\"asset_id\":\"61819828071723399190623735325323968706432622380635304641786792960078828866875\", \"price\":\"0.94\", \"size\":\"5971.67\", \"side\":\"SELL\", \"hash\":\"0874ffd5ea26fc38479487cc4625e3927004daa4\", \"best_bid\":\"0.86\", \"best_ask\":\"0.87\"}], \"timestamp\":\"1789987928326\", \"event_type\":\"price_change\"}","raw_base64":null}
{"received_ms":1789987928353,"monotonic_ns":1019369184157000,"raw":"{\"market\":\"0x28a45972fccdaf0fba75dacc59725521035e177d09dd92174f9f52740bccb025\", \"price_changes\":[{\"asset_id\":\"61819828071723399190623735325323968706432622380635304641786792960078828866875\", \"price\":\"0.86\", \"size\":\"3407\", \"side\":\"BUY\", \"hash\":\"e731b39d277d5b636e1343a50c9eb61357164ce8\", \"best_bid\":\"0.86\", \"best_ask\":\"0.87\"}, {\"asset_id\":\"114356653315647913247200886351065428002113119844334520181865067698979836634569\", \"price\":\"0.14\", \"size\":\"3407\", \"side\":\"SELL\", \"hash\":\"8a66c7331a191c295f13d8dad9a19cd1ece97c54\", \"best_bid\":\"0.13\", \"best_ask\":\"0.14\"}], \"timestamp\":\"1789987928332\", \"event_type\":\"price_change\"}","raw_base64":null}
{"received_ms":1789987928356,"monotonic_ns":1019369186939700,"raw":"{\"market\":\"0x28a45972fccdaf0fba75dacc59725521035e177d09dd92174f9f52740bccb025\", \"price_changes\":[{\"asset_id\":\"61819828071723399190623735325323968706432622380635304641786792960078828866875\", \"price\":\"0.86\", \"size\":\"1751\", \"side\":\"BUY\", \"hash\":\"6a7fc2da8133a07557f7f3891f8da78a9a977fac\", \"best_bid\":\"0.86\", \"best_ask\":\"0.87\"}, {\"asset_id\":\"114356653315647913247200886351065428002113119844334520181865067698979836634569\", \"price\":\"0.14\", \"size\":\"1751\", \"side\":\"SELL\", \"hash\":\"f29c1f57490a43a92db622da6d63c385b710c70d\", \"best_bid\":\"0.13\", \"best_ask\":\"0.14\"}], \"timestamp\":\"1789987928334\", \"event_type\":\"price_change\"}","raw_base64":null}
{"received_ms":1789987928356,"monotonic_ns":1019369186996600,"raw":"{\"market\":\"0x28a45972fccdaf0fba75dacc59725521035e177d09dd92174f9f52740bccb025\", \"price_changes\":[{\"asset_id\":\"114356653315647913247200886351065428002113119844334520181865067698979836634569\", \"price\":\"0.06\", \"size\":\"5163.67\", \"side\":\"BUY\", \"hash\":\"ff3235b849d2db23742b6ab9370cfef8b9404de7\", \"best_bid\":\"0.13\", \"best_ask\":\"0.14\"}, {\"asset_id\":\"61819828071723399190623735325323968706432622380635304641786792960078828866875\", \"price\":\"0.94\", \"size\":\"5163.67\", \"side\":\"SELL\", \"hash\":\"7afa3592fa39cfc32a3ae8792b4514956cf3424f\", \"best_bid\":\"0.86\", \"best_ask\":\"0.87\"}], \"timestamp\":\"1789987928334\", \"event_type\":\"price_change\"}","raw_base64":null}
{"received_ms":1789987928359,"monotonic_ns":1019369189448700,"raw":"{\"market\":\"0x28a45972fccdaf0fba75dacc59725521035e177d09dd92174f9f52740bccb025\", \"price_changes\":[{\"asset_id\":\"61819828071723399190623735325323968706432622380635304641786792960078828866875\", \"price\":\"0.84\", \"size\":\"2620\", \"side\":\"BUY\", \"hash\":\"8873c20c2466b9fb3d921f2916bbdea13c313317\", \"best_bid\":\"0.86\", \"best_ask\":\"0.87\"}, {\"asset_id\":\"114356653315647913247200886351065428002113119844334520181865067698979836634569\", \"price\":\"0.16\", \"size\":\"2620\", \"side\":\"SELL\", \"hash\":\"61ab88c6d81dcfac4b7808e9da7245fe77fd60a1\", \"best_bid\":\"0.13\", \"best_ask\":\"0.14\"}], \"timestamp\":\"1789987928336\", \"event_type\":\"price_change\"}","raw_base64":null}
{"received_ms":1789987928359,"monotonic_ns":1019369189534600,"raw":"{\"market\":\"0x28a45972fccdaf0fba75dacc59725521035e177d09dd92174f9f52740bccb025\", \"price_changes\":[{\"asset_id\":\"61819828071723399190623735325323968706432622380635304641786792960078828866875\", \"price\":\"0.86\", \"size\":\"1851\", \"side\":\"BUY\", \"hash\":\"ea07b82e425c07a290165d5fa5fe7752cf15d4ee\", \"best_bid\":\"0.86\", \"best_ask\":\"0.87\"}, {\"asset_id\":\"114356653315647913247200886351065428002113119844334520181865067698979836634569\", \"price\":\"0.14\", \"size\":\"1851\", \"side\":\"SELL\", \"hash\":\"a40d26d1affda10ade39c4256fd0496ffaac1ad8\", \"best_bid\":\"0.13\", \"best_ask\":\"0.14\"}], \"timestamp\":\"1789987928337\", \"event_type\":\"price_change\"}","raw_base64":null}
{"received_ms":1789987928376,"monotonic_ns":1019369207209600,"raw":"{\"market\":\"0x28a45972fccdaf0fba75dacc59725521035e177d09dd92174f9f52740bccb025\", \"price_changes\":[{\"asset_id\":\"61819828071723399190623735325323968706432622380635304641786792960078828866875\", \"price\":\"0.77\", \"size\":\"587.49\", \"side\":\"BUY\", \"hash\":\"c89cd75983cd883dc4b055f44d055659fd1fb365\", \"best_bid\":\"0.86\", \"best_ask\":\"0.87\"}, {\"asset_id\":\"114356653315647913247200886351065428002113119844334520181865067698979836634569\", \"price\":\"0.23\", \"size\":\"587.49\", \"side\":\"SELL\", \"hash\":\"6773497f12b6fb365a929a475d89c3f945a5526e\", \"best_bid\":\"0.13\", \"best_ask\":\"0.14\"}], \"timestamp\":\"1789987928357\", \"event_type\":\"price_change\"}","raw_base64":null}
{"received_ms":1789987928377,"monotonic_ns":1019369207674400,"raw":"{\"market\":\"0x28a45972fccdaf0fba75dacc59725521035e177d09dd92174f9f52740bccb025\", \"price_changes\":[{\"asset_id\":\"61819828071723399190623735325323968706432622380635304641786792960078828866875\", \"price\":\"0.77\", \"size\":\"547.49\", \"side\":\"BUY\", \"hash\":\"ddb54d21cf383cf13fb75436ebf7385b648632f2\", \"best_bid\":\"0.86\", \"best_ask\":\"0.87\"}, {\"asset_id\":\"114356653315647913247200886351065428002113119844334520181865067698979836634569\", \"price\":\"0.23\", \"size\":\"547.49\", \"side\":\"SELL\", \"hash\":\"fae1d340bd90a74983115ed9a6141d3e00081aab\", \"best_bid\":\"0.13\", \"best_ask\":\"0.14\"}], \"timestamp\":\"1789987928357\", \"event_type\":\"price_change\"}","raw_base64":null}
{"received_ms":1789987928384,"monotonic_ns":1019369214410900,"raw":"{\"market\":\"0x28a45972fccdaf0fba75dacc59725521035e177d09dd92174f9f52740bccb025\", \"price_changes\":[{\"asset_id\":\"114356653315647913247200886351065428002113119844334520181865067698979836634569\", \"price\":\"0.13\", \"size\":\"280\", \"side\":\"BUY\", \"hash\":\"0dc78b506323334e1c7929f58cda16550075dcca\", \"best_bid\":\"0.13\", \"best_ask\":\"0.14\"}, {\"asset_id\":\"61819828071723399190623735325323968706432622380635304641786792960078828866875\", \"price\":\"0.87\", \"size\":\"280\", \"side\":\"SELL\", \"hash\":\"ff7c1bf2c3b6f87f0587079ed6442d56bde1e461\", \"best_bid\":\"0.86\", \"best_ask\":\"0.87\"}], \"timestamp\":\"1789987928363\", \"event_type\":\"price_change\"}","raw_base64":null}
{"received_ms":1789987928384,"monotonic_ns":1019369214470100,"raw":"{\"market\":\"0x28a45972fccdaf0fba75dacc59725521035e177d09dd92174f9f52740bccb025\", \"price_changes\":[{\"asset_id\":\"114356653315647913247200886351065428002113119844334520181865067698979836634569\", \"price\":\"0.05\", \"size\":\"5615\", \"side\":\"BUY\", \"hash\":\"778d0ba510a7f635461d2e97bf6d38b53847dccd\", \"best_bid\":\"0.13\", \"best_ask\":\"0.14\"}, {\"asset_id\":\"61819828071723399190623735325323968706432622380635304641786792960078828866875\", \"price\":\"0.95\", \"size\":\"5615\", \"side\":\"SELL\", \"hash\":\"e86b8436bff378d2c019cf78e685df691f966e09\", \"best_bid\":\"0.86\", \"best_ask\":\"0.87\"}], \"timestamp\":\"1789987928364\", \"event_type\":\"price_change\"}","raw_base64":null}
{"received_ms":1789987928385,"monotonic_ns":1019369215343100,"raw":"{\"market\":\"0x28a45972fccdaf0fba75dacc59725521035e177d09dd92174f9f52740bccb025\", \"price_changes\":[{\"asset_id\":\"114356653315647913247200886351065428002113119844334520181865067698979836634569\", \"price\":\"0.07\", \"size\":\"6669.71\", \"side\":\"BUY\", \"hash\":\"958088270c503eb47ec1db8de88fb768113187f8\", \"best_bid\":\"0.13\", \"best_ask\":\"0.14\"}, {\"asset_id\":\"61819828071723399190623735325323968706432622380635304641786792960078828866875\", \"price\":\"0.93\", \"size\":\"6669.71\", \"side\":\"SELL\", \"hash\":\"62e00e67809257188beb007aa4fc914b49c66a60\", \"best_bid\":\"0.86\", \"best_ask\":\"0.87\"}], \"timestamp\":\"1789987928364\", \"event_type\":\"price_change\"}","raw_base64":null}
{"received_ms":1789987928385,"monotonic_ns":1019369215943300,"raw":"{\"market\":\"0x28a45972fccdaf0fba75dacc59725521035e177d09dd92174f9f52740bccb025\", \"price_changes\":[{\"asset_id\":\"114356653315647913247200886351065428002113119844334520181865067698979836634569\", \"price\":\"0.06\", \"size\":\"5278.67\", \"side\":\"BUY\", \"hash\":\"3492eda56f171344a1a17acc3fd4bdaba0007b6d\", \"best_bid\":\"0.13\", \"best_ask\":\"0.14\"}, {\"asset_id\":\"61819828071723399190623735325323968706432622380635304641786792960078828866875\", \"price\":\"0.94\", \"size\":\"5278.67\", \"side\":\"SELL\", \"hash\":\"76ea841d6767658197c49b6a80f4bd599e12d7b2\", \"best_bid\":\"0.86\", \"best_ask\":\"0.87\"}], \"timestamp\":\"1789987928365\", \"event_type\":\"price_change\"}","raw_base64":null}
{"received_ms":1789987928387,"monotonic_ns":1019369217614300,"raw":"{\"market\":\"0x28a45972fccdaf0fba75dacc59725521035e177d09dd92174f9f52740bccb025\", \"price_changes\":[{\"asset_id\":\"61819828071723399190623735325323968706432622380635304641786792960078828866875\", \"price\":\"0.91\", \"size\":\"610.12\", \"side\":\"SELL\", \"hash\":\"eb8477c7de8df01f80319536545a315b674b47cd\", \"best_bid\":\"0.86\", \"best_ask\":\"0.87\"}, {\"asset_id\":\"114356653315647913247200886351065428002113119844334520181865067698979836634569\", \"price\":\"0.09\", \"size\":\"610.12\", \"side\":\"BUY\", \"hash\":\"584fdc4b68c8247fdd2c07cc9a62ccebedc52725\", \"best_bid\":\"0.13\", \"best_ask\":\"0.14\"}], \"timestamp\":\"1789987928367\", \"event_type\":\"price_change\"}","raw_base64":null}
{"received_ms":1789987928400,"monotonic_ns":1019369231059300,"raw":"{\"market\":\"0x28a45972fccdaf0fba75dacc59725521035e177d09dd92174f9f52740bccb025\", \"price_changes\":[{\"asset_id\":\"61819828071723399190623735325323968706432622380635304641786792960078828866875\", \"price\":\"0.92\", \"size\":\"694.5\", \"side\":\"SELL\", \"hash\":\"d94472c06e0f4e69f0b3d2c8e11d9a724a737328\", \"best_bid\":\"0.86\", \"best_ask\":\"0.87\"}, {\"asset_id\":\"114356653315647913247200886351065428002113119844334520181865067698979836634569\", \"price\":\"0.08\", \"size\":\"694.5\", \"side\":\"BUY\", \"hash\":\"cc6738fc0bea626129e2fe3446b4160661131dfc\", \"best_bid\":\"0.13\", \"best_ask\":\"0.14\"}], \"timestamp\":\"1789987928379\", \"event_type\":\"price_change\"}","raw_base64":null}
{"received_ms":1789987928410,"monotonic_ns":1019369241197600,"raw":"{\"market\":\"0x28a45972fccdaf0fba75dacc59725521035e177d09dd92174f9f52740bccb025\", \"price_changes\":[{\"asset_id\":\"61819828071723399190623735325323968706432622380635304641786792960078828866875\", \"price\":\"0.73\", \"size\":\"504\", \"side\":\"BUY\", \"hash\":\"ca1108c865c5eb5d4645d5b4189c78d482b411e6\", \"best_bid\":\"0.86\", \"best_ask\":\"0.87\"}, {\"asset_id\":\"114356653315647913247200886351065428002113119844334520181865067698979836634569\", \"price\":\"0.27\", \"size\":\"504\", \"side\":\"SELL\", \"hash\":\"1424df41cda4bf8f0c12e065a965f2225e4d6d95\", \"best_bid\":\"0.13\", \"best_ask\":\"0.14\"}], \"timestamp\":\"1789987928388\", \"event_type\":\"price_change\"}","raw_base64":null}
{"received_ms":1789987928414,"monotonic_ns":1019369244966100,"raw":"{\"market\":\"0x28a45972fccdaf0fba75dacc59725521035e177d09dd92174f9f52740bccb025\", \"price_changes\":[{\"asset_id\":\"61819828071723399190623735325323968706432622380635304641786792960078828866875\", \"price\":\"0.73\", \"size\":\"404\", \"side\":\"BUY\", \"hash\":\"81e00d639de3f665471d3b0191b71f8a40d16834\", \"best_bid\":\"0.86\", \"best_ask\":\"0.87\"}, {\"asset_id\":\"114356653315647913247200886351065428002113119844334520181865067698979836634569\", \"price\":\"0.27\", \"size\":\"404\", \"side\":\"SELL\", \"hash\":\"76fa4da665be9a4c7036e552439382b1216dbd78\", \"best_bid\":\"0.13\", \"best_ask\":\"0.14\"}], \"timestamp\":\"1789987928392\", \"event_type\":\"price_change\"}","raw_base64":null}
{"received_ms":1789987928414,"monotonic_ns":1019369245020800,"raw":"{\"market\":\"0x28a45972fccdaf0fba75dacc59725521035e177d09dd92174f9f52740bccb025\", \"price_changes\":[{\"asset_id\":\"114356653315647913247200886351065428002113119844334520181865067698979836634569\", \"price\":\"0.07\", \"size\":\"5482.71\", \"side\":\"BUY\", \"hash\":\"7c490ab5648735f61dc24103ba2508dc0b616a4a\", \"best_bid\":\"0.13\", \"best_ask\":\"0.14\"}, {\"asset_id\":\"61819828071723399190623735325323968706432622380635304641786792960078828866875\", \"price\":\"0.93\", \"size\":\"5482.71\", \"side\":\"SELL\", \"hash\":\"339c44480611b2f02b49bfc9c9eb82e194151876\", \"best_bid\":\"0.86\", \"best_ask\":\"0.87\"}], \"timestamp\":\"1789987928393\", \"event_type\":\"price_change\"}","raw_base64":null}
{"received_ms":1789987928418,"monotonic_ns":1019369248467000,"raw":"{\"market\":\"0x28a45972fccdaf0fba75dacc59725521035e177d09dd92174f9f52740bccb025\", \"price_changes\":[{\"asset_id\":\"61819828071723399190623735325323968706432622380635304641786792960078828866875\", \"price\":\"0.85\", \"size\":\"2857.52\", \"side\":\"BUY\", \"hash\":\"34e25707e4d71fe0a39d67c67936250d8a19c48f\", \"best_bid\":\"0.86\", \"best_ask\":\"0.87\"}, {\"asset_id\":\"114356653315647913247200886351065428002113119844334520181865067698979836634569\", \"price\":\"0.15\", \"size\":\"2857.52\", \"side\":\"SELL\", \"hash\":\"f28c415e8673eac24a4add56b06bc0e43258b2c9\", \"best_bid\":\"0.13\", \"best_ask\":\"0.14\"}], \"timestamp\":\"1789987928395\", \"event_type\":\"price_change\"}","raw_base64":null}
{"received_ms":1789987928418,"monotonic_ns":1019369248519800,"raw":"{\"market\":\"0x28a45972fccdaf0fba75dacc59725521035e177d09dd92174f9f52740bccb025\", \"price_changes\":[{\"asset_id\":\"61819828071723399190623735325323968706432622380635304641786792960078828866875\", \"price\":\"0.86\", \"size\":\"3390\", \"side\":\"BUY\", \"hash\":\"a29af156273dec05406231834eb76f172db635f4\", \"best_bid\":\"0.86\", \"best_ask\":\"0.87\"}, {\"asset_id\":\"114356653315647913247200886351065428002113119844334520181865067698979836634569\", \"price\":\"0.14\", \"size\":\"3390\", \"side\":\"SELL\", \"hash\":\"b341779b10b0a8e03e8ba7b35ea0661fd638c392\", \"best_bid\":\"0.13\", \"best_ask\":\"0.14\"}], \"timestamp\":\"1789987928396\", \"event_type\":\"price_change\"}","raw_base64":null}
{"received_ms":1789987928418,"monotonic_ns":1019369248562900,"raw":"{\"market\":\"0x28a45972fccdaf0fba75dacc59725521035e177d09dd92174f9f52740bccb025\", \"price_changes\":[{\"asset_id\":\"114356653315647913247200886351065428002113119844334520181865067698979836634569\", \"price\":\"0.06\", \"size\":\"5258.67\", \"side\":\"BUY\", \"hash\":\"e5093907f89a834185e589e847dce0c241827546\", \"best_bid\":\"0.13\", \"best_ask\":\"0.14\"}, {\"asset_id\":\"61819828071723399190623735325323968706432622380635304641786792960078828866875\", \"price\":\"0.94\", \"size\":\"5258.67\", \"side\":\"SELL\", \"hash\":\"2134e95310e15a73fe17ba34bbe965fce3384153\", \"best_bid\":\"0.86\", \"best_ask\":\"0.87\"}], \"timestamp\":\"1789987928397\", \"event_type\":\"price_change\"}","raw_base64":null}
{"received_ms":1789987928418,"monotonic_ns":1019369248610700,"raw":"{\"market\":\"0x28a45972fccdaf0fba75dacc59725521035e177d09dd92174f9f52740bccb025\", \"price_changes\":[{\"asset_id\":\"114356653315647913247200886351065428002113119844334520181865067698979836634569\", \"price\":\"0.03\", \"size\":\"4012.57\", \"side\":\"BUY\", \"hash\":\"e5093907f89a834185e589e847dce0c241827546\", \"best_bid\":\"0.13\", \"best_ask\":\"0.14\"}, {\"asset_id\":\"61819828071723399190623735325323968706432622380635304641786792960078828866875\", \"price\":\"0.97\", \"size\":\"4012.57\", \"side\":\"SELL\", \"hash\":\"2134e95310e15a73fe17ba34bbe965fce3384153\", \"best_bid\":\"0.86\", \"best_ask\":\"0.87\"}], \"timestamp\":\"1789987928397\", \"event_type\":\"price_change\"}","raw_base64":null}
{"received_ms":1789987928444,"monotonic_ns":1019369274494800,"raw":"{\"market\":\"0x28a45972fccdaf0fba75dacc59725521035e177d09dd92174f9f52740bccb025\", \"price_changes\":[{\"asset_id\":\"114356653315647913247200886351065428002113119844334520181865067698979836634569\", \"price\":\"0.07\", \"size\":\"6663.71\", \"side\":\"BUY\", \"hash\":\"b2c1feda2338d4a5a77608a46f294b4d0d2820d2\", \"best_bid\":\"0.13\", \"best_ask\":\"0.14\"}, {\"asset_id\":\"61819828071723399190623735325323968706432622380635304641786792960078828866875\", \"price\":\"0.93\", \"size\":\"6663.71\", \"side\":\"SELL\", \"hash\":\"1754e2ac51a4b810d86966be85724761347104e6\", \"best_bid\":\"0.86\", \"best_ask\":\"0.87\"}], \"timestamp\":\"1789987928423\", \"event_type\":\"price_change\"}","raw_base64":null}
{"received_ms":1789987928446,"monotonic_ns":1019369276454200,"raw":"{\"market\":\"0x28a45972fccdaf0fba75dacc59725521035e177d09dd92174f9f52740bccb025\", \"price_changes\":[{\"asset_id\":\"114356653315647913247200886351065428002113119844334520181865067698979836634569\", \"price\":\"0.13\", \"size\":\"270\", \"side\":\"BUY\", \"hash\":\"30c93dde0e14a6c53e3920eb26b113e8b92c8754\", \"best_bid\":\"0.13\", \"best_ask\":\"0.14\"}, {\"asset_id\":\"61819828071723399190623735325323968706432622380635304641786792960078828866875\", \"price\":\"0.87\", \"size\":\"270\", \"side\":\"SELL\", \"hash\":\"240d9a1a182626d33fb179ebba97a2fdc01105e5\", \"best_bid\":\"0.86\", \"best_ask\":\"0.87\"}], \"timestamp\":\"1789987928425\", \"event_type\":\"price_change\"}","raw_base64":null}
{"received_ms":1789987928449,"monotonic_ns":1019369279494500,"raw":"{\"market\":\"0x28a45972fccdaf0fba75dacc59725521035e177d09dd92174f9f52740bccb025\", \"price_changes\":[{\"asset_id\":\"114356653315647913247200886351065428002113119844334520181865067698979836634569\", \"price\":\"0.06\", \"size\":\"6127.67\", \"side\":\"BUY\", \"hash\":\"b5e4447c6cd45817731cb120693736414c6c03c3\", \"best_bid\":\"0.13\", \"best_ask\":\"0.14\"}, {\"asset_id\":\"61819828071723399190623735325323968706432622380635304641786792960078828866875\", \"price\":\"0.94\", \"size\":\"6127.67\", \"side\":\"SELL\", \"hash\":\"2447c6ca29ea52f5246759987733910e3a9ed25a\", \"best_bid\":\"0.86\", \"best_ask\":\"0.87\"}], \"timestamp\":\"1789987928427\", \"event_type\":\"price_change\"}","raw_base64":null}
{"received_ms":1789987928461,"monotonic_ns":1019369291452700,"raw":"{\"market\":\"0x28a45972fccdaf0fba75dacc59725521035e177d09dd92174f9f52740bccb025\", \"price_changes\":[{\"asset_id\":\"61819828071723399190623735325323968706432622380635304641786792960078828866875\", \"price\":\"0.76\", \"size\":\"434.91\", \"side\":\"BUY\", \"hash\":\"5e30e2f051d4086f7ec348036dd5c73f77485b17\", \"best_bid\":\"0.86\", \"best_ask\":\"0.87\"}, {\"asset_id\":\"114356653315647913247200886351065428002113119844334520181865067698979836634569\", \"price\":\"0.24\", \"size\":\"434.91\", \"side\":\"SELL\", \"hash\":\"460402d48dc3ee40747ffb27195d2e46766247dd\", \"best_bid\":\"0.13\", \"best_ask\":\"0.14\"}], \"timestamp\":\"1789987928441\", \"event_type\":\"price_change\"}","raw_base64":null}
{"received_ms":1789987928472,"monotonic_ns":1019369303163800,"raw":"{\"market\":\"0x28a45972fccdaf0fba75dacc59725521035e177d09dd92174f9f52740bccb025\", \"price_changes\":[{\"asset_id\":\"114356653315647913247200886351065428002113119844334520181865067698979836634569\", \"price\":\"0.07\", \"size\":\"5482.71\", \"side\":\"BUY\", \"hash\":\"a3a8679afd08765e4b06271023a3aff545ffa162\", \"best_bid\":\"0.13\", \"best_ask\":\"0.14\"}, {\"asset_id\":\"61819828071723399190623735325323968706432622380635304641786792960078828866875\", \"price\":\"0.93\", \"size\":\"5482.71\", \"side\":\"SELL\", \"hash\":\"d0405e46899398b671a9b2e34d58e439f88161f7\", \"best_bid\":\"0.86\", \"best_ask\":\"0.87\"}], \"timestamp\":\"1789987928452\", \"event_type\":\"price_change\"}","raw_base64":null}
{"received_ms":1789987928477,"monotonic_ns":1019369307318400,"raw":"{\"market\":\"0x28a45972fccdaf0fba75dacc59725521035e177d09dd92174f9f52740bccb025\", \"price_changes\":[{\"asset_id\":\"61819828071723399190623735325323968706432622380635304641786792960078828866875\", \"price\":\"0.73\", \"size\":\"504\", \"side\":\"BUY\", \"hash\":\"bf5bb0497de1d29983f8e8f32791f558cd1d9d13\", \"best_bid\":\"0.86\", \"best_ask\":\"0.87\"}, {\"asset_id\":\"114356653315647913247200886351065428002113119844334520181865067698979836634569\", \"price\":\"0.27\", \"size\":\"504\", \"side\":\"SELL\", \"hash\":\"c99759445f3f26be87d195957c27482ef317967f\", \"best_bid\":\"0.13\", \"best_ask\":\"0.14\"}], \"timestamp\":\"1789987928456\", \"event_type\":\"price_change\"}","raw_base64":null}
{"received_ms":1789987928480,"monotonic_ns":1019369310951900,"raw":"{\"market\":\"0x28a45972fccdaf0fba75dacc59725521035e177d09dd92174f9f52740bccb025\", \"price_changes\":[{\"asset_id\":\"61819828071723399190623735325323968706432622380635304641786792960078828866875\", \"price\":\"0.86\", \"size\":\"3570\", \"side\":\"BUY\", \"hash\":\"0974fb97a2c6035b08ba3fa5540eb5f3e55d9d18\", \"best_bid\":\"0.86\", \"best_ask\":\"0.87\"}, {\"asset_id\":\"114356653315647913247200886351065428002113119844334520181865067698979836634569\", \"price\":\"0.14\", \"size\":\"3570\", \"side\":\"SELL\", \"hash\":\"360d8f081a8c9788401e967f190af9d7484acf23\", \"best_bid\":\"0.13\", \"best_ask\":\"0.14\"}], \"timestamp\":\"1789987928458\", \"event_type\":\"price_change\"}","raw_base64":null}
{"received_ms":1789987928480,"monotonic_ns":1019369311044300,"raw":"{\"market\":\"0x28a45972fccdaf0fba75dacc59725521035e177d09dd92174f9f52740bccb025\", \"price_changes\":[{\"asset_id\":\"61819828071723399190623735325323968706432622380635304641786792960078828866875\", \"price\":\"0.84\", \"size\":\"2692\", \"side\":\"BUY\", \"hash\":\"af035746d4ef5c1edc0708629b8d100eed0de403\", \"best_bid\":\"0.86\", \"best_ask\":\"0.87\"}, {\"asset_id\":\"114356653315647913247200886351065428002113119844334520181865067698979836634569\", \"price\":\"0.16\", \"size\":\"2692\", \"side\":\"SELL\", \"hash\":\"7dd77feb0497b4e339d5e21a6efe9aa8c8514c92\", \"best_bid\":\"0.13\", \"best_ask\":\"0.14\"}], \"timestamp\":\"1789987928459\", \"event_type\":\"price_change\"}","raw_base64":null}
{"received_ms":1789987928485,"monotonic_ns":1019369315570800,"raw":"{\"market\":\"0x28a45972fccdaf0fba75dacc59725521035e177d09dd92174f9f52740bccb025\", \"price_changes\":[{\"asset_id\":\"61819828071723399190623735325323968706432622380635304641786792960078828866875\", \"price\":\"0.73\", \"size\":\"404\", \"side\":\"BUY\", \"hash\":\"646df4975c367cfbbb9b6b31dde1389e79b4048d\", \"best_bid\":\"0.86\", \"best_ask\":\"0.87\"}, {\"asset_id\":\"114356653315647913247200886351065428002113119844334520181865067698979836634569\", \"price\":\"0.27\", \"size\":\"404\", \"side\":\"SELL\", \"hash\":\"c111695a62cc4822bcd1952f9547dc3338946dba\", \"best_bid\":\"0.13\", \"best_ask\":\"0.14\"}], \"timestamp\":\"1789987928463\", \"event_type\":\"price_change\"}","raw_base64":null}
{"received_ms":1789987928491,"monotonic_ns":1019369322146300,"raw":"{\"market\":\"0x28a45972fccdaf0fba75dacc59725521035e177d09dd92174f9f52740bccb025\", \"price_changes\":[{\"asset_id\":\"114356653315647913247200886351065428002113119844334520181865067698979836634569\", \"price\":\"0.06\", \"size\":\"6132.67\", \"side\":\"BUY\", \"hash\":\"5d7ab94db1e8e5437c14425efee17a93e17b43bf\", \"best_bid\":\"0.13\", \"best_ask\":\"0.14\"}, {\"asset_id\":\"61819828071723399190623735325323968706432622380635304641786792960078828866875\", \"price\":\"0.94\", \"size\":\"6132.67\", \"side\":\"SELL\", \"hash\":\"7c6657397c8228b6ffa3ffd44fd86b0af0d212c4\", \"best_bid\":\"0.86\", \"best_ask\":\"0.87\"}], \"timestamp\":\"1789987928471\", \"event_type\":\"price_change\"}","raw_base64":null}
{"received_ms":1789987928493,"monotonic_ns":1019369323736800,"raw":"{\"market\":\"0x28a45972fccdaf0fba75dacc59725521035e177d09dd92174f9f52740bccb025\", \"price_changes\":[{\"asset_id\":\"114356653315647913247200886351065428002113119844334520181865067698979836634569\", \"price\":\"0.05\", \"size\":\"5620\", \"side\":\"BUY\", \"hash\":\"4653eee94a7e5ade7f4ab54a79297278a0c0dde8\", \"best_bid\":\"0.13\", \"best_ask\":\"0.14\"}, {\"asset_id\":\"61819828071723399190623735325323968706432622380635304641786792960078828866875\", \"price\":\"0.95\", \"size\":\"5620\", \"side\":\"SELL\", \"hash\":\"3d786a3f2aeeec9c5d7ec6e134d88ece2a0cd720\", \"best_bid\":\"0.86\", \"best_ask\":\"0.87\"}], \"timestamp\":\"1789987928472\", \"event_type\":\"price_change\"}","raw_base64":null}
{"received_ms":1789987928497,"monotonic_ns":1019369327498400,"raw":"{\"market\":\"0x28a45972fccdaf0fba75dacc59725521035e177d09dd92174f9f52740bccb025\", \"price_changes\":[{\"asset_id\":\"114356653315647913247200886351065428002113119844334520181865067698979836634569\", \"price\":\"0.04\", \"size\":\"615.48\", \"side\":\"BUY\", \"hash\":\"362cb911e90307b1869ff4365f5729a8bc6e5d56\", \"best_bid\":\"0.13\", \"best_ask\":\"0.14\"}, {\"asset_id\":\"61819828071723399190623735325323968706432622380635304641786792960078828866875\", \"price\":\"0.96\", \"size\":\"615.48\", \"side\":\"SELL\", \"hash\":\"e315e3aa4b832c70c81cca851d3e184b3ff8b6dc\", \"best_bid\":\"0.86\", \"best_ask\":\"0.87\"}], \"timestamp\":\"1789987928476\", \"event_type\":\"price_change\"}","raw_base64":null}
{"received_ms":1789987928515,"monotonic_ns":1019369345980300,"raw":"{\"market\":\"0x28a45972fccdaf0fba75dacc59725521035e177d09dd92174f9f52740bccb025\", \"price_changes\":[{\"asset_id\":\"114356653315647913247200886351065428002113119844334520181865067698979836634569\", \"price\":\"0.06\", \"size\":\"6137.67\", \"side\":\"BUY\", \"hash\":\"93ade49c06f052a555b84602c34927702d7db634\", \"best_bid\":\"0.13\", \"best_ask\":\"0.14\"}, {\"asset_id\":\"61819828071723399190623735325323968706432622380635304641786792960078828866875\", \"price\":\"0.94\", \"size\":\"6137.67\", \"side\":\"SELL\", \"hash\":\"0c7928e00cc1b7f7bd555ae56eede7a20d1d81b0\", \"best_bid\":\"0.86\", \"best_ask\":\"0.87\"}], \"timestamp\":\"1789987928489\", \"event_type\":\"price_change\"}","raw_base64":null}
{"received_ms":1789987928515,"monotonic_ns":1019369346062900,"raw":"{\"market\":\"0x28a45972fccdaf0fba75dacc59725521035e177d09dd92174f9f52740bccb025\", \"price_changes\":[{\"asset_id\":\"114356653315647913247200886351065428002113119844334520181865067698979836634569\", \"price\":\"0.04\", \"size\":\"620.48\", \"side\":\"BUY\", \"hash\":\"e4449c4efb18d55f0ad958330b4abe2d9d91a807\", \"best_bid\":\"0.13\", \"best_ask\":\"0.14\"}, {\"asset_id\":\"61819828071723399190623735325323968706432622380635304641786792960078828866875\", \"price\":\"0.96\", \"size\":\"620.48\", \"side\":\"SELL\", \"hash\":\"543c36659ebf066a284ee6c6f8adb93930fdfb8f\", \"best_bid\":\"0.86\", \"best_ask\":\"0.87\"}], \"timestamp\":\"1789987928490\", \"event_type\":\"price_change\"}","raw_base64":null}
{"received_ms":1789987928515,"monotonic_ns":1019369346108400,"raw":"{\"market\":\"0x28a45972fccdaf0fba75dacc59725521035e177d09dd92174f9f52740bccb025\", \"price_changes\":[{\"asset_id\":\"114356653315647913247200886351065428002113119844334520181865067698979836634569\", \"price\":\"0.05\", \"size\":\"5625\", \"side\":\"BUY\", \"hash\":\"3b9fc6ff4e14cb2571cef763a350f2d2bd0053ff\", \"best_bid\":\"0.13\", \"best_ask\":\"0.14\"}, {\"asset_id\":\"61819828071723399190623735325323968706432622380635304641786792960078828866875\", \"price\":\"0.95\", \"size\":\"5625\", \"side\":\"SELL\", \"hash\":\"b294669405ce3d0ecfd1493523849ba465168d85\", \"best_bid\":\"0.86\", \"best_ask\":\"0.87\"}], \"timestamp\":\"1789987928491\", \"event_type\":\"price_change\"}","raw_base64":null}
{"received_ms":1789987928515,"monotonic_ns":1019369346152100,"raw":"{\"market\":\"0x28a45972fccdaf0fba75dacc59725521035e177d09dd92174f9f52740bccb025\", \"price_changes\":[{\"asset_id\":\"114356653315647913247200886351065428002113119844334520181865067698979836634569\", \"price\":\"0.07\", \"size\":\"6171.71\", \"side\":\"BUY\", \"hash\":\"dbeeb2db5a42e49caf1df27ce5c094012bda6d6e\", \"best_bid\":\"0.13\", \"best_ask\":\"0.14\"}, {\"asset_id\":\"61819828071723399190623735325323968706432622380635304641786792960078828866875\", \"price\":\"0.93\", \"size\":\"6171.71\", \"side\":\"SELL\", \"hash\":\"7aafcca8500c73991819b23510abe04f53d76655\", \"best_bid\":\"0.86\", \"best_ask\":\"0.87\"}], \"timestamp\":\"1789987928492\", \"event_type\":\"price_change\"}","raw_base64":null}
{"received_ms":1789987928515,"monotonic_ns":1019369346194000,"raw":"{\"market\":\"0x28a45972fccdaf0fba75dacc59725521035e177d09dd92174f9f52740bccb025\", \"price_changes\":[{\"asset_id\":\"114356653315647913247200886351065428002113119844334520181865067698979836634569\", \"price\":\"0.06\", \"size\":\"6449.67\", \"side\":\"BUY\", \"hash\":\"1e9bddb3b2a1e40958b9600e06733c2e3888bc68\", \"best_bid\":\"0.13\", \"best_ask\":\"0.14\"}, {\"asset_id\":\"61819828071723399190623735325323968706432622380635304641786792960078828866875\", \"price\":\"0.94\", \"size\":\"6449.67\", \"side\":\"SELL\", \"hash\":\"aac85d57ea8639dd82aa99ce3a729f84b9872cdc\", \"best_bid\":\"0.86\", \"best_ask\":\"0.87\"}], \"timestamp\":\"1789987928493\", \"event_type\":\"price_change\"}","raw_base64":null}
{"received_ms":1789987928515,"monotonic_ns":1019369346235500,"raw":"{\"market\":\"0x28a45972fccdaf0fba75dacc59725521035e177d09dd92174f9f52740bccb025\", \"price_changes\":[{\"asset_id\":\"61819828071723399190623735325323968706432622380635304641786792960078828866875\", \"price\":\"0.85\", \"size\":\"2887.52\", \"side\":\"BUY\", \"hash\":\"00932a59d3a5b87b86859642ed731aa8ea5b17f8\", \"best_bid\":\"0.86\", \"best_ask\":\"0.87\"}, {\"asset_id\":\"114356653315647913247200886351065428002113119844334520181865067698979836634569\", \"price\":\"0.15\", \"size\":\"2887.52\", \"side\":\"SELL\", \"hash\":\"61f731e780d4461e720a7984a1658f74be713aec\", \"best_bid\":\"0.13\", \"best_ask\":\"0.14\"}], \"timestamp\":\"1789987928494\", \"event_type\":\"price_change\"}","raw_base64":null}
{"received_ms":1789987928516,"monotonic_ns":1019369346704200,"raw":"{\"market\":\"0x28a45972fccdaf0fba75dacc59725521035e177d09dd92174f9f52740bccb025\", \"price_changes\":[{\"asset_id\":\"114356653315647913247200886351065428002113119844334520181865067698979836634569\", \"price\":\"0.07\", \"size\":\"6176.71\", \"side\":\"BUY\", \"hash\":\"6426ce7680f7c15ceb46f0cda1f89328773ef85f\", \"best_bid\":\"0.13\", \"best_ask\":\"0.14\"}, {\"asset_id\":\"61819828071723399190623735325323968706432622380635304641786792960078828866875\", \"price\":\"0.93\", \"size\":\"6176.71\", \"side\":\"SELL\", \"hash\":\"2b6a572318462606d049d66c18c809525ebc7ef2\", \"best_bid\":\"0.86\", \"best_ask\":\"0.87\"}], \"timestamp\":\"1789987928495\", \"event_type\":\"price_change\"}","raw_base64":null}
{"received_ms":1789987928516,"monotonic_ns":1019369346758400,"raw":"{\"market\":\"0x28a45972fccdaf0fba75dacc59725521035e177d09dd92174f9f52740bccb025\", \"price_changes\":[{\"asset_id\":\"114356653315647913247200886351065428002113119844334520181865067698979836634569\", \"price\":\"0.08\", \"size\":\"699.5\", \"side\":\"BUY\", \"hash\":\"6082d719b621ab61612338b6ebad65096f505d7b\", \"best_bid\":\"0.13\", \"best_ask\":\"0.14\"}, {\"asset_id\":\"61819828071723399190623735325323968706432622380635304641786792960078828866875\", \"price\":\"0.92\", \"size\":\"699.5\", \"side\":\"SELL\", \"hash\":\"976c3ab4abfdc45477a862b45bd99cf233e709d0\", \"best_bid\":\"0.86\", \"best_ask\":\"0.87\"}], \"timestamp\":\"1789987928496\", \"event_type\":\"price_change\"}","raw_base64":null}
{"received_ms":1789987928517,"monotonic_ns":1019369348187100,"raw":"{\"market\":\"0x28a45972fccdaf0fba75dacc59725521035e177d09dd92174f9f52740bccb025\", \"price_changes\":[{\"asset_id\":\"114356653315647913247200886351065428002113119844334520181865067698979836634569\", \"price\":\"0.06\", \"size\":\"6454.67\", \"side\":\"BUY\", \"hash\":\"e95de9c46f5032394381c4b0f2092220d10a7374\", \"best_bid\":\"0.13\", \"best_ask\":\"0.14\"}, {\"asset_id\":\"61819828071723399190623735325323968706432622380635304641786792960078828866875\", \"price\":\"0.94\", \"size\":\"6454.67\", \"side\":\"SELL\", \"hash\":\"8f809a05c01b6134bc4157634e5e85c943f5ce52\", \"best_bid\":\"0.86\", \"best_ask\":\"0.87\"}], \"timestamp\":\"1789987928496\", \"event_type\":\"price_change\"}","raw_base64":null}
{"received_ms":1789987928521,"monotonic_ns":1019369352171500,"raw":"{\"market\":\"0x28a45972fccdaf0fba75dacc59725521035e177d09dd92174f9f52740bccb025\", \"price_changes\":[{\"asset_id\":\"114356653315647913247200886351065428002113119844334520181865067698979836634569\", \"price\":\"0.07\", \"size\":\"6181.71\", \"side\":\"BUY\", \"hash\":\"302d6f238bcf08ae1e3cba6c655383f3c74a7683\", \"best_bid\":\"0.13\", \"best_ask\":\"0.14\"}, {\"asset_id\":\"61819828071723399190623735325323968706432622380635304641786792960078828866875\", \"price\":\"0.93\", \"size\":\"6181.71\", \"side\":\"SELL\", \"hash\":\"add4927d269ccd7cd47e5ba872d6b60b36d9bf95\", \"best_bid\":\"0.86\", \"best_ask\":\"0.87\"}], \"timestamp\":\"1789987928500\", \"event_type\":\"price_change\"}","raw_base64":null}
{"received_ms":1789987928521,"monotonic_ns":1019369352251600,"raw":"{\"market\":\"0x28a45972fccdaf0fba75dacc59725521035e177d09dd92174f9f52740bccb025\", \"price_changes\":[{\"asset_id\":\"114356653315647913247200886351065428002113119844334520181865067698979836634569\", \"price\":\"0.06\", \"size\":\"6459.67\", \"side\":\"BUY\", \"hash\":\"18b43fcaff483725da8dfaac4826da5f84166fa5\", \"best_bid\":\"0.13\", \"best_ask\":\"0.14\"}, {\"asset_id\":\"61819828071723399190623735325323968706432622380635304641786792960078828866875\", \"price\":\"0.94\", \"size\":\"6459.67\", \"side\":\"SELL\", \"hash\":\"a5aef6ccab007a87c0aa3008139ab1ddeb798daf\", \"best_bid\":\"0.86\", \"best_ask\":\"0.87\"}], \"timestamp\":\"1789987928500\", \"event_type\":\"price_change\"}","raw_base64":null}
{"received_ms":1789987928522,"monotonic_ns":1019369352295300,"raw":"{\"market\":\"0x28a45972fccdaf0fba75dacc59725521035e177d09dd92174f9f52740bccb025\", \"price_changes\":[{\"asset_id\":\"114356653315647913247200886351065428002113119844334520181865067698979836634569\", \"price\":\"0.05\", \"size\":\"5630\", \"side\":\"BUY\", \"hash\":\"9cb1dd49537d65cd88df2940f1c4e7edb46dfea6\", \"best_bid\":\"0.13\", \"best_ask\":\"0.14\"}, {\"asset_id\":\"61819828071723399190623735325323968706432622380635304641786792960078828866875\", \"price\":\"0.95\", \"size\":\"5630\", \"side\":\"SELL\", \"hash\":\"3e776b3c3a0dddb3140301f6d83fef425e85a58c\", \"best_bid\":\"0.86\", \"best_ask\":\"0.87\"}], \"timestamp\":\"1789987928501\", \"event_type\":\"price_change\"}","raw_base64":null}
{"received_ms":1789987928522,"monotonic_ns":1019369352764500,"raw":"{\"market\":\"0x28a45972fccdaf0fba75dacc59725521035e177d09dd92174f9f52740bccb025\", \"price_changes\":[{\"asset_id\":\"114356653315647913247200886351065428002113119844334520181865067698979836634569\", \"price\":\"0.08\", \"size\":\"704.5\", \"side\":\"BUY\", \"hash\":\"62adb2379a2ec4d34682b00daaf76da2f8245d8d\", \"best_bid\":\"0.13\", \"best_ask\":\"0.14\"}, {\"asset_id\":\"61819828071723399190623735325323968706432622380635304641786792960078828866875\", \"price\":\"0.92\", \"size\":\"704.5\", \"side\":\"SELL\", \"hash\":\"99e8d059d4fef3063d792c5fe950ad07eebd5886\", \"best_bid\":\"0.86\", \"best_ask\":\"0.87\"}], \"timestamp\":\"1789987928502\", \"event_type\":\"price_change\"}","raw_base64":null}
{"received_ms":1789987928523,"monotonic_ns":1019369354129300,"raw":"{\"market\":\"0x28a45972fccdaf0fba75dacc59725521035e177d09dd92174f9f52740bccb025\", \"price_changes\":[{\"asset_id\":\"114356653315647913247200886351065428002113119844334520181865067698979836634569\", \"price\":\"0.07\", \"size\":\"6186.71\", \"side\":\"BUY\", \"hash\":\"7c2f821624f60612654c3a7876222af164789270\", \"best_bid\":\"0.13\", \"best_ask\":\"0.14\"}, {\"asset_id\":\"61819828071723399190623735325323968706432622380635304641786792960078828866875\", \"price\":\"0.93\", \"size\":\"6186.71\", \"side\":\"SELL\", \"hash\":\"58f10ecf2b4a5d747c730fd0585d9cfcbd4beb1f\", \"best_bid\":\"0.86\", \"best_ask\":\"0.87\"}], \"timestamp\":\"1789987928503\", \"event_type\":\"price_change\"}","raw_base64":null}
{"received_ms":1789987928524,"monotonic_ns":1019369354388500,"raw":"{\"market\":\"0x28a45972fccdaf0fba75dacc59725521035e177d09dd92174f9f52740bccb025\", \"price_changes\":[{\"asset_id\":\"114356653315647913247200886351065428002113119844334520181865067698979836634569\", \"price\":\"0.06\", \"size\":\"6464.67\", \"side\":\"BUY\", \"hash\":\"29ee4ae872b080767ea8c3df2a0084bea9d5d6fb\", \"best_bid\":\"0.13\", \"best_ask\":\"0.14\"}, {\"asset_id\":\"61819828071723399190623735325323968706432622380635304641786792960078828866875\", \"price\":\"0.94\", \"size\":\"6464.67\", \"side\":\"SELL\", \"hash\":\"2d744c6840ee1f201753fff1dab839d8421a1ac1\", \"best_bid\":\"0.86\", \"best_ask\":\"0.87\"}], \"timestamp\":\"1789987928503\", \"event_type\":\"price_change\"}","raw_base64":null}
{"received_ms":1789987928527,"monotonic_ns":1019369357796900,"raw":"{\"market\":\"0x28a45972fccdaf0fba75dacc59725521035e177d09dd92174f9f52740bccb025\", \"price_changes\":[{\"asset_id\":\"114356653315647913247200886351065428002113119844334520181865067698979836634569\", \"price\":\"0.07\", \"size\":\"6191.71\", \"side\":\"BUY\", \"hash\":\"81e9c216cae0967a03dd5e6984d810351a11e477\", \"best_bid\":\"0.13\", \"best_ask\":\"0.14\"}, {\"asset_id\":\"61819828071723399190623735325323968706432622380635304641786792960078828866875\", \"price\":\"0.93\", \"size\":\"6191.71\", \"side\":\"SELL\", \"hash\":\"771b2ce54763aac025d758249f63fac753274a76\", \"best_bid\":\"0.86\", \"best_ask\":\"0.87\"}], \"timestamp\":\"1789987928507\", \"event_type\":\"price_change\"}","raw_base64":null}
{"received_ms":1789987928528,"monotonic_ns":1019369358397600,"raw":"{\"market\":\"0x28a45972fccdaf0fba75dacc59725521035e177d09dd92174f9f52740bccb025\", \"price_changes\":[{\"asset_id\":\"114356653315647913247200886351065428002113119844334520181865067698979836634569\", \"price\":\"0.08\", \"size\":\"709.5\", \"side\":\"BUY\", \"hash\":\"43cb12ca0635fc2de3e4e43a5af172166f546b7c\", \"best_bid\":\"0.13\", \"best_ask\":\"0.14\"}, {\"asset_id\":\"61819828071723399190623735325323968706432622380635304641786792960078828866875\", \"price\":\"0.92\", \"size\":\"709.5\", \"side\":\"SELL\", \"hash\":\"db8ee0e8970eaa3c9c3a50258c6c5ea10954cdd9\", \"best_bid\":\"0.86\", \"best_ask\":\"0.87\"}], \"timestamp\":\"1789987928508\", \"event_type\":\"price_change\"}","raw_base64":null}
{"received_ms":1789987928529,"monotonic_ns":1019369359504200,"raw":"{\"market\":\"0x28a45972fccdaf0fba75dacc59725521035e177d09dd92174f9f52740bccb025\", \"price_changes\":[{\"asset_id\":\"114356653315647913247200886351065428002113119844334520181865067698979836634569\", \"price\":\"0.06\", \"size\":\"6469.67\", \"side\":\"BUY\", \"hash\":\"51711f95349c240f705bd745dce1a773fa0d1e17\", \"best_bid\":\"0.13\", \"best_ask\":\"0.14\"}, {\"asset_id\":\"61819828071723399190623735325323968706432622380635304641786792960078828866875\", \"price\":\"0.94\", \"size\":\"6469.67\", \"side\":\"SELL\", \"hash\":\"334689c4d17ee7fb4d60ba10e237486ccd2ebdad\", \"best_bid\":\"0.86\", \"best_ask\":\"0.87\"}], \"timestamp\":\"1789987928509\", \"event_type\":\"price_change\"}","raw_base64":null}
{"received_ms":1789987928530,"monotonic_ns":1019369361204000,"raw":"{\"market\":\"0x28a45972fccdaf0fba75dacc59725521035e177d09dd92174f9f52740bccb025\", \"price_changes\":[{\"asset_id\":\"114356653315647913247200886351065428002113119844334520181865067698979836634569\", \"price\":\"0.04\", \"size\":\"625.48\", \"side\":\"BUY\", \"hash\":\"6099a110b327201e857864128bdcad293387e694\", \"best_bid\":\"0.13\", \"best_ask\":\"0.14\"}, {\"asset_id\":\"61819828071723399190623735325323968706432622380635304641786792960078828866875\", \"price\":\"0.96\", \"size\":\"625.48\", \"side\":\"SELL\", \"hash\":\"d5a22497a4c2afc466f1a2a0e76a11aa5c9de4f8\", \"best_bid\":\"0.86\", \"best_ask\":\"0.87\"}], \"timestamp\":\"1789987928510\", \"event_type\":\"price_change\"}","raw_base64":null}
{"received_ms":1789987928532,"monotonic_ns":1019369362895700,"raw":"{\"market\":\"0x28a45972fccdaf0fba75dacc59725521035e177d09dd92174f9f52740bccb025\", \"price_changes\":[{\"asset_id\":\"114356653315647913247200886351065428002113119844334520181865067698979836634569\", \"price\":\"0.06\", \"size\":\"6474.67\", \"side\":\"BUY\", \"hash\":\"7a9a8f7592c2047d945115da21529f7320c40b8a\", \"best_bid\":\"0.13\", \"best_ask\":\"0.14\"}, {\"asset_id\":\"61819828071723399190623735325323968706432622380635304641786792960078828866875\", \"price\":\"0.94\", \"size\":\"6474.67\", \"side\":\"SELL\", \"hash\":\"aae8d03852c2ac37dc66e18656e4173609ab3214\", \"best_bid\":\"0.86\", \"best_ask\":\"0.87\"}], \"timestamp\":\"1789987928511\", \"event_type\":\"price_change\"}","raw_base64":null}
{"received_ms":1789987928532,"monotonic_ns":1019369363093300,"raw":"{\"market\":\"0x28a45972fccdaf0fba75dacc59725521035e177d09dd92174f9f52740bccb025\", \"price_changes\":[{\"asset_id\":\"114356653315647913247200886351065428002113119844334520181865067698979836634569\", \"price\":\"0.05\", \"size\":\"5635\", \"side\":\"BUY\", \"hash\":\"ae79d24e26c481b2842399f0e2956ea41eb35980\", \"best_bid\":\"0.13\", \"best_ask\":\"0.14\"}, {\"asset_id\":\"61819828071723399190623735325323968706432622380635304641786792960078828866875\", \"price\":\"0.95\", \"size\":\"5635\", \"side\":\"SELL\", \"hash\":\"782539a1938b0ef8c8518aff25d4f70037f3144d\", \"best_bid\":\"0.86\", \"best_ask\":\"0.87\"}], \"timestamp\":\"1789987928512\", \"event_type\":\"price_change\"}","raw_base64":null}
{"received_ms":1789987928533,"monotonic_ns":1019369363689600,"raw":"{\"market\":\"0x28a45972fccdaf0fba75dacc59725521035e177d09dd92174f9f52740bccb025\", \"price_changes\":[{\"asset_id\":\"114356653315647913247200886351065428002113119844334520181865067698979836634569\", \"price\":\"0.06\", \"size\":\"6479.67\", \"side\":\"BUY\", \"hash\":\"3291a120b4b20f54b2b9124753263b90f711a4b6\", \"best_bid\":\"0.13\", \"best_ask\":\"0.14\"}, {\"asset_id\":\"61819828071723399190623735325323968706432622380635304641786792960078828866875\", \"price\":\"0.94\", \"size\":\"6479.67\", \"side\":\"SELL\", \"hash\":\"2b3cf9e7b6daf624a9ebf2b548626c88382fa8f3\", \"best_bid\":\"0.86\", \"best_ask\":\"0.87\"}], \"timestamp\":\"1789987928513\", \"event_type\":\"price_change\"}","raw_base64":null}
{"received_ms":1789987928534,"monotonic_ns":1019369365159100,"raw":"{\"market\":\"0x28a45972fccdaf0fba75dacc59725521035e177d09dd92174f9f52740bccb025\", \"price_changes\":[{\"asset_id\":\"114356653315647913247200886351065428002113119844334520181865067698979836634569\", \"price\":\"0.08\", \"size\":\"714.5\", \"side\":\"BUY\", \"hash\":\"a8a08c7624589e33508fbd0819e92848802704fb\", \"best_bid\":\"0.13\", \"best_ask\":\"0.14\"}, {\"asset_id\":\"61819828071723399190623735325323968706432622380635304641786792960078828866875\", \"price\":\"0.92\", \"size\":\"714.5\", \"side\":\"SELL\", \"hash\":\"1c7c0750f59789cfa9c86ed1fc533b63f530ac15\", \"best_bid\":\"0.86\", \"best_ask\":\"0.87\"}], \"timestamp\":\"1789987928514\", \"event_type\":\"price_change\"}","raw_base64":null}
{"received_ms":1789987928535,"monotonic_ns":1019369366210800,"raw":"{\"market\":\"0x28a45972fccdaf0fba75dacc59725521035e177d09dd92174f9f52740bccb025\", \"price_changes\":[{\"asset_id\":\"114356653315647913247200886351065428002113119844334520181865067698979836634569\", \"price\":\"0.07\", \"size\":\"6196.71\", \"side\":\"BUY\", \"hash\":\"4b648f5178edcad06c8bebf7308d4acc2ee4ac47\", \"best_bid\":\"0.13\", \"best_ask\":\"0.14\"}, {\"asset_id\":\"61819828071723399190623735325323968706432622380635304641786792960078828866875\", \"price\":\"0.93\", \"size\":\"6196.71\", \"side\":\"SELL\", \"hash\":\"7ea7bdf95f9e5d574b9855f5fa49727c92f529f8\", \"best_bid\":\"0.86\", \"best_ask\":\"0.87\"}], \"timestamp\":\"1789987928516\", \"event_type\":\"price_change\"}","raw_base64":null}
{"received_ms":1789987928547,"monotonic_ns":1019369377429100,"raw":"{\"market\":\"0x28a45972fccdaf0fba75dacc59725521035e177d09dd92174f9f52740bccb025\", \"price_changes\":[{\"asset_id\":\"114356653315647913247200886351065428002113119844334520181865067698979836634569\", \"price\":\"0.06\", \"size\":\"6167.67\", \"side\":\"BUY\", \"hash\":\"75bb4125716d258859051dd29cf3f2e84efdbaed\", \"best_bid\":\"0.13\", \"best_ask\":\"0.14\"}, {\"asset_id\":\"61819828071723399190623735325323968706432622380635304641786792960078828866875\", \"price\":\"0.94\", \"size\":\"6167.67\", \"side\":\"SELL\", \"hash\":\"98d54676502a10827eb2de1babd039287a1160f5\", \"best_bid\":\"0.86\", \"best_ask\":\"0.87\"}], \"timestamp\":\"1789987928526\", \"event_type\":\"price_change\"}","raw_base64":null}
{"received_ms":1789987928548,"monotonic_ns":1019369378814800,"raw":"{\"market\":\"0x28a45972fccdaf0fba75dacc59725521035e177d09dd92174f9f52740bccb025\", \"price_changes\":[{\"asset_id\":\"61819828071723399190623735325323968706432622380635304641786792960078828866875\", \"price\":\"0.84\", \"size\":\"2992\", \"side\":\"BUY\", \"hash\":\"d336658f8c1d0fd13d7855383188b346a1cbd2f0\", \"best_bid\":\"0.86\", \"best_ask\":\"0.87\"}, {\"asset_id\":\"114356653315647913247200886351065428002113119844334520181865067698979836634569\", \"price\":\"0.16\", \"size\":\"2992\", \"side\":\"SELL\", \"hash\":\"e290b9e0fa941c29b3a48c40c38da84e2d71eaf5\", \"best_bid\":\"0.13\", \"best_ask\":\"0.14\"}], \"timestamp\":\"1789987928528\", \"event_type\":\"price_change\"}","raw_base64":null}
{"received_ms":1789987928549,"monotonic_ns":1019369379651900,"raw":"{\"market\":\"0x28a45972fccdaf0fba75dacc59725521035e177d09dd92174f9f52740bccb025\", \"price_changes\":[{\"asset_id\":\"114356653315647913247200886351065428002113119844334520181865067698979836634569\", \"price\":\"0.06\", \"size\":\"5298.67\", \"side\":\"BUY\", \"hash\":\"d84ca8bf7d61642cb00ded3b43a1a465370359e3\", \"best_bid\":\"0.13\", \"best_ask\":\"0.14\"}, {\"asset_id\":\"61819828071723399190623735325323968706432622380635304641786792960078828866875\", \"price\":\"0.94\", \"size\":\"5298.67\", \"side\":\"SELL\", \"hash\":\"8c30dc4280efda8bbfd847d7ec6badc944d0d17b\", \"best_bid\":\"0.86\", \"best_ask\":\"0.87\"}], \"timestamp\":\"1789987928529\", \"event_type\":\"price_change\"}","raw_base64":null}
{"received_ms":1789987928552,"monotonic_ns":1019369382469100,"raw":"{\"market\":\"0x28a45972fccdaf0fba75dacc59725521035e177d09dd92174f9f52740bccb025\", \"price_changes\":[{\"asset_id\":\"61819828071723399190623735325323968706432622380635304641786792960078828866875\", \"price\":\"0.73\", \"size\":\"504\", \"side\":\"BUY\", \"hash\":\"a14368cd54549840507cd9a378577a3b91a158cd\", \"best_bid\":\"0.86\", \"best_ask\":\"0.87\"}, {\"asset_id\":\"114356653315647913247200886351065428002113119844334520181865067698979836634569\", \"price\":\"0.27\", \"size\":\"504\", \"side\":\"SELL\", \"hash\":\"374b53c4e4374cb830085d7c664125a398ce2c9c\", \"best_bid\":\"0.13\", \"best_ask\":\"0.14\"}], \"timestamp\":\"1789987928532\", \"event_type\":\"price_change\"}","raw_base64":null}
{"received_ms":1789987928555,"monotonic_ns":1019369385474800,"raw":"{\"market\":\"0x28a45972fccdaf0fba75dacc59725521035e177d09dd92174f9f52740bccb025\", \"price_changes\":[{\"asset_id\":\"61819828071723399190623735325323968706432622380635304641786792960078828866875\", \"price\":\"0.73\", \"size\":\"404\", \"side\":\"BUY\", \"hash\":\"c5850b4a42d37cd31bc3684a0e0e1a905cb7ec10\", \"best_bid\":\"0.86\", \"best_ask\":\"0.87\"}, {\"asset_id\":\"114356653315647913247200886351065428002113119844334520181865067698979836634569\", \"price\":\"0.27\", \"size\":\"404\", \"side\":\"SELL\", \"hash\":\"3e8f15308e9763860f7c33f5867650c1a64285d6\", \"best_bid\":\"0.13\", \"best_ask\":\"0.14\"}], \"timestamp\":\"1789987928535\", \"event_type\":\"price_change\"}","raw_base64":null}
{"received_ms":1789987928577,"monotonic_ns":1019369407604800,"raw":"{\"market\":\"0x28a45972fccdaf0fba75dacc59725521035e177d09dd92174f9f52740bccb025\", \"price_changes\":[{\"asset_id\":\"61819828071723399190623735325323968706432622380635304641786792960078828866875\", \"price\":\"0.84\", \"size\":\"2692\", \"side\":\"BUY\", \"hash\":\"d007cda767bcf1baf48d692a09eb24ea4b6d18e7\", \"best_bid\":\"0.86\", \"best_ask\":\"0.87\"}, {\"asset_id\":\"114356653315647913247200886351065428002113119844334520181865067698979836634569\", \"price\":\"0.16\", \"size\":\"2692\", \"side\":\"SELL\", \"hash\":\"22f708ae4c907e15abdb291b74f4cf40139372af\", \"best_bid\":\"0.13\", \"best_ask\":\"0.14\"}], \"timestamp\":\"1789987928557\", \"event_type\":\"price_change\"}","raw_base64":null}
{"received_ms":1789987928578,"monotonic_ns":1019369408369700,"raw":"{\"market\":\"0x28a45972fccdaf0fba75dacc59725521035e177d09dd92174f9f52740bccb025\", \"price_changes\":[{\"asset_id\":\"114356653315647913247200886351065428002113119844334520181865067698979836634569\", \"price\":\"0.07\", \"size\":\"6581.71\", \"side\":\"BUY\", \"hash\":\"88f7d1ce98e54ba336a0d9cd880a3954b299bf01\", \"best_bid\":\"0.13\", \"best_ask\":\"0.14\"}, {\"asset_id\":\"61819828071723399190623735325323968706432622380635304641786792960078828866875\", \"price\":\"0.93\", \"size\":\"6581.71\", \"side\":\"SELL\", \"hash\":\"5817605f2b1e09d4111bfada7de664c7d7f94152\", \"best_bid\":\"0.86\", \"best_ask\":\"0.87\"}], \"timestamp\":\"1789987928558\", \"event_type\":\"price_change\"}","raw_base64":null}
{"received_ms":1789987928586,"monotonic_ns":1019369416556700,"raw":"{\"market\":\"0x28a45972fccdaf0fba75dacc59725521035e177d09dd92174f9f52740bccb025\", \"price_changes\":[{\"asset_id\":\"61819828071723399190623735325323968706432622380635304641786792960078828866875\", \"price\":\"0.79\", \"size\":\"487\", \"side\":\"BUY\", \"hash\":\"7a621de95d1975e692f5ddecc4c993f281eca0ef\", \"best_bid\":\"0.86\", \"best_ask\":\"0.87\"}, {\"asset_id\":\"114356653315647913247200886351065428002113119844334520181865067698979836634569\", \"price\":\"0.21\", \"size\":\"487\", \"side\":\"SELL\", \"hash\":\"e3bd07b36169575981356582bf684834ec19a9c3\", \"best_bid\":\"0.13\", \"best_ask\":\"0.14\"}], \"timestamp\":\"1789987928565\", \"event_type\":\"price_change\"}","raw_base64":null}
{"received_ms":1789987928587,"monotonic_ns":1019369417557700,"raw":"{\"market\":\"0x28a45972fccdaf0fba75dacc59725521035e177d09dd92174f9f52740bccb025\", \"price_changes\":[{\"asset_id\":\"61819828071723399190623735325323968706432622380635304641786792960078828866875\", \"price\":\"0.77\", \"size\":\"587.49\", \"side\":\"BUY\", \"hash\":\"c5e6775e7d58ab046f1f09e8e58ca94ced5d106a\", \"best_bid\":\"0.86\", \"best_ask\":\"0.87\"}, {\"asset_id\":\"114356653315647913247200886351065428002113119844334520181865067698979836634569\", \"price\":\"0.23\", \"size\":\"587.49\", \"side\":\"SELL\", \"hash\":\"76a6ec853365eef999077010c3af761636396bcd\", \"best_bid\":\"0.13\", \"best_ask\":\"0.14\"}], \"timestamp\":\"1789987928566\", \"event_type\":\"price_change\"}","raw_base64":null}
{"received_ms":1789987928591,"monotonic_ns":1019369421572800,"raw":"{\"market\":\"0x28a45972fccdaf0fba75dacc59725521035e177d09dd92174f9f52740bccb025\", \"price_changes\":[{\"asset_id\":\"61819828071723399190623735325323968706432622380635304641786792960078828866875\", \"price\":\"0.77\", \"size\":\"547.49\", \"side\":\"BUY\", \"hash\":\"2d5a3d92e91fdbafd2a777008390e5cdd551eaae\", \"best_bid\":\"0.86\", \"best_ask\":\"0.87\"}, {\"asset_id\":\"114356653315647913247200886351065428002113119844334520181865067698979836634569\", \"price\":\"0.23\", \"size\":\"547.49\", \"side\":\"SELL\", \"hash\":\"cc1c39362ef6ac1d6474c66c49d846e14d13cb42\", \"best_bid\":\"0.13\", \"best_ask\":\"0.14\"}], \"timestamp\":\"1789987928570\", \"event_type\":\"price_change\"}","raw_base64":null}
{"received_ms":1789987928591,"monotonic_ns":1019369421638300,"raw":"{\"market\":\"0x28a45972fccdaf0fba75dacc59725521035e177d09dd92174f9f52740bccb025\", \"price_changes\":[{\"asset_id\":\"61819828071723399190623735325323968706432622380635304641786792960078828866875\", \"price\":\"0.79\", \"size\":\"427\", \"side\":\"BUY\", \"hash\":\"2d5a3d92e91fdbafd2a777008390e5cdd551eaae\", \"best_bid\":\"0.86\", \"best_ask\":\"0.87\"}, {\"asset_id\":\"114356653315647913247200886351065428002113119844334520181865067698979836634569\", \"price\":\"0.21\", \"size\":\"427\", \"side\":\"SELL\", \"hash\":\"cc1c39362ef6ac1d6474c66c49d846e14d13cb42\", \"best_bid\":\"0.13\", \"best_ask\":\"0.14\"}], \"timestamp\":\"1789987928570\", \"event_type\":\"price_change\"}","raw_base64":null}
{"received_ms":1789987928609,"monotonic_ns":1019369439946800,"raw":"{\"market\":\"0x28a45972fccdaf0fba75dacc59725521035e177d09dd92174f9f52740bccb025\", \"price_changes\":[{\"asset_id\":\"114356653315647913247200886351065428002113119844334520181865067698979836634569\", \"price\":\"0.06\", \"size\":\"6197.67\", \"side\":\"BUY\", \"hash\":\"fc91af02643b23da880a24d75ddf7d01873a1e37\", \"best_bid\":\"0.13\", \"best_ask\":\"0.14\"}, {\"asset_id\":\"61819828071723399190623735325323968706432622380635304641786792960078828866875\", \"price\":\"0.94\", \"size\":\"6197.67\", \"side\":\"SELL\", \"hash\":\"b52defea18e82fd789099eaeeb457b79f7f94877\", \"best_bid\":\"0.86\", \"best_ask\":\"0.87\"}], \"timestamp\":\"1789987928587\", \"event_type\":\"price_change\"}","raw_base64":null}
{"received_ms":1789987928610,"monotonic_ns":1019369440304400,"raw":"{\"market\":\"0x28a45972fccdaf0fba75dacc59725521035e177d09dd92174f9f52740bccb025\", \"price_changes\":[{\"asset_id\":\"61819828071723399190623735325323968706432622380635304641786792960078828866875\", \"price\":\"0.84\", \"size\":\"2920\", \"side\":\"BUY\", \"hash\":\"f8d3b72b29473cf9499c47a595331c5ed561c92a\", \"best_bid\":\"0.86\", \"best_ask\":\"0.87\"}, {\"asset_id\":\"114356653315647913247200886351065428002113119844334520181865067698979836634569\", \"price\":\"0.16\", \"size\":\"2920\", \"side\":\"SELL\", \"hash\":\"c526d01d3cf8c82c2351d46f876f71df501ba456\", \"best_bid\":\"0.13\", \"best_ask\":\"0.14\"}], \"timestamp\":\"1789987928588\", \"event_type\":\"price_change\"}","raw_base64":null}
{"received_ms":1789987928610,"monotonic_ns":1019369440698500,"raw":"{\"market\":\"0x28a45972fccdaf0fba75dacc59725521035e177d09dd92174f9f52740bccb025\", \"price_changes\":[{\"asset_id\":\"61819828071723399190623735325323968706432622380635304641786792960078828866875\", \"price\":\"0.85\", \"size\":\"2976.52\", \"side\":\"BUY\", \"hash\":\"e14d7ffb1561f86086d7a073f07bf9ff3e8ac8f8\", \"best_bid\":\"0.86\", \"best_ask\":\"0.87\"}, {\"asset_id\":\"114356653315647913247200886351065428002113119844334520181865067698979836634569\", \"price\":\"0.15\", \"size\":\"2976.52\", \"side\":\"SELL\", \"hash\":\"4df4946dbfa281b71cf581f73632a3b8714546e0\", \"best_bid\":\"0.13\", \"best_ask\":\"0.14\"}], \"timestamp\":\"1789987928589\", \"event_type\":\"price_change\"}","raw_base64":null}
{"received_ms":1789987928622,"monotonic_ns":1019369452666600,"raw":"{\"market\":\"0x28a45972fccdaf0fba75dacc59725521035e177d09dd92174f9f52740bccb025\", \"price_changes\":[{\"asset_id\":\"61819828071723399190623735325323968706432622380635304641786792960078828866875\", \"price\":\"0.73\", \"size\":\"504\", \"side\":\"BUY\", \"hash\":\"3245f62384c03945e819d4eb6460f3859c78a71b\", \"best_bid\":\"0.86\", \"best_ask\":\"0.87\"}, {\"asset_id\":\"114356653315647913247200886351065428002113119844334520181865067698979836634569\", \"price\":\"0.27\", \"size\":\"504\", \"side\":\"SELL\", \"hash\":\"f7a0e51eb55c27b84a3ea827abe2bb039b6410f8\", \"best_bid\":\"0.13\", \"best_ask\":\"0.14\"}], \"timestamp\":\"1789987928601\", \"event_type\":\"price_change\"}","raw_base64":null}
{"received_ms":1789987928625,"monotonic_ns":1019369455907900,"raw":"{\"market\":\"0x28a45972fccdaf0fba75dacc59725521035e177d09dd92174f9f52740bccb025\", \"price_changes\":[{\"asset_id\":\"61819828071723399190623735325323968706432622380635304641786792960078828866875\", \"price\":\"0.73\", \"size\":\"404\", \"side\":\"BUY\", \"hash\":\"9aa4d97584a7b82d7568e3f18a429b0407da0579\", \"best_bid\":\"0.86\", \"best_ask\":\"0.87\"}, {\"asset_id\":\"114356653315647913247200886351065428002113119844334520181865067698979836634569\", \"price\":\"0.27\", \"size\":\"404\", \"side\":\"SELL\", \"hash\":\"57adf086eedb5f25e08a553eb412e62fc13798f9\", \"best_bid\":\"0.13\", \"best_ask\":\"0.14\"}], \"timestamp\":\"1789987928605\", \"event_type\":\"price_change\"}","raw_base64":null}
{"received_ms":1789987928635,"monotonic_ns":1019369465961400,"raw":"{\"market\":\"0x28a45972fccdaf0fba75dacc59725521035e177d09dd92174f9f52740bccb025\", \"price_changes\":[{\"asset_id\":\"61819828071723399190623735325323968706432622380635304641786792960078828866875\", \"price\":\"0.85\", \"size\":\"2961.35\", \"side\":\"BUY\", \"hash\":\"5ee267849a0a6c9348af4ea4af014a4fbffc5510\", \"best_bid\":\"0.86\", \"best_ask\":\"0.87\"}, {\"asset_id\":\"114356653315647913247200886351065428002113119844334520181865067698979836634569\", \"price\":\"0.15\", \"size\":\"2961.35\", \"side\":\"SELL\", \"hash\":\"f9e6548f98e4a3e12d70331cdc6920d3df7d04fa\", \"best_bid\":\"0.13\", \"best_ask\":\"0.14\"}], \"timestamp\":\"1789987928615\", \"event_type\":\"price_change\"}","raw_base64":null}
{"received_ms":1789987928640,"monotonic_ns":1019369470671600,"raw":"{\"market\":\"0x28a45972fccdaf0fba75dacc59725521035e177d09dd92174f9f52740bccb025\", \"price_changes\":[{\"asset_id\":\"61819828071723399190623735325323968706432622380635304641786792960078828866875\", \"price\":\"0.85\", \"size\":\"2971.35\", \"side\":\"BUY\", \"hash\":\"59525bc0d35ca562372bbd5c24fa7c1b29c58d05\", \"best_bid\":\"0.86\", \"best_ask\":\"0.87\"}, {\"asset_id\":\"114356653315647913247200886351065428002113119844334520181865067698979836634569\", \"price\":\"0.15\", \"size\":\"2971.35\", \"side\":\"SELL\", \"hash\":\"86f22cf0ba321cd673445de6f82440d5a216acf3\", \"best_bid\":\"0.13\", \"best_ask\":\"0.14\"}], \"timestamp\":\"1789987928619\", \"event_type\":\"price_change\"}","raw_base64":null}
{"received_ms":1789987928643,"monotonic_ns":1019369474078000,"raw":"{\"market\":\"0x28a45972fccdaf0fba75dacc59725521035e177d09dd92174f9f52740bccb025\", \"price_changes\":[{\"asset_id\":\"61819828071723399190623735325323968706432622380635304641786792960078828866875\", \"price\":\"0.86\", \"size\":\"3575\", \"side\":\"BUY\", \"hash\":\"68475f7a9a5fc47c093d693c0567be9bc8cb2f93\", \"best_bid\":\"0.86\", \"best_ask\":\"0.87\"}, {\"asset_id\":\"114356653315647913247200886351065428002113119844334520181865067698979836634569\", \"price\":\"0.14\", \"size\":\"3575\", \"side\":\"SELL\", \"hash\":\"a75aee9521cb5f87659b353eceba5cab426e1278\", \"best_bid\":\"0.13\", \"best_ask\":\"0.14\"}], \"timestamp\":\"1789987928623\", \"event_type\":\"price_change\"}","raw_base64":null}
{"received_ms":1789987928645,"monotonic_ns":1019369476162300,"raw":"{\"market\":\"0x28a45972fccdaf0fba75dacc59725521035e177d09dd92174f9f52740bccb025\", \"price_changes\":[{\"asset_id\":\"61819828071723399190623735325323968706432622380635304641786792960078828866875\", \"price\":\"0.86\", \"size\":\"3585\", \"side\":\"BUY\", \"hash\":\"db2b6f093e43be2351296a8606f77689bbe0f6d8\", \"best_bid\":\"0.86\", \"best_ask\":\"0.87\"}, {\"asset_id\":\"114356653315647913247200886351065428002113119844334520181865067698979836634569\", \"price\":\"0.14\", \"size\":\"3585\", \"side\":\"SELL\", \"hash\":\"318e7fa0656e78868c00f76832cd0bedcfa9c3c1\", \"best_bid\":\"0.13\", \"best_ask\":\"0.14\"}], \"timestamp\":\"1789987928624\", \"event_type\":\"price_change\"}","raw_base64":null}
{"received_ms":1789987928655,"monotonic_ns":1019369485653600,"raw":"{\"market\":\"0x28a45972fccdaf0fba75dacc59725521035e177d09dd92174f9f52740bccb025\", \"price_changes\":[{\"asset_id\":\"61819828071723399190623735325323968706432622380635304641786792960078828866875\", \"price\":\"0.75\", \"size\":\"520\", \"side\":\"BUY\", \"hash\":\"9e065dc12bb13c4d2c8dee05afac3c9410955ab6\", \"best_bid\":\"0.86\", \"best_ask\":\"0.87\"}, {\"asset_id\":\"114356653315647913247200886351065428002113119844334520181865067698979836634569\", \"price\":\"0.25\", \"size\":\"520\", \"side\":\"SELL\", \"hash\":\"d4399e63106f0d051141c1e09e118abdd052fb09\", \"best_bid\":\"0.13\", \"best_ask\":\"0.14\"}], \"timestamp\":\"1789987928635\", \"event_type\":\"price_change\"}","raw_base64":null}
{"received_ms":1789987928655,"monotonic_ns":1019369485709300,"raw":"{\"market\":\"0x28a45972fccdaf0fba75dacc59725521035e177d09dd92174f9f52740bccb025\", \"price_changes\":[{\"asset_id\":\"61819828071723399190623735325323968706432622380635304641786792960078828866875\", \"price\":\"0.76\", \"size\":\"424.91\", \"side\":\"BUY\", \"hash\":\"9e065dc12bb13c4d2c8dee05afac3c9410955ab6\", \"best_bid\":\"0.86\", \"best_ask\":\"0.87\"}, {\"asset_id\":\"114356653315647913247200886351065428002113119844334520181865067698979836634569\", \"price\":\"0.24\", \"size\":\"424.91\", \"side\":\"SELL\", \"hash\":\"d4399e63106f0d051141c1e09e118abdd052fb09\", \"best_bid\":\"0.13\", \"best_ask\":\"0.14\"}], \"timestamp\":\"1789987928635\", \"event_type\":\"price_change\"}","raw_base64":null}
{"received_ms":1789987928671,"monotonic_ns":1019369501956200,"raw":"{\"market\":\"0x28a45972fccdaf0fba75dacc59725521035e177d09dd92174f9f52740bccb025\", \"price_changes\":[{\"asset_id\":\"61819828071723399190623735325323968706432622380635304641786792960078828866875\", \"price\":\"0.86\", \"size\":\"3600.17\", \"side\":\"BUY\", \"hash\":\"d3d0d64ff8e77f2ad9f06a27e496858646aa089c\", \"best_bid\":\"0.86\", \"best_ask\":\"0.87\"}, {\"asset_id\":\"114356653315647913247200886351065428002113119844334520181865067698979836634569\", \"price\":\"0.14\", \"size\":\"3600.17\", \"side\":\"SELL\", \"hash\":\"648bc8395567a69f457e4a9cba0b6e8306c5770e\", \"best_bid\":\"0.13\", \"best_ask\":\"0.14\"}], \"timestamp\":\"1789987928650\", \"event_type\":\"price_change\"}","raw_base64":null}
{"received_ms":1789987928681,"monotonic_ns":1019369511689200,"raw":"{\"market\":\"0x28a45972fccdaf0fba75dacc59725521035e177d09dd92174f9f52740bccb025\", \"price_changes\":[{\"asset_id\":\"114356653315647913247200886351065428002113119844334520181865067698979836634569\", \"price\":\"0.07\", \"size\":\"6196.71\", \"side\":\"BUY\", \"hash\":\"4bbf9e16d6a45810c1cc7c771bc3097869977615\", \"best_bid\":\"0.13\", \"best_ask\":\"0.14\"}, {\"asset_id\":\"61819828071723399190623735325323968706432622380635304641786792960078828866875\", \"price\":\"0.93\", \"size\":\"6196.71\", \"side\":\"SELL\", \"hash\":\"4891816f802aab6868ebe13218ba78b2e54acc4b\", \"best_bid\":\"0.86\", \"best_ask\":\"0.87\"}], \"timestamp\":\"1789987928661\", \"event_type\":\"price_change\"}","raw_base64":null}
{"received_ms":1789987928687,"monotonic_ns":1019369517424400,"raw":"{\"market\":\"0x28a45972fccdaf0fba75dacc59725521035e177d09dd92174f9f52740bccb025\", \"price_changes\":[{\"asset_id\":\"61819828071723399190623735325323968706432622380635304641786792960078828866875\", \"price\":\"0.73\", \"size\":\"504\", \"side\":\"BUY\", \"hash\":\"73652a6643dd0202cab68c94c0c9ed8fa7176cd2\", \"best_bid\":\"0.86\", \"best_ask\":\"0.87\"}, {\"asset_id\":\"114356653315647913247200886351065428002113119844334520181865067698979836634569\", \"price\":\"0.27\", \"size\":\"504\", \"side\":\"SELL\", \"hash\":\"afe87cbd1f6c6b870c922b27524501ce41540abd\", \"best_bid\":\"0.13\", \"best_ask\":\"0.14\"}], \"timestamp\":\"1789987928667\", \"event_type\":\"price_change\"}","raw_base64":null}
{"received_ms":1789987928694,"monotonic_ns":1019369524937800,"raw":"{\"market\":\"0x28a45972fccdaf0fba75dacc59725521035e177d09dd92174f9f52740bccb025\", \"price_changes\":[{\"asset_id\":\"114356653315647913247200886351065428002113119844334520181865067698979836634569\", \"price\":\"0.01\", \"size\":\"1609.43\", \"side\":\"BUY\", \"hash\":\"44d1b5f0256d2554e6a57db2d137c93aeaee483b\", \"best_bid\":\"0.13\", \"best_ask\":\"0.14\"}, {\"asset_id\":\"61819828071723399190623735325323968706432622380635304641786792960078828866875\", \"price\":\"0.99\", \"size\":\"1609.43\", \"side\":\"SELL\", \"hash\":\"1a00676a96aa39ce42db57c431d93c97c00406e1\", \"best_bid\":\"0.86\", \"best_ask\":\"0.87\"}], \"timestamp\":\"1789987928673\", \"event_type\":\"price_change\"}","raw_base64":null}
{"received_ms":1789987928702,"monotonic_ns":1019369532616400,"raw":"{\"market\":\"0x28a45972fccdaf0fba75dacc59725521035e177d09dd92174f9f52740bccb025\", \"price_changes\":[{\"asset_id\":\"61819828071723399190623735325323968706432622380635304641786792960078828866875\", \"price\":\"0.73\", \"size\":\"404\", \"side\":\"BUY\", \"hash\":\"44301dc6dbcd0247e65b33510f697cde4e1a36c6\", \"best_bid\":\"0.86\", \"best_ask\":\"0.87\"}, {\"asset_id\":\"114356653315647913247200886351065428002113119844334520181865067698979836634569\", \"price\":\"0.27\", \"size\":\"404\", \"side\":\"SELL\", \"hash\":\"664f0a631382edb047e44749ff5588ea20d912ef\", \"best_bid\":\"0.13\", \"best_ask\":\"0.14\"}], \"timestamp\":\"1789987928682\", \"event_type\":\"price_change\"}","raw_base64":null}
{"received_ms":1789987928713,"monotonic_ns":1019369544140100,"raw":"{\"market\":\"0x28a45972fccdaf0fba75dacc59725521035e177d09dd92174f9f52740bccb025\", \"price_changes\":[{\"asset_id\":\"114356653315647913247200886351065428002113119844334520181865067698979836634569\", \"price\":\"0.06\", \"size\":\"5298.67\", \"side\":\"BUY\", \"hash\":\"bff7f2187e0a262fe1a88df65162e3291fcf4600\", \"best_bid\":\"0.13\", \"best_ask\":\"0.14\"}, {\"asset_id\":\"61819828071723399190623735325323968706432622380635304641786792960078828866875\", \"price\":\"0.94\", \"size\":\"5298.67\", \"side\":\"SELL\", \"hash\":\"8c923aa23288407a1537f235b1d2214025dde29c\", \"best_bid\":\"0.86\", \"best_ask\":\"0.87\"}], \"timestamp\":\"1789987928693\", \"event_type\":\"price_change\"}","raw_base64":null}
{"received_ms":1789987928716,"monotonic_ns":1019369547249800,"raw":"{\"market\":\"0x28a45972fccdaf0fba75dacc59725521035e177d09dd92174f9f52740bccb025\", \"price_changes\":[{\"asset_id\":\"114356653315647913247200886351065428002113119844334520181865067698979836634569\", \"price\":\"0.13\", \"size\":\"265\", \"side\":\"BUY\", \"hash\":\"6eb971054f6eb4fd9ca10cad142387644a3354cf\", \"best_bid\":\"0.13\", \"best_ask\":\"0.14\"}, {\"asset_id\":\"61819828071723399190623735325323968706432622380635304641786792960078828866875\", \"price\":\"0.87\", \"size\":\"265\", \"side\":\"SELL\", \"hash\":\"2f464cbbd1afdc6f3a672c0252102f6ce89b2e6d\", \"best_bid\":\"0.86\", \"best_ask\":\"0.87\"}], \"timestamp\":\"1789987928697\", \"event_type\":\"price_change\"}","raw_base64":null}
