{"received_ms":1789987926134,"monotonic_ns":1019366964659600,"raw":"[{\"market\":\"0x28a45972fccdaf0fba75dacc59725521035e177d09dd92174f9f52740bccb025\",\"asset_id\":\"114356653315647913247200886351065428002113119844334520181865067698979836634569\",\"timestamp\":\"1789987926108\",\"hash\":\"db0ae2c506077851a9e320258152d3145dba5e35\",\"bids\":[{\"price\":\"0.01\",\"size\":\"1694.43\"},{\"price\":\"0.02\",\"size\":\"567.82\"},{\"price\":\"0.03\",\"size\":\"3852.57\"},{\"price\":\"0.04\",\"size\":\"763.48\"},{\"price\":\"0.05\",\"size\":\"11850\"},{\"price\":\"0.06\",\"size\":\"5328.67\"},{\"price\":\"0.07\",\"size\":\"4051.71\"},{\"price\":\"0.08\",\"size\":\"547.5\"},{\"price\":\"0.09\",\"size\":\"770.12\"},{\"price\":\"0.1\",\"size\":\"337\"},{\"price\":\"0.11\",\"size\":\"118.1\"},{\"price\":\"0.12\",\"size\":\"250\"},{\"price\":\"0.13\",\"size\":\"245\"}],\"asks\":[{\"price\":\"0.99\",\"size\":\"1491.91\"},{\"price\":\"0.98\",\"size\":\"385.35\"},{\"price\":\"0.97\",\"size\":\"1270.08\"},{\"price\":\"0.96\",\"size\":\"165.3\"},{\"price\":\"0.95\",\"size\":\"237.01\"},{\"price\":\"0.94\",\"size\":\"85.67\"},{\"price\":\"0.93\",\"size\":\"159.29\"},{\"price\":\"0.92\",\"size\":\"81.51\"},{\"price\":\"0.91\",\"size\":\"252.12\"},{\"price\":\"0.9\",\"size\":\"99.01\"},{\"price\":\"0.89\",\"size\":\"129.1\"},{\"price\":\"0.88\",\"size\":\"67.34\"},{\"price\":\"0.87\",\"size\":\"123.7\"},{\"price\":\"0.86\",\"size\":\"66.15\"},{\"price\":\"0.85\",\"size\":\"197.39\"},{\"price\":\"0.84\",\"size\":\"65.25\"},{\"price\":\"0.83\",\"size\":\"115.89\"},{\"price\":\"0.82\",\"size\":\"64.56\"},{\"price\":\"0.81\",\"size\":\"113.27\"},{\"price\":\"0.8\",\"size\":\"74.81\"},{\"price\":\"0.79\",\"size\":\"112\"},{\"price\":\"0.78\",\"size\":\"64\"},{\"price\":\"0.77\",\"size\":\"111\"},{\"price\":\"0.76\",\"size\":\"64\"},{\"price\":\"0.75\",\"size\":\"110\"},{\"price\":\"0.74\",\"size\":\"250\"},{\"price\":\"0.73\",\"size\":\"289\"},{\"price\":\"0.72\",\"size\":\"244\"},{\"price\":\"0.71\",\"size\":\"297\"},{\"price\":\"0.7\",\"size\":\"281\"},{\"price\":\"0.69\",\"size\":\"297\"},{\"price\":\"0.68\",\"size\":\"267\"},{\"price\":\"0.67\",\"size\":\"310\"},{\"price\":\"0.66\",\"size\":\"272.64\"},{\"price\":\"0.65\",\"size\":\"297\"},{\"price\":\"0.64\",\"size\":\"285.33\"},{\"price\":\"0.63\",\"size\":\"297\"},{\"price\":\"0.62\",\"size\":\"272.05\"},{\"price\":\"0.61\",\"size\":\"310\"},{\"price\":\"0.6\",\"size\":\"1067\"},{\"price\":\"0.59\",\"size\":\"297\"},{\"price\":\"0.58\",\"size\":\"279\"},{\"price\":\"0.57\",\"size\":\"297\"},{\"price\":\"0.56\",\"size\":\"267\"},{\"price\":\"0.55\",\"size\":\"297\"},{\"price\":\"0.54\",\"size\":\"267\"},{\"price\":\"0.53\",\"size\":\"302\"},{\"price\":\"0.52\",\"size\":\"267\"},{\"price\":\"0.51\",\"size\":\"297\"},{\"price\":\"0.5\",\"size\":\"267\"},{\"price\":\"0.49\",\"size\":\"297\"},{\"price\":\"0.48\",\"size\":\"267\"},{\"price\":\"0.47\",\"size\":\"297\"},{\"price\":\"0.46\",\"size\":\"267\"},{\"price\":\"0.45\",\"size\":\"297\"},{\"price\":\"0.44\",\"size\":\"267\"},{\"price\":\"0.43\",\"size\":\"309\"},{\"price\":\"0.42\",\"size\":\"267\"},{\"price\":\"0.41\",\"size\":\"297\"},{\"price\":\"0.4\",\"size\":\"279\"},{\"price\":\"0.39\",\"size\":\"297\"},{\"price\":\"0.38\",\"size\":\"267\"},{\"price\":\"0.37\",\"size\":\"309\"},{\"price\":\"0.36\",\"size\":\"267\"},{\"price\":\"0.35\",\"size\":\"297\"},{\"price\":\"0.34\",\"size\":\"267\"},{\"price\":\"0.33\",\"size\":\"322\"},{\"price\":\"0.32\",\"size\":\"292\"},{\"price\":\"0.31\",\"size\":\"322\"},{\"price\":\"0.3\",\"size\":\"292\"},{\"price\":\"0.29\",\"size\":\"372\"},{\"price\":\"0.28\",\"size\":\"438.8\"},{\"price\":\"0.27\",\"size\":\"409\"},{\"price\":\"0.26\",\"size\":\"455.53\"},{\"price\":\"0.25\",\"size\":\"420\"},{\"price\":\"0.24\",\"size\":\"380\"},{\"price\":\"0.23\",\"size\":\"587.49\"},{\"price\":\"0.22\",\"size\":\"473.82\"},{\"price\":\"0.21\",\"size\":\"422\"},{\"price\":\"0.2\",\"size\":\"569\"},{\"price\":\"0.19\",\"size\":\"743\"},{\"price\":\"0.18\",\"size\":\"600\"},{\"price\":\"0.17\",\"size\":\"2358\"},{\"price\":\"0.16\",\"size\":\"4726\"},{\"price\":\"0.15\",\"size\":\"8521.35\"},{\"price\":\"0.14\",\"size\":\"614\"}],\"tick_size\":\"0.01\",\"event_type\":\"book\",\"last_trade_price\":\"0.850\"},{\"market\":\"0x28a45972fccdaf0fba75dacc59725521035e177d09dd92174f9f52740bccb025\",\"asset_id\":\"61819828071723399190623735325323968706432622380635304641786792960078828866875\",\"timestamp\":\"1789987926108\",\"hash\":\"7965acf1011ed53b933cb041904d4c00651eedeb\",\"bids\":[{\"price\":\"0.01\",\"size\":\"1491.91\"},{\"price\":\"0.02\",\"size\":\"385.35\"},{\"price\":\"0.03\",\"size\":\"1270.08\"},{\"price\":\"0.04\",\"size\":\"165.3\"},{\"price\":\"0.05\",\"size\":\"237.01\"},{\"price\":\"0.06\",\"size\":\"85.67\"},{\"price\":\"0.07\",\"size\":\"159.29\"},{\"price\":\"0.08\",\"size\":\"81.51\"},{\"price\":\"0.09\",\"size\":\"252.12\"},{\"price\":\"0.1\",\"size\":\"99.01\"},{\"price\":\"0.11\",\"size\":\"129.1\"},{\"price\":\"0.12\",\"size\":\"67.34\"},{\"price\":\"0.13\",\"size\":\"123.7\"},{\"price\":\"0.14\",\"size\":\"66.15\"},{\"price\":\"0.15\",\"size\":\"197.39\"},{\"price\":\"0.16\",\"size\":\"65.25\"},{\"price\":\"0.17\",\"size\":\"115.89\"},{\"price\":\"0.18\",\"size\":\"64.56\"},{\"price\":\"0.19\",\"size\":\"113.27\"},{\"price\":\"0.2\",\"size\":\"74.81\"},{\"price\":\"0.21\",\"size\":\"112\"},{\"price\":\"0.22\",\"size\":\"64\"},{\"price\":\"0.23\",\"size\":\"111\"},{\"price\":\"0.24\",\"size\":\"64\"},{\"price\":\"0.25\",\"size\":\"110\"},{\"price\":\"0.26\",\"size\":\"250\"},{\"price\":\"0.27\",\"size\":\"289\"},{\"price\":\"0.28\",\"size\":\"244\"},{\"price\":\"0.29\",\"size\":\"297\"},{\"price\":\"0.3\",\"size\":\"281\"},{\"price\":\"0.31\",\"size\":\"297\"},{\"price\":\"0.32\",\"size\":\"267\"},{\"price\":\"0.33\",\"size\":\"310\"},{\"price\":\"0.34\",\"size\":\"272.64\"},{\"price\":\"0.35\",\"size\":\"297\"},{\"price\":\"0.36\",\"size\":\"285.33\"},{\"price\":\"0.37\",\"size\":\"297\"},{\"price\":\"0.38\",\"size\":\"272.05\"},{\"price\":\"0.39\",\"size\":\"310\"},{\"price\":\"0.4\",\"size\":\"1067\"},{\"price\":\"0.41\",\"size\":\"297\"},{\"price\":\"0.42\",\"size\":\"279\"},{\"price\":\"0.43\",\"size\":\"297\"},{\"price\":\"0.44\",\"size\":\"267\"},{\"price\":\"0.45\",\"size\":\"297\"},{\"price\":\"0.46\",\"size\":\"267\"},{\"price\":\"0.47\",\"size\":\"302\"},{\"price\":\"0.48\",\"size\":\"267\"},{\"price\":\"0.49\",\"size\":\"297\"},{\"price\":\"0.5\",\"size\":\"267\"},{\"price\":\"0.51\",\"size\":\"297\"},{\"price\":\"0.52\",\"size\":\"267\"},{\"price\":\"0.53\",\"size\":\"297\"},{\"price\":\"0.54\",\"size\":\"267\"},{\"price\":\"0.55\",\"size\":\"297\"},{\"price\":\"0.56\",\"size\":\"267\"},{\"price\":\"0.57\",\"size\":\"309\"},{\"price\":\"0.58\",\"size\":\"267\"},{\"price\":\"0.59\",\"size\":\"297\"},{\"price\":\"0.6\",\"size\":\"279\"},{\"price\":\"0.61\",\"size\":\"297\"},{\"price\":\"0.62\",\"size\":\"267\"},{\"price\":\"0.63\",\"size\":\"309\"},{\"price\":\"0.64\",\"size\":\"267\"},{\"price\":\"0.65\",\"size\":\"297\"},{\"price\":\"0.66\",\"size\":\"267\"},{\"price\":\"0.67\",\"size\":\"322\"},{\"price\":\"0.68\",\"size\":\"292\"},{\"price\":\"0.69\",\"size\":\"322\"},{\"price\":\"0.7\",\"size\":\"292\"},{\"price\":\"0.71\",\"size\":\"372\"},{\"price\":\"0.72\",\"size\":\"438.8\"},{\"price\":\"0.73\",\"size\":\"409\"},{\"price\":\"0.74\",\"size\":\"455.53\"},{\"price\":\"0.75\",\"size\":\"420\"},{\"price\":\"0.76\",\"size\":\"380\"},{\"price\":\"0.77\",\"size\":\"587.49\"},{\"price\":\"0.78\",\"size\":\"473.82\"},{\"price\":\"0.79\",\"size\":\"422\"},{\"price\":\"0.8\",\"size\":\"569\"},{\"price\":\"0.81\",\"size\":\"743\"},{\"price\":\"0.82\",\"size\":\"600\"},{\"price\":\"0.83\",\"size\":\"2358\"},{\"price\":\"0.84\",\"size\":\"4726\"},{\"price\":\"0.85\",\"size\":\"8521.35\"},{\"price\":\"0.86\",\"size\":\"614\"}],\"asks\":[{\"price\":\"0.99\",\"size\":\"1694.43\"},{\"price\":\"0.98\",\"size\":\"567.82\"},{\"price\":\"0.97\",\"size\":\"3852.57\"},{\"price\":\"0.96\",\"size\":\"763.48\"},{\"price\":\"0.95\",\"size\":\"11850\"},{\"price\":\"0.94\",\"size\":\"5328.67\"},{\"price\":\"0.93\",\"size\":\"4051.71\"},{\"price\":\"0.92\",\"size\":\"547.5\"},{\"price\":\"0.91\",\"size\":\"770.12\"},{\"price\":\"0.9\",\"size\":\"337\"},{\"price\":\"0.89\",\"size\":\"118.1\"},{\"price\":\"0.88\",\"size\":\"250\"},{\"price\":\"0.87\",\"size\":\"245\"}],\"tick_size\":\"0.01\",\"event_type\":\"book\",\"last_trade_price\":\"0.850\"}]\n","raw_base64":null}
{"received_ms":1789987926144,"monotonic_ns":1019366974412100,"raw":"{\"market\":\"0x28a45972fccdaf0fba75dacc59725521035e177d09dd92174f9f52740bccb025\", \"price_changes\":[{\"asset_id\":\"61819828071723399190623735325323968706432622380635304641786792960078828866875\", \"price\":\"0.83\", \"size\":\"662\", \"side\":\"BUY\", \"hash\":\"2d409c3ca702db9a23f03d56f84c72875ebf608a\", \"best_bid\":\"0.86\", \"best_ask\":\"0.87\"}, {\"asset_id\":\"114356653315647913247200886351065428002113119844334520181865067698979836634569\", \"price\":\"0.17\", \"size\":\"662\", \"side\":\"SELL\", \"hash\":\"bfdf430a0aed85d9b2da73a86824737b0c9b29c3\", \"best_bid\":\"0.13\", \"best_ask\":\"0.14\"}], \"timestamp\":\"1789987926120\", \"event_type\":\"price_change\"}","raw_base64":null}
{"received_ms":1789987926144,"monotonic_ns":1019366974498200,"raw":"{\"market\":\"0x28a45972fccdaf0fba75dacc59725521035e177d09dd92174f9f52740bccb025\", \"price_changes\":[{\"asset_id\":\"61819828071723399190623735325323968706432622380635304641786792960078828866875\", \"price\":\"0.86\", \"size\":\"649.17\", \"side\":\"BUY\", \"hash\":\"e0332652109b033df7da3cfd1dde69dc85da6e54\", \"best_bid\":\"0.86\", \"best_ask\":\"0.87\"}, {\"asset_id\":\"114356653315647913247200886351065428002113119844334520181865067698979836634569\", \"price\":\"0.14\", \"size\":\"649.17\", \"side\":\"SELL\", \"hash\":\"22b0c15d0cf291e2140b8b89a3d1e1504d70d7f0\", \"best_bid\":\"0.13\", \"best_ask\":\"0.14\"}], \"timestamp\":\"1789987926121\", \"event_type\":\"price_change\"}","raw_base64":null}
{"received_ms":1789987926151,"monotonic_ns":1019366981911300,"raw":"{\"market\":\"0x28a45972fccdaf0fba75dacc59725521035e177d09dd92174f9f52740bccb025\", \"price_changes\":[{\"asset_id\":\"114356653315647913247200886351065428002113119844334520181865067698979836634569\", \"price\":\"0.13\", \"size\":\"255\", \"side\":\"BUY\", \"hash\":\"539b9252556cd114a43f84fd331bf4a4aa72fea7\", \"best_bid\":\"0.13\", \"best_ask\":\"0.14\"}, {\"asset_id\":\"61819828071723399190623735325323968706432622380635304641786792960078828866875\", \"price\":\"0.87\", \"size\":\"255\", \"side\":\"SELL\", \"hash\":\"03c4baabaf3c54fd3e2de9beb36db0a189084b38\", \"best_bid\":\"0.86\", \"best_ask\":\"0.87\"}], \"timestamp\":\"1789987926130\", \"event_type\":\"price_change\"}","raw_base64":null}
{"received_ms":1789987926157,"monotonic_ns":1019366987371200,"raw":"{\"market\":\"0x28a45972fccdaf0fba75dacc59725521035e177d09dd92174f9f52740bccb025\", \"price_changes\":[{\"asset_id\":\"114356653315647913247200886351065428002113119844334520181865067698979836634569\", \"price\":\"0.09\", \"size\":\"778.12\", \"side\":\"BUY\", \"hash\":\"61d85319d5d9128648f48ca43fc7fcee93254844\", \"best_bid\":\"0.13\", \"best_ask\":\"0.14\"}, {\"asset_id\":\"61819828071723399190623735325323968706432622380635304641786792960078828866875\", \"price\":\"0.91\", \"size\":\"778.12\", \"side\":\"SELL\", \"hash\":\"52d882813b7494061fc85f929accf7148762f328\", \"best_bid\":\"0.86\", \"best_ask\":\"0.87\"}], \"timestamp\":\"1789987926135\", \"event_type\":\"price_change\"}","raw_base64":null}
{"received_ms":1789987926158,"monotonic_ns":1019366988735100,"raw":"{\"market\":\"0x28a45972fccdaf0fba75dacc59725521035e177d09dd92174f9f52740bccb025\", \"price_changes\":[{\"asset_id\":\"61819828071723399190623735325323968706432622380635304641786792960078828866875\", \"price\":\"0.83\", \"size\":\"597\", \"side\":\"BUY\", \"hash\":\"500308c4eb45d5164b35349f9632bb928aa23822\", \"best_bid\":\"0.86\", \"best_ask\":\"0.87\"}, {\"asset_id\":\"114356653315647913247200886351065428002113119844334520181865067698979836634569\", \"price\":\"0.17\", \"size\":\"597\", \"side\":\"SELL\", \"hash\":\"81f40cc4b6fc8dc5593e205677fef46729d026bd\", \"best_bid\":\"0.13\", \"best_ask\":\"0.14\"}], \"timestamp\":\"1789987926137\", \"event_type\":\"price_change\"}","raw_base64":null}
{"received_ms":1789987926162,"monotonic_ns":1019366992357000,"raw":"{\"market\":\"0x28a45972fccdaf0fba75dacc59725521035e177d09dd92174f9f52740bccb025\", \"price_changes\":[{\"asset_id\":\"114356653315647913247200886351065428002113119844334520181865067698979836634569\", \"price\":\"0.06\", \"size\":\"6565.67\", \"side\":\"BUY\", \"hash\":\"042331e81ccbabf3249b225c327000c181bf2673\", \"best_bid\":\"0.13\", \"best_ask\":\"0.14\"}, {\"asset_id\":\"61819828071723399190623735325323968706432622380635304641786792960078828866875\", \"price\":\"0.94\", \"size\":\"6565.67\", \"side\":\"SELL\", \"hash\":\"1ee2512be3d59145602d4101ba37fa33d3ebda36\", \"best_bid\":\"0.86\", \"best_ask\":\"0.87\"}], \"timestamp\":\"1789987926141\", \"event_type\":\"price_change\"}","raw_base64":null}
{"received_ms":1789987926164,"monotonic_ns":1019366994589600,"raw":"{\"market\":\"0x28a45972fccdaf0fba75dacc59725521035e177d09dd92174f9f52740bccb025\", \"price_changes\":[{\"asset_id\":\"114356653315647913247200886351065428002113119844334520181865067698979836634569\", \"price\":\"0.05\", \"size\":\"11868\", \"side\":\"BUY\", \"hash\":\"87a51febab3c09433325b9a6a58028eec8b1640c\", \"best_bid\":\"0.13\", \"best_ask\":\"0.14\"}, {\"asset_id\":\"61819828071723399190623735325323968706432622380635304641786792960078828866875\", \"price\":\"0.95\", \"size\":\"11868\", \"side\":\"SELL\", \"hash\":\"5b18859fca87712984d7cbd63785f54f487d049c\", \"best_bid\":\"0.86\", \"best_ask\":\"0.87\"}], \"timestamp\":\"1789987926142\", \"event_type\":\"price_change\"}","raw_base64":null}
{"received_ms":1789987926165,"monotonic_ns":1019366995542800,"raw":"{\"market\":\"0x28a45972fccdaf0fba75dacc59725521035e177d09dd92174f9f52740bccb025\", \"price_changes\":[{\"asset_id\":\"61819828071723399190623735325323968706432622380635304641786792960078828866875\", \"price\":\"0.93\", \"size\":\"782.71\", \"side\":\"SELL\", \"hash\":\"95bb87b228f0abee56e1315c79122092cf00256a\", \"best_bid\":\"0.86\", \"best_ask\":\"0.87\"}, {\"asset_id\":\"114356653315647913247200886351065428002113119844334520181865067698979836634569\", \"price\":\"0.07\", \"size\":\"782.71\", \"side\":\"BUY\", \"hash\":\"d86e8e647fa87150d3fec4fab8210719e22cc9e9\", \"best_bid\":\"0.13\", \"best_ask\":\"0.14\"}], \"timestamp\":\"1789987926144\", \"event_type\":\"price_change\"}","raw_base64":null}
{"received_ms":1789987926165,"monotonic_ns":1019366995607900,"raw":"{\"market\":\"0x28a45972fccdaf0fba75dacc59725521035e177d09dd92174f9f52740bccb025\", \"price_changes\":[{\"asset_id\":\"114356653315647913247200886351065428002113119844334520181865067698979836634569\", \"price\":\"0.05\", \"size\":\"613\", \"side\":\"BUY\", \"hash\":\"d86e8e647fa87150d3fec4fab8210719e22cc9e9\", \"best_bid\":\"0.13\", \"best_ask\":\"0.14\"}, {\"asset_id\":\"61819828071723399190623735325323968706432622380635304641786792960078828866875\", \"price\":\"0.95\", \"size\":\"613\", \"side\":\"SELL\", \"hash\":\"95bb87b228f0abee56e1315c79122092cf00256a\", \"best_bid\":\"0.86\", \"best_ask\":\"0.87\"}], \"timestamp\":\"1789987926144\", \"event_type\":\"price_change\"}","raw_base64":null}
{"received_ms":1789987926166,"monotonic_ns":1019366996403200,"raw":"{\"market\":\"0x28a45972fccdaf0fba75dacc59725521035e177d09dd92174f9f52740bccb025\", \"price_changes\":[{\"asset_id\":\"114356653315647913247200886351065428002113119844334520181865067698979836634569\", \"price\":\"0.07\", \"size\":\"782.71\", \"side\":\"BUY\", \"hash\":\"d86e8e647fa87150d3fec4fab8210719e22cc9e9\", \"best_bid\":\"0.13\", \"best_ask\":\"0.14\"}, {\"asset_id\":\"61819828071723399190623735325323968706432622380635304641786792960078828866875\", \"price\":\"0.93\", \"size\":\"782.71\", \"side\":\"SELL\", \"hash\":\"95bb87b228f0abee56e1315c79122092cf00256a\", \"best_bid\":\"0.86\", \"best_ask\":\"0.87\"}], \"timestamp\":\"1789987926144\", \"event_type\":\"price_change\"}","raw_base64":null}
{"received_ms":1789987926168,"monotonic_ns":1019366998667000,"raw":"{\"market\":\"0x28a45972fccdaf0fba75dacc59725521035e177d09dd92174f9f52740bccb025\", \"price_changes\":[{\"asset_id\":\"61819828071723399190623735325323968706432622380635304641786792960078828866875\", \"price\":\"0.78\", \"size\":\"433.82\", \"side\":\"BUY\", \"hash\":\"538690dc35d9aad3e1d07d93be4aedfbbe9da4f9\", \"best_bid\":\"0.86\", \"best_ask\":\"0.87\"}, {\"asset_id\":\"114356653315647913247200886351065428002113119844334520181865067698979836634569\", \"price\":\"0.22\", \"size\":\"433.82\", \"side\":\"SELL\", \"hash\":\"b9174fbf84dc326730d1800ec3dba951eefdca67\", \"best_bid\":\"0.13\", \"best_ask\":\"0.14\"}], \"timestamp\":\"1789987926147\", \"event_type\":\"price_change\"}","raw_base64":null}
{"received_ms":1789987926170,"monotonic_ns":1019367000391700,"raw":"{\"market\":\"0x28a45972fccdaf0fba75dacc59725521035e177d09dd92174f9f52740bccb025\", \"price_changes\":[{\"asset_id\":\"61819828071723399190623735325323968706432622380635304641786792960078828866875\", \"price\":\"0.84\", \"size\":\"4666\", \"side\":\"BUY\", \"hash\":\"538690dc35d9aad3e1d07d93be4aedfbbe9da4f9\", \"best_bid\":\"0.86\", \"best_ask\":\"0.87\"}, {\"asset_id\":\"114356653315647913247200886351065428002113119844334520181865067698979836634569\", \"price\":\"0.16\", \"size\":\"4666\", \"side\":\"SELL\", \"hash\":\"b9174fbf84dc326730d1800ec3dba951eefdca67\", \"best_bid\":\"0.13\", \"best_ask\":\"0.14\"}], \"timestamp\":\"1789987926147\", \"event_type\":\"price_change\"}","raw_base64":null}
{"received_ms":1789987926170,"monotonic_ns":1019367000441800,"raw":"{\"market\":\"0x28a45972fccdaf0fba75dacc59725521035e177d09dd92174f9f52740bccb025\", \"price_changes\":[{\"asset_id\":\"114356653315647913247200886351065428002113119844334520181865067698979836634569\", \"price\":\"0.1\", \"size\":\"317\", \"side\":\"BUY\", \"hash\":\"b9174fbf84dc326730d1800ec3dba951eefdca67\", \"best_bid\":\"0.13\", \"best_ask\":\"0.14\"}, {\"asset_id\":\"61819828071723399190623735325323968706432622380635304641786792960078828866875\", \"price\":\"0.9\", \"size\":\"317\", \"side\":\"SELL\", \"hash\":\"538690dc35d9aad3e1d07d93be4aedfbbe9da4f9\", \"best_bid\":\"0.86\", \"best_ask\":\"0.87\"}], \"timestamp\":\"1789987926147\", \"event_type\":\"price_change\"}","raw_base64":null}
{"received_ms":1789987926172,"monotonic_ns":1019367002988800,"raw":"{\"market\":\"0x28a45972fccdaf0fba75dacc59725521035e177d09dd92174f9f52740bccb025\", \"price_changes\":[{\"asset_id\":\"61819828071723399190623735325323968706432622380635304641786792960078828866875\", \"price\":\"0.85\", \"size\":\"3784.35\", \"side\":\"BUY\", \"hash\":\"2a403371dfdd4a257c3e7a13af9e0d7207b7e054\", \"best_bid\":\"0.86\", \"best_ask\":\"0.87\"}, {\"asset_id\":\"114356653315647913247200886351065428002113119844334520181865067698979836634569\", \"price\":\"0.15\", \"size\":\"3784.35\", \"side\":\"SELL\", \"hash\":\"552aa0b00c19fc928383a161124fee4127a36d56\", \"best_bid\":\"0.13\", \"best_ask\":\"0.14\"}], \"timestamp\":\"1789987926150\", \"event_type\":\"price_change\"}","raw_base64":null}
{"received_ms":1789987926175,"monotonic_ns":1019367006180200,"raw":"{\"market\":\"0x28a45972fccdaf0fba75dacc59725521035e177d09dd92174f9f52740bccb025\", \"price_changes\":[{\"asset_id\":\"61819828071723399190623735325323968706432622380635304641786792960078828866875\", \"price\":\"0.86\", \"size\":\"639.17\", \"side\":\"BUY\", \"hash\":\"e26414309116b692f4a95e3dcd9f99a28d4341ea\", \"best_bid\":\"0.86\", \"best_ask\":\"0.87\"}, {\"asset_id\":\"114356653315647913247200886351065428002113119844334520181865067698979836634569\", \"price\":\"0.14\", \"size\":\"639.17\", \"side\":\"SELL\", \"hash\":\"044c145b2ccc9cbd269ea905cf2a1dcc2f796702\", \"best_bid\":\"0.13\", \"best_ask\":\"0.14\"}], \"timestamp\":\"1789987926153\", \"event_type\":\"price_change\"}","raw_base64":null}
{"received_ms":1789987926178,"monotonic_ns":1019367008959000,"raw":"{\"market\":\"0x28a45972fccdaf0fba75dacc59725521035e177d09dd92174f9f52740bccb025\", \"price_changes\":[{\"asset_id\":\"114356653315647913247200886351065428002113119844334520181865067698979836634569\", \"price\":\"0.12\", \"size\":\"260\", \"side\":\"BUY\", \"hash\":\"5b18ef799c2411ea501eb948a007a6f524c2e39b\", \"best_bid\":\"0.13\", \"best_ask\":\"0.14\"}, {\"asset_id\":\"61819828071723399190623735325323968706432622380635304641786792960078828866875\", \"price\":\"0.88\", \"size\":\"260\", \"side\":\"SELL\", \"hash\":\"d67700f76cdc3a8762837efdded3418474bfee44\", \"best_bid\":\"0.86\", \"best_ask\":\"0.87\"}], \"timestamp\":\"1789987926157\", \"event_type\":\"price_change\"}","raw_base64":null}
{"received_ms":1789987926184,"monotonic_ns":1019367015061600,"raw":"{\"market\":\"0x28a45972fccdaf0fba75dacc59725521035e177d09dd92174f9f52740bccb025\", \"price_changes\":[{\"asset_id\":\"61819828071723399190623735325323968706432622380635304641786792960078828866875\", \"price\":\"0.76\", \"size\":\"390\", \"side\":\"BUY\", \"hash\":\"6c94c225e26663caf65c6cdc727b1e4ec767cf54\", \"best_bid\":\"0.86\", \"best_ask\":\"0.87\"}, {\"asset_id\":\"114356653315647913247200886351065428002113119844334520181865067698979836634569\", \"price\":\"0.24\", \"size\":\"390\", \"side\":\"SELL\", \"hash\":\"2a9b164ef7284859b601890e7d3e03212210200e\", \"best_bid\":\"0.13\", \"best_ask\":\"0.14\"}], \"timestamp\":\"1789987926160\", \"event_type\":\"price_change\"}","raw_base64":null}
{"received_ms":1789987926193,"monotonic_ns":1019367023629200,"raw":"{\"market\":\"0x28a45972fccdaf0fba75dacc59725521035e177d09dd92174f9f52740bccb025\", \"price_changes\":[{\"asset_id\":\"61819828071723399190623735325323968706432622380635304641786792960078828866875\", \"price\":\"0.91\", \"size\":\"698.12\", \"side\":\"SELL\", \"hash\":\"9029eabb6d5eb417b7602629a4e06d579d9f9808\", \"best_bid\":\"0.86\", \"best_ask\":\"0.87\"}, {\"asset_id\":\"114356653315647913247200886351065428002113119844334520181865067698979836634569\", \"price\":\"0.09\", \"size\":\"698.12\", \"side\":\"BUY\", \"hash\":\"c401269b5ceae285cea97d9f964cebd574d99490\", \"best_bid\":\"0.13\", \"best_ask\":\"0.14\"}], \"timestamp\":\"1789987926164\", \"event_type\":\"price_change\"}","raw_base64":null}
{"received_ms":1789987926193,"monotonic_ns":1019367023729600,"raw":"{\"market\":\"0x28a45972fccdaf0fba75dacc59725521035e177d09dd92174f9f52740bccb025\", \"price_changes\":[{\"asset_id\":\"114356653315647913247200886351065428002113119844334520181865067698979836634569\", \"price\":\"0.06\", \"size\":\"6485.67\", \"side\":\"BUY\", \"hash\":\"8f6471f7baa733e4218bf4bb2ec821477fedd346\", \"best_bid\":\"0.13\", \"best_ask\":\"0.14\"}, {\"asset_id\":\"61819828071723399190623735325323968706432622380635304641786792960078828866875\", \"price\":\"0.94\", \"size\":\"6485.67\", \"side\":\"SELL\", \"hash\":\"9b148b0b828f0adad7d1e5bd0a9c3ca9a3b00fd5\", \"best_bid\":\"0.86\", \"best_ask\":\"0.87\"}], \"timestamp\":\"1789987926164\", \"event_type\":\"price_change\"}","raw_base64":null}
{"received_ms":1789987926193,"monotonic_ns":1019367023783200,"raw":"{\"market\":\"0x28a45972fccdaf0fba75dacc59725521035e177d09dd92174f9f52740bccb025\", \"price_changes\":[{\"asset_id\":\"114356653315647913247200886351065428002113119844334520181865067698979836634569\", \"price\":\"0.04\", \"size\":\"683.48\", \"side\":\"BUY\", \"hash\":\"bfc920a2eb30d75ce5ab6d658680cd1ade6189bf\", \"best_bid\":\"0.13\", \"best_ask\":\"0.14\"}, {\"asset_id\":\"61819828071723399190623735325323968706432622380635304641786792960078828866875\", \"price\":\"0.96\", \"size\":\"683.48\", \"side\":\"SELL\", \"hash\":\"ea5ff795a7bfee68ec40f3a05165fa11953ab9ff\", \"best_bid\":\"0.86\", \"best_ask\":\"0.87\"}], \"timestamp\":\"1789987926165\", \"event_type\":\"price_change\"}","raw_base64":null}
{"received_ms":1789987926193,"monotonic_ns":1019367023831700,"raw":"{\"market\":\"0x28a45972fccdaf0fba75dacc59725521035e177d09dd92174f9f52740bccb025\", \"price_changes\":[{\"asset_id\":\"61819828071723399190623735325323968706432622380635304641786792960078828866875\", \"price\":\"0.91\", \"size\":\"618.12\", \"side\":\"SELL\", \"hash\":\"9d5f853e4a3ca845d9922e8a88ba8ad374632d99\", \"best_bid\":\"0.86\", \"best_ask\":\"0.87\"}, {\"asset_id\":\"114356653315647913247200886351065428002113119844334520181865067698979836634569\", \"price\":\"0.09\", \"size\":\"618.12\", \"side\":\"BUY\", \"hash\":\"fbc11dabbd13ce41ba31b1ca64076cee72cf397b\", \"best_bid\":\"0.13\", \"best_ask\":\"0.14\"}], \"timestamp\":\"1789987926165\", \"event_type\":\"price_change\"}","raw_base64":null}
{"received_ms":1789987926193,"monotonic_ns":1019367023877300,"raw":"{\"market\":\"0x28a45972fccdaf0fba75dacc59725521035e177d09dd92174f9f52740bccb025\", \"price_changes\":[{\"asset_id\":\"114356653315647913247200886351065428002113119844334520181865067698979836634569\", \"price\":\"0.06\", \"size\":\"6405.67\", \"side\":\"BUY\", \"hash\":\"ac9753426a89c120864059e604e166f7bf8ffcde\", \"best_bid\":\"0.13\", \"best_ask\":\"0.14\"}, {\"asset_id\":\"61819828071723399190623735325323968706432622380635304641786792960078828866875\", \"price\":\"0.94\", \"size\":\"6405.67\", \"side\":\"SELL\", \"hash\":\"77fb727c1811c77f1a4bb9f071aa8d58f49d5313\", \"best_bid\":\"0.86\", \"best_ask\":\"0.87\"}], \"timestamp\":\"1789987926167\", \"event_type\":\"price_change\"}","raw_base64":null}
{"received_ms":1789987926193,"monotonic_ns":1019367023928200,"raw":"{\"market\":\"0x28a45972fccdaf0fba75dacc59725521035e177d09dd92174f9f52740bccb025\", \"price_changes\":[{\"asset_id\":\"114356653315647913247200886351065428002113119844334520181865067698979836634569\", \"price\":\"0.07\", \"size\":\"702.71\", \"side\":\"BUY\", \"hash\":\"01eec8a1987a05931ee29e60d65f2a5c4af3552e\", \"best_bid\":\"0.13\", \"best_ask\":\"0.14\"}, {\"asset_id\":\"61819828071723399190623735325323968706432622380635304641786792960078828866875\", \"price\":\"0.93\", \"size\":\"702.71\", \"side\":\"SELL\", \"hash\":\"efa9c8930b93ed389a4bd80b8bbace6ddcb72a1c\", \"best_bid\":\"0.86\", \"best_ask\":\"0.87\"}], \"timestamp\":\"1789987926167\", \"event_type\":\"price_change\"}","raw_base64":null}
{"received_ms":1789987926193,"monotonic_ns":1019367023973500,"raw":"{\"market\":\"0x28a45972fccdaf0fba75dacc59725521035e177d09dd92174f9f52740bccb025\", \"price_changes\":[{\"asset_id\":\"61819828071723399190623735325323968706432622380635304641786792960078828866875\", \"price\":\"0.92\", \"size\":\"539.5\", \"side\":\"SELL\", \"hash\":\"756e69a1fedd17ff2395b85a384a8a99cd612a5e\", \"best_bid\":\"0.86\", \"best_ask\":\"0.87\"}, {\"asset_id\":\"114356653315647913247200886351065428002113119844334520181865067698979836634569\", \"price\":\"0.08\", \"size\":\"539.5\", \"side\":\"BUY\", \"hash\":\"6e68fcb9e5f6f433c7f0b24c6fa5117768ab5595\", \"best_bid\":\"0.13\", \"best_ask\":\"0.14\"}], \"timestamp\":\"1789987926169\", \"event_type\":\"price_change\"}","raw_base64":null}
{"received_ms":1789987926193,"monotonic_ns":1019367024018000,"raw":"{\"market\":\"0x28a45972fccdaf0fba75dacc59725521035e177d09dd92174f9f52740bccb025\", \"price_changes\":[{\"asset_id\":\"114356653315647913247200886351065428002113119844334520181865067698979836634569\", \"price\":\"0.07\", \"size\":\"622.71\", \"side\":\"BUY\", \"hash\":\"488083de5fc0bfc8127cba89c6e3a403ec7d79fd\", \"best_bid\":\"0.13\", \"best_ask\":\"0.14\"}, {\"asset_id\":\"61819828071723399190623735325323968706432622380635304641786792960078828866875\", \"price\":\"0.93\", \"size\":\"622.71\", \"side\":\"SELL\", \"hash\":\"20b0b53745b51f18ccd36eb884ebaeb9ad6ba641\", \"best_bid\":\"0.86\", \"best_ask\":\"0.87\"}], \"timestamp\":\"1789987926170\", \"event_type\":\"price_change\"}","raw_base64":null}
{"received_ms":1789987926193,"monotonic_ns":1019367024061300,"raw":"{\"market\":\"0x28a45972fccdaf0fba75dacc59725521035e177d09dd92174f9f52740bccb025\", \"price_changes\":[{\"asset_id\":\"61819828071723399190623735325323968706432622380635304641786792960078828866875\", \"price\":\"0.85\", \"size\":\"3777.35\", \"side\":\"BUY\", \"hash\":\"dd7dbcda2f3f85c51370f24cc83f69fc4689bee5\", \"best_bid\":\"0.86\", \"best_ask\":\"0.87\"}, {\"asset_id\":\"114356653315647913247200886351065428002113119844334520181865067698979836634569\", \"price\":\"0.15\", \"size\":\"3777.35\", \"side\":\"SELL\", \"hash\":\"258e0f55d9e5fbcd85f5467c7b5c17eeb522d052\", \"best_bid\":\"0.13\", \"best_ask\":\"0.14\"}], \"timestamp\":\"1789987926171\", \"event_type\":\"price_change\"}","raw_base64":null}
{"received_ms":1789987926193,"monotonic_ns":1019367024103400,"raw":"{\"market\":\"0x28a45972fccdaf0fba75dacc59725521035e177d09dd92174f9f52740bccb025\", \"price_changes\":[{\"asset_id\":\"61819828071723399190623735325323968706432622380635304641786792960078828866875\", \"price\":\"0.82\", \"size\":\"593\", \"side\":\"BUY\", \"hash\":\"71547edd93a28361cbefc69baa7d78944976efce\", \"best_bid\":\"0.86\", \"best_ask\":\"0.87\"}, {\"asset_id\":\"114356653315647913247200886351065428002113119844334520181865067698979836634569\", \"price\":\"0.18\", \"size\":\"593\", \"side\":\"SELL\", \"hash\":\"651274e0e4241ed83563315eaf5214548a1c3fe6\", \"best_bid\":\"0.13\", \"best_ask\":\"0.14\"}], \"timestamp\":\"1789987926172\", \"event_type\":\"price_change\"}","raw_base64":null}
{"received_ms":1789987926193,"monotonic_ns":1019367024145900,"raw":"{\"market\":\"0x28a45972fccdaf0fba75dacc59725521035e177d09dd92174f9f52740bccb025\", \"price_changes\":[{\"asset_id\":\"61819828071723399190623735325323968706432622380635304641786792960078828866875\", \"price\":\"0.84\", \"size\":\"4659\", \"side\":\"BUY\", \"hash\":\"2d9ffeab5f4a34b1a1469f11e475ffdb12c713ee\", \"best_bid\":\"0.86\", \"best_ask\":\"0.87\"}, {\"asset_id\":\"114356653315647913247200886351065428002113119844334520181865067698979836634569\", \"price\":\"0.16\", \"size\":\"4659\", \"side\":\"SELL\", \"hash\":\"6f2126452fd9c496b83ecff12bc469d00b0a0503\", \"best_bid\":\"0.13\", \"best_ask\":\"0.14\"}], \"timestamp\":\"1789987926172\", \"event_type\":\"price_change\"}","raw_base64":null}
{"received_ms":1789987926195,"monotonic_ns":1019367025897200,"raw":"{\"market\":\"0x28a45972fccdaf0fba75dacc59725521035e177d09dd92174f9f52740bccb025\", \"price_changes\":[{\"asset_id\":\"61819828071723399190623735325323968706432622380635304641786792960078828866875\", \"price\":\"0.8\", \"size\":\"562\", \"side\":\"BUY\", \"hash\":\"ddd9019fc1a2954bf26e86a7c89425f581fef725\", \"best_bid\":\"0.86\", \"best_ask\":\"0.87\"}, {\"asset_id\":\"114356653315647913247200886351065428002113119844334520181865067698979836634569\", \"price\":\"0.2\", \"size\":\"562\", \"side\":\"SELL\", \"hash\":\"f498167064c3d8a839cb307d0d1fe091f7ec3214\", \"best_bid\":\"0.13\", \"best_ask\":\"0.14\"}], \"timestamp\":\"1789987926173\", \"event_type\":\"price_change\"}","raw_base64":null}
{"received_ms":1789987926195,"monotonic_ns":1019367025955100,"raw":"{\"market\":\"0x28a45972fccdaf0fba75dacc59725521035e177d09dd92174f9f52740bccb025\", \"price_changes\":[{\"asset_id\":\"61819828071723399190623735325323968706432622380635304641786792960078828866875\", \"price\":\"0.85\", \"size\":\"3772.35\", \"side\":\"BUY\", \"hash\":\"f3d543a3461e0d76f6e2a8bc23088ebd9bbcdce3\", \"best_bid\":\"0.86\", \"best_ask\":\"0.87\"}, {\"asset_id\":\"114356653315647913247200886351065428002113119844334520181865067698979836634569\", \"price\":\"0.15\", \"size\":\"3772.35\", \"side\":\"SELL\", \"hash\":\"94fa75945c50482292dafc80a4db2fade35622c0\", \"best_bid\":\"0.13\", \"best_ask\":\"0.14\"}], \"timestamp\":\"1789987926173\", \"event_type\":\"price_change\"}","raw_base64":null}
{"received_ms":1789987926200,"monotonic_ns":1019367030326300,"raw":"{\"market\":\"0x28a45972fccdaf0fba75dacc59725521035e177d09dd92174f9f52740bccb025\", \"price_changes\":[{\"asset_id\":\"114356653315647913247200886351065428002113119844334520181865067698979836634569\", \"price\":\"0.06\", \"size\":\"5168.67\", \"side\":\"BUY\", \"hash\":\"c1ded075a1759915ff94165b80a4cee28dd0c277\", \"best_bid\":\"0.13\", \"best_ask\":\"0.14\"}, {\"asset_id\":\"61819828071723399190623735325323968706432622380635304641786792960078828866875\", \"price\":\"0.94\", \"size\":\"5168.67\", \"side\":\"SELL\", \"hash\":\"0ab11c5085b5bb85482f43c12e3ce4a844d24240\", \"best_bid\":\"0.86\", \"best_ask\":\"0.87\"}], \"timestamp\":\"1789987926178\", \"event_type\":\"price_change\"}","raw_base64":null}
{"received_ms":1789987926200,"monotonic_ns":1019367030420000,"raw":"{\"market\":\"0x28a45972fccdaf0fba75dacc59725521035e177d09dd92174f9f52740bccb025\", \"price_changes\":[{\"asset_id\":\"61819828071723399190623735325323968706432622380635304641786792960078828866875\", \"price\":\"0.84\", \"size\":\"3335\", \"side\":\"BUY\", \"hash\":\"52731207ca054653ed21371c6c7e7c0d92df9227\", \"best_bid\":\"0.86\", \"best_ask\":\"0.87\"}, {\"asset_id\":\"114356653315647913247200886351065428002113119844334520181865067698979836634569\", \"price\":\"0.16\", \"size\":\"3335\", \"side\":\"SELL\", \"hash\":\"c676d1963db44d514f6766965ea0d786ba9f9a36\", \"best_bid\":\"0.13\", \"best_ask\":\"0.14\"}], \"timestamp\":\"1789987926179\", \"event_type\":\"price_change\"}","raw_base64":null}
{"received_ms":1789987926200,"monotonic_ns":1019367031262500,"raw":"{\"market\":\"0x28a45972fccdaf0fba75dacc59725521035e177d09dd92174f9f52740bccb025\", \"price_changes\":[{\"asset_id\":\"61819828071723399190623735325323968706432622380635304641786792960078828866875\", \"price\":\"0.93\", \"size\":\"628.71\", \"side\":\"SELL\", \"hash\":\"aff3b8541a067cd3ac6a06559a911181246b6522\", \"best_bid\":\"0.86\", \"best_ask\":\"0.87\"}, {\"asset_id\":\"114356653315647913247200886351065428002113119844334520181865067698979836634569\", \"price\":\"0.07\", \"size\":\"628.71\", \"side\":\"BUY\", \"hash\":\"8c6ea68e0651fb866cb18eaeed59b88f2c80b275\", \"best_bid\":\"0.13\", \"best_ask\":\"0.14\"}], \"timestamp\":\"1789987926179\", \"event_type\":\"price_change\"}","raw_base64":null}
{"received_ms":1789987926201,"monotonic_ns":1019367031809300,"raw":"{\"market\":\"0x28a45972fccdaf0fba75dacc59725521035e177d09dd92174f9f52740bccb025\", \"price_changes\":[{\"asset_id\":\"61819828071723399190623735325323968706432622380635304641786792960078828866875\", \"price\":\"0.84\", \"size\":\"3325\", \"side\":\"BUY\", \"hash\":\"9a43ca3f9a3618833dff8199e54dce1ddc8521ed\", \"best_bid\":\"0.86\", \"best_ask\":\"0.87\"}, {\"asset_id\":\"114356653315647913247200886351065428002113119844334520181865067698979836634569\", \"price\":\"0.16\", \"size\":\"3325\", \"side\":\"SELL\", \"hash\":\"911767d571a459d42c829bc6fe35739492b419be\", \"best_bid\":\"0.13\", \"best_ask\":\"0.14\"}], \"timestamp\":\"1789987926180\", \"event_type\":\"price_change\"}","raw_base64":null}
{"received_ms":1789987926201,"monotonic_ns":1019367031859400,"raw":"{\"market\":\"0x28a45972fccdaf0fba75dacc59725521035e177d09dd92174f9f52740bccb025\", \"price_changes\":[{\"asset_id\":\"61819828071723399190623735325323968706432622380635304641786792960078828866875\", \"price\":\"0.84\", \"size\":\"2230\", \"side\":\"BUY\", \"hash\":\"0327f35203c7cea49bc8dc370cab10a3d4d7b335\", \"best_bid\":\"0.86\", \"best_ask\":\"0.87\"}, {\"asset_id\":\"114356653315647913247200886351065428002113119844334520181865067698979836634569\", \"price\":\"0.16\", \"size\":\"2230\", \"side\":\"SELL\", \"hash\":\"1e13a309e372cda05a15985cc3e590d56de79a36\", \"best_bid\":\"0.13\", \"best_ask\":\"0.14\"}], \"timestamp\":\"1789987926180\", \"event_type\":\"price_change\"}","raw_base64":null}
{"received_ms":1789987926204,"monotonic_ns":1019367034825200,"raw":"{\"market\":\"0x28a45972fccdaf0fba75dacc59725521035e177d09dd92174f9f52740bccb025\", \"price_changes\":[{\"asset_id\":\"114356653315647913247200886351065428002113119844334520181865067698979836634569\", \"price\":\"0.07\", \"size\":\"4879.71\", \"side\":\"BUY\", \"hash\":\"a31adc0967a58c9436f3838a245348954b0c6af5\", \"best_bid\":\"0.13\", \"best_ask\":\"0.14\"}, {\"asset_id\":\"61819828071723399190623735325323968706432622380635304641786792960078828866875\", \"price\":\"0.93\", \"size\":\"4879.71\", \"side\":\"SELL\", \"hash\":\"3d7143fdd41f262995d8a01394b7ba74254fa193\", \"best_bid\":\"0.86\", \"best_ask\":\"0.87\"}], \"timestamp\":\"1789987926181\", \"event_type\":\"price_change\"}","raw_base64":null}
{"received_ms":1789987926205,"monotonic_ns":1019367036277200,"raw":"{\"market\":\"0x28a45972fccdaf0fba75dacc59725521035e177d09dd92174f9f52740bccb025\", \"price_changes\":[{\"asset_id\":\"114356653315647913247200886351065428002113119844334520181865067698979836634569\", \"price\":\"0.21\", \"size\":\"427\", \"side\":\"SELL\", \"hash\":\"f877b6bb240ef20183811c4b89ae4b31cd0894ea\", \"best_bid\":\"0.13\", \"best_ask\":\"0.14\"}, {\"asset_id\":\"61819828071723399190623735325323968706432622380635304641786792960078828866875\", \"price\":\"0.79\", \"size\":\"427\", \"side\":\"BUY\", \"hash\":\"a4e95e097c75bcbaeb81ccd245cb467b4ed689a3\", \"best_bid\":\"0.86\", \"best_ask\":\"0.87\"}], \"timestamp\":\"1789987926185\", \"event_type\":\"price_change\"}","raw_base64":null}
{"received_ms":1789987926206,"monotonic_ns":1019367037043000,"raw":"{\"market\":\"0x28a45972fccdaf0fba75dacc59725521035e177d09dd92174f9f52740bccb025\", \"price_changes\":[{\"asset_id\":\"114356653315647913247200886351065428002113119844334520181865067698979836634569\", \"price\":\"0.05\", \"size\":\"11869\", \"side\":\"BUY\", \"hash\":\"25821e95ef32beb611785a1cd2e652fd12d02992\", \"best_bid\":\"0.13\", \"best_ask\":\"0.14\"}, {\"asset_id\":\"61819828071723399190623735325323968706432622380635304641786792960078828866875\", \"price\":\"0.95\", \"size\":\"11869\", \"side\":\"SELL\", \"hash\":\"0961c38a2e786060f2153841e81d2e9a295e6e64\", \"best_bid\":\"0.86\", \"best_ask\":\"0.87\"}], \"timestamp\":\"1789987926186\", \"event_type\":\"price_change\"}","raw_base64":null}
{"received_ms":1789987926207,"monotonic_ns":1019367037515800,"raw":"{\"market\":\"0x28a45972fccdaf0fba75dacc59725521035e177d09dd92174f9f52740bccb025\", \"price_changes\":[{\"asset_id\":\"114356653315647913247200886351065428002113119844334520181865067698979836634569\", \"price\":\"0.04\", \"size\":\"603.48\", \"side\":\"BUY\", \"hash\":\"f29dcc045697b74f50627c4e1e171251d61cd8f9\", \"best_bid\":\"0.13\", \"best_ask\":\"0.14\"}, {\"asset_id\":\"61819828071723399190623735325323968706432622380635304641786792960078828866875\", \"price\":\"0.96\", \"size\":\"603.48\", \"side\":\"SELL\", \"hash\":\"df79265f0356e4b289dea395bb0be329a12d9201\", \"best_bid\":\"0.86\", \"best_ask\":\"0.87\"}], \"timestamp\":\"1789987926187\", \"event_type\":\"price_change\"}","raw_base64":null}
{"received_ms":1789987926208,"monotonic_ns":1019367038534700,"raw":"{\"market\":\"0x28a45972fccdaf0fba75dacc59725521035e177d09dd92174f9f52740bccb025\", \"price_changes\":[{\"asset_id\":\"61819828071723399190623735325323968706432622380635304641786792960078828866875\", \"price\":\"0.86\", \"size\":\"659.17\", \"side\":\"BUY\", \"hash\":\"d8302b42601b983ceef4c96872cc33ad60572924\", \"best_bid\":\"0.86\", \"best_ask\":\"0.87\"}, {\"asset_id\":\"114356653315647913247200886351065428002113119844334520181865067698979836634569\", \"price\":\"0.14\", \"size\":\"659.17\", \"side\":\"SELL\", \"hash\":\"e5acf23f58315d269b33477c90d2dce77f687ef3\", \"best_bid\":\"0.13\", \"best_ask\":\"0.14\"}], \"timestamp\":\"1789987926187\", \"event_type\":\"price_change\"}","raw_base64":null}
{"received_ms":1789987926219,"monotonic_ns":1019367049904800,"raw":"{\"market\":\"0x28a45972fccdaf0fba75dacc59725521035e177d09dd92174f9f52740bccb025\", \"price_changes\":[{\"asset_id\":\"61819828071723399190623735325323968706432622380635304641786792960078828866875\", \"price\":\"0.92\", \"size\":\"619.5\", \"side\":\"SELL\", \"hash\":\"d1d0ba499b2409fac238115cf2d5503ab980b2b3\", \"best_bid\":\"0.86\", \"best_ask\":\"0.87\"}, {\"asset_id\":\"114356653315647913247200886351065428002113119844334520181865067698979836634569\", \"price\":\"0.08\", \"size\":\"619.5\", \"side\":\"BUY\", \"hash\":\"11ee0be2b74335b52c4255c29aeb74f79b646539\", \"best_bid\":\"0.13\", \"best_ask\":\"0.14\"}], \"timestamp\":\"1789987926197\", \"event_type\":\"price_change\"}","raw_base64":null}
{"received_ms":1789987926230,"monotonic_ns":1019367060704500,"raw":"{\"market\":\"0x28a45972fccdaf0fba75dacc59725521035e177d09dd92174f9f52740bccb025\", \"price_changes\":[{\"asset_id\":\"61819828071723399190623735325323968706432622380635304641786792960078828866875\", \"price\":\"0.92\", \"size\":\"699.5\", \"side\":\"SELL\", \"hash\":\"1a7904210d160e80f6db9d04dfaa278a20ab4857\", \"best_bid\":\"0.86\", \"best_ask\":\"0.87\"}, {\"asset_id\":\"114356653315647913247200886351065428002113119844334520181865067698979836634569\", \"price\":\"0.08\", \"size\":\"699.5\", \"side\":\"BUY\", \"hash\":\"f2f1de37dc699175990240be15f3ee01b74cd2d4\", \"best_bid\":\"0.13\", \"best_ask\":\"0.14\"}], \"timestamp\":\"1789987926200\", \"event_type\":\"price_change\"}","raw_base64":null}
{"received_ms":1789987926230,"monotonic_ns":1019367060758600,"raw":"{\"market\":\"0x28a45972fccdaf0fba75dacc59725521035e177d09dd92174f9f52740bccb025\", \"price_changes\":[{\"asset_id\":\"114356653315647913247200886351065428002113119844334520181865067698979836634569\", \"price\":\"0.05\", \"size\":\"11949\", \"side\":\"BUY\", \"hash\":\"14deb6dc651ade8014647e4dcb7269f7c10660a3\", \"best_bid\":\"0.13\", \"best_ask\":\"0.14\"}, {\"asset_id\":\"61819828071723399190623735325323968706432622380635304641786792960078828866875\", \"price\":\"0.95\", \"size\":\"11949\", \"side\":\"SELL\", \"hash\":\"cd13d43f0c8cbf94d4a17c37762670515bbb4430\", \"best_bid\":\"0.86\", \"best_ask\":\"0.87\"}], \"timestamp\":\"1789987926201\", \"event_type\":\"price_change\"}","raw_base64":null}
{"received_ms":1789987926230,"monotonic_ns":1019367060808400,"raw":"{\"market\":\"0x28a45972fccdaf0fba75dacc59725521035e177d09dd92174f9f52740bccb025\", \"price_changes\":[{\"asset_id\":\"114356653315647913247200886351065428002113119844334520181865067698979836634569\", \"price\":\"0.05\", \"size\":\"12029\", \"side\":\"BUY\", \"hash\":\"eb3df5818643ea2b9ccf3387ec052ecbebf27406\", \"best_bid\":\"0.13\", \"best_ask\":\"0.14\"}, {\"asset_id\":\"61819828071723399190623735325323968706432622380635304641786792960078828866875\", \"price\":\"0.95\", \"size\":\"12029\", \"side\":\"SELL\", \"hash\":\"3795b8eca4244564f1756b2568743f0c01746bbf\", \"best_bid\":\"0.86\", \"best_ask\":\"0.87\"}], \"timestamp\":\"1789987926203\", \"event_type\":\"price_change\"}","raw_base64":null}
{"received_ms":1789987926245,"monotonic_ns":1019367075376600,"raw":"{\"market\":\"0x28a45972fccdaf0fba75dacc59725521035e177d09dd92174f9f52740bccb025\", \"price_changes\":[{\"asset_id\":\"61819828071723399190623735325323968706432622380635304641786792960078828866875\", \"price\":\"0.86\", \"size\":\"640.17\", \"side\":\"BUY\", \"hash\":\"c0b34f3593641694e635b18a23ba96af799f7f62\", \"best_bid\":\"0.86\", \"best_ask\":\"0.87\"}, {\"asset_id\":\"114356653315647913247200886351065428002113119844334520181865067698979836634569\", \"price\":\"0.14\", \"size\":\"640.17\", \"side\":\"SELL\", \"hash\":\"0ee976d41731294ac2b3b37b86e265ac323e7c1c\", \"best_bid\":\"0.13\", \"best_ask\":\"0.14\"}], \"timestamp\":\"1789987926209\", \"event_type\":\"price_change\"}","raw_base64":null}
{"received_ms":1789987926245,"monotonic_ns":1019367075475000,"raw":"{\"market\":\"0x28a45972fccdaf0fba75dacc59725521035e177d09dd92174f9f52740bccb025\", \"price_changes\":[{\"asset_id\":\"114356653315647913247200886351065428002113119844334520181865067698979836634569\", \"price\":\"0.03\", \"size\":\"3932.57\", \"side\":\"BUY\", \"hash\":\"900aba81238415cd83d24e6da10b97169a4a1722\", \"best_bid\":\"0.13\", \"best_ask\":\"0.14\"}, {\"asset_id\":\"61819828071723399190623735325323968706432622380635304641786792960078828866875\", \"price\":\"0.97\", \"size\":\"3932.57\", \"side\":\"SELL\", \"hash\":\"366cb83268f2eb9b6bfb866c8717ba57661759c1\", \"best_bid\":\"0.86\", \"best_ask\":\"0.87\"}], \"timestamp\":\"1789987926210\", \"event_type\":\"price_change\"}","raw_base64":null}
{"received_ms":1789987926245,"monotonic_ns":1019367075538600,"raw":"{\"market\":\"0x28a45972fccdaf0fba75dacc59725521035e177d09dd92174f9f52740bccb025\", \"price_changes\":[{\"asset_id\":\"61819828071723399190623735325323968706432622380635304641786792960078828866875\", \"price\":\"0.76\", \"size\":\"400\", \"side\":\"BUY\", \"hash\":\"6c3c846278321d87658995a05aa964d9b2aeda83\", \"best_bid\":\"0.86\", \"best_ask\":\"0.87\"}, {\"asset_id\":\"114356653315647913247200886351065428002113119844334520181865067698979836634569\", \"price\":\"0.24\", \"size\":\"400\", \"side\":\"SELL\", \"hash\":\"18a984fc66e5a60e344be32dbf4b72ec4483e0df\", \"best_bid\":\"0.13\", \"best_ask\":\"0.14\"}], \"timestamp\":\"1789987926210\", \"event_type\":\"price_change\"}","raw_base64":null}
{"received_ms":1789987926245,"monotonic_ns":1019367075594800,"raw":"{\"market\":\"0x28a45972fccdaf0fba75dacc59725521035e177d09dd92174f9f52740bccb025\", \"price_changes\":[{\"asset_id\":\"61819828071723399190623735325323968706432622380635304641786792960078828866875\", \"price\":\"0.93\", \"size\":\"4887.71\", \"side\":\"SELL\", \"hash\":\"cd8d541fbba9f583b6aa0a41c3b511a8a325182b\", \"best_bid\":\"0.86\", \"best_ask\":\"0.87\"}, {\"asset_id\":\"114356653315647913247200886351065428002113119844334520181865067698979836634569\", \"price\":\"0.07\", \"size\":\"4887.71\", \"side\":\"BUY\", \"hash\":\"babcc4254a16dc38252b3571c7d9a29a0a62dc67\", \"best_bid\":\"0.13\", \"best_ask\":\"0.14\"}], \"timestamp\":\"1789987926211\", \"event_type\":\"price_change\"}","raw_base64":null}
{"received_ms":1789987926245,"monotonic_ns":1019367075647400,"raw":"{\"market\":\"0x28a45972fccdaf0fba75dacc59725521035e177d09dd92174f9f52740bccb025\", \"price_changes\":[{\"asset_id\":\"114356653315647913247200886351065428002113119844334520181865067698979836634569\", \"price\":\"0.11\", \"size\":\"126.1\", \"side\":\"BUY\", \"hash\":\"a429ab40667a55c5eee667eb5f4768d263836ab0\", \"best_bid\":\"0.13\", \"best_ask\":\"0.14\"}, {\"asset_id\":\"61819828071723399190623735325323968706432622380635304641786792960078828866875\", \"price\":\"0.89\", \"size\":\"126.1\", \"side\":\"SELL\", \"hash\":\"9bb45b53c1d039eabcd336d2669f556672f74bd3\", \"best_bid\":\"0.86\", \"best_ask\":\"0.87\"}], \"timestamp\":\"1789987926213\", \"event_type\":\"price_change\"}","raw_base64":null}
{"received_ms":1789987926245,"monotonic_ns":1019367075698600,"raw":"{\"market\":\"0x28a45972fccdaf0fba75dacc59725521035e177d09dd92174f9f52740bccb025\", \"price_changes\":[{\"asset_id\":\"114356653315647913247200886351065428002113119844334520181865067698979836634569\", \"price\":\"0.13\", \"size\":\"265\", \"side\":\"BUY\", \"hash\":\"45190435bd5d336c7ab987b848ed8f8aa3b31d41\", \"best_bid\":\"0.13\", \"best_ask\":\"0.14\"}, {\"asset_id\":\"61819828071723399190623735325323968706432622380635304641786792960078828866875\", \"price\":\"0.87\", \"size\":\"265\", \"side\":\"SELL\", \"hash\":\"ee1174182035be8b85f08e5c8777c545ca2ea60a\", \"best_bid\":\"0.86\", \"best_ask\":\"0.87\"}], \"timestamp\":\"1789987926214\", \"event_type\":\"price_change\"}","raw_base64":null}
{"received_ms":1789987926246,"monotonic_ns":1019367076828700,"raw":"{\"market\":\"0x28a45972fccdaf0fba75dacc59725521035e177d09dd92174f9f52740bccb025\", \"price_changes\":[{\"asset_id\":\"114356653315647913247200886351065428002113119844334520181865067698979836634569\", \"price\":\"0.06\", \"size\":\"5248.67\", \"side\":\"BUY\", \"hash\":\"1925a59cc008de63a7dde17e814cdc6b086fd911\", \"best_bid\":\"0.13\", \"best_ask\":\"0.14\"}, {\"asset_id\":\"61819828071723399190623735325323968706432622380635304641786792960078828866875\", \"price\":\"0.94\", \"size\":\"5248.67\", \"side\":\"SELL\", \"hash\":\"15f3fe1a9b832a3b945009d54cb7f2add40d270f\", \"best_bid\":\"0.86\", \"best_ask\":\"0.87\"}], \"timestamp\":\"1789987926214\", \"event_type\":\"price_change\"}","raw_base64":null}
{"received_ms":1789987926246,"monotonic_ns":1019367076888500,"raw":"{\"market\":\"0x28a45972fccdaf0fba75dacc59725521035e177d09dd92174f9f52740bccb025\", \"price_changes\":[{\"asset_id\":\"61819828071723399190623735325323968706432622380635304641786792960078828866875\", \"price\":\"0.78\", \"size\":\"453.82\", \"side\":\"BUY\", \"hash\":\"d9cc681b14660c48ea727e544880a6bfdf9c5758\", \"best_bid\":\"0.86\", \"best_ask\":\"0.87\"}, {\"asset_id\":\"114356653315647913247200886351065428002113119844334520181865067698979836634569\", \"price\":\"0.22\", \"size\":\"453.82\", \"side\":\"SELL\", \"hash\":\"27fe621118370e5ee516d60c621f40ea10e49981\", \"best_bid\":\"0.13\", \"best_ask\":\"0.14\"}], \"timestamp\":\"1789987926220\", \"event_type\":\"price_change\"}","raw_base64":null}
{"received_ms":1789987926246,"monotonic_ns":1019367076939600,"raw":"{\"market\":\"0x28a45972fccdaf0fba75dacc59725521035e177d09dd92174f9f52740bccb025\", \"price_changes\":[{\"asset_id\":\"61819828071723399190623735325323968706432622380635304641786792960078828866875\", \"price\":\"0.86\", \"size\":\"5352.17\", \"side\":\"BUY\", \"hash\":\"2a40840698a563887fad05c00981ce474c407a2a\", \"best_bid\":\"0.86\", \"best_ask\":\"0.87\"}, {\"asset_id\":\"114356653315647913247200886351065428002113119844334520181865067698979836634569\", \"price\":\"0.14\", \"size\":\"5352.17\", \"side\":\"SELL\", \"hash\":\"d8a3e56d60ef57e6c9e08372a5fcb307d1a64d66\", \"best_bid\":\"0.13\", \"best_ask\":\"0.14\"}], \"timestamp\":\"1789987926220\", \"event_type\":\"price_change\"}","raw_base64":null}
{"received_ms":1789987926246,"monotonic_ns":1019367076988400,"raw":"{\"market\":\"0x28a45972fccdaf0fba75dacc59725521035e177d09dd92174f9f52740bccb025\", \"price_changes\":[{\"asset_id\":\"114356653315647913247200886351065428002113119844334520181865067698979836634569\", \"price\":\"0.09\", \"size\":\"678.12\", \"side\":\"BUY\", \"hash\":\"568a534621a0e0923a6cc9d964f2a61710e81d6b\", \"best_bid\":\"0.13\", \"best_ask\":\"0.14\"}, {\"asset_id\":\"61819828071723399190623735325323968706432622380635304641786792960078828866875\", \"price\":\"0.91\", \"size\":\"678.12\", \"side\":\"SELL\", \"hash\":\"2812221d11e8e1e7cab2e527c046168847891b8b\", \"best_bid\":\"0.86\", \"best_ask\":\"0.87\"}], \"timestamp\":\"1789987926221\", \"event_type\":\"price_change\"}","raw_base64":null}
{"received_ms":1789987926247,"monotonic_ns":1019367077523800,"raw":"{\"market\":\"0x28a45972fccdaf0fba75dacc59725521035e177d09dd92174f9f52740bccb025\", \"price_changes\":[{\"asset_id\":\"114356653315647913247200886351065428002113119844334520181865067698979836634569\", \"price\":\"0.06\", \"size\":\"5328.67\", \"side\":\"BUY\", \"hash\":\"0a322deb892c2a9d1fb24ec1f1a6583599e86e6f\", \"best_bid\":\"0.13\", \"best_ask\":\"0.14\"}, {\"asset_id\":\"61819828071723399190623735325323968706432622380635304641786792960078828866875\", \"price\":\"0.94\", \"size\":\"5328.67\", \"side\":\"SELL\", \"hash\":\"6ef0e724cdf04adc261e60c3e522a7e1a3c84969\", \"best_bid\":\"0.86\", \"best_ask\":\"0.87\"}], \"timestamp\":\"1789987926222\", \"event_type\":\"price_change\"}","raw_base64":null}
{"received_ms":1789987926247,"monotonic_ns":1019367077600400,"raw":"{\"market\":\"0x28a45972fccdaf0fba75dacc59725521035e177d09dd92174f9f52740bccb025\", \"price_changes\":[{\"asset_id\":\"61819828071723399190623735325323968706432622380635304641786792960078828866875\", \"price\":\"0.84\", \"size\":\"3021\", \"side\":\"BUY\", \"hash\":\"c4766ca9dad2c5b128049736b18b26179018b488\", \"best_bid\":\"0.86\", \"best_ask\":\"0.87\"}, {\"asset_id\":\"114356653315647913247200886351065428002113119844334520181865067698979836634569\", \"price\":\"0.16\", \"size\":\"3021\", \"side\":\"SELL\", \"hash\":\"0f3a2c1ac64453138d8fb14fb85aa0d0b89f0d77\", \"best_bid\":\"0.13\", \"best_ask\":\"0.14\"}], \"timestamp\":\"1789987926223\", \"event_type\":\"price_change\"}","raw_base64":null}
{"received_ms":1789987926247,"monotonic_ns":1019367077655500,"raw":"{\"market\":\"0x28a45972fccdaf0fba75dacc59725521035e177d09dd92174f9f52740bccb025\", \"price_changes\":[{\"asset_id\":\"61819828071723399190623735325323968706432622380635304641786792960078828866875\", \"price\":\"0.85\", \"size\":\"4925.35\", \"side\":\"BUY\", \"hash\":\"49d666b00829f836a927e78e950e5b1dc9f303d8\", \"best_bid\":\"0.86\", \"best_ask\":\"0.87\"}, {\"asset_id\":\"114356653315647913247200886351065428002113119844334520181865067698979836634569\", \"price\":\"0.15\", \"size\":\"4925.35\", \"side\":\"SELL\", \"hash\":\"5288f1bc66139d2d2ac3d682f77b7405b59c5ac2\", \"best_bid\":\"0.13\", \"best_ask\":\"0.14\"}], \"timestamp\":\"1789987926224\", \"event_type\":\"price_change\"}","raw_base64":null}
{"received_ms":1789987926247,"monotonic_ns":1019367077705600,"raw":"{\"market\":\"0x28a45972fccdaf0fba75dacc59725521035e177d09dd92174f9f52740bccb025\", \"price_changes\":[{\"asset_id\":\"114356653315647913247200886351065428002113119844334520181865067698979836634569\", \"price\":\"0.03\", \"size\":\"4012.57\", \"side\":\"BUY\", \"hash\":\"fc8d227ad87b5fd35d94556e53ac2f545e5a96c7\", \"best_bid\":\"0.13\", \"best_ask\":\"0.14\"}, {\"asset_id\":\"61819828071723399190623735325323968706432622380635304641786792960078828866875\", \"price\":\"0.97\", \"size\":\"4012.57\", \"side\":\"SELL\", \"hash\":\"81fc67d0c691da200282e1f2990c63a9faf8c70b\", \"best_bid\":\"0.86\", \"best_ask\":\"0.87\"}], \"timestamp\":\"1789987926226\", \"event_type\":\"price_change\"}","raw_base64":null}
{"received_ms":1789987926247,"monotonic_ns":1019367078039900,"raw":"{\"market\":\"0x28a45972fccdaf0fba75dacc59725521035e177d09dd92174f9f52740bccb025\", \"price_changes\":[{\"asset_id\":\"114356653315647913247200886351065428002113119844334520181865067698979836634569\", \"price\":\"0.05\", \"size\":\"773\", \"side\":\"BUY\", \"hash\":\"9be646c02ee63cc58b33fdb0086deddcae517b06\", \"best_bid\":\"0.13\", \"best_ask\":\"0.14\"}, {\"asset_id\":\"61819828071723399190623735325323968706432622380635304641786792960078828866875\", \"price\":\"0.95\", \"size\":\"773\", \"side\":\"SELL\", \"hash\":\"f5248aadbfca479e0f24f3a578291d9160fe651f\", \"best_bid\":\"0.86\", \"best_ask\":\"0.87\"}], \"timestamp\":\"1789987926226\", \"event_type\":\"price_change\"}","raw_base64":null}
{"received_ms":1789987926269,"monotonic_ns":1019367099950800,"raw":"{\"market\":\"0x28a45972fccdaf0fba75dacc59725521035e177d09dd92174f9f52740bccb025\", \"price_changes\":[{\"asset_id\":\"61819828071723399190623735325323968706432622380635304641786792960078828866875\", \"price\":\"0.83\", \"size\":\"517\", \"side\":\"BUY\", \"hash\":\"8af9c0e45ad060410191670e2d5b61476d34bfa4\", \"best_bid\":\"0.86\", \"best_ask\":\"0.87\"}, {\"asset_id\":\"114356653315647913247200886351065428002113119844334520181865067698979836634569\", \"price\":\"0.17\", \"size\":\"517\", \"side\":\"SELL\", \"hash\":\"2120bd8b11a602def550fb9752a641d2619576fb\", \"best_bid\":\"0.13\", \"best_ask\":\"0.14\"}], \"timestamp\":\"1789987926233\", \"event_type\":\"price_change\"}","raw_base64":null}
{"received_ms":1789987926276,"monotonic_ns":1019367107053400,"raw":"{\"market\":\"0x28a45972fccdaf0fba75dacc59725521035e177d09dd92174f9f52740bccb025\", \"price_changes\":[{\"asset_id\":\"61819828071723399190623735325323968706432622380635304641786792960078828866875\", \"price\":\"0.83\", \"size\":\"437\", \"side\":\"BUY\", \"hash\":\"a31cfbeecac6ab7e254ce20d535007eb9cdd4caf\", \"best_bid\":\"0.86\", \"best_ask\":\"0.87\"}, {\"asset_id\":\"114356653315647913247200886351065428002113119844334520181865067698979836634569\", \"price\":\"0.17\", \"size\":\"437\", \"side\":\"SELL\", \"hash\":\"b707334f56aed8ea6ea9704f36aaf8bb1658ba2f\", \"best_bid\":\"0.13\", \"best_ask\":\"0.14\"}], \"timestamp\":\"1789987926238\", \"event_type\":\"price_change\"}","raw_base64":null}
{"received_ms":1789987926276,"monotonic_ns":1019367107118800,"raw":"{\"market\":\"0x28a45972fccdaf0fba75dacc59725521035e177d09dd92174f9f52740bccb025\", \"price_changes\":[{\"asset_id\":\"114356653315647913247200886351065428002113119844334520181865067698979836634569\", \"price\":\"0.11\", \"size\":\"118.1\", \"side\":\"BUY\", \"hash\":\"47461075fab3b74710cdfc88893f3b7da23c332e\", \"best_bid\":\"0.13\", \"best_ask\":\"0.14\"}, {\"asset_id\":\"61819828071723399190623735325323968706432622380635304641786792960078828866875\", \"price\":\"0.89\", \"size\":\"118.1\", \"side\":\"SELL\", \"hash\":\"c43bc287863f325b90542b5932c76894144f73e8\", \"best_bid\":\"0.86\", \"best_ask\":\"0.87\"}], \"timestamp\":\"1789987926241\", \"event_type\":\"price_change\"}","raw_base64":null}
{"received_ms":1789987926276,"monotonic_ns":1019367107169500,"raw":"{\"market\":\"0x28a45972fccdaf0fba75dacc59725521035e177d09dd92174f9f52740bccb025\", \"price_changes\":[{\"asset_id\":\"61819828071723399190623735325323968706432622380635304641786792960078828866875\", \"price\":\"0.78\", \"size\":\"433.82\", \"side\":\"BUY\", \"hash\":\"7d1079dcf84ba25dea56a244aa0709d3cc6c75fa\", \"best_bid\":\"0.86\", \"best_ask\":\"0.87\"}, {\"asset_id\":\"114356653315647913247200886351065428002113119844334520181865067698979836634569\", \"price\":\"0.22\", \"size\":\"433.82\", \"side\":\"SELL\", \"hash\":\"dad59922ebc8b43a1977cdbbb7c18f0a06ee3fa9\", \"best_bid\":\"0.13\", \"best_ask\":\"0.14\"}], \"timestamp\":\"1789987926245\", \"event_type\":\"price_change\"}","raw_base64":null}
{"received_ms":1789987926299,"monotonic_ns":1019367129912500,"raw":"{\"market\":\"0x28a45972fccdaf0fba75dacc59725521035e177d09dd92174f9f52740bccb025\", \"price_changes\":[{\"asset_id\":\"61819828071723399190623735325323968706432622380635304641786792960078828866875\", \"price\":\"0.81\", \"size\":\"663\", \"side\":\"BUY\", \"hash\":\"bd19f1dc76b211b3e134eb2ab88dfa51ea8b65a9\", \"best_bid\":\"0.86\", \"best_ask\":\"0.87\"}, {\"asset_id\":\"114356653315647913247200886351065428002113119844334520181865067698979836634569\", \"price\":\"0.19\", \"size\":\"663\", \"side\":\"SELL\", \"hash\":\"d228711824bb949137f53ad88fca3ce372142a5b\", \"best_bid\":\"0.13\", \"best_ask\":\"0.14\"}], \"timestamp\":\"1789987926246\", \"event_type\":\"price_change\"}","raw_base64":null}
{"received_ms":1789987926299,"monotonic_ns":1019367129973100,"raw":"{\"market\":\"0x28a45972fccdaf0fba75dacc59725521035e177d09dd92174f9f52740bccb025\", \"price_changes\":[{\"asset_id\":\"61819828071723399190623735325323968706432622380635304641786792960078828866875\", \"price\":\"0.84\", \"size\":\"2941\", \"side\":\"BUY\", \"hash\":\"f5ec7ab77e8e1aeb9f5177d44207c9877ec1bd18\", \"best_bid\":\"0.86\", \"best_ask\":\"0.87\"}, {\"asset_id\":\"114356653315647913247200886351065428002113119844334520181865067698979836634569\", \"price\":\"0.16\", \"size\":\"2941\", \"side\":\"SELL\", \"hash\":\"28aaa2af262b37c70cb5de2149a5400020850291\", \"best_bid\":\"0.13\", \"best_ask\":\"0.14\"}], \"timestamp\":\"1789987926251\", \"event_type\":\"price_change\"}","raw_base64":null}
{"received_ms":1789987926299,"monotonic_ns":1019367130024100,"raw":"{\"market\":\"0x28a45972fccdaf0fba75dacc59725521035e177d09dd92174f9f52740bccb025\", \"price_changes\":[{\"asset_id\":\"114356653315647913247200886351065428002113119844334520181865067698979836634569\", \"price\":\"0.09\", \"size\":\"670.12\", \"side\":\"BUY\", \"hash\":\"845f686ea6af53880d227bfa156a0b117a11d978\", \"best_bid\":\"0.13\", \"best_ask\":\"0.14\"}, {\"asset_id\":\"61819828071723399190623735325323968706432622380635304641786792960078828866875\", \"price\":\"0.91\", \"size\":\"670.12\", \"side\":\"SELL\", \"hash\":\"f3ab5c05c14a442fb6bf1497753ba29999d6277f\", \"best_bid\":\"0.86\", \"best_ask\":\"0.87\"}], \"timestamp\":\"1789987926252\", \"event_type\":\"price_change\"}","raw_base64":null}
{"received_ms":1789987926308,"monotonic_ns":1019367138593900,"raw":"{\"market\":\"0x28a45972fccdaf0fba75dacc59725521035e177d09dd92174f9f52740bccb025\", \"price_changes\":[{\"asset_id\":\"114356653315647913247200886351065428002113119844334520181865067698979836634569\", \"price\":\"0.13\", \"size\":\"255\", \"side\":\"BUY\", \"hash\":\"013bae644727b12f3044880bf1739c3a52826f5d\", \"best_bid\":\"0.13\", \"best_ask\":\"0.14\"}, {\"asset_id\":\"61819828071723399190623735325323968706432622380635304641786792960078828866875\", \"price\":\"0.87\", \"size\":\"255\", \"side\":\"SELL\", \"hash\":\"2dba4502118b95ab45cf95139c802fa8b31e419b\", \"best_bid\":\"0.86\", \"best_ask\":\"0.87\"}], \"timestamp\":\"1789987926253\", \"event_type\":\"price_change\"}","raw_base64":null}
{"received_ms":1789987926308,"monotonic_ns":1019367138662200,"raw":"{\"market\":\"0x28a45972fccdaf0fba75dacc59725521035e177d09dd92174f9f52740bccb025\", \"price_changes\":[{\"asset_id\":\"61819828071723399190623735325323968706432622380635304641786792960078828866875\", \"price\":\"0.85\", \"size\":\"4985.35\", \"side\":\"BUY\", \"hash\":\"9ba57d8082bd89ca61274b4085b7720549e7f223\", \"best_bid\":\"0.86\", \"best_ask\":\"0.87\"}, {\"asset_id\":\"114356653315647913247200886351065428002113119844334520181865067698979836634569\", \"price\":\"0.15\", \"size\":\"4985.35\", \"side\":\"SELL\", \"hash\":\"ca9b0348622a4a618ae9c9fbbe9bbab6e7bfaca9\", \"best_bid\":\"0.13\", \"best_ask\":\"0.14\"}], \"timestamp\":\"1789987926255\", \"event_type\":\"price_change\"}","raw_base64":null}
{"received_ms":1789987926308,"monotonic_ns":1019367138714600,"raw":"{\"market\":\"0x28a45972fccdaf0fba75dacc59725521035e177d09dd92174f9f52740bccb025\", \"price_changes\":[{\"asset_id\":\"114356653315647913247200886351065428002113119844334520181865067698979836634569\", \"price\":\"0.06\", \"size\":\"6900.67\", \"side\":\"BUY\", \"hash\":\"b02bb06840781f75930e04581dfc4d12b7ce8b4d\", \"best_bid\":\"0.13\", \"best_ask\":\"0.14\"}, {\"asset_id\":\"61819828071723399190623735325323968706432622380635304641786792960078828866875\", \"price\":\"0.94\", \"size\":\"6900.67\", \"side\":\"SELL\", \"hash\":\"c9d79288087448c47335322ccf83179a04c8fd63\", \"best_bid\":\"0.86\", \"best_ask\":\"0.87\"}], \"timestamp\":\"1789987926256\", \"event_type\":\"price_change\"}","raw_base64":null}
{"received_ms":1789987926308,"monotonic_ns":1019367138904100,"raw":"{\"market\":\"0x28a45972fccdaf0fba75dacc59725521035e177d09dd92174f9f52740bccb025\", \"price_changes\":[{\"asset_id\":\"61819828071723399190623735325323968706432622380635304641786792960078828866875\", \"price\":\"0.84\", \"size\":\"2861\", \"side\":\"BUY\", \"hash\":\"087301b13aefaef82e3966bb58df25929b8e3307\", \"best_bid\":\"0.86\", \"best_ask\":\"0.87\"}, {\"asset_id\":\"114356653315647913247200886351065428002113119844334520181865067698979836634569\", \"price\":\"0.16\", \"size\":\"2861\", \"side\":\"SELL\", \"hash\":\"d6041daff035695cb74693c151901290638a695f\", \"best_bid\":\"0.13\", \"best_ask\":\"0.14\"}], \"timestamp\":\"1789987926257\", \"event_type\":\"price_change\"}","raw_base64":null}
{"received_ms":1789987926313,"monotonic_ns":1019367143471100,"raw":"{\"market\":\"0x28a45972fccdaf0fba75dacc59725521035e177d09dd92174f9f52740bccb025\", \"price_changes\":[{\"asset_id\":\"61819828071723399190623735325323968706432622380635304641786792960078828866875\", \"price\":\"0.85\", \"size\":\"3832.35\", \"side\":\"BUY\", \"hash\":\"8c2ab91da452f0d09f8f24934af26c726a9109b1\", \"best_bid\":\"0.86\", \"best_ask\":\"0.87\"}, {\"asset_id\":\"114356653315647913247200886351065428002113119844334520181865067698979836634569\", \"price\":\"0.15\", \"size\":\"3832.35\", \"side\":\"SELL\", \"hash\":\"39ee87b22b62742bc56adf040ab4af36d171825d\", \"best_bid\":\"0.13\", \"best_ask\":\"0.14\"}], \"timestamp\":\"1789987926257\", \"event_type\":\"price_change\"}","raw_base64":null}
{"received_ms":1789987926313,"monotonic_ns":1019367143555600,"raw":"{\"market\":\"0x28a45972fccdaf0fba75dacc59725521035e177d09dd92174f9f52740bccb025\", \"price_changes\":[{\"asset_id\":\"114356653315647913247200886351065428002113119844334520181865067698979836634569\", \"price\":\"0.05\", \"size\":\"5754\", \"side\":\"BUY\", \"hash\":\"c6be09849889d96081d9462a4e5624cc5bc001f1\", \"best_bid\":\"0.13\", \"best_ask\":\"0.14\"}, {\"asset_id\":\"61819828071723399190623735325323968706432622380635304641786792960078828866875\", \"price\":\"0.95\", \"size\":\"5754\", \"side\":\"SELL\", \"hash\":\"6403595ee854fd4ca27f5c1152bfa28545a349c8\", \"best_bid\":\"0.86\", \"best_ask\":\"0.87\"}], \"timestamp\":\"1789987926259\", \"event_type\":\"price_change\"}","raw_base64":null}
{"received_ms":1789987926313,"monotonic_ns":1019367143621600,"raw":"{\"market\":\"0x28a45972fccdaf0fba75dacc59725521035e177d09dd92174f9f52740bccb025\", \"price_changes\":[{\"asset_id\":\"114356653315647913247200886351065428002113119844334520181865067698979836634569\", \"price\":\"0.07\", \"size\":\"5096.71\", \"side\":\"BUY\", \"hash\":\"6606d973bd123fb19abdd97fcb7a8fa6fb562aa9\", \"best_bid\":\"0.13\", \"best_ask\":\"0.14\"}, {\"asset_id\":\"61819828071723399190623735325323968706432622380635304641786792960078828866875\", \"price\":\"0.93\", \"size\":\"5096.71\", \"side\":\"SELL\", \"hash\":\"2a915406fce03a2b91d2438d92c9d3fd5c663ef4\", \"best_bid\":\"0.86\", \"best_ask\":\"0.87\"}], \"timestamp\":\"1789987926260\", \"event_type\":\"price_change\"}","raw_base64":null}
{"received_ms":1789987926313,"monotonic_ns":1019367143671600,"raw":"{\"market\":\"0x28a45972fccdaf0fba75dacc59725521035e177d09dd92174f9f52740bccb025\", \"price_changes\":[{\"asset_id\":\"61819828071723399190623735325323968706432622380635304641786792960078828866875\", \"price\":\"0.81\", \"size\":\"583\", \"side\":\"BUY\", \"hash\":\"b524485f96c29709c05e937952ed1f77f0b60044\", \"best_bid\":\"0.86\", \"best_ask\":\"0.87\"}, {\"asset_id\":\"114356653315647913247200886351065428002113119844334520181865067698979836634569\", \"price\":\"0.19\", \"size\":\"583\", \"side\":\"SELL\", \"hash\":\"ee119d26f1623b08ff1d5a689ea0e842fa99055c\", \"best_bid\":\"0.13\", \"best_ask\":\"0.14\"}], \"timestamp\":\"1789987926262\", \"event_type\":\"price_change\"}","raw_base64":null}
{"received_ms":1789987926313,"monotonic_ns":1019367143721300,"raw":"{\"market\":\"0x28a45972fccdaf0fba75dacc59725521035e177d09dd92174f9f52740bccb025\", \"price_changes\":[{\"asset_id\":\"61819828071723399190623735325323968706432622380635304641786792960078828866875\", \"price\":\"0.84\", \"size\":\"2070\", \"side\":\"BUY\", \"hash\":\"bc287bb265155dcc6e33f78f66b6cd9c10deadcb\", \"best_bid\":\"0.86\", \"best_ask\":\"0.87\"}, {\"asset_id\":\"114356653315647913247200886351065428002113119844334520181865067698979836634569\", \"price\":\"0.16\", \"size\":\"2070\", \"side\":\"SELL\", \"hash\":\"40a2299ec950d6347508dc49d69057eb1dfe36f3\", \"best_bid\":\"0.13\", \"best_ask\":\"0.14\"}], \"timestamp\":\"1789987926262\", \"event_type\":\"price_change\"}","raw_base64":null}
{"received_ms":1789987926313,"monotonic_ns":1019367143770700,"raw":"{\"market\":\"0x28a45972fccdaf0fba75dacc59725521035e177d09dd92174f9f52740bccb025\", \"price_changes\":[{\"asset_id\":\"61819828071723399190623735325323968706432622380635304641786792960078828866875\", \"price\":\"0.84\", \"size\":\"2150\", \"side\":\"BUY\", \"hash\":\"867c6c3e1adaae2f4c08e7b1a65ba5db2cc8c5a2\", \"best_bid\":\"0.86\", \"best_ask\":\"0.87\"}, {\"asset_id\":\"114356653315647913247200886351065428002113119844334520181865067698979836634569\", \"price\":\"0.16\", \"size\":\"2150\", \"side\":\"SELL\", \"hash\":\"95a57b6c80ea1cdd84095d021bc366545301fa93\", \"best_bid\":\"0.13\", \"best_ask\":\"0.14\"}], \"timestamp\":\"1789987926265\", \"event_type\":\"price_change\"}","raw_base64":null}
{"received_ms":1789987926313,"monotonic_ns":1019367143819400,"raw":"{\"market\":\"0x28a45972fccdaf0fba75dacc59725521035e177d09dd92174f9f52740bccb025\", \"price_changes\":[{\"asset_id\":\"114356653315647913247200886351065428002113119844334520181865067698979836634569\", \"price\":\"0.09\", \"size\":\"610.12\", \"side\":\"BUY\", \"hash\":\"8a89fb9e8a4b5672d9dec23d362225d172faf130\", \"best_bid\":\"0.13\", \"best_ask\":\"0.14\"}, {\"asset_id\":\"61819828071723399190623735325323968706432622380635304641786792960078828866875\", \"price\":\"0.91\", \"size\":\"610.12\", \"side\":\"SELL\", \"hash\":\"a0dc82d1a74fb3a1096e9e9119db8a04f065db4f\", \"best_bid\":\"0.86\", \"best_ask\":\"0.87\"}], \"timestamp\":\"1789987926268\", \"event_type\":\"price_change\"}","raw_base64":null}
{"received_ms":1789987926313,"monotonic_ns":1019367144108000,"raw":"{\"market\":\"0x28a45972fccdaf0fba75dacc59725521035e177d09dd92174f9f52740bccb025\", \"price_changes\":[{\"asset_id\":\"114356653315647913247200886351065428002113119844334520181865067698979836634569\", \"price\":\"0.01\", \"size\":\"1689.43\", \"side\":\"BUY\", \"hash\":\"d66c9a138a701bf4a8316c157ee43689f396a9a9\", \"best_bid\":\"0.13\", \"best_ask\":\"0.14\"}, {\"asset_id\":\"61819828071723399190623735325323968706432622380635304641786792960078828866875\", \"price\":\"0.99\", \"size\":\"1689.43\", \"side\":\"SELL\", \"hash\":\"699bd0b93bfa52da16b7d7f0ca320d02ac2fa632\", \"best_bid\":\"0.86\", \"best_ask\":\"0.87\"}], \"timestamp\":\"1789987926269\", \"event_type\":\"price_change\"}","raw_base64":null}
{"received_ms":1789987926313,"monotonic_ns":1019367144163500,"raw":"{\"market\":\"0x28a45972fccdaf0fba75dacc59725521035e177d09dd92174f9f52740bccb025\", \"price_changes\":[{\"asset_id\":\"61819828071723399190623735325323968706432622380635304641786792960078828866875\", \"price\":\"0.84\", \"size\":\"2230\", \"side\":\"BUY\", \"hash\":\"3b05fead3aae52bcc15c6dfcfdc0a122013ab457\", \"best_bid\":\"0.86\", \"best_ask\":\"0.87\"}, {\"asset_id\":\"114356653315647913247200886351065428002113119844334520181865067698979836634569\", \"price\":\"0.16\", \"size\":\"2230\", \"side\":\"SELL\", \"hash\":\"f9989c01ed84cdeea3e195833cdaff623836c82e\", \"best_bid\":\"0.13\", \"best_ask\":\"0.14\"}], \"timestamp\":\"1789987926270\", \"event_type\":\"price_change\"}","raw_base64":null}
{"received_ms":1789987926313,"monotonic_ns":1019367144212700,"raw":"{\"market\":\"0x28a45972fccdaf0fba75dacc59725521035e177d09dd92174f9f52740bccb025\", \"price_changes\":[{\"asset_id\":\"114356653315647913247200886351065428002113119844334520181865067698979836634569\", \"price\":\"0.11\", \"size\":\"126.1\", \"side\":\"BUY\", \"hash\":\"883e228b21fa085cf0881c2cef083b662b0ad730\", \"best_bid\":\"0.13\", \"best_ask\":\"0.14\"}, {\"asset_id\":\"61819828071723399190623735325323968706432622380635304641786792960078828866875\", \"price\":\"0.89\", \"size\":\"126.1\", \"side\":\"SELL\", \"hash\":\"b0eadfa72746a789b3f0818f809dd9427fc35ab6\", \"best_bid\":\"0.86\", \"best_ask\":\"0.87\"}], \"timestamp\":\"1789987926274\", \"event_type\":\"price_change\"}","raw_base64":null}
{"received_ms":1789987926315,"monotonic_ns":1019367145986000,"raw":"{\"market\":\"0x28a45972fccdaf0fba75dacc59725521035e177d09dd92174f9f52740bccb025\", \"price_changes\":[{\"asset_id\":\"61819828071723399190623735325323968706432622380635304641786792960078828866875\", \"price\":\"0.86\", \"size\":\"5362.17\", \"side\":\"BUY\", \"hash\":\"11f9889fd5b4793c35b0a071cfc4fd10dd1f6ea2\", \"best_bid\":\"0.86\", \"best_ask\":\"0.87\"}, {\"asset_id\":\"114356653315647913247200886351065428002113119844334520181865067698979836634569\", \"price\":\"0.14\", \"size\":\"5362.17\", \"side\":\"SELL\", \"hash\":\"a3d61d7fd9a099940728dc39baf39059cf10bdac\", \"best_bid\":\"0.13\", \"best_ask\":\"0.14\"}], \"timestamp\":\"1789987926282\", \"event_type\":\"price_change\"}","raw_base64":null}
{"received_ms":1789987926315,"monotonic_ns":1019367146029500,"raw":"{\"market\":\"0x28a45972fccdaf0fba75dacc59725521035e177d09dd92174f9f52740bccb025\", \"price_changes\":[{\"asset_id\":\"61819828071723399190623735325323968706432622380635304641786792960078828866875\", \"price\":\"0.86\", \"size\":\"5367.17\", \"side\":\"BUY\", \"hash\":\"2ab8af074c5ea7cf7b7c997a2e9d802b6e515ab3\", \"best_bid\":\"0.86\", \"best_ask\":\"0.87\"}, {\"asset_id\":\"114356653315647913247200886351065428002113119844334520181865067698979836634569\", \"price\":\"0.14\", \"size\":\"5367.17\", \"side\":\"SELL\", \"hash\":\"05303b9a587fde4420ef8f658f3bc2c674289e48\", \"best_bid\":\"0.13\", \"best_ask\":\"0.14\"}], \"timestamp\":\"1789987926283\", \"event_type\":\"price_change\"}","raw_base64":null}
{"received_ms":1789987926315,"monotonic_ns":1019367146070200,"raw":"{\"market\":\"0x28a45972fccdaf0fba75dacc59725521035e177d09dd92174f9f52740bccb025\", \"price_changes\":[{\"asset_id\":\"61819828071723399190623735325323968706432622380635304641786792960078828866875\", \"price\":\"0.82\", \"size\":\"673\", \"side\":\"BUY\", \"hash\":\"bdcfbfac08c5a9b8ea970acb521ffd31db947fe5\", \"best_bid\":\"0.86\", \"best_ask\":\"0.87\"}, {\"asset_id\":\"114356653315647913247200886351065428002113119844334520181865067698979836634569\", \"price\":\"0.18\", \"size\":\"673\", \"side\":\"SELL\", \"hash\":\"d5390fa8d61f1c8cfeb33797fa3772ddb104d2e1\", \"best_bid\":\"0.13\", \"best_ask\":\"0.14\"}], \"timestamp\":\"1789987926283\", \"event_type\":\"price_change\"}","raw_base64":null}
{"received_ms":1789987926315,"monotonic_ns":1019367146110900,"raw":"{\"market\":\"0x28a45972fccdaf0fba75dacc59725521035e177d09dd92174f9f52740bccb025\", \"price_changes\":[{\"asset_id\":\"61819828071723399190623735325323968706432622380635304641786792960078828866875\", \"price\":\"0.86\", \"size\":\"5332\", \"side\":\"BUY\", \"hash\":\"a6c1a4bbf7c96c7114c5c0cffdb46d69c67ee2ea\", \"best_bid\":\"0.86\", \"best_ask\":\"0.87\"}, {\"asset_id\":\"114356653315647913247200886351065428002113119844334520181865067698979836634569\", \"price\":\"0.14\", \"size\":\"5332\", \"side\":\"SELL\", \"hash\":\"205c2b08e470fa3832d5ad5bf00ac4f1f5721345\", \"best_bid\":\"0.13\", \"best_ask\":\"0.14\"}], \"timestamp\":\"1789987926288\", \"event_type\":\"price_change\"}","raw_base64":null}
{"received_ms":1789987926316,"monotonic_ns":1019367146776400,"raw":"{\"market\":\"0x28a45972fccdaf0fba75dacc59725521035e177d09dd92174f9f52740bccb025\", \"price_changes\":[{\"asset_id\":\"61819828071723399190623735325323968706432622380635304641786792960078828866875\", \"price\":\"0.86\", \"size\":\"5327\", \"side\":\"BUY\", \"hash\":\"9d1406782bfade56613e3182ea4ff41ec2b4d3ec\", \"best_bid\":\"0.86\", \"best_ask\":\"0.87\"}, {\"asset_id\":\"114356653315647913247200886351065428002113119844334520181865067698979836634569\", \"price\":\"0.14\", \"size\":\"5327\", \"side\":\"SELL\", \"hash\":\"15840e9eef0ee0074058be916f999e6e84b5c125\", \"best_bid\":\"0.13\", \"best_ask\":\"0.14\"}], \"timestamp\":\"1789987926291\", \"event_type\":\"price_change\"}","raw_base64":null}
{"received_ms":1789987926316,"monotonic_ns":1019367146825600,"raw":"{\"market\":\"0x28a45972fccdaf0fba75dacc59725521035e177d09dd92174f9f52740bccb025\", \"price_changes\":[{\"asset_id\":\"61819828071723399190623735325323968706432622380635304641786792960078828866875\", \"price\":\"0.86\", \"size\":\"5317\", \"side\":\"BUY\", \"hash\":\"4fd679d802f70c05e1afb39c9bec47622565d169\", \"best_bid\":\"0.86\", \"best_ask\":\"0.87\"}, {\"asset_id\":\"114356653315647913247200886351065428002113119844334520181865067698979836634569\", \"price\":\"0.14\", \"size\":\"5317\", \"side\":\"SELL\", \"hash\":\"e718082c137eebe2fbec1f6a3df845a39243a982\", \"best_bid\":\"0.13\", \"best_ask\":\"0.14\"}], \"timestamp\":\"1789987926291\", \"event_type\":\"price_change\"}","raw_base64":null}
{"received_ms":1789987926316,"monotonic_ns":1019367146860500,"raw":"{\"market\":\"0x28a45972fccdaf0fba75dacc59725521035e177d09dd92174f9f52740bccb025\", \"price_changes\":[{\"asset_id\":\"61819828071723399190623735325323968706432622380635304641786792960078828866875\", \"price\":\"0.76\", \"size\":\"390\", \"side\":\"BUY\", \"hash\":\"06820abf993dc5b274e11fdc8eb6fe9b0eaf2a46\", \"best_bid\":\"0.86\", \"best_ask\":\"0.87\"}, {\"asset_id\":\"114356653315647913247200886351065428002113119844334520181865067698979836634569\", \"price\":\"0.24\", \"size\":\"390\", \"side\":\"SELL\", \"hash\":\"5b280b32a616b7d20e6285c85f8e86ed64861d45\", \"best_bid\":\"0.13\", \"best_ask\":\"0.14\"}], \"timestamp\":\"1789987926291\", \"event_type\":\"price_change\"}","raw_base64":null}
{"received_ms":1789987926316,"monotonic_ns":1019367146893900,"raw":"{\"market\":\"0x28a45972fccdaf0fba75dacc59725521035e177d09dd92174f9f52740bccb025\", \"price_changes\":[{\"asset_id\":\"114356653315647913247200886351065428002113119844334520181865067698979836634569\", \"price\":\"0.05\", \"size\":\"773\", \"side\":\"BUY\", \"hash\":\"a94873be1eb0e3b47182694d2c28ae74145f39b8\", \"best_bid\":\"0.13\", \"best_ask\":\"0.14\"}, {\"asset_id\":\"61819828071723399190623735325323968706432622380635304641786792960078828866875\", \"price\":\"0.95\", \"size\":\"773\", \"side\":\"SELL\", \"hash\":\"4f6ff2779da86db976aec8b5dfee562699d75b57\", \"best_bid\":\"0.86\", \"best_ask\":\"0.87\"}], \"timestamp\":\"1789987926292\", \"event_type\":\"price_change\"}","raw_base64":null}
{"received_ms":1789987926319,"monotonic_ns":1019367149587500,"raw":"{\"market\":\"0x28a45972fccdaf0fba75dacc59725521035e177d09dd92174f9f52740bccb025\", \"price_changes\":[{\"asset_id\":\"114356653315647913247200886351065428002113119844334520181865067698979836634569\", \"price\":\"0.07\", \"size\":\"4887.71\", \"side\":\"BUY\", \"hash\":\"ed3fe604cf84bd1b40fb8eab3c8f09ade3b330cb\", \"best_bid\":\"0.13\", \"best_ask\":\"0.14\"}, {\"asset_id\":\"61819828071723399190623735325323968706432622380635304641786792960078828866875\", \"price\":\"0.93\", \"size\":\"4887.71\", \"side\":\"SELL\", \"hash\":\"5261a5ec714a4b1bd236c04e3eba6dc266c881e9\", \"best_bid\":\"0.86\", \"best_ask\":\"0.87\"}], \"timestamp\":\"1789987926298\", \"event_type\":\"price_change\"}","raw_base64":null}
{"received_ms":1789987926319,"monotonic_ns":1019367149631900,"raw":"{\"market\":\"0x28a45972fccdaf0fba75dacc59725521035e177d09dd92174f9f52740bccb025\", \"price_changes\":[{\"asset_id\":\"61819828071723399190623735325323968706432622380635304641786792960078828866875\", \"price\":\"0.85\", \"size\":\"3912.35\", \"side\":\"BUY\", \"hash\":\"d6c446a2495df624fc20ef48bb560288aae9b4f1\", \"best_bid\":\"0.86\", \"best_ask\":\"0.87\"}, {\"asset_id\":\"114356653315647913247200886351065428002113119844334520181865067698979836634569\", \"price\":\"0.15\", \"size\":\"3912.35\", \"side\":\"SELL\", \"hash\":\"f2bc10fea50142f39545c32206c01c5db561137a\", \"best_bid\":\"0.13\", \"best_ask\":\"0.14\"}], \"timestamp\":\"1789987926298\", \"event_type\":\"price_change\"}","raw_base64":null}
{"received_ms":1789987926321,"monotonic_ns":1019367151300200,"raw":"{\"market\":\"0x28a45972fccdaf0fba75dacc59725521035e177d09dd92174f9f52740bccb025\", \"price_changes\":[{\"asset_id\":\"61819828071723399190623735325323968706432622380635304641786792960078828866875\", \"price\":\"0.85\", \"size\":\"3992.35\", \"side\":\"BUY\", \"hash\":\"ccd799145413b7eecd68173f067f5039763fd732\", \"best_bid\":\"0.86\", \"best_ask\":\"0.87\"}, {\"asset_id\":\"114356653315647913247200886351065428002113119844334520181865067698979836634569\", \"price\":\"0.15\", \"size\":\"3992.35\", \"side\":\"SELL\", \"hash\":\"6015cf5b912dc5dd5de47cdc28d3aa6a32e521c4\", \"best_bid\":\"0.13\", \"best_ask\":\"0.14\"}], \"timestamp\":\"1789987926300\", \"event_type\":\"price_change\"}","raw_base64":null}
{"received_ms":1789987926322,"monotonic_ns":1019367152903500,"raw":"{\"market\":\"0x28a45972fccdaf0fba75dacc59725521035e177d09dd92174f9f52740bccb025\", \"price_changes\":[{\"asset_id\":\"61819828071723399190623735325323968706432622380635304641786792960078828866875\", \"price\":\"0.84\", \"size\":\"2992\", \"side\":\"BUY\", \"hash\":\"e00155acb8a7b3b85117a374c13f0e5c0493c8a5\", \"best_bid\":\"0.86\", \"best_ask\":\"0.87\"}, {\"asset_id\":\"114356653315647913247200886351065428002113119844334520181865067698979836634569\", \"price\":\"0.16\", \"size\":\"2992\", \"side\":\"SELL\", \"hash\":\"f3407576a5fe679c2f701fe9be4d7a550c217f2d\", \"best_bid\":\"0.13\", \"best_ask\":\"0.14\"}], \"timestamp\":\"1789987926302\", \"event_type\":\"price_change\"}","raw_base64":null}
{"received_ms":1789987926323,"monotonic_ns":1019367154027200,"raw":"{\"market\":\"0x28a45972fccdaf0fba75dacc59725521035e177d09dd92174f9f52740bccb025\", \"price_changes\":[{\"asset_id\":\"61819828071723399190623735325323968706432622380635304641786792960078828866875\", \"price\":\"0.85\", \"size\":\"5143.35\", \"side\":\"BUY\", \"hash\":\"a2a45d3f79c81567d01f47a2d20939d905312fd6\", \"best_bid\":\"0.86\", \"best_ask\":\"0.87\"}, {\"asset_id\":\"114356653315647913247200886351065428002113119844334520181865067698979836634569\", \"price\":\"0.15\", \"size\":\"5143.35\", \"side\":\"SELL\", \"hash\":\"23e5ba362f594b0203542ab6b75f5d54da767be9\", \"best_bid\":\"0.13\", \"best_ask\":\"0.14\"}], \"timestamp\":\"1789987926302\", \"event_type\":\"price_change\"}","raw_base64":null}
{"received_ms":1789987926323,"monotonic_ns":1019367154085200,"raw":"{\"market\":\"0x28a45972fccdaf0fba75dacc59725521035e177d09dd92174f9f52740bccb025\", \"price_changes\":[{\"asset_id\":\"61819828071723399190623735325323968706432622380635304641786792960078828866875\", \"price\":\"0.82\", \"size\":\"753\", \"side\":\"BUY\", \"hash\":\"d01156587eda9ba4aa66249125cc42265cf0e985\", \"best_bid\":\"0.86\", \"best_ask\":\"0.87\"}, {\"asset_id\":\"114356653315647913247200886351065428002113119844334520181865067698979836634569\", \"price\":\"0.18\", \"size\":\"753\", \"side\":\"SELL\", \"hash\":\"c00888051c0fe5fb1843b1b44c5701c22000d9e2\", \"best_bid\":\"0.13\", \"best_ask\":\"0.14\"}], \"timestamp\":\"1789987926303\", \"event_type\":\"price_change\"}","raw_base64":null}
{"received_ms":1789987926324,"monotonic_ns":1019367154528800,"raw":"{\"market\":\"0x28a45972fccdaf0fba75dacc59725521035e177d09dd92174f9f52740bccb025\", \"price_changes\":[{\"asset_id\":\"61819828071723399190623735325323968706432622380635304641786792960078828866875\", \"price\":\"0.86\", \"size\":\"5413\", \"side\":\"BUY\", \"hash\":\"63b67f5754534ab765a3f78936f8b5a286c6ac31\", \"best_bid\":\"0.86\", \"best_ask\":\"0.87\"}, {\"asset_id\":\"114356653315647913247200886351065428002113119844334520181865067698979836634569\", \"price\":\"0.14\", \"size\":\"5413\", \"side\":\"SELL\", \"hash\":\"25ad8f7a90a6549de266ddd56730331d1c31b84a\", \"best_bid\":\"0.13\", \"best_ask\":\"0.14\"}], \"timestamp\":\"1789987926304\", \"event_type\":\"price_change\"}","raw_base64":null}
{"received_ms":1789987926326,"monotonic_ns":1019367156432100,"raw":"{\"market\":\"0x28a45972fccdaf0fba75dacc59725521035e177d09dd92174f9f52740bccb025\", \"price_changes\":[{\"asset_id\":\"114356653315647913247200886351065428002113119844334520181865067698979836634569\", \"price\":\"0.04\", \"size\":\"610.48\", \"side\":\"BUY\", \"hash\":\"aff2375f012851148fb32108d7cdd4d70b5d1004\", \"best_bid\":\"0.13\", \"best_ask\":\"0.14\"}, {\"asset_id\":\"61819828071723399190623735325323968706432622380635304641786792960078828866875\", \"price\":\"0.96\", \"size\":\"610.48\", \"side\":\"SELL\", \"hash\":\"2796707ce707fef1861639fb8a30da218c917068\", \"best_bid\":\"0.86\", \"best_ask\":\"0.87\"}], \"timestamp\":\"1789987926304\", \"event_type\":\"price_change\"}","raw_base64":null}
{"received_ms":1789987926326,"monotonic_ns":1019367156495400,"raw":"{\"market\":\"0x28a45972fccdaf0fba75dacc59725521035e177d09dd92174f9f52740bccb025\", \"price_changes\":[{\"asset_id\":\"114356653315647913247200886351065428002113119844334520181865067698979836634569\", \"price\":\"0.06\", \"size\":\"5328.67\", \"side\":\"BUY\", \"hash\":\"571ee512ca6a28fad9a663f1c2d4b9dc03cb46cf\", \"best_bid\":\"0.13\", \"best_ask\":\"0.14\"}, {\"asset_id\":\"61819828071723399190623735325323968706432622380635304641786792960078828866875\", \"price\":\"0.94\", \"size\":\"5328.67\", \"side\":\"SELL\", \"hash\":\"92057c82f97ec0f05a9ec5f0d7a9cd2264afabc0\", \"best_bid\":\"0.86\", \"best_ask\":\"0.87\"}], \"timestamp\":\"1789987926305\", \"event_type\":\"price_change\"}","raw_base64":null}
{"received_ms":1789987926349,"monotonic_ns":1019367179295500,"raw":"{\"market\":\"0x28a45972fccdaf0fba75dacc59725521035e177d09dd92174f9f52740bccb025\", \"price_changes\":[{\"asset_id\":\"61819828071723399190623735325323968706432622380635304641786792960078828866875\", \"price\":\"0.86\", \"size\":\"5367\", \"side\":\"BUY\", \"hash\":\"354d799cfee1615a6aff80c76b499941053e3ca6\", \"best_bid\":\"0.86\", \"best_ask\":\"0.87\"}, {\"asset_id\":\"114356653315647913247200886351065428002113119844334520181865067698979836634569\", \"price\":\"0.14\", \"size\":\"5367\", \"side\":\"SELL\", \"hash\":\"15c905d7fb53fb227ef6f153a205f2f950dcc0d0\", \"best_bid\":\"0.13\", \"best_ask\":\"0.14\"}], \"timestamp\":\"1789987926328\", \"event_type\":\"price_change\"}","raw_base64":null}
{"received_ms":1789987926349,"monotonic_ns":1019367180273600,"raw":"{\"market\":\"0x28a45972fccdaf0fba75dacc59725521035e177d09dd92174f9f52740bccb025\", \"price_changes\":[{\"asset_id\":\"61819828071723399190623735325323968706432622380635304641786792960078828866875\", \"price\":\"0.76\", \"size\":\"400\", \"side\":\"BUY\", \"hash\":\"cb9e3ec48bb35c944c95d27d759c72ffdb36badf\", \"best_bid\":\"0.86\", \"best_ask\":\"0.87\"}, {\"asset_id\":\"114356653315647913247200886351065428002113119844334520181865067698979836634569\", \"price\":\"0.24\", \"size\":\"400\", \"side\":\"SELL\", \"hash\":\"f22334b70102fbdf32cd9923f990cb710ed749bc\", \"best_bid\":\"0.13\", \"best_ask\":\"0.14\"}], \"timestamp\":\"1789987926328\", \"event_type\":\"price_change\"}","raw_base64":null}
{"received_ms":1789987926352,"monotonic_ns":1019367182333900,"raw":"{\"market\":\"0x28a45972fccdaf0fba75dacc59725521035e177d09dd92174f9f52740bccb025\", \"price_changes\":[{\"asset_id\":\"61819828071723399190623735325323968706432622380635304641786792960078828866875\", \"price\":\"0.86\", \"size\":\"5271\", \"side\":\"BUY\", \"hash\":\"459a6be3c1949b94e12b5b9640bd9a9b6bc8d5c4\", \"best_bid\":\"0.86\", \"best_ask\":\"0.87\"}, {\"asset_id\":\"114356653315647913247200886351065428002113119844334520181865067698979836634569\", \"price\":\"0.14\", \"size\":\"5271\", \"side\":\"SELL\", \"hash\":\"d2b9a3b769f09ec701244d6503db8c538b622a61\", \"best_bid\":\"0.13\", \"best_ask\":\"0.14\"}], \"timestamp\":\"1789987926331\", \"event_type\":\"price_change\"}","raw_base64":null}
{"received_ms":1789987926352,"monotonic_ns":1019367182405500,"raw":"{\"market\":\"0x28a45972fccdaf0fba75dacc59725521035e177d09dd92174f9f52740bccb025\", \"price_changes\":[{\"asset_id\":\"114356653315647913247200886351065428002113119844334520181865067698979836634569\", \"price\":\"0.13\", \"size\":\"155\", \"side\":\"BUY\", \"hash\":\"5499b4da36973515a2c1d9d6b9b061945dd617d0\", \"best_bid\":\"0.13\", \"best_ask\":\"0.14\"}, {\"asset_id\":\"61819828071723399190623735325323968706432622380635304641786792960078828866875\", \"price\":\"0.87\", \"size\":\"155\", \"side\":\"SELL\", \"hash\":\"0f953e6e851cf1f2ebb7b5056b6bde281582c1b5\", \"best_bid\":\"0.86\", \"best_ask\":\"0.87\"}], \"timestamp\":\"1789987926331\", \"event_type\":\"price_change\"}","raw_base64":null}
{"received_ms":1789987926354,"monotonic_ns":1019367185198400,"raw":"{\"market\":\"0x28a45972fccdaf0fba75dacc59725521035e177d09dd92174f9f52740bccb025\", \"price_changes\":[{\"asset_id\":\"114356653315647913247200886351065428002113119844334520181865067698979836634569\", \"price\":\"0.11\", \"size\":\"226.1\", \"side\":\"BUY\", \"hash\":\"3f76db727c5f97864de840f0aad38feb9543779a\", \"best_bid\":\"0.13\", \"best_ask\":\"0.14\"}, {\"asset_id\":\"61819828071723399190623735325323968706432622380635304641786792960078828866875\", \"price\":\"0.89\", \"size\":\"226.1\", \"side\":\"SELL\", \"hash\":\"9108798291ab5112e618ed12458abe1d175704ad\", \"best_bid\":\"0.86\", \"best_ask\":\"0.87\"}], \"timestamp\":\"1789987926334\", \"event_type\":\"price_change\"}","raw_base64":null}
{"received_ms":1789987926356,"monotonic_ns":1019367186916700,"raw":"{\"market\":\"0x28a45972fccdaf0fba75dacc59725521035e177d09dd92174f9f52740bccb025\", \"price_changes\":[{\"asset_id\":\"61819828071723399190623735325323968706432622380635304641786792960078828866875\", \"price\":\"0.84\", \"size\":\"2230\", \"side\":\"BUY\", \"hash\":\"13eb925edd98852d29ed9452ce1adf9e78330bb3\", \"best_bid\":\"0.86\", \"best_ask\":\"0.87\"}, {\"asset_id\":\"114356653315647913247200886351065428002113119844334520181865067698979836634569\", \"price\":\"0.16\", \"size\":\"2230\", \"side\":\"SELL\", \"hash\":\"8fac6aa1dbaa644ef713f5e030eac2c08cd869f4\", \"best_bid\":\"0.13\", \"best_ask\":\"0.14\"}], \"timestamp\":\"1789987926336\", \"event_type\":\"price_change\"}","raw_base64":null}
{"received_ms":1789987926357,"monotonic_ns":1019367187525500,"raw":"{\"market\":\"0x28a45972fccdaf0fba75dacc59725521035e177d09dd92174f9f52740bccb025\", \"price_changes\":[{\"asset_id\":\"114356653315647913247200886351065428002113119844334520181865067698979836634569\", \"price\":\"0.05\", \"size\":\"5732\", \"side\":\"BUY\", \"hash\":\"aa48921deeb2f6d25edbf7232dc01964a2dd41d8\", \"best_bid\":\"0.13\", \"best_ask\":\"0.14\"}, {\"asset_id\":\"61819828071723399190623735325323968706432622380635304641786792960078828866875\", \"price\":\"0.95\", \"size\":\"5732\", \"side\":\"SELL\", \"hash\":\"7aae3343e2c3bf071d5b5136ad3c0bd654192c1e\", \"best_bid\":\"0.86\", \"best_ask\":\"0.87\"}], \"timestamp\":\"1789987926337\", \"event_type\":\"price_change\"}","raw_base64":null}
{"received_ms":1789987926358,"monotonic_ns":1019367189066200,"raw":"{\"market\":\"0x28a45972fccdaf0fba75dacc59725521035e177d09dd92174f9f52740bccb025\", \"price_changes\":[{\"asset_id\":\"114356653315647913247200886351065428002113119844334520181865067698979836634569\", \"price\":\"0.07\", \"size\":\"5076.71\", \"side\":\"BUY\", \"hash\":\"64ee40d9781bdd0a08058d63f7671bc56e43cba4\", \"best_bid\":\"0.13\", \"best_ask\":\"0.14\"}, {\"asset_id\":\"61819828071723399190623735325323968706432622380635304641786792960078828866875\", \"price\":\"0.93\", \"size\":\"5076.71\", \"side\":\"SELL\", \"hash\":\"8aac7c9c37294bc3bb13e8082d4ba49b3f99eb9b\", \"best_bid\":\"0.86\", \"best_ask\":\"0.87\"}], \"timestamp\":\"1789987926337\", \"event_type\":\"price_change\"}","raw_base64":null}
{"received_ms":1789987926358,"monotonic_ns":1019367189150500,"raw":"{\"market\":\"0x28a45972fccdaf0fba75dacc59725521035e177d09dd92174f9f52740bccb025\", \"price_changes\":[{\"asset_id\":\"114356653315647913247200886351065428002113119844334520181865067698979836634569\", \"price\":\"0.06\", \"size\":\"5986.67\", \"side\":\"BUY\", \"hash\":\"08aac89cfa610229e502341dd0a5da2e0d7422a0\", \"best_bid\":\"0.13\", \"best_ask\":\"0.14\"}, {\"asset_id\":\"61819828071723399190623735325323968706432622380635304641786792960078828866875\", \"price\":\"0.94\", \"size\":\"5986.67\", \"side\":\"SELL\", \"hash\":\"a3e092df9ec37939517bd884885aba0932cec717\", \"best_bid\":\"0.86\", \"best_ask\":\"0.87\"}], \"timestamp\":\"1789987926338\", \"event_type\":\"price_change\"}","raw_base64":null}
{"received_ms":1789987926363,"monotonic_ns":1019367193347000,"raw":"{\"market\":\"0x28a45972fccdaf0fba75dacc59725521035e177d09dd92174f9f52740bccb025\", \"price_changes\":[{\"asset_id\":\"61819828071723399190623735325323968706432622380635304641786792960078828866875\", \"price\":\"0.86\", \"size\":\"5306.17\", \"side\":\"BUY\", \"hash\":\"c15080dcb7b08a360d1567504e96af393cd05544\", \"best_bid\":\"0.86\", \"best_ask\":\"0.87\"}, {\"asset_id\":\"114356653315647913247200886351065428002113119844334520181865067698979836634569\", \"price\":\"0.14\", \"size\":\"5306.17\", \"side\":\"SELL\", \"hash\":\"6a17f0b44b8302fe28f65e9290c57efaaaac9c3c\", \"best_bid\":\"0.13\", \"best_ask\":\"0.14\"}], \"timestamp\":\"1789987926342\", \"event_type\":\"price_change\"}","raw_base64":null}
{"received_ms":1789987926364,"monotonic_ns":1019367194863000,"raw":"{\"market\":\"0x28a45972fccdaf0fba75dacc59725521035e177d09dd92174f9f52740bccb025\", \"price_changes\":[{\"asset_id\":\"114356653315647913247200886351065428002113119844334520181865067698979836634569\", \"price\":\"0.09\", \"size\":\"670.12\", \"side\":\"BUY\", \"hash\":\"c8bc3d745b0f548916286206102b5e31931f512a\", \"best_bid\":\"0.13\", \"best_ask\":\"0.14\"}, {\"asset_id\":\"61819828071723399190623735325323968706432622380635304641786792960078828866875\", \"price\":\"0.91\", \"size\":\"670.12\", \"side\":\"SELL\", \"hash\":\"6139a9b2da59b8002b9187b3ca4759158167385c\", \"best_bid\":\"0.86\", \"best_ask\":\"0.87\"}], \"timestamp\":\"1789987926344\", \"event_type\":\"price_change\"}","raw_base64":null}
{"received_ms":1789987926373,"monotonic_ns":1019367203700700,"raw":"{\"market\":\"0x28a45972fccdaf0fba75dacc59725521035e177d09dd92174f9f52740bccb025\", \"price_changes\":[{\"asset_id\":\"114356653315647913247200886351065428002113119844334520181865067698979836634569\", \"price\":\"0.11\", \"size\":\"218.1\", \"side\":\"BUY\", \"hash\":\"ef26f8ca55c14dcb36855a6b8f2ed30db42e48d6\", \"best_bid\":\"0.13\", \"best_ask\":\"0.14\"}, {\"asset_id\":\"61819828071723399190623735325323968706432622380635304641786792960078828866875\", \"price\":\"0.89\", \"size\":\"218.1\", \"side\":\"SELL\", \"hash\":\"c9763358fb65ec06939951b2f4c65030b99927be\", \"best_bid\":\"0.86\", \"best_ask\":\"0.87\"}], \"timestamp\":\"1789987926352\", \"event_type\":\"price_change\"}","raw_base64":null}
{"received_ms":1789987926379,"monotonic_ns":1019367209967900,"raw":"{\"market\":\"0x28a45972fccdaf0fba75dacc59725521035e177d09dd92174f9f52740bccb025\", \"price_changes\":[{\"asset_id\":\"114356653315647913247200886351065428002113119844334520181865067698979836634569\", \"price\":\"0.09\", \"size\":\"678.12\", \"side\":\"BUY\", \"hash\":\"4f0f0f09857a76cc0425d71d4586f25584235610\", \"best_bid\":\"0.13\", \"best_ask\":\"0.14\"}, {\"asset_id\":\"61819828071723399190623735325323968706432622380635304641786792960078828866875\", \"price\":\"0.91\", \"size\":\"678.12\", \"side\":\"SELL\", \"hash\":\"ed52bb64d8e9f93410c99a62eef1d6aa3b3c2846\", \"best_bid\":\"0.86\", \"best_ask\":\"0.87\"}], \"timestamp\":\"1789987926357\", \"event_type\":\"price_change\"}","raw_base64":null}
{"received_ms":1789987926381,"monotonic_ns":1019367211869300,"raw":"{\"market\":\"0x28a45972fccdaf0fba75dacc59725521035e177d09dd92174f9f52740bccb025\", \"price_changes\":[{\"asset_id\":\"61819828071723399190623735325323968706432622380635304641786792960078828866875\", \"price\":\"0.76\", \"size\":\"390\", \"side\":\"BUY\", \"hash\":\"129a65142c2a18561deacdb7dae60a6cff2c3531\", \"best_bid\":\"0.86\", \"best_ask\":\"0.87\"}, {\"asset_id\":\"114356653315647913247200886351065428002113119844334520181865067698979836634569\", \"price\":\"0.24\", \"size\":\"390\", \"side\":\"SELL\", \"hash\":\"eb1326ea187b764636e3c33dc8c8574c86289cc6\", \"best_bid\":\"0.13\", \"best_ask\":\"0.14\"}], \"timestamp\":\"1789987926361\", \"event_type\":\"price_change\"}","raw_base64":null}
{"received_ms":1789987926382,"monotonic_ns":1019367213201600,"raw":"{\"market\":\"0x28a45972fccdaf0fba75dacc59725521035e177d09dd92174f9f52740bccb025\", \"price_changes\":[{\"asset_id\":\"61819828071723399190623735325323968706432622380635304641786792960078828866875\", \"price\":\"0.85\", \"size\":\"5158.35\", \"side\":\"BUY\", \"hash\":\"f0a3436f51b745cd6f9e694a7741769fff9fe34a\", \"best_bid\":\"0.86\", \"best_ask\":\"0.87\"}, {\"asset_id\":\"114356653315647913247200886351065428002113119844334520181865067698979836634569\", \"price\":\"0.15\", \"size\":\"5158.35\", \"side\":\"SELL\", \"hash\":\"00289a2c0d77aa79758b43d588e5528006ade27f\", \"best_bid\":\"0.13\", \"best_ask\":\"0.14\"}], \"timestamp\":\"1789987926362\", \"event_type\":\"price_change\"}","raw_base64":null}
{"received_ms":1789987926383,"monotonic_ns":1019367213380800,"raw":"{\"market\":\"0x28a45972fccdaf0fba75dacc59725521035e177d09dd92174f9f52740bccb025\", \"price_changes\":[{\"asset_id\":\"61819828071723399190623735325323968706432622380635304641786792960078828866875\", \"price\":\"0.86\", \"size\":\"5316.17\", \"side\":\"BUY\", \"hash\":\"f6275dbeba8cdd00234108086684367be02150e4\", \"best_bid\":\"0.86\", \"best_ask\":\"0.87\"}, {\"asset_id\":\"114356653315647913247200886351065428002113119844334520181865067698979836634569\", \"price\":\"0.14\", \"size\":\"5316.17\", \"side\":\"SELL\", \"hash\":\"8475d78076b9814a924d8f055e8520b686d2b20a\", \"best_bid\":\"0.13\", \"best_ask\":\"0.14\"}], \"timestamp\":\"1789987926362\", \"event_type\":\"price_change\"}","raw_base64":null}
{"received_ms":1789987926386,"monotonic_ns":1019367216863200,"raw":"{\"market\":\"0x28a45972fccdaf0fba75dacc59725521035e177d09dd92174f9f52740bccb025\", \"price_changes\":[{\"asset_id\":\"61819828071723399190623735325323968706432622380635304641786792960078828866875\", \"price\":\"0.86\", \"size\":\"5281\", \"side\":\"BUY\", \"hash\":\"c49c1caa54910583693e26d2d798db223ce1409d\", \"best_bid\":\"0.86\", \"best_ask\":\"0.87\"}, {\"asset_id\":\"114356653315647913247200886351065428002113119844334520181865067698979836634569\", \"price\":\"0.14\", \"size\":\"5281\", \"side\":\"SELL\", \"hash\":\"5635b6e57d1450d5a944c6304eab60bfb2343486\", \"best_bid\":\"0.13\", \"best_ask\":\"0.14\"}], \"timestamp\":\"1789987926366\", \"event_type\":\"price_change\"}","raw_base64":null}
{"received_ms":1789987926388,"monotonic_ns":1019367218432200,"raw":"{\"market\":\"0x28a45972fccdaf0fba75dacc59725521035e177d09dd92174f9f52740bccb025\", \"price_changes\":[{\"asset_id\":\"61819828071723399190623735325323968706432622380635304641786792960078828866875\", \"price\":\"0.86\", \"size\":\"5271\", \"side\":\"BUY\", \"hash\":\"e3d136fc8039e28fa5e062958a1a769dd6779f08\", \"best_bid\":\"0.86\", \"best_ask\":\"0.87\"}, {\"asset_id\":\"114356653315647913247200886351065428002113119844334520181865067698979836634569\", \"price\":\"0.14\", \"size\":\"5271\", \"side\":\"SELL\", \"hash\":\"58217169fd7d0d3c436fed30c5c2d6f1e6df5bb7\", \"best_bid\":\"0.13\", \"best_ask\":\"0.14\"}], \"timestamp\":\"1789987926367\", \"event_type\":\"price_change\"}","raw_base64":null}
{"received_ms":1789987926389,"monotonic_ns":1019367219574400,"raw":"{\"market\":\"0x28a45972fccdaf0fba75dacc59725521035e177d09dd92174f9f52740bccb025\", \"price_changes\":[{\"asset_id\":\"61819828071723399190623735325323968706432622380635304641786792960078828866875\", \"price\":\"0.84\", \"size\":\"3105\", \"side\":\"BUY\", \"hash\":\"ee81e454514ccf569af33d6b99c8eddff9f3e159\", \"best_bid\":\"0.86\", \"best_ask\":\"0.87\"}, {\"asset_id\":\"114356653315647913247200886351065428002113119844334520181865067698979836634569\", \"price\":\"0.16\", \"size\":\"3105\", \"side\":\"SELL\", \"hash\":\"806cd65ae78f1c7633ddce3743d697130ae8dc24\", \"best_bid\":\"0.13\", \"best_ask\":\"0.14\"}], \"timestamp\":\"1789987926368\", \"event_type\":\"price_change\"}","raw_base64":null}
{"received_ms":1789987926390,"monotonic_ns":1019367221254300,"raw":"{\"market\":\"0x28a45972fccdaf0fba75dacc59725521035e177d09dd92174f9f52740bccb025\", \"price_changes\":[{\"asset_id\":\"61819828071723399190623735325323968706432622380635304641786792960078828866875\", \"price\":\"0.86\", \"size\":\"5464\", \"side\":\"BUY\", \"hash\":\"0c11ffa7db3b9e979576275a720dd3fdb6b98639\", \"best_bid\":\"0.86\", \"best_ask\":\"0.87\"}, {\"asset_id\":\"114356653315647913247200886351065428002113119844334520181865067698979836634569\", \"price\":\"0.14\", \"size\":\"5464\", \"side\":\"SELL\", \"hash\":\"0da5fefbbb5e4ce2b788e43c52a65b333f217de9\", \"best_bid\":\"0.13\", \"best_ask\":\"0.14\"}], \"timestamp\":\"1789987926370\", \"event_type\":\"price_change\"}","raw_base64":null}
{"received_ms":1789987926394,"monotonic_ns":1019367224552400,"raw":"{\"market\":\"0x28a45972fccdaf0fba75dacc59725521035e177d09dd92174f9f52740bccb025\", \"price_changes\":[{\"asset_id\":\"61819828071723399190623735325323968706432622380635304641786792960078828866875\", \"price\":\"0.85\", \"size\":\"4007.35\", \"side\":\"BUY\", \"hash\":\"f82ad974efda7e78ce4c9c69ca1436959ebb102d\", \"best_bid\":\"0.86\", \"best_ask\":\"0.87\"}, {\"asset_id\":\"114356653315647913247200886351065428002113119844334520181865067698979836634569\", \"price\":\"0.15\", \"size\":\"4007.35\", \"side\":\"SELL\", \"hash\":\"ec78e67888d60e1eb0a29f86cb2e63f5e8616b73\", \"best_bid\":\"0.13\", \"best_ask\":\"0.14\"}], \"timestamp\":\"1789987926373\", \"event_type\":\"price_change\"}","raw_base64":null}
{"received_ms":1789987926394,"monotonic_ns":1019367225107400,"raw":"{\"market\":\"0x28a45972fccdaf0fba75dacc59725521035e177d09dd92174f9f52740bccb025\", \"price_changes\":[{\"asset_id\":\"61819828071723399190623735325323968706432622380635304641786792960078828866875\", \"price\":\"0.79\", \"size\":\"447\", \"side\":\"BUY\", \"hash\":\"282a1fd08cc5f8f0431734d40120286837a3a5fa\", \"best_bid\":\"0.86\", \"best_ask\":\"0.87\"}, {\"asset_id\":\"114356653315647913247200886351065428002113119844334520181865067698979836634569\", \"price\":\"0.21\", \"size\":\"447\", \"side\":\"SELL\", \"hash\":\"ea9a0cb73bd1f3a3bf6c1aee7455c44a3a8ba73f\", \"best_bid\":\"0.13\", \"best_ask\":\"0.14\"}], \"timestamp\":\"1789987926374\", \"event_type\":\"price_change\"}","raw_base64":null}
{"received_ms":1789987926406,"monotonic_ns":1019367237273200,"raw":"{\"market\":\"0x28a45972fccdaf0fba75dacc59725521035e177d09dd92174f9f52740bccb025\", \"price_changes\":[{\"asset_id\":\"114356653315647913247200886351065428002113119844334520181865067698979836634569\", \"price\":\"0.07\", \"size\":\"5081.71\", \"side\":\"BUY\", \"hash\":\"60862ca4046fd008c815b59e964e6c02c9dace90\", \"best_bid\":\"0.13\", \"best_ask\":\"0.14\"}, {\"asset_id\":\"61819828071723399190623735325323968706432622380635304641786792960078828866875\", \"price\":\"0.93\", \"size\":\"5081.71\", \"side\":\"SELL\", \"hash\":\"366bf933c68cca250a63dde48f1174711fe3e21f\", \"best_bid\":\"0.86\", \"best_ask\":\"0.87\"}], \"timestamp\":\"1789987926387\", \"event_type\":\"price_change\"}","raw_base64":null}
{"received_ms":1789987926412,"monotonic_ns":1019367242642900,"raw":"{\"market\":\"0x28a45972fccdaf0fba75dacc59725521035e177d09dd92174f9f52740bccb025\", \"price_changes\":[{\"asset_id\":\"114356653315647913247200886351065428002113119844334520181865067698979836634569\", \"price\":\"0.02\", \"size\":\"574.82\", \"side\":\"BUY\", \"hash\":\"aa8f6db49116ecd7dbc2a6296d85ea73f4b66173\", \"best_bid\":\"0.13\", \"best_ask\":\"0.14\"}, {\"asset_id\":\"61819828071723399190623735325323968706432622380635304641786792960078828866875\", \"price\":\"0.98\", \"size\":\"574.82\", \"side\":\"SELL\", \"hash\":\"3be036531dfbb0d6a00325e205262b4534509888\", \"best_bid\":\"0.86\", \"best_ask\":\"0.87\"}], \"timestamp\":\"1789987926390\", \"event_type\":\"price_change\"}","raw_base64":null}
{"received_ms":1789987926419,"monotonic_ns":1019367249386600,"raw":"{\"market\":\"0x28a45972fccdaf0fba75dacc59725521035e177d09dd92174f9f52740bccb025\", \"price_changes\":[{\"asset_id\":\"114356653315647913247200886351065428002113119844334520181865067698979836634569\", \"price\":\"0.09\", \"size\":\"670.12\", \"side\":\"BUY\", \"hash\":\"d0616a16363a4890f1643651f9da0623b403f60d\", \"best_bid\":\"0.13\", \"best_ask\":\"0.14\"}, {\"asset_id\":\"61819828071723399190623735325323968706432622380635304641786792960078828866875\", \"price\":\"0.91\", \"size\":\"670.12\", \"side\":\"SELL\", \"hash\":\"3c8c81477d68feab728f43a5d9f122cf105841a8\", \"best_bid\":\"0.86\", \"best_ask\":\"0.87\"}], \"timestamp\":\"1789987926396\", \"event_type\":\"price_change\"}","raw_base64":null}
{"received_ms":1789987926419,"monotonic_ns":1019367249448200,"raw":"{\"market\":\"0x28a45972fccdaf0fba75dacc59725521035e177d09dd92174f9f52740bccb025\", \"price_changes\":[{\"asset_id\":\"114356653315647913247200886351065428002113119844334520181865067698979836634569\", \"price\":\"0.11\", \"size\":\"226.1\", \"side\":\"BUY\", \"hash\":\"1dade71dae90e95376f219c377b427a965c1e753\", \"best_bid\":\"0.13\", \"best_ask\":\"0.14\"}, {\"asset_id\":\"61819828071723399190623735325323968706432622380635304641786792960078828866875\", \"price\":\"0.89\", \"size\":\"226.1\", \"side\":\"SELL\", \"hash\":\"bd324489a6f30f50c2d950be4ee93308a1ada0d4\", \"best_bid\":\"0.86\", \"best_ask\":\"0.87\"}], \"timestamp\":\"1789987926396\", \"event_type\":\"price_change\"}","raw_base64":null}
{"received_ms":1789987926419,"monotonic_ns":1019367249500400,"raw":"{\"market\":\"0x28a45972fccdaf0fba75dacc59725521035e177d09dd92174f9f52740bccb025\", \"price_changes\":[{\"asset_id\":\"61819828071723399190623735325323968706432622380635304641786792960078828866875\", \"price\":\"0.86\", \"size\":\"5474\", \"side\":\"BUY\", \"hash\":\"756e64a93197afa273859b44f4364d878e0f9558\", \"best_bid\":\"0.86\", \"best_ask\":\"0.87\"}, {\"asset_id\":\"114356653315647913247200886351065428002113119844334520181865067698979836634569\", \"price\":\"0.14\", \"size\":\"5474\", \"side\":\"SELL\", \"hash\":\"a1154bc85825fef004e8b96d5d85e45d5ef77b23\", \"best_bid\":\"0.13\", \"best_ask\":\"0.14\"}], \"timestamp\":\"1789987926397\", \"event_type\":\"price_change\"}","raw_base64":null}
{"received_ms":1789987926419,"monotonic_ns":1019367249847000,"raw":"{\"market\":\"0x28a45972fccdaf0fba75dacc59725521035e177d09dd92174f9f52740bccb025\", \"price_changes\":[{\"asset_id\":\"61819828071723399190623735325323968706432622380635304641786792960078828866875\", \"price\":\"0.86\", \"size\":\"5489.17\", \"side\":\"BUY\", \"hash\":\"0a125aef1eba86f76ef5393567f77f71861b4e08\", \"best_bid\":\"0.86\", \"best_ask\":\"0.87\"}, {\"asset_id\":\"114356653315647913247200886351065428002113119844334520181865067698979836634569\", \"price\":\"0.14\", \"size\":\"5489.17\", \"side\":\"SELL\", \"hash\":\"78aee420d5e0763e8f3d37bd73758d296ea6a4a5\", \"best_bid\":\"0.13\", \"best_ask\":\"0.14\"}], \"timestamp\":\"1789987926398\", \"event_type\":\"price_change\"}","raw_base64":null}
{"received_ms":1789987926419,"monotonic_ns":1019367249909600,"raw":"{\"market\":\"0x28a45972fccdaf0fba75dacc59725521035e177d09dd92174f9f52740bccb025\", \"price_changes\":[{\"asset_id\":\"114356653315647913247200886351065428002113119844334520181865067698979836634569\", \"price\":\"0.06\", \"size\":\"5993.67\", \"side\":\"BUY\", \"hash\":\"b3d65210c929b5c5d01d9482282e1c7a8ffcd0d5\", \"best_bid\":\"0.13\", \"best_ask\":\"0.14\"}, {\"asset_id\":\"61819828071723399190623735325323968706432622380635304641786792960078828866875\", \"price\":\"0.94\", \"size\":\"5993.67\", \"side\":\"SELL\", \"hash\":\"f09e002051949f97e4eaa3b32bf6844db3e2f234\", \"best_bid\":\"0.86\", \"best_ask\":\"0.87\"}], \"timestamp\":\"1789987926398\", \"event_type\":\"price_change\"}","raw_base64":null}
{"received_ms":1789987926421,"monotonic_ns":1019367251376900,"raw":"{\"market\":\"0x28a45972fccdaf0fba75dacc59725521035e177d09dd92174f9f52740bccb025\", \"price_changes\":[{\"asset_id\":\"61819828071723399190623735325323968706432622380635304641786792960078828866875\", \"price\":\"0.01\", \"size\":\"1496.91\", \"side\":\"BUY\", \"hash\":\"78618f1972618afbbbb1afd2e54ad2f0b60bae7c\", \"best_bid\":\"0.86\", \"best_ask\":\"0.87\"}, {\"asset_id\":\"114356653315647913247200886351065428002113119844334520181865067698979836634569\", \"price\":\"0.99\", \"size\":\"1496.91\", \"side\":\"SELL\", \"hash\":\"d52339938f035ec5ba7e0c9270eabb87ddc78d30\", \"best_bid\":\"0.13\", \"best_ask\":\"0.14\"}], \"timestamp\":\"1789987926399\", \"event_type\":\"price_change\"}","raw_base64":null}
{"received_ms":1789987926422,"monotonic_ns":1019367252769200,"raw":"{\"market\":\"0x28a45972fccdaf0fba75dacc59725521035e177d09dd92174f9f52740bccb025\", \"price_changes\":[{\"asset_id\":\"114356653315647913247200886351065428002113119844334520181865067698979836634569\", \"price\":\"0.11\", \"size\":\"236.1\", \"side\":\"BUY\", \"hash\":\"e074c621ef4eb5fa3d65c5230fa672aa8d697624\", \"best_bid\":\"0.13\", \"best_ask\":\"0.14\"}, {\"asset_id\":\"61819828071723399190623735325323968706432622380635304641786792960078828866875\", \"price\":\"0.89\", \"size\":\"236.1\", \"side\":\"SELL\", \"hash\":\"af02f1b0891a2bc265c583d72e7910a4e3ef797a\", \"best_bid\":\"0.86\", \"best_ask\":\"0.87\"}], \"timestamp\":\"1789987926401\", \"event_type\":\"price_change\"}","raw_base64":null}
{"received_ms":1789987926426,"monotonic_ns":1019367256304900,"raw":"{\"market\":\"0x28a45972fccdaf0fba75dacc59725521035e177d09dd92174f9f52740bccb025\", \"price_changes\":[{\"asset_id\":\"61819828071723399190623735325323968706432622380635304641786792960078828866875\", \"price\":\"0.86\", \"size\":\"5494.17\", \"side\":\"BUY\", \"hash\":\"5f6aa9e8fb6dbc1019db1e311a29c43fe4439930\", \"best_bid\":\"0.86\", \"best_ask\":\"0.87\"}, {\"asset_id\":\"114356653315647913247200886351065428002113119844334520181865067698979836634569\", \"price\":\"0.14\", \"size\":\"5494.17\", \"side\":\"SELL\", \"hash\":\"08eb7e149a10da1ecefc86ffdcdbbfad38fe78b9\", \"best_bid\":\"0.13\", \"best_ask\":\"0.14\"}], \"timestamp\":\"1789987926404\", \"event_type\":\"price_change\"}","raw_base64":null}
{"received_ms":1789987926428,"monotonic_ns":1019367258497300,"raw":"{\"market\":\"0x28a45972fccdaf0fba75dacc59725521035e177d09dd92174f9f52740bccb025\", \"price_changes\":[{\"asset_id\":\"61819828071723399190623735325323968706432622380635304641786792960078828866875\", \"price\":\"0.86\", \"size\":\"5994.17\", \"side\":\"BUY\", \"hash\":\"511526881e4f0d940cad0594e8db8a3906a4aa2d\", \"best_bid\":\"0.86\", \"best_ask\":\"0.87\"}, {\"asset_id\":\"114356653315647913247200886351065428002113119844334520181865067698979836634569\", \"price\":\"0.14\", \"size\":\"5994.17\", \"side\":\"SELL\", \"hash\":\"1ce17b72eeb95c447dda80ec57bc41ff489c8f5b\", \"best_bid\":\"0.13\", \"best_ask\":\"0.14\"}], \"timestamp\":\"1789987926407\", \"event_type\":\"price_change\"}","raw_base64":null}
{"received_ms":1789987926433,"monotonic_ns":1019367264074200,"raw":"{\"market\":\"0x28a45972fccdaf0fba75dacc59725521035e177d09dd92174f9f52740bccb025\", \"price_changes\":[{\"asset_id\":\"114356653315647913247200886351065428002113119844334520181865067698979836634569\", \"price\":\"0.13\", \"size\":\"145\", \"side\":\"BUY\", \"hash\":\"93dfc6b2ce235d5a5c7448ea64b2154f5ee1c23a\", \"best_bid\":\"0.13\", \"best_ask\":\"0.14\"}, {\"asset_id\":\"61819828071723399190623735325323968706432622380635304641786792960078828866875\", \"price\":\"0.87\", \"size\":\"145\", \"side\":\"SELL\", \"hash\":\"30ad6b9e8ce48e36ed8afac12d46211ab7921c7f\", \"best_bid\":\"0.86\", \"best_ask\":\"0.87\"}], \"timestamp\":\"1789987926408\", \"event_type\":\"price_change\"}","raw_base64":null}
{"received_ms":1789987926433,"monotonic_ns":1019367264112500,"raw":"{\"market\":\"0x28a45972fccdaf0fba75dacc59725521035e177d09dd92174f9f52740bccb025\", \"price_changes\":[{\"asset_id\":\"61819828071723399190623735325323968706432622380635304641786792960078828866875\", \"price\":\"0.85\", \"size\":\"4658.35\", \"side\":\"BUY\", \"hash\":\"bb9acc0742f7f698b9c375e0daedcc0594f70d40\", \"best_bid\":\"0.86\", \"best_ask\":\"0.87\"}, {\"asset_id\":\"114356653315647913247200886351065428002113119844334520181865067698979836634569\", \"price\":\"0.15\", \"size\":\"4658.35\", \"side\":\"SELL\", \"hash\":\"fc74d6405a5384d88bfae14d93294247bd57629a\", \"best_bid\":\"0.13\", \"best_ask\":\"0.14\"}], \"timestamp\":\"1789987926408\", \"event_type\":\"price_change\"}","raw_base64":null}
{"received_ms":1789987926433,"monotonic_ns":1019367264151600,"raw":"{\"market\":\"0x28a45972fccdaf0fba75dacc59725521035e177d09dd92174f9f52740bccb025\", \"price_changes\":[{\"asset_id\":\"61819828071723399190623735325323968706432622380635304641786792960078828866875\", \"price\":\"0.84\", \"size\":\"3129\", \"side\":\"BUY\", \"hash\":\"5c119dbd563731541ed2d943483d3e9064f6a480\", \"best_bid\":\"0.86\", \"best_ask\":\"0.87\"}, {\"asset_id\":\"114356653315647913247200886351065428002113119844334520181865067698979836634569\", \"price\":\"0.16\", \"size\":\"3129\", \"side\":\"SELL\", \"hash\":\"2ddc7e5b0a72f45cac380d56b0c2ebfe2ab015e7\", \"best_bid\":\"0.13\", \"best_ask\":\"0.14\"}], \"timestamp\":\"1789987926409\", \"event_type\":\"price_change\"}","raw_base64":null}
{"received_ms":1789987926443,"monotonic_ns":1019367273382900,"raw":"{\"market\":\"0x28a45972fccdaf0fba75dacc59725521035e177d09dd92174f9f52740bccb025\", \"price_changes\":[{\"asset_id\":\"114356653315647913247200886351065428002113119844334520181865067698979836634569\", \"price\":\"0.11\", \"size\":\"136.1\", \"side\":\"BUY\", \"hash\":\"efe1df4e5a6ec1debd7b9552bfe216595b3f6a2c\", \"best_bid\":\"0.13\", \"best_ask\":\"0.14\"}, {\"asset_id\":\"61819828071723399190623735325323968706432622380635304641786792960078828866875\", \"price\":\"0.89\", \"size\":\"136.1\", \"side\":\"SELL\", \"hash\":\"08ca7d56231446d78e71a0c00bb2e1ccfd72a152\", \"best_bid\":\"0.86\", \"best_ask\":\"0.87\"}], \"timestamp\":\"1789987926421\", \"event_type\":\"price_change\"}","raw_base64":null}
{"received_ms":1789987926449,"monotonic_ns":1019367279647900,"raw":"{\"market\":\"0x28a45972fccdaf0fba75dacc59725521035e177d09dd92174f9f52740bccb025\", \"price_changes\":[{\"asset_id\":\"114356653315647913247200886351065428002113119844334520181865067698979836634569\", \"price\":\"0.13\", \"size\":\"245\", \"side\":\"BUY\", \"hash\":\"d7d1656102ef4d5334986d952bb07140fc2a882c\", \"best_bid\":\"0.13\", \"best_ask\":\"0.14\"}, {\"asset_id\":\"61819828071723399190623735325323968706432622380635304641786792960078828866875\", \"price\":\"0.87\", \"size\":\"245\", \"side\":\"SELL\", \"hash\":\"4cc24aadb4bb85eb028aa5c416f7797ea11c94ad\", \"best_bid\":\"0.86\", \"best_ask\":\"0.87\"}], \"timestamp\":\"1789987926424\", \"event_type\":\"price_change\"}","raw_base64":null}
{"received_ms":1789987926455,"monotonic_ns":1019367285629200,"raw":"{\"market\":\"0x28a45972fccdaf0fba75dacc59725521035e177d09dd92174f9f52740bccb025\", \"price_changes\":[{\"asset_id\":\"114356653315647913247200886351065428002113119844334520181865067698979836634569\", \"price\":\"0.09\", \"size\":\"678.12\", \"side\":\"BUY\", \"hash\":\"96d7ad43f2b0cc3e1087b16cbfe62c5091a4cd5f\", \"best_bid\":\"0.13\", \"best_ask\":\"0.14\"}, {\"asset_id\":\"61819828071723399190623735325323968706432622380635304641786792960078828866875\", \"price\":\"0.91\", \"size\":\"678.12\", \"side\":\"SELL\", \"hash\":\"a8fc383cc5ccc36786e72a157c2471190d28e51a\", \"best_bid\":\"0.86\", \"best_ask\":\"0.87\"}], \"timestamp\":\"1789987926432\", \"event_type\":\"price_change\"}","raw_base64":null}
{"received_ms":1789987926455,"monotonic_ns":1019367285700600,"raw":"{\"market\":\"0x28a45972fccdaf0fba75dacc59725521035e177d09dd92174f9f52740bccb025\", \"price_changes\":[{\"asset_id\":\"61819828071723399190623735325323968706432622380635304641786792960078828866875\", \"price\":\"0.01\", \"size\":\"1491.91\", \"side\":\"BUY\", \"hash\":\"455b190556deebb910cde322d405f968d06e0af6\", \"best_bid\":\"0.86\", \"best_ask\":\"0.87\"}, {\"asset_id\":\"114356653315647913247200886351065428002113119844334520181865067698979836634569\", \"price\":\"0.99\", \"size\":\"1491.91\", \"side\":\"SELL\", \"hash\":\"499cf68136db3c6cdbc4b4b61c356b1f636e1638\", \"best_bid\":\"0.13\", \"best_ask\":\"0.14\"}], \"timestamp\":\"1789987926433\", \"event_type\":\"price_change\"}","raw_base64":null}
{"received_ms":1789987926455,"monotonic_ns":1019367285756600,"raw":"{\"market\":\"0x28a45972fccdaf0fba75dacc59725521035e177d09dd92174f9f52740bccb025\", \"price_changes\":[{\"asset_id\":\"114356653315647913247200886351065428002113119844334520181865067698979836634569\", \"price\":\"0.11\", \"size\":\"128.1\", \"side\":\"BUY\", \"hash\":\"c35537f2cf6ea931839fc25f94e1a83cbc8cc1e9\", \"best_bid\":\"0.13\", \"best_ask\":\"0.14\"}, {\"asset_id\":\"61819828071723399190623735325323968706432622380635304641786792960078828866875\", \"price\":\"0.89\", \"size\":\"128.1\", \"side\":\"SELL\", \"hash\":\"7b69d190109637bbeb3a21f4a14597e1ce6df7ba\", \"best_bid\":\"0.86\", \"best_ask\":\"0.87\"}], \"timestamp\":\"1789987926434\", \"event_type\":\"price_change\"}","raw_base64":null}
{"received_ms":1789987926466,"monotonic_ns":1019367297092300,"raw":"{\"market\":\"0x28a45972fccdaf0fba75dacc59725521035e177d09dd92174f9f52740bccb025\", \"price_changes\":[{\"asset_id\":\"61819828071723399190623735325323968706432622380635304641786792960078828866875\", \"price\":\"0.85\", \"size\":\"4007.35\", \"side\":\"BUY\", \"hash\":\"deb55f87d32142d618f2225144ae1adf5f97aa2e\", \"best_bid\":\"0.86\", \"best_ask\":\"0.87\"}, {\"asset_id\":\"114356653315647913247200886351065428002113119844334520181865067698979836634569\", \"price\":\"0.15\", \"size\":\"4007.35\", \"side\":\"SELL\", \"hash\":\"80bbb776d244e1da5eb2a057430e693867c3a0ca\", \"best_bid\":\"0.13\", \"best_ask\":\"0.14\"}], \"timestamp\":\"1789987926444\", \"event_type\":\"price_change\"}","raw_base64":null}
{"received_ms":1789987926466,"monotonic_ns":1019367297159200,"raw":"{\"market\":\"0x28a45972fccdaf0fba75dacc59725521035e177d09dd92174f9f52740bccb025\", \"price_changes\":[{\"asset_id\":\"61819828071723399190623735325323968706432622380635304641786792960078828866875\", \"price\":\"0.84\", \"size\":\"3105\", \"side\":\"BUY\", \"hash\":\"794246a349ad1aa9ed45e387826662e8055d5951\", \"best_bid\":\"0.86\", \"best_ask\":\"0.87\"}, {\"asset_id\":\"114356653315647913247200886351065428002113119844334520181865067698979836634569\", \"price\":\"0.16\", \"size\":\"3105\", \"side\":\"SELL\", \"hash\":\"3b7d8217d0da9619074441e64e605cffa11c0e27\", \"best_bid\":\"0.13\", \"best_ask\":\"0.14\"}], \"timestamp\":\"1789987926445\", \"event_type\":\"price_change\"}","raw_base64":null}
{"received_ms":1789987926467,"monotonic_ns":1019367297738100,"raw":"{\"market\":\"0x28a45972fccdaf0fba75dacc59725521035e177d09dd92174f9f52740bccb025\", \"price_changes\":[{\"asset_id\":\"114356653315647913247200886351065428002113119844334520181865067698979836634569\", \"price\":\"0.06\", \"size\":\"6642.67\", \"side\":\"BUY\", \"hash\":\"93a2cc12fac023618df5610a1308f28f3c16f707\", \"best_bid\":\"0.13\", \"best_ask\":\"0.14\"}, {\"asset_id\":\"61819828071723399190623735325323968706432622380635304641786792960078828866875\", \"price\":\"0.94\", \"size\":\"6642.67\", \"side\":\"SELL\", \"hash\":\"fc7959a82c9449dde803be18309bd33e442f2ae3\", \"best_bid\":\"0.86\", \"best_ask\":\"0.87\"}], \"timestamp\":\"1789987926446\", \"event_type\":\"price_change\"}","raw_base64":null}
{"received_ms":1789987926472,"monotonic_ns":1019367302678000,"raw":"{\"market\":\"0x28a45972fccdaf0fba75dacc59725521035e177d09dd92174f9f52740bccb025\", \"price_changes\":[{\"asset_id\":\"61819828071723399190623735325323968706432622380635304641786792960078828866875\", \"price\":\"0.86\", \"size\":\"5999.17\", \"side\":\"BUY\", \"hash\":\"e14c14d158638a61dc97de5afa8b980807d37591\", \"best_bid\":\"0.86\", \"best_ask\":\"0.87\"}, {\"asset_id\":\"114356653315647913247200886351065428002113119844334520181865067698979836634569\", \"price\":\"0.14\", \"size\":\"5999.17\", \"side\":\"SELL\", \"hash\":\"dd926b6520bdde6aedd71e259a417af71d72431f\", \"best_bid\":\"0.13\", \"best_ask\":\"0.14\"}], \"timestamp\":\"1789987926452\", \"event_type\":\"price_change\"}","raw_base64":null}
{"received_ms":1789987926472,"monotonic_ns":1019367303231500,"raw":"{\"market\":\"0x28a45972fccdaf0fba75dacc59725521035e177d09dd92174f9f52740bccb025\", \"price_changes\":[{\"asset_id\":\"114356653315647913247200886351065428002113119844334520181865067698979836634569\", \"price\":\"0.07\", \"size\":\"5956.71\", \"side\":\"BUY\", \"hash\":\"cf213ddc568f28df661ee5ffd613fc53dc773348\", \"best_bid\":\"0.13\", \"best_ask\":\"0.14\"}, {\"asset_id\":\"61819828071723399190623735325323968706432622380635304641786792960078828866875\", \"price\":\"0.93\", \"size\":\"5956.71\", \"side\":\"SELL\", \"hash\":\"409ef8ad2c03bbd4eea88f3a21f7428512507faa\", \"best_bid\":\"0.86\", \"best_ask\":\"0.87\"}], \"timestamp\":\"1789987926452\", \"event_type\":\"price_change\"}","raw_base64":null}
{"received_ms":1789987926473,"monotonic_ns":1019367303656700,"raw":"{\"market\":\"0x28a45972fccdaf0fba75dacc59725521035e177d09dd92174f9f52740bccb025\", \"price_changes\":[{\"asset_id\":\"61819828071723399190623735325323968706432622380635304641786792960078828866875\", \"price\":\"0.86\", \"size\":\"5984\", \"side\":\"BUY\", \"hash\":\"61ab37257f89bd657b778a5adbc834283b380f9e\", \"best_bid\":\"0.86\", \"best_ask\":\"0.87\"}, {\"asset_id\":\"114356653315647913247200886351065428002113119844334520181865067698979836634569\", \"price\":\"0.14\", \"size\":\"5984\", \"side\":\"SELL\", \"hash\":\"3ee8abb49e9d590b81927741f841b37481d0abcc\", \"best_bid\":\"0.13\", \"best_ask\":\"0.14\"}], \"timestamp\":\"1789987926453\", \"event_type\":\"price_change\"}","raw_base64":null}
{"received_ms":1789987926476,"monotonic_ns":1019367306636700,"raw":"{\"market\":\"0x28a45972fccdaf0fba75dacc59725521035e177d09dd92174f9f52740bccb025\", \"price_changes\":[{\"asset_id\":\"61819828071723399190623735325323968706432622380635304641786792960078828866875\", \"price\":\"0.76\", \"size\":\"400\", \"side\":\"BUY\", \"hash\":\"a01c09238fe9d3b0220d224e94de2c90007dd4c3\", \"best_bid\":\"0.86\", \"best_ask\":\"0.87\"}, {\"asset_id\":\"114356653315647913247200886351065428002113119844334520181865067698979836634569\", \"price\":\"0.24\", \"size\":\"400\", \"side\":\"SELL\", \"hash\":\"65070e96e6e090024d54459bf5e086b9076ee4b5\", \"best_bid\":\"0.13\", \"best_ask\":\"0.14\"}], \"timestamp\":\"1789987926454\", \"event_type\":\"price_change\"}","raw_base64":null}
{"received_ms":1789987926477,"monotonic_ns":1019367307322900,"raw":"{\"market\":\"0x28a45972fccdaf0fba75dacc59725521035e177d09dd92174f9f52740bccb025\", \"price_changes\":[{\"asset_id\":\"61819828071723399190623735325323968706432622380635304641786792960078828866875\", \"price\":\"0.86\", \"size\":\"5974\", \"side\":\"BUY\", \"hash\":\"f564dcf56b83c6fb809bc0b77406df1948aeb512\", \"best_bid\":\"0.86\", \"best_ask\":\"0.87\"}, {\"asset_id\":\"114356653315647913247200886351065428002113119844334520181865067698979836634569\", \"price\":\"0.14\", \"size\":\"5974\", \"side\":\"SELL\", \"hash\":\"5e02ae39e5510f4cae525150aa5d112b797d41c2\", \"best_bid\":\"0.13\", \"best_ask\":\"0.14\"}], \"timestamp\":\"1789987926455\", \"event_type\":\"price_change\"}","raw_base64":null}
{"received_ms":1789987926477,"monotonic_ns":1019367307523500,"raw":"{\"market\":\"0x28a45972fccdaf0fba75dacc59725521035e177d09dd92174f9f52740bccb025\", \"price_changes\":[{\"asset_id\":\"61819828071723399190623735325323968706432622380635304641786792960078828866875\", \"price\":\"0.86\", \"size\":\"5969\", \"side\":\"BUY\", \"hash\":\"96556498e05b2f1f62ca3493c4b43f0d0d885408\", \"best_bid\":\"0.86\", \"best_ask\":\"0.87\"}, {\"asset_id\":\"114356653315647913247200886351065428002113119844334520181865067698979836634569\", \"price\":\"0.14\", \"size\":\"5969\", \"side\":\"SELL\", \"hash\":\"3d3146f22850c2ec5e7aefd06ec9f948563a6f44\", \"best_bid\":\"0.13\", \"best_ask\":\"0.14\"}], \"timestamp\":\"1789987926457\", \"event_type\":\"price_change\"}","raw_base64":null}
{"received_ms":1789987926479,"monotonic_ns":1019367309292500,"raw":"{\"market\":\"0x28a45972fccdaf0fba75dacc59725521035e177d09dd92174f9f52740bccb025\", \"price_changes\":[{\"asset_id\":\"114356653315647913247200886351065428002113119844334520181865067698979836634569\", \"price\":\"0.09\", \"size\":\"670.12\", \"side\":\"BUY\", \"hash\":\"caeffad9d73e846949f52154d1af11422f1988ee\", \"best_bid\":\"0.13\", \"best_ask\":\"0.14\"}, {\"asset_id\":\"61819828071723399190623735325323968706432622380635304641786792960078828866875\", \"price\":\"0.91\", \"size\":\"670.12\", \"side\":\"SELL\", \"hash\":\"25feafe09bb9dd39649f2e65c71e2a0050766a8f\", \"best_bid\":\"0.86\", \"best_ask\":\"0.87\"}], \"timestamp\":\"1789987926458\", \"event_type\":\"price_change\"}","raw_base64":null}
{"received_ms":1789987926481,"monotonic_ns":1019367311439500,"raw":"{\"market\":\"0x28a45972fccdaf0fba75dacc59725521035e177d09dd92174f9f52740bccb025\", \"price_changes\":[{\"asset_id\":\"114356653315647913247200886351065428002113119844334520181865067698979836634569\", \"price\":\"0.1\", \"size\":\"497\", \"side\":\"BUY\", \"hash\":\"e009ef44ef8331b03e73019de04dfc191e735980\", \"best_bid\":\"0.13\", \"best_ask\":\"0.14\"}, {\"asset_id\":\"61819828071723399190623735325323968706432622380635304641786792960078828866875\", \"price\":\"0.9\", \"size\":\"497\", \"side\":\"SELL\", \"hash\":\"0ca56658f42dea436deb580a470f228c9261bedc\", \"best_bid\":\"0.86\", \"best_ask\":\"0.87\"}], \"timestamp\":\"1789987926459\", \"event_type\":\"price_change\"}","raw_base64":null}
{"received_ms":1789987926481,"monotonic_ns":1019367311504500,"raw":"{\"market\":\"0x28a45972fccdaf0fba75dacc59725521035e177d09dd92174f9f52740bccb025\", \"price_changes\":[{\"asset_id\":\"61819828071723399190623735325323968706432622380635304641786792960078828866875\", \"price\":\"0.81\", \"size\":\"590\", \"side\":\"BUY\", \"hash\":\"392ca2c79f37575c4fe8141723a3895e68213117\", \"best_bid\":\"0.86\", \"best_ask\":\"0.87\"}, {\"asset_id\":\"114356653315647913247200886351065428002113119844334520181865067698979836634569\", \"price\":\"0.19\", \"size\":\"590\", \"side\":\"SELL\", \"hash\":\"d0a38ee98598f6a5ed5c64e0c4b45078ec05933e\", \"best_bid\":\"0.13\", \"best_ask\":\"0.14\"}], \"timestamp\":\"1789987926460\", \"event_type\":\"price_change\"}","raw_base64":null}
{"received_ms":1789987926486,"monotonic_ns":1019367317267400,"raw":"{\"market\":\"0x28a45972fccdaf0fba75dacc59725521035e177d09dd92174f9f52740bccb025\", \"price_changes\":[{\"asset_id\":\"114356653315647913247200886351065428002113119844334520181865067698979836634569\", \"price\":\"0.13\", \"size\":\"145\", \"side\":\"BUY\", \"hash\":\"b963c328ff783d7cc0694a24644afca0392a914c\", \"best_bid\":\"0.13\", \"best_ask\":\"0.14\"}, {\"asset_id\":\"61819828071723399190623735325323968706432622380635304641786792960078828866875\", \"price\":\"0.87\", \"size\":\"145\", \"side\":\"SELL\", \"hash\":\"d5eacb89437611f7acedc5da1f188da000d11210\", \"best_bid\":\"0.86\", \"best_ask\":\"0.87\"}], \"timestamp\":\"1789987926466\", \"event_type\":\"price_change\"}","raw_base64":null}
{"received_ms":1789987926487,"monotonic_ns":1019367318221200,"raw":"{\"market\":\"0x28a45972fccdaf0fba75dacc59725521035e177d09dd92174f9f52740bccb025\", \"price_changes\":[{\"asset_id\":\"61819828071723399190623735325323968706432622380635304641786792960078828866875\", \"price\":\"0.86\", \"size\":\"5469\", \"side\":\"BUY\", \"hash\":\"002b3ac37cab5d9515f4df33e6e78af427a3f7f5\", \"best_bid\":\"0.86\", \"best_ask\":\"0.87\"}, {\"asset_id\":\"114356653315647913247200886351065428002113119844334520181865067698979836634569\", \"price\":\"0.14\", \"size\":\"5469\", \"side\":\"SELL\", \"hash\":\"5912471f712241d7531706a16490c2e1f1610b6d\", \"best_bid\":\"0.13\", \"best_ask\":\"0.14\"}], \"timestamp\":\"1789987926467\", \"event_type\":\"price_change\"}","raw_base64":null}
{"received_ms":1789987926493,"monotonic_ns":1019367324173700,"raw":"{\"market\":\"0x28a45972fccdaf0fba75dacc59725521035e177d09dd92174f9f52740bccb025\", \"price_changes\":[{\"asset_id\":\"114356653315647913247200886351065428002113119844334520181865067698979836634569\", \"price\":\"0.11\", \"size\":\"228.1\", \"side\":\"BUY\", \"hash\":\"024847cb9bbe898735d625967f4d6996c193ef93\", \"best_bid\":\"0.13\", \"best_ask\":\"0.14\"}, {\"asset_id\":\"61819828071723399190623735325323968706432622380635304641786792960078828866875\", \"price\":\"0.89\", \"size\":\"228.1\", \"side\":\"SELL\", \"hash\":\"0bfb34178eede5f562c62bdd1eae25a9ee5a4a9d\", \"best_bid\":\"0.86\", \"best_ask\":\"0.87\"}], \"timestamp\":\"1789987926470\", \"event_type\":\"price_change\"}","raw_base64":null}
{"received_ms":1789987926498,"monotonic_ns":1019367328571300,"raw":"{\"market\":\"0x28a45972fccdaf0fba75dacc59725521035e177d09dd92174f9f52740bccb025\", \"price_changes\":[{\"asset_id\":\"114356653315647913247200886351065428002113119844334520181865067698979836634569\", \"price\":\"0.11\", \"size\":\"236.1\", \"side\":\"BUY\", \"hash\":\"dce0d78b30c7ed20ba4d77eaf04b1adc1fe89323\", \"best_bid\":\"0.13\", \"best_ask\":\"0.14\"}, {\"asset_id\":\"61819828071723399190623735325323968706432622380635304641786792960078828866875\", \"price\":\"0.89\", \"size\":\"236.1\", \"side\":\"SELL\", \"hash\":\"741857d1b9798b3002a30824f925c472a10f7e23\", \"best_bid\":\"0.86\", \"best_ask\":\"0.87\"}], \"timestamp\":\"1789987926478\", \"event_type\":\"price_change\"}","raw_base64":null}
{"received_ms":1789987926503,"monotonic_ns":1019367334044100,"raw":"{\"market\":\"0x28a45972fccdaf0fba75dacc59725521035e177d09dd92174f9f52740bccb025\", \"price_changes\":[{\"asset_id\":\"114356653315647913247200886351065428002113119844334520181865067698979836634569\", \"price\":\"0.07\", \"size\":\"5081.71\", \"side\":\"BUY\", \"hash\":\"74d3999011a165effbd2f86b6ee901915e0cbea7\", \"best_bid\":\"0.13\", \"best_ask\":\"0.14\"}, {\"asset_id\":\"61819828071723399190623735325323968706432622380635304641786792960078828866875\", \"price\":\"0.93\", \"size\":\"5081.71\", \"side\":\"SELL\", \"hash\":\"358636054670897724ff4615bf6e8decc71b026f\", \"best_bid\":\"0.86\", \"best_ask\":\"0.87\"}], \"timestamp\":\"1789987926483\", \"event_type\":\"price_change\"}","raw_base64":null}
{"received_ms":1789987926506,"monotonic_ns":1019367336371300,"raw":"{\"market\":\"0x28a45972fccdaf0fba75dacc59725521035e177d09dd92174f9f52740bccb025\", \"price_changes\":[{\"asset_id\":\"114356653315647913247200886351065428002113119844334520181865067698979836634569\", \"price\":\"0.09\", \"size\":\"610.12\", \"side\":\"BUY\", \"hash\":\"38039a645564bebd1139e24566fa9eb74d4b4a75\", \"best_bid\":\"0.13\", \"best_ask\":\"0.14\"}, {\"asset_id\":\"61819828071723399190623735325323968706432622380635304641786792960078828866875\", \"price\":\"0.91\", \"size\":\"610.12\", \"side\":\"SELL\", \"hash\":\"b419d82852eb34ab55f7eb52e818a10a3f076ddd\", \"best_bid\":\"0.86\", \"best_ask\":\"0.87\"}], \"timestamp\":\"1789987926485\", \"event_type\":\"price_change\"}","raw_base64":null}
{"received_ms":1789987926508,"monotonic_ns":1019367338435700,"raw":"{\"market\":\"0x28a45972fccdaf0fba75dacc59725521035e177d09dd92174f9f52740bccb025\", \"price_changes\":[{\"asset_id\":\"61819828071723399190623735325323968706432622380635304641786792960078828866875\", \"price\":\"0.79\", \"size\":\"467\", \"side\":\"BUY\", \"hash\":\"2d03162ccd69d77dcb60bd2362ce41d4520fbbbb\", \"best_bid\":\"0.86\", \"best_ask\":\"0.87\"}, {\"asset_id\":\"114356653315647913247200886351065428002113119844334520181865067698979836634569\", \"price\":\"0.21\", \"size\":\"467\", \"side\":\"SELL\", \"hash\":\"409d481dbeae594d25728ca075558fbb1c31d24b\", \"best_bid\":\"0.13\", \"best_ask\":\"0.14\"}], \"timestamp\":\"1789987926487\", \"event_type\":\"price_change\"}","raw_base64":null}
{"received_ms":1789987926512,"monotonic_ns":1019367342478300,"raw":"{\"market\":\"0x28a45972fccdaf0fba75dacc59725521035e177d09dd92174f9f52740bccb025\", \"price_changes\":[{\"asset_id\":\"61819828071723399190623735325323968706432622380635304641786792960078828866875\", \"price\":\"0.86\", \"size\":\"5504.17\", \"side\":\"BUY\", \"hash\":\"cba549adeff93c1204c4b7be463c390049081fd7\", \"best_bid\":\"0.86\", \"best_ask\":\"0.87\"}, {\"asset_id\":\"114356653315647913247200886351065428002113119844334520181865067698979836634569\", \"price\":\"0.14\", \"size\":\"5504.17\", \"side\":\"SELL\", \"hash\":\"45f3fda9097568c1ae62e81a977549349162e2a2\", \"best_bid\":\"0.13\", \"best_ask\":\"0.14\"}], \"timestamp\":\"1789987926488\", \"event_type\":\"price_change\"}","raw_base64":null}
{"received_ms":1789987926515,"monotonic_ns":1019367346167000,"raw":"{\"market\":\"0x28a45972fccdaf0fba75dacc59725521035e177d09dd92174f9f52740bccb025\", \"price_changes\":[{\"asset_id\":\"114356653315647913247200886351065428002113119844334520181865067698979836634569\", \"price\":\"0.09\", \"size\":\"618.12\", \"side\":\"BUY\", \"hash\":\"c4e5729b59fda4ea78a50ece9f1d847d65ec2754\", \"best_bid\":\"0.13\", \"best_ask\":\"0.14\"}, {\"asset_id\":\"61819828071723399190623735325323968706432622380635304641786792960078828866875\", \"price\":\"0.91\", \"size\":\"618.12\", \"side\":\"SELL\", \"hash\":\"c037b9f01b1dbf71d861c6263629caede3b026d1\", \"best_bid\":\"0.86\", \"best_ask\":\"0.87\"}], \"timestamp\":\"1789987926492\", \"event_type\":\"price_change\"}","raw_base64":null}
{"received_ms":1789987926518,"monotonic_ns":1019367349059300,"raw":"{\"market\":\"0x28a45972fccdaf0fba75dacc59725521035e177d09dd92174f9f52740bccb025\", \"price_changes\":[{\"asset_id\":\"61819828071723399190623735325323968706432622380635304641786792960078828866875\", \"price\":\"0.86\", \"size\":\"5509.17\", \"side\":\"BUY\", \"hash\":\"8d6a182a235ef3245c775bd3e0205bc28d33ac0c\", \"best_bid\":\"0.86\", \"best_ask\":\"0.87\"}, {\"asset_id\":\"114356653315647913247200886351065428002113119844334520181865067698979836634569\", \"price\":\"0.14\", \"size\":\"5509.17\", \"side\":\"SELL\", \"hash\":\"3185f6d67f04bf2ff88b71a84f09508a21cf49f8\", \"best_bid\":\"0.13\", \"best_ask\":\"0.14\"}], \"timestamp\":\"1789987926497\", \"event_type\":\"price_change\"}","raw_base64":null}
{"received_ms":1789987926521,"monotonic_ns":1019367351360000,"raw":"{\"market\":\"0x28a45972fccdaf0fba75dacc59725521035e177d09dd92174f9f52740bccb025\", \"price_changes\":[{\"asset_id\":\"61819828071723399190623735325323968706432622380635304641786792960078828866875\", \"price\":\"0.86\", \"size\":\"5474\", \"side\":\"BUY\", \"hash\":\"772ec99fabebc8ae602c55d6fb3ac595d799575d\", \"best_bid\":\"0.86\", \"best_ask\":\"0.87\"}, {\"asset_id\":\"114356653315647913247200886351065428002113119844334520181865067698979836634569\", \"price\":\"0.14\", \"size\":\"5474\", \"side\":\"SELL\", \"hash\":\"107bb84958d22c887752d56e11041b819ef0a058\", \"best_bid\":\"0.13\", \"best_ask\":\"0.14\"}], \"timestamp\":\"1789987926500\", \"event_type\":\"price_change\"}","raw_base64":null}
{"received_ms":1789987926522,"monotonic_ns":1019367352925000,"raw":"{\"market\":\"0x28a45972fccdaf0fba75dacc59725521035e177d09dd92174f9f52740bccb025\", \"price_changes\":[{\"asset_id\":\"61819828071723399190623735325323968706432622380635304641786792960078828866875\", \"price\":\"0.76\", \"size\":\"390\", \"side\":\"BUY\", \"hash\":\"c9f05aa146f8bcbd54212b8d7e690f69bf6c994e\", \"best_bid\":\"0.86\", \"best_ask\":\"0.87\"}, {\"asset_id\":\"114356653315647913247200886351065428002113119844334520181865067698979836634569\", \"price\":\"0.24\", \"size\":\"390\", \"side\":\"SELL\", \"hash\":\"3f4d97fe43edeb180d09d680b429beb791d6c674\", \"best_bid\":\"0.13\", \"best_ask\":\"0.14\"}], \"timestamp\":\"1789987926501\", \"event_type\":\"price_change\"}","raw_base64":null}
{"received_ms":1789987926522,"monotonic_ns":1019367352963100,"raw":"{\"market\":\"0x28a45972fccdaf0fba75dacc59725521035e177d09dd92174f9f52740bccb025\", \"price_changes\":[{\"asset_id\":\"61819828071723399190623735325323968706432622380635304641786792960078828866875\", \"price\":\"0.86\", \"size\":\"5484\", \"side\":\"BUY\", \"hash\":\"fcd3b4b5c06e6322ff3ad1a2d030fbe4927f05fd\", \"best_bid\":\"0.86\", \"best_ask\":\"0.87\"}, {\"asset_id\":\"114356653315647913247200886351065428002113119844334520181865067698979836634569\", \"price\":\"0.14\", \"size\":\"5484\", \"side\":\"SELL\", \"hash\":\"427ebbb7db2ebf4bec1f7d1191ad46da12346b24\", \"best_bid\":\"0.13\", \"best_ask\":\"0.14\"}], \"timestamp\":\"1789987926501\", \"event_type\":\"price_change\"}","raw_base64":null}
{"received_ms":1789987926529,"monotonic_ns":1019367359806900,"raw":"{\"market\":\"0x28a45972fccdaf0fba75dacc59725521035e177d09dd92174f9f52740bccb025\", \"price_changes\":[{\"asset_id\":\"114356653315647913247200886351065428002113119844334520181865067698979836634569\", \"price\":\"0.13\", \"size\":\"155\", \"side\":\"BUY\", \"hash\":\"d399c1b5a7939c23bb167ccb5dbc82e0d89367da\", \"best_bid\":\"0.13\", \"best_ask\":\"0.14\"}, {\"asset_id\":\"61819828071723399190623735325323968706432622380635304641786792960078828866875\", \"price\":\"0.87\", \"size\":\"155\", \"side\":\"SELL\", \"hash\":\"8dd2baf26fdf3e616f108af62f1dff27b717b34d\", \"best_bid\":\"0.86\", \"best_ask\":\"0.87\"}], \"timestamp\":\"1789987926507\", \"event_type\":\"price_change\"}","raw_base64":null}
{"received_ms":1789987926529,"monotonic_ns":1019367359887100,"raw":"{\"market\":\"0x28a45972fccdaf0fba75dacc59725521035e177d09dd92174f9f52740bccb025\", \"price_changes\":[{\"asset_id\":\"61819828071723399190623735325323968706432622380635304641786792960078828866875\", \"price\":\"0.86\", \"size\":\"5291\", \"side\":\"BUY\", \"hash\":\"6cf305c78b9a05cae8e7fd8b23b34f76258b0d5f\", \"best_bid\":\"0.86\", \"best_ask\":\"0.87\"}, {\"asset_id\":\"114356653315647913247200886351065428002113119844334520181865067698979836634569\", \"price\":\"0.14\", \"size\":\"5291\", \"side\":\"SELL\", \"hash\":\"5c8900f3f497df284a1faccd615ab093cf0d9ee2\", \"best_bid\":\"0.13\", \"best_ask\":\"0.14\"}], \"timestamp\":\"1789987926508\", \"event_type\":\"price_change\"}","raw_base64":null}
{"received_ms":1789987926531,"monotonic_ns":1019367362201600,"raw":"{\"market\":\"0x28a45972fccdaf0fba75dacc59725521035e177d09dd92174f9f52740bccb025\", \"price_changes\":[{\"asset_id\":\"114356653315647913247200886351065428002113119844334520181865067698979836634569\", \"price\":\"0.11\", \"size\":\"136.1\", \"side\":\"BUY\", \"hash\":\"9a6b26244a5ba8ace14ee8350a7dce9a99c304ef\", \"best_bid\":\"0.13\", \"best_ask\":\"0.14\"}, {\"asset_id\":\"61819828071723399190623735325323968706432622380635304641786792960078828866875\", \"price\":\"0.89\", \"size\":\"136.1\", \"side\":\"SELL\", \"hash\":\"58f6141ee0cacd68da47c64ff636c3cab21acdd9\", \"best_bid\":\"0.86\", \"best_ask\":\"0.87\"}], \"timestamp\":\"1789987926511\", \"event_type\":\"price_change\"}","raw_base64":null}
{"received_ms":1789987926535,"monotonic_ns":1019367365882000,"raw":"{\"market\":\"0x28a45972fccdaf0fba75dacc59725521035e177d09dd92174f9f52740bccb025\", \"price_changes\":[{\"asset_id\":\"114356653315647913247200886351065428002113119844334520181865067698979836634569\", \"price\":\"0.06\", \"size\":\"7100.67\", \"side\":\"BUY\", \"hash\":\"0d99aea33aba9a8de5f92cf1ebc55a31154b6b57\", \"best_bid\":\"0.13\", \"best_ask\":\"0.14\"}, {\"asset_id\":\"61819828071723399190623735325323968706432622380635304641786792960078828866875\", \"price\":\"0.94\", \"size\":\"7100.67\", \"side\":\"SELL\", \"hash\":\"50f565102ddb2bea63a9b5785e472539df142c04\", \"best_bid\":\"0.86\", \"best_ask\":\"0.87\"}], \"timestamp\":\"1789987926515\", \"event_type\":\"price_change\"}","raw_base64":null}
{"received_ms":1789987926536,"monotonic_ns":1019367367014900,"raw":"{\"market\":\"0x28a45972fccdaf0fba75dacc59725521035e177d09dd92174f9f52740bccb025\", \"price_changes\":[{\"asset_id\":\"61819828071723399190623735325323968706432622380635304641786792960078828866875\", \"price\":\"0.79\", \"size\":\"447\", \"side\":\"BUY\", \"hash\":\"7cda3cb353333907e4770eb00e70184042424a8f\", \"best_bid\":\"0.86\", \"best_ask\":\"0.87\"}, {\"asset_id\":\"114356653315647913247200886351065428002113119844334520181865067698979836634569\", \"price\":\"0.21\", \"size\":\"447\", \"side\":\"SELL\", \"hash\":\"bde702ce1a387e78024e1c04b600048a0ad078ec\", \"best_bid\":\"0.13\", \"best_ask\":\"0.14\"}], \"timestamp\":\"1789987926515\", \"event_type\":\"price_change\"}","raw_base64":null}
{"received_ms":1789987926536,"monotonic_ns":1019367367057100,"raw":"{\"market\":\"0x28a45972fccdaf0fba75dacc59725521035e177d09dd92174f9f52740bccb025\", \"price_changes\":[{\"asset_id\":\"114356653315647913247200886351065428002113119844334520181865067698979836634569\", \"price\":\"0.07\", \"size\":\"5323.71\", \"side\":\"BUY\", \"hash\":\"52360bcc52005387c4326fc8a0900ae394b5e2b0\", \"best_bid\":\"0.13\", \"best_ask\":\"0.14\"}, {\"asset_id\":\"61819828071723399190623735325323968706432622380635304641786792960078828866875\", \"price\":\"0.93\", \"size\":\"5323.71\", \"side\":\"SELL\", \"hash\":\"0a767db1ef82cc69af9138caa40ed832cd4f9787\", \"best_bid\":\"0.86\", \"best_ask\":\"0.87\"}], \"timestamp\":\"1789987926516\", \"event_type\":\"price_change\"}","raw_base64":null}
{"received_ms":1789987926537,"monotonic_ns":1019367367480000,"raw":"{\"market\":\"0x28a45972fccdaf0fba75dacc59725521035e177d09dd92174f9f52740bccb025\", \"price_changes\":[{\"asset_id\":\"114356653315647913247200886351065428002113119844334520181865067698979836634569\", \"price\":\"0.09\", \"size\":\"678.12\", \"side\":\"BUY\", \"hash\":\"cce0e104ac9bd26ad22125a9b950f03ec7454469\", \"best_bid\":\"0.13\", \"best_ask\":\"0.14\"}, {\"asset_id\":\"61819828071723399190623735325323968706432622380635304641786792960078828866875\", \"price\":\"0.91\", \"size\":\"678.12\", \"side\":\"SELL\", \"hash\":\"d84e83131df7e0ab842ff56d3477023ff1a6b36c\", \"best_bid\":\"0.86\", \"best_ask\":\"0.87\"}], \"timestamp\":\"1789987926517\", \"event_type\":\"price_change\"}","raw_base64":null}
{"received_ms":1789987926537,"monotonic_ns":1019367368223700,"raw":"{\"market\":\"0x28a45972fccdaf0fba75dacc59725521035e177d09dd92174f9f52740bccb025\", \"price_changes\":[{\"asset_id\":\"114356653315647913247200886351065428002113119844334520181865067698979836634569\", \"price\":\"0.13\", \"size\":\"255\", \"side\":\"BUY\", \"hash\":\"0fc2772474d8360c7f568bfef284a74cdf9cd99d\", \"best_bid\":\"0.13\", \"best_ask\":\"0.14\"}, {\"asset_id\":\"61819828071723399190623735325323968706432622380635304641786792960078828866875\", \"price\":\"0.87\", \"size\":\"255\", \"side\":\"SELL\", \"hash\":\"1c83be5da2b747ba41b7aa9071a3b03ea2b6f71d\", \"best_bid\":\"0.86\", \"best_ask\":\"0.87\"}], \"timestamp\":\"1789987926517\", \"event_type\":\"price_change\"}","raw_base64":null}
{"received_ms":1789987926540,"monotonic_ns":1019367370882000,"raw":"{\"market\":\"0x28a45972fccdaf0fba75dacc59725521035e177d09dd92174f9f52740bccb025\", \"price_changes\":[{\"asset_id\":\"114356653315647913247200886351065428002113119844334520181865067698979836634569\", \"price\":\"0.09\", \"size\":\"670.12\", \"side\":\"BUY\", \"hash\":\"6088f6cc9cc3aa13f12b5b324a55594e1803d4b2\", \"best_bid\":\"0.13\", \"best_ask\":\"0.14\"}, {\"asset_id\":\"61819828071723399190623735325323968706432622380635304641786792960078828866875\", \"price\":\"0.91\", \"size\":\"670.12\", \"side\":\"SELL\", \"hash\":\"1f849ec494ebfecf1db8c7d84aac1c4f8f657034\", \"best_bid\":\"0.86\", \"best_ask\":\"0.87\"}], \"timestamp\":\"1789987926520\", \"event_type\":\"price_change\"}","raw_base64":null}
{"received_ms":1789987926548,"monotonic_ns":1019367378795300,"raw":"{\"market\":\"0x28a45972fccdaf0fba75dacc59725521035e177d09dd92174f9f52740bccb025\", \"price_changes\":[{\"asset_id\":\"114356653315647913247200886351065428002113119844334520181865067698979836634569\", \"price\":\"0.13\", \"size\":\"155\", \"side\":\"BUY\", \"hash\":\"921f2d521361e0adb4a61ab008f4d8de71d31dfa\", \"best_bid\":\"0.13\", \"best_ask\":\"0.14\"}, {\"asset_id\":\"61819828071723399190623735325323968706432622380635304641786792960078828866875\", \"price\":\"0.87\", \"size\":\"155\", \"side\":\"SELL\", \"hash\":\"1097d0dd739a201c3c04127d95c2c46608d86e7c\", \"best_bid\":\"0.86\", \"best_ask\":\"0.87\"}], \"timestamp\":\"1789987926528\", \"event_type\":\"price_change\"}","raw_base64":null}
{"received_ms":1789987926552,"monotonic_ns":1019367382617000,"raw":"{\"market\":\"0x28a45972fccdaf0fba75dacc59725521035e177d09dd92174f9f52740bccb025\", \"price_changes\":[{\"asset_id\":\"114356653315647913247200886351065428002113119844334520181865067698979836634569\", \"price\":\"0.11\", \"size\":\"236.1\", \"side\":\"BUY\", \"hash\":\"2a84d939f7e68f31c33cd17c14a90ce8d89914a9\", \"best_bid\":\"0.13\", \"best_ask\":\"0.14\"}, {\"asset_id\":\"61819828071723399190623735325323968706432622380635304641786792960078828866875\", \"price\":\"0.89\", \"size\":\"236.1\", \"side\":\"SELL\", \"hash\":\"30ff5842767937d28eb8b4a10958379af1b90fd3\", \"best_bid\":\"0.86\", \"best_ask\":\"0.87\"}], \"timestamp\":\"1789987926530\", \"event_type\":\"price_change\"}","raw_base64":null}
{"received_ms":1789987926553,"monotonic_ns":1019367383445900,"raw":"{\"market\":\"0x28a45972fccdaf0fba75dacc59725521035e177d09dd92174f9f52740bccb025\", \"price_changes\":[{\"asset_id\":\"61819828071723399190623735325323968706432622380635304641786792960078828866875\", \"price\":\"0.86\", \"size\":\"5306.17\", \"side\":\"BUY\", \"hash\":\"01df85b208c0c71adc7a869a4936228db7c87185\", \"best_bid\":\"0.86\", \"best_ask\":\"0.87\"}, {\"asset_id\":\"114356653315647913247200886351065428002113119844334520181865067698979836634569\", \"price\":\"0.14\", \"size\":\"5306.17\", \"side\":\"SELL\", \"hash\":\"de8fa61b8902c17effbd9590535d034156d0a681\", \"best_bid\":\"0.13\", \"best_ask\":\"0.14\"}], \"timestamp\":\"1789987926531\", \"event_type\":\"price_change\"}","raw_base64":null}
{"received_ms":1789987926553,"monotonic_ns":1019367383499400,"raw":"{\"market\":\"0x28a45972fccdaf0fba75dacc59725521035e177d09dd92174f9f52740bccb025\", \"price_changes\":[{\"asset_id\":\"114356653315647913247200886351065428002113119844334520181865067698979836634569\", \"price\":\"0.09\", \"size\":\"610.12\", \"side\":\"BUY\", \"hash\":\"6d86c72514271306d2d5dcfdd710229a8e5ff08d\", \"best_bid\":\"0.13\", \"best_ask\":\"0.14\"}, {\"asset_id\":\"61819828071723399190623735325323968706432622380635304641786792960078828866875\", \"price\":\"0.91\", \"size\":\"610.12\", \"side\":\"SELL\", \"hash\":\"6b2bf7a3d8727c16e31cb11a5be02c950b45aef3\", \"best_bid\":\"0.86\", \"best_ask\":\"0.87\"}], \"timestamp\":\"1789987926532\", \"event_type\":\"price_change\"}","raw_base64":null}
{"received_ms":1789987926564,"monotonic_ns":1019367395229300,"raw":"{\"market\":\"0x28a45972fccdaf0fba75dacc59725521035e177d09dd92174f9f52740bccb025\", \"price_changes\":[{\"asset_id\":\"114356653315647913247200886351065428002113119844334520181865067698979836634569\", \"price\":\"0.06\", \"size\":\"6642.67\", \"side\":\"BUY\", \"hash\":\"07eadf61ad8e8318964873f43d9867e6563252ed\", \"best_bid\":\"0.13\", \"best_ask\":\"0.14\"}, {\"asset_id\":\"61819828071723399190623735325323968706432622380635304641786792960078828866875\", \"price\":\"0.94\", \"size\":\"6642.67\", \"side\":\"SELL\", \"hash\":\"54852ece6454ae940ac87dd7fc831189c1048c21\", \"best_bid\":\"0.86\", \"best_ask\":\"0.87\"}], \"timestamp\":\"1789987926543\", \"event_type\":\"price_change\"}","raw_base64":null}
{"received_ms":1789987926565,"monotonic_ns":1019367395434700,"raw":"{\"market\":\"0x28a45972fccdaf0fba75dacc59725521035e177d09dd92174f9f52740bccb025\", \"price_changes\":[{\"asset_id\":\"61819828071723399190623735325323968706432622380635304641786792960078828866875\", \"price\":\"0.86\", \"size\":\"5313.17\", \"side\":\"BUY\", \"hash\":\"fb8892113a03aec236cb591b82b0ff50262a1dee\", \"best_bid\":\"0.86\", \"best_ask\":\"0.87\"}, {\"asset_id\":\"114356653315647913247200886351065428002113119844334520181865067698979836634569\", \"price\":\"0.14\", \"size\":\"5313.17\", \"side\":\"SELL\", \"hash\":\"bae234e5ecf391daf7357a7d3d73afe3db41c203\", \"best_bid\":\"0.13\", \"best_ask\":\"0.14\"}], \"timestamp\":\"1789987926544\", \"event_type\":\"price_change\"}","raw_base64":null}
{"received_ms":1789987926567,"monotonic_ns":1019367397783400,"raw":"{\"market\":\"0x28a45972fccdaf0fba75dacc59725521035e177d09dd92174f9f52740bccb025\", \"price_changes\":[{\"asset_id\":\"61819828071723399190623735325323968706432622380635304641786792960078828866875\", \"price\":\"0.86\", \"size\":\"5308.17\", \"side\":\"BUY\", \"hash\":\"78da98220426723ea54012023c5f518b3d28a7ef\", \"best_bid\":\"0.86\", \"best_ask\":\"0.87\"}, {\"asset_id\":\"114356653315647913247200886351065428002113119844334520181865067698979836634569\", \"price\":\"0.14\", \"size\":\"5308.17\", \"side\":\"SELL\", \"hash\":\"e50dac911cace42ba8c2f3280b9d1d3da0126700\", \"best_bid\":\"0.13\", \"best_ask\":\"0.14\"}], \"timestamp\":\"1789987926544\", \"event_type\":\"price_change\"}","raw_base64":null}
{"received_ms":1789987926568,"monotonic_ns":1019367399131500,"raw":"{\"market\":\"0x28a45972fccdaf0fba75dacc59725521035e177d09dd92174f9f52740bccb025\", \"price_changes\":[{\"asset_id\":\"61819828071723399190623735325323968706432622380635304641786792960078828866875\", \"price\":\"0.85\", \"size\":\"5004.35\", \"side\":\"BUY\", \"hash\":\"7d6e5b328d8eb78c2e408ab5ed399faa08686e7f\", \"best_bid\":\"0.86\", \"best_ask\":\"0.87\"}, {\"asset_id\":\"114356653315647913247200886351065428002113119844334520181865067698979836634569\", \"price\":\"0.15\", \"size\":\"5004.35\", \"side\":\"SELL\", \"hash\":\"d749352f958b39511ccad22b279b87ddb5126c58\", \"best_bid\":\"0.13\", \"best_ask\":\"0.14\"}], \"timestamp\":\"1789987926548\", \"event_type\":\"price_change\"}","raw_base64":null}
{"received_ms":1789987926569,"monotonic_ns":1019367399682200,"raw":"{\"market\":\"0x28a45972fccdaf0fba75dacc59725521035e177d09dd92174f9f52740bccb025\", \"price_changes\":[{\"asset_id\":\"61819828071723399190623735325323968706432622380635304641786792960078828866875\", \"price\":\"0.86\", \"size\":\"5298.17\", \"side\":\"BUY\", \"hash\":\"e3d126869384c451eda6bc33abef80753dc3b21d\", \"best_bid\":\"0.86\", \"best_ask\":\"0.87\"}, {\"asset_id\":\"114356653315647913247200886351065428002113119844334520181865067698979836634569\", \"price\":\"0.14\", \"size\":\"5298.17\", \"side\":\"SELL\", \"hash\":\"5a01d4fec03e4c2b25de66ffd6b5d28a1efa887a\", \"best_bid\":\"0.13\", \"best_ask\":\"0.14\"}], \"timestamp\":\"1789987926549\", \"event_type\":\"price_change\"}","raw_base64":null}
{"received_ms":1789987926569,"monotonic_ns":1019367400071200,"raw":"{\"market\":\"0x28a45972fccdaf0fba75dacc59725521035e177d09dd92174f9f52740bccb025\", \"price_changes\":[{\"asset_id\":\"61819828071723399190623735325323968706432622380635304641786792960078828866875\", \"price\":\"0.76\", \"size\":\"400\", \"side\":\"BUY\", \"hash\":\"bb6a444c4a2c484bd05221f6140726a4e8f37ede\", \"best_bid\":\"0.86\", \"best_ask\":\"0.87\"}, {\"asset_id\":\"114356653315647913247200886351065428002113119844334520181865067698979836634569\", \"price\":\"0.24\", \"size\":\"400\", \"side\":\"SELL\", \"hash\":\"6177cac27bf7560b876553285bfbeb61b94ed353\", \"best_bid\":\"0.13\", \"best_ask\":\"0.14\"}], \"timestamp\":\"1789987926549\", \"event_type\":\"price_change\"}","raw_base64":null}
{"received_ms":1789987926571,"monotonic_ns":1019367402009800,"raw":"{\"market\":\"0x28a45972fccdaf0fba75dacc59725521035e177d09dd92174f9f52740bccb025\", \"price_changes\":[{\"asset_id\":\"61819828071723399190623735325323968706432622380635304641786792960078828866875\", \"price\":\"0.84\", \"size\":\"3129\", \"side\":\"BUY\", \"hash\":\"46e0441dc02c535b95c186485c62f267f7fe55b9\", \"best_bid\":\"0.86\", \"best_ask\":\"0.87\"}, {\"asset_id\":\"114356653315647913247200886351065428002113119844334520181865067698979836634569\", \"price\":\"0.16\", \"size\":\"3129\", \"side\":\"SELL\", \"hash\":\"003835d3e6a57b85755082ea2b6c8642e116b3ac\", \"best_bid\":\"0.13\", \"best_ask\":\"0.14\"}], \"timestamp\":\"1789987926550\", \"event_type\":\"price_change\"}","raw_base64":null}
{"received_ms":1789987926571,"monotonic_ns":1019367402073700,"raw":"{\"market\":\"0x28a45972fccdaf0fba75dacc59725521035e177d09dd92174f9f52740bccb025\", \"price_changes\":[{\"asset_id\":\"61819828071723399190623735325323968706432622380635304641786792960078828866875\", \"price\":\"0.86\", \"size\":\"5283\", \"side\":\"BUY\", \"hash\":\"ac314f6401c0e06e355f6a7f756bb50293267995\", \"best_bid\":\"0.86\", \"best_ask\":\"0.87\"}, {\"asset_id\":\"114356653315647913247200886351065428002113119844334520181865067698979836634569\", \"price\":\"0.14\", \"size\":\"5283\", \"side\":\"SELL\", \"hash\":\"21928761d1476e9ddd20f34a3b57fa551159e216\", \"best_bid\":\"0.13\", \"best_ask\":\"0.14\"}], \"timestamp\":\"1789987926550\", \"event_type\":\"price_change\"}","raw_base64":null}
{"received_ms":1789987926571,"monotonic_ns":1019367402117900,"raw":"{\"market\":\"0x28a45972fccdaf0fba75dacc59725521035e177d09dd92174f9f52740bccb025\", \"price_changes\":[{\"asset_id\":\"61819828071723399190623735325323968706432622380635304641786792960078828866875\", \"price\":\"0.86\", \"size\":\"5406\", \"side\":\"BUY\", \"hash\":\"ec2239375245cf042d1db92fb34dc1e3231cd6f5\", \"best_bid\":\"0.86\", \"best_ask\":\"0.87\"}, {\"asset_id\":\"114356653315647913247200886351065428002113119844334520181865067698979836634569\", \"price\":\"0.14\", \"size\":\"5406\", \"side\":\"SELL\", \"hash\":\"a9dcd9bb1aa4fe21c7442a6e37ea5525c9a1739b\", \"best_bid\":\"0.13\", \"best_ask\":\"0.14\"}], \"timestamp\":\"1789987926551\", \"event_type\":\"price_change\"}","raw_base64":null}
{"received_ms":1789987926572,"monotonic_ns":1019367402641900,"raw":"{\"market\":\"0x28a45972fccdaf0fba75dacc59725521035e177d09dd92174f9f52740bccb025\", \"price_changes\":[{\"asset_id\":\"61819828071723399190623735325323968706432622380635304641786792960078828866875\", \"price\":\"0.85\", \"size\":\"5011.35\", \"side\":\"BUY\", \"hash\":\"9d42ababbdb16b5d68cdcb368f8cd9f1fa5a679d\", \"best_bid\":\"0.86\", \"best_ask\":\"0.87\"}, {\"asset_id\":\"114356653315647913247200886351065428002113119844334520181865067698979836634569\", \"price\":\"0.15\", \"size\":\"5011.35\", \"side\":\"SELL\", \"hash\":\"9c88cb19540dfdad814f1303a0488366639a8aa3\", \"best_bid\":\"0.13\", \"best_ask\":\"0.14\"}], \"timestamp\":\"1789987926551\", \"event_type\":\"price_change\"}","raw_base64":null}
{"received_ms":1789987926573,"monotonic_ns":1019367403366800,"raw":"{\"market\":\"0x28a45972fccdaf0fba75dacc59725521035e177d09dd92174f9f52740bccb025\", \"price_changes\":[{\"asset_id\":\"114356653315647913247200886351065428002113119844334520181865067698979836634569\", \"price\":\"0.11\", \"size\":\"136.1\", \"side\":\"BUY\", \"hash\":\"c2fd136b3b8fe5e99028ebb9baf7815ec2c28e22\", \"best_bid\":\"0.13\", \"best_ask\":\"0.14\"}, {\"asset_id\":\"61819828071723399190623735325323968706432622380635304641786792960078828866875\", \"price\":\"0.89\", \"size\":\"136.1\", \"side\":\"SELL\", \"hash\":\"5c2d6c8dd94d52007415326ca0dd1bec33fe1950\", \"best_bid\":\"0.86\", \"best_ask\":\"0.87\"}], \"timestamp\":\"1789987926552\", \"event_type\":\"price_change\"}","raw_base64":null}
{"received_ms":1789987926573,"monotonic_ns":1019367404131700,"raw":"{\"market\":\"0x28a45972fccdaf0fba75dacc59725521035e177d09dd92174f9f52740bccb025\", \"price_changes\":[{\"asset_id\":\"114356653315647913247200886351065428002113119844334520181865067698979836634569\", \"price\":\"0.13\", \"size\":\"255\", \"side\":\"BUY\", \"hash\":\"99ecf656fc582380d3585a7261e388bf3f439fcc\", \"best_bid\":\"0.13\", \"best_ask\":\"0.14\"}, {\"asset_id\":\"61819828071723399190623735325323968706432622380635304641786792960078828866875\", \"price\":\"0.87\", \"size\":\"255\", \"side\":\"SELL\", \"hash\":\"1231caf3f9f44e9000fe521e2175f38094fe5db8\", \"best_bid\":\"0.86\", \"best_ask\":\"0.87\"}], \"timestamp\":\"1789987926553\", \"event_type\":\"price_change\"}","raw_base64":null}
{"received_ms":1789987926577,"monotonic_ns":1019367407947300,"raw":"{\"market\":\"0x28a45972fccdaf0fba75dacc59725521035e177d09dd92174f9f52740bccb025\", \"price_changes\":[{\"asset_id\":\"61819828071723399190623735325323968706432622380635304641786792960078828866875\", \"price\":\"0.76\", \"size\":\"390\", \"side\":\"BUY\", \"hash\":\"d0d9c6823aab9b51f6ca969d7e4182b5e3169dc2\", \"best_bid\":\"0.86\", \"best_ask\":\"0.87\"}, {\"asset_id\":\"114356653315647913247200886351065428002113119844334520181865067698979836634569\", \"price\":\"0.24\", \"size\":\"390\", \"side\":\"SELL\", \"hash\":\"a7187cc7df5092cf6bd470419e24333cc4d3aaa7\", \"best_bid\":\"0.13\", \"best_ask\":\"0.14\"}], \"timestamp\":\"1789987926556\", \"event_type\":\"price_change\"}","raw_base64":null}
{"received_ms":1789987926581,"monotonic_ns":1019367411926900,"raw":"{\"market\":\"0x28a45972fccdaf0fba75dacc59725521035e177d09dd92174f9f52740bccb025\", \"price_changes\":[{\"asset_id\":\"61819828071723399190623735325323968706432622380635304641786792960078828866875\", \"price\":\"0.83\", \"size\":\"444\", \"side\":\"BUY\", \"hash\":\"521345b63744666f5f66abef445905ca44e21569\", \"best_bid\":\"0.86\", \"best_ask\":\"0.87\"}, {\"asset_id\":\"114356653315647913247200886351065428002113119844334520181865067698979836634569\", \"price\":\"0.17\", \"size\":\"444\", \"side\":\"SELL\", \"hash\":\"94b984f6f266cc82cb2e7516cb8ddf043844f910\", \"best_bid\":\"0.13\", \"best_ask\":\"0.14\"}], \"timestamp\":\"1789987926557\", \"event_type\":\"price_change\"}","raw_base64":null}
{"received_ms":1789987926585,"monotonic_ns":1019367416222700,"raw":"{\"market\":\"0x28a45972fccdaf0fba75dacc59725521035e177d09dd92174f9f52740bccb025\", \"price_changes\":[{\"asset_id\":\"114356653315647913247200886351065428002113119844334520181865067698979836634569\", \"price\":\"0.09\", \"size\":\"670.12\", \"side\":\"BUY\", \"hash\":\"551c1fc9b258b9cbd4fb072679f0de58a053f3cd\", \"best_bid\":\"0.13\", \"best_ask\":\"0.14\"}, {\"asset_id\":\"61819828071723399190623735325323968706432622380635304641786792960078828866875\", \"price\":\"0.91\", \"size\":\"670.12\", \"side\":\"SELL\", \"hash\":\"e706c47a21938c0dc6bb150ff05789b034ac6932\", \"best_bid\":\"0.86\", \"best_ask\":\"0.87\"}], \"timestamp\":\"1789987926565\", \"event_type\":\"price_change\"}","raw_base64":null}
{"received_ms":1789987926593,"monotonic_ns":1019367423610400,"raw":"{\"market\":\"0x28a45972fccdaf0fba75dacc59725521035e177d09dd92174f9f52740bccb025\", \"price_changes\":[{\"asset_id\":\"114356653315647913247200886351065428002113119844334520181865067698979836634569\", \"price\":\"0.11\", \"size\":\"128.1\", \"side\":\"BUY\", \"hash\":\"8d5c4500125fda108d062114b83d206c3c70fd67\", \"best_bid\":\"0.13\", \"best_ask\":\"0.14\"}, {\"asset_id\":\"61819828071723399190623735325323968706432622380635304641786792960078828866875\", \"price\":\"0.89\", \"size\":\"128.1\", \"side\":\"SELL\", \"hash\":\"910be4e0eb601ff8784edd70ecd553eddb6c8878\", \"best_bid\":\"0.86\", \"best_ask\":\"0.87\"}], \"timestamp\":\"1789987926573\", \"event_type\":\"price_change\"}","raw_base64":null}
{"received_ms":1789987926599,"monotonic_ns":1019367429973400,"raw":"{\"market\":\"0x28a45972fccdaf0fba75dacc59725521035e177d09dd92174f9f52740bccb025\", \"price_changes\":[{\"asset_id\":\"114356653315647913247200886351065428002113119844334520181865067698979836634569\", \"price\":\"0.09\", \"size\":\"678.12\", \"side\":\"BUY\", \"hash\":\"c6f8489f89514c6f4807b4159a69f7f9bea2c186\", \"best_bid\":\"0.13\", \"best_ask\":\"0.14\"}, {\"asset_id\":\"61819828071723399190623735325323968706432622380635304641786792960078828866875\", \"price\":\"0.91\", \"size\":\"678.12\", \"side\":\"SELL\", \"hash\":\"d970bb4fa548e3495a18632724c907fcc14b50a4\", \"best_bid\":\"0.86\", \"best_ask\":\"0.87\"}], \"timestamp\":\"1789987926579\", \"event_type\":\"price_change\"}","raw_base64":null}
{"received_ms":1789987926602,"monotonic_ns":1019367433007400,"raw":"{\"market\":\"0x28a45972fccdaf0fba75dacc59725521035e177d09dd92174f9f52740bccb025\", \"price_changes\":[{\"asset_id\":\"114356653315647913247200886351065428002113119844334520181865067698979836634569\", \"price\":\"0.07\", \"size\":\"5760.71\", \"side\":\"BUY\", \"hash\":\"8602ade2abc92392c8086498a6e883adaf3e176c\", \"best_bid\":\"0.13\", \"best_ask\":\"0.14\"}, {\"asset_id\":\"61819828071723399190623735325323968706432622380635304641786792960078828866875\", \"price\":\"0.93\", \"size\":\"5760.71\", \"side\":\"SELL\", \"hash\":\"3646efa36a5ed89f6369a45c377c4636011afc19\", \"best_bid\":\"0.86\", \"best_ask\":\"0.87\"}], \"timestamp\":\"1789987926582\", \"event_type\":\"price_change\"}","raw_base64":null}
{"received_ms":1789987926602,"monotonic_ns":1019367433079500,"raw":"{\"market\":\"0x28a45972fccdaf0fba75dacc59725521035e177d09dd92174f9f52740bccb025\", \"price_changes\":[{\"asset_id\":\"61819828071723399190623735325323968706432622380635304641786792960078828866875\", \"price\":\"0.86\", \"size\":\"5456\", \"side\":\"BUY\", \"hash\":\"534332e226533271f38ec3344bb9cdce66bc51d3\", \"best_bid\":\"0.86\", \"best_ask\":\"0.87\"}, {\"asset_id\":\"114356653315647913247200886351065428002113119844334520181865067698979836634569\", \"price\":\"0.14\", \"size\":\"5456\", \"side\":\"SELL\", \"hash\":\"43ee8c3d5d9109170ab6c82d6e44d15990ae66e1\", \"best_bid\":\"0.13\", \"best_ask\":\"0.14\"}], \"timestamp\":\"1789987926582\", \"event_type\":\"price_change\"}","raw_base64":null}
{"received_ms":1789987926605,"monotonic_ns":1019367435575300,"raw":"{\"market\":\"0x28a45972fccdaf0fba75dacc59725521035e177d09dd92174f9f52740bccb025\", \"price_changes\":[{\"asset_id\":\"114356653315647913247200886351065428002113119844334520181865067698979836634569\", \"price\":\"0.07\", \"size\":\"5767.71\", \"side\":\"BUY\", \"hash\":\"e250535de59b1f4e1e9e0394abfcf75e85e54376\", \"best_bid\":\"0.13\", \"best_ask\":\"0.14\"}, {\"asset_id\":\"61819828071723399190623735325323968706432622380635304641786792960078828866875\", \"price\":\"0.93\", \"size\":\"5767.71\", \"side\":\"SELL\", \"hash\":\"9c9fcb5316f494675066b9bbab987b85acb84e3b\", \"best_bid\":\"0.86\", \"best_ask\":\"0.87\"}], \"timestamp\":\"1789987926585\", \"event_type\":\"price_change\"}","raw_base64":null}
{"received_ms":1789987926606,"monotonic_ns":1019367436602400,"raw":"{\"market\":\"0x28a45972fccdaf0fba75dacc59725521035e177d09dd92174f9f52740bccb025\", \"price_changes\":[{\"asset_id\":\"114356653315647913247200886351065428002113119844334520181865067698979836634569\", \"price\":\"0.06\", \"size\":\"6707.67\", \"side\":\"BUY\", \"hash\":\"ba932e1f492c383a31759301f537ab168cfb5754\", \"best_bid\":\"0.13\", \"best_ask\":\"0.14\"}, {\"asset_id\":\"61819828071723399190623735325323968706432622380635304641786792960078828866875\", \"price\":\"0.94\", \"size\":\"6707.67\", \"side\":\"SELL\", \"hash\":\"2df56d9f11f303d30b293c2a78600e1dc578e992\", \"best_bid\":\"0.86\", \"best_ask\":\"0.87\"}], \"timestamp\":\"1789987926586\", \"event_type\":\"price_change\"}","raw_base64":null}
{"received_ms":1789987926609,"monotonic_ns":1019367439519200,"raw":"{\"market\":\"0x28a45972fccdaf0fba75dacc59725521035e177d09dd92174f9f52740bccb025\", \"price_changes\":[{\"asset_id\":\"61819828071723399190623735325323968706432622380635304641786792960078828866875\", \"price\":\"0.76\", \"size\":\"400\", \"side\":\"BUY\", \"hash\":\"792c49a9ab4c3211312c191d4782bcc52321259e\", \"best_bid\":\"0.86\", \"best_ask\":\"0.87\"}, {\"asset_id\":\"114356653315647913247200886351065428002113119844334520181865067698979836634569\", \"price\":\"0.24\", \"size\":\"400\", \"side\":\"SELL\", \"hash\":\"7973db892428c0184ca07c20b81ca7312f209b6c\", \"best_bid\":\"0.13\", \"best_ask\":\"0.14\"}], \"timestamp\":\"1789987926587\", \"event_type\":\"price_change\"}","raw_base64":null}
{"received_ms":1789987926614,"monotonic_ns":1019367444931700,"raw":"{\"market\":\"0x28a45972fccdaf0fba75dacc59725521035e177d09dd92174f9f52740bccb025\", \"price_changes\":[{\"asset_id\":\"61819828071723399190623735325323968706432622380635304641786792960078828866875\", \"price\":\"0.86\", \"size\":\"5491.17\", \"side\":\"BUY\", \"hash\":\"85ffc4ea7788f5e48a53766f23872faba32de8ef\", \"best_bid\":\"0.86\", \"best_ask\":\"0.87\"}, {\"asset_id\":\"114356653315647913247200886351065428002113119844334520181865067698979836634569\", \"price\":\"0.14\", \"size\":\"5491.17\", \"side\":\"SELL\", \"hash\":\"68dba76c5050332b0c74285b33c45a17d03b7816\", \"best_bid\":\"0.13\", \"best_ask\":\"0.14\"}], \"timestamp\":\"1789987926590\", \"event_type\":\"price_change\"}","raw_base64":null}
{"received_ms":1789987926627,"monotonic_ns":1019367457944500,"raw":"{\"market\":\"0x28a45972fccdaf0fba75dacc59725521035e177d09dd92174f9f52740bccb025\", \"price_changes\":[{\"asset_id\":\"114356653315647913247200886351065428002113119844334520181865067698979836634569\", \"price\":\"0.11\", \"size\":\"136.1\", \"side\":\"BUY\", \"hash\":\"83f03c88317108ee42d3329b4bb3efd855a81d60\", \"best_bid\":\"0.13\", \"best_ask\":\"0.14\"}, {\"asset_id\":\"61819828071723399190623735325323968706432622380635304641786792960078828866875\", \"price\":\"0.89\", \"size\":\"136.1\", \"side\":\"SELL\", \"hash\":\"2d571920b4e4f73ca8a3e02dac1e0dc248181617\", \"best_bid\":\"0.86\", \"best_ask\":\"0.87\"}], \"timestamp\":\"1789987926604\", \"event_type\":\"price_change\"}","raw_base64":null}
{"received_ms":1789987926651,"monotonic_ns":1019367481334600,"raw":"{\"market\":\"0x28a45972fccdaf0fba75dacc59725521035e177d09dd92174f9f52740bccb025\", \"price_changes\":[{\"asset_id\":\"114356653315647913247200886351065428002113119844334520181865067698979836634569\", \"price\":\"0.09\", \"size\":\"670.12\", \"side\":\"BUY\", \"hash\":\"e82a52da03bea3c45316072923ebe79462633bf9\", \"best_bid\":\"0.13\", \"best_ask\":\"0.14\"}, {\"asset_id\":\"61819828071723399190623735325323968706432622380635304641786792960078828866875\", \"price\":\"0.91\", \"size\":\"670.12\", \"side\":\"SELL\", \"hash\":\"a3d83e1de775b1898b734c6863eb2a0571c1f635\", \"best_bid\":\"0.86\", \"best_ask\":\"0.87\"}], \"timestamp\":\"1789987926627\", \"event_type\":\"price_change\"}","raw_base64":null}
{"received_ms":1789987926674,"monotonic_ns":1019367504515000,"raw":"{\"market\":\"0x28a45972fccdaf0fba75dacc59725521035e177d09dd92174f9f52740bccb025\", \"price_changes\":[{\"asset_id\":\"61819828071723399190623735325323968706432622380635304641786792960078828866875\", \"price\":\"0.85\", \"size\":\"4014.35\", \"side\":\"BUY\", \"hash\":\"ce1b92b1f93f0fa23fda22eccd0ffdec5ab3854f\", \"best_bid\":\"0.86\", \"best_ask\":\"0.87\"}, {\"asset_id\":\"114356653315647913247200886351065428002113119844334520181865067698979836634569\", \"price\":\"0.15\", \"size\":\"4014.35\", \"side\":\"SELL\", \"hash\":\"ed7eefe587042ed1338484f012036c0e052c941b\", \"best_bid\":\"0.13\", \"best_ask\":\"0.14\"}], \"timestamp\":\"1789987926648\", \"event_type\":\"price_change\"}","raw_base64":null}
{"received_ms":1789987926677,"monotonic_ns":1019367507719200,"raw":"{\"market\":\"0x28a45972fccdaf0fba75dacc59725521035e177d09dd92174f9f52740bccb025\", \"price_changes\":[{\"asset_id\":\"114356653315647913247200886351065428002113119844334520181865067698979836634569\", \"price\":\"0.09\", \"size\":\"610.12\", \"side\":\"BUY\", \"hash\":\"f2b92498c29b4f847b781f3276886605e3fa1f9d\", \"best_bid\":\"0.13\", \"best_ask\":\"0.14\"}, {\"asset_id\":\"61819828071723399190623735325323968706432622380635304641786792960078828866875\", \"price\":\"0.91\", \"size\":\"610.12\", \"side\":\"SELL\", \"hash\":\"e5670ff29f1c09585ff500dafc856f2ca09425c1\", \"best_bid\":\"0.86\", \"best_ask\":\"0.87\"}], \"timestamp\":\"1789987926654\", \"event_type\":\"price_change\"}","raw_base64":null}
{"received_ms":1789987926700,"monotonic_ns":1019367531037300,"raw":"{\"market\":\"0x28a45972fccdaf0fba75dacc59725521035e177d09dd92174f9f52740bccb025\", \"price_changes\":[{\"asset_id\":\"61819828071723399190623735325323968706432622380635304641786792960078828866875\", \"price\":\"0.85\", \"size\":\"4661.35\", \"side\":\"BUY\", \"hash\":\"b6dc7609bbcb0d8159931047fbc6d1229e6f20de\", \"best_bid\":\"0.86\", \"best_ask\":\"0.87\"}, {\"asset_id\":\"114356653315647913247200886351065428002113119844334520181865067698979836634569\", \"price\":\"0.15\", \"size\":\"4661.35\", \"side\":\"SELL\", \"hash\":\"3df7159c608aa5ecee2e86d9f6607761afe15335\", \"best_bid\":\"0.13\", \"best_ask\":\"0.14\"}], \"timestamp\":\"1789987926678\", \"event_type\":\"price_change\"}","raw_base64":null}
{"received_ms":1789987926704,"monotonic_ns":1019367535276600,"raw":"{\"market\":\"0x28a45972fccdaf0fba75dacc59725521035e177d09dd92174f9f52740bccb025\", \"price_changes\":[{\"asset_id\":\"61819828071723399190623735325323968706432622380635304641786792960078828866875\", \"price\":\"0.86\", \"size\":\"6171.17\", \"side\":\"BUY\", \"hash\":\"f5d0ab940b2478f623a86eec982da1040e340400\", \"best_bid\":\"0.86\", \"best_ask\":\"0.87\"}, {\"asset_id\":\"114356653315647913247200886351065428002113119844334520181865067698979836634569\", \"price\":\"0.14\", \"size\":\"6171.17\", \"side\":\"SELL\", \"hash\":\"9c4352da28a4a7926f2078b5207d493e98345ebd\", \"best_bid\":\"0.13\", \"best_ask\":\"0.14\"}], \"timestamp\":\"1789987926681\", \"event_type\":\"price_change\"}","raw_base64":null}
{"received_ms":1789987926720,"monotonic_ns":1019367550694200,"raw":"{\"market\":\"0x28a45972fccdaf0fba75dacc59725521035e177d09dd92174f9f52740bccb025\", \"price_changes\":[{\"asset_id\":\"61819828071723399190623735325323968706432622380635304641786792960078828866875\", \"price\":\"0.84\", \"size\":\"3105\", \"side\":\"BUY\", \"hash\":\"96e207d3287ccef921f93b3ed553ca71904f93c9\", \"best_bid\":\"0.86\", \"best_ask\":\"0.87\"}, {\"asset_id\":\"114356653315647913247200886351065428002113119844334520181865067698979836634569\", \"price\":\"0.16\", \"size\":\"3105\", \"side\":\"SELL\", \"hash\":\"4ada1f983e29a400375362883b23c35a512eea37\", \"best_bid\":\"0.13\", \"best_ask\":\"0.14\"}], \"timestamp\":\"1789987926698\", \"event_type\":\"price_change\"}","raw_base64":null}
{"received_ms":1789987926720,"monotonic_ns":1019367550763000,"raw":"{\"market\":\"0x28a45972fccdaf0fba75dacc59725521035e177d09dd92174f9f52740bccb025\", \"price_changes\":[{\"asset_id\":\"114356653315647913247200886351065428002113119844334520181865067698979836634569\", \"price\":\"0.07\", \"size\":\"5330.71\", \"side\":\"BUY\", \"hash\":\"ceccd55dffb57ceabb1101a89cf6c30c927090ac\", \"best_bid\":\"0.13\", \"best_ask\":\"0.14\"}, {\"asset_id\":\"61819828071723399190623735325323968706432622380635304641786792960078828866875\", \"price\":\"0.93\", \"size\":\"5330.71\", \"side\":\"SELL\", \"hash\":\"84f757468eccb0fa42f58a2490d2671a18905171\", \"best_bid\":\"0.86\", \"best_ask\":\"0.87\"}], \"timestamp\":\"1789987926698\", \"event_type\":\"price_change\"}","raw_base64":null}
{"received_ms":1789987926727,"monotonic_ns":1019367557568500,"raw":"{\"market\":\"0x28a45972fccdaf0fba75dacc59725521035e177d09dd92174f9f52740bccb025\", \"price_changes\":[{\"asset_id\":\"61819828071723399190623735325323968706432622380635304641786792960078828866875\", \"price\":\"0.84\", \"size\":\"2230\", \"side\":\"BUY\", \"hash\":\"fb148ad121efb7aa99bfdaddf78c5c644940da1f\", \"best_bid\":\"0.86\", \"best_ask\":\"0.87\"}, {\"asset_id\":\"114356653315647913247200886351065428002113119844334520181865067698979836634569\", \"price\":\"0.16\", \"size\":\"2230\", \"side\":\"SELL\", \"hash\":\"6649621a089937409200e3456630731382d87852\", \"best_bid\":\"0.13\", \"best_ask\":\"0.14\"}], \"timestamp\":\"1789987926703\", \"event_type\":\"price_change\"}","raw_base64":null}
{"received_ms":1789987926727,"monotonic_ns":1019367557665000,"raw":"{\"market\":\"0x28a45972fccdaf0fba75dacc59725521035e177d09dd92174f9f52740bccb025\", \"price_changes\":[{\"asset_id\":\"114356653315647913247200886351065428002113119844334520181865067698979836634569\", \"price\":\"0.06\", \"size\":\"5335.67\", \"side\":\"BUY\", \"hash\":\"ff924c7638542ca8a8c6fc086aa1d0d8dd39950a\", \"best_bid\":\"0.13\", \"best_ask\":\"0.14\"}, {\"asset_id\":\"61819828071723399190623735325323968706432622380635304641786792960078828866875\", \"price\":\"0.94\", \"size\":\"5335.67\", \"side\":\"SELL\", \"hash\":\"debdb4280ba83522182a2ef8ad0ec9ba29a1b1ce\", \"best_bid\":\"0.86\", \"best_ask\":\"0.87\"}], \"timestamp\":\"1789987926705\", \"event_type\":\"price_change\"}","raw_base64":null}
{"received_ms":1789987926732,"monotonic_ns":1019367563214200,"raw":"{\"market\":\"0x28a45972fccdaf0fba75dacc59725521035e177d09dd92174f9f52740bccb025\", \"price_changes\":[{\"asset_id\":\"61819828071723399190623735325323968706432622380635304641786792960078828866875\", \"price\":\"0.86\", \"size\":\"5491.17\", \"side\":\"BUY\", \"hash\":\"5e2b1b7fa351c5f1ff5c62239b2625f83eb79780\", \"best_bid\":\"0.86\", \"best_ask\":\"0.87\"}, {\"asset_id\":\"114356653315647913247200886351065428002113119844334520181865067698979836634569\", \"price\":\"0.14\", \"size\":\"5491.17\", \"side\":\"SELL\", \"hash\":\"a7213a7152e62783dbb08ac86ba522d73604f2c0\", \"best_bid\":\"0.13\", \"best_ask\":\"0.14\"}], \"timestamp\":\"1789987926712\", \"event_type\":\"price_change\"}","raw_base64":null}
{"received_ms":1789987926740,"monotonic_ns":1019367570288000,"raw":"{\"market\":\"0x28a45972fccdaf0fba75dacc59725521035e177d09dd92174f9f52740bccb025\", \"price_changes\":[{\"asset_id\":\"114356653315647913247200886351065428002113119844334520181865067698979836634569\", \"price\":\"0.09\", \"size\":\"670.12\", \"side\":\"BUY\", \"hash\":\"d39ba9cd53f8c70e376f100303ef82639efdcc66\", \"best_bid\":\"0.13\", \"best_ask\":\"0.14\"}, {\"asset_id\":\"61819828071723399190623735325323968706432622380635304641786792960078828866875\", \"price\":\"0.91\", \"size\":\"670.12\", \"side\":\"SELL\", \"hash\":\"1cadba374bfa439ac32af2c5d6ba5b1c3e75cf7e\", \"best_bid\":\"0.86\", \"best_ask\":\"0.87\"}], \"timestamp\":\"1789987926717\", \"event_type\":\"price_change\"}","raw_base64":null}
{"received_ms":1789987926760,"monotonic_ns":1019367590416800,"raw":"{\"market\":\"0x28a45972fccdaf0fba75dacc59725521035e177d09dd92174f9f52740bccb025\", \"price_changes\":[{\"asset_id\":\"114356653315647913247200886351065428002113119844334520181865067698979836634569\", \"price\":\"0.07\", \"size\":\"5560.71\", \"side\":\"BUY\", \"hash\":\"dd829b8bf25beaa1d1e61d44cecb0795a8a2c327\", \"best_bid\":\"0.13\", \"best_ask\":\"0.14\"}, {\"asset_id\":\"61819828071723399190623735325323968706432622380635304641786792960078828866875\", \"price\":\"0.93\", \"size\":\"5560.71\", \"side\":\"SELL\", \"hash\":\"dfee5d38552074795466deb80be87e8aa62d01e8\", \"best_bid\":\"0.86\", \"best_ask\":\"0.87\"}], \"timestamp\":\"1789987926738\", \"event_type\":\"price_change\"}","raw_base64":null}
{"received_ms":1789987926761,"monotonic_ns":1019367591550900,"raw":"{\"market\":\"0x28a45972fccdaf0fba75dacc59725521035e177d09dd92174f9f52740bccb025\", \"price_changes\":[{\"asset_id\":\"114356653315647913247200886351065428002113119844334520181865067698979836634569\", \"price\":\"0.06\", \"size\":\"5828.67\", \"side\":\"BUY\", \"hash\":\"e7bf77a8a1a59e9f5a833c7050c2b6f8cdd78556\", \"best_bid\":\"0.13\", \"best_ask\":\"0.14\"}, {\"asset_id\":\"61819828071723399190623735325323968706432622380635304641786792960078828866875\", \"price\":\"0.94\", \"size\":\"5828.67\", \"side\":\"SELL\", \"hash\":\"8ab15711468dfe4f40aaa37aceba3d2a5c71b030\", \"best_bid\":\"0.86\", \"best_ask\":\"0.87\"}], \"timestamp\":\"1789987926739\", \"event_type\":\"price_change\"}","raw_base64":null}
{"received_ms":1789987926776,"monotonic_ns":1019367607155000,"raw":"{\"market\":\"0x28a45972fccdaf0fba75dacc59725521035e177d09dd92174f9f52740bccb025\", \"price_changes\":[{\"asset_id\":\"61819828071723399190623735325323968706432622380635304641786792960078828866875\", \"price\":\"0.85\", \"size\":\"4014.35\", \"side\":\"BUY\", \"hash\":\"a31bfe8f7ea27828ea9920371cffaad43b4403cc\", \"best_bid\":\"0.86\", \"best_ask\":\"0.87\"}, {\"asset_id\":\"114356653315647913247200886351065428002113119844334520181865067698979836634569\", \"price\":\"0.15\", \"size\":\"4014.35\", \"side\":\"SELL\", \"hash\":\"ee10268fdbebdba65c2a31cf70158747dc1f79c8\", \"best_bid\":\"0.13\", \"best_ask\":\"0.14\"}], \"timestamp\":\"1789987926755\", \"event_type\":\"price_change\"}","raw_base64":null}
{"received_ms":1789987926790,"monotonic_ns":1019367621170100,"raw":"{\"market\":\"0x28a45972fccdaf0fba75dacc59725521035e177d09dd92174f9f52740bccb025\", \"price_changes\":[{\"asset_id\":\"114356653315647913247200886351065428002113119844334520181865067698979836634569\", \"price\":\"0.05\", \"size\":\"773\", \"side\":\"BUY\", \"hash\":\"7c73c11a19ee82f9d53b985b856587881c39375d\", \"best_bid\":\"0.13\", \"best_ask\":\"0.14\"}, {\"asset_id\":\"61819828071723399190623735325323968706432622380635304641786792960078828866875\", \"price\":\"0.95\", \"size\":\"773\", \"side\":\"SELL\", \"hash\":\"4d50af492bee6db7a588da4d7134eb41a3f4fd21\", \"best_bid\":\"0.86\", \"best_ask\":\"0.87\"}], \"timestamp\":\"1789987926766\", \"event_type\":\"price_change\"}","raw_base64":null}
{"received_ms":1789987926818,"monotonic_ns":1019367648895900,"raw":"{\"market\":\"0x28a45972fccdaf0fba75dacc59725521035e177d09dd92174f9f52740bccb025\", \"price_changes\":[{\"asset_id\":\"61819828071723399190623735325323968706432622380635304641786792960078828866875\", \"price\":\"0.81\", \"size\":\"610\", \"side\":\"BUY\", \"hash\":\"15dcf421ca7ca756f7fd05f2708a3440d4ad001d\", \"best_bid\":\"0.86\", \"best_ask\":\"0.87\"}, {\"asset_id\":\"114356653315647913247200886351065428002113119844334520181865067698979836634569\", \"price\":\"0.19\", \"size\":\"610\", \"side\":\"SELL\", \"hash\":\"612273aabd3ad18d959592a89d8188cb5e37c68d\", \"best_bid\":\"0.13\", \"best_ask\":\"0.14\"}], \"timestamp\":\"1789987926790\", \"event_type\":\"price_change\"}","raw_base64":null}
{"received_ms":1789987926818,"monotonic_ns":1019367648938800,"raw":"{\"market\":\"0x28a45972fccdaf0fba75dacc59725521035e177d09dd92174f9f52740bccb025\", \"price_changes\":[{\"asset_id\":\"61819828071723399190623735325323968706432622380635304641786792960078828866875\", \"price\":\"0.79\", \"size\":\"527\", \"side\":\"BUY\", \"hash\":\"f4242e911b83fd7b95a848d97995dfaf84b2ffe2\", \"best_bid\":\"0.86\", \"best_ask\":\"0.87\"}, {\"asset_id\":\"114356653315647913247200886351065428002113119844334520181865067698979836634569\", \"price\":\"0.21\", \"size\":\"527\", \"side\":\"SELL\", \"hash\":\"719a432d962c53f4e958eac715e0812ca86abafa\", \"best_bid\":\"0.13\", \"best_ask\":\"0.14\"}], \"timestamp\":\"1789987926791\", \"event_type\":\"price_change\"}","raw_base64":null}
{"received_ms":1789987926818,"monotonic_ns":1019367648977500,"raw":"{\"market\":\"0x28a45972fccdaf0fba75dacc59725521035e177d09dd92174f9f52740bccb025\", \"price_changes\":[{\"asset_id\":\"61819828071723399190623735325323968706432622380635304641786792960078828866875\", \"price\":\"0.86\", \"size\":\"6141.17\", \"side\":\"BUY\", \"hash\":\"de6c8bca327bfb51fb94b819b2c75cae92c4cfcb\", \"best_bid\":\"0.86\", \"best_ask\":\"0.87\"}, {\"asset_id\":\"114356653315647913247200886351065428002113119844334520181865067698979836634569\", \"price\":\"0.14\", \"size\":\"6141.17\", \"side\":\"SELL\", \"hash\":\"5c3c5a277671587578cb65753b47e8769747491c\", \"best_bid\":\"0.13\", \"best_ask\":\"0.14\"}], \"timestamp\":\"1789987926792\", \"event_type\":\"price_change\"}","raw_base64":null}
{"received_ms":1789987926818,"monotonic_ns":1019367649015500,"raw":"{\"market\":\"0x28a45972fccdaf0fba75dacc59725521035e177d09dd92174f9f52740bccb025\", \"price_changes\":[{\"asset_id\":\"61819828071723399190623735325323968706432622380635304641786792960078828866875\", \"price\":\"0.79\", \"size\":\"447\", \"side\":\"BUY\", \"hash\":\"da7e4f7aae2b09749b8a052c75b4473f4c00dec1\", \"best_bid\":\"0.86\", \"best_ask\":\"0.87\"}, {\"asset_id\":\"114356653315647913247200886351065428002113119844334520181865067698979836634569\", \"price\":\"0.21\", \"size\":\"447\", \"side\":\"SELL\", \"hash\":\"696c661171c800f09ef1a77a179b0e81a788a4c0\", \"best_bid\":\"0.13\", \"best_ask\":\"0.14\"}], \"timestamp\":\"1789987926793\", \"event_type\":\"price_change\"}","raw_base64":null}
{"received_ms":1789987926818,"monotonic_ns":1019367649056100,"raw":"{\"market\":\"0x28a45972fccdaf0fba75dacc59725521035e177d09dd92174f9f52740bccb025\", \"price_changes\":[{\"asset_id\":\"61819828071723399190623735325323968706432622380635304641786792960078828866875\", \"price\":\"0.81\", \"size\":\"590\", \"side\":\"BUY\", \"hash\":\"da7e4f7aae2b09749b8a052c75b4473f4c00dec1\", \"best_bid\":\"0.86\", \"best_ask\":\"0.87\"}, {\"asset_id\":\"114356653315647913247200886351065428002113119844334520181865067698979836634569\", \"price\":\"0.19\", \"size\":\"590\", \"side\":\"SELL\", \"hash\":\"696c661171c800f09ef1a77a179b0e81a788a4c0\", \"best_bid\":\"0.13\", \"best_ask\":\"0.14\"}], \"timestamp\":\"1789987926793\", \"event_type\":\"price_change\"}","raw_base64":null}
{"received_ms":1789987926818,"monotonic_ns":1019367649097700,"raw":"{\"market\":\"0x28a45972fccdaf0fba75dacc59725521035e177d09dd92174f9f52740bccb025\", \"price_changes\":[{\"asset_id\":\"61819828071723399190623735325323968706432622380635304641786792960078828866875\", \"price\":\"0.84\", \"size\":\"3084\", \"side\":\"BUY\", \"hash\":\"3820ceeed1857f9d9b6513b244780b952007c7d8\", \"best_bid\":\"0.86\", \"best_ask\":\"0.87\"}, {\"asset_id\":\"114356653315647913247200886351065428002113119844334520181865067698979836634569\", \"price\":\"0.16\", \"size\":\"3084\", \"side\":\"SELL\", \"hash\":\"7454a351dcb10fa118c0c2e358c099e8075808db\", \"best_bid\":\"0.13\", \"best_ask\":\"0.14\"}], \"timestamp\":\"1789987926793\", \"event_type\":\"price_change\"}","raw_base64":null}
{"received_ms":1789987926822,"monotonic_ns":1019367652656800,"raw":"{\"market\":\"0x28a45972fccdaf0fba75dacc59725521035e177d09dd92174f9f52740bccb025\", \"price_changes\":[{\"asset_id\":\"114356653315647913247200886351065428002113119844334520181865067698979836634569\", \"price\":\"0.09\", \"size\":\"610.12\", \"side\":\"BUY\", \"hash\":\"bbb2d0ab03176611fa5ff42a3156c4cc6a8d3616\", \"best_bid\":\"0.13\", \"best_ask\":\"0.14\"}, {\"asset_id\":\"61819828071723399190623735325323968706432622380635304641786792960078828866875\", \"price\":\"0.91\", \"size\":\"610.12\", \"side\":\"SELL\", \"hash\":\"32e45fbc9f4b033f55adfc985b95e0bbff2ef55e\", \"best_bid\":\"0.86\", \"best_ask\":\"0.87\"}], \"timestamp\":\"1789987926800\", \"event_type\":\"price_change\"}","raw_base64":null}
{"received_ms":1789987926839,"monotonic_ns":1019367669964400,"raw":"{\"market\":\"0x28a45972fccdaf0fba75dacc59725521035e177d09dd92174f9f52740bccb025\", \"price_changes\":[{\"asset_id\":\"114356653315647913247200886351065428002113119844334520181865067698979836634569\", \"price\":\"0.07\", \"size\":\"5330.71\", \"side\":\"BUY\", \"hash\":\"5abd3b58f6b4b5371d0723e5e8d536fffdae1238\", \"best_bid\":\"0.13\", \"best_ask\":\"0.14\"}, {\"asset_id\":\"61819828071723399190623735325323968706432622380635304641786792960078828866875\", \"price\":\"0.93\", \"size\":\"5330.71\", \"side\":\"SELL\", \"hash\":\"bc06a9d71e3ca3cfb6f47214c2f6f8c75119d2b0\", \"best_bid\":\"0.86\", \"best_ask\":\"0.87\"}], \"timestamp\":\"1789987926817\", \"event_type\":\"price_change\"}","raw_base64":null}
{"received_ms":1789987926847,"monotonic_ns":1019367677856000,"raw":"{\"market\":\"0x28a45972fccdaf0fba75dacc59725521035e177d09dd92174f9f52740bccb025\", \"price_changes\":[{\"asset_id\":\"61819828071723399190623735325323968706432622380635304641786792960078828866875\", \"price\":\"0.85\", \"size\":\"4557.35\", \"side\":\"BUY\", \"hash\":\"b9098318382a602e0d58aa5759693a6ee274e096\", \"best_bid\":\"0.86\", \"best_ask\":\"0.87\"}, {\"asset_id\":\"114356653315647913247200886351065428002113119844334520181865067698979836634569\", \"price\":\"0.15\", \"size\":\"4557.35\", \"side\":\"SELL\", \"hash\":\"1055d52e5590fcdee5919d188354837de30a6a96\", \"best_bid\":\"0.13\", \"best_ask\":\"0.14\"}], \"timestamp\":\"1789987926824\", \"event_type\":\"price_change\"}","raw_base64":null}
{"received_ms":1789987926854,"monotonic_ns":1019367684852000,"raw":"{\"market\":\"0x28a45972fccdaf0fba75dacc59725521035e177d09dd92174f9f52740bccb025\", \"price_changes\":[{\"asset_id\":\"114356653315647913247200886351065428002113119844334520181865067698979836634569\", \"price\":\"0.1\", \"size\":\"517\", \"side\":\"BUY\", \"hash\":\"d38b7f81794689bee2436c16e1fece3ccf93a805\", \"best_bid\":\"0.13\", \"best_ask\":\"0.14\"}, {\"asset_id\":\"61819828071723399190623735325323968706432622380635304641786792960078828866875\", \"price\":\"0.9\", \"size\":\"517\", \"side\":\"SELL\", \"hash\":\"aab96b38a0608b0880e9f2255f6f337f0b543b40\", \"best_bid\":\"0.86\", \"best_ask\":\"0.87\"}], \"timestamp\":\"1789987926831\", \"event_type\":\"price_change\"}","raw_base64":null}
{"received_ms":1789987926854,"monotonic_ns":1019367684939000,"raw":"{\"market\":\"0x28a45972fccdaf0fba75dacc59725521035e177d09dd92174f9f52740bccb025\", \"price_changes\":[{\"asset_id\":\"114356653315647913247200886351065428002113119844334520181865067698979836634569\", \"price\":\"0.1\", \"size\":\"497\", \"side\":\"BUY\", \"hash\":\"9de67578b889d1edc78d2b37941d646c7d0279b8\", \"best_bid\":\"0.13\", \"best_ask\":\"0.14\"}, {\"asset_id\":\"61819828071723399190623735325323968706432622380635304641786792960078828866875\", \"price\":\"0.9\", \"size\":\"497\", \"side\":\"SELL\", \"hash\":\"086928853906053d55aad81db38810ad2801eaf0\", \"best_bid\":\"0.86\", \"best_ask\":\"0.87\"}], \"timestamp\":\"1789987926834\", \"event_type\":\"price_change\"}","raw_base64":null}
{"received_ms":1789987926875,"monotonic_ns":1019367705923200,"raw":"{\"market\":\"0x28a45972fccdaf0fba75dacc59725521035e177d09dd92174f9f52740bccb025\", \"price_changes\":[{\"asset_id\":\"114356653315647913247200886351065428002113119844334520181865067698979836634569\", \"price\":\"0.07\", \"size\":\"5649.71\", \"side\":\"BUY\", \"hash\":\"5565c23eb5fb6f4191cc06cb9f1e14d564e3ac5b\", \"best_bid\":\"0.13\", \"best_ask\":\"0.14\"}, {\"asset_id\":\"61819828071723399190623735325323968706432622380635304641786792960078828866875\", \"price\":\"0.93\", \"size\":\"5649.71\", \"side\":\"SELL\", \"hash\":\"8e1e18d5360ba5c61260ffaa15236f2d16a4285a\", \"best_bid\":\"0.86\", \"best_ask\":\"0.87\"}], \"timestamp\":\"1789987926855\", \"event_type\":\"price_change\"}","raw_base64":null}
{"received_ms":1789987926878,"monotonic_ns":1019367708331400,"raw":"{\"market\":\"0x28a45972fccdaf0fba75dacc59725521035e177d09dd92174f9f52740bccb025\", \"price_changes\":[{\"asset_id\":\"114356653315647913247200886351065428002113119844334520181865067698979836634569\", \"price\":\"0.06\", \"size\":\"6828.67\", \"side\":\"BUY\", \"hash\":\"e6204d8631bf8c96130b207ec601c52d1266d78e\", \"best_bid\":\"0.13\", \"best_ask\":\"0.14\"}, {\"asset_id\":\"61819828071723399190623735325323968706432622380635304641786792960078828866875\", \"price\":\"0.94\", \"size\":\"6828.67\", \"side\":\"SELL\", \"hash\":\"6c3242cbf738d145771ad8c2d4782c10d9176db5\", \"best_bid\":\"0.86\", \"best_ask\":\"0.87\"}], \"timestamp\":\"1789987926856\", \"event_type\":\"price_change\"}","raw_base64":null}
{"received_ms":1789987926878,"monotonic_ns":1019367708415700,"raw":"{\"market\":\"0x28a45972fccdaf0fba75dacc59725521035e177d09dd92174f9f52740bccb025\", \"price_changes\":[{\"asset_id\":\"61819828071723399190623735325323968706432622380635304641786792960078828866875\", \"price\":\"0.85\", \"size\":\"4657.35\", \"side\":\"BUY\", \"hash\":\"5eb7ba34db82e1456b473b1fe8502e8dea5b6dec\", \"best_bid\":\"0.86\", \"best_ask\":\"0.87\"}, {\"asset_id\":\"114356653315647913247200886351065428002113119844334520181865067698979836634569\", \"price\":\"0.15\", \"size\":\"4657.35\", \"side\":\"SELL\", \"hash\":\"2040df3df4de5e555928db88fe3f43a099be9902\", \"best_bid\":\"0.13\", \"best_ask\":\"0.14\"}], \"timestamp\":\"1789987926856\", \"event_type\":\"price_change\"}","raw_base64":null}
{"received_ms":1789987926878,"monotonic_ns":1019367708461500,"raw":"{\"market\":\"0x28a45972fccdaf0fba75dacc59725521035e177d09dd92174f9f52740bccb025\", \"price_changes\":[{\"asset_id\":\"114356653315647913247200886351065428002113119844334520181865067698979836634569\", \"price\":\"0.05\", \"size\":\"5717\", \"side\":\"BUY\", \"hash\":\"5d7e318dd76cb8e2fbdb88d470394dd737c42cac\", \"best_bid\":\"0.13\", \"best_ask\":\"0.14\"}, {\"asset_id\":\"61819828071723399190623735325323968706432622380635304641786792960078828866875\", \"price\":\"0.95\", \"size\":\"5717\", \"side\":\"SELL\", \"hash\":\"5914be06ae274427cd8a431381dc396c1e0b5cd5\", \"best_bid\":\"0.86\", \"best_ask\":\"0.87\"}], \"timestamp\":\"1789987926857\", \"event_type\":\"price_change\"}","raw_base64":null}
{"received_ms":1789987926880,"monotonic_ns":1019367710469500,"raw":"{\"market\":\"0x28a45972fccdaf0fba75dacc59725521035e177d09dd92174f9f52740bccb025\", \"price_changes\":[{\"asset_id\":\"61819828071723399190623735325323968706432622380635304641786792960078828866875\", \"price\":\"0.85\", \"size\":\"4597.35\", \"side\":\"BUY\", \"hash\":\"e7e4f35a8eddde9213cf7c31b2bd522970926787\", \"best_bid\":\"0.86\", \"best_ask\":\"0.87\"}, {\"asset_id\":\"114356653315647913247200886351065428002113119844334520181865067698979836634569\", \"price\":\"0.15\", \"size\":\"4597.35\", \"side\":\"SELL\", \"hash\":\"fe9ab1863c3cdc48647632195888a8e520d22da2\", \"best_bid\":\"0.13\", \"best_ask\":\"0.14\"}], \"timestamp\":\"1789987926858\", \"event_type\":\"price_change\"}","raw_base64":null}
{"received_ms":1789987926884,"monotonic_ns":1019367715095400,"raw":"{\"market\":\"0x28a45972fccdaf0fba75dacc59725521035e177d09dd92174f9f52740bccb025\", \"price_changes\":[{\"asset_id\":\"114356653315647913247200886351065428002113119844334520181865067698979836634569\", \"price\":\"0.09\", \"size\":\"670.12\", \"side\":\"BUY\", \"hash\":\"b328c60479706eed2b5b1e227001304880ae38a6\", \"best_bid\":\"0.13\", \"best_ask\":\"0.14\"}, {\"asset_id\":\"61819828071723399190623735325323968706432622380635304641786792960078828866875\", \"price\":\"0.91\", \"size\":\"670.12\", \"side\":\"SELL\", \"hash\":\"6d57ec3297d5624f693922b24f1ed8eabf98ea3c\", \"best_bid\":\"0.86\", \"best_ask\":\"0.87\"}], \"timestamp\":\"1789987926862\", \"event_type\":\"price_change\"}","raw_base64":null}
{"received_ms":1789987926893,"monotonic_ns":1019367723646800,"raw":"{\"market\":\"0x28a45972fccdaf0fba75dacc59725521035e177d09dd92174f9f52740bccb025\", \"price_changes\":[{\"asset_id\":\"114356653315647913247200886351065428002113119844334520181865067698979836634569\", \"price\":\"0.09\", \"size\":\"610.12\", \"side\":\"BUY\", \"hash\":\"2f1d52532edc39a808747fe7166ff9bae3bd8e1b\", \"best_bid\":\"0.13\", \"best_ask\":\"0.14\"}, {\"asset_id\":\"61819828071723399190623735325323968706432622380635304641786792960078828866875\", \"price\":\"0.91\", \"size\":\"610.12\", \"side\":\"SELL\", \"hash\":\"7e031e0af7c7fe97cf3b7cd4b4348c665ce4fb60\", \"best_bid\":\"0.86\", \"best_ask\":\"0.87\"}], \"timestamp\":\"1789987926868\", \"event_type\":\"price_change\"}","raw_base64":null}
{"received_ms":1789987926912,"monotonic_ns":1019367742298400,"raw":"{\"market\":\"0x28a45972fccdaf0fba75dacc59725521035e177d09dd92174f9f52740bccb025\", \"price_changes\":[{\"asset_id\":\"61819828071723399190623735325323968706432622380635304641786792960078828866875\", \"price\":\"0.84\", \"size\":\"3144\", \"side\":\"BUY\", \"hash\":\"11ae84d4d7de54e0da3d04a52fcfc4b7785fbe32\", \"best_bid\":\"0.86\", \"best_ask\":\"0.87\"}, {\"asset_id\":\"114356653315647913247200886351065428002113119844334520181865067698979836634569\", \"price\":\"0.16\", \"size\":\"3144\", \"side\":\"SELL\", \"hash\":\"e43406174c5f72396c774faa3540b81388df9a61\", \"best_bid\":\"0.13\", \"best_ask\":\"0.14\"}], \"timestamp\":\"1789987926883\", \"event_type\":\"price_change\"}","raw_base64":null}
{"received_ms":1789987926913,"monotonic_ns":1019367743691200,"raw":"{\"market\":\"0x28a45972fccdaf0fba75dacc59725521035e177d09dd92174f9f52740bccb025\", \"price_changes\":[{\"asset_id\":\"61819828071723399190623735325323968706432622380635304641786792960078828866875\", \"price\":\"0.79\", \"size\":\"507\", \"side\":\"BUY\", \"hash\":\"c69a4a83b9d45ca4934111b2988bdc4de850f36d\", \"best_bid\":\"0.86\", \"best_ask\":\"0.87\"}, {\"asset_id\":\"114356653315647913247200886351065428002113119844334520181865067698979836634569\", \"price\":\"0.21\", \"size\":\"507\", \"side\":\"SELL\", \"hash\":\"da09d4245d35fc948722dbd40e97e8513518dc84\", \"best_bid\":\"0.13\", \"best_ask\":\"0.14\"}], \"timestamp\":\"1789987926891\", \"event_type\":\"price_change\"}","raw_base64":null}
{"received_ms":1789987926921,"monotonic_ns":1019367751351100,"raw":"{\"market\":\"0x28a45972fccdaf0fba75dacc59725521035e177d09dd92174f9f52740bccb025\", \"price_changes\":[{\"asset_id\":\"61819828071723399190623735325323968706432622380635304641786792960078828866875\", \"price\":\"0.86\", \"size\":\"5491.17\", \"side\":\"BUY\", \"hash\":\"58b6ba51e9be1beb95b0b4331dafea91a7698034\", \"best_bid\":\"0.86\", \"best_ask\":\"0.87\"}, {\"asset_id\":\"114356653315647913247200886351065428002113119844334520181865067698979836634569\", \"price\":\"0.14\", \"size\":\"5491.17\", \"side\":\"SELL\", \"hash\":\"235285db9db09a9712ac2507c207607ab1b25643\", \"best_bid\":\"0.13\", \"best_ask\":\"0.14\"}], \"timestamp\":\"1789987926898\", \"event_type\":\"price_change\"}","raw_base64":null}
{"received_ms":1789987926921,"monotonic_ns":1019367751398600,"raw":"{\"market\":\"0x28a45972fccdaf0fba75dacc59725521035e177d09dd92174f9f52740bccb025\", \"price_changes\":[{\"asset_id\":\"114356653315647913247200886351065428002113119844334520181865067698979836634569\", \"price\":\"0.1\", \"size\":\"517\", \"side\":\"BUY\", \"hash\":\"c56e8bcc24b61110809e120aad7d702b7af7ae04\", \"best_bid\":\"0.13\", \"best_ask\":\"0.14\"}, {\"asset_id\":\"61819828071723399190623735325323968706432622380635304641786792960078828866875\", \"price\":\"0.9\", \"size\":\"517\", \"side\":\"SELL\", \"hash\":\"bf5f73925a4d22631d698dcf69da5ce4873c892d\", \"best_bid\":\"0.86\", \"best_ask\":\"0.87\"}], \"timestamp\":\"1789987926900\", \"event_type\":\"price_change\"}","raw_base64":null}
{"received_ms":1789987926921,"monotonic_ns":1019367751597700,"raw":"{\"market\":\"0x28a45972fccdaf0fba75dacc59725521035e177d09dd92174f9f52740bccb025\", \"price_changes\":[{\"asset_id\":\"61819828071723399190623735325323968706432622380635304641786792960078828866875\", \"price\":\"0.84\", \"size\":\"2290\", \"side\":\"BUY\", \"hash\":\"9c0aa224558c6163cd7f0df98388e4cc7b21b017\", \"best_bid\":\"0.86\", \"best_ask\":\"0.87\"}, {\"asset_id\":\"114356653315647913247200886351065428002113119844334520181865067698979836634569\", \"price\":\"0.16\", \"size\":\"2290\", \"side\":\"SELL\", \"hash\":\"a7f956f4dff08ad9105e41bf0cb37e9193eb04c3\", \"best_bid\":\"0.13\", \"best_ask\":\"0.14\"}], \"timestamp\":\"1789987926900\", \"event_type\":\"price_change\"}","raw_base64":null}
{"received_ms":1789987926932,"monotonic_ns":1019367762398900,"raw":"{\"market\":\"0x28a45972fccdaf0fba75dacc59725521035e177d09dd92174f9f52740bccb025\", \"price_changes\":[{\"asset_id\":\"114356653315647913247200886351065428002113119844334520181865067698979836634569\", \"price\":\"0.13\", \"size\":\"265\", \"side\":\"BUY\", \"hash\":\"0553eef74c1f4f40b7deda926041ab2417f4cf47\", \"best_bid\":\"0.13\", \"best_ask\":\"0.14\"}, {\"asset_id\":\"61819828071723399190623735325323968706432622380635304641786792960078828866875\", \"price\":\"0.87\", \"size\":\"265\", \"side\":\"SELL\", \"hash\":\"9573619a895b4c16a5c806e80139dfb15f109781\", \"best_bid\":\"0.86\", \"best_ask\":\"0.87\"}], \"timestamp\":\"1789987926910\", \"event_type\":\"price_change\"}","raw_base64":null}
{"received_ms":1789987926953,"monotonic_ns":1019367783726900,"raw":"{\"market\":\"0x28a45972fccdaf0fba75dacc59725521035e177d09dd92174f9f52740bccb025\", \"price_changes\":[{\"asset_id\":\"61819828071723399190623735325323968706432622380635304641786792960078828866875\", \"price\":\"0.86\", \"size\":\"5931.17\", \"side\":\"BUY\", \"hash\":\"ebe136cefddfa5550d2db92fdb9c67d10eacb0b3\", \"best_bid\":\"0.86\", \"best_ask\":\"0.87\"}, {\"asset_id\":\"114356653315647913247200886351065428002113119844334520181865067698979836634569\", \"price\":\"0.14\", \"size\":\"5931.17\", \"side\":\"SELL\", \"hash\":\"076461c37ba19cc8da47adb61f972c2a098e9205\", \"best_bid\":\"0.13\", \"best_ask\":\"0.14\"}], \"timestamp\":\"1789987926931\", \"event_type\":\"price_change\"}","raw_base64":null}
{"received_ms":1789987926958,"monotonic_ns":1019367789096200,"raw":"{\"market\":\"0x28a45972fccdaf0fba75dacc59725521035e177d09dd92174f9f52740bccb025\", \"price_changes\":[{\"asset_id\":\"114356653315647913247200886351065428002113119844334520181865067698979836634569\", \"price\":\"0.05\", \"size\":\"773\", \"side\":\"BUY\", \"hash\":\"98c719209ae18f482f8009ca1e12dc14df1fd53e\", \"best_bid\":\"0.13\", \"best_ask\":\"0.14\"}, {\"asset_id\":\"61819828071723399190623735325323968706432622380635304641786792960078828866875\", \"price\":\"0.95\", \"size\":\"773\", \"side\":\"SELL\", \"hash\":\"2c3df254cd86952711fc6c9cf962169bdf18a967\", \"best_bid\":\"0.86\", \"best_ask\":\"0.87\"}], \"timestamp\":\"1789987926936\", \"event_type\":\"price_change\"}","raw_base64":null}
{"received_ms":1789987926958,"monotonic_ns":1019367789179900,"raw":"{\"market\":\"0x28a45972fccdaf0fba75dacc59725521035e177d09dd92174f9f52740bccb025\", \"price_changes\":[{\"asset_id\":\"114356653315647913247200886351065428002113119844334520181865067698979836634569\", \"price\":\"0.07\", \"size\":\"5330.71\", \"side\":\"BUY\", \"hash\":\"e346615cdcd42f2dc6b0bba23137151680615c77\", \"best_bid\":\"0.13\", \"best_ask\":\"0.14\"}, {\"asset_id\":\"61819828071723399190623735325323968706432622380635304641786792960078828866875\", \"price\":\"0.93\", \"size\":\"5330.71\", \"side\":\"SELL\", \"hash\":\"6e292fdcf3a2e1b53a74a0846eb05431298370dd\", \"best_bid\":\"0.86\", \"best_ask\":\"0.87\"}], \"timestamp\":\"1789987926937\", \"event_type\":\"price_change\"}","raw_base64":null}
{"received_ms":1789987926964,"monotonic_ns":1019367794936300,"raw":"{\"market\":\"0x28a45972fccdaf0fba75dacc59725521035e177d09dd92174f9f52740bccb025\", \"price_changes\":[{\"asset_id\":\"61819828071723399190623735325323968706432622380635304641786792960078828866875\", \"price\":\"0.84\", \"size\":\"2300\", \"side\":\"BUY\", \"hash\":\"7c532b45c2fe073a3c9faff121e5cbe659e88ded\", \"best_bid\":\"0.86\", \"best_ask\":\"0.87\"}, {\"asset_id\":\"114356653315647913247200886351065428002113119844334520181865067698979836634569\", \"price\":\"0.16\", \"size\":\"2300\", \"side\":\"SELL\", \"hash\":\"29e25d0c4f39172cf96816c2ad6e1a43e1d4831a\", \"best_bid\":\"0.13\", \"best_ask\":\"0.14\"}], \"timestamp\":\"1789987926943\", \"event_type\":\"price_change\"}","raw_base64":null}
{"received_ms":1789987926983,"monotonic_ns":1019367813399100,"raw":"{\"market\":\"0x28a45972fccdaf0fba75dacc59725521035e177d09dd92174f9f52740bccb025\", \"price_changes\":[{\"asset_id\":\"61819828071723399190623735325323968706432622380635304641786792960078828866875\", \"price\":\"0.84\", \"size\":\"3157\", \"side\":\"BUY\", \"hash\":\"e2a635d1804667475d68e6bb0f817fd0f39fb7a8\", \"best_bid\":\"0.86\", \"best_ask\":\"0.87\"}, {\"asset_id\":\"114356653315647913247200886351065428002113119844334520181865067698979836634569\", \"price\":\"0.16\", \"size\":\"3157\", \"side\":\"SELL\", \"hash\":\"00e7ecc97478024375e6a8e890fae68d653db033\", \"best_bid\":\"0.13\", \"best_ask\":\"0.14\"}], \"timestamp\":\"1789987926962\", \"event_type\":\"price_change\"}","raw_base64":null}
{"received_ms":1789987926987,"monotonic_ns":1019367817463300,"raw":"{\"market\":\"0x28a45972fccdaf0fba75dacc59725521035e177d09dd92174f9f52740bccb025\", \"price_changes\":[{\"asset_id\":\"61819828071723399190623735325323968706432622380635304641786792960078828866875\", \"price\":\"0.77\", \"size\":\"487.49\", \"side\":\"BUY\", \"hash\":\"7548cde71aaf8b6fe04bdf1a2521fc05667cc836\", \"best_bid\":\"0.86\", \"best_ask\":\"0.87\"}, {\"asset_id\":\"114356653315647913247200886351065428002113119844334520181865067698979836634569\", \"price\":\"0.23\", \"size\":\"487.49\", \"side\":\"SELL\", \"hash\":\"6cfcfec3df8c6806af0f31e5d3b3570f95d621b5\", \"best_bid\":\"0.13\", \"best_ask\":\"0.14\"}], \"timestamp\":\"1789987926965\", \"event_type\":\"price_change\"}","raw_base64":null}
{"received_ms":1789987926987,"monotonic_ns":1019367817553100,"raw":"{\"market\":\"0x28a45972fccdaf0fba75dacc59725521035e177d09dd92174f9f52740bccb025\", \"price_changes\":[{\"asset_id\":\"61819828071723399190623735325323968706432622380635304641786792960078828866875\", \"price\":\"0.84\", \"size\":\"3097\", \"side\":\"BUY\", \"hash\":\"7548cde71aaf8b6fe04bdf1a2521fc05667cc836\", \"best_bid\":\"0.86\", \"best_ask\":\"0.87\"}, {\"asset_id\":\"114356653315647913247200886351065428002113119844334520181865067698979836634569\", \"price\":\"0.16\", \"size\":\"3097\", \"side\":\"SELL\", \"hash\":\"6cfcfec3df8c6806af0f31e5d3b3570f95d621b5\", \"best_bid\":\"0.13\", \"best_ask\":\"0.14\"}], \"timestamp\":\"1789987926965\", \"event_type\":\"price_change\"}","raw_base64":null}
{"received_ms":1789987926994,"monotonic_ns":1019367824437100,"raw":"{\"market\":\"0x28a45972fccdaf0fba75dacc59725521035e177d09dd92174f9f52740bccb025\", \"price_changes\":[{\"asset_id\":\"114356653315647913247200886351065428002113119844334520181865067698979836634569\", \"price\":\"0.06\", \"size\":\"5828.67\", \"side\":\"BUY\", \"hash\":\"28b47f15b550451d3e8ffc0f56f31f69bb7c5d73\", \"best_bid\":\"0.13\", \"best_ask\":\"0.14\"}, {\"asset_id\":\"61819828071723399190623735325323968706432622380635304641786792960078828866875\", \"price\":\"0.94\", \"size\":\"5828.67\", \"side\":\"SELL\", \"hash\":\"20e12d4336ecb734ca489d3b96bdf0aaccbc2b35\", \"best_bid\":\"0.86\", \"best_ask\":\"0.87\"}], \"timestamp\":\"1789987926968\", \"event_type\":\"price_change\"}","raw_base64":null}
